Workbook
Name CONTRATISTA: 'Mano de Obra'!$A$2:$D$2
Name CONTRATISTA: Materiales!$A$2
Name CONTRATISTA: 'Precio Equipos'!#REF!
Name CONTRATISTA: 'Rend. Equipos'!#REF!
Name CONTRATISTA: 'Sub CONTRATOS'!$A$2:$E$2
Name FECHA: Materiales!$D$4
Name FECHA: 'Precio Equipos'!#REF!
Name FECHA: 'Rend. Equipos'!$E$3
Name FECHA: 'Sub CONTRATOS'!$E$4
Name FECHA: 'Mano de Obra'!$D$4
Name INICIO: Materiales!$A$1
Name INICIO: 'Precio Equipos'!$A$1
Name INICIO: 'Rend. Equipos'!$A$1
Name INICIO: 'Sub CONTRATOS'!$A$1
Name INICIO: 'Mano de Obra'!$A$1
Name OBRA: 'Mano de Obra'!$A$3:$D$3
Name OBRA: Materiales!$A$3
Name OBRA: 'Precio Equipos'!#REF!
Name OBRA: 'Rend. Equipos'!#REF!
Name OBRA: 'Sub CONTRATOS'!$A$3:$E$3
Name PARTIDABASE: Materiales!$A$107:$D$107
Name PARTIDABASE: 'Precio Equipos'!#REF!
Name PARTIDABASE: 'Rend. Equipos'!$A$7:$E$7
Name PARTIDABASE: 'Sub CONTRATOS'!$A$8:$E$8
Name PARTIDABASE: 'Mano de Obra'!$A$8:$D$8
Name TITULO: 'Mano de Obra'!#REF!
Name TITULO: Materiales!#REF!
Name TITULO: 'Precio Equipos'!$A$4
Name TITULO: 'Rend. Equipos'!$A$2
Name TITULO: 'Sub CONTRATOS'!#REF!

Sheet RESUMEN
F2: GG | I2: 0 | L2: Mes: | M2: DICIEMBRE
F3: BB | I3: 0 | L3: Año: | M3: 2024
L4: Revisado: | M4: MC
D5: ANALISIS DE PRECIO UNITARIO - RESUMEN
F6: PRECIO UNITARIO
F7: Unitario Materiales: | I7: Unitario Mano de Obra: | L7: Unitario Equipos: | O7: REND.
A8: CODIGO | B8: REV | C8: P | D8: DETALLE | E8: u | F8: MAT | I8: MO | L8: EQUIPOS | M8: TOTAL | O8: u/dia
B9: SI | C9: 32 | D9: =+VLOOKUP("Partida:",'P-32'!$A$7:$G$7,2,FALSE) -> Movimiento de suelos para bases c/ aporte de tosca (e: 40 cm en 2 capas de 20 cm) | E9: =+'P-32'!$C$9 -> m3 | F9: =+VLOOKUP(F$7,'P-32'!F11:G65536,2,FALSE) -> 12754.673 | I9: =+VLOOKUP(I$7,'P-32'!F11:G65536,2,FALSE) -> 6056.8068 | L9: =+VLOOKUP(L$7,'P-32'!F11:G65536,2,FALSE) -> 34605.5 | M9: =SUM(F9:L9) -> 53416.98 | O9: =+'P-32'!$F$9 -> 25
A10: ARQUIN21 | B10: SI | C10: 33 | D10: =+VLOOKUP("Partida:",'P-33'!$A$7:$G$7,2,FALSE) -> Ladrillo común 12,5 x 5,5 x 25 (e:15 cm) | E10: =+'P-33'!$C$9 -> m2 | F10: =+VLOOKUP(F$7,'P-33'!F11:G65539,2,FALSE) -> 12909.38 | I10: =+VLOOKUP(I$7,'P-33'!F11:G65539,2,FALSE) -> 20969.668 | L10: =+VLOOKUP(L$7,'P-33'!F11:G65539,2,FALSE) -> 504.28267 | M10: =SUM(F10:L10) -> 34383.331 | O10: =+'P-33'!$F$9 -> 7
A11: ARQUIN21 | B11: SI | C11: 34 | D11: =+VLOOKUP("Partida:",'P-34'!$A$7:$G$7,2,FALSE) -> Ladrillo cerámico 8 x 18 x 33 cm | E11: =+'P-34'!$C$9 -> m2 | F11: =+VLOOKUP(F$7,'P-34'!$F11:$G65539,2,FALSE) -> 6590.9962 | I11: =+VLOOKUP(I$7,'P-34'!$F11:$G65539,2,FALSE) -> 9785.8452 | L11: =+VLOOKUP(L$7,'P-34'!$F11:$G65539,2,FALSE) -> 235.33191 | M11: =SUM(F11:L11) -> 16612.173 | O11: =+'P-34'!$F$9 -> 15
A12: ARQUIN21 | B12: SI | C12: 35 | D12: =+VLOOKUP("Partida:",'P-35'!$A$7:$G$7,2,FALSE) -> Ladrillo cerámico 12 x 18 x 33 cm | E12: =+'P-35'!$C$9 -> m2 | F12: =+VLOOKUP(F$7,'P-35'!$F11:$G65539,2,FALSE) -> 8314.4981 | I12: =+VLOOKUP(I$7,'P-35'!$F11:$G65539,2,FALSE) -> 9785.8452 | L12: =+VLOOKUP(L$7,'P-35'!$F11:$G65539,2,FALSE) -> 235.33191 | M12: =SUM(F12:L12) -> 18335.675 | O12: =+'P-35'!$F$9 -> 15
A13: ARQUIN21 | B13: SI | C13: 36 | D13: =+VLOOKUP("Partida:",'P-36'!$A$7:$G$7,2,FALSE) -> Ladrillo cerámico 18 x 18 x 33 cm | E13: =+'P-36'!$C$9 -> m2 | F13: =+VLOOKUP(F$7,'P-36'!$F11:$G65539,2,FALSE) -> 11492.44 | I13: =+VLOOKUP(I$7,'P-36'!$F11:$G65539,2,FALSE) -> 9785.8452 | L13: =+VLOOKUP(L$7,'P-36'!$F11:$G65539,2,FALSE) -> 235.33191 | M13: =SUM(F13:L13) -> 21513.617 | O13: =+'P-36'!$F$9 -> 15
A14: ARQUIN21 | B14: SI | C14: 37 | D14: =+VLOOKUP("Partida:",'P-37'!$A$7:$G$7,2,FALSE) -> Pared DOBLE Comun / 5 / LHC 08 - (ladrillo a la vista) | E14: =+'P-37'!$C$9 -> m2 | F14: =+VLOOKUP(F$7,'P-37'!$F11:$G65553,2,FALSE) -> 27983.302 | I14: =+VLOOKUP(I$7,'P-37'!$F11:$G65553,2,FALSE) -> 35327.556 | L14: =+VLOOKUP(L$7,'P-37'!$F11:$G65553,2,FALSE) -> 882.49467 | M14: =SUM(F14:L14) -> 64193.353 | O14: =+'P-37'!$F$9 -> 4
A15: ARQUIN21 | B15: SI | C15: 38 | D15: =+VLOOKUP("Partida:",'P-38'!$A$7:$G$7,2,FALSE) -> Ladrillo hueco portante 12 x 19 x 33 | E15: =+'P-38'!$C$9 -> m2 | F15: =+VLOOKUP(F$7,'P-38'!$F11:$G65539,2,FALSE) -> 11547.894 | I15: =+VLOOKUP(I$7,'P-38'!$F11:$G65539,2,FALSE) -> 9785.8452 | L15: =+VLOOKUP(L$7,'P-38'!$F11:$G65539,2,FALSE) -> 235.33191 | M15: =SUM(F15:L15) -> 21569.071 | O15: =+'P-38'!$F$9 -> 15
A16: ARQUIN21 | B16: SI | C16: 39 | D16: =+VLOOKUP("Partida:",'P-39'!$A$7:$G$7,2,FALSE) -> Amure puertas tipo (0,90 x 2,00 m) | E16: =+'P-39'!$C$9 -> u | F16: =+VLOOKUP(F$7,'P-39'!$F11:$G65537,2,FALSE) -> 4066.3296 | I16: =+VLOOKUP(I$7,'P-39'!$F11:$G65537,2,FALSE) -> 55045.379 | L16: =+VLOOKUP(L$7,'P-39'!$F11:$G65537,2,FALSE) -> 405.54862 | M16: =SUM(F16:L16) -> 59517.257 | O16: =+'P-39'!$F$9 -> 2
A17: ARQUIN21 | B17: SI | C17: 40 | D17: =+VLOOKUP("Partida:",'P-40'!$A$7:$G$7,2,FALSE) -> Amure Premarcos | E17: =+'P-40'!$C$9 -> u | F17: =+VLOOKUP(F$7,'P-40'!$F11:$G65537,2,FALSE) -> 1487.907 | I17: =+VLOOKUP(I$7,'P-40'!$F11:$G65537,2,FALSE) -> 36696.919 | L17: =+VLOOKUP(L$7,'P-40'!$F11:$G65537,2,FALSE) -> 202.77431 | M17: =SUM(F17:L17) -> 38387.601 | O17: =+'P-40'!$F$9 -> 4
A18: ARQUIN21 | B18: SI | C18: 41 | D18: =+VLOOKUP("Partida:",'P-41'!$A$7:$G$7,2,FALSE) -> Amure barandas (insertos c/1,00 m) | E18: =+'P-41'!$C$9 -> ml | F18: =+VLOOKUP(F$7,'P-41'!$F11:$G65538,2,FALSE) -> 308.02446 | I18: =+VLOOKUP(I$7,'P-41'!$F11:$G65538,2,FALSE) -> 29357.536 | L18: =+VLOOKUP(L$7,'P-41'!$F11:$G65538,2,FALSE) -> 276.57623 | M18: =SUM(F18:L18) -> 29942.136 | O18: =+'P-41'!$F$9 -> 5
A19: ARQUIN21 | B19: SI | C19: 42 | D19: =+VLOOKUP("Partida:",'P-42'!$A$7:$G$7,2,FALSE) -> Azotado hidrófugo | E19: =+'P-42'!$C$9 -> m2 | F19: =+VLOOKUP(F$7,'P-42'!$F11:$G65537,2,FALSE) -> 809.61503 | I19: =+VLOOKUP(I$7,'P-42'!$F11:$G65537,2,FALSE) -> 3938.2618 | L19: =+VLOOKUP(L$7,'P-42'!$F11:$G65537,2,FALSE) -> 126.07067 | M19: =SUM(F19:L19) -> 4873.9475 | O19: =+'P-42'!$F$9 -> 28
A20: ARQUIN21 | B20: SI | C20: 43 | D20: =+VLOOKUP("Partida:",'P-43'!$A$7:$G$7,2,FALSE) -> Interior jaharro a la cal + Enlucido a la cal | E20: =+'P-43'!$C$9 -> m2 | F20: =+VLOOKUP(F$7,'P-43'!$F11:$G65540,2,FALSE) -> 2735.3164 | I20: =+VLOOKUP(I$7,'P-43'!$F11:$G65540,2,FALSE) -> 20914.412 | L20: =+VLOOKUP(L$7,'P-43'!$F11:$G65540,2,FALSE) -> 588.32978 | M20: =SUM(F20:L20) -> 24238.059 | O20: =+'P-43'!$F$9 -> 6
A21: ARQUIN21 | B21: SI | C21: 44 | D21: =+VLOOKUP("Partida:",'P-44'!$A$7:$G$7,2,FALSE) -> Revoque Grueso impermeable Exterior hasta 3.00 m - Incl. Azotado hidrófugo | E21: =+'P-44'!$C$9 -> m2 | F21: =+VLOOKUP(F$7,'P-44'!$F11:$G65540,2,FALSE) -> 4009.2266 | I21: =+VLOOKUP(I$7,'P-44'!$F11:$G65540,2,FALSE) -> 10647.256 | L21: =+VLOOKUP(L$7,'P-44'!$F11:$G65540,2,FALSE) -> 306.95467 | M21: =SUM(F21:L21) -> 14963.437 | O21: =+'P-44'!$F$9 -> 11.5
A22: ARQUIN21 | B22: SI | C22: 45 | D22: =+VLOOKUP("Partida:",'P-45'!$A$7:$G$7,2,FALSE) -> Revoque Grueso impermeable Exterior a mas de 3.00 m - Incl. Azotado hidrófugo | E22: =+'P-45'!$C$9 -> m2 | F22: =+VLOOKUP(F$7,'P-45'!$F11:$G65540,2,FALSE) -> 4009.2266 | I22: =+VLOOKUP(I$7,'P-45'!$F11:$G65540,2,FALSE) -> 15305.431 | L22: =+VLOOKUP(L$7,'P-45'!$F11:$G65540,2,FALSE) -> 769.31526 | M22: =SUM(F22:L22) -> 20083.973 | O22: =+'P-45'!$F$9 -> 8
A23: ARQUIN21 | B23: SI | C23: 46 | D23: =+VLOOKUP("Partida:",'P-46'!$A$7:$G$7,2,FALSE) -> Contrapiso HHRP | E23: =+'P-46'!$C$9 -> m3 | F23: =+VLOOKUP(F$7,'P-46'!$F11:$G65534,2,FALSE) -> 67465.639 | I23: =+VLOOKUP(I$7,'P-46'!$F11:$G65534,2,FALSE) -> 89504.217 | L23: =+VLOOKUP(L$7,'P-46'!$F11:$G65540,2,FALSE) -> 2317.4207 | M23: =SUM(F23:L23) -> 159287.28 | O23: =+'P-46'!$F$9 -> 1.4
A24: ARQUIN21 | B24: SI | C24: 47 | D24: =+VLOOKUP("Partida:",'P-47'!$A$7:$G$7,2,FALSE) -> Carpeta MC 1:3 (e: 2cm) | E24: =+'P-47'!$C$9 -> m2 | F24: =+VLOOKUP(F$7,'P-47'!$F11:$G65533,2,FALSE) -> 3388.608 | I24: =+VLOOKUP(I$7,'P-47'!$F11:$G65533,2,FALSE) -> 7554.2906 | L24: =+VLOOKUP(L$7,'P-47'!$F11:$G65533,2,FALSE) -> 216.2926 | M24: =SUM(F24:L24) -> 11159.191 | O24: =+'P-47'!$F$9 -> 15
A25: ARQUIN21 | B25: SI | C25: 48 | D25: =+VLOOKUP("Partida:",'P-48'!$A$7:$G$7,2,FALSE) -> Carpeta monolítico h = 7 cm | E25: =+'P-48'!$C$9 -> m2 | F25: =+VLOOKUP(F$7,'P-48'!$F11:$G65536,2,FALSE) -> 6968.0306 | I25: =+VLOOKUP(I$7,'P-48'!$F11:$G65536,2,FALSE) -> 10126.741 | L25: =+VLOOKUP(L$7,'P-48'!$F11:$G65536,2,FALSE) -> 120.04692 | M25: =SUM(F25:L25) -> 17214.819 | O25: =+'P-48'!$F$9 -> 35
A26: ARQUIN21 | B26: SI | C26: 49 | D26: =+VLOOKUP("Partida:",'P-49'!$A$7:$G$7,2,FALSE) -> Carpeta hidrófuga (e: 2 cm) | E26: =+'P-49'!$C$9 -> m2 | F26: =+VLOOKUP(F$7,'P-49'!$F11:$G65537,2,FALSE) -> 4048.0752 | I26: =+VLOOKUP(I$7,'P-49'!$F11:$G65537,2,FALSE) -> 7554.2906 | L26: =+VLOOKUP(L$7,'P-49'!$F11:$G65537,2,FALSE) -> 216.2926 | M26: =SUM(F26:L26) -> 11818.658 | O26: =+'P-49'!$F$9 -> 15
A27: ARQUIN21 | B27: SI | C27: 50 | D27: =+VLOOKUP("Partida:",'P-50'!$A$7:$G$7,2,FALSE) -> Cemento alisado o cilindrado (e: 3 cm) | E27: =+'P-50'!$C$9 -> m2 | F27: =+VLOOKUP(F$7,'P-50'!$F11:$G65538,2,FALSE) -> 4066.3296 | I27: =+VLOOKUP(I$7,'P-50'!$F11:$G65538,2,FALSE) -> 10118.034 | L27: =+VLOOKUP(L$7,'P-50'!$F11:$G65538,2,FALSE) -> 282.12078 | M27: =SUM(F27:L27) -> 14466.484 | O27: =+'P-50'!$F$9 -> 11.5
A28: ARQUIN21 | B28: SI | C28: 51 | D28: =+VLOOKUP("Partida:",'P-51'!$A$7:$G$7,2,FALSE) -> Látex interior para paredes (incl. enduido) | E28: =+'P-51'!$C$9 -> m2 | F28: =+VLOOKUP(F$7,'P-51'!$F11:$G65539,2,FALSE) -> 2923.7665 | I28: =+VLOOKUP(I$7,'P-51'!$F12:$G65539,2,FALSE) -> 7626.9744 | L28: =+VLOOKUP(L$7,'P-51'!$F11:$G65539,2,FALSE) -> 174.89809 | M28: =SUM(F28:L28) -> 10725.639 | O28: =+'P-51'!$F$9 -> 22
A29: ARQUIN21 | B29: SI | C29: 52 | D29: =+VLOOKUP("Partida:",'P-52'!$A$7:$G$7,2,FALSE) -> látex para cielorrasos (incl. enduido) | E29: =+'P-52'!$C$9 -> m2 | F29: =+VLOOKUP(F$7,'P-52'!$F11:$G65541,2,FALSE) -> 2923.7665 | I29: =+VLOOKUP(I$7,'P-52'!$F13:$G65540,2,FALSE) -> 8652.5811 | L29: =+VLOOKUP(L$7,'P-52'!$F11:$G65541,2,FALSE) -> 241.06769 | M29: =SUM(F29:L29) -> 11817.415 | O29: =+'P-52'!$F$9 -> 17.5
A30: ARQUIN21 | B30: SI | C30: 53 | D30: =+VLOOKUP("Partida:",'P-53'!$A$7:$G$7,2,FALSE) -> látex exterior para paredes hasta 3.00 m de altura | E30: =+'P-53'!$C$9 -> m2 | F30: =+VLOOKUP(F$7,'P-53'!$F11:$G65536,2,FALSE) -> 1824.9263 | I30: =+VLOOKUP(I$7,'P-53'!$F14:$G65541,2,FALSE) -> 5543.6837 | L30: =+VLOOKUP(L$7,'P-53'!$F11:$G65536,2,FALSE) -> 124.12123 | M30: =SUM(F30:L30) -> 7492.7312 | O30: =+'P-53'!$F$9 -> 15.5
A31: ARQUIN21 | B31: SI | C31: 53 bis | D31: =+VLOOKUP("Partida:",'P-53 bis'!$A$7:$G$7,2,FALSE) -> látex exterior para paredes a más 3.00 m de altura | E31: =+'P-53'!$C$9 -> m2 | F31: =+VLOOKUP(F$7,'P-53 bis'!$F12:$G65537,2,FALSE) -> 1824.9263 | I31: =+VLOOKUP(I$7,'P-53 bis'!$F15:$G65542,2,FALSE) -> 14504.13 | L31: =+VLOOKUP(L$7,'P-53 bis'!$F12:$G65537,2,FALSE) -> 234.44231 | M31: =SUM(F31:L31) -> 16563.498 | O31: =+'P-53 bis'!$F$9 -> 15.5
A32: ARQUIN21 | B32: SI | C32: 54 | D32: =+VLOOKUP("Partida:",'P-54'!$A$7:$G$7,2,FALSE) -> Esmalte sintético sobre carpintería metálica , herrería (cuando es vacio x lleno contemplar MAT al 60%) | E32: =+'P-54'!$C$9 -> m2 | F32: =+VLOOKUP(F$7,'P-54'!$F11:$G65536,2,FALSE) -> 2585.0849 | I32: =+VLOOKUP(I$7,'P-54'!$F15:$G65542,2,FALSE) -> 10740.887 | L32: =+VLOOKUP(L$7,'P-54'!$F11:$G65536,2,FALSE) -> 240.48488 | M32: =SUM(F32:L32) -> 13566.457 | O32: =+'P-54'!$F$9 -> 8
A33: ARQUIN21 | B33: SI | C33: 55 | D33: =+VLOOKUP("Partida:",'P-55'!$A$7:$G$7,2,FALSE) -> Revestimiento plastico texturado tipo Quimtex fino | E33: =+'P-55'!$C$9 -> m2 | F33: =+VLOOKUP(F$7,'P-55'!$F11:$G65541,2,FALSE) -> 6000.929 | I33: =+VLOOKUP(I$7,'P-55'!$F16:$G65543,2,FALSE) -> 11240.7 | L33: =+VLOOKUP(L$7,'P-55'!$F11:$G65541,2,FALSE) -> 181.69279 | M33: =SUM(F33:L33) -> 17423.322 | O33: =+'P-55'!$F$9 -> 20
A34: ARQUIN21 | B34: SI | C34: 56 | D34: =+VLOOKUP("Partida:",'P-56'!$A$7:$G$7,2,FALSE) -> Colocación porcelanato en pisos (no incluye baños) | E34: =+'P-56'!$C$9 -> m2 | F34: =+VLOOKUP(F$7,'P-56'!$F10:$G65540,2,FALSE) -> 7156.2986 | I34: =+VLOOKUP(I$7,'P-56'!$F18:$G65545,2,FALSE) -> 11647.705 | L34: =+VLOOKUP(L$7,'P-56'!$F10:$G65540,2,FALSE) -> 225.81275 | M34: =SUM(F34:L34) -> 19029.817 | O34: =+'P-56'!$F$9 -> 13
A35: ARQUIN21 | B35: SI | C35: 57 | D35: =+VLOOKUP("Partida:",'P-57'!$A$7:$G$7,2,FALSE) -> Revestimiento porcelanato en paredes y piso baños | E35: =+'P-57'!$C$9 -> m2 | F35: =+VLOOKUP(F$7,'P-57'!$F10:$G65541,2,FALSE) -> 7156.2986 | I35: =+VLOOKUP(I$7,'P-57'!$F19:$G65546,2,FALSE) -> 15142.017 | L35: =+VLOOKUP(L$7,'P-57'!$F10:$G65541,2,FALSE) -> 293.55657 | M35: =SUM(F35:L35) -> 22591.872 | O35: =+'P-57'!$F$9 -> 10
A36: ARQUIN21 | B36: SI | C36: 58 | D36: =+VLOOKUP("Partida:",'P-58'!$A$7:$G$7,2,FALSE) -> Colocacion de zocalo porcelanato | E36: =+'P-58'!$C$9 -> ml | F36: =+VLOOKUP(F$7,'P-58'!$F11:$G65541,2,FALSE) -> 1066.3432 | I36: =+VLOOKUP(I$7,'P-58'!$F11:$G65541,2,FALSE) -> 5047.339 | L36: =+VLOOKUP(L$7,'P-58'!$F11:$G65541,2,FALSE) -> 97.85219 | M36: =SUM(F36:L36) -> 6211.5344 | O36: =+'P-58'!$F$9 -> 30
A37: ARQUIN22 | B37: SI | C37: 59 | D37: =+VLOOKUP("Partida:",'P-59'!$A$7:$G$7,2,FALSE) -> Látex interior satinado para paredes | E37: =+'P-59'!$C$9 -> m2 | F37: =+VLOOKUP(F$7,'P-59'!$F11:$G65536,2,FALSE) -> 5093.055 | I37: =+VLOOKUP(I$7,'P-59'!$F12:$G65542,2,FALSE) -> 13765.47 | L37: =+VLOOKUP(L$7,'P-59'!$F11:$G65536,2,FALSE) -> 331.59136 | M37: =SUM(F37:L37) -> 19190.116 | O37: =+'P-59'!$F$9 -> 11
A38: ARQUIN23 | B38: SI | C38: 60 | D38: =+VLOOKUP("Partida:",'P-60'!$A$7:$G$7,2,FALSE) -> Cielorraso Durlock - Junta Tomada STD | E38: =+'P-60'!$C$9 -> m2 | F38: =+VLOOKUP(F$7,'P-60'!$F12:$G65537,2,FALSE) -> 10671.937 | I38: =+VLOOKUP(I$7,'P-60'!$F13:$G65543,2,FALSE) -> 15938.965 | L38: =+VLOOKUP(L$7,'P-60'!$F12:$G65537,2,FALSE) -> 263.73013 | M38: =SUM(F38:L38) -> 26874.632 | O38: =+'P-60'!$F$9 -> 9.5
A39: ARQUIN24 | B39: SI | C39: 61 | D39: =+VLOOKUP("Partida:",'P-61'!$A$7:$G$7,2,FALSE) -> Cielorraso Durlock - Junta Tomada RH | E39: =+'P-61'!$C$9 -> m2 | F39: =+VLOOKUP(F$7,'P-61'!$F13:$G65538,2,FALSE) -> 14660.055 | I39: =+VLOOKUP(I$7,'P-61'!$F14:$G65544,2,FALSE) -> 15938.965 | L39: =+VLOOKUP(L$7,'P-61'!$F13:$G65538,2,FALSE) -> 263.73013 | M39: =SUM(F39:L39) -> 30862.75 | O39: =+'P-61'!$F$9 -> 9.5
A40: ARQUIN25 | B40: SI | C40: 62 | D40: =+VLOOKUP("Partida:",'P-62'!$A$7:$G$7,2,FALSE) -> Cielorraso Durlock - Junta Tomada RF | E40: =+'P-62'!$C$9 -> m2 | F40: =+VLOOKUP(F$7,'P-62'!$F14:$G65539,2,FALSE) -> 13890.957 | I40: =+VLOOKUP(I$7,'P-62'!$F15:$G65545,2,FALSE) -> 15938.965 | L40: =+VLOOKUP(L$7,'P-62'!$F14:$G65539,2,FALSE) -> 263.73013 | M40: =SUM(F40:L40) -> 30093.652 | O40: =+'P-62'!$F$9 -> 9.5
A41: ARQUIN26 | B41: SI | C41: 63 | D41: =+VLOOKUP("Partida:",'P-63'!$A$7:$G$7,2,FALSE) -> Cielorraso Desmontable 60x60 - sin provision | E41: =+'P-63'!$C$9 -> m2 | F41: =+VLOOKUP(F$7,'P-63'!$F15:$G65540,2,FALSE) -> 5516.6996 | I41: =+VLOOKUP(I$7,'P-63'!$F16:$G65546,2,FALSE) -> 15142.017 | L41: =+VLOOKUP(L$7,'P-63'!$F15:$G65540,2,FALSE) -> 250.54362 | M41: =SUM(F41:L41) -> 20909.26 | O41: =+'P-63'!$F$9 -> 10
...

Sheet Rend. Equipos
A2: EQUIPOS
B3: Fecha: | C3: 45631
H5: 360
A6: Código | B6: DESCRIPCION | C6: P unit | D6: Cant | E6: Costo (referencial) | G6: Años | H6: Dias | I6: $ x dia | J6: % Deprec.
A7: *ANDAM05 | B7: ANDAMIO TUBULAR DE UNO A TRES CUERPOS | E7: =+SUM(E8:E10) -> 1028123.1 | G7: 5 | H7: =+G7*$H$5 -> 1800 | I7: =+E7/H7 -> 571.17949 | J7: =+I7/E7 -> 0.00055555556
B8: Andamio reforzado tubular 2,5 mts | C8: =VLOOKUP(B8,'Precio Equipos'!B:C,2,0) -> 237068.27 | D8: 3 | E8: =+C8*D8 -> 711204.81
B9: Tablon Para Andamio 2,5 M Metalico Antideslizante Tca Duroll | C9: =VLOOKUP(B9,'Precio Equipos'!B:C,2,0) -> 94209.625 | D9: 2 | E9: =+C9*D9 -> 188419.25
B10: Rueda para andamio giratoria c/freno | C10: =VLOOKUP(B10,'Precio Equipos'!B:C,2,0) -> 32124.755 | D10: 4 | E10: =+C10*D10 -> 128499.02
A11: EQALBA | B11: EQUIPO DE ALBAÑILERIA, carpetas, ladrillo | E11: =+SUM(E12:E31) -> 2470106.6 | G11: 3 | H11: =+G11*$H$5 -> 1080 | I11: =+E11/H11 -> 2287.1357 | J11: =+I11/E11 -> 0.00092592593
B12: REGLA ALUMINIO 6,00MTS | C12: =VLOOKUP(B12,'Precio Equipos'!B:C,2,0) -> 238945.46 | D12: 2 | E12: =+C12*D12 -> 477890.91
B13: Amoladora 4 1/2 850 w - BOSCH | C13: =VLOOKUP(B13,'Precio Equipos'!B:C,2,0) -> 137903.31 | D13: 1 | E13: =+C13*D13 -> 137903.31
B14: Rotopercutor RPK-32KA - BAROVO (5 kg) | C14: =VLOOKUP(B14,'Precio Equipos'!B:C,2,0) -> 180879.68 | D14: 1 | E14: =+C14*D14 -> 180879.68
B15: Sierra circular 7 1/4 - BOSCH | C15: =VLOOKUP(B15,'Precio Equipos'!B:C,2,0) -> 396998.4 | D15: 1 | E15: =+C15*D15 -> 396998.4
B16: Nivel Laser Dewalt Auto.alc.30mt 4p | C16: =VLOOKUP(B16,'Precio Equipos'!B:C,2,0) -> 832041.76 | D16: 0.5 | E16: =+C16*D16 -> 416020.88
B17: PALA FORJADA ANCHA - Gherardi | C17: =VLOOKUP(B17,'Precio Equipos'!B:C,2,0) -> 53370.69 | D17: 2 | E17: =+C17*D17 -> 106741.38
B18: PALA FORJADA DE PUNTA - Gherardi | C18: =VLOOKUP(B18,'Precio Equipos'!B:C,2,0) -> 53370.69 | D18: 2 | E18: =+C18*D18 -> 106741.38
B19: Carretilla Duroll 100 Litros Chapa 16 Profesional Rueda Maciza | C19: =VLOOKUP(B19,'Precio Equipos'!B:C,2,0) -> 107853.34 | D19: 1 | E19: =+C19*D19 -> 107853.34
B20: RUEDA MACIZA CARRETILLA C100DU | C20: =VLOOKUP(B20,'Precio Equipos'!B:C,2,0) -> 15556.499 | D20: 1 | E20: =+C20*D20 -> 15556.499
B21: FRATACHO DE ALGARROBO DE 30 CM | C21: =VLOOKUP(B21,'Precio Equipos'!B:C,2,0) -> 4646.285 | D21: 6 | E21: =+C21*D21 -> 27877.71
B22: Llana de yesero 12 x 30 cm | C22: =VLOOKUP(B22,'Precio Equipos'!B:C,2,0) -> 13904.259 | D22: 2 | E22: =+C22*D22 -> 27808.517
B23: CUCHARA ALBAÑIL FORJADA 6″ | C23: =VLOOKUP(B23,'Precio Equipos'!B:C,2,0) -> 18146.757 | D23: 2 | E23: =+C23*D23 -> 36293.514
... B31: Rodillo de bronce para cementista grande 17 cm | C31: =VLOOKUP(B31,'Precio Equipos'!B:C,2,0) -> 72426.909 | D31: 1 | E31: =+C31*D31 -> 72426.909
A32: EQCERAMI | B32: EQUIPO PARA COLOCACION DE CERAMICA | E32: =+SUM(E33:E46) -> 1424056.6 | G32: 1.5 | H32: =+G32*$H$5 -> 540 | I32: =+E32/H32 -> 2637.1418 | J32: =+I32/E32 -> 0.0018518519
B33: Amoladora 4 1/2 850 w - BOSCH | C33: =VLOOKUP(B33,'Precio Equipos'!B:C,2,0) -> 137903.31 | D33: 1 | E33: =+C33*D33 -> 137903.31
B34: MEZCLADOR ELECTRICO 2V. 50HZ 1200W | C34: =VLOOKUP(B34,'Precio Equipos'!B:C,2,0) -> 143732.28 | D34: 1 | E34: =+C34*D34 -> 143732.28
B35: Nivel Laser Dewalt Auto.alc.30mt 4p | C35: =VLOOKUP(B35,'Precio Equipos'!B:C,2,0) -> 832041.76 | D35: 1 | E35: =+C35*D35 -> 832041.76
B36: Rodillera de seguridad goma espuma | C36: =VLOOKUP(B36,'Precio Equipos'!B:C,2,0) -> 6903.8056 | D36: 3 | E36: =+C36*D36 -> 20711.417
B37: Martillo Maza De Goma | C37: =VLOOKUP(B37,'Precio Equipos'!B:C,2,0) -> 8898.892 | D37: 1 | E37: =+C37*D37 -> 8898.892
B38: LLANA DENTADA DE 12 X 12 CMS | C38: =VLOOKUP(B38,'Precio Equipos'!B:C,2,0) -> 13983.677 | D38: 2 | E38: =+C38*D38 -> 27967.355
B39: CUCHARA ALBAÑIL FORJADA 6″ | C39: =VLOOKUP(B39,'Precio Equipos'!B:C,2,0) -> 18146.757 | D39: 2 | E39: =+C39*D39 -> 36293.514
B40: BALDE ALBAÑIL PLÁSTICO – MANIJA PLÁSTICA – BAE | C40: =VLOOKUP(B40,'Precio Equipos'!B:C,2,0) -> 2097.2847 | D40: 6 | E40: =+C40*D40 -> 12583.708
B41: Lapiz carpintero 18 cm | C41: =VLOOKUP(B41,'Precio Equipos'!B:C,2,0) -> 1387.6932 | D41: 12 | E41: =+C41*D41 -> 16652.318
B42: CHOCLA PARA ALBAÑIL C/RECIPIENTE CON TIZA - DUROLL | C42: =VLOOKUP(B42,'Precio Equipos'!B:C,2,0) -> 4206.1727 | D42: 1 | E42: =+C42*D42 -> 4206.1727
B43: CINTA METRICA 510 RETROFLEX 10MTS - Evel | C43: =VLOOKUP(B43,'Precio Equipos'!B:C,2,0) -> 26993.867 | D43: 1 | E43: =+C43*D43 -> 26993.867
B44: Metro madera | C44: =VLOOKUP(B44,'Precio Equipos'!B:C,2,0) -> 4852.6243 | D44: 1 | E44: =+C44*D44 -> 4852.6243
... B46: RODEL RUEDITA 8MM P/C 1958 | C46: =VLOOKUP(B46,'Precio Equipos'!B:C,2,0) -> 39721.703 | D46: 3 | E46: =+C46*D46 -> 119165.11
A47: *EQUIP09 | B47: EQUIPO PARA INSTALACION ELECTRICA | E47: =+SUM(E48:E61) -> 2734071.2 | G47: 1.5 | H47: =+G47*$H$5 -> 540 | I47: =+E47/H47 -> 5063.0948 | J47: =+I47/E47 -> 0.0018518519
B48: Amoladora 4 1/2 850 w - BOSCH | C48: =VLOOKUP(B48,'Precio Equipos'!B:C,2,0) -> 137903.31 | D48: 1 | E48: =+C48*D48 -> 137903.31
B49: Rotopercutor RPK-32KA - BAROVO (5 kg) | C49: =VLOOKUP(B49,'Precio Equipos'!B:C,2,0) -> 180879.68 | D49: 1 | E49: =+C49*D49 -> 180879.68
B50: Taladro Percutor/Atornillador de 1/2″ (13mm) Inalámbrico 20V + 2 Baterías + Cargador + Maletín | C50: =VLOOKUP(B50,'Precio Equipos'!B:C,2,0) -> 555611 | D50: 1 | E50: =+C50*D50 -> 555611
...

Sheet Precio Equipos
G1: DÓLAR USD | H1: DÓLAR MEP
B2: PRECIOS DE EQUIPOS | F2: 45631 | G2: 1033 | H2: 1075
H3: 13277.8 | I3: 45292
B4: DESCRIPCION | C4: P. Unit | D4: Fecha | E4: Proveedor | H4: 17149.9 | I4: 45566
A5: 1 | B5: IZAJE, TRASLADO Y ALTURA | H5: =+H4/H3 -> 1.2916221
A6: 1.01 | B6: Andamio reforzado tubular 2,5 mts | C6: =+H6*$H$5 -> 237068.27 | E6: Abrafer WEB | H6: =222087.1/1.21 -> 183543.06 | I6: 45299
A7: 1.02 | B7: Tablon Para Andamio 2,5 M Metalico Antideslizante Tca Duroll | C7: =+H7*$H$5 -> 94209.625 | E7: Abrafer WEB | H7: =88256.19/1.21 -> 72939 | I7: 45299
A8: 1.03 | B8: Rueda para andamio giratoria c/freno | C8: =+H8*$H$5 -> 32124.755 | E8: Abrafer WEB | H8: =30094.68/1.21 -> 24871.636 | I8: 45299
A9: 1.04 | B9: Carretilla Duroll 100 Litros Chapa 16 Profesional Rueda Maciza | C9: =+H9*$H$5 -> 107853.34 | E9: Abrafer WEB | H9: =101037.71/1.21 -> 83502.24 | I9: 45303
A10: 1.05 | B10: RUEDA MACIZA CARRETILLA C100DU | C10: =+H10*$H$5 -> 15556.499 | E10: Abrafer WEB | H10: =14573.43/1.21 -> 12044.157 | I10: 45303
A11: 1.06 | B11: ESCALERA GLOSS ALUMINIO ARTICULADA 4 X 4 ESCALONES HASTA 150KG | C11: =+H11*$H$5 -> 201885.25 | E11: Abrafer WEB | H11: =189127.42/1.21 -> 156303.65 | I11: 45303
A12: 1.07 | B12: ESCALERA MADERA PINTOR 8 ESCALONES | C12: =+H12*$H$5 -> 72091.109 | E12: Abrafer WEB | H12: =67535.42/1.21 -> 55814.397 | I12: 45299
A13: 1.08 | B13: Kit Complementario Silleta Descensor Conector Soga X 50 Mts | C13: =+H13*$H$5 -> 683705.75 | E13: Mercado Libre | H13: =640500/1.21 -> 529338.84 | I13: 45327
A14: 1.09 | B14: Balancin | C14: =+F14*$G$2 -> 10476479 | D14: 45631 | E14: Leiten | F14: 10141.8
A15: 2 | B15: HERRAMIENTAS ELECTRICAS
A16: 2.01 | B16: Amoladora 4 1/2 850 w - BOSCH | C16: =+H16*$H$5 -> 137903.31 | E16: Abrafer WEB | H16: =129188.72/1.21 -> 106767.54 | I16: 45303
A17: 2.02 | B17: AMOLADORA BOSCH 7″ GWS 22-180 2200W | C17: =+H17*$H$5 -> 452946.11 | E17: Abrafer WEB | H17: =424322.87/1.21 -> 350680.06 | I17: 45327
A18: 2.03 | B18: Rotopercutor RPK-32KA - BAROVO (5 kg) | C18: =+H18*$H$5 -> 180879.68 | E18: Abrafer WEB | H18: =169449.26/1.21 -> 140040.71 | I18: 45303
A19: 2.04 | B19: Termofusora 1800 w - 220 v s/ boquilla | C19: =+H19*$H$5 -> 294158.54 | E19: Abrafer WEB | H19: =275569.64/1.21 -> 227743.5 | I19: 45307
A20: 2.05 | B20: Sierra circular 7 1/4 - BOSCH | C20: =+H20*$H$5 -> 396998.4 | E20: Abrafer WEB | H20: =371910.69/1.21 -> 307364.21 | I20: 45303
A21: 2.06 | B21: Nivel Laser Dewalt Auto.alc.30mt 4p | C21: =+H21*$H$5 -> 832041.76 | E21: Abrafer WEB | H21: =779462.14/1.21 -> 644183.59 | I21: 45327
A22: 2.07 | B22: Taladro Percutor/Atornillador de 1/2″ (13mm) Inalámbrico 20V + 2 Baterías + Cargador + Maletín | C22: =+H22*$H$5 -> 555611 | E22: Abrafer WEB | H22: =520500/1.21 -> 430165.29 | I22: 45327
A23: 2.08 | B23: Vibrador de hormigón | C23: =+H23*$H$5 -> 1090691 | E23: Abrafer WEB | H23: =1021766.47/1.21 -> 844435.1 | I23: 45303
A24: 2.09 | B24: MEZCLADOR ELECTRICO 2V. 50HZ 1200W | C24: =+H24*$H$5 -> 143732.28 | E24: Abrafer WEB | H24: 111280.45 | I24: 45303
A25: 2.1 | B25: Equipo De Pintar Hvlp Pistola Máquina Adiabatic Ec2000 | C25: =+H25*$H$5 -> 401156.67 | E25: Abrafer WEB | H25: =375806.18/1.21 -> 310583.62 | I25: 45327
A26: 2.11 | B26: PISTOLA DE CALOR BOSCH GHG180 | C26: =+H26*$H$5 -> 222728.18 | E26: Abrafer WEB | H26: =208653.21/1.21 -> 172440.67 | I26: 45327
A27: 2.12 | B27: Lijadora Orbital de Palma Bosch GSS 140-1A | C27: =+H27*$H$5 -> 220003.08 | E27: Abrafer WEB | H27: =206100.32/1.21 -> 170330.84 | I27: 45327
A28: 2.13 | B28: Soldadora inverter ESAB LHN 240i Plus amarilla y negra 50Hz/60Hz 220V | C28: =+H28*$H$5 -> 1002877.3 | E28: Mercado Libre | H28: =939502/1.21 -> 776447.93 | I28: 45327
A29: 2.14 | B29: MASCARA FOTOSENSIBLE | C29: =+H29*$H$5 -> 53027.866 | E29: Abrafer WEB | H29: =49676.85/1.21 -> 41055.248 | I29: 45327
A30: 2.15 | B30: Sierra de metal de banco gco 220 | C30: =+H30*$H$5 -> 549290.39 | E30: Abrafer WEB | H30: =514578.81/1.21 -> 425271.74 | I30: 45327
A31: 2.16 | B31: Martillo demoledor MPK-125K | C31: =+H31*$H$5 -> 886390.57 | E31: Abrafer WEB | H31: =830376.46/1.21 -> 686261.54 | I31: 45327
A32: 2.17 | B32: Hormigonera De 150 Litros 1hp Con Rueda Maciza | C32: =+H32*$H$5 -> 499025.69 | E32: Abrafer WEB | H32: =467490.52/1.21 -> 386355.8 | I32: 45303
A33: 2.18 | B33: REPUESTO MOTOR HORMIGONERA 1HP CLASICO | C33: =+H33*$H$5 -> 151447.94 | E33: Abrafer WEB | H33: =141877.42/1.21 -> 117254.07 | I33: 45303
A34: 2.19 | B34: Correa | C34: =+H34*$H$5 -> 12916.221 | E34: Abrafer WEB | H34: 10000 | I34: 45303
A35: 3 | B35: HERRAMIENTAS
A36: 3.01 | B36: Set de herramientas profesional duroll - S88PD | C36: =+H36*$H$5 -> 248336.44 | E36: Abrafer WEB | H36: =232643.19/1.21 -> 192267.1 | I36: 45303
A37: 3.02 | B37: CORTADORA CERAMICA PROFESIONAL 1200MM (PORCELANATO HASTA 16MM) | C37: =+H37*$H$5 -> 537162.92 | E37: Abrafer WEB | H37: =503217.72/1.21 -> 415882.41 | I37: 45303
A38: 3.03 | B38: REGLA ALUMINIO 6,00MTS | C38: =+H38*$H$5 -> 238945.46 | E38: Abrafer WEB | H38: =223845.66/1.21 -> 184996.41 | I38: 45303
A39: 3.04 | B39: PALA FORJADA ANCHA - Gherardi | C39: =+H39*$H$5 -> 53370.69 | E39: Abrafer WEB | H39: =49998.01/1.21 -> 41320.669 | I39: 45303
A40: 3.05 | B40: PALA FORJADA DE PUNTA - Gherardi | C40: =+H40*$H$5 -> 53370.69 | E40: Abrafer WEB | H40: =49998.01/1.21 -> 41320.669 | I40: 45303
...

Sheet Mano de Obra
A3: MANO DE OBRA
C4: Fecha: | D4: 45627
A7: Código | B7: DESCRIPCION | C7: Salario (Día) | D7: Prestaciones Sociales | G7: COSTO Jornal
A8: *AYUDAN1 | B8: AYUDANTE | C8: =+$G$12 -> 60860.581 | D8: 0 | F8: CAPATAZ | G8: 147709.44
A9: AYUDANTE | B9: AYUDANTE ALBAÑIL | C9: =+$G$12 -> 60860.581 | D9: 0 | F9: ESPECIALIZADO | G9: 85927.097
A10: AYAR | B10: AYUDANTE ARMADOR | C10: =+$G$12 -> 60860.581 | D10: 0 | F10: OFICIAL | G10: 76955.08
A11: AYUCARP | B11: AYUDANTE CARPINTERO | C11: =+$G$12 -> 60860.581 | D11: 0 | F11: MEDIO OFICIAL | G11: 65493.072
A12: AYELECT | B12: AYUDANTE ELECTRICISTA | C12: =+$G$12 -> 60860.581 | D12: 0 | F12: AYUDANTE | G12: 60860.581
A13: AYPLOMER | B13: AYUDANTE PLOMERO | C13: =+$G$12 -> 60860.581 | D13: 0
A14: MOFAL | B14: MEDIO OFICIAL ALBAÑIL | C14: =+$G$11 -> 65493.072 | D14: 0 | F14: SOBRESTANTE | G14: 3009340.6
A15: MEDARM | B15: MEDIO OFICIAL ARMADOR | C15: =+$G$11 -> 65493.072 | D15: 0 | F15: JEFE DE OBRA | G15: 4372210.6
A16: MEDOFCAR | B16: MEDIO OFICIAL CARPINTERO | C16: =+$G$11 -> 65493.072 | D16: 0 | F16: COORD OBRAS | G16: 5273644.1
A17: MEDPINTO | B17: MEDIO OFICIAL PINTOR | C17: =+$G$11 -> 65493.072 | D17: 0 | F17: CAPATAZ | G17: 3545026.5
A18: OFCOLOCA | B18: OFICIAL COLOCADOR | C18: =+$G$9 -> 85927.097 | D18: 0
A19: OFAL | B19: OFICIAL ESPECIALIZADO ALBAÑIL | C19: =+$G$9 -> 85927.097 | D19: 0
A20: OFAR | B20: OFICIAL ESPECIALIZADO ARMADOR | C20: =+$G$9 -> 85927.097 | D20: 0
A21: OFICARPI | B21: OFICIAL ESPECIALIZADO CARPINTERO | C21: =+$G$9 -> 85927.097 | D21: 0
A22: OFELECT | B22: OFICIAL ESPECIALIZADO ELECTRICISTA | C22: =+$G$9 -> 85927.097 | D22: 0
A23: OFINST | B23: OFICIAL ESPECIALIZADO INSTALADOR | C23: =+$G$9 -> 85927.097 | D23: 0
A24: OFPINTOR | B24: OFICIAL ESPECIALIZADO PINTOR | C24: =+$G$9 -> 85927.097 | D24: 0
A25: OFPLOMER | B25: OFICIAL ESPECIALIZADO PLOMERO | C25: =+$G$9 -> 85927.097 | D25: 0
A26: *TOPOGRA | B26: TOPOGRAFO | C26: =+G9*2 -> 171854.19 | D26: 0
B28: 0 | C28: 0 | D28: 0

Sheet Sub CONTRATOS
J2: CAC OCT 24 | N2: CAC OCT 24 | O2: Retroactivo oct.
A3: SUBCONTRATOS | H3: CAC sep 22 | I3: 1541.9 | J3: =+$O$3 -> 10902.632 | K3: =+J3/I3+$K$2 -> 7.0709073 | M3: 1.04 | N3: 10483.3 | O3: =+M3*N3 -> 10902.632
H4: CAC jul 22 | I4: 1322.6 | J4: =+$O$3 -> 10902.632 | K4: =+J4/I4+$K$2 -> 8.2433328
A7: RUBRO | B7: TAREA | C7: CONTRATISTA | D7: U | E7: PU | F7: FECHA | H7: CAC nov 22 | I7: 1815.7 | J7: =+$O$3 -> 10902.632 | K7: =+J7/I7+$K$2 -> 6.0046439
A8: Colocacion | B8: Ceramico en pisos y pared | C8: Zotelo | D8: m2 | E8: =+H8*$K$3 -> 14141.815 | F8: 45631 | H8: 2000 | I8: 44835
A9: Colocacion | B9: Porcelanato en piso | C9: Zotelo | D9: m2 | E9: =+H9*$K$3 -> 12727.633 | F9: 45631 | H9: 1800 | I9: 44835
A10: Pintura | B10: Latex Mate | C10: Lionel | D10: m2 | E10: =+H10*$K$7 -> 4803.7152 | F10: 45631 | H10: 800 | I10: 44896
A11: Pintura | B11: Latex Mate s/ Pared + Enduido | C11: Lionel | D11: m2 | E11: =+H11*$K$7 -> 6004.6439 | F11: 45631 | H11: 1000 | I11: 44896
A12: Pintura | B12: Latex Mate s/ Cielorraso + Enduido | C12: Lionel | D12: m2 | E12: =+H12*$K$7 -> 6004.6439 | F12: 45631 | H12: 1000 | I12: 44896
A13: Pintura | B13: Latex Satinado s/ Pared + Enduido | C13: Lionel | D13: m2 | E13: =+H13*$K$7 -> 12009.288 | F13: 45631 | H13: 2000 | I13: 44896
A14: Pintura | B14: Latex Satinado s/ Cielorraso + Enduido | C14: Lionel | D14: m2 | E14: =+H14*$K$7 -> 12009.288 | F14: 45631 | H14: 2000 | I14: 44896
A15: Pintura | B15: Esmalte Sintetico | C15: Lionel | D15: m2 | E15: =+H15*$K$7 -> 7806.0371 | F15: 45631 | H15: 1300 | I15: 44896
A16: Pintura | B16: Esmalte sintetico en Herrerias | C16: Lionel | D16: m2 | E16: =+H16*$K$7 -> 7806.0371 | F16: 45631 | H16: 1300 | I16: 44896
A17: Pintura | B17: Tarquini | C17: Lionel | D17: m2 | E17: =+H17*$K$7 -> 9006.9659 | F17: 45631 | H17: 1500 | I17: 45017
A18: Durlock | B18: Tabique simple | C18: Mario Silva | D18: m2 | E18: =+H18*$K$4 -> 20608.332 | F18: 45631 | H18: 2500 | I18: 44774 | J18: Neogen
A19: Durlock | B19: Tabique simple, doble placa | C19: Mario Silva | D19: m2 | E19: =+H19*$K$4 -> 0 | F19: 45631
A20: Durlock | B20: Medio Forro | C20: Mario Silva | D20: m2 | E20: =+H20*$K$4 -> 14837.999 | F20: 45631 | H20: 1800 | I20: 44774 | J20: Neogen | K20: =+H20/H18 -> 0.72
A21: Durlock | B21: Cielorraso Junta Tomada | C21: Mario Silva | D21: m2 | E21: =+H21*$K$4 -> 14837.999 | F21: 45631 | H21: 1800 | I21: 44774 | J21: Neogen
A22: Durlock | B22: Cielorraso Desmontable | C22: Mario Silva | D22: m2 | E22: =+H22*$K$4 -> 13189.333 | F22: 45631 | H22: 1600 | I22: 44774 | J22: Neogen | K22: =+H22/H21 -> 0.88888889
A23: Durlock | B23: Cajon cielorraso | C23: Mario Silva | D23: m2 | E23: =+H23*$K$4 -> 16486.666 | F23: 45631 | H23: 2000 | I23: 44774 | J23: Neogen
A24: Techos | B24: Cubierta Metalica c/Aislacion | C24: Acevedo | D24: m2 | E24: =+H24*K7 -> 42032.508 | F24: 45631 | H24: 7000 | I24: 45279 | J24: HUA
A25: Techos | B25: Babeta | C25: Acevedo | D25: ml | E25: 0 | F25: 45631
A26: Techos | B26: Banda Soler | C26: Acevedo | D26: ml | E26: 0 | F26: 45631
A27: Techos | B27: Canaleta | C27: Acevedo | D27: ml | E27: 0 | F27: 45631
A28: Techos | B28: Cumbrera | C28: Acevedo | D28: ml | E28: 0 | F28: 45631
A29: Yeso | B29: Cielorraso aplicado yeso | C29: Miguel Galleguillo | D29: m2 | E29: =+H29*$K$7 -> 9607.4303 | F29: 45631 | H29: 1600 | I29: 44890
A30: Yeso | B30: Cielorraso armado yeso | C30: Jorge Yesero (CDR) | D30: m2 | E30: =+H30*$K$7 -> 15011.61 | F30: 45631 | H30: 2500 | I30: 44890 | K30: CDR
A31: Yeso | B31: Aristas | C31: Miguel Galleguillo | D31: ml | E31: =+E29*0.5 -> 4803.7152 | F31: 45631 | H31: 750 | I31: 44890 | J31: =+H31/H29 -> 0.46875 | M31: Cielorraso armado CDR | N31: 220000 | O31: 60 | P31: =+N31/O31 -> 3666.6667 | Q31: =+P31/2 -> 1833.3333
A32: Yeso | B32: Enlucidos en paredes | C32: Miguel Galleguillo | D32: m2 | E32: =+E29 -> 9607.4303 | F32: 45631 | M32: Buña | O32: 70
A33: Yeso | B33: Buñas | C33: Jorge Yesero (CDR) | D33: ml | E33: =+E31 -> 4803.7152 | F33: 45631 | H33: 750 | I33: 44890 | K33: CDR
B34: Enduido Tabiques | C34: Fredi Austral | D34: m2 | F34: 45631 | H34: 500 | I34: 44593
B35: Enduido Cielorraso | C35: Fredi Austral | D35: m2 | F35: 45631 | H35: 450 | I35: 44593
F36: 45631
F37: 45631 | L37: 45597
F38: 45631 | H38: =+K3 -> 7.0709073 | L38: AAIERIC | M38: 1
A39: Electrico | B39: Cableado x boca | C39: Demian | D39: u | E39: =+H39*$H$38 -> 10606.361 | F39: 45631 | H39: 1500 | I39: 44835 | L39: 15156 | M39: =+L39/$M$38 -> 15156 | N39: =+E39/M39 -> 0.69981268
A40: Electrico | B40: Cableado x bandeja (cable 4x10mm x ml) | C40: Demian | D40: ml | E40: =+H40*$H$38 -> 10606.361 | F40: 45631 | H40: 1500 | I40: 44835 | M40: =+L40/$M$38 -> 0 | N40: =+E40/M40 -> #DIV/0!
A41: Electrico | B41: Cañeria PVC (x boca) | C41: Demian | D41: u | E41: =+H41*$H$38 -> 21212.722 | F41: 45631 | H41: 3000 | I41: 44835 | L41: 31184 | M41: =+L41/$M$38 -> 31184 | N41: =+E41/M41 -> 0.68024378
A42: Electrico | B42: Cañeria Metalica (x boca) | C42: Demian | D42: u | E42: =+H42*$H$38 -> 21212.722 | F42: 45631 | H42: 3000 | I42: 44835 | L42: 31184 | M42: =+L42/$M$38 -> 31184 | N42: =+E42/M42 -> 0.68024378
A43: Electrico | B43: Cañeria EXT | C43: Demian | D43: ml | E43: =+H43*$H$38 -> 21212.722 | F43: 45631 | H43: 3000 | I43: 44835 | L43: 28325 | M43: =+L43/$M$38 -> 28325 | N43: =+E43/M43 -> 0.74890457
...

Sheet Materiales
A3: PRECIOS UNITARIOS POR MATERIAL
D4: 45536
A7: Código | B7: DESCRIPCION | C7: UNIDAD | D7: Costo Material | E7: Proveedor
A8: *AGREG02 | B8: ARENA LAVADA | C8: m3 | D8: 32399.77 | E8: Cutuli Hnos | F8: 45625 | G8: BOLSÓN
B9: Piedra Partida | C9: m3 | D9: 56202.3 | E9: Cutuli Hnos | F9: 45625 | G9: BOLSÓN
B10: Cascote | C10: m3 | D10: 34246.8 | E10: Cutuli Hnos | F10: 45625 | G10: BOLSÓN
A11: *AGREG01 | B11: Cemento Portland x 50kg | C11: Bol | D11: 7809.48 | E11: Cutuli Hnos | F11: 45625 | G11: CEMENTO AVELLANEDA
A12: AGREG11 | B12: Cal Comun x 25kg | C12: bol | D12: 3837.96 | E12: Cutuli Hnos | F12: 45625
A13: CALMILAG | B13: cal milagro | C13: bol | D13: 10936.8 | E13: Cutuli Hnos | F13: 45625
A14: FE06 | B14: Barra de Acero Aleteado - 6mm x 12m | C14: u | D14: 3424.53 | E14: Cutuli Hnos | F14: 45625
B15: Barra de Acero Aleteado - 8mm x 12m | C15: u | D15: 6017.04 | E15: Cutuli Hnos | F15: 45625
B16: Barra de Acero Aleteado - 10mm x 12m | C16: u | D16: 9272.75 | E16: Cutuli Hnos | F16: 45625
B17: Barra de Acero Aleteado - 12mm x 12m | C17: u | D17: 13312.25 | E17: Cutuli Hnos | F17: 45625
B18: Barra de Acero Aleteado - 16mm x 12m | C18: u | D18: 23236.16 | E18: Cutuli Hnos | F18: 45625
B19: Barra de Acero Aleteado - 20mm x 12m | C19: u | D19: 36391.64 | E19: Cutuli Hnos | F19: 45625
B20: Barra de Acero Aleteado - 25mm x 12m | C20: u | D20: 56794.12 | E20: Cutuli Hnos | F20: 45625
A21: LADVISTA | B21: ladrillo a la vista 1 cara | C21: u | D21: 233.44 | E21: Cutuli Hnos | F21: 45625 | G21: 1/2 VISTA MDQ
A22: *LADRI03 | B22: LADRILLO CERAMICO 8 x 18 x 33 cm | C22: u | D22: 292.32 | E22: Cutuli Hnos | F22: 45625
A23: LADRI12 | B23: LADRILLO CERAMICO 12 x 18 x 33 cm | C23: u | D23: 365.4 | E23: Cutuli Hnos | F23: 45625
A24: LADRI181 | B24: LADRILLO CERAMICO 18 x 18 x 33 cm | C24: u | D24: 519.12 | E24: Cutuli Hnos | F24: 45625
A25: LADRIC | B25: Ladrillo Comun 12.5 x 5.5 x 25 | C25: u | D25: 132.3 | E25: Cutuli Hnos | F25: 45625
A26: LADRI182 | B26: Ladrillo hueco ceramico 12x19x33 - Portante | C26: u | D26: 563.22 | E26: Cutuli Hnos | F26: 45625
B27: Ladrillo hueco ceramico 18x19x33 - Portante | C27: u | D27: 694.26 | E27: Cutuli Hnos | F27: 45625
B28: Ladrillo Ceramico Kilablock 27 x 18 x 33 | C28: u
B29: Bloque de Hormigon 19 x 19 x 39 | C29: u | D29: 1016.6 | E29: Cutuli Hnos | F29: 45625
B30: Bloque de Hormigon 10 x 19 x 39 | C30: u | D30: 682.52 | E30: Cutuli Hnos | F30: 45625 | I30: Precio x 25 kg | J30: kg | K30: Precio x 30 kg | L30: kg
B31: Bloque de Hormigon 39 x 19 x 19 - simil pieda | C31: u
A32: *AGREG11 | B32: Adhesivo Klaukol Porcellanato Fluido x 30Kg | C32: bol | D32: =+K32 -> 18802.512 | E32: Cutuli Hnos | F32: 45625 | G32: WEBER FORTE PORCELLANATO X 25 KG | I32: 15668.76 | J32: 25 | K32: =+L32*I32/J32 -> 18802.512 | L32: 30
B33: Adhesivo Klaukol Impermeable Petenciado x 30Kg | C33: bol | D33: =+K33 -> 29811.732 | E33: Cutuli Hnos | F33: 45625 | G33: WEBER SUPLER FLEX 25 KG | I33: 24843.11 | J33: 25 | K33: =+L33*I33/J33 -> 29811.732 | L33: 30
A34: AGREG07 | B34: Aditivo Hidrofugo en pasta - Ceresita x 1kg | C34: kg | D34: =25122.56/20 -> 1256.128 | E34: Cutuli Hnos | F34: 45625 | G34: CERESITA X 20 LTS
A35: PINT015 | B35: Yeso Tuyango x 30kg | C35: b | D35: 9639 | E35: Cutuli Hnos | F35: 45625
B36: Pastina Klaukol x 1kg - Alta performance | C36: u | D36: =6428.7/2 -> 3214.35 | E36: Cutuli Hnos | F36: 45625 | G36: Prestige nieve
B37: Revoque Cementicio Exterior 3en1 | C37: bol | D37: 7534.8 | E37: Cutuli Hnos | F37: 45625 | G37: PROMEX E X 30
B38: Malla SIMA Q335 (8mm) | C38: u | D38: 126755.8 | E38: Cutuli Hnos | F38: 45625
B39: Malla SIMA Q188 (6mm) | C39: u | D39: 69985.79 | E39: Cutuli Hnos | F39: 45625
B40: Malla SIMA Q92 (4.2mm) | C40: u
B41: Alambre de Fardo | C41: kg | D41: 2302.02 | E41: Cutuli Hnos | F41: 45625 | G41: Alambre N°16
B42: Sika Poro Plus x 10 kg | C42: b | D42: =305000/1.21 -> 252066.12 | E42: ML | F42: 45631 | G42: https://articulo.mercadolibre.com.ar/MLA-1239468887-sika-poro-plus-espumigeno-para-hormigon-10-kg-_JM#polycard_client=search-nordic&position=11&search_layout=grid&type=item&tracking_id=c5802d9e-4804-403a-958c-824dd473f5b4
B44: Solera 70mm x 2.60m | C44: u | D44: 2932.93 | E44: Cutuli Hnos | F44: 45625
B45: Montante 69mm x 2.60m | C45: u | D45: 3295.47 | E45: Cutuli Hnos | F45: 45625
...

Sheet P-32
F2: Fecha: | G2: Completar…
A3: ANALISIS DE PRECIO UNITARIO
F4: Partida N°: | G4: 32
A5: Obra: | B5: Completar…
A6: Cliente: | B6: Completar… | F6: Código de Obra: | G6: Completar…
A7: Partida: | B7: Movimiento de suelos para bases c/ aporte de tosca (e: 40 cm en 2 capas de 20 cm)
C8: Unidad: | E8: Cantidad: | F8: Rendimiento:
C9: m3 | E9: 100 | F9: 25 | G9: m3/dia | J9: =65*0.4 -> 26 | L9: 120 | M9: 0.4 | N9: =+L9*M9 -> 48
A10: 1.- MATERIALES | L10: 60 | M10: 0.4 | N10: =+L10*M10 -> 24
A11: Código | B11: Descripción | C11: Unidad | D11: Cantidad | E11: Costo $ | F11: % Desp. | G11: Total $ | H11: Cant. x Obra
B12: Aporte de Tosca | C12: m3 | D12: 1 | E12: =VLOOKUP(B12,Materiales!$B$8:$D$118,3,FALSE) -> 9811.2872 | F12: 30 | G12: =+D12*E12*((F12+100)/100) -> 12754.673 | H12: =+D12*$E$9 -> 100
F13: Total Materiales: | G13: =SUM(G12:G12) -> 12754.673 | M13: 250 | N13: 0.5 | O13: =+M13*N13 -> 125
F14: Unitario Materiales: | G14: =+G13 -> 12754.673 | M14: 250 | N14: 0.4 | O14: =+M14*N14 -> 100
A15: 2.- EQUIPOS
A16: Código | B16: Descripción | D16: Cantidad | E16: Tarifa $ | F16: % Deprec. | G16: Total $
B17: Pala y retro 310J (c/ operario y combustible) - Alq. X dia | C17: d | D17: 1 | E17: =VLOOKUP(B17,'Rend. Equipos'!$B$7:$E$222,4,FALSE) -> 464850 | F17: 1 | G17: =+E17*D17*F17 -> 464850
B18: Combustible Retroexcav (96 lts) | C18: d | D18: 0 | E18: =VLOOKUP(B18,'Rend. Equipos'!$B$7:$E$222,4,FALSE) -> 107808 | F18: 1 | G18: =+E18*D18*F18 -> 0
B19: Camion chasis volcador 170E22 - (c/ operario y combustible) - Alq. X dia | C19: d | D19: 1 | E19: =VLOOKUP(B19,'Rend. Equipos'!$B$7:$E$222,4,FALSE) -> 258250 | F19: 1 | G19: =+E19*D19*F19 -> 258250
B20: Compactador pata de cabra 612H - (c/operario y combustible) - Alq. X dia | C20: d | D20: 0.25 | E20: =VLOOKUP(B20,'Rend. Equipos'!$B$7:$E$222,4,FALSE) -> 568150 | F20: 1 | G20: =+E20*D20*F20 -> 142037.5
F21: Total Equipos: | G21: =SUM(G17:G20) -> 865137.5
F22: Unitario Equipos: | G22: =+G21/F9 -> 34605.5
A23: 3.- MANO DE OBRA
A24: Código | B24: Descripción | C24: Unidad | D24: Cantidad | E24: Salario $ | G24: Total $
A25: OFAL | B25: OFICIAL ESPECIALIZADO ALBAÑIL | C25: j | D25: 1 | E25: =VLOOKUP(B25,'Mano de Obra'!$B$8:$C$100,2,FALSE) -> 85927.097 | G25: =+E25*D25 -> 85927.097
A26: MOFAL | B26: MEDIO OFICIAL ALBAÑIL | C26: j | D26: 1 | E26: =VLOOKUP(B26,'Mano de Obra'!$B$8:$C$100,2,FALSE) -> 65493.072 | G26: =+E26*D26 -> 65493.072
F27: Total Mano de Obra Menor: | G27: =SUM(G25:G26) -> 151420.17
F28: Grado de dificultad | G28: 1
F29: Total Mano de Obra: | G29: =+G28*G27 -> 151420.17
F30: Unitario Mano de Obra: | G30: =+G29/F9 -> 6056.8068
F34: Costo Directo por Unidad: | G34: =+G30+G22+G14 -> 53416.98
E35: Gastos Generales: | F35: =+RESUMEN!$I$2 -> 0 | G35: =IF(F35=0,0,F35*G34) -> 0
E36: Beneficio: | F36: =+RESUMEN!$I$3 -> 0 | G36: =IF(F36=0,0,F36*G34) -> 0
F37: PRECIO UNITARIO: | G37: =SUM(G34:G36) -> 53416.98

Sheet P-33
F2: Fecha: | G2: Completar …
A3: ANALISIS DE PRECIO UNITARIO
F4: Partida N°: | G4: 33
A5: Obra: | B5: Completar …
A6: Cliente: | B6: Completar … | F6: Código de Obra: | G6: Completar …
A7: Partida: | B7: Ladrillo común 12,5 x 5,5 x 25 (e:15 cm)
C8: Unidad: | E8: Cantidad: | F8: Rendimiento:
C9: m2 | E9: 100 | F9: 7 | G9: m2/dia
A10: 1.- MATERIALES | L10: 7
A11: Código | B11: Descripción | C11: Unidad | D11: Cantidad | E11: Costo $ | F11: % Desp. | G11: Total $ | H11: Cant. x Obra | L11: para 1 m2
A12: *AGREG01 | B12: Cemento Portland x 50kg | C12: bol | D12: 0.15 | E12: =VLOOKUP(B12,Materiales!$B$8:$D$118,3,FALSE) -> 7809.48 | F12: 10 | G12: =+D12*E12*((F12+100)/100) -> 1288.5642 | H12: =+D12*$E$9 -> 15 | I12: =+G12/4 -> 322.14105 | L12: 7.5 | M12: 50 | N12: =+L12/M12 -> 0.15
A13: AGREG11 | B13: Cal Comun x 25kg | C13: bol | D13: 0.3 | E13: =VLOOKUP(B13,Materiales!$B$8:$D$118,3,FALSE) -> 3837.96 | F13: 10 | G13: =+D13*E13*((F13+100)/100) -> 1266.5268 | H13: =+D13*$E$9 -> 30 | I13: =+G13/4 -> 316.6317 | L13: 7.5 | M13: 25 | N13: =+L13/M13 -> 0.3
A14: FE06 | B14: Barra de Acero Aleteado - 6mm x 12m | C14: u | D14: 0.17 | E14: =VLOOKUP(B14,Materiales!$B$8:$D$118,3,FALSE) -> 3424.53 | F14: 10 | G14: =+D14*E14*((F14+100)/100) -> 640.38711 | H14: =+D14*$E$9 -> 17 | I14: =+G14/4 -> 160.09678
A15: LADRIC | B15: Ladrillo Comun 12.5 x 5.5 x 25 | C15: u | D15: 60 | E15: =VLOOKUP(B15,Materiales!$B$8:$D$118,3,FALSE) -> 132.3 | F15: 5 | G15: =+D15*E15*((F15+100)/100) -> 8334.9 | H15: =+D15*$E$9 -> 6000 | I15: =+G15/4 -> 2083.725 | L15: 60 | M15: 1 | N15: =+L15/M15 -> 60
A16: *AGREG02 | B16: ARENA LAVADA | C16: m3 | D16: 0.035 | E16: =VLOOKUP(B16,Materiales!$B$8:$D$118,3,FALSE) -> 32399.77 | F16: 10 | G16: =+D16*E16*((F16+100)/100) -> 1247.3911 | H16: =+D16*$E$9 -> 3.5 | I16: =+G16/4 -> 311.84779 | L16: 0.035 | M16: 1 | N16: =+L16/M16 -> 0.035
B17: Consumibles (discos, alambre, maderas, etc.) | C17: gl | D17: 0.01 | E17: =+SUM(G12:G16) -> 12777.769 | F17: 3 | G17: =+D17*E17*((F17+100)/100) -> 131.61102 | H17: =+D17*$E$9 -> 1 | I17: =+G17/4 -> 32.902756
F18: Total Materiales: | G18: =SUM(G12:G17) -> 12909.38 | H18: =+G18/2 -> 6454.6901
F19: Unitario Materiales: | G19: =+G18 -> 12909.38
A20: 2.- EQUIPOS
A21: Código | B21: Descripción | C21: Unidad | D21: Cantidad | E21: Tarifa $ | F21: % Deprec. | G21: Total $
A22: EQALBA | B22: EQUIPO DE ALBAÑILERIA, carpetas, ladrillo | C22: gl | D22: 1 | E22: =VLOOKUP(B22,'Rend. Equipos'!$B$7:$E$222,4,FALSE) -> 2470106.6 | F22: =VLOOKUP(B22,'Rend. Equipos'!$B$6:$L$166,MATCH($F$21,'Rend. Equipos'!$B$6:$L$6,0),0) -> 0.00092592593 | G22: =+E22*D22*F22 -> 2287.1357
A23: *ANDAM05 | B23: ANDAMIO TUBULAR DE UNO A TRES CUERPOS | C23: gl | D23: 0.5 | E23: =VLOOKUP(B23,'Rend. Equipos'!$B$7:$E$222,4,FALSE) -> 1028123.1 | F23: =VLOOKUP(B23,'Rend. Equipos'!$B$6:$L$166,MATCH($F$21,'Rend. Equipos'!$B$6:$L$6,0),0) -> 0.00055555556 | G23: =+E23*D23*F23 -> 285.58975
A24: TROMPO | B24: Hormigonera De 150 Litros 1hp Con Rueda Maciza | C24: u | D24: 1 | E24: =VLOOKUP(B24,'Rend. Equipos'!$B$7:$E$222,4,FALSE) -> 689222.3 | F24: =VLOOKUP(B24,'Rend. Equipos'!$B$6:$L$166,MATCH($F$21,'Rend. Equipos'!$B$6:$L$6,0),0) -> 0.0013888889 | G24: =+E24*D24*F24 -> 957.2532
F25: Total Equipos: | G25: =SUM(G22:G24) -> 3529.9787
F26: Unitario Equipos: | G26: =+G25/F9 -> 504.28267
A27: 3.- MANO DE OBRA
A28: Código | B28: Descripción | C28: Unidad | D28: Cantidad | E28: Salario $ | G28: Total $
A29: OFAL | B29: OFICIAL ESPECIALIZADO ALBAÑIL | C29: j | D29: 1 | E29: =VLOOKUP(B29,'Mano de Obra'!$B$8:$C$100,2,FALSE) -> 85927.097 | G29: =+E29*D29 -> 85927.097
A30: AYUDANTE | B30: AYUDANTE ALBAÑIL | C30: j | D30: 1 | E30: =VLOOKUP(B30,'Mano de Obra'!$B$8:$C$100,2,FALSE) -> 60860.581 | G30: =+E30*D30 -> 60860.581
F31: Total Mano de Obra Menor: | G31: =SUM(G29:G30) -> 146787.68
F32: Grado de dificultad | G32: 1
F33: Total Mano de Obra: | G33: =+G32*G31 -> 146787.68
F34: Unitario Mano de Obra: | G34: =+G33/F9 -> 20969.668
E36: Costo Directo por Unidad: | G36: =+G34+G26+G19 -> 34383.331
E37: Gastos Generales: | F37: =+RESUMEN!$I$2 -> 0 | G37: =IF(F37=0,0,F37*G36) -> 0
E38: Beneficio: | F38: =+RESUMEN!$I$3 -> 0 | G38: =IF(F38=0,0,F38*G36) -> 0
F39: PRECIO UNITARIO: | G39: =SUM(G36:G38) -> 34383.331

Sheet P-34
F2: Fecha: | G2: Completar …
A3: ANALISIS DE PRECIO UNITARIO
F4: Partida N°: | G4: 34
A5: Obra: | B5: Completar …
A6: Cliente: | B6: Completar … | F6: Código de Obra: | G6: Completar …
A7: Partida: | B7: Ladrillo cerámico 8 x 18 x 33 cm
C8: Unidad: | E8: Cantidad: | F8: Rendimiento:
B9: (10 lts mezcla x m2) | C9: m2 | E9: 100 | F9: 15 | G9: m2/dia
A10: 1.- MATERIALES
A11: Código | B11: Descripción | C11: Unidad | D11: Cantidad | E11: Costo $ | F11: % Desp. | G11: Total $ | H11: Cant. x Obra | J11: Para 1 m2
A12: *LADRI03 | B12: LADRILLO CERAMICO 8 x 18 x 33 cm | C12: u | D12: 15 | E12: =VLOOKUP(B12,Materiales!$B$8:$D$118,3,FALSE) -> 292.32 | F12: 5 | G12: =+D12*E12*((F12+100)/100) -> 4604.04 | H12: =+D12*$E$9 -> 1500 | J12: 15.5
A13: FE06 | B13: Barra de Acero Aleteado - 6mm x 12m | C13: u | D13: 0.17 | E13: =VLOOKUP(B13,Materiales!$B$8:$D$118,3,FALSE) -> 3424.53 | F13: 10 | G13: =+D13*E13*((F13+100)/100) -> 640.38711 | H13: =+D13*$E$9 -> 17
A14: *AGREG02 | B14: ARENA LAVADA | C14: m3 | D14: 0.012 | E14: =VLOOKUP(B14,Materiales!$B$8:$D$118,3,FALSE) -> 32399.77 | F14: 10 | G14: =+D14*E14*((F14+100)/100) -> 427.67696 | H14: =+D14*$E$9 -> 1.2 | J14: 0.012
A15: AGREG11 | B15: Cal Comun x 25kg | C15: bol | D15: 0.1 | E15: =VLOOKUP(B15,Materiales!$B$8:$D$118,3,FALSE) -> 3837.96 | F15: 10 | G15: =+D15*E15*((F15+100)/100) -> 422.1756 | H15: =+D15*$E$9 -> 10 | J15: 2.5 | K15: 25 | L15: =+J15/K15 -> 0.1
A16: *AGREG01 | B16: Cemento Portland x 50kg | C16: bol | D16: 0.05 | E16: =VLOOKUP(B16,Materiales!$B$8:$D$118,3,FALSE) -> 7809.48 | F16: 10 | G16: =+D16*E16*((F16+100)/100) -> 429.5214 | H16: =+D16*$E$9 -> 5 | J16: 2.6 | K16: 50 | L16: =+J16/K16 -> 0.052
B17: Consumibles (discos, alambre, maderas, etc.) | C17: gl | D17: 0.01 | E17: =+SUM(G12:G16) -> 6523.8011 | F17: 3 | G17: =+D17*E17*((F17+100)/100) -> 67.195151 | H17: =+D17*$E$9 -> 1
F18: Total Materiales: | G18: =SUM(G12:G17) -> 6590.9962
F19: Unitario Materiales: | G19: =+G18 -> 6590.9962
A20: 2.- EQUIPOS
A21: Código | B21: Descripción | C21: Unidad | D21: Cantidad | E21: Tarifa $ | F21: % Deprec. | G21: Total $
A22: EQALBA | B22: EQUIPO DE ALBAÑILERIA, carpetas, ladrillo | C22: gl | D22: 1 | E22: =VLOOKUP(B22,'Rend. Equipos'!$B$7:$E$222,4,FALSE) -> 2470106.6 | F22: =VLOOKUP(B22,'Rend. Equipos'!$B$6:$L$166,MATCH($F$21,'Rend. Equipos'!$B$6:$L$6,0),0) -> 0.00092592593 | G22: =+E22*D22*F22 -> 2287.1357
A23: *ANDAM05 | B23: ANDAMIO TUBULAR DE UNO A TRES CUERPOS | C23: gl | D23: 0.5 | E23: =VLOOKUP(B23,'Rend. Equipos'!$B$7:$E$222,4,FALSE) -> 1028123.1 | F23: =VLOOKUP(B23,'Rend. Equipos'!$B$6:$L$166,MATCH($F$21,'Rend. Equipos'!$B$6:$L$6,0),0) -> 0.00055555556 | G23: =+E23*D23*F23 -> 285.58975
A24: TROMPO | B24: Hormigonera De 150 Litros 1hp Con Rueda Maciza | C24: u | D24: 1 | E24: =VLOOKUP(B24,'Rend. Equipos'!$B$7:$E$222,4,FALSE) -> 689222.3 | F24: =VLOOKUP(B24,'Rend. Equipos'!$B$6:$L$166,MATCH($F$21,'Rend. Equipos'!$B$6:$L$6,0),0) -> 0.0013888889 | G24: =+E24*D24*F24 -> 957.2532
F25: Total Equipos: | G25: =SUM(G22:G24) -> 3529.9787
F26: Unitario Equipos: | G26: =+G25/F9 -> 235.33191
A27: 3.- MANO DE OBRA
A28: Código | B28: Descripción | C28: Unidad | D28: Cantidad | E28: Salario $ | G28: Total $
A29: OFAL | B29: OFICIAL ESPECIALIZADO ALBAÑIL | C29: j | D29: 1 | E29: =VLOOKUP(B29,'Mano de Obra'!$B$8:$C$100,2,FALSE) -> 85927.097 | G29: =+E29*D29 -> 85927.097
A30: AYUDANTE | B30: AYUDANTE ALBAÑIL | C30: j | D30: 1 | E30: =VLOOKUP(B30,'Mano de Obra'!$B$8:$C$100,2,FALSE) -> 60860.581 | G30: =+E30*D30 -> 60860.581
F31: Total Mano de Obra Menor: | G31: =SUM(G29:G30) -> 146787.68
F32: Grado de dificultad | G32: 1
F33: Total Mano de Obra: | G33: =+G32*G31 -> 146787.68
F34: Unitario Mano de Obra: | G34: =+G33/F9 -> 9785.8452
F36: Costo Directo por Unidad: | G36: =+G34+G26+G19 -> 16612.173
E37: Gastos Generales: | F37: =+RESUMEN!$I$2 -> 0 | G37: =IF(F37=0,0,F37*G36) -> 0
E38: Beneficio: | F38: =+RESUMEN!$I$3 -> 0 | G38: =IF(F38=0,0,F38*G36) -> 0
F39: PRECIO UNITARIO: | G39: =SUM(G36:G38) -> 16612.173

Sheet P-35
F2: Fecha: | G2: Completar …
A3: ANALISIS DE PRECIO UNITARIO
F4: Partida N°: | G4: 35
A5: Obra: | B5: Completar …
A6: Cliente: | B6: Completar … | F6: Código de Obra: | G6: Completar …
A7: Partida: | B7: Ladrillo cerámico 12 x 18 x 33 cm
C8: Unidad: | E8: Cantidad: | F8: Rendimiento:
B9: (15 lts mezcla x m2) | C9: m2 | E9: 100 | F9: 15 | G9: m2/dia
A10: 1.- MATERIALES
A11: Código | B11: Descripción | C11: Unidad | D11: Cantidad | E11: Costo $ | F11: % Desp. | G11: Total $ | H11: Cant. x Obra
A12: FE06 | B12: Barra de Acero Aleteado - 6mm x 12m | C12: u | D12: 0.17 | E12: =VLOOKUP(B12,Materiales!$B$8:$D$118,3,FALSE) -> 3424.53 | F12: 10 | G12: =+D12*E12*((F12+100)/100) -> 640.38711 | H12: =+D12*$E$9 -> 17 | M12: lt | N12: lts
A13: LADRI12 | B13: LADRILLO CERAMICO 12 x 18 x 33 cm | C13: u | D13: 15 | E13: =VLOOKUP(B13,Materiales!$B$8:$D$118,3,FALSE) -> 365.4 | F13: 5 | G13: =+D13*E13*((F13+100)/100) -> 5755.05 | H13: =+D13*$E$9 -> 1500 | M13: 10 | N13: 15
A14: AGREG11 | B14: Cal Comun x 25kg | C14: bol | D14: 0.15 | E14: =VLOOKUP(B14,Materiales!$B$8:$D$118,3,FALSE) -> 3837.96 | F14: 10 | G14: =+D14*E14*((F14+100)/100) -> 633.2634 | H14: =+D14*$E$9 -> 15 | K14: ARENA LAVADA | L14: m3 | M14: 0.012 | N14: =+$N$13*M14/$M$13 -> 0.018
A15: *AGREG01 | B15: Cemento Portland x 50kg | C15: bol | D15: 0.075 | E15: =VLOOKUP(B15,Materiales!$B$8:$D$118,3,FALSE) -> 7809.48 | F15: 10 | G15: =+D15*E15*((F15+100)/100) -> 644.2821 | H15: =+D15*$E$9 -> 7.5 | K15: Cal Comun x 25kg | L15: bol | M15: 0.1 | N15: =+$N$13*M15/$M$13 -> 0.15
A16: *AGREG02 | B16: ARENA LAVADA | C16: m3 | D16: 0.018 | E16: =VLOOKUP(B16,Materiales!$B$8:$D$118,3,FALSE) -> 32399.77 | F16: 10 | G16: =+D16*E16*((F16+100)/100) -> 641.51545 | H16: =+D16*$E$9 -> 1.8 | K16: Cemento Portland x 50kg | L16: bol | M16: 0.05 | N16: =+$N$13*M16/$M$13 -> 0.075
B17: Consumibles (discos, alambre, maderas, etc.) | C17: gl | D17: 0.01 | E17: =+SUM(G12:G16) -> 8314.4981 | F17: 3 | G17: =+D17*E17*((F17+100)/100) -> 85.63933 | H17: =+D17*$E$9 -> 1
F18: Total Materiales: | G18: =SUM(G12:G16) -> 8314.4981
F19: Unitario Materiales: | G19: =+G18 -> 8314.4981
A20: 2.- EQUIPOS
A21: Código | B21: Descripción | C21: Unidad | D21: Cantidad | E21: Tarifa $ | F21: % Deprec. | G21: Total $
A22: EQALBA | B22: EQUIPO DE ALBAÑILERIA, carpetas, ladrillo | C22: gl | D22: 1 | E22: =VLOOKUP(B22,'Rend. Equipos'!$B$7:$E$222,4,FALSE) -> 2470106.6 | F22: =VLOOKUP(B22,'Rend. Equipos'!$B$6:$L$166,MATCH($F$21,'Rend. Equipos'!$B$6:$L$6,0),0) -> 0.00092592593 | G22: =+E22*D22*F22 -> 2287.1357 | J22: 60105.537
A23: *ANDAM05 | B23: ANDAMIO TUBULAR DE UNO A TRES CUERPOS | C23: gl | D23: 0.5 | E23: =VLOOKUP(B23,'Rend. Equipos'!$B$7:$E$222,4,FALSE) -> 1028123.1 | F23: =VLOOKUP(B23,'Rend. Equipos'!$B$6:$L$166,MATCH($F$21,'Rend. Equipos'!$B$6:$L$6,0),0) -> 0.00055555556 | G23: =+E23*D23*F23 -> 285.58975
A24: TROMPO | B24: Hormigonera De 150 Litros 1hp Con Rueda Maciza | C24: u | D24: 1 | E24: =VLOOKUP(B24,'Rend. Equipos'!$B$7:$E$222,4,FALSE) -> 689222.3 | F24: =VLOOKUP(B24,'Rend. Equipos'!$B$6:$L$166,MATCH($F$21,'Rend. Equipos'!$B$6:$L$6,0),0) -> 0.0013888889 | G24: =+E24*D24*F24 -> 957.2532
F25: Total Equipos: | G25: =SUM(G22:G24) -> 3529.9787 | J25: 0.02
F26: Unitario Equipos: | G26: =+G25/F9 -> 235.33191 | J26: =+J22*J25 -> 1202.1107
A27: 3.- MANO DE OBRA | J27: =+J26/F9 -> 80.140716
A28: Código | B28: Descripción | D28: Cantidad | E28: Salario $ | G28: Total $
A29: OFAL | B29: OFICIAL ESPECIALIZADO ALBAÑIL | D29: 1 | E29: =VLOOKUP(B29,'Mano de Obra'!$B$8:$C$100,2,FALSE) -> 85927.097 | G29: =+E29*D29 -> 85927.097
A30: AYUDANTE | B30: AYUDANTE ALBAÑIL | D30: 1 | E30: =VLOOKUP(B30,'Mano de Obra'!$B$8:$C$100,2,FALSE) -> 60860.581 | G30: =+E30*D30 -> 60860.581
F31: Total Mano de Obra Menor: | G31: =SUM(G29:G30) -> 146787.68
F32: Grado de dificultad | G32: 1
F33: Total Mano de Obra: | G33: =+G32*G31 -> 146787.68
F34: Unitario Mano de Obra: | G34: =+G33/F9 -> 9785.8452
F36: Costo Directo por Unidad: | G36: =+G34+G26+G19 -> 18335.675
E37: Gastos Generales: | F37: =+RESUMEN!$I$2 -> 0 | G37: =IF(F37=0,0,F37*G36) -> 0
E38: Beneficio: | F38: =+RESUMEN!$I$3 -> 0 | G38: =IF(F38=0,0,F38*G36) -> 0
F39: PRECIO UNITARIO: | G39: =SUM(G36:G38) -> 18335.675

Sheet P-36
F2: Fecha: | G2: Completar …
A3: ANALISIS DE PRECIO UNITARIO
F4: Partida N°: | G4: 36
A5: Obra: | B5: Completar …
A6: Cliente: | B6: Completar … | F6: Código de Obra: | G6: Completar …
A7: Partida: | B7: Ladrillo cerámico 18 x 18 x 33 cm
C8: Unidad: | E8: Cantidad: | F8: Rendimiento:
B9: (20 lts mezcla x m2) | C9: m2 | E9: 100 | F9: 15 | G9: m2/dia
A10: 1.- MATERIALES
A11: Código | B11: Descripción | C11: Unidad | D11: Cantidad | E11: Costo $ | F11: % Desp. | G11: Total $ | H11: Cant. x Obra
A12: LADRI181 | B12: LADRILLO CERAMICO 18 x 18 x 33 cm | C12: u | D12: 15 | E12: =VLOOKUP(B12,Materiales!$B$8:$D$118,3,FALSE) -> 519.12 | F12: 5 | G12: =+D12*E12*((F12+100)/100) -> 8176.14 | H12: =+D12*$E$9 -> 1500 | M12: lt | N12: lt
A13: FE06 | B13: Barra de Acero Aleteado - 6mm x 12m | C13: u | D13: 0.17 | E13: =VLOOKUP(B13,Materiales!$B$8:$D$118,3,FALSE) -> 3424.53 | F13: 10 | G13: =+D13*E13*((F13+100)/100) -> 640.38711 | H13: =+D13*$E$9 -> 17 | M13: 10 | N13: 20
A14: AGREG11 | B14: Cal Comun x 25kg | C14: bol | D14: 0.2 | E14: =VLOOKUP(B14,Materiales!$B$8:$D$118,3,FALSE) -> 3837.96 | F14: 10 | G14: =+D14*E14*((F14+100)/100) -> 844.3512 | H14: =+D14*$E$9 -> 20 | K14: Cal Comun x 25kg | L14: bol | M14: 0.1 | N14: =+$N$13*M14/$M$13 -> 0.2
A15: *AGREG01 | B15: Cemento Portland x 50kg | C15: bol | D15: 0.1 | E15: =VLOOKUP(B15,Materiales!$B$8:$D$118,3,FALSE) -> 7809.48 | F15: 10 | G15: =+D15*E15*((F15+100)/100) -> 859.0428 | H15: =+D15*$E$9 -> 10 | K15: Cemento Portland x 50kg | L15: bol | M15: 0.05 | N15: =+$N$13*M15/$M$13 -> 0.1
A16: *AGREG02 | B16: ARENA LAVADA | C16: m3 | D16: 0.024 | E16: =VLOOKUP(B16,Materiales!$B$8:$D$118,3,FALSE) -> 32399.77 | F16: 10 | G16: =+D16*E16*((F16+100)/100) -> 855.35393 | H16: =+D16*$E$9 -> 2.4 | K16: ARENA LAVADA | L16: m3 | M16: 0.012 | N16: =+$N$13*M16/$M$13 -> 0.024
B17: Consumibles (discos, alambre, maderas, etc.) | C17: gl | D17: 0.01 | E17: =+SUM(G12:G16) -> 11375.275 | F17: 3 | G17: =+D17*E17*((F17+100)/100) -> 117.16533 | H17: =+D17*$E$9 -> 1
F18: Total Materiales: | G18: =SUM(G12:G17) -> 11492.44
F19: Unitario Materiales: | G19: =+G18 -> 11492.44
A20: 2.- EQUIPOS
A21: Código | B21: Descripción | C21: Unidad | D21: Cantidad | E21: Tarifa $ | F21: % Deprec. | G21: Total $
A22: EQALBA | B22: EQUIPO DE ALBAÑILERIA, carpetas, ladrillo | C22: gl | D22: 1 | E22: =VLOOKUP(B22,'Rend. Equipos'!$B$7:$E$222,4,FALSE) -> 2470106.6 | F22: =VLOOKUP(B22,'Rend. Equipos'!$B$6:$L$166,MATCH($F$21,'Rend. Equipos'!$B$6:$L$6,0),0) -> 0.00092592593 | G22: =+E22*D22*F22 -> 2287.1357
A23: *ANDAM05 | B23: ANDAMIO TUBULAR DE UNO A TRES CUERPOS | C23: gl | D23: 0.5 | E23: =VLOOKUP(B23,'Rend. Equipos'!$B$7:$E$222,4,FALSE) -> 1028123.1 | F23: =VLOOKUP(B23,'Rend. Equipos'!$B$6:$L$166,MATCH($F$21,'Rend. Equipos'!$B$6:$L$6,0),0) -> 0.00055555556 | G23: =+E23*D23*F23 -> 285.58975
A24: TROMPO | B24: Hormigonera De 150 Litros 1hp Con Rueda Maciza | C24: u | D24: 1 | E24: =VLOOKUP(B24,'Rend. Equipos'!$B$7:$E$222,4,FALSE) -> 689222.3 | F24: =VLOOKUP(B24,'Rend. Equipos'!$B$6:$L$166,MATCH($F$21,'Rend. Equipos'!$B$6:$L$6,0),0) -> 0.0013888889 | G24: =+E24*D24*F24 -> 957.2532
F25: Total Equipos: | G25: =SUM(G22:G24) -> 3529.9787
F26: Unitario Equipos: | G26: =+G25/F9 -> 235.33191
A27: 3.- MANO DE OBRA
A28: Código | B28: Descripción | C28: Unidad | D28: Cantidad | E28: Salario $ | G28: Total $
A29: OFAL | B29: OFICIAL ESPECIALIZADO ALBAÑIL | C29: j | D29: 1 | E29: =VLOOKUP(B29,'Mano de Obra'!$B$8:$C$100,2,FALSE) -> 85927.097 | G29: =+E29*D29 -> 85927.097
A30: AYUDANTE | B30: AYUDANTE ALBAÑIL | C30: j | D30: 1 | E30: =VLOOKUP(B30,'Mano de Obra'!$B$8:$C$100,2,FALSE) -> 60860.581 | G30: =+E30*D30 -> 60860.581
F31: Total Mano de Obra Menor: | G31: =SUM(G29:G30) -> 146787.68
F32: Grado de dificultad | G32: 1
F33: Total Mano de Obra: | G33: =+G32*G31 -> 146787.68
F34: Unitario Mano de Obra: | G34: =+G33/F9 -> 9785.8452
F36: Costo Directo por Unidad: | G36: =+G34+G26+G19 -> 21513.617
E37: Gastos Generales: | F37: =+RESUMEN!$I$2 -> 0 | G37: =IF(F37=0,0,F37*G36) -> 0
E38: Beneficio: | F38: =+RESUMEN!$I$3 -> 0 | G38: =IF(F38=0,0,F38*G36) -> 0
F39: PRECIO UNITARIO: | G39: =SUM(G36:G38) -> 21513.617

Sheet P-37
F2: Fecha: | G2: Completar …
A3: ANALISIS DE PRECIO UNITARIO
F4: Partida N°: | G4: 37
A5: Obra: | B5: Completar …
A6: Cliente: | B6: Completar … | F6: Código de Obra: | G6: Completar …
A7: Partida: | B7: Pared DOBLE Comun / 5 / LHC 08 - (ladrillo a la vista)
C8: Unidad: | E8: Cantidad: | F8: Rendimiento:
C9: m2 | E9: 100 | F9: 4 | G9: m2/dia
A10: 1.- MATERIALES
A11: Código | B11: Descripción | C11: Unidad | D11: Cantidad | E11: Costo $ | F11: % Desp. | G11: Total $ | H11: Cant. x Obra
B12: Mamposteria LHC 08
A13: AGREG11 | B13: LADRILLO CERAMICO 8 x 18 x 33 cm | C13: u | D13: 15 | E13: =VLOOKUP(B13,Materiales!$B$8:$D$118,3,FALSE) -> 292.32 | F13: 5 | G13: =+D13*E13*((F13+100)/100) -> 4604.04 | H13: =+D13*$E$9 -> 1500 | I13: 7.3 | J13: 25 | K13: =+I13/J13 -> 0.292
A14: *AGREG01 | B14: Barra de Acero Aleteado - 6mm x 12m | C14: u | D14: 0.17 | E14: =VLOOKUP(B14,Materiales!$B$8:$D$118,3,FALSE) -> 3424.53 | F14: 10 | G14: =+D14*E14*((F14+100)/100) -> 640.38711 | H14: =+D14*$E$9 -> 17 | I14: 7.5 | J14: 50 | K14: =+I14/J14 -> 0.15
A15: *AGREG02 | B15: ARENA LAVADA | C15: m3 | D15: 0.012 | E15: =VLOOKUP(B15,Materiales!$B$8:$D$118,3,FALSE) -> 32399.77 | F15: 10 | G15: =+D15*E15*((F15+100)/100) -> 427.67696 | H15: =+D15*$E$9 -> 1.2 | I15: 0.04 | J15: 1 | K15: =+I15/J15 -> 0.04
A16: LADVISTA | B16: Cal Comun x 25kg | C16: bol | D16: 0.1 | E16: =VLOOKUP(B16,Materiales!$B$8:$D$118,3,FALSE) -> 3837.96 | F16: 10 | G16: =+D16*E16*((F16+100)/100) -> 422.1756 | H16: =+D16*$E$9 -> 10
A17: FE06 | B17: Cemento Portland x 50kg | C17: bol | D17: 0.05 | E17: =VLOOKUP(B17,Materiales!$B$8:$D$118,3,FALSE) -> 7809.48 | F17: 10 | G17: =+D17*E17*((F17+100)/100) -> 429.5214 | H17: =+D17*$E$9 -> 5
B18: Azotado hidrófugo + pintura asfáltica
A19: *AGREG02 | B19: ARENA LAVADA | C19: m3 | D19: 0.006 | E19: =VLOOKUP(B19,Materiales!$B$8:$D$118,3,FALSE) -> 32399.77 | F19: 10 | G19: =+D19*E19*((F19+100)/100) -> 213.83848 | H19: =+D19*$E$9 -> 0.6
A20: AGREG07 | B20: Aditivo Hidrofugo en pasta - Ceresita x 1kg | C20: kg | D20: 0.1 | E20: =VLOOKUP(B20,Materiales!$B$8:$D$118,3,FALSE) -> 1256.128 | F20: 5 | G20: =+D20*E20*((F20+100)/100) -> 131.89344 | H20: =+D20*$E$9 -> 10
A21: *AGREG01 | B21: Cemento Portland x 50kg | C21: bol | D21: 0.054 | E21: =VLOOKUP(B21,Materiales!$B$8:$D$118,3,FALSE) -> 7809.48 | F21: 10 | G21: =+D21*E21*((F21+100)/100) -> 463.88311 | H21: =+D21*$E$9 -> 5.4
B22: Pintura Asfaltica Asfasol x18ts | C22: b | D22: =1/36 -> 0.027777778 | E22: =VLOOKUP(B22,Materiales!$B$8:$D$118,3,FALSE) -> 32845.78 | F22: 10 | G22: =+D22*E22*((F22+100)/100) -> 1003.6211 | H22: =+D22*$E$9 -> 2.7777778 | I22: Rend. 0,50 lts x m2
A23: PINT016 | B23: Aguarras Hydrarras Hydra x 18lts | C23: b | D23: 0.005 | E23: =VLOOKUP(B23,Materiales!$B$8:$D$118,3,FALSE) -> 26907.33 | F23: 5 | G23: =+D23*E23*((F23+100)/100) -> 141.26348 | H23: =+D23*$E$9 -> 0.5
