Workbook
Name \0: #REF!
Name \0: #REF!
Name \0: #REF!
Name \0: #REF!
Name \0: #REF!
Name \c: #REF!
Name \c: #REF!
Name \E: #REF!
Name \E: #REF!
Name \i: #REF!
Name \j: #REF!
Name \m: #REF!
Name \P: #REF!
Name \P: #REF!
Name \P: #REF!
Name \r: #N/A
Name \x: #REF!
Name \z: #REF!
Name __________ben1: #REF!
Name __________ben1: #REF!
Name __________ben1: #REF!
Name __________ben1: #REF!
Name __________ben10: #REF!
Name __________ben10: #REF!
Name __________ben10: #REF!
Name __________ben15: #REF!
Name __________ben15: #REF!
Name __________ben15: #REF!
Name __________BEN2: #REF!
Name __________BEN2: #REF!
Name __________BEN2: [1]Beneficios!$C$3
Name __________BEN2: #REF!
Name __________BEN2: [1]Beneficios!$C$3
Name __________BEN2: #REF!
Name __________BEN2: #REF!
Name __________BEN2: [1]Beneficios!$C$3
Name __________BEN2: #REF!
Name __________ben20: #REF!
Name __________ben20: #REF!
Name __________ben20: #REF!
Name __________ben25: #REF!
Name __________ben25: #REF!
Name __________ben25: #REF!
Name __________BEN3: #REF!
Name __________BEN3: #REF!
Name __________BEN3: #REF!
Name __________BEN4: #REF!
Name __________BEN4: #REF!
Name __________BEN4: #REF!
Name __________ben5: #REF!
Name __________ben5: #REF!
Name __________ben5: #REF!
Name _________ben1: #REF!
Name _________ben1: #REF!
Name _________ben1: #REF!
Name _________ben10: #REF!
Name _________ben10: #REF!
Name _________ben10: #REF!
Name _________ben15: #REF!
Name _________ben15: #REF!

Sheet Cotizaciones
I1: =+GGBB!H2 -> 45846
B2: Descripcion | C2: Un | D2: P unit | E2: Proveedor | F2: Fecha | H2: DÓLAR BNA | I2: DÓLAR MEP
B3: PRELIMINARES | H3: =+GGBB!G4 -> 1280 | I3: =+GGBB!H4 -> 1276
B4: C. CIN. T101 ESP 0,50 MM (C25) | C4: m2 | D4: =13142.74/1.21 -> 10861.769 | E4: CMP Web | F4: 45785
B5: Peril UPN 100 x 12 m | C5: bar | D5: =328085.32/1.21 -> 271144.89 | E5: CMP Web | F5: 45785
B6: Tubo estructural 40 x 40 x 2, Largo 6 metros | C6: bar | D6: =28463.74/1.21 -> 23523.752 | E6: CMP Web | F6: 45785
B7: Riel Roma 174 e: 2,1 mm. 53 x 60 x 6000 | C7: bar | D7: =103323.57/1.21 -> 85391.38 | E7: CMP Web | F7: 45785
B8: Carro acero 174 4 ruedas puertas portones Ø45mm | C8: u | D8: =13957.04/1.21 -> 11534.744 | E8: CMP Web | F8: 45785
B9: PLACA CEMENTICIA CONSTRUCCION SECO SUPERBOARD ESTRUCTURAL BORDE RECTO 10MM X 1200MM X 2400MM | C9: u | D9: =57320.11/1.21 -> 47371.992 | E9: CMP Web | F9: 45785
B10: CHAPA LISA GALVANIZADA C27 - 1,22 x 2,00 m | C10: u | D10: =20659.53/1.21 -> 17073.992 | E10: CMP Web | F10: 45785
B11: CHAPA LISA GALVANIZADA C27 - 1,22 x 2,44 m | C11: u | D11: =25162.26/1.21 -> 20795.256 | E11: CMP Web | F11: 45785
B12: CHAPA LISA GALVANIZADA C25 - 1,22 x 2,00 m | C12: u | D12: =24100.79/1.21 -> 19918.008 | E12: CMP Web | F12: 45785
B13: CHAPA LISA GALVANIZADA C25 - 1,22 x 2,44 m | C13: u | D13: =29391.17/1.21 -> 24290.223 | E13: CMP Web | F13: 45785
B14: CHAPA LISA GALVANIZADA C22 - 1,22 x 2,44 m | C14: u | D14: =41709.52/1.21 -> 34470.678 | E14: CMP Web | F14: 45785
B15: CHAPA LISA PREP C25 - 1,22 x 2,44 m | C15: u | D15: =46496.8/1.21 -> 38427.107 | E15: CMP Web | F15: 45785 | H15: =+D15/D13 -> 1.5819989
B16: PERFIL ANGULO ALAS IGUALES ESTRUCTURAL ACERO 6M X 5/8" X 1/8 | C16: u | D16: =12473.83/1.21 -> 10308.95 | E16: CMP Web | F16: 45785
B17: Zócalo Contramarco Curvo Atenneas 7.5cm x 15mm MDF Prepintado Blanco 2.75m | C17: tira | D17: =5615/1.21 -> 4640.4959 | E17: GUALA | F17: 45846
B18: Sikaflex®-1A Sellador Poliuretano Color Gris 300ml | C18: u | D18: =29859.05/1.21 -> 24676.901 | E18: ABRAFER WEB | F18: 45845
B19: Babeta amure gris C25 Des. 200mm x 2.44m | C19: tira | D19: 21485.39 | E19: CMP Web | F19: 45845
B20: MADERA
B21: Precio fenolico comun e: 18 mm | C21: placa | D21: 26393.8 | E21: NEWTON | F21: 45782
B22: Precio fenolico visto e: 18 mm | C22: placa | D22: =61746/1.21 -> 51029.752 | E22: ML | F22: 45785
B23: Tabla 4 x 1 x 3,6 Saligna bruto | C23: u | D23: =133124.28/60 -> 2218.738 | E23: NEWTON | F23: 45782
B24: Tirante 3 x 3 x 3,6 Saligna bruto | C24: u | D24: =149764.94/30 -> 4992.1647 | E24: NEWTON | F24: 45782
B25: HORMIGON
B26: H30 6.12 Gunitado | C26: m3 | D26: 148900 | E26: FENOMIX | F26: 45785
B27: H30 6.20 | C27: m3 | D27: 125000 | E27: FENOMIX | F27: 45832
B28: H13 6.20 | C28: m3 | D28: 115100 | E28: FENOMIX | F28: 45785
B29: Acarreo | C29: gl | D29: 533000 | E29: FENOMIX | F29: 45832
B30: Bombeo | C30: m3 | D30: 5330 | E30: FENOMIX | F30: 45832
B31: Super | C31: m3 | D31: 1500 | E31: FENOMIX | F31: 45832
B32: Hidrofugo
B33: HIERRO CONSTRUCCION
B34: Hierro del 6 | C34: kg | D34: 1769.41 | E34: NUQLEA | F34: 45800 | H34: =+D34/D41 -> 1.3216487
B35: Hierro del 8 | C35: kg | D35: 1641.01 | E35: NUQLEA | F35: 45800 | H35: =+D35/D42 -> 1.2605797
B36: Hierro del 10 | C36: kg | D36: 1610.19 | E36: NUQLEA | F36: 45800 | H36: =+D36/D43 -> 1.2369046
B37: Hierro del 12 | C37: kg | D37: 1569.1 | E37: NUQLEA | F37: 45800 | H37: =+D37/D44 -> 1.2136752
B38: Hierro del 16 | C38: kg | D38: 1537 | E38: NUQLEA | F38: 45800 | H38: =+D38/D45 -> 1.203687
B39: Hierro del 20 | C39: kg | D39: 1526.73 | E39: NUQLEA | F39: 45800 | H39: =+D39/D46 -> 1.1956442
B40: Hierro del 25 | C40: kg | D40: 1526.73 | E40: NUQLEA | F40: 45800 | H40: =+D40/D47 -> 1.1956442
...

Sheet SUBCONTRATOS
J2: 10331 | K2: 45292 | M2: DÓLAR BNA | N2: DÓLAR MEP
B3: Descripcion | C3: Un | D3: Precio | E3: Fecha | F3: Contratista | H3: Pres. BASE ENE | J3: 16253.5 | K3: 45748 | M3: =+GGBB!G4 -> 1280 | N3: =+GGBB!H4 -> 1276
B4: GESTOR ELECTRICO | J4: =+J3/J2 -> 1.5732746 | K4: CAC
B5: Proyecto instalacion electrica | C5: gl | D5: =+H5*$J$4 -> 1274352.4 | E5: 45748 | F5: IGT | H5: 810000 | I5: 45356
B6: Baja de suministros | C6: gl | D6: =+H6*$J$4 -> 51918.062 | E6: 45749 | F6: IGT | H6: 33000 | I6: 45356
B7: Corte por demolicion | C7: gl | D7: =+H7*$J$4 -> 116422.32 | E7: 45750 | F7: IGT | H7: 74000 | I7: 45356
B8: Instalacion electrica desenergizada | C8: gl | D8: =+H8*$J$4 -> 143167.99 | E8: 45751 | F8: IGT | H8: 91000 | I8: 45356
B9: Traslado de alumbrado publico | C9: gl | D9: =+H9*$J$4 -> 121142.15 | E9: 45752 | F9: IGT | H9: 77000 | I9: 45356
B10: Factibilidad y renovacion | C10: gl | D10: =+H10*$J$4 -> 259590.31 | E10: 45753 | F10: IGT | H10: 165000 | I10: 45356
B11: Gestion suministros luz de obra | C11: gl | D11: =+H11*$J$4 -> 157327.46 | E11: 45754 | F11: IGT | H11: 100000 | I11: 45356
B12: Sala de medidores / Camara transformadora | C12: gl | D12: =+H12*$J$4 -> 550646.11 | E12: 45755 | F12: IGT | H12: 350000 | I12: 45356
B13: Certificados
B14: Luz de Obra | C14: u | D14: =+H14*$J$4 -> 113275.77 | E14: 45757 | F14: IGT | H14: 72000 | I14: 45356
B15: Servicios grales T1 | C15: u | D15: =+H15*$J$4 -> 113275.77 | E15: 45758 | F15: IGT | H15: 72000 | I15: 45356
B16: Servicios grales T2 | C16: u | D16: =+H16*$J$4 -> 166767.11 | E16: 45759 | F16: IGT | H16: 106000 | I16: 45356
B17: Residencial | C17: u | D17: =+H17*$J$4 -> 78663.731 | E17: 45760 | F17: IGT | H17: 50000 | I17: 45356
B18: Medicion PAT luz de obra | C18: u | D18: =+H18*$J$4 -> 99116.3 | E18: 45761 | F18: IGT | H18: 63000 | I18: 45356
B19: Medicion PAT adicional c/u tableros | C19: u | D19: =+H19*$J$4 -> 49558.15 | E19: 45762 | F19: IGT | H19: 31500 | I19: 45356
B20: ENSAYOS HORMIGON
B21: Ensayo probeta 15 x 30 x un | C21: gl | D21: =(38800+(22000/2))/1.21 -> 41157.025 | E21: 45756 | F21: INTI
B22: MOVIMIENTO DE SUELOS | I22: M.O Ago-24 | J22: 10084.9
B23: Excavación por m3 | C23: m3 | D23: 19500 | E23: 45783 | F23: CELSI VIAL | I23: M.O. Abr 25 | J23: 12755.3 | L23: 0.665 | M23: Cargas
B24: Desmonte y aporte de tosca | C24: m2 | D24: =+H24/600 -> 21120 | E24: 45790 | F24: CELSI VIAL | G24: Polo Palermo (600 m2) | H24: 12672000 | J24: =+J23/J22+K24 -> 1.3447919 | K24: 0.08 | L24: 0.9 | M24: Subcontrato
B25: Desmonte y aporte de tosca | C25: m2 | D25: =+H25/180 -> 23552.222 | E25: 45652 | F25: CELSI VIAL | G25: VL 572 (180 m2) | H25: =3854000*1.1 -> 4239400
B26: Maquina 6 tn | C26: d | D26: 528000 | E26: 45833 | F26: CELSI VIAL
B27: Viaje camión | C27: d | D27: 140000 | E27: 45833 | F27: CELSI VIAL
B28: Traslado de maquina | C28: u | D28: 80000 | E28: 45833 | F28: CELSI VIAL
B29: PROYECTABLE | H29: Base Agosto 24 | L29: Cargas sociales
B30: Monolitico | C30: m2 | D30: =+L30 -> 9100.0957 | E30: 45748 | F30: JUAN VAZQUEZ | H30: 4500 | I30: 45510 | J30: =+H30*$J$24 -> 6051.5636 | L30: =+J30/$L$23 -> 9100.0957
B31: Alivianado | C31: m2 | D31: =+L31 -> 8088.9739 | E31: 45748 | F31: JUAN VAZQUEZ | H31: 4000 | I31: 45510 | J31: =+H31*$J$24 -> 5379.1677 | L31: =+J31/$L$23 -> 8088.9739
B32: Yeso | C32: m2 | D32: =+L32 -> 12252.549 | E32: 45748 | F32: JUAN VAZQUEZ | H32: 8200 | I32: 45510 | J32: =+H32*$J$24 -> 11027.294 | L32: =+J32/$L$24 -> 12252.549
B33: Arista / Buña | C33: ml | D33: =+L33 -> 13144.583 | E33: 45748 | F33: JUAN VAZQUEZ | H33: 6500 | I33: 45510 | J33: =+H33*$J$24 -> 8741.1475 | L33: =+J33/$L$23 -> 13144.583
B34: Cantonera | C34: u | D34: =+L34 -> 13144.583 | E34: 45748 | F34: JUAN VAZQUEZ | H34: 6500 | I34: 45510 | J34: =+H34*$J$24 -> 8741.1475 | L34: =+J34/$L$23 -> 13144.583
B35: Revoque 3 en 1 | C35: m2 | D35: =+L35 -> 22244.678 | E35: 45748 | F35: JUAN VAZQUEZ | H35: 11000 | I35: 45510 | J35: =+H35*$J$24 -> 14792.711 | L35: =+J35/$L$23 -> 22244.678
B36: Buña en revoque | C36: ml | D36: =+L36 -> 11122.339 | E36: 45748 | F36: JUAN VAZQUEZ | H36: 5500 | I36: 45510 | J36: =+H36*$J$24 -> 7396.3555 | L36: =+J36/$L$23 -> 11122.339
B37: TARQUINI
B38: Revestimiento plastico | C38: m2 | D38: =+L38 -> 10111.217 | E38: 45748 | F38: CRISTIAN CAPONE | H38: 5000 | I38: 45510 | J38: =+H38*$J$24 -> 6723.9596 | L38: =+J38/$L$23 -> 10111.217
B39: Revestimiento plastico | C39: m2 | D39: =+L39 -> 14155.704 | E39: 45748 | F39: CRISTIAN CAPONE | G39: 15% plus altura + 25% menor rendimiento | H39: =+H38*1.4 -> 7000 | I39: 45510 | J39: =+H39*$J$24 -> 9413.5434 | L39: =+J39/$L$23 -> 14155.704 | M39: 15% plus altura + 25% menor rendimiento
B40: AA.CC - PREINSTALACIONES | G40: 40
B41: Preinstalacion MAT | C41: u | D41: =+G41/$G$40 -> 247500 | E41: 45840 | F41: GUILLERMO ERBA | G41: 9900000
...

Sheet APU 06.25
A1: , | K1: Mes: | L1: JUNIO
K2: Año: | L2: 2025
K3: Revisado: | L3: MC
C5: ANALISIS DE PRECIO UNITARIO
C7: RESUMEN
E8: PRECIO UNITARIO
E9: Unitario Materiales: | H9: Unitario Mano de Obra: | K9: Unitario Equipos: | M9: RENDIMIENTO
A10: CODIGO | B10: PARTIDA | C10: DETALLE | E10: MAT | H10: MO | K10: EQUIPOS | L10: TOTAL | M10: u/dia
B11: 32 | C11: Movimiento de suelos para bases c/ aporte de tosca (e: 40 cm en 2 capas de 20 cm) | D11: m3 | E11: 12754.673 | H11: 6652.371 | K11: 40200 | L11: =+SUM(E11:K11) -> 59607.044 | M11: 25
A12: ARQUIN21 | B12: 33 | C12: Ladrillo común 12,5 x 5,5 x 25 (e:15 cm) | D12: m2 | E12: 14000.877 | H12: 23059.662 | K12: 548.10112 | L12: =+SUM(E12:K12) -> 37608.641 | M12: 7
A13: ARQUIN21 | B13: 34 | C13: Ladrillo cerámico 8 x 18 x 33 cm | D13: m2 | E13: 10053.788 | H13: 10761.176 | K13: 255.78052 | L13: =+SUM(E13:K13) -> 21070.744 | M13: 15
A14: ARQUIN21 | B14: 35 | C14: Ladrillo cerámico 12 x 18 x 33 cm | D14: m2 | E14: 12465.038 | H14: 10761.176 | K14: 255.78052 | L14: =+SUM(E14:K14) -> 23481.994 | M14: 15
A15: ARQUIN21 | B15: 36 | C15: Ladrillo cerámico 18 x 18 x 33 cm | D15: m2 | E15: 17538.995 | H15: 10761.176 | K15: 255.78052 | L15: =+SUM(E15:K15) -> 28555.952 | M15: 15
A16: ARQUIN21 | B16: 37 | C16: Pared DOBLE Comun / 5 / LHC 08 - (ladrillo a la vista) | D16: m2 | E16: 31798.204 | H16: 38841.498 | K16: 959.17696 | L16: =+SUM(E16:K16) -> 71598.879 | M16: 4
A17: ARQUIN21 | B17: 38 | C17: Ladrillo hueco portante 12 x 19 x 33 | D17: m2 | E17: 18207.26 | H17: 10761.176 | K17: 255.78052 | L17: =+SUM(E17:K17) -> 29224.217 | M17: 15
A18: ARQUIN21 | B18: 39 | C18: Amure puertas tipo (0,90 x 2,00 m) | D18: u | E18: 4104.3832 | H18: 60531.614 | K18: 440.78781 | L18: =+SUM(E18:K18) -> 65076.785 | M18: 2
A19: ARQUIN21 | B19: 40 | C19: Amure Premarcos | D19: u | E19: 1501.8311 | H19: 40354.409 | K19: 220.3939 | L19: =+SUM(E19:K19) -> 42076.634 | M19: 4
A20: ARQUIN21 | B20: 41 | C20: Amure barandas (insertos c/1,00 m) | D20: ml | E20: 310.90703 | H20: 32283.527 | K20: 300.60867 | L20: =+SUM(E20:K20) -> 32895.043 | M20: 5
A21: ARQUIN21 | B21: 42 | C21: Azotado hidrófugo | D21: m2 | E21: 827.27861 | H21: 4324.0478 | K21: 137.02528 | L21: =+SUM(E21:K21) -> 5288.3517 | M21: 28
A22: ARQUIN21 | B22: 43 | C22: Interior jaharro a la cal + Enlucido a la cal | D22: m2 | E22: 2891.2175 | H22: 22980.577 | K22: 639.45131 | L22: =+SUM(E22:K22) -> 26511.246 | M22: 6
A23: ARQUIN21 | B23: 44 | C23: Revoque Grueso impermeable Exterior hasta 3.00 m - Incl. Azotado hidrófugo | D23: m2 | E23: 4061.1651 | H23: 11697.516 | K23: 333.62677 | L23: =+SUM(E23:K23) -> 16092.308 | M23: 11.5
... A28: ARQUIN21 | B28: 49 | C28: Carpeta hidrófuga (e: 2 cm) | D28: m2 | E28: 4136.3931 | H28: 8295.6908 | K28: 235.08683 | L28: =+SUM(E28:K28) -> 12667.171 | M28: 15
A29: ARQUIN21 | B29: 50 | C29: Cemento alisado o cilindrado (e: 3 cm) | D29: m2 | E29: 4104.3832 | H29: 11112.816 | K29: 306.635 | L29: =+SUM(E29:K29) -> 15523.834 | M29: 11.5 | U29: perim | V29: h
A30: ARQUIN21 | B30: 51 | C30: Látex interior para paredes (incl. enduido) | D30: m2 | E30: 4251.3982 | H30: 8379.1959 | K30: 190.09545 | L30: =+SUM(E30:K30) -> 12820.69 | M30: 22 | Q30: Living | R30: 8 | S30: 4 | T30: =+R30*S30 -> 32 | U30: =+R30*2+S30*2 -> 24 | V30: 4.5 | W30: =+U30*V30 -> 108
A31: ARQUIN21 | B31: 52 | C31: látex para cielorrasos (incl. enduido) | D31: m2 | E31: 4251.3982 | H31: 9503.3872 | K31: 262.01469 | L31: =+SUM(E31:K31) -> 14016.8 | M31: 17.5 | Q31: Cocina | R31: 3 | S31: 5 | T31: =+R31*S31 -> 15 | U31: =+R31*2+S31*2 -> 16 | V31: 1 | W31: =+U31*V31 -> 16
A32: ARQUIN21 | B32: 53 | C32: látex exterior para paredes hasta 3.00 m de altura | D32: m2 | E32: 2901.8567 | H32: 6075.9444 | K32: 134.90645 | L32: =+SUM(E32:K32) -> 9112.7075 | M32: 15.5 | Q32: Dormitori | R32: 6 | S32: 4 | T32: =+R32*S32 -> 24 | U32: =+R32*2+S32*2 -> 20 | V32: 4.5 | W32: =+U32*V32 -> 90
A33: ARQUIN22 | B33: 53 bis | C33: látex exterior para paredes a más 3.00 m de altura | D33: m2 | E33: 2901.8567 | H33: 15936.651 | K33: 254.81362 | L33: =+SUM(E33:K33) -> 19093.322 | M33: 15.5 | Q33: Dormitori | R33: 3 | S33: 4 | T33: =+R33*S33 -> 12 | U33: =+R33*2+S33*2 -> 14 | V33: 2 | W33: =+U33*V33 -> 28
A34: ARQUIN21 | B34: 54 | C34: Esmalte sintético sobre carpintería metálica , herrería (cuando es vacio x lleno contemplar MAT al 60%) | D34: m2 | E34: 4460.7312 | H34: 11772.142 | K34: 261.38124 | L34: =+SUM(E34:K34) -> 16494.255 | M34: 8 | Q34: Baño | R34: 3 | S34: 2 | T34: =+R34*S34 -> 6 | U34: =+R34*2+S34*2 -> 10 | V34: 1 | W34: =+U34*V34 -> 10 | Z34: =+Z36*1.35 -> 6356.9568
A35: ARQUIN21 | B35: 55 | C35: Revestimiento plastico texturado tipo Quimtex fino | D35: m2 | E35: 6929.178 | H35: 12350.905 | K35: 197.48055 | L35: =+SUM(E35:K35) -> 19477.563 | M35: 20 | Q35: Baño | R35: 1.5 | S35: 2 | T35: =+R35*S35 -> 3 | U35: =+R35*2+S35*2 -> 7 | V35: 1 | W35: =+U35*V35 -> 7
A36: ARQUIN21 | B36: 56 | C36: Colocación porcelanato en pisos (no incluye baños) | D36: m2 | E36: 6932.2708 | H36: 12793.021 | K36: 245.43421 | L36: =+SUM(E36:K36) -> 19970.726 | M36: 13 | T36: =+SUM(T30:T35) -> 92 | W36: =+SUM(W30:W35) -> 259 | Y36: =+T36+W36 -> 351 | Z36: =+H80 -> 4708.8569 | AA36: =+Y36*Z36 -> 1652808.8
A37: ARQUIN21 | B37: 57 | C37: Revestimiento porcelanato en paredes y piso baños | D37: m2 | E37: 6932.2708 | H37: 16630.928 | K37: 319.06447 | L37: =+SUM(E37:K37) -> 23882.263 | M37: 10 | Y37: =+Y36 -> 351 | Z37: 2126.0865 | AA37: =+Y37*Z37 -> 746256.36
A38: ARQUIN21 | B38: 58 | C38: Colocacion de zocalo porcelanato | D38: ml | E38: 1001.4972 | H38: 5543.6425 | K38: 106.35482 | L38: =+SUM(E38:K38) -> 6651.4946 | M38: 30
A39: ARQUIN22 | B39: 59 | C39: Látex interior satinado para paredes | D39: m2 | E39: 6691.9788 | H39: 15119.025 | K39: 360.40421 | L39: =+SUM(E39:K39) -> 22171.408 | M39: 11 | AA39: =+AA36+AA37 -> 2399065.1
A40: ARQUIN23 | B40: 60 | C40: Cielorraso Durlock - Junta Tomada STD | D40: m2 | E40: 10667.045 | H40: 17506.24 | K40: 286.64634 | L40: =+SUM(E40:K40) -> 28459.931 | M40: 9.5
A41: ARQUIN24 | B41: 61 | C41: Cielorraso Durlock - Junta Tomada RH | D41: m2 | E41: 14748.7 | H41: 17506.24 | K41: 286.64634 | L41: =+SUM(E41:K41) -> 32541.586 | M41: 9.5
A42: ARQUIN25 | B42: 62 | C42: Cielorraso Durlock - Junta Tomada RF | D42: m2 | E42: 13947.896 | H42: 17506.24 | K42: 286.64634 | L42: =+SUM(E42:K42) -> 31740.781 | M42: 9.5
A43: ARQUIN26 | B43: 63 | C43: Cielorraso Desmontable 60x60 - sin provision | D43: m2 | E43: 6636.1994 | H43: 16630.928 | K43: 272.31402 | L43: =+SUM(E43:K43) -> 23539.441 | M43: 10
B44: 63 bis | C44: Cielorraso Desmontable 60x60 - incluye placa Deco Vinyl | D44: m2 | E44: 33199.927 | H44: 16630.928 | K44: 272.31402 | L44: =+SUM(E44:K44) -> 50103.169 | M44: 10
A45: ARQUIN27 | B45: 64 | C45: Pared Durlock - Simple | D45: m2 | E45: 16393.937 | H45: 23758.468 | K45: 378.13572 | L45: =+SUM(E45:K45) -> 40530.54 | M45: 7
A46: ARQUIN28 | B46: 65 | C46: Pared Durlock - Doble placa STD ambas caras y asilación lana de vidrio | D46: m2 | E46: 28944.105 | H46: 27718.213 | K46: 441.15834 | L46: =+SUM(E46:K46) -> 57103.476 | M46: 6
...

Sheet P.MO 06.25
A1: COSTO M.O. | B1: 45809 | F1: Carga Manual
A3: Costo Real (B+N) | B3: Jornal | C3: Mensual | D3: Hora | E3: Dif real / teorico | F3: Mano Jornal | G3: Hora Uocra
A4: ESPECIALIZADO | B4: 94177.138 | C4: 2260251.3 | D4: 11772.142 | E4: 1.1585236 | F4: 59355.621 | G4: 5121.2727 | I4: =+B4/F4 -> 1.5866591
A5: OFICIAL | B5: 84612.513 | C5: 2030700.3 | D5: 10576.564 | E5: 1.1076363 | F5: 51821.351 | G5: 4402.9091 | I5: =+B5/F5 -> 1.6327732
A6: MEDIO OFICIAL | B6: 72132.138 | C6: 1731171.3 | D6: 9016.5173 | E6: 1.0989982 | F6: 43355.923 | G6: 4062.1818 | I6: =+B6/F6 -> 1.6637205
A7: AYUDANTE | B7: 67240.499 | C7: 1613772 | D7: 8405.0624 | E7: 1.1023505 | F7: 40254.783 | G7: 3748.5 | I7: =+B7/F7 -> 1.6703729
A9: SOBRESTANTE | B9: 147568.59 | C9: 3246508.9 | D9: 18446.073 | F9: 2265320.2
A10: JEFE DE OBRA | B10: 214394.06 | C10: 4716669.4 | D10: 26799.258 | F10: 3290107.9
A11: COORD OBRAS | B11: 258581.93 | C11: 5688802.4 | D11: 32322.741 | F11: 4314895.6
A12: CAPATAZ | B12: 161430.42 | C12: 3874330.1 | D12: 20178.803 | F12: 2804682.1 | G12: 5121.2727

Sheet INFO.
C2: USD | F2: DÓLAR MEP
B3: VALOR ESTIMADO REFERENCIA COSTO | F3: =+GGBB!H4 -> 1276 | G3: =+F6/F3 -> 1460381.2
D4: Coef Complej
C5: m2 | D5: 1 | E5: USD/ m2
B6: SUPERFICIE CUBIERTA | C6: =+ROUNDUP(F20,0) -> 1452 | D6: =+C3*D5 -> 0 | E6: =+F32 -> 1005.7722 | F6: =+E6*F3*C6 -> 1.8634464e+09 | G6: Valor estimado precio de venta
B8: Lote | E8: 1 | F8: SS
B9: Pisada | E9: 0.25 | F9: Patios
E10: 0.5 | F10: Balcones y semicubiertos
B11: Superficie | C11: Cubierto | D11: Semicubierto | E11: % | F11: Subtotal
B12: SS | C12: 24 | E12: =+D12*$E$8 -> 0 | F12: =+C12+E12 -> 24
B13: PB | C13: 65 | D13: 137 | E13: =+D13*$E$10 -> 68.5 | F13: =+C13+E13 -> 133.5
B14: PB (patio) | D14: 51.5 | E14: =+D14*$E$9 -> 12.875 | F14: =+C14+E14 -> 12.875
B15: P 1º a 5° | C15: 175 | D15: =11+10.5 -> 21.5 | E15: =+D15*$E$10 -> 10.75 | F15: =+C15+E15 -> 185.75 | G15: 4
C16: =+C15*G15 -> 700 | D16: =+D15*G15 -> 86 | E16: =+E15*G15 -> 43 | F16: =+C16+E16 -> 743
B17: P 6° | C17: 160 | D17: =11+16 -> 27 | E17: =+D17*$E$10 -> 13.5 | F17: =+C17+E17 -> 173.5
B18: P 7° | C18: 111 | D18: =32+16 -> 48 | E18: =+D18*$E$10 -> 24 | F18: =+C18+E18 -> 135
B19: PLANTA TECHOS | C19: 22 | D19: 89 | E19: =+D19*$E$9 -> 22.25 | F19: =+C19+E19 -> 44.25
C20: =SUM(C12:C19) -> 1257 | D20: =SUM(D12:D19) -> 460 | E20: =SUM(E12:E19) -> 194.875 | F20: =SUM(F12:F19) -> 1451.875
H21: usd/m2
B22: OBRA CIVIL | E22: 0.7 | F22: =+'01'!W213 -> 1540618531 | G22: =+F22/F3 -> 1207381.3 | H22: =+G22/C6 -> 831.52982
B23: PROVISIONES | E23: =1-E22 -> 0.3 | F23: =+G23*F22 -> 6.6026508e+08 | G23: =+E23/E22 -> 0.42857143
F24: =+F23+F22 -> 2.2008836e+09
B25: ARQ CLARIN
B26: 45800 | C26: Fecha
B28: (se toma MODELO 6 Vivienda en altura) | C28: m2 | D28: $/ m2
B29: VALOR ESTIMADO REFERENCIA COSTO | C29: =+C6 -> 1452 | D29: 1833379 | F29: =+D29*C29 -> 2662066308 | G29: Valor estimado precio de venta
D30: usd/m2 | F30: =+F29/F3 -> 2086258.9 | G30: USD
D31: =+D29/F3 -> 1436.8174 | F31: =+F30/C29 -> 1436.8174 | G31: usd/m2
F32: =+F31*E22 -> 1005.7722 | G32: usd/m2 sin provisiones

Sheet 01
F1: OK | G1: Listo | V1: DÓLAR BNA | W1: DÓLAR MEP
F2: IN | G2: Estimado | V2: =+GGBB!G4 -> 1280 | W2: =+GGBB!H4 -> 1276
F3: C | G3: Chekear (Inventado)
F4: R | G4: Sin hacer/revisar | V4: 45817
C5: OBRA: EDIFICIO CHIVILCOY 2171 | F5: MATERIAL | I5: M. DE OBRA | N5: MATERIAL | P5: M. DE OBRA | T5: =+GGBB!F61 -> 1.3564677
C6: PRESUPUESTO OBRA CIVIL | T6: 1.1
B7: E | C7: Descripción | D7: U | E7: Cant | F7: Otro | G7: Corralón | H7: Total | I7: Otro | J7: Albañil | K7: Total | L7: EQUIPOS | M7: P.Unit | N7: Otro | O7: Corralón | P7: Otro | Q7: Albañil | R7: EQUIPOS | S7: Total | T7: Subtotal | U7: P unit | V7: Subtotal
A8: 1 | C8: TAREAS PRELIMINARES | T8: =SUM(S9:S17) -> 17207623 | W8: =SUM(V9:V17) -> 23341592 | X8: =+W8/$W$213 -> 0.015150793
A9: 1.01 | B9: OK | C9: Limpieza y preparación del terreno - No cotiza | D9: gl | E9: 0 | H9: =F9+G9 -> 0 | K9: =I9+J9 -> 0 | M9: =H9+K9+L9 -> 0 | N9: =F9*E9 -> 0 | O9: =G9*E9 -> 0 | P9: =I9*E9 -> 0 | Q9: =J9*E9 -> 0 | R9: =+L9*E9 -> 0 | S9: =SUM(N9:R9) -> 0 | U9: =+ROUNDUP(M9*$T$5,0) -> 0 | V9: =+U9*E9 -> 0
A10: 1.02 | B10: OK | C10: Topógrafo - Visita de obra replanteo | D10: un | E10: 4 | F10: =+Tareas!H8 -> 0 | G10: =+Tareas!I8 -> 25000 | H10: =F10+G10 -> 25000 | I10: =+Tareas!Q8 -> 214394.06 | J10: =+Tareas!R8 -> 67240.499 | K10: =I10+J10 -> 281634.56 | L10: =+(H10+K10)*0.015 -> 4599.5184 | M10: =H10+K10+L10 -> 311234.08 | N10: =F10*E10 -> 0 | O10: =G10*E10 -> 100000 | P10: =I10*E10 -> 857576.25 | Q10: =J10*E10 -> 268962 | R10: =+L10*E10 -> 18398.074 | S10: =SUM(N10:R10) -> 1244936.3 | U10: =+ROUNDUP(M10*$T$5,0) -> 422179 | V10: =+U10*E10 -> 1688716
A11: 1.03 | B11: OK | C11: Cartel de Obra - No cotiza | D11: gl | E11: 1 | H11: =F11+G11 -> 0 | K11: =I11+J11 -> 0 | M11: =H11+K11+L11 -> 0 | N11: =F11*E11 -> 0 | O11: =G11*E11 -> 0 | P11: =I11*E11 -> 0 | Q11: =J11*E11 -> 0 | R11: =+L11*E11 -> 0 | S11: =SUM(N11:R11) -> 0 | U11: =+ROUNDUP(M11*$T$5,0) -> 0 | V11: =+U11*E11 -> 0
A12: 1.04 | B12: OK | C12: Cerco de obra perimetral - En chapa C25 + Concertina + Porton corredizo | D12: ml | E12: 10 | F12: =+Tareas!H12 -> 98815.568 | G12: =+Tareas!I12 -> 0 | H12: =F12+G12 -> 98815.568 | I12: =+Tareas!Q12 -> 0 | J12: =+Tareas!R12 -> 111992.57 | K12: =I12+J12 -> 111992.57 | L12: =+(H12+K12)*0.015 -> 3162.1221 | M12: =H12+K12+L12 -> 213970.27 | N12: =F12*E12 -> 988155.68 | O12: =G12*E12 -> 0 | P12: =I12*E12 -> 0 | Q12: =J12*E12 -> 1119925.7 | R12: =+L12*E12 -> 31621.221 | S12: =SUM(N12:R12) -> 2139702.7 | U12: =+ROUNDUP(M12*$T$5,0) -> 290244 | V12: =+U12*E12 -> 2902440
A13: 1.05 | B13: OK | C13: Obrador, pañol y ducha | D13: gl | E13: 1 | F13: =+Tareas!H23 -> 2270625.2 | G13: =+Tareas!I23 -> 300000 | H13: =F13+G13 -> 2570625.2 | I13: =+Tareas!Q23 -> 1000000 | J13: =+Tareas!R23 -> 5023936.4 | K13: =I13+J13 -> 6023936.4 | L13: =+(H13+K13)*0.015 -> 128918.42 | M13: =H13+K13+L13 -> 8723480 | N13: =F13*E13 -> 2270625.2 | O13: =G13*E13 -> 300000 | P13: =I13*E13 -> 1000000 | Q13: =J13*E13 -> 5023936.4 | R13: =+L13*E13 -> 128918.42 | S13: =SUM(N13:R13) -> 8723480 | U13: =+ROUNDUP(M13*$T$5,0) -> 11833120 | V13: =+U13*E13 -> 11833120
A14: 1.06 | B14: OK | C14: Alquiler de baños quimicos y duchas portatiles | D14: mes | E14: 4 | F14: =+Tareas!H47 -> 0 | G14: =+Tareas!I47 -> 0 | H14: =F14+G14 -> 0 | I14: =+Tareas!Q47 -> 260000 | J14: =+Tareas!R47 -> 0 | K14: =I14+J14 -> 260000 | M14: =H14+K14+L14 -> 260000 | N14: =F14*E14 -> 0 | O14: =G14*E14 -> 0 | P14: =I14*E14 -> 1040000 | Q14: =J14*E14 -> 0 | R14: =+L14*E14 -> 0 | S14: =SUM(N14:R14) -> 1040000 | U14: =+ROUNDUP(M14*$T$5,0) -> 352682 | V14: =+U14*E14 -> 1410728
A15: 1.07 | B15: OK | C15: Conexión pilar y luz de obra + Tablero de obra | D15: gl | E15: 1 | F15: =+Tareas!H52 -> 1290000 | G15: =+Tareas!I52 -> 100000 | H15: =F15+G15 -> 1390000 | I15: =+Tareas!Q52 -> 0 | J15: =+Tareas!R52 -> 661285.32 | K15: =I15+J15 -> 661285.32 | L15: =+(H15+K15)*0.015 -> 30769.28 | M15: =H15+K15+L15 -> 2082054.6 | N15: =F15*E15 -> 1290000 | O15: =G15*E15 -> 100000 | P15: =I15*E15 -> 0 | Q15: =J15*E15 -> 661285.32 | R15: =+L15*E15 -> 30769.28 | S15: =SUM(N15:R15) -> 2082054.6 | U15: =+ROUNDUP(M15*$T$5,0) -> 2824240 | V15: =+U15*E15 -> 2824240
A16: 1.08 | B16: OK | C16: Conexión agua de obra, tanque + bomba | D16: gl | E16: 1 | F16: =+Tareas!H59 -> 936000 | G16: =+Tareas!I59 -> 0 | H16: =F16+G16 -> 936000 | I16: =+Tareas!Q59 -> 0 | J16: =+Tareas!R59 -> 536368.95 | K16: =I16+J16 -> 536368.95 | L16: =+(H16+K16)*0.015 -> 22085.534 | M16: =H16+K16+L16 -> 1494454.5 | N16: =F16*E16 -> 936000 | O16: =G16*E16 -> 0 | P16: =I16*E16 -> 0 | Q16: =J16*E16 -> 536368.95 | R16: =+L16*E16 -> 22085.534 | S16: =SUM(N16:R16) -> 1494454.5 | U16: =+ROUNDUP(M16*$T$5,0) -> 2027180 | V16: =+U16*E16 -> 2027180
A17: 1.09 | B17: OK | C17: Tramite luz de obra, certificado luz de obra (2) y medición PAT | D17: gl | E17: 1 | F17: =+Tareas!H69 -> 0 | G17: =+Tareas!I69 -> 0 | H17: =F17+G17 -> 0 | I17: =+Tareas!Q69 -> 482995.31 | J17: =+Tareas!R69 -> 0 | K17: =I17+J17 -> 482995.31 | M17: =H17+K17+L17 -> 482995.31 | N17: =F17*E17 -> 0 | O17: =G17*E17 -> 0 | P17: =I17*E17 -> 482995.31 | Q17: =J17*E17 -> 0 | R17: =+L17*E17 -> 0 | S17: =SUM(N17:R17) -> 482995.31 | U17: =+ROUNDUP(M17*$T$5,0) -> 655168 | V17: =+U17*E17 -> 655168
A18: 2 | C18: MOVIMIENTO DE TIERRA, COMPACTACION Y RELLENO | T18: =SUM(S19:S22) -> 12400628 | W18: =SUM(V19:V22) -> 16821282 | X18: =+W18/$W$213 -> 0.010918525
A19: 2.01 | B19: OK | C19: Retiro de suelo vegetal e: 50 cm, aporte y compactación de tosca e: 40 cm (dos capas de 20 cm) | D19: m2 | E19: =+Exc.!G53 -> 219 | F19: =+Tareas!H74 -> 0 | G19: =+Tareas!I74 -> 0 | H19: =F19+G19 -> 0 | I19: =+Tareas!Q74 -> 25907.444 | J19: =+Tareas!R74 -> 3070.3424 | K19: =I19+J19 -> 28977.787 | M19: =H19+K19+L19 -> 28977.787 | N19: =F19*E19 -> 0 | O19: =G19*E19 -> 0 | P19: =I19*E19 -> 5673730.3 | Q19: =J19*E19 -> 672404.99 | R19: =+L19*E19 -> 0 | S19: =SUM(N19:R19) -> 6346135.3 | U19: =+ROUNDUP(M19*$T$5,0) -> 39308 | V19: =+U19*E19 -> 8608452
A20: 2.02 | B20: OK | C20: Excavación para cámara transformadora | D20: m3 | E20: =+Exc.!I6 -> 100 | F20: =+Tareas!H77 -> 0 | G20: =+Tareas!I77 -> 0 | H20: =F20+G20 -> 0 | I20: =+Tareas!Q77 -> 24440 | J20: =+Tareas!R77 -> 6724.0499 | K20: =I20+J20 -> 31164.05 | L20: =+(H20+K20)*0.015 -> 467.46075 | M20: =H20+K20+L20 -> 31631.511 | N20: =F20*E20 -> 0 | O20: =G20*E20 -> 0 | P20: =I20*E20 -> 2444000 | Q20: =J20*E20 -> 672404.99 | R20: =+L20*E20 -> 46746.075 | S20: =SUM(N20:R20) -> 3163151.1 | U20: =+ROUNDUP(M20*$T$5,0) -> 42908 | V20: =+U20*E20 -> 4290800
A21: 2.03 | B21: OK | C21: Excavación manual para tensores y vigas de fundación | D21: m3 | E21: =+Exc.!I8 -> 43 | H21: =F21+G21 -> 0 | J21: =+'P.MO 06.25'!B7 -> 67240.499 | K21: =I21+J21 -> 67240.499 | M21: =H21+K21+L21 -> 67240.499 | N21: =F21*E21 -> 0 | O21: =G21*E21 -> 0 | P21: =I21*E21 -> 0 | Q21: =J21*E21 -> 2891341.5 | R21: =+L21*E21 -> 0 | S21: =SUM(N21:R21) -> 2891341.5 | U21: =+ROUNDUP(M21*$T$5,0) -> 91210 | V21: =+U21*E21 -> 3922030
A22: 2.04 | B22: OK | C22: Demolición y retiro de fundaciones existentes - No cotiza | D22: gl | E22: 0 | H22: =F22+G22 -> 0 | K22: =I22+J22 -> 0 | M22: =H22+K22+L22 -> 0 | N22: =F22*E22 -> 0 | O22: =G22*E22 -> 0 | P22: =I22*E22 -> 0 | Q22: =J22*E22 -> 0 | R22: =+L22*E22 -> 0 | S22: =SUM(N22:R22) -> 0 | U22: =+ROUNDUP(M22*$T$5,0) -> 0 | V22: =+U22*E22 -> 0
A23: 3 | C23: ESTRUCTURA RESISTENTE | T23: =SUM(S24:S45) -> 3.3368577e+08 | W23: =SUM(V24:V45) -> 452634152 | X23: =+W23/$W$213 -> 0.29380028 | Y23: M.O HA | Z23: =+SUM(P24:R41,Q19:R21)-P25 -> 1.3371847e+08
A24: 3.01 | B24: OK | C24: Hormigón de limpieza - e: 10 cm | D24: m3 | E24: 3 | F24: =+Tareas!H83 -> 120430 | G24: =+Tareas!I83 -> 0 | H24: =F24+G24 -> 120430 | I24: =+Tareas!Q83 -> 0 | J24: =+Tareas!R83 -> 155041.22 | K24: =I24+J24 -> 155041.22 | L24: =+(H24+K24)*0.015 -> 4132.0683 | M24: =H24+K24+L24 -> 279603.29 | N24: =F24*E24 -> 361290 | O24: =G24*E24 -> 0 | P24: =I24*E24 -> 0 | Q24: =J24*E24 -> 465123.66 | R24: =+L24*E24 -> 12396.205 | S24: =SUM(N24:R24) -> 838809.86 | U24: =+ROUNDUP(M24*$T$5,0) -> 379273 | V24: =+U24*E24 -> 1137819 | Y24: S/cargas | Z24: =+Z23/AA24 -> 83574041 | AA24: 1.6
A25: 3.02 | B25: OK | C25: Micropilotes Ø 20 cm | D25: gl | E25: 1 | F25: =+Tareas!H88 -> 11090041 | G25: =+Tareas!I88 -> 0 | H25: =F25+G25 -> 11090041 | I25: =+Tareas!Q88 -> 34350000 | J25: =+Tareas!R88 -> 2460301.5 | K25: =I25+J25 -> 36810301 | L25: =+(H25+K25)*0.015 -> 718505.14 | M25: =H25+K25+L25 -> 48618848 | N25: =F25*E25 -> 11090041 | O25: =G25*E25 -> 0 | P25: =I25*E25 -> 34350000 | Q25: =J25*E25 -> 2460301.5 | R25: =+L25*E25 -> 718505.14 | S25: =SUM(N25:R25) -> 48618848 | U25: =+ROUNDUP(M25*$T$5,0) -> 65949899 | V25: =+U25*E25 -> 65949899 | Y25: Meses | Z25: =+Z24/Z26 -> 8.1451198
A26: 3.03 | B26: OK | C26: Platea - H30 (110 kg/m3 de hierro) | D26: m3 | E26: =+'H°A° '!O4 -> 7 | F26: =+'H°A° '!F47 -> 357146.17 | H26: =F26+G26 -> 357146.17 | I26: =+'MO HA AING'!C5 -> 222927.96 | K26: =I26+J26 -> 222927.96 | L26: =+(H26+K26)*0.015 -> 8701.1119 | M26: =H26+K26+L26 -> 588775.24 | N26: =F26*E26 -> 2500023.2 | O26: =G26*E26 -> 0 | P26: =I26*E26 -> 1560495.7 | Q26: =J26*E26 -> 0 | R26: =+L26*E26 -> 60907.784 | S26: =SUM(N26:R26) -> 4121426.7 | U26: =+ROUNDUP(M26*$T$5,0) -> 798655 | V26: =+U26*E26 -> 5590585 | Y26: Cuadrilla (9) | Z26: =9*'P.MO 06.25'!F5*22 -> 10260628
A27: 3.04 | B27: OK | C27: Zapata corrida tabique - H30 (180 kg/m3 de hierro) | D27: m3 | E27: =+'H°A° '!O5 -> 4 | F27: =+'H°A° '!F48 -> 537813.29 | H27: =F27+G27 -> 537813.29 | I27: =+'MO HA AING'!C6 -> 323084 | K27: =I27+J27 -> 323084 | L27: =+(H27+K27)*0.015 -> 12913.459 | M27: =H27+K27+L27 -> 873810.75 | N27: =F27*E27 -> 2151253.2 | O27: =G27*E27 -> 0 | P27: =I27*E27 -> 1292336 | Q27: =J27*E27 -> 0 | R27: =+L27*E27 -> 51653.837 | S27: =SUM(N27:R27) -> 3495243 | U27: =+ROUNDUP(M27*$T$5,0) -> 1185297 | V27: =+U27*E27 -> 4741188
A28: 3.05 | B28: OK | C28: Bases aisladas - H30 (110 kg/m3 de hierro) | D28: m3 | E28: =+'H°A° '!O6 -> 2 | F28: =+'H°A° '!F49 -> 357146.17 | H28: =F28+G28 -> 357146.17 | I28: =+'MO HA AING'!C5 -> 222927.96 | K28: =I28+J28 -> 222927.96 | L28: =+(H28+K28)*0.015 -> 8701.1119 | M28: =H28+K28+L28 -> 588775.24 | N28: =F28*E28 -> 714292.34 | O28: =G28*E28 -> 0 | P28: =I28*E28 -> 445855.92 | Q28: =J28*E28 -> 0 | R28: =+L28*E28 -> 17402.224 | S28: =SUM(N28:R28) -> 1177550.5 | U28: =+ROUNDUP(M28*$T$5,0) -> 798655 | V28: =+U28*E28 -> 1597310
A29: 3.06 | B29: OK | C29: Cabezales - H30 (130 kg/m3 de hierro) | D29: m3 | E29: =+'H°A° '!O7 -> 11 | F29: =+'H°A° '!F50 -> 392586.17 | H29: =F29+G29 -> 392586.17 | I29: =+'MO HA AING'!C5 -> 222927.96 | K29: =I29+J29 -> 222927.96 | L29: =+(H29+K29)*0.015 -> 9232.7119 | M29: =H29+K29+L29 -> 624746.84 | N29: =F29*E29 -> 4318447.9 | O29: =G29*E29 -> 0 | P29: =I29*E29 -> 2452207.6 | Q29: =J29*E29 -> 0 | R29: =+L29*E29 -> 101559.83 | S29: =SUM(N29:R29) -> 6872215.3 | U29: =+ROUNDUP(M29*$T$5,0) -> 847449 | V29: =+U29*E29 -> 9321939
A30: 3.07 | B30: OK | C30: Viga de fundación - H30 (180 kg/m3 de hierro) | D30: m3 | E30: =+'H°A° '!O8 -> 9 | F30: =+'H°A° '!F51 -> 537813.29 | H30: =F30+G30 -> 537813.29 | I30: =+'MO HA AING'!C6 -> 323084 | K30: =I30+J30 -> 323084 | L30: =+(H30+K30)*0.015 -> 12913.459 | M30: =H30+K30+L30 -> 873810.75 | N30: =F30*E30 -> 4840319.6 | O30: =G30*E30 -> 0 | P30: =I30*E30 -> 2907756 | Q30: =J30*E30 -> 0 | R30: =+L30*E30 -> 116221.13 | S30: =SUM(N30:R30) -> 7864296.7 | U30: =+ROUNDUP(M30*$T$5,0) -> 1185297 | V30: =+U30*E30 -> 10667673
A31: 3.08 | B31: OK | C31: Tabique submuración - H30 (90 kg/m3 de hierro) | D31: m3 | E31: =+'H°A° '!O9 -> 9 | F31: =+'H°A° '!F52 -> 394401.89 | H31: =F31+G31 -> 394401.89 | I31: =+'MO HA AING'!D72 -> 392678.73 | K31: =I31+J31 -> 392678.73 | L31: =+(H31+K31)*0.015 -> 11806.209 | M31: =H31+K31+L31 -> 798886.83 | N31: =F31*E31 -> 3549617 | O31: =G31*E31 -> 0 | P31: =I31*E31 -> 3534108.6 | Q31: =J31*E31 -> 0 | R31: =+L31*E31 -> 106255.88 | S31: =SUM(N31:R31) -> 7189981.5 | U31: =+ROUNDUP(M31*$T$5,0) -> 1083665 | V31: =+U31*E31 -> 9752985 | Y31: $ x m3 | Z31: =+Z24/AA31 -> 284265.44 | AA31: =+SUM(E31:E40) -> 294
A32: 3.09 | B32: OK | C32: Puntales de compresión/codales - H30 (120 kg/m3) | D32: m3 | E32: 1 | F32: =+'H°A° '!F53 -> 542036.05 | H32: =F32+G32 -> 542036.05 | I32: =+'MO HA AING'!D47 -> 362209.61 | K32: =I32+J32 -> 362209.61 | L32: =+(H32+K32)*0.015 -> 13563.685 | M32: =H32+K32+L32 -> 917809.34 | N32: =F32*E32 -> 542036.05 | O32: =G32*E32 -> 0 | P32: =I32*E32 -> 362209.61 | Q32: =J32*E32 -> 0 | R32: =+L32*E32 -> 13563.685 | S32: =SUM(N32:R32) -> 917809.34 | U32: =+ROUNDUP(M32*$T$5,0) -> 1244979 | V32: =+U32*E32 -> 1244979
A33: 3.1 | B33: OK | C33: Columna - H30 (240 kg/m3 de hierro) | D33: m3 | E33: =+'H°A° '!O12 -> 32 | F33: =+'H°A° '!F55 -> 648356.05 | H33: =F33+G33 -> 648356.05 | I33: =+'MO HA AING'!D47 -> 362209.61 | K33: =I33+J33 -> 362209.61 | L33: =+(H33+K33)*0.015 -> 15158.485 | M33: =H33+K33+L33 -> 1025724.1 | N33: =F33*E33 -> 20747394 | O33: =G33*E33 -> 0 | P33: =I33*E33 -> 11590707 | Q33: =J33*E33 -> 0 | R33: =+L33*E33 -> 485071.52 | S33: =SUM(N33:R33) -> 32823173 | U33: =+ROUNDUP(M33*$T$5,0) -> 1391362 | V33: =+U33*E33 -> 44523584
A34: 3.11 | B34: OK | C34: Tabiques - H30 (120 kg/m3 de hierro) | D34: m3 | E34: =+'H°A° '!O13 -> 30 | F34: =+'H°A° '!F56 -> 447561.89 | H34: =F34+G34 -> 447561.89 | I34: =+'MO HA AING'!D72 -> 392678.73 | K34: =I34+J34 -> 392678.73 | L34: =+(H34+K34)*0.015 -> 12603.609 | M34: =H34+K34+L34 -> 852844.23 | N34: =F34*E34 -> 13426857 | O34: =G34*E34 -> 0 | P34: =I34*E34 -> 11780362 | Q34: =J34*E34 -> 0 | R34: =+L34*E34 -> 378108.28 | S34: =SUM(N34:R34) -> 25585327 | U34: =+ROUNDUP(M34*$T$5,0) -> 1156856 | V34: =+U34*E34 -> 34705680
A35: 3.12 | B35: OK | C35: Viga H° Visto - H30 (120 kg/m3 de hierro) | D35: m3 | E35: =+'H°A° '!O14 -> 7 | F35: =+'H°A° '!F57 -> 466389.3 | H35: =F35+G35 -> 466389.3 | I35: =+'MO HA AING'!D99 -> 629584.36 | J35: =+I35*0.25 -> 157396.09 | K35: =I35+J35 -> 786980.44 | L35: =+(H35+K35)*0.015 -> 18800.546 | M35: =H35+K35+L35 -> 1272170.3 | N35: =F35*E35 -> 3264725.1 | O35: =G35*E35 -> 0 | P35: =I35*E35 -> 4407090.5 | Q35: =J35*E35 -> 1101772.6 | R35: =+L35*E35 -> 131603.82 | S35: =SUM(N35:R35) -> 8905192 | U35: =+ROUNDUP(M35*$T$5,0) -> 1725658 | V35: =+U35*E35 -> 12079606
A36: 3.13 | B36: OK | C36: Viga apeo s/PB - H30 (180 kg/m3 de hierro) | D36: m3 | E36: =+'H°A° '!O15 -> 12 | F36: =+'H°A° '!F58 -> 578369.51 | H36: =F36+G36 -> 578369.51 | I36: =+'MO HA AING'!D99 -> 629584.36 | J36: =+I36*0.25 -> 157396.09 | K36: =I36+J36 -> 786980.44 | L36: =+(H36+K36)*0.015 -> 20480.249 | M36: =H36+K36+L36 -> 1385830.2 | N36: =F36*E36 -> 6940434.1 | O36: =G36*E36 -> 0 | P36: =I36*E36 -> 7555012.3 | Q36: =J36*E36 -> 1888753.1 | R36: =+L36*E36 -> 245762.99 | S36: =SUM(N36:R36) -> 16629962 | U36: =+ROUNDUP(M36*$T$5,0) -> 1879834 | V36: =+U36*E36 -> 22558008
A37: 3.14 | B37: OK | C37: Viga - H30 (120 kg/m3 de hierro) | D37: m3 | E37: =+'H°A° '!O16 -> 41 | F37: =+'H°A° '!F59 -> 472049.51 | H37: =F37+G37 -> 472049.51 | I37: =+'MO HA AING'!D99 -> 629584.36 | K37: =I37+J37 -> 629584.36 | L37: =+(H37+K37)*0.015 -> 16524.508 | M37: =H37+K37+L37 -> 1118158.4 | N37: =F37*E37 -> 19354030 | O37: =G37*E37 -> 0 | P37: =I37*E37 -> 25812959 | Q37: =J37*E37 -> 0 | R37: =+L37*E37 -> 677504.83 | S37: =SUM(N37:R37) -> 45844493 | U37: =+ROUNDUP(M37*$T$5,0) -> 1516746 | V37: =+U37*E37 -> 62186586
A38: 3.15 | B38: OK | C38: Losa - H30 (95 kg/m3 de hierro) | D38: m3 | E38: =+'H°A° '!O17 -> 135 | F38: =+'H°A° '!F60 -> 361563.22 | H38: =F38+G38 -> 361563.22 | I38: =+'MO HA AING'!D123 -> 253632.45 | K38: =I38+J38 -> 253632.45 | L38: =+(H38+K38)*0.015 -> 9227.9351 | M38: =H38+K38+L38 -> 624423.61 | N38: =F38*E38 -> 48811035 | O38: =G38*E38 -> 0 | P38: =I38*E38 -> 34240381 | Q38: =J38*E38 -> 0 | R38: =+L38*E38 -> 1245771.2 | S38: =SUM(N38:R38) -> 84297187 | U38: =+ROUNDUP(M38*$T$5,0) -> 847011 | V38: =+U38*E38 -> 114346485
A39: 3.16 | B39: OK | C39: Losa H° Visto - H30 (95 kg/m3 de hierro) | D39: m3 | E39: =+'H°A° '!O18 -> 13 | F39: =+'H°A° '!F61 -> 367994.55 | H39: =F39+G39 -> 367994.55 | I39: =+'MO HA AING'!D123 -> 253632.45 | J39: =+I39*0.25 -> 63408.113 | K39: =I39+J39 -> 317040.56 | L39: =+(H39+K39)*0.015 -> 10275.527 | M39: =H39+K39+L39 -> 695310.64 | N39: =F39*E39 -> 4783929.2 | O39: =G39*E39 -> 0 | P39: =I39*E39 -> 3297221.9 | Q39: =J39*E39 -> 824305.46 | R39: =+L39*E39 -> 133581.85 | S39: =SUM(N39:R39) -> 9039038.3 | U39: =+ROUNDUP(M39*$T$5,0) -> 943167 | V39: =+U39*E39 -> 12261171
A40: 3.17 | B40: OK | C40: Escalera - H30 (105 kg/m3) | D40: m3 | E40: =+'H°A° '!O19 -> 14 | F40: =+'H°A° '!F62 -> 404870.23 | H40: =F40+G40 -> 404870.23 | I40: =+'MO HA AING'!D148 -> 370454.15 | K40: =I40+J40 -> 370454.15 | L40: =+(H40+K40)*0.015 -> 11629.866 | M40: =H40+K40+L40 -> 786954.25 | N40: =F40*E40 -> 5668183.3 | O40: =G40*E40 -> 0 | P40: =I40*E40 -> 5186358.1 | Q40: =J40*E40 -> 0 | R40: =+L40*E40 -> 162818.12 | S40: =SUM(N40:R40) -> 11017359 | U40: =+ROUNDUP(M40*$T$5,0) -> 1067479 | V40: =+U40*E40 -> 14944706
...

Sheet Tareas
H4: MATERIALES | Q4: MANO DE OBRA
H5: PU | J5: TOTAL | M5: =+'P.MO 06.25'!B4 -> 94177.138 | N5: =+'P.MO 06.25'!B5 -> 84612.513 | O5: =+'P.MO 06.25'!B6 -> 72132.138 | P5: =+'P.MO 06.25'!B7 -> 67240.499 | Q5: PU | S5: TOTAL
C6: Descripción | D6: U | E6: Cant | F6: OTRO | G6: CORRALON | H6: OTRO | I6: CORRALON | J6: OTRO | K6: CORRALON | L6: OTRO | M6: ES | N6: OF | O6: MED | P6: AY | Q6: OTRO | R6: ALB | S6: OTRO | T6: ALB
A7: =+'01'!A8 -> 1 | C7: =+'01'!C8 -> TAREAS PRELIMINARES
A8: =+'01'!A10 -> 1.02 | B8: =+'01'!B10 -> OK | C8: =+'01'!C10 -> Topógrafo - Visita de obra replanteo | D8: =+'01'!D10 -> un | E8: =+'01'!E10 -> 4 | H8: =+J8/E8 -> 0 | I8: =+K8/E8 -> 25000 | J8: =SUM(J9:J11) -> 0 | K8: =SUM(K9:K11) -> 100000 | Q8: =+U8/E8 -> 214394.06 | R8: =+V8/E8 -> 67240.499 | U8: =SUM(S9:S11) -> 857576.25 | V8: =SUM(T9:T11) -> 268962
C9: M.Obra topografo | D9: d | E9: =+E8 -> 4 | J9: =+F9*E9 -> 0 | K9: =+G9*E9 -> 0 | L9: =+'P.MO 06.25'!B10 -> 214394.06 | S9: =+L9*E9 -> 857576.25 | T9: =(+M9*$M$5+N9*$N$5+O9*$O$5+P9*$P$5)*E9 -> 0
C10: M.Obra ayudante | D10: d | E10: =+E8 -> 4 | J10: =+F10*E10 -> 0 | K10: =+G10*E10 -> 0 | P10: 1 | S10: =+L10*E10 -> 0 | T10: =(+M10*$M$5+N10*$N$5+O10*$O$5+P10*$P$5)*E10 -> 268962
C11: Consumibles | D11: gl | E11: =+E8 -> 4 | G11: 25000 | J11: =+F11*E11 -> 0 | K11: =+G11*E11 -> 100000 | S11: =+L11*E11 -> 0 | T11: =(+M11*$M$5+N11*$N$5+O11*$O$5+P11*$P$5)*E11 -> 0
A12: =+'01'!A12 -> 1.04 | B12: =+'01'!B12 -> OK | C12: =+'01'!C12 -> Cerco de obra perimetral - En chapa C25 + Concertina + Porton corredizo | D12: =+'01'!D12 -> ml | E12: =+'01'!E12 -> 10 | H12: =+J12/E12 -> 98815.568 | I12: =+K12/E12 -> 0 | J12: =+SUM(J13:J22) -> 988155.68 | K12: =+SUM(K13:K22) -> 0 | Q12: =+U12/E12 -> 0 | R12: =+V12/E12 -> 111992.57 | U12: =SUM(S13:S22) -> 0 | V12: =SUM(T13:T22) -> 1119925.7
C13: Chapa acanalada C25 | D13: m2 | E13: =+E12*2.5 -> 25 | F13: =+Cotizaciones!D4 -> 10861.769 | J13: =+F13*E13 -> 271544.21 | K13: =+G13*E13 -> 0 | S13: =+L13*E13 -> 0 | T13: =(+M13*$M$5+N13*$N$5+O13*$O$5+P13*$P$5)*E13 -> 0
C14: Perfiles UPN 100 | D14: un | E14: 1 | F14: =+Cotizaciones!D5 -> 271144.89 | J14: =+F14*E14 -> 271144.89 | K14: =+G14*E14 -> 0 | S14: =+L14*E14 -> 0 | T14: =(+M14*$M$5+N14*$N$5+O14*$O$5+P14*$P$5)*E14 -> 0
C15: Bastidor para porton corredizo - Perfil 40 x 40 x 2 | D15: u | E15: 2 | F15: =+Cotizaciones!D6 -> 23523.752 | J15: =+F15*E15 -> 47047.504 | K15: =+G15*E15 -> 0 | S15: =+L15*E15 -> 0 | T15: =(+M15*$M$5+N15*$N$5+O15*$O$5+P15*$P$5)*E15 -> 0
C16: Riel Roma 174 e: 2,1 mm. 53 x 60 x 6000 | D16: u | E16: 1 | F16: =+Cotizaciones!D7 -> 85391.38 | J16: =+F16*E16 -> 85391.38 | K16: =+G16*E16 -> 0 | S16: =+L16*E16 -> 0 | T16: =(+M16*$M$5+N16*$N$5+O16*$O$5+P16*$P$5)*E16 -> 0
C17: Carro acero 174 4 ruedas puertas portones Ø45mm | D17: u | E17: 2 | F17: =+Cotizaciones!D8 -> 11534.744 | J17: =+F17*E17 -> 23069.488 | K17: =+G17*E17 -> 0 | S17: =+L17*E17 -> 0 | T17: =(+M17*$M$5+N17*$N$5+O17*$O$5+P17*$P$5)*E17 -> 0
C18: Autoperforantes punta mecha 14 x 2 | D18: u | E18: =+E13*4.5 -> 112.5 | F18: 120 | J18: =+F18*E18 -> 13500 | K18: =+G18*E18 -> 0 | S18: =+L18*E18 -> 0 | T18: =(+M18*$M$5+N18*$N$5+O18*$O$5+P18*$P$5)*E18 -> 0
C19: Rollo Concertina | D19: rol | E19: 2 | F19: =50000/1.21 -> 41322.314 | J19: =+F19*E19 -> 82644.628 | K19: =+G19*E19 -> 0 | S19: =+L19*E19 -> 0 | T19: =(+M19*$M$5+N19*$N$5+O19*$O$5+P19*$P$5)*E19 -> 0
C20: Puntales 3 x 3 x 3,7 | D20: u | E20: 7 | F20: =+Cotizaciones!D24 -> 4992.1647 | J20: =+F20*E20 -> 34945.153 | K20: =+G20*E20 -> 0 | S20: =+L20*E20 -> 0 | T20: =(+M20*$M$5+N20*$N$5+O20*$O$5+P20*$P$5)*E20 -> 0
C21: Consumibles | D21: gl | E21: 0.2 | F21: =+SUM(J13:J19) -> 794342.11 | J21: =+F21*E21 -> 158868.42 | K21: =+G21*E21 -> 0 | S21: =+L21*E21 -> 0 | T21: =(+M21*$M$5+N21*$N$5+O21*$O$5+P21*$P$5)*E21 -> 0
C22: M.Obra | D22: d | E22: 5 | J22: =+F22*E22 -> 0 | K22: =+G22*E22 -> 0 | N22: 1 | O22: 1 | P22: 1 | S22: =+L22*E22 -> 0 | T22: =(+M22*$M$5+N22*$N$5+O22*$O$5+P22*$P$5)*E22 -> 1119925.7
A23: =+'01'!A13 -> 1.05 | B23: =+'01'!B13 -> OK | C23: =+'01'!C13 -> Obrador, pañol y ducha | D23: =+'01'!D13 -> gl | E23: =+'01'!E13 -> 1 | H23: =+J23/E23 -> 2270625.2 | I23: =+K23/E23 -> 300000 | J23: =+SUM(J24:J46) -> 2270625.2 | K23: =+SUM(K24:K46) -> 300000 | Q23: =+U23/E23 -> 1000000 | R23: =+V23/E23 -> 5023936.4 | U23: =SUM(S24:S46) -> 1000000 | V23: =SUM(T24:T46) -> 5023936.4 | AD23: 0.66
C24: Chapa acanalada C25 - Reutilizado (estimado 3 usos) | D24: m2 | E24: 30 | F24: =+Cotizaciones!D4/2 -> 5430.8843 | J24: =+F24*E24 -> 162926.53 | K24: =+G24*E24 -> 0 | S24: =+L24*E24 -> 0 | T24: =(+M24*$M$5+N24*$N$5+O24*$O$5+P24*$P$5)*E24 -> 0 | X24: Largo | Y24: Ancho | Z24: perim | AA24: h | AB24: m2 | AD24: Puntales
C25: Fenolico 1,22 x 2,44 - Reutilizado (estimado 3 usos) | D25: u | E25: =+AB33 -> 30 | F25: =+Cotizaciones!D21/2 -> 13196.9 | J25: =+F25*E25 -> 395907 | K25: =+G25*E25 -> 0 | S25: =+L25*E25 -> 0 | T25: =(+M25*$M$5+N25*$N$5+O25*$O$5+P25*$P$5)*E25 -> 0 | W25: Paredes | X25: 8 | Y25: 4 | Z25: =+X25 -> 8 | AA25: 2.4 | AB25: =+Z25*AA25 -> 19.2 | AD25: =+ROUNDUP(X25/$AD$23,0) -> 13 | AE25: =+AD25*AA25 -> 31.2 | AF25: =+ROUNDUP(AE25/3.7,0) -> 9
C26: Puntales 1 x 4 x 3,7 - Reutilizado (estimado 3 usos) | D26: u | E26: =+E27*2 -> 74 | F26: =+Cotizaciones!D23/2 -> 1109.369 | J26: =+F26*E26 -> 82093.306 | K26: =+G26*E26 -> 0 | S26: =+L26*E26 -> 0 | T26: =(+M26*$M$5+N26*$N$5+O26*$O$5+P26*$P$5)*E26 -> 0 | W26: Piso | X26: =+X25 -> 8 | Y26: 4 | AB26: =+X26*Y26 -> 32 | AD26: =+ROUNDUP(Y26/$AD$23,0) -> 7 | AE26: =+AD26*X26 -> 56 | AF26: =+ROUNDUP(AE26/3.7,0) -> 16
C27: Puntales 3 x 3 x 3,7 - Reutilizado (estimado 3 usos) | D27: u | E27: =+AF28 -> 37 | F27: =+Cotizaciones!D24/2 -> 2496.0823 | J27: =+F27*E27 -> 92355.046 | K27: =+G27*E27 -> 0 | S27: =+L27*E27 -> 0 | T27: =(+M27*$M$5+N27*$N$5+O27*$O$5+P27*$P$5)*E27 -> 0 | W27: Paredes interiores | X27: 3 | Y27: 3 | AA27: 2.4 | AB27: =+X27*Y27*AA27 -> 21.6 | AD27: =+ROUNDUP(Y27*3/$AD$23,0) -> 14 | AE27: =+AD27*X27 -> 42 | AF27: =+ROUNDUP(AE27/3.7,0) -> 12
C28: Flechas 3 x 6 x 3,7 - Reutilizado (estimado 3 usos) | D28: u | E28: 20 | F28: =+F27*2 -> 4992.1647 | J28: =+F28*E28 -> 99843.293 | K28: =+G28*E28 -> 0 | S28: =+L28*E28 -> 0 | T28: =(+M28*$M$5+N28*$N$5+O28*$O$5+P28*$P$5)*E28 -> 0 | W28: Galeria | AF28: =+SUM(AF25:AF27) -> 37
C29: Escalera | D29: gl | E29: 0 | F29: =+SUM(J26:J28) -> 274291.65 | J29: =+F29*E29 -> 0 | K29: =+G29*E29 -> 0 | S29: =+L29*E29 -> 0 | T29: =(+M29*$M$5+N29*$N$5+O29*$O$5+P29*$P$5)*E29 -> 0
C30: Flete madera | D30: u | E30: 2 | J30: =+F30*E30 -> 0 | K30: =+G30*E30 -> 0 | L30: 250000 | S30: =+L30*E30 -> 500000 | T30: =(+M30*$M$5+N30*$N$5+O30*$O$5+P30*$P$5)*E30 -> 0 | AB30: =+SUM(AB25:AB27) -> 72.8
C31: Materiales varios | D31: gl | E31: 1 | G31: 300000 | J31: =+F31*E31 -> 0 | K31: =+G31*E31 -> 300000 | S31: =+L31*E31 -> 0 | T31: =(+M31*$M$5+N31*$N$5+O31*$O$5+P31*$P$5)*E31 -> 0
C32: M.Obra carpinteros | D32: d | E32: 5 | J32: =+F32*E32 -> 0 | K32: =+G32*E32 -> 0 | N32: 1 | O32: 1 | P32: 2 | S32: =+L32*E32 -> 0 | T32: =(+M32*$M$5+N32*$N$5+O32*$O$5+P32*$P$5)*E32 -> 1456128.2 | U32: =+N32*$E32 -> 5 | V32: =+O32*$E32 -> 5 | W32: =+P32*$E32 -> 10 | AB32: =1.2*2.4 -> 2.88
C33: Rollo de cable TPR 3 x 2,5 | D33: rol | E33: 1 | F33: 250000 | J33: =+F33*E33 -> 250000 | K33: =+G33*E33 -> 0 | S33: =+L33*E33 -> 0 | T33: =(+M33*$M$5+N33*$N$5+O33*$O$5+P33*$P$5)*E33 -> 0 | AB33: =+ROUNDUP(AB30/AB32*1.15,0) -> 30 | AD33: =+SUM(AD25:AD32)*1.15 -> 39.1
C34: Zocalo E27 | D34: u | E34: 10 | F34: 500 | J34: =+F34*E34 -> 5000 | K34: =+G34*E34 -> 0 | S34: =+L34*E34 -> 0 | T34: =(+M34*$M$5+N34*$N$5+O34*$O$5+P34*$P$5)*E34 -> 0
C35: Lampara Led 12 w | D35: u | E35: =+E34 -> 10 | F35: 3000 | J35: =+F35*E35 -> 30000 | K35: =+G35*E35 -> 0 | S35: =+L35*E35 -> 0 | T35: =(+M35*$M$5+N35*$N$5+O35*$O$5+P35*$P$5)*E35 -> 0
C36: Mat. Elect. (tomas, enchufes, etc.) | D36: gl | E36: 0.5 | F36: =+SUM(J33:J35) -> 285000 | J36: =+F36*E36 -> 142500 | K36: =+G36*E36 -> 0 | S36: =+L36*E36 -> 0 | T36: =(+M36*$M$5+N36*$N$5+O36*$O$5+P36*$P$5)*E36 -> 0
C37: M.Obra elect | D37: d | E37: 3 | J37: =+F37*E37 -> 0 | K37: =+G37*E37 -> 0 | M37: 1 | N37: 1 | S37: =+L37*E37 -> 0 | T37: =(+M37*$M$5+N37*$N$5+O37*$O$5+P37*$P$5)*E37 -> 536368.95 | U37: =+N37*$E37 -> 3 | V37: =+O37*$E37 -> 0 | W37: =+P37*$E37 -> 0
C38: Materiales Sanit | D38: gl | E38: 1 | F38: 300000 | J38: =+F38*E38 -> 300000 | K38: =+G38*E38 -> 0 | S38: =+L38*E38 -> 0 | T38: =(+M38*$M$5+N38*$N$5+O38*$O$5+P38*$P$5)*E38 -> 0
C39: Inodoro | D39: u | E39: 2 | F39: 150000 | J39: =+F39*E39 -> 300000 | K39: =+G39*E39 -> 0 | S39: =+L39*E39 -> 0 | T39: =(+M39*$M$5+N39*$N$5+O39*$O$5+P39*$P$5)*E39 -> 0
C40: Mochila plastico | D40: u | E40: 2 | F40: 25000 | J40: =+F40*E40 -> 50000 | K40: =+G40*E40 -> 0 | S40: =+L40*E40 -> 0 | T40: =(+M40*$M$5+N40*$N$5+O40*$O$5+P40*$P$5)*E40 -> 0
C41: Bacha | D41: u | E41: 2 | F41: 30000 | J41: =+F41*E41 -> 60000 | K41: =+G41*E41 -> 0 | S41: =+L41*E41 -> 0 | T41: =(+M41*$M$5+N41*$N$5+O41*$O$5+P41*$P$5)*E41 -> 0
C42: Termo electrico 40 lts | D42: u | E42: 1 | F42: 300000 | J42: =+F42*E42 -> 300000 | K42: =+G42*E42 -> 0 | S42: =+L42*E42 -> 0 | T42: =(+M42*$M$5+N42*$N$5+O42*$O$5+P42*$P$5)*E42 -> 0
C43: M.Obra sanit | D43: d | E43: 4 | J43: =+F43*E43 -> 0 | K43: =+G43*E43 -> 0 | M43: 1 | N43: 1 | S43: =+L43*E43 -> 0 | T43: =(+M43*$M$5+N43*$N$5+O43*$O$5+P43*$P$5)*E43 -> 715158.6 | U43: =+N43*$E43 -> 4 | V43: =+O43*$E43 -> 0 | W43: =+P43*$E43 -> 0
...

Sheet GGBB
H2: 45846 | O2: 24
F3: MESES | G3: DÓLAR BNA | H3: DÓLAR MEP | M3: Descrip | N3: Mes | O3: Total Dias
B4: GASTOS GENERALES y BENEFICIO | F4: =+ROUNDUP(N21,0) -> 19 | G4: 1280 | H4: 1276 | M4: Prelim | N4: 0.5 | O4: =+N4*$O$2 -> 12 | Q4: Syh permanente
M5: Micropilotes | N5: 2 | O5: =+N5*$O$2 -> 48 | Q5: =+ROUNDUP(SUM(N6),0) -> 1
B6: Gastos Grales de obra en items | C6: Un | D6: Meses | E6: Cant | F6: Precio Unit | G6: Subtotal | H6: =SUM(G7:G10) -> 3040000 | M6: Subsuelo y VF | N6: 1 | O6: =+N6*$O$2 -> 24
B7: Oficina en obra (6x3 c/AA) | C7: mes | D7: =+$F$4 -> 19 | E7: 0 | F7: =E7*I7+J7 -> 0 | G7: =+F7*D7*E7 -> 0 | M7: Losa sobre PB | N7: 1 | O7: =+N7*$O$2 -> 24
B8: Obrador 6x3 s/AA | C8: mes | D8: =+$F$4 -> 19 | E8: 0 | F8: =E8*I8+J8 -> 0 | G8: =+F8*D8*E8 -> 0 | M8: Losa sobre 1 | N8: 0.75 | O8: =+N8*$O$2 -> 18
B9: Pañol (6x3) | C9: mes | D9: =+$F$4 -> 19 | E9: 0 | F9: 180000 | G9: =+F9*D9*E9 -> 0 | M9: Losa sobre 2 | N9: 0.75 | O9: =+N9*$O$2 -> 18
B10: Baños | C10: mes | D10: =+$F$4 -> 19 | E10: 2 | F10: 80000 | G10: =+F10*D10*E10 -> 3040000 | M10: Losa sobre 3 | N10: 0.75 | O10: =+N10*$O$2 -> 18
B11: Gastos Grales de obra en items | H11: =SUM(G12:G19) -> 39866835 | M11: Losa sobre 4 | N11: 0.75 | O11: =+N11*$O$2 -> 18 | P11: Inicio mamposteria | Q11: Meses H° | R11: Estacionamiento en contramano
B12: HyS permanente | C12: mes | D12: =+Q5 -> 1 | E12: 1 | G12: =+F12*D12*E12 -> 0 | J12: =+'P.MO 06.25'!C9/2 -> 1623254.5 | K12: =+J12*D12*E12 -> 1623254.5 | M12: Losa sobre 5 | N12: 0.75 | O12: =+N12*$O$2 -> 18 | Q12: =+SUM(N6:N15) -> 7.5 | R12: =+ROUNDUP(Q12/3,0) -> 3
B13: HyS | C13: mes | D13: =+$F$4 -> 19 | E13: 1 | G13: =+F13*D13*E13 -> 0 | J13: 300000 | K13: =+J13*D13*E13 -> 5700000 | M13: Losa sobre 6 | N13: 0.75 | O13: =+N13*$O$2 -> 18
B14: Energía de obra | C14: mes | D14: =+$F$4 -> 19 | E14: 0.5 | F14: 200000 | G14: =+F14*D14*E14 -> 1900000 | M14: Losa sobre 7 | N14: 0.5 | O14: =+N14*$O$2 -> 12
B15: Agua de obra | C15: mes | D15: =+$F$4 -> 19 | E15: 1 | F15: 300000 | G15: =+F15*D15*E15 -> 5700000 | M15: Losa Techos | N15: 0.5 | O15: =+N15*$O$2 -> 12
B16: Internet | C16: mes | D16: =+$F$4 -> 19 | E16: 1 | F16: 75000 | G16: =+F16*D16*E16 -> 1425000 | M16: Mampostería | N16: 2 | O16: =+N16*$O$2 -> 48
B17: Alquiler cerco de obra chapa | C17: mes | D17: =+$F$4 -> 19 | E17: 0 | F17: 10000 | G17: =+F17*D17*E17 -> 0 | M17: Revoques, contrap y carp | N17: 2 | O17: =+N17*$O$2 -> 48
B18: Proyecto Ejecutivo | C18: mes | D18: =+$F$4 -> 19 | E18: 0 | F18: =+'P.MO 06.25'!C9 -> 3246508.9 | G18: =+F18*D18*E18 -> 0 | M18: Colocación | N18: 2 | O18: =+N18*$O$2 -> 48
B19: Proyecto (50%) | C19: mes | D19: =+$F$4 -> 19 | E19: 0.5 | F19: =+'P.MO 06.25'!C9 -> 3246508.9 | G19: =+F19*D19*E19 -> 30841835 | M19: Pintura | N19: 2 | O19: =+N19*$O$2 -> 48
B20: Gastos Directos | H20: =SUM(G21:G30) -> 89942566 | M20: Terminaciones | N20: 1 | O20: =+N20*$O$2 -> 24
B21: Coordinacion de obra | C21: mes | D21: =+$F$4 -> 19 | E21: 0.15 | F21: =+'P.MO 06.25'!C11 -> 5688802.4 | G21: =+F21*D21*E21 -> 16213087 | N21: =SUM(N4:N20) -> 19 | O21: =SUM(O4:O20) -> 456
B22: Jefe de obra | C22: mes | D22: =+$F$4 -> 19 | E22: 0.2 | F22: =+'P.MO 06.25'!C10 -> 4716669.4 | G22: =+F22*D22*E22 -> 17923344
B23: Sobrestante | C23: mes | D23: =+$F$4 -> 19 | E23: 1 | G23: =+F23*D23*E23 -> 0 | J23: =+'P.MO 06.25'!C9 -> 3246508.9 | K23: =+J23*D23*E23 -> 61683669
B24: Administrativo en obra | C24: mes | D24: =+$F$4 -> 19 | E24: 0 | F24: =+J23 -> 3246508.9 | G24: =+F24*D24*E24 -> 0
B25: Capataz | C25: mes | D25: =+$F$4 -> 19 | E25: 0.5 | F25: =+'P.MO 06.25'!C12 -> 3874330.1 | G25: =+F25*D25*E25 -> 36806136
B26: Logistica | C26: mes | D26: =+$F$4 -> 19 | E26: 1 | F26: 500000 | G26: =+F26*D26*E26 -> 9500000
B27: Vehiculo obra | C27: mes | D27: =+$F$4 -> 19 | E27: 1 | F27: =F26 -> 500000 | G27: =+F27*D27*E27 -> 9500000
B28: Mov y viaticos | C28: mes | D28: =+$F$4 -> 19 | E28: 1 | G28: =+F28*D28*E28 -> 0 | J28: =F26 -> 500000 | K28: =+J28*D28*E28 -> 9500000
B29: UOCRA | C29: mes | D29: =+$F$4 -> 19 | E29: 1 | G29: =+F29*D29*E29 -> 0
B30: Pañolero/Sereno | C30: mes | D30: =+$F$4 -> 19 | E30: 1 | J30: =+'P.MO 06.25'!C7/2 -> 806885.99 | K30: =+J30*D30*E30 -> 15330834
B31: Equipos | H31: =SUM(G32:G36) -> 0
B32: Bobcat | C32: mes | F32: 130000 | G32: =+F32*D32 -> 0
B33: Camion limpieza | C33: mes | F33: 100000 | G33: =+F33*D33 -> 0
B34: Tijera electrica 12 | C34: mes | F34: 33600 | G34: =+F34*D34 -> 0
B35: JLG | C35: mes | F35: 89000 | G35: =+F35*D35 -> 0
B36: Grua 20ton | C36: mes | F36: 70000 | G36: =+F36*D36 -> 0
B37: Gastos Indirectos | H37: =SUM(G38:G42) -> 94164835
B38: Admin (50%Compras - 50%RRHH) | C38: mes | D38: =+$F$4 -> 19 | E38: 0.5 | F38: ='P.MO 06.25'!C9 -> 3246508.9 | G38: =+F38*D38*E38 -> 30841835
B39: Seguros | C39: gl | D39: =+D38 -> 19 | E39: 1 | F39: 250000 | G39: =+F39*D39 -> 4750000
B40: IIBB (monto venta obra gris) | C40: gl | D40: 0.04 | E40: 0.7 | F40: 1550000000 | G40: =+F40*D40*E40 -> 43400000
B41: Imp cheque | C41: gl | D41: =1.2/100 -> 0.012 | E41: =+E40 -> 0.7 | F41: =+F40*1.15 -> 1.7825e+09 | G41: =+F41*D41*E41 -> 14973000
...

Sheet Locales
J2: H Promedio | N2: ALBAÑILERIA | U2: REVOQUES | AD2: AISLACIONES | AL2: CIELORRASOS | AW2: CARPINTERIAS | BD2: PISOS (m2) | BL2: ZOCALOS (ml) | BQ2: TERMINACIONES | CB2: ELECTRICIDAD | CZ2: ART SANITARIO | DE2: GRIFERIAS
J3: H a revisar | N3: CONTRAPISOS | Q3: CARPETAS | U3: CEMENTICIO | Z3: YESO | AL3: SECO | AR3: YESO | AU3: H°A° | AW3: Puertas | BB3: Ventanas | BQ3: REV | BT3: PAREDES | BW3: CIELORRASO | CB3: ARTEFACTOS ILUM | CE3: TENSION | CV3: MBT
J4: Revisar | N4: C1 | O4: C2 | P4: C3 | Q4: C4 | R4: C5 | S4: C6 | U4: R1 | V4: R2 | W4: R3 | X4: R4 | Y4: R5 | Z4: R6 | AA4: R7 | AB4: R8 | AD4: A1 | AE4: A1.1 | AF4: A2 | AG4: A3 | AH4: A4 | AI4: A5 | AJ4: A5.1 | AL4: C1 | AM4: C2 | AN4: C3 | AO4: C4 | AP4: C5 | AQ4: C6 | AR4: C7 | AS4: C8 | AT4: C9 | AU4: C10 | AW4: P1 | AX4: P2 | AY4: P3 | AZ4: P4 | BA4: P5 | BB4: PM | BD4: P1 | BE4: P2 | BF4: P3 | BG4: P4 | BH4: P5 | BI4: P6 | BJ4: P7 | BK4: S1 | BL4: Z1 | BM4: Z2 | BN4: Z3 | BO4: Z4 | BQ4: RV1 | BR4: RV2 | BS4: RV3 | BT4: PI1 | BU4: PI2 | BV4: PI4 | BW4: PCI1 | BX4: PCI2 | BY4: PCI3 | BZ4: PCI4 | CB4: AI1 | CC4: AI2 | CD4: AI3 | CE4: IL1 | CF4: IL2 | CG4: IL3 | CH4: IL4 | CI4: IL5 | CJ4: IL6 | CK4: IL7 | CL4: IL8 | CM4: IL9 | CN4: IL10 | CO4: IL11 | CP4: IL12 | CQ4: IL13 | CR4: IL14 | CS4: IL15 | CT4: IL16 | CU4: IL17 | CV4: BT1 | CW4: BT2 | CX4: BT3 | CZ4: IS1 | DA4: IS2 | DB4: IS3 | DC4: IS4 | DD4: IS5 | DE4: IS6 | DF4: IS7 | DG4: IS8 | DH4: IS9 | DI4: IS10
J5: Revisado | N5: MC | O5: MC | P5: MC | Q5: MC | R5: MC | S5: MC | U5: MC | V5: MC | W5: MC | X5: MC | Y5: MC | Z5: MC | AA5: MC | AB5: MC | AD5: MC | AE5: MC | AF5: MC | AG5: MC | AH5: MC | AI5: MC | AJ5: MC | AL5: MC | AM5: MC | AN5: MC | AO5: MC | AP5: MC | AQ5: MC | AR5: MC | AS5: MC | AT5: MC | AU5: MC | AW5: MC | AX5: MC | AY5: MC | AZ5: MC | BA5: MC | BB5: MC | BD5: MC | BE5: MC | BF5: MC | BG5: MC | BH5: MC | BI5: MC | BJ5: MC | BK5: MC | BL5: MC | BM5: MC | BN5: MC | BO5: MC | BQ5: MC | BR5: MC | BS5: MC | BT5: MC | BU5: MC | BV5: MC | BW5: MC | BX5: MC | BY5: MC | BZ5: MC
C6: CHIVILCOY 2171 | N6: Contrapiso alivianado c/ pendiente en azotea | O6: Contrapiso s/ss | P6: Contrapiso armado s/ suelo nat | Q6: Monolitico | R6: Carpeta | S6: Carpeta s/ membrana | U6: Revoque 2 en 1 | V6: Aristas (esq. Metalico) | W6: Cantonera en revoque | X6: Grueso bajo reves | Y6: Revoque 3 en 1 | Z6: Yeso | AA6: Aristas (esq. Metalico) | AB6: Cantoneras | AD6: Aislacion Horizontal en Baños | AE6: Babeta | AF6: Aislaciòn hidrofuga sobre contrapiso | AG6: Barrera de vapor (pintura asfaltica) | AH6: Aislaciòn termica EPS | AI6: Membrana geotextil - Balcones y azotea | AJ6: Babeta | AL6: Suspendido placa STD | AM6: Suspendido placa RH | AN6: Buña "Z" Durlock | AO6: Cantonera dk | AP6: Cajòn durlock | AQ6: Garganta | AR6: Yeso aplicado | AS6: Buña de Yeso | AT6: Arista | AU6: Hormigon visto / Maquillaje | AW6: Puerta placa F30 de 90cm (acceso a UF) | AX6: Pueras F60 | AY6: Puerta placa MDF (blanco semi mate) | AZ6: Puerta de chapa (espacios comunes) | BA6: Frente ascensor | BB6: Premarco | BD6: Porcelanato exterior | BE6: Palieres / Terrazas | BF6: Porcelanato en UF | BG6: Porcelanato en baños | BH6: Alisado de cemento rodillado | BI6: Sustrato | BJ6: Baldosas 40x40 | BK6: Solia de entrada | BL6: MDF Pintado | BM6: Concreto | BN6: Porcelanato UF | BO6: Porcelanato | BQ6: Revestimiento cocina | BR6: Revestimiento baño | BS6: Revestimiento texturado con llana metalica | BT6: Latex interior color a definir enduido completo | BU6: Latex interior color a definir enduido parcial | BV6: Latex interior color a definir s/ enduido | BW6: Latex interior color a definir enduido completo | BX6: Latex interior color a definir enduido parcial | BY6: Revestimiento plastico | BZ6: Latex exterior color a definir s/ enduido | CB6: Extractor | CC6: Espacio comun/balcones | CD6: Luz de emergencia | CE6: Boca ilum losa | CF6: Boca ilum pared | CG6: Caja para led | CH6: Pulsador | CI6: Tecla 1 mod | CJ6: Tecla 2 mod | CK6: Tecla 3 mod | CL6: Tomas simple | CM6: Toma doble | CN6: Toma encapsulado | CO6: Toma Esp. Anafe/Horno | CP6: Toma A/A | CQ6: Tablero 1 amb | CR6: Tablero 2/3 amb | CS6: Tablero SG | CT6: Tablero TSFM | CU6: Tablero TSBT | CV6: Pulsador timbre | CW6: Boca de Portero | CX6: Boca TV | CZ6: Indoro Roca monaco | DA6: Bidet Roca monaco | DB6: Bacha de losa Roca | DC6: Bañera Roca | DD6: Bacha A.I Johnson | DE6: Accesorios de Baño FV alerce o similar | DF6: Griferia de lavarotio FV alerce o similar | DG6: Griferia de bidet 3 agujeros con tapita FV alerce o similar | DH6: Griferia de ducha FV alerce o similar | DI6: Griferia de cocina FV alerce o similar
A7: PLANTA | B7: Nº | C7: LOCAL | D7: Largo | E7: Ancho | F7: SUP | G7: perim unit | H7: vacio | I7: perim real | J7: H | K7: H r | L7: aux | N7: m2 | O7: m2 | P7: m2 | Q7: m2 | R7: m2 | S7: m2 | U7: m2 | V7: ml | W7: un | X7: m2 | Y7: m2 | Z7: m2 | AA7: ml | AB7: un | AD7: m2 | AE7: ml | AF7: m2 | AG7: m2 | AH7: m2 | AI7: m2 | AJ7: ml | AL7: m2 | AM7: m2 | AN7: ml | AO7: ml | AP7: ml | AQ7: ml | AR7: m2 | AS7: ml | AT7: ml | AU7: m2 | AW7: u | AX7: u | AY7: u | AZ7: u | BA7: u | BB7: u | BD7: m2 | BE7: m2 | BF7: m2 | BG7: m2 | BH7: m2 | BI7: m2 | BJ7: m2 | BK7: ml | BL7: ml | BM7: ml | BN7: ml | BO7: ml | BQ7: m2 | BR7: m2 | BS7: m2 | BT7: m2 | BU7: m2 | BV7: m2 | BW7: m2 | BX7: m2 | BY7: m2 | BZ7: m2 | CB7: un | CC7: un | CD7: un | CE7: un | CF7: un | CG7: un | CH7: un | CI7: un | CJ7: un | CK7: un | CL7: un | CM7: un | CN7: un | CO7: un | CP7: un | CQ7: un | CR7: un | CS7: un | CT7: un | CU7: un | CV7: un | CW7: un | CX7: un | CZ7: un | DA7: un | DB7: un | DC7: un | DD7: un | DE7: un | DF7: un | DG7: un | DH7: un | DI7: un
A8: Subsuelo | B8: 1 | C8: CT | D8: 5 | E8: 4.13 | F8: =D8*E8 -> 20.65 | G8: =+D8*2+E8*2 -> 18.26 | I8: =+G8-H8 -> 18.26 | J8: 3.5 | O8: =+F8 -> 20.65 | U8: =+I8*J8 -> 63.91 | AU8: =+F8 -> 20.65 | BV8: =+I8*J8 -> 63.91 | BZ8: =+F8 -> 20.65
A9: PB | B9: 2 | C9: Vereda | D9: 8.1 | E9: 3.2 | F9: =D9*E9 -> 25.92 | G9: =+D9*2+E9*2 -> 22.6 | H9: 0 | I9: =+G9-H9 -> 22.6 | L9: =7.5*1.4 -> 10.5 | P9: =+F9 -> 25.92 | AF9: =+F9 -> 25.92 | AU9: =+L9 -> 10.5 | BJ9: =+F9 -> 25.92 | BZ9: =+L9 -> 10.5 | CC9: 3 | CF9: 3
B10: 3 | C10: Acceso cocheras exterior | D10: 4.03 | E10: 3 | F10: =D10*E10 -> 12.09 | G10: =+D10*2+E10*2 -> 14.06 | H10: =+D11+E10*2 -> 9.73 | I10: =+G10-H10 -> 4.33 | J10: 3 | P10: =+F10 -> 12.09 | AF10: =+F10 -> 12.09 | AU10: =+F10 -> 12.09 | BJ10: =+F10 -> 12.09 | BZ10: =+F10 -> 12.09 | CC10: 1 | CE10: 1
B11: 4 | C11: Medidores de luz | D11: 3.73 | E11: 0.4 | F11: =D11*E11 -> 1.492 | G11: =+D11*2+E11*2 -> 8.26 | H11: =+D11 -> 3.73 | I11: =+G11-H11 -> 4.53 | J11: 3 | P11: =+F11 -> 1.492 | AF11: =+F11 -> 1.492 | AU11: =+F11 -> 1.492 | BH11: =+F11 -> 1.492 | BZ11: =+F11 -> 1.492 | CM11: 1
B12: 5 | C12: Ingreso vehicular | D12: =13.04-D13 -> 6.9 | E12: 4.13 | F12: =D12*E12 -> 28.497 | G12: =+D12*2+E12*2 -> 22.06 | H12: =+E12*2 -> 8.26 | I12: =+G12-H12 -> 13.8 | J12: 3 | P12: =+F12 -> 28.497 | AF12: =+F12 -> 28.497 | AU12: =+F12 -> 28.497 | BJ12: =+F12 -> 28.497 | BZ12: =+F12 -> 28.497 | CC12: 2 | CE12: 2 | CM12: 1 | CS12: 1
B13: 6 | C13: Ingreso vehicular s/cielorraso | D13: 6.14 | E13: 4.13 | F13: =D13*E13 -> 25.3582 | G13: =+D13*2+E13*2 -> 20.54 | H13: =+E13*2 -> 8.26 | I13: =+G13-H13 -> 12.28 | J13: 3 | P13: =+F13 -> 25.3582 | AF13: =+F13 -> 25.3582 | BJ13: =+F13 -> 25.3582 | CC13: 2 | CF13: 2 | CM13: 1
B14: 7 | C14: Espacio guardacoche | D14: 7.93 | E14: 7.76 | F14: =D14*E14 -> 61.5368 | G14: =+D14*2+E14*2 -> 31.38 | H14: =+E14+E12 -> 11.89 | I14: =+G14-H14 -> 19.49 | J14: 3 | L14: =7.45*1.5 -> 11.175 | P14: =+F14 -> 61.5368 | AF14: =+F14 -> 61.5368 | AU14: =+F14+L14 -> 72.7118 | BJ14: =+F14 -> 61.5368 | BZ14: =+F14+L14 -> 72.7118 | CC14: 4 | CE14: 4
B15: 8 | C15: Terreno absorbente | F15: 48.35 | G15: 27.98 | H15: =+E14 -> 7.76 | I15: =+G15-H15 -> 20.22 | J15: 3 | CC15: 2 | CF15: 2
