Workbook
Name \0: #REF!
Name \0: #REF!
Name \c: #REF!
Name \c: #REF!
Name \E: #REF!
Name \E: #REF!
Name \i: #REF!
Name \j: #REF!
Name \m: #REF!
Name \P: #REF!
Name \P: #REF!
Name \P: #REF!
Name \P: #REF!
Name \P: #REF!
Name \P: #REF!
Name \P: #REF!
Name \P: #REF!
Name \P: #REF!
Name \P: #REF!
Name \P: #REF!
Name \P: #REF!
Name \P: #REF!
Name \P: #REF!
Name \P: #REF!
Name \r: #N/A
Name \x: #REF!
Name \z: #REF!
Name \z: #REF!
Name __________ben1: #REF!
Name __________ben1: #REF!
Name __________ben1: #REF!
Name __________ben1: #REF!
Name __________ben1: #REF!
Name __________ben1: #REF!
Name __________ben1: #REF!
Name __________ben1: #REF!
Name __________ben1: #REF!
Name __________ben1: #REF!
Name __________ben1: #REF!
Name __________ben1: #REF!
Name __________ben1: #REF!
Name __________ben1: #REF!
Name __________ben1: #REF!
Name __________ben1: #REF!
Name __________ben10: #REF!
Name __________ben10: #REF!
Name __________ben10: #REF!
Name __________ben10: #REF!
Name __________ben10: #REF!
Name __________ben10: #REF!
Name __________ben10: #REF!
Name __________ben10: #REF!
Name __________ben10: #REF!
Name __________ben10: #REF!
Name __________ben10: #REF!
Name __________ben10: #REF!
Name __________ben10: #REF!
Name __________ben10: #REF!
Name __________ben10: #REF!
Name __________ben10: #REF!

Sheet Resumen General
U1: Actualizado | V1: 46156
B3: OBRA: CHIVILCOY 2171
B4: RESUMEN DE OBRA
D5: 45962 | E5: 45992 | F5: 46023 | G5: 46054 | H5: 46082 | I5: 46113 | J5: 46143 | L5: Acum. Descontado | N5: Presupuesto #1 | O5: Presupuesto #2 | P5: Previsto | Q5: % Cert. Acum. | R5: Saldo Disponible | S5: Disponible % | T5: Rubro Completado
B6: Ingresos de Obra
B7: Ingresos por Certificados | D7: =SUM(VLOOKUP($B7,'Resumen Pto #1'!$B$5:$I$10,MATCH(D$5,'Resumen Pto #1'!$B$5:$I$5,0),0),VLOOKUP($B7,'Resumen Pto #2'!$B$5:$I$9,MATCH(D$5,'Resumen Pto #2'!$B$5:$I$5,0),0)) -> 0 | E7: =SUM(VLOOKUP($B7,'Resumen Pto #1'!$B$5:$I$10,MATCH(E$5,'Resumen Pto #1'!$B$5:$I$5,0),0),VLOOKUP($B7,'Resumen Pto #2'!$B$5:$I$9,MATCH(E$5,'Resumen Pto #2'!$B$5:$I$5,0),0)) -> 0 | F7: =SUM(VLOOKUP($B7,'Resumen Pto #1'!$B$5:$I$10,MATCH(F$5,'Resumen Pto #1'!$B$5:$I$5,0),0),VLOOKUP($B7,'Resumen Pto #2'!$B$5:$I$9,MATCH(F$5,'Resumen Pto #2'!$B$5:$I$5,0),0)) -> 0 | G7: =SUM(VLOOKUP($B7,'Resumen Pto #1'!$B$5:$I$10,MATCH(G$5,'Resumen Pto #1'!$B$5:$I$5,0),0),VLOOKUP($B7,'Resumen Pto #2'!$B$5:$I$9,MATCH(G$5,'Resumen Pto #2'!$B$5:$I$5,0),0)) -> 0 | H7: =SUM(VLOOKUP($B7,'Resumen Pto #1'!$B$5:$I$10,MATCH(H$5,'Resumen Pto #1'!$B$5:$I$5,0),0),VLOOKUP($B7,'Resumen Pto #2'!$B$5:$I$9,MATCH(H$5,'Resumen Pto #2'!$B$5:$I$5,0),0)) -> 120095631 | I7: =SUM(VLOOKUP($B7,'Resumen Pto #1'!$B$5:I$10,MATCH(I$5,'Resumen Pto #1'!$B$5:I$5,0),0),VLOOKUP($B7,'Resumen Pto #2'!$B$5:I$9,MATCH(I$5,'Resumen Pto #2'!$B$5:I$5,0),0)) -> 51205725 | J7: =SUM(VLOOKUP($B7,'Resumen Pto #1'!$B$5:J$10,MATCH(J$5,'Resumen Pto #1'!$B$5:J$5,0),0),VLOOKUP($B7,'Resumen Pto #2'!$B$5:J$9,MATCH(J$5,'Resumen Pto #2'!$B$5:J$5,0),0)) -> 0 | L7: =SUM(D7:K7) -> 1.7130136e+08 | N7: ='Resumen Pto #1'!N7 -> 3.903108e+08 | O7: ='Resumen Pto #2'!N7 -> 6.1109415e+08 | P7: =SUM(N7:O7) -> 1.001405e+09 | R7: =IF(Q7=100%,0,IF(OR(L7<>0,P7),P7-L7)) -> 8.301036e+08 | S7: =IF(OR(R7<0,P7),R7/P7,0%) -> 0.82893898 | T7: =IF(Q7=100%,IF(OR(K7<>0,P7),P7-K7),0) -> 0
B8: Total Ingresos de Obra | D8: =SUM(D7) -> 0 | E8: =SUM(E7) -> 0 | F8: =SUM(F7) -> 0 | G8: =SUM(G7) -> 0 | H8: =SUM(H7) -> 120095631 | I8: =SUM(I7) -> 51205725 | J8: =SUM(J7) -> 0 | L8: =SUM(L7) -> 1.7130136e+08 | N8: =SUM(N7) -> 3.903108e+08 | O8: =SUM(O7) -> 6.1109415e+08 | P8: =SUM(P7) -> 1.001405e+09 | R8: =SUM(R7) -> 8.301036e+08 | S8: =IF(OR(R8<0,P8),R8/P8,0%) -> 0.82893898 | T8: =SUM(T7) -> 0
B9: Actualización por CAC | D9: =SUM(VLOOKUP($B9,'Resumen Pto #1'!$B$5:$I$10,MATCH(D$5,'Resumen Pto #1'!$B$5:$I$5,0),0),VLOOKUP($B9,'Resumen Pto #2'!$B$5:$I$9,MATCH(D$5,'Resumen Pto #2'!$B$5:$I$5,0),0)) -> 0 | E9: =SUM(VLOOKUP($B9,'Resumen Pto #1'!$B$5:$I$10,MATCH(E$5,'Resumen Pto #1'!$B$5:$I$5,0),0),VLOOKUP($B9,'Resumen Pto #2'!$B$5:$I$9,MATCH(E$5,'Resumen Pto #2'!$B$5:$I$5,0),0)) -> 0 | F9: =SUM(VLOOKUP($B9,'Resumen Pto #1'!$B$5:$I$10,MATCH(F$5,'Resumen Pto #1'!$B$5:$I$5,0),0),VLOOKUP($B9,'Resumen Pto #2'!$B$5:$I$9,MATCH(F$5,'Resumen Pto #2'!$B$5:$I$5,0),0)) -> 0 | G9: =SUM(VLOOKUP($B9,'Resumen Pto #1'!$B$5:$I$10,MATCH(G$5,'Resumen Pto #1'!$B$5:$I$5,0),0),VLOOKUP($B9,'Resumen Pto #2'!$B$5:$I$9,MATCH(G$5,'Resumen Pto #2'!$B$5:$I$5,0),0)) -> 0 | H9: =SUM(VLOOKUP($B9,'Resumen Pto #1'!$B$5:$I$10,MATCH(H$5,'Resumen Pto #1'!$B$5:$I$5,0),0),VLOOKUP($B9,'Resumen Pto #2'!$B$5:$I$9,MATCH(H$5,'Resumen Pto #2'!$B$5:$I$5,0),0)) -> 21310936 | I9: =SUM(VLOOKUP($B9,'Resumen Pto #1'!$B$5:I$10,MATCH(I$5,'Resumen Pto #1'!$B$5:I$5,0),0),VLOOKUP($B9,'Resumen Pto #2'!$B$5:I$9,MATCH(I$5,'Resumen Pto #2'!$B$5:I$5,0),0)) -> 10072663 | J9: =SUM(VLOOKUP($B9,'Resumen Pto #1'!$B$5:J$10,MATCH(J$5,'Resumen Pto #1'!$B$5:J$5,0),0),VLOOKUP($B9,'Resumen Pto #2'!$B$5:J$9,MATCH(J$5,'Resumen Pto #2'!$B$5:J$5,0),0)) -> 0 | L9: =SUM(D9:K9) -> 31383599 | N9: ='[1]Resumen Pto #1'!X9 -> 0 | O9: ='[1]Resumen Pto #2'!X9 -> 0 | P9: =SUM(N9:O9) -> 0 | R9: =IF(Q9=100%,0,IF(P9=0,P9,P9-L9)) -> 0 | S9: =IF(OR(R9<0,P9),R9/P9,0%) -> 0 | T9: =IF(Q9=100%,IF(OR(K9<>0,P9),P9-K9),0) -> 0
B10: Total Ingresos de Obra | D10: =SUM(D9) -> 0 | E10: =SUM(E9) -> 0 | F10: =SUM(F9) -> 0 | G10: =SUM(G9) -> 0 | H10: =SUM(H9) -> 21310936 | I10: =SUM(I9) -> 10072663 | J10: =SUM(J9) -> 0 | L10: =SUM(L9) -> 31383599 | N10: =SUM(N9) -> 0 | O10: =SUM(O9) -> 0 | P10: =SUM(P9) -> 0 | R10: =SUM(R9) -> 0 | S10: =IF(OR(R10<0,P10),R10/P10,0%) -> 0 | T10: =SUM(T9) -> 0
B12: Costos de Obra
B13: Seguridad e Higiene | D13: ='Resumen Pto #1'!D15+'Resumen Pto #2'!D14 -> 0 | E13: ='Resumen Pto #1'!E15+'Resumen Pto #2'!E14 -> 0 | F13: ='Resumen Pto #1'!F15+'Resumen Pto #2'!F14 -> 0 | G13: ='Resumen Pto #1'!G15+'Resumen Pto #2'!G14 -> 517195 | H13: ='Resumen Pto #1'!H15+'Resumen Pto #2'!H14 -> 826285.91 | I13: ='Resumen Pto #1'!I15+'Resumen Pto #2'!I14 -> 517195 | J13: ='Resumen Pto #1'!J15+'Resumen Pto #2'!K14 -> 1195790 | L13: {=SUMPRODUCT($D13:$K13,TRANSPOSE('Indice CAC'!$E$12:$E$19))} -> 2519063.7 | N13: =IFERROR(VLOOKUP($B13&$C13,'Resumen Pto #1'!$B$13:$N$23,13,0),0) -> 4623254.5 | O13: =VLOOKUP($B13,'Resumen Pto #2'!$B$13:$N$30,12,0) -> 0 | P13: =SUM(N13:O13) -> 4623254.5 | R13: =IF(Q13=100%,0,IF(OR(L13<>0,P13),P13-L13,0)) -> 2104190.8 | S13: =IF(OR(R13<0,P13),R13/P13,0%) -> 0.45513194 | T13: =IF(Q13=100%,IF(OR(L13<>0,P13),P13-L13),0) -> 0
B14: Supervisión de Obra | D14: ='Resumen Pto #2'!D13 -> 0 | E14: ='Resumen Pto #2'!E13 -> 0 | F14: ='Resumen Pto #2'!F13 -> 0 | G14: ='Resumen Pto #2'!G13 -> 0 | H14: ='Resumen Pto #2'!H13+'Resumen Pto #1'!H24 -> 2800000 | I14: ='Resumen Pto #2'!I13+'Resumen Pto #1'!I24 -> 2867000 | J14: ='Resumen Pto #2'!K13+'Resumen Pto #1'!J24 -> 2850000 | L14: {=SUMPRODUCT($D14:$K14,TRANSPOSE('Indice CAC'!$E$12:$E$19))} -> 6991833.5 | N14: =VLOOKUP($B14&$C14,'Resumen Pto #1'!$B$13:$N$24,13,0) -> 32465089 | O14: =VLOOKUP($B14,'Resumen Pto #2'!$B$13:$N$30,12,0) -> 0 | P14: =SUM(N14:O14) -> 32465089 | R14: =IF(Q14=100%,0,IF(OR(L14<>0,P14),P14-L14,0)) -> 25473256 | S14: =IF(OR(R14<0,P14),R14/P14,0%) -> 0.78463532 | T14: =IF(Q14=100%,IF(OR(L14<>0,P14),P14-L14),0) -> 0
B15: Movilidad | D15: ='Resumen Pto #1'!D16+'Resumen Pto #2'!D15 -> 0 | E15: ='Resumen Pto #1'!E16+'Resumen Pto #2'!E15 -> 0 | F15: ='Resumen Pto #1'!F16+'Resumen Pto #2'!F15 -> 0 | G15: ='Resumen Pto #1'!G16+'Resumen Pto #2'!G15 -> 0 | H15: ='Resumen Pto #1'!H16+'Resumen Pto #2'!H15 -> 639742.64 | I15: ='Resumen Pto #1'!I16+'Resumen Pto #2'!I15 -> 716525.59 | J15: ='Resumen Pto #1'!J16+'Resumen Pto #2'!K15 -> 38016.53 | L15: {=SUMPRODUCT($D15:$K15,TRANSPOSE('Indice CAC'!$E$12:$E$19))} -> 1153083.2 | N15: =IFERROR(VLOOKUP($B15&$C15,'Resumen Pto #1'!$B$13:$N$23,13,0),0) -> 8000000 | O15: =VLOOKUP($B15,'Resumen Pto #2'!$B$13:$N$30,12,0) -> 0 | P15: =SUM(N15:O15) -> 8000000 | R15: =IF(Q15=100%,0,IF(OR(L15<>0,P15),P15-L15,0)) -> 6846916.8 | S15: =IF(OR(R15<0,P15),R15/P15,0%) -> 0.85586461 | T15: =IF(Q15=100%,IF(OR(L15<>0,P15),P15-L15),0) -> 0
B16: Preliminares | D16: ='Resumen Pto #1'!D13 -> 0 | E16: ='Resumen Pto #1'!E13 -> 0 | F16: ='Resumen Pto #1'!F13 -> 939182.1 | G16: ='Resumen Pto #1'!G13 -> 1539988.9 | H16: ='Resumen Pto #1'!H13 -> 3125044.3 | I16: ='Resumen Pto #1'!I13 -> 734909.88 | J16: ='Resumen Pto #1'!J13 -> 0 | L16: {=SUMPRODUCT($D16:$K16,TRANSPOSE('Indice CAC'!$E$12:$E$19))} -> 5329921.3 | N16: =VLOOKUP($B16,'Resumen Pto #1'!$B$13:$N$23,13,0) -> 14709293 | O16: =IFERROR(VLOOKUP($B16,'Resumen Pto #2'!$B$13:$N$30,12,0),0) -> 0 | P16: =SUM(N16:O16) -> 14709293 | R16: =IF(Q16=100%,0,IF(OR(L16<>0,P16),P16-L16,0)) -> 9379371.2 | S16: =IF(OR(R16<0,P16),R16/P16,0%) -> 0.63764938 | T16: =IF(Q16=100%,IF(OR(L16<>0,P16),P16-L16),0) -> 0
B17: Agrimensura | D17: ='Resumen Pto #1'!D14 -> 0 | E17: ='Resumen Pto #1'!E14 -> 0 | F17: ='Resumen Pto #1'!F14 -> 0 | G17: ='Resumen Pto #1'!G14 -> 0 | H17: ='Resumen Pto #1'!H14 -> 730000 | I17: ='Resumen Pto #1'!I14 -> 0 | J17: ='Resumen Pto #1'!J14 -> 0 | L17: {=SUMPRODUCT($D17:$K17,TRANSPOSE('Indice CAC'!$E$12:$E$19))} -> 610005.92 | N17: =VLOOKUP($B17,'Resumen Pto #1'!$B$13:$N$23,13,0) -> 1226538.2 | O17: =IFERROR(VLOOKUP($B17,'Resumen Pto #2'!$B$13:$N$30,12,0),0) -> 0 | P17: =SUM(N17:O17) -> 1226538.2 | R17: =IF(Q17=100%,0,IF(OR(L17<>0,P17),P17-L17,0)) -> 616532.32 | S17: =IF(OR(R17<0,P17),R17/P17,0%) -> 0.5026605 | T17: =IF(Q17=100%,IF(OR(L17<>0,P17),P17-L17),0) -> 0
B18: Excavación y Mov. de Suelos | D18: ='Resumen Pto #1'!D19 -> 0 | E18: ='Resumen Pto #1'!E19 -> 0 | F18: ='Resumen Pto #1'!F19 -> 0 | G18: ='Resumen Pto #1'!G19 -> 0 | H18: ='Resumen Pto #1'!H19 -> 0 | I18: ='Resumen Pto #1'!I19 -> 1310000 | J18: ='Resumen Pto #1'!J19 -> 0 | L18: {=SUMPRODUCT($D18:$K18,TRANSPOSE('Indice CAC'!$E$12:$E$19))} -> 1074687.2 | N18: =VLOOKUP($B18,'Resumen Pto #1'!$B$13:$N$23,13,0) -> 9462540.3 | O18: =IFERROR(VLOOKUP($B18,'Resumen Pto #2'!$B$13:$N$30,12,0),0) -> 0 | P18: =SUM(N18:O18) -> 9462540.3 | R18: =IF(Q18=100%,0,IF(OR(L18<>0,P18),P18-L18,0)) -> 8387853.1 | S18: =IF(OR(R18<0,P18),R18/P18,0%) -> 0.8864272 | T18: =IF(Q18=100%,IF(OR(L18<>0,P18),P18-L18),0) -> 0
B19: Hormigón | C19: MAT | D19: ='Resumen Pto #1'!D20 -> 0 | E19: ='Resumen Pto #1'!E20 -> 0 | F19: ='Resumen Pto #1'!F20 -> 0 | G19: ='Resumen Pto #1'!G20 -> 0 | H19: ='Resumen Pto #1'!H20 -> 20721536 | I19: ='Resumen Pto #1'!I20 -> 4488122.6 | J19: ='Resumen Pto #1'!J20 -> 13222352 | L19: {=SUMPRODUCT($D19:$K19,TRANSPOSE('Indice CAC'!$E$12:$E$19))} -> 31668388 | N19: ='Resumen Pto #1'!N20 -> 1.55289e+08 | O19: =IFERROR(VLOOKUP($B19,'Resumen Pto #2'!$B$13:$N$30,12,0),0) -> 0 | P19: =SUM(N19:O19) -> 1.55289e+08 | R19: =IF(Q19=100%,0,IF(OR(L19<>0,P19),P19-L19,0)) -> 1.2362062e+08 | S19: =IF(OR(R19<0,P19),R19/P19,0%) -> 0.79606806 | T19: =IF(Q19=100%,IF(OR(L19<>0,P19),P19-L19),0) -> 0
B20: Hormigón | C20: MO | D20: ='Resumen Pto #1'!D21 -> 0 | E20: ='Resumen Pto #1'!E21 -> 0 | F20: ='Resumen Pto #1'!F21 -> 0 | G20: ='Resumen Pto #1'!G21 -> 0 | H20: ='Resumen Pto #1'!H21 -> 19211836 | I20: ='Resumen Pto #1'!I21 -> 19661613 | J20: ='Resumen Pto #1'!J21 -> 30526436 | L20: {=SUMPRODUCT($D20:$K20,TRANSPOSE('Indice CAC'!$E$12:$E$19))} -> 56819928 | N20: ='Resumen Pto #1'!N21 -> 1.6857077e+08 | O20: =IFERROR(VLOOKUP($B20,'Resumen Pto #2'!$B$13:$N$30,12,0),0) -> 0 | P20: =SUM(N20:O20) -> 1.6857077e+08 | R20: =IF(Q20=100%,0,IF(OR(L20<>0,P20),P20-L20,0)) -> 1.1175085e+08 | S20: =IF(OR(R20<0,P20),R20/P20,0%) -> 0.66293132 | T20: =IF(Q20=100%,IF(OR(L20<>0,P20),P20-L20),0) -> 0
B21: Albañilería | C21: MAT | D21: ='Resumen Pto #1'!D17+'Resumen Pto #2'!D16 -> 0 | E21: ='Resumen Pto #1'!E17+'Resumen Pto #2'!E16 -> 0 | F21: ='Resumen Pto #1'!F17+'Resumen Pto #2'!F16 -> 0 | G21: ='Resumen Pto #1'!G17+'Resumen Pto #2'!G16 -> 48248.1 | H21: ='Resumen Pto #1'!H17+'Resumen Pto #2'!H16 -> 95942.03 | I21: ='Resumen Pto #1'!I17+'Resumen Pto #2'!I16 -> 371787.4 | J21: ='Resumen Pto #1'!J17+'Resumen Pto #2'!K16 -> 171269.97 | L21: {=SUMPRODUCT($D21:$K21,TRANSPOSE('Indice CAC'!$E$12:$E$19))} -> 564374.82 | N21: ='Resumen Pto #1'!N17 -> 1000000 | O21: =VLOOKUP($B21,'Resumen Pto #2'!$B$13:$N$30,12,0) -> 0 | P21: =SUM(N21:O21) -> 1000000 | R21: =IF(Q21=100%,0,IF(OR(L21<>0,P21),P21-L21,0)) -> 435625.18 | S21: =IF(OR(R21<0,P21),R21/P21,0%) -> 0.43562518 | T21: =IF(Q21=100%,IF(OR(L21<>0,P21),P21-L21),0) -> 0
B22: Albañilería | C22: MO | D22: ='Resumen Pto #1'!D18+'Resumen Pto #2'!D17 -> 0 | E22: ='Resumen Pto #1'!E18+'Resumen Pto #2'!E17 -> 0 | F22: ='Resumen Pto #1'!F18+'Resumen Pto #2'!F17 -> 0 | G22: ='Resumen Pto #1'!G18+'Resumen Pto #2'!G17 -> 0 | H22: ='Resumen Pto #1'!H18+'Resumen Pto #2'!H17 -> 0 | I22: ='Resumen Pto #1'!I18+'Resumen Pto #2'!I17 -> 2330315.7 | J22: ='Resumen Pto #1'!J18+'Resumen Pto #2'!K17 -> 0 | L22: {=SUMPRODUCT($D22:$K22,TRANSPOSE('Indice CAC'!$E$12:$E$19))} -> 1911725.5 | N22: ='Resumen Pto #1'!N18 -> 20558829 | O22: ='Resumen Pto #2'!N17 -> 1.5272197e+08 | P22: =SUM(N22:O22) -> 1.732808e+08 | R22: =IF(Q22=100%,0,IF(OR(L22<>0,P22),P22-L22,0)) -> 1.7136907e+08 | S22: =IF(OR(R22<0,P22),R22/P22,0%) -> 0.98896747 | T22: =IF(Q22=100%,IF(OR(L22<>0,P22),P22-L22),0) -> 0
B23: Durlock | C23: MAT | D23: ='Resumen Pto #2'!D18 -> 0 | E23: ='Resumen Pto #2'!E18 -> 0 | F23: ='Resumen Pto #2'!F18 -> 0 | G23: ='Resumen Pto #2'!G18 -> 0 | H23: ='Resumen Pto #2'!H18 -> 0 | I23: ='Resumen Pto #2'!I18 -> 0 | J23: ='Resumen Pto #2'!K18 -> 0 | L23: {=SUMPRODUCT($D23:$K23,TRANSPOSE('Indice CAC'!$E$12:$E$19))} -> 0 | N23: =IFERROR(VLOOKUP($B23,'Resumen Pto #1'!$B$13:$N$23,13,0),0) -> 0 | O23: =VLOOKUP($B23,'Resumen Pto #2'!$B$13:$N$30,12,0) -> 0 | P23: =SUM(N23:O23) -> 0 | R23: =IF(Q23=100%,0,IF(OR(L23<>0,P23),P23-L23,0)) -> 0 | S23: =IF(OR(R23<0,P23),R23/P23,0%) -> 0 | T23: =IF(Q23=100%,IF(OR(L23<>0,P23),P23-L23),0) -> 0
B24: Durlock | C24: MO | D24: ='Resumen Pto #2'!D19 -> 0 | E24: ='Resumen Pto #2'!E19 -> 0 | F24: ='Resumen Pto #2'!F19 -> 0 | G24: ='Resumen Pto #2'!G19 -> 0 | H24: ='Resumen Pto #2'!H19 -> 0 | I24: ='Resumen Pto #2'!I19 -> 0 | J24: ='Resumen Pto #2'!K19 -> 0 | L24: {=SUMPRODUCT($D24:$K24,TRANSPOSE('Indice CAC'!$E$12:$E$19))} -> 0 | N24: =IFERROR(VLOOKUP($B24,'Resumen Pto #1'!$B$13:$N$23,13,0),0) -> 0 | O24: ='Resumen Pto #2'!N19 -> 55470003 | P24: =SUM(N24:O24) -> 55470003 | R24: =IF(Q24=100%,0,IF(OR(L24<>0,P24),P24-L24,0)) -> 55470003 | S24: =IF(OR(R24<0,P24),R24/P24,0%) -> 1 | T24: =IF(Q24=100%,IF(OR(L24<>0,P24),P24-L24),0) -> 0
B25: Pintura | C25: MAT | D25: ='Resumen Pto #2'!D20 -> 0 | E25: ='Resumen Pto #2'!E20 -> 0 | F25: ='Resumen Pto #2'!F20 -> 0 | G25: ='Resumen Pto #2'!G20 -> 0 | H25: ='Resumen Pto #2'!H20 -> 0 | I25: ='Resumen Pto #2'!I20 -> 0 | J25: ='Resumen Pto #2'!K20 -> 0 | L25: {=SUMPRODUCT($D25:$K25,TRANSPOSE('Indice CAC'!$E$12:$E$19))} -> 0 | N25: =IFERROR(VLOOKUP($B25,'Resumen Pto #1'!$B$13:$N$23,13,0),0) -> 0 | O25: =VLOOKUP($B25,'Resumen Pto #2'!$B$13:$N$30,12,0) -> 0 | P25: =SUM(N25:O25) -> 0 | R25: =IF(Q25=100%,0,IF(OR(L25<>0,P25),P25-L25,0)) -> 0 | S25: =IF(OR(R25<0,P25),R25/P25,0%) -> 0 | T25: =IF(Q25=100%,IF(OR(L25<>0,P25),P25-L25),0) -> 0
B26: Pintura | C26: MO | D26: ='Resumen Pto #2'!D21 -> 0 | E26: ='Resumen Pto #2'!E21 -> 0 | F26: ='Resumen Pto #2'!F21 -> 0 | G26: ='Resumen Pto #2'!G21 -> 0 | H26: ='Resumen Pto #2'!H21 -> 0 | I26: ='Resumen Pto #2'!I21 -> 0 | J26: ='Resumen Pto #2'!K21 -> 0 | L26: {=SUMPRODUCT($D26:$K26,TRANSPOSE('Indice CAC'!$E$12:$E$19))} -> 0 | N26: =IFERROR(VLOOKUP($B26,'Resumen Pto #1'!$B$13:$N$23,13,0),0) -> 0 | O26: ='Resumen Pto #2'!N21 -> 60159232 | P26: =SUM(N26:O26) -> 60159232 | R26: =IF(Q26=100%,0,IF(OR(L26<>0,P26),P26-L26,0)) -> 60159232 | S26: =IF(OR(R26<0,P26),R26/P26,0%) -> 1 | T26: =IF(Q26=100%,IF(OR(L26<>0,P26),P26-L26),0) -> 0
B27: Revestimiento | C27: MAT | D27: ='Resumen Pto #2'!D22 -> 0 | E27: ='Resumen Pto #2'!E22 -> 0 | F27: ='Resumen Pto #2'!F22 -> 0 | G27: ='Resumen Pto #2'!G22 -> 0 | H27: ='Resumen Pto #2'!H22 -> 0 | I27: ='Resumen Pto #2'!I22 -> 0 | J27: ='Resumen Pto #2'!K22 -> 0 | L27: {=SUMPRODUCT($D27:$K27,TRANSPOSE('Indice CAC'!$E$12:$E$19))} -> 0 | N27: =IFERROR(VLOOKUP($B27,'Resumen Pto #1'!$B$13:$N$23,13,0),0) -> 0 | O27: =VLOOKUP($B27,'Resumen Pto #2'!$B$13:$N$30,12,0) -> 0 | P27: =SUM(N27:O27) -> 0 | R27: =IF(Q27=100%,0,IF(OR(L27<>0,P27),P27-L27,0)) -> 0 | S27: =IF(OR(R27<0,P27),R27/P27,0%) -> 0 | T27: =IF(Q27=100%,IF(OR(L27<>0,P27),P27-L27),0) -> 0
B28: Revestimiento | C28: MO | D28: ='Resumen Pto #2'!D23 -> 0 | E28: ='Resumen Pto #2'!E23 -> 0 | F28: ='Resumen Pto #2'!F23 -> 0 | G28: ='Resumen Pto #2'!G23 -> 0 | H28: ='Resumen Pto #2'!H23 -> 0 | I28: ='Resumen Pto #2'!I23 -> 0 | J28: ='Resumen Pto #2'!K23 -> 0 | L28: {=SUMPRODUCT($D28:$K28,TRANSPOSE('Indice CAC'!$E$12:$E$19))} -> 0 | N28: =IFERROR(VLOOKUP($B28,'Resumen Pto #1'!$B$13:$N$23,13,0),0) -> 0 | O28: ='Resumen Pto #2'!N23 -> 35274699 | P28: =SUM(N28:O28) -> 35274699 | R28: =IF(Q28=100%,0,IF(OR(L28<>0,P28),P28-L28,0)) -> 35274699 | S28: =IF(OR(R28<0,P28),R28/P28,0%) -> 1 | T28: =IF(Q28=100%,IF(OR(L28<>0,P28),P28-L28),0) -> 0
B29: Eléctrico | C29: MAT | D29: ='Resumen Pto #2'!D24 -> 0 | E29: ='Resumen Pto #2'!E24 -> 0 | F29: ='Resumen Pto #2'!F24 -> 0 | G29: ='Resumen Pto #2'!G24 -> 0 | H29: ='Resumen Pto #2'!H24 -> 0 | I29: ='Resumen Pto #2'!I24 -> 0 | J29: ='Resumen Pto #2'!K24 -> 0 | L29: {=SUMPRODUCT($D29:$K29,TRANSPOSE('Indice CAC'!$E$12:$E$19))} -> 0 | N29: =IFERROR(VLOOKUP($B29,'Resumen Pto #1'!$B$13:$N$23,13,0),0) -> 0 | O29: =VLOOKUP($B29,'Resumen Pto #2'!$B$13:$N$30,12,0) -> 0 | P29: =SUM(N29:O29) -> 0 | R29: =IF(Q29=100%,0,IF(OR(L29<>0,P29),P29-L29,0)) -> 0 | S29: =IF(OR(R29<0,P29),R29/P29,0%) -> 0 | T29: =IF(Q29=100%,IF(OR(L29<>0,P29),P29-L29),0) -> 0
B30: Eléctrico | C30: MO | D30: ='Resumen Pto #2'!D25 -> 0 | E30: ='Resumen Pto #2'!E25 -> 0 | F30: ='Resumen Pto #2'!F25 -> 0 | G30: ='Resumen Pto #2'!G25 -> 0 | H30: ='Resumen Pto #2'!H25 -> 0 | I30: ='Resumen Pto #2'!I25 -> 0 | J30: ='Resumen Pto #2'!K25 -> 0 | L30: {=SUMPRODUCT($D30:$K30,TRANSPOSE('Indice CAC'!$E$12:$E$19))} -> 0 | N30: =IFERROR(VLOOKUP($B30,'Resumen Pto #1'!$B$13:$N$23,13,0),0) -> 0 | O30: ='Resumen Pto #2'!N25 -> 64414415 | P30: =SUM(N30:O30) -> 64414415 | R30: =IF(Q30=100%,0,IF(OR(L30<>0,P30),P30-L30,0)) -> 64414415 | S30: =IF(OR(R30<0,P30),R30/P30,0%) -> 1 | T30: =IF(Q30=100%,IF(OR(L30<>0,P30),P30-L30),0) -> 0
B31: Sanitaria | C31: MAT | D31: ='Resumen Pto #2'!D26 -> 0 | E31: ='Resumen Pto #2'!E26 -> 0 | F31: ='Resumen Pto #2'!F26 -> 0 | G31: ='Resumen Pto #2'!G26 -> 0 | H31: ='Resumen Pto #2'!H26 -> 0 | I31: ='Resumen Pto #2'!I26 -> 0 | J31: ='Resumen Pto #2'!K26 -> 0 | L31: {=SUMPRODUCT($D31:$K31,TRANSPOSE('Indice CAC'!$E$12:$E$19))} -> 0 | N31: =IFERROR(VLOOKUP($B31,'Resumen Pto #1'!$B$13:$N$23,13,0),0) -> 0 | O31: =VLOOKUP($B31,'Resumen Pto #2'!$B$13:$N$30,12,0) -> 0 | P31: =SUM(N31:O31) -> 0 | R31: =IF(Q31=100%,0,IF(OR(L31<>0,P31),P31-L31,0)) -> 0 | S31: =IF(OR(R31<0,P31),R31/P31,0%) -> 0 | T31: =IF(Q31=100%,IF(OR(L31<>0,P31),P31-L31),0) -> 0
B32: Sanitaria | C32: MO | D32: ='Resumen Pto #2'!D27 -> 0 | E32: ='Resumen Pto #2'!E27 -> 0 | F32: ='Resumen Pto #2'!F27 -> 0 | G32: ='Resumen Pto #2'!G27 -> 0 | H32: ='Resumen Pto #2'!H27 -> 0 | I32: ='Resumen Pto #2'!I27 -> 0 | J32: ='Resumen Pto #2'!K27 -> 0 | L32: {=SUMPRODUCT($D32:$K32,TRANSPOSE('Indice CAC'!$E$12:$E$19))} -> 0 | N32: =IFERROR(VLOOKUP($B32,'Resumen Pto #1'!$B$13:$N$23,13,0),0) -> 0 | O32: ='Resumen Pto #2'!N27 -> 52462847 | P32: =SUM(N32:O32) -> 52462847 | R32: =IF(Q32=100%,0,IF(OR(L32<>0,P32),P32-L32,0)) -> 52462847 | S32: =IF(OR(R32<0,P32),R32/P32,0%) -> 1 | T32: =IF(Q32=100%,IF(OR(L32<>0,P32),P32-L32),0) -> 0
B33: Termomecánica | D33: ='Resumen Pto #2'!D28 -> 0 | E33: ='Resumen Pto #2'!E28 -> 0 | F33: ='Resumen Pto #2'!F28 -> 0 | G33: ='Resumen Pto #2'!G28 -> 0 | H33: ='Resumen Pto #2'!H28 -> 0 | I33: ='Resumen Pto #2'!I28 -> 0 | J33: ='Resumen Pto #2'!K28 -> 0 | L33: {=SUMPRODUCT($D33:$K33,TRANSPOSE('Indice CAC'!$E$12:$E$19))} -> 0 | N33: =IFERROR(VLOOKUP($B33,'Resumen Pto #1'!$B$13:$N$23,13,0),0) -> 0 | O33: ='Resumen Pto #2'!N28 -> 19100000 | P33: =SUM(N33:O33) -> 19100000 | R33: =IF(Q33=100%,0,IF(OR(L33<>0,P33),P33-L33,0)) -> 19100000 | S33: =IF(OR(R33<0,P33),R33/P33,0%) -> 1 | T33: =IF(Q33=100%,IF(OR(L33<>0,P33),P33-L33),0) -> 0
B34: Equipos | D34: ='Resumen Pto #1'!D22+'Resumen Pto #2'!D29 -> 0 | E34: ='Resumen Pto #1'!E22+'Resumen Pto #2'!E29 -> 0 | F34: ='Resumen Pto #1'!F22+'Resumen Pto #2'!F29 -> 0 | G34: ='Resumen Pto #1'!G22+'Resumen Pto #2'!G29 -> 0 | H34: ='Resumen Pto #1'!H22+'Resumen Pto #2'!H29 -> 0 | I34: ='Resumen Pto #1'!I22+'Resumen Pto #2'!I29 -> 0 | J34: ='Resumen Pto #1'!J22+'Resumen Pto #2'!K29 -> 702737.42 | L34: {=SUMPRODUCT($D34:$K34,TRANSPOSE('Indice CAC'!$E$12:$E$19))} -> 567140.81 | N34: =VLOOKUP($B34,'Resumen Pto #1'!$B$13:$N$23,13,0) -> 15976116 | O34: =VLOOKUP($B34,'Resumen Pto #2'!$B$13:$N$30,12,0) -> 0 | P34: =SUM(N34:O34) -> 15976116 | R34: =IF(Q34=100%,0,IF(OR(L34<>0,P34),P34-L34,0)) -> 15408975 | S34: =IF(OR(R34<0,P34),R34/P34,0%) -> 0.96450071 | T34: =IF(Q34=100%,IF(OR(L34<>0,P34),P34-L34),0) -> 0
B35: Gastos Generales Obra | D35: ='Resumen Pto #1'!D23+'Resumen Pto #2'!D30 -> 0 | E35: ='Resumen Pto #1'!E23+'Resumen Pto #2'!E30 -> 0 | F35: ='Resumen Pto #1'!F23+'Resumen Pto #2'!F30 -> 0 | G35: ='Resumen Pto #1'!G23+'Resumen Pto #2'!G30 -> 247000 | H35: ='Resumen Pto #1'!H23+'Resumen Pto #2'!H30 -> 227000 | I35: ='Resumen Pto #1'!I23+'Resumen Pto #2'!I30 -> 1101000 | J35: ='Resumen Pto #1'!J23+'Resumen Pto #2'!K30 -> 1520000 | L35: {=SUMPRODUCT($D35:$K35,TRANSPOSE('Indice CAC'!$E$12:$E$19))} -> 2529400.2 | N35: =VLOOKUP($B35,'Resumen Pto #1'!$B$13:$N$23,13,0) -> 3712405 | O35: =VLOOKUP($B35,'Resumen Pto #2'!$B$13:$N$30,12,0) -> 0 | P35: =SUM(N35:O35) -> 3712405 | R35: =IF(Q35=100%,0,IF(OR(L35<>0,P35),P35-L35,0)) -> 1183004.8 | S35: =IF(OR(R35<0,P35),R35/P35,0%) -> 0.31866264 | T35: =IF(Q35=100%,IF(OR(L35<>0,P35),P35-L35),0) -> 0
B36: Total Egresos de Obra | D36: =SUM(D13:D35) -> 0 | E36: =SUM(E13:E35) -> 0 | F36: =SUM(F13:F35) -> 939182.1 | G36: =SUM(G13:G35) -> 2352432 | H36: =SUM(H13:H35) -> 48377387 | I36: =SUM(I13:I35) -> 34098469 | J36: =SUM(J13:J35) -> 50226602 | L36: =SUM(L13:L35) -> 1.1173955e+08 | N36: =SUM(N13:N35) -> 4.3559384e+08 | O36: =SUM(O13:O35) -> 4.3960316e+08 | P36: =SUM(P13:P35) -> 8.7519701e+08 | R36: =IF(Q36=100%,0,IF(OR(L36<>0,P36),P36-L36)) -> 7.6345745e+08 | S36: =IF(OR(R36<0,P36),R36/P36,0%) -> 0.8723264 | T36: =SUM(T13:T35) -> 0
B38: Gastos Generales
B39: Gastos Directos | D39: =SUM(VLOOKUP($B39,'C. Gestión Pto #1'!$B$33:$H$33,MATCH(D$5,'C. Gestión Pto #1'!B19:H19,0),0),VLOOKUP($B39,'C. Gestión Pto #2'!$B$40:$H$40,MATCH(D$5,'C. Gestión Pto #2'!$B$26:$H$26,0),0)) -> 0 | E39: =SUM(VLOOKUP($B39,'C. Gestión Pto #1'!$B$33:$H$33,MATCH(E$5,'C. Gestión Pto #1'!C19:I19,0),0),VLOOKUP($B39,'C. Gestión Pto #2'!$B$40:$H$40,MATCH(E$5,'C. Gestión Pto #2'!$B$26:$H$26,0),0)) -> 0 | F39: =SUM(VLOOKUP($B39,'C. Gestión Pto #1'!$B$33:$H$33,MATCH(F$5,'C. Gestión Pto #1'!D19:J19,0),0),VLOOKUP($B39,'C. Gestión Pto #2'!$B$40:$H$40,MATCH(F$5,'C. Gestión Pto #2'!$B$26:$H$26,0),0)) -> 0 | G39: =SUM(VLOOKUP($B39,'C. Gestión Pto #1'!$B$33:$H$33,MATCH(G$5,'C. Gestión Pto #1'!E19:K19,0),0),VLOOKUP($B39,'C. Gestión Pto #2'!$B$40:$H$40,MATCH(G$5,'C. Gestión Pto #2'!$B$26:$H$26,0),0)) -> 0 | H39: =SUM(VLOOKUP($B39,'C. Gestión Pto #1'!$B$33:$L$33,MATCH(H$5,'C. Gestión Pto #1'!$B$19:L19,0),0),VLOOKUP($B39,'C. Gestión Pto #2'!$B$40:$H$40,MATCH(H$5,'C. Gestión Pto #2'!$B$26:$H$26,0),0)) -> 1521288.1 | I39: =SUM(VLOOKUP($B39,'C. Gestión Pto #1'!$B$33:$L$33,MATCH(I$5,'C. Gestión Pto #1'!$B$19:M19,0),0),VLOOKUP($B39,'C. Gestión Pto #2'!$B$40:$H$40,MATCH(I$5,'C. Gestión Pto #2'!$B$26:$H$26,0),0)) -> 1597596 | J39: =SUM(VLOOKUP($B39,'C. Gestión Pto #1'!$B$33:$L$33,MATCH(J$5,'C. Gestión Pto #1'!$B$19:L19,0),0),VLOOKUP($B39,'C. Gestión Pto #2'!$B$40:$I$40,MATCH(J$5,'C. Gestión Pto #2'!$B$26:$I$26,0),0)) -> 1736014.7 | L39: {=SUMPRODUCT($D39:$K39,TRANSPOSE('Indice CAC'!$E$12:$E$19))} -> 3982890.6 | P39: =SUM(GGBB!H6:H36) -> 1.328494e+08 | R39: =IF(Q39=100%,0,IF(OR(L39<>0,P39),P39-L39)) -> 1.2886651e+08 | S39: =IF(OR(R39<0,P39),R39/P39,0%) -> 0.97001951 | T39: =IF(Q39=100%,IF(OR(L39<>0,P39),P39-L39),0) -> 0
B40: Gastos Indirectos | D40: =SUM(VLOOKUP($B40,'C. Gestión Pto #1'!$B$39:$H$39,MATCH(D$5,'C. Gestión Pto #1'!B35:H35,0),0),VLOOKUP($B40,'C. Gestión Pto #2'!$B$46:$H$46,MATCH(D$5,'C. Gestión Pto #2'!$B$42:$H$42,0),0)) -> 0 | E40: =SUM(VLOOKUP($B40,'C. Gestión Pto #1'!$B$39:$H$39,MATCH(E$5,'C. Gestión Pto #1'!C35:I35,0),0),VLOOKUP($B40,'C. Gestión Pto #2'!$B$46:$H$46,MATCH(E$5,'C. Gestión Pto #2'!$B$42:$H$42,0),0)) -> 0 | F40: =SUM(VLOOKUP($B40,'C. Gestión Pto #1'!$B$39:$H$39,MATCH(F$5,'C. Gestión Pto #1'!D35:J35,0),0),VLOOKUP($B40,'C. Gestión Pto #2'!$B$46:$H$46,MATCH(F$5,'C. Gestión Pto #2'!$B$42:$H$42,0),0)) -> 0 | G40: =SUM(VLOOKUP($B40,'C. Gestión Pto #1'!$B$39:$H$39,MATCH(G$5,'C. Gestión Pto #1'!E35:K35,0),0),VLOOKUP($B40,'C. Gestión Pto #2'!$B$46:$H$46,MATCH(G$5,'C. Gestión Pto #2'!$B$42:$H$42,0),0)) -> 0 | H40: =SUM(VLOOKUP($B40,'C. Gestión Pto #1'!$B$39:$L$39,MATCH(H$5,'C. Gestión Pto #1'!$B$35:L35,0),0),VLOOKUP($B40,'C. Gestión Pto #2'!$B$46:$L$46,MATCH(H$5,'C. Gestión Pto #2'!$B$42:$L$42,0),0)) -> 1734248.2 | I40: =SUM(VLOOKUP($B40,'C. Gestión Pto #1'!$B$39:$L$39,MATCH(I$5,'C. Gestión Pto #1'!$B$35:M35,0),0),VLOOKUP($B40,'C. Gestión Pto #2'!$B$46:$L$46,MATCH(I$5,'C. Gestión Pto #2'!$B$42:$L$42,0),0)) -> 1886946.4 | J40: =SUM(VLOOKUP($B40,'C. Gestión Pto #1'!$B$39:$L$39,MATCH(J$5,'C. Gestión Pto #1'!$B$35:N35,0),0),VLOOKUP($B40,'C. Gestión Pto #2'!$B$46:$L$46,MATCH(J$5,'C. Gestión Pto #2'!$B$42:$L$42,0),0)) -> 1833735.9 | L40: {=SUMPRODUCT($D40:$K40,TRANSPOSE('Indice CAC'!$E$12:$E$19))} -> 4477085.8 | P40: =SUM(GGBB!H37:H42) -> 94164835 | R40: =IF(Q40=100%,0,IF(OR(L40<>0,P40),P40-L40)) -> 89687749 | S40: =IF(OR(R40<0,P40),R40/P40,0%) -> 0.9524548 | T40: =IF(Q40=100%,IF(OR(L40<>0,P40),P40-L40),0) -> 0
B41: Total Gastos Generales | D41: =SUM(D39:D40) -> 0 | E41: =SUM(E39:E40) -> 0 | F41: =SUM(F39:F40) -> 0 | G41: =SUM(G39:G40) -> 0 | H41: =SUM(H39:H40) -> 3255536.3 | I41: =SUM(I39:I40) -> 3484542.4 | J41: =SUM(J39:J40) -> 3569750.6 | L41: =SUM(L39:L40) -> 8459976.4 | N41: =SUM(N39:N40) -> 0 | O41: =SUM(O39:O40) -> 0 | P41: =SUM(P39:P40) -> 2.2701424e+08 | R41: =IF(Q41=100%,0,IF(OR(L41<>0,P41),P41-L41)) -> 2.1855426e+08 | S41: =IF(OR(R41<0,P41),R41/P41,0%) -> 0.96273372 | T41: =SUM(T39:T40) -> 0
B43: Total Egresos | D43: =D36+D41 -> 0 | E43: =E36+E41 -> 0 | F43: =F36+F41 -> 939182.1 | G43: =G36+G41 -> 2352432 | H43: =H36+H41 -> 51632923 | I43: =I36+I41 -> 37583012 | J43: =J36+J41 -> 53796353 | L43: =L36+L41 -> 1.2019953e+08 | N43: =N36+N41 -> 4.3559384e+08 | O43: =O36+O41 -> 4.3960316e+08 | P43: =P36+P41 -> 1.1022112e+09
B45: Resultado Operativo | D45: =SUM(D8,D10,-D43) -> 0 | E45: =SUM(E8,E10,-E43) -> 0 | F45: =SUM(F8,F10,-F43) -> -939182.1 | G45: =SUM(G8,G10,-G43) -> -2352432 | H45: =SUM(H8,H10,-H43) -> 89773643 | I45: =SUM(I8,I10,-I43) -> 23695377 | J45: =SUM(J8,J10,-J43) -> -53796353 | L45: =L8-L43 -> 51101828 | P45: =P8-P43 -> -1.0080629e+08
...

Sheet Resumen Pto #1
S1: Actualizado | T1: 46156
B3: OBRA: CHIVILCOY 2171
B4: RESUMEN DE OBRA
D5: 45962 | E5: 45992 | F5: 46023 | G5: 46054 | H5: 46082 | I5: 46113 | J5: 46143 | L5: Acum. Descontado | N5: Previsto | O5: % Cert. Acum. | P5: Saldo Disponible | Q5: Disponible % | R5: Rubro Completado
B6: Ingresos de Obra
B7: Ingresos por certificados | D7: =SUMIFS(Certificados!$E$12:$E$21,Certificados!$A$12:$A$21,">="&DATE(2025,11,1),Certificados!$A$12:$A$21,"<="&DATE(2025,11,30),Certificados!$C$12:$C$21,"Pto 1") -> 0 | E7: =SUMIFS(Certificados!$E$12:$E$21,Certificados!$A$12:$A$21,">="&DATE(2025,12,1),Certificados!$A$12:$A$21,"<="&DATE(2025,12,31),Certificados!$C$12:$C$21,"Pto 1") -> 0 | F7: =SUMIFS(Certificados!$E$12:$E$21,Certificados!$A$12:$A$21,">="&DATE(2026,1,1),Certificados!$A$12:$A$21,"<="&DATE(2026,1,31),Certificados!$C$12:$C$21,"Pto 1") -> 0 | G7: =SUMIFS(Certificados!$E$12:$E$21,Certificados!$A$12:$A$21,">="&DATE(2026,2,1),Certificados!$A$12:$A$21,"<="&DATE(2026,2,29),Certificados!$C$12:$C$21,"Pto 1") -> 0 | H7: =SUMIFS(Certificados!$E$12:$E$21,Certificados!$A$12:$A$21,">="&DATE(2026,3,1),Certificados!$A$12:$A$21,"<="&DATE(2026,3,31),Certificados!$B$12:$B$21,"Pto 1") -> 120095631 | I7: =SUMIFS(Certificados!$E$12:$E$21,Certificados!$A$12:$A$21,">="&DATE(2026,4,1),Certificados!$A$12:$A$21,"<="&DATE(2026,4,30),Certificados!$B$12:$B$21,"Pto 1") -> 51205725 | J7: =SUMIFS(Certificados!$E$12:$E$21,Certificados!$A$12:$A$21,">="&DATE(2026,5,1),Certificados!$A$12:$A$21,"<="&DATE(2026,5,31),Certificados!$B$12:$B$21,"Pto 1") -> 0 | L7: =SUM(D7:I7) -> 1.7130136e+08 | N7: =SUM(Facturacion!E4:E4) -> 3.903108e+08 | P7: =IF(O7=100%,0,IF(OR(L7<>0,N7),N7-L7)) -> 2.1900944e+08 | Q7: =IF(OR(P7<0,N7),P7/N7,0%) -> 0.56111551 | R7: =IF(O7=100%,IF(OR(L7<>0,N7),N7-L7),0) -> 0
B8: Total Ingresos de Obra | D8: =SUM(D7) -> 0 | E8: =SUM(E7) -> 0 | F8: =SUM(F7) -> 0 | G8: =SUM(G7) -> 0 | H8: =SUM(H7) -> 120095631 | I8: =SUM(I7) -> 51205725 | J8: =SUM(J7) -> 0 | L8: =SUM(L7) -> 1.7130136e+08 | N8: =SUM(N7) -> 3.903108e+08 | P8: =SUM(P7) -> 2.1900944e+08 | Q8: =IF(OR(P8<0,N8),P8/N8,0%) -> 0.56111551 | R8: =SUM(R7) -> 0
B9: Actualización por CAC | D9: =SUMIFS(Certificados!$F$12:$F$21,Certificados!$A$12:$A$21,">="&DATE(2025,11,1),Certificados!$A$12:$A$21,"<="&DATE(2025,11,30),Certificados!$C$12:$C$21,"Pto. 1") -> 0 | E9: =SUMIFS(Certificados!$F$12:$F$21,Certificados!$A$12:$A$21,">="&DATE(2025,12,1),Certificados!$A$12:$A$21,"<="&DATE(2025,12,31),Certificados!$C$12:$C$21,"Pto. 1") -> 0 | F9: =SUMIFS(Certificados!$F$12:$F$21,Certificados!$A$12:$A$21,">="&DATE(2026,1,1),Certificados!$A$12:$A$21,"<="&DATE(2026,1,31),Certificados!$C$12:$C$21,"Pto. 1") -> 0 | G9: =SUMIFS(Certificados!$F$12:$F$21,Certificados!$A$12:$A$21,">="&DATE(2026,2,1),Certificados!$A$12:$A$21,"<="&DATE(2026,2,29),Certificados!$C$12:$C$21,"Pto. 1") -> 0 | H9: =SUMIFS(Certificados!$F$12:$F$21,Certificados!$A$12:$A$21,">="&DATE(2026,3,1),Certificados!$A$12:$A$21,"<="&DATE(2026,3,31),Certificados!$B$12:$B$21,"Pto 1") -> 21310936 | I9: =SUMIFS(Certificados!$F$12:$F$21,Certificados!$A$12:$A$21,">="&DATE(2026,4,1),Certificados!$A$12:$A$21,"<="&DATE(2026,4,30),Certificados!$B$12:$B$21,"Pto 1") -> 10072663 | J9: =SUMIFS(Certificados!$F$12:$F$21,Certificados!$A$12:$A$21,">="&DATE(2026,5,1),Certificados!$A$12:$A$21,"<="&DATE(2026,5,31),Certificados!$C$12:$C$21,"Pto 1") -> 0 | L9: =SUM(D9:I9) -> 31383599 | N9: 0 | O9: 0 | P9: =IF(O9=100%,0,IF(N9=0,N9,N9-L9)) -> 0 | Q9: =IF(OR(P9<0,N9),P9/N9,0%) -> 0 | R9: =IF(O9=100%,IF(OR(L9<>0,N9),N9-L9),0) -> 0
B10: Total Ingresos por CAC | D10: =SUM(D9) -> 0 | E10: =SUM(E9) -> 0 | F10: =SUM(F9) -> 0 | G10: =SUM(G9) -> 0 | H10: =SUM(H9) -> 21310936 | I10: =SUM(I9) -> 10072663 | J10: =SUM(J9) -> 0 | L10: =SUM(L9) -> 31383599 | N10: =SUM(N9) -> 0 | P10: =SUM(P9) -> 0 | Q10: =IF(OR(P10<0,N10),P10/N10,0%) -> 0 | R10: =SUM(R9) -> 0
B12: Costos de Obra
B13: Preliminares | D13: =IFERROR(VLOOKUP($B13&$C13,'C. Gestión Pto #1'!$B$4:H$16,MATCH(D$5,'C. Gestión Pto #1'!$B$4:H$4,0),FALSE),0) -> 0 | E13: =IFERROR(VLOOKUP($B13&$C13,'C. Gestión Pto #1'!$B$4:I$16,MATCH(E$5,'C. Gestión Pto #1'!$B$4:I$4,0),"FALSO"),0) -> 0 | F13: =IFERROR(VLOOKUP($B13&$C13,'C. Gestión Pto #1'!$B$4:J$16,MATCH(F$5,'C. Gestión Pto #1'!$B$4:J$4,0),"FALSO"),0) -> 939182.1 | G13: =IFERROR(VLOOKUP($B13&$C13,'C. Gestión Pto #1'!$B$4:K$16,MATCH(G$5,'C. Gestión Pto #1'!$B$4:K$4,0),"FALSO"),0) -> 1539988.9 | H13: =IFERROR(VLOOKUP($B13&$C13,'C. Gestión Pto #1'!$B$4:L$16,MATCH(H$5,'C. Gestión Pto #1'!$B$4:L$4,0),"FALSO"),0) -> 3125044.3 | I13: =IFERROR(VLOOKUP($B13&$C13,'C. Gestión Pto #1'!$B$4:M$16,MATCH(I$5,'C. Gestión Pto #1'!$B$4:M$4,0),"FALSO"),0) -> 734909.88 | J13: =IFERROR(VLOOKUP($B13&$C13,'C. Gestión Pto #1'!$B$4:N$16,MATCH(J$5,'C. Gestión Pto #1'!$B$4:N$4,0),"FALSO"),0) -> 0 | L13: {=SUMPRODUCT($D13:$K13,TRANSPOSE('Indice CAC'!$E$12:$E$19))} -> 5329921.3 | N13: =IF($C13="MAT",SUMIF('Preventivo Costo CH2171 '!$A$9:$A$57,$B13,'Preventivo Costo CH2171 '!$I$9:$I$57),IF($C13="MO",SUMIF('Preventivo Costo CH2171 '!$A$9:$A$57,$B13,'Preventivo Costo CH2171 '!$L$9:$L$57),SUMIF('Preventivo Costo CH2171 '!$A$9:$A$57,$B13,'Preventivo Costo CH2171 '!$N$9:$N$57))) -> 14709293 | P13: =IF(O13=100%,0,IF(OR(L13<>0,N13),N13-L13)) -> 9379371.2 | Q13: =IF(OR(P13<0,N13),P13/N13,0%) -> 0.63764938 | R13: =IF(O13=100%,IF(OR(L13<>0,N13),N13-L13),0) -> 0
B14: Agrimensura | D14: =IFERROR(VLOOKUP($B14&$C14,'C. Gestión Pto #1'!$B$4:H$16,MATCH(D$5,'C. Gestión Pto #1'!$B$4:H$4,0),FALSE),0) -> 0 | E14: =IFERROR(VLOOKUP($B14&$C14,'C. Gestión Pto #1'!$B$4:I$16,MATCH(E$5,'C. Gestión Pto #1'!$B$4:I$4,0),"FALSO"),0) -> 0 | F14: =IFERROR(VLOOKUP($B14&$C14,'C. Gestión Pto #1'!$B$4:J$16,MATCH(F$5,'C. Gestión Pto #1'!$B$4:J$4,0),"FALSO"),0) -> 0 | G14: =IFERROR(VLOOKUP($B14&$C14,'C. Gestión Pto #1'!$B$4:K$16,MATCH(G$5,'C. Gestión Pto #1'!$B$4:K$4,0),"FALSO"),0) -> 0 | H14: =IFERROR(VLOOKUP($B14&$C14,'C. Gestión Pto #1'!$B$4:L$16,MATCH(H$5,'C. Gestión Pto #1'!$B$4:L$4,0),"FALSO"),0) -> 730000 | I14: =IFERROR(VLOOKUP($B14&$C14,'C. Gestión Pto #1'!$B$4:M$16,MATCH(I$5,'C. Gestión Pto #1'!$B$4:M$4,0),"FALSO"),0) -> 0 | J14: =IFERROR(VLOOKUP($B14&$C14,'C. Gestión Pto #1'!$B$4:N$16,MATCH(J$5,'C. Gestión Pto #1'!$B$4:N$4,0),"FALSO"),0) -> 0 | L14: {=SUMPRODUCT($D14:$K14,TRANSPOSE('Indice CAC'!$E$12:$E$19))} -> 610005.92 | N14: =IF($C14="MAT",SUMIF('Preventivo Costo CH2171 '!$A$9:$A$57,$B14,'Preventivo Costo CH2171 '!$I$9:$I$57),IF($C14="MO",SUMIF('Preventivo Costo CH2171 '!$A$9:$A$57,$B14,'Preventivo Costo CH2171 '!$L$9:$L$57),SUMIF('Preventivo Costo CH2171 '!$A$9:$A$57,$B14,'Preventivo Costo CH2171 '!$N$9:$N$57))) -> 1226538.2 | P14: =IF(O14=100%,0,IF(OR(L14<>0,N14),N14-L14)) -> 616532.32 | Q14: =IF(OR(P14<0,N14),P14/N14,0%) -> 0.5026605 | R14: =IF(O14=100%,IF(OR(L14<>0,N14),N14-L14),0) -> 0
B15: Seguridad e Higiene | D15: =IFERROR(VLOOKUP($B15&$C15,'C. Gestión Pto #1'!$B$4:H$16,MATCH(D$5,'C. Gestión Pto #1'!$B$4:H$4,0),"FALSO"),0) -> 0 | E15: =IFERROR(VLOOKUP($B15&$C15,'C. Gestión Pto #1'!$B$4:I$16,MATCH(E$5,'C. Gestión Pto #1'!$B$4:I$4,0),"FALSO"),0) -> 0 | F15: =IFERROR(VLOOKUP($B15&$C15,'C. Gestión Pto #1'!$B$4:J$16,MATCH(F$5,'C. Gestión Pto #1'!$B$4:J$4,0),"FALSO"),0) -> 0 | G15: =IFERROR(VLOOKUP($B15&$C15,'C. Gestión Pto #1'!$B$4:K$16,MATCH(G$5,'C. Gestión Pto #1'!$B$4:K$4,0),"FALSO"),0) -> 517195 | H15: =IFERROR(VLOOKUP($B15&$C15,'C. Gestión Pto #1'!$B$4:L$16,MATCH(H$5,'C. Gestión Pto #1'!$B$4:L$4,0),"FALSO"),0) -> 826285.91 | I15: =IFERROR(VLOOKUP($B15&$C15,'C. Gestión Pto #1'!$B$4:M$16,MATCH(I$5,'C. Gestión Pto #1'!$B$4:M$4,0),"FALSO"),0) -> 517195 | J15: =IFERROR(VLOOKUP($B15&$C15,'C. Gestión Pto #1'!$B$4:N$16,MATCH(J$5,'C. Gestión Pto #1'!$B$4:N$4,0),"FALSO"),0) -> 1195790 | L15: {=SUMPRODUCT($D15:$K15,TRANSPOSE('Indice CAC'!$E$12:$E$19))} -> 2519063.7 | N15: =IF($C15="MAT",SUMIF('Preventivo Costo CH2171 '!$A$9:$A$57,$B15,'Preventivo Costo CH2171 '!$I$9:$I$57),IF($C15="MO",SUMIF('Preventivo Costo CH2171 '!$A$9:$A$57,$B15,'Preventivo Costo CH2171 '!$L$9:$L$57),SUMIF('Preventivo Costo CH2171 '!$A$9:$A$57,$B15,'Preventivo Costo CH2171 '!$N$9:$N$57))) -> 4623254.5 | P15: =IF(O15=100%,0,IF(OR(L15<>0,N15),N15-L15)) -> 2104190.8 | Q15: =IF(OR(P15<0,N15),P15/N15,0%) -> 0.45513194 | R15: =IF(O15=100%,IF(OR(L15<>0,N15),N15-L15),0) -> 0
B16: Movilidad | D16: =IFERROR(VLOOKUP($B16&$C16,'C. Gestión Pto #1'!$B$4:H$16,MATCH(D$5,'C. Gestión Pto #1'!$B$4:H$4,0),"FALSO"),0) -> 0 | E16: =IFERROR(VLOOKUP($B16&$C16,'C. Gestión Pto #1'!$B$4:I$16,MATCH(E$5,'C. Gestión Pto #1'!$B$4:I$4,0),"FALSO"),0) -> 0 | F16: =IFERROR(VLOOKUP($B16&$C16,'C. Gestión Pto #1'!$B$4:J$16,MATCH(F$5,'C. Gestión Pto #1'!$B$4:J$4,0),"FALSO"),0) -> 0 | G16: =IFERROR(VLOOKUP($B16&$C16,'C. Gestión Pto #1'!$B$4:K$16,MATCH(G$5,'C. Gestión Pto #1'!$B$4:K$4,0),"FALSO"),0) -> 0 | H16: =IFERROR(VLOOKUP($B16&$C16,'C. Gestión Pto #1'!$B$4:L$16,MATCH(H$5,'C. Gestión Pto #1'!$B$4:L$4,0),"FALSO"),0) -> 639742.64 | I16: =IFERROR(VLOOKUP($B16&$C16,'C. Gestión Pto #1'!$B$4:M$16,MATCH(I$5,'C. Gestión Pto #1'!$B$4:M$4,0),"FALSO"),0) -> 716525.59 | J16: =IFERROR(VLOOKUP($B16&$C16,'C. Gestión Pto #1'!$B$4:N$16,MATCH(J$5,'C. Gestión Pto #1'!$B$4:N$4,0),"FALSO"),0) -> 38016.53 | L16: {=SUMPRODUCT($D16:$K16,TRANSPOSE('Indice CAC'!$E$12:$E$19))} -> 1153083.2 | N16: =IF($C16="MAT",SUMIF('Preventivo Costo CH2171 '!$A$9:$A$57,$B16,'Preventivo Costo CH2171 '!$I$9:$I$57),IF($C16="MO",SUMIF('Preventivo Costo CH2171 '!$A$9:$A$57,$B16,'Preventivo Costo CH2171 '!$L$9:$L$57),SUMIF('Preventivo Costo CH2171 '!$A$9:$A$57,$B16,'Preventivo Costo CH2171 '!$N$9:$N$57))) -> 8000000 | P16: =IF(O16=100%,0,IF(OR(L16<>0,N16),N16-L16)) -> 6846916.8 | Q16: =IF(OR(P16<0,N16),P16/N16,0%) -> 0.85586461 | R16: =IF(O16=100%,IF(OR(L16<>0,N16),N16-L16),0) -> 0
B17: Albañilería | C17: MAT | D17: =IFERROR(VLOOKUP($B17&$C17,'C. Gestión Pto #1'!$B$4:H$16,MATCH(D$5,'C. Gestión Pto #1'!$B$4:H$4,0),"FALSO"),0) -> 0 | E17: =IFERROR(VLOOKUP($B17&$C17,'C. Gestión Pto #1'!$B$4:I$16,MATCH(E$5,'C. Gestión Pto #1'!$B$4:I$4,0),"FALSO"),0) -> 0 | F17: =IFERROR(VLOOKUP($B17&$C17,'C. Gestión Pto #1'!$B$4:J$16,MATCH(F$5,'C. Gestión Pto #1'!$B$4:J$4,0),"FALSO"),0) -> 0 | G17: =IFERROR(VLOOKUP($B17&$C17,'C. Gestión Pto #1'!$B$4:K$16,MATCH(G$5,'C. Gestión Pto #1'!$B$4:K$4,0),"FALSO"),0) -> 48248.1 | H17: =IFERROR(VLOOKUP($B17&$C17,'C. Gestión Pto #1'!$B$4:L$16,MATCH(H$5,'C. Gestión Pto #1'!$B$4:L$4,0),"FALSO"),0) -> 95942.03 | I17: =IFERROR(VLOOKUP($B17&$C17,'C. Gestión Pto #1'!$B$4:M$16,MATCH(I$5,'C. Gestión Pto #1'!$B$4:M$4,0),"FALSO"),0) -> 371787.4 | J17: =IFERROR(VLOOKUP($B17&$C17,'C. Gestión Pto #1'!$B$4:N$16,MATCH(J$5,'C. Gestión Pto #1'!$B$4:N$4,0),"FALSO"),0) -> 171269.97 | L17: {=SUMPRODUCT($D17:$K17,TRANSPOSE('Indice CAC'!$E$12:$E$19))} -> 564374.82 | N17: =IF($C17="MAT",SUMIF('Preventivo Costo CH2171 '!$A$9:$A$57,$B17,'Preventivo Costo CH2171 '!$I$9:$I$57),IF($C17="MO",SUMIF('Preventivo Costo CH2171 '!$A$9:$A$57,$B17,'Preventivo Costo CH2171 '!$L$9:$L$57),SUMIF('Preventivo Costo CH2171 '!$A$9:$A$57,$B17,'Preventivo Costo CH2171 '!$N$9:$N$57))) -> 1000000 | P17: =IF(O17=100%,0,IF(OR(L17<>0,N17),N17-L17)) -> 435625.18 | Q17: =IF(OR(P17<0,N17),P17/N17,0%) -> 0.43562518 | R17: =IF(O17=100%,IF(OR(L17<>0,N17),N17-L17),0) -> 0
B18: Albañilería | C18: MO | D18: =IFERROR(VLOOKUP($B18&$C18,'C. Gestión Pto #1'!$B$4:H$16,MATCH(D$5,'C. Gestión Pto #1'!$B$4:H$4,0),"FALSO"),0) -> 0 | E18: =IFERROR(VLOOKUP($B18&$C18,'C. Gestión Pto #1'!$B$4:I$16,MATCH(E$5,'C. Gestión Pto #1'!$B$4:I$4,0),"FALSO"),0) -> 0 | F18: =IFERROR(VLOOKUP($B18&$C18,'C. Gestión Pto #1'!$B$4:J$16,MATCH(F$5,'C. Gestión Pto #1'!$B$4:J$4,0),"FALSO"),0) -> 0 | G18: =IFERROR(VLOOKUP($B18&$C18,'C. Gestión Pto #1'!$B$4:K$16,MATCH(G$5,'C. Gestión Pto #1'!$B$4:K$4,0),"FALSO"),0) -> 0 | H18: =IFERROR(VLOOKUP($B18&$C18,'C. Gestión Pto #1'!$B$4:L$16,MATCH(H$5,'C. Gestión Pto #1'!$B$4:L$4,0),"FALSO"),0) -> 0 | I18: =IFERROR(VLOOKUP($B18&$C18,'C. Gestión Pto #1'!$B$4:M$16,MATCH(I$5,'C. Gestión Pto #1'!$B$4:M$4,0),"FALSO"),0) -> 2330315.7 | J18: =IFERROR(VLOOKUP($B18&$C18,'C. Gestión Pto #1'!$B$4:N$16,MATCH(J$5,'C. Gestión Pto #1'!$B$4:N$4,0),"FALSO"),0) -> 0 | L18: {=SUMPRODUCT($D18:$K18,TRANSPOSE('Indice CAC'!$E$12:$E$19))} -> 1911725.5 | N18: =IF($C18="MAT",SUMIF('Preventivo Costo CH2171 '!$A$9:$A$57,$B18,'Preventivo Costo CH2171 '!$I$9:$I$57),IF($C18="MO",SUMIF('Preventivo Costo CH2171 '!$A$9:$A$57,$B18,'Preventivo Costo CH2171 '!$L$9:$L$57),SUMIF('Preventivo Costo CH2171 '!$A$9:$A$57,$B18,'Preventivo Costo CH2171 '!$N$9:$N$57))) -> 20558829 | P18: =IF(O18=100%,0,IF(OR(L18<>0,N18),N18-L18)) -> 18647104 | Q18: =IF(OR(P18<0,N18),P18/N18,0%) -> 0.90701195 | R18: =IF(O18=100%,IF(OR(L18<>0,N18),N18-L18),0) -> 0
B19: Excavación y Mov. de Suelos | D19: =IFERROR(VLOOKUP($B19&$C19,'C. Gestión Pto #1'!$B$4:H$16,MATCH(D$5,'C. Gestión Pto #1'!$B$4:H$4,0),"FALSO"),0) -> 0 | E19: =IFERROR(VLOOKUP($B19&$C19,'C. Gestión Pto #1'!$B$4:I$16,MATCH(E$5,'C. Gestión Pto #1'!$B$4:I$4,0),"FALSO"),0) -> 0 | F19: =IFERROR(VLOOKUP($B19&$C19,'C. Gestión Pto #1'!$B$4:J$16,MATCH(F$5,'C. Gestión Pto #1'!$B$4:J$4,0),"FALSO"),0) -> 0 | G19: =IFERROR(VLOOKUP($B19&$C19,'C. Gestión Pto #1'!$B$4:K$16,MATCH(G$5,'C. Gestión Pto #1'!$B$4:K$4,0),"FALSO"),0) -> 0 | H19: =IFERROR(VLOOKUP($B19&$C19,'C. Gestión Pto #1'!$B$4:L$16,MATCH(H$5,'C. Gestión Pto #1'!$B$4:L$4,0),"FALSO"),0) -> 0 | I19: =IFERROR(VLOOKUP($B19&$C19,'C. Gestión Pto #1'!$B$4:M$16,MATCH(I$5,'C. Gestión Pto #1'!$B$4:M$4,0),"FALSO"),0) -> 1310000 | J19: =IFERROR(VLOOKUP($B19&$C19,'C. Gestión Pto #1'!$B$4:N$16,MATCH(J$5,'C. Gestión Pto #1'!$B$4:N$4,0),"FALSO"),0) -> 0 | L19: {=SUMPRODUCT($D19:$K19,TRANSPOSE('Indice CAC'!$E$12:$E$19))} -> 1074687.2 | N19: =IF($C19="MAT",SUMIF('Preventivo Costo CH2171 '!$A$9:$A$57,$B19,'Preventivo Costo CH2171 '!$I$9:$I$57),IF($C19="MO",SUMIF('Preventivo Costo CH2171 '!$A$9:$A$57,$B19,'Preventivo Costo CH2171 '!$L$9:$L$57),SUMIF('Preventivo Costo CH2171 '!$A$9:$A$57,$B19,'Preventivo Costo CH2171 '!$N$9:$N$57))) -> 9462540.3 | P19: =IF(O19=100%,0,IF(OR(L19<>0,N19),N19-L19)) -> 8387853.1 | Q19: =IF(OR(P19<0,N19),P19/N19,0%) -> 0.8864272 | R19: =IF(O19=100%,IF(OR(L19<>0,N19),N19-L19),0) -> 0
B20: Hormigón | C20: MAT | D20: =IFERROR(VLOOKUP($B20&$C20,'C. Gestión Pto #1'!$B$4:H$16,MATCH(D$5,'C. Gestión Pto #1'!$B$4:H$4,0),"FALSO"),0) -> 0 | E20: =IFERROR(VLOOKUP($B20&$C20,'C. Gestión Pto #1'!$B$4:I$16,MATCH(E$5,'C. Gestión Pto #1'!$B$4:I$4,0),"FALSO"),0) -> 0 | F20: =IFERROR(VLOOKUP($B20&$C20,'C. Gestión Pto #1'!$B$4:J$16,MATCH(F$5,'C. Gestión Pto #1'!$B$4:J$4,0),"FALSO"),0) -> 0 | G20: =IFERROR(VLOOKUP($B20&$C20,'C. Gestión Pto #1'!$B$4:K$16,MATCH(G$5,'C. Gestión Pto #1'!$B$4:K$4,0),"FALSO"),0) -> 0 | H20: =IFERROR(VLOOKUP($B20&$C20,'C. Gestión Pto #1'!$B$4:L$16,MATCH(H$5,'C. Gestión Pto #1'!$B$4:L$4,0),"FALSO"),0) -> 20721536 | I20: =IFERROR(VLOOKUP($B20&$C20,'C. Gestión Pto #1'!$B$4:M$16,MATCH(I$5,'C. Gestión Pto #1'!$B$4:M$4,0),"FALSO"),0) -> 4488122.6 | J20: =IFERROR(VLOOKUP($B20&$C20,'C. Gestión Pto #1'!$B$4:N$16,MATCH(J$5,'C. Gestión Pto #1'!$B$4:N$4,0),"FALSO"),0) -> 13222352 | L20: {=SUMPRODUCT($D20:$K20,TRANSPOSE('Indice CAC'!$E$12:$E$19))} -> 31668388 | N20: =IF($C20="MAT",SUMIF('Preventivo Costo CH2171 '!$A$9:$A$57,$B20,'Preventivo Costo CH2171 '!$I$9:$I$57),IF($C20="MO",SUMIF('Preventivo Costo CH2171 '!$A$9:$A$57,$B20,'Preventivo Costo CH2171 '!$L$9:$L$57),SUMIF('Preventivo Costo CH2171 '!$A$9:$A$57,$B20,'Preventivo Costo CH2171 '!$N$9:$N$57))) -> 1.55289e+08 | P20: =IF(O20=100%,0,IF(OR(L20<>0,N20),N20-L20)) -> 1.2362062e+08 | Q20: =IF(OR(P20<0,N20),P20/N20,0%) -> 0.79606806 | R20: =IF(O20=100%,IF(OR(L20<>0,N20),N20-L20),0) -> 0
B21: Hormigón | C21: MO | D21: =IFERROR(VLOOKUP($B21&$C21,'C. Gestión Pto #1'!$B$4:H$16,MATCH(D$5,'C. Gestión Pto #1'!$B$4:H$4,0),"FALSO"),0) -> 0 | E21: =IFERROR(VLOOKUP($B21&$C21,'C. Gestión Pto #1'!$B$4:I$16,MATCH(E$5,'C. Gestión Pto #1'!$B$4:I$4,0),"FALSO"),0) -> 0 | F21: =IFERROR(VLOOKUP($B21&$C21,'C. Gestión Pto #1'!$B$4:J$16,MATCH(F$5,'C. Gestión Pto #1'!$B$4:J$4,0),"FALSO"),0) -> 0 | G21: =IFERROR(VLOOKUP($B21&$C21,'C. Gestión Pto #1'!$B$4:K$16,MATCH(G$5,'C. Gestión Pto #1'!$B$4:K$4,0),"FALSO"),0) -> 0 | H21: =IFERROR(VLOOKUP($B21&$C21,'C. Gestión Pto #1'!$B$4:L$16,MATCH(H$5,'C. Gestión Pto #1'!$B$4:L$4,0),"FALSO"),0) -> 19211836 | I21: =IFERROR(VLOOKUP($B21&$C21,'C. Gestión Pto #1'!$B$4:M$16,MATCH(I$5,'C. Gestión Pto #1'!$B$4:M$4,0),"FALSO"),0) -> 19661613 | J21: =IFERROR(VLOOKUP($B21&$C21,'C. Gestión Pto #1'!$B$4:N$16,MATCH(J$5,'C. Gestión Pto #1'!$B$4:N$4,0),"FALSO"),0) -> 30526436 | L21: {=SUMPRODUCT($D21:$K21,TRANSPOSE('Indice CAC'!$E$12:$E$19))} -> 56819928 | N21: =IF($C21="MAT",SUMIF('Preventivo Costo CH2171 '!$A$9:$A$57,$B21,'Preventivo Costo CH2171 '!$I$9:$I$57),IF($C21="MO",SUMIF('Preventivo Costo CH2171 '!$A$9:$A$57,$B21,'Preventivo Costo CH2171 '!$L$9:$L$57),SUMIF('Preventivo Costo CH2171 '!$A$9:$A$57,$B21,'Preventivo Costo CH2171 '!$N$9:$N$57))) -> 1.6857077e+08 | P21: =IF(O21=100%,0,IF(OR(L21<>0,N21),N21-L21)) -> 1.1175085e+08 | Q21: =IF(OR(P21<0,N21),P21/N21,0%) -> 0.66293132 | R21: =IF(O21=100%,IF(OR(L21<>0,N21),N21-L21),0) -> 0
B22: Equipos | D22: =IFERROR(VLOOKUP($B22&$C22,'C. Gestión Pto #1'!$B$4:H$16,MATCH(D$5,'C. Gestión Pto #1'!$B$4:H$4,0),"FALSO"),0) -> 0 | E22: =IFERROR(VLOOKUP($B22&$C22,'C. Gestión Pto #1'!$B$4:I$16,MATCH(E$5,'C. Gestión Pto #1'!$B$4:I$4,0),"FALSO"),0) -> 0 | F22: =IFERROR(VLOOKUP($B22&$C22,'C. Gestión Pto #1'!$B$4:J$16,MATCH(F$5,'C. Gestión Pto #1'!$B$4:J$4,0),"FALSO"),0) -> 0 | G22: =IFERROR(VLOOKUP($B22&$C22,'C. Gestión Pto #1'!$B$4:K$16,MATCH(G$5,'C. Gestión Pto #1'!$B$4:K$4,0),"FALSO"),0) -> 0 | H22: =IFERROR(VLOOKUP($B22&$C22,'C. Gestión Pto #1'!$B$4:L$16,MATCH(H$5,'C. Gestión Pto #1'!$B$4:L$4,0),"FALSO"),0) -> 0 | I22: =IFERROR(VLOOKUP($B22&$C22,'C. Gestión Pto #1'!$B$4:M$16,MATCH(I$5,'C. Gestión Pto #1'!$B$4:M$4,0),"FALSO"),0) -> 0 | J22: =IFERROR(VLOOKUP($B22&$C22,'C. Gestión Pto #1'!$B$4:N$16,MATCH(J$5,'C. Gestión Pto #1'!$B$4:N$4,0),"FALSO"),0) -> 702737.42 | L22: {=SUMPRODUCT($D22:$K22,TRANSPOSE('Indice CAC'!$E$12:$E$19))} -> 567140.81 | N22: =IF($C22="MAT",SUMIF('Preventivo Costo CH2171 '!$A$9:$A$57,$B22,'Preventivo Costo CH2171 '!$I$9:$I$57),IF($C22="MO",SUMIF('Preventivo Costo CH2171 '!$A$9:$A$57,$B22,'Preventivo Costo CH2171 '!$L$9:$L$57),SUM('Preventivo Costo CH2171 '!M9:M57))) -> 15976116 | P22: =IF(O22=100%,0,IF(OR(L22<>0,N22),N22-L22)) -> 15408975 | Q22: =IF(OR(P22<0,N22),P22/N22,0%) -> 0.96450071 | R22: =IF(O22=100%,IF(OR(L22<>0,N22),N22-L22),0) -> 0
B23: Gastos Generales Obra | D23: =IFERROR(VLOOKUP($B23&$C23,'C. Gestión Pto #1'!$B$4:H$16,MATCH(D$5,'C. Gestión Pto #1'!$B$4:H$4,0),"FALSO"),0) -> 0 | E23: =IFERROR(VLOOKUP($B23&$C23,'C. Gestión Pto #1'!$B$4:I$16,MATCH(E$5,'C. Gestión Pto #1'!$B$4:I$4,0),"FALSO"),0) -> 0 | F23: =IFERROR(VLOOKUP($B23&$C23,'C. Gestión Pto #1'!$B$4:J$16,MATCH(F$5,'C. Gestión Pto #1'!$B$4:J$4,0),"FALSO"),0) -> 0 | G23: =IFERROR(VLOOKUP($B23&$C23,'C. Gestión Pto #1'!$B$4:K$16,MATCH(G$5,'C. Gestión Pto #1'!$B$4:K$4,0),"FALSO"),0) -> 247000 | H23: =IFERROR(VLOOKUP($B23&$C23,'C. Gestión Pto #1'!$B$4:L$16,MATCH(H$5,'C. Gestión Pto #1'!$B$4:L$4,0),"FALSO"),0) -> 227000 | I23: =IFERROR(VLOOKUP($B23&$C23,'C. Gestión Pto #1'!$B$4:M$16,MATCH(I$5,'C. Gestión Pto #1'!$B$4:M$4,0),"FALSO"),0) -> 1101000 | J23: =IFERROR(VLOOKUP($B23&$C23,'C. Gestión Pto #1'!$B$4:N$16,MATCH(J$5,'C. Gestión Pto #1'!$B$4:N$4,0),"FALSO"),0) -> 1520000 | L23: {=SUMPRODUCT($D23:$K23,TRANSPOSE('Indice CAC'!$E$12:$E$19))} -> 2529400.2 | N23: =IF($C23="MAT",SUMIF('Preventivo Costo CH2171 '!$A$9:$A$57,$B23,'Preventivo Costo CH2171 '!$I$9:$I$57),IF($C23="MO",SUMIF('Preventivo Costo CH2171 '!$A$9:$A$57,$B23,'Preventivo Costo CH2171 '!$L$9:$L$57),SUMIF('Preventivo Costo CH2171 '!$A$9:$A$57,$B23,'Preventivo Costo CH2171 '!$N$9:$N$57))) -> 3712405 | P23: =IF(O23=100%,0,IF(OR(L23<>0,N23),N23-L23)) -> 1183004.8 | Q23: =IF(OR(P23<0,N23),P23/N23,0%) -> 0.31866264 | R23: =IF(O23=100%,IF(OR(L23<>0,N23),N23-L23),0) -> 0
B24: Supervisión de Obra | D24: =IFERROR(VLOOKUP($B24&$C24,'C. Gestión Pto #1'!$B$4:H$16,MATCH(D$5,'C. Gestión Pto #1'!$B$4:H$4,0),"FALSO"),0) -> 0 | E24: =IFERROR(VLOOKUP($B24&$C24,'C. Gestión Pto #1'!$B$4:I$16,MATCH(E$5,'C. Gestión Pto #1'!$B$4:I$4,0),"FALSO"),0) -> 0 | F24: =IFERROR(VLOOKUP($B24&$C24,'C. Gestión Pto #1'!$B$4:J$16,MATCH(F$5,'C. Gestión Pto #1'!$B$4:J$4,0),"FALSO"),0) -> 0 | G24: =IFERROR(VLOOKUP($B24&$C24,'C. Gestión Pto #1'!$B$4:K$16,MATCH(G$5,'C. Gestión Pto #1'!$B$4:K$4,0),"FALSO"),0) -> 0 | H24: =IFERROR(VLOOKUP($B24&$C24,'C. Gestión Pto #1'!$B$4:L$16,MATCH(H$5,'C. Gestión Pto #1'!$B$4:L$4,0),"FALSO"),0) -> 2800000 | I24: =IFERROR(VLOOKUP($B24&$C24,'C. Gestión Pto #1'!$B$4:M$16,MATCH(I$5,'C. Gestión Pto #1'!$B$4:M$4,0),"FALSO"),0) -> 2867000 | J24: =IFERROR(VLOOKUP($B24&$C24,'C. Gestión Pto #1'!$B$4:N$16,MATCH(J$5,'C. Gestión Pto #1'!$B$4:N$4,0),"FALSO"),0) -> 2850000 | L24: {=SUMPRODUCT($D24:$K24,TRANSPOSE('Indice CAC'!$E$12:$E$19))} -> 6991833.5 | N24: =IF($C24="MAT",SUMIF('Preventivo Costo CH2171 '!$A$9:$A$57,$B24,'Preventivo Costo CH2171 '!$I$9:$I$57),IF($C24="MO",SUMIF('Preventivo Costo CH2171 '!$A$9:$A$57,$B24,'Preventivo Costo CH2171 '!$L$9:$L$57),SUMIF('Preventivo Costo CH2171 '!$A$9:$A$57,$B24,'Preventivo Costo CH2171 '!$N$9:$N$57))) -> 32465089 | P24: =IF(O24=100%,0,IF(OR(L24<>0,N24),N24-L24)) -> 25473256 | Q24: =IF(OR(P24<0,N24),P24/N24,0%) -> 0.78463532 | R24: =IF(O24=100%,IF(OR(L24<>0,N24),N24-L24),0) -> 0
B25: Total Egresos de Obra | D25: =SUM(D13:D24) -> 0 | E25: =SUM(E13:E24) -> 0 | F25: =SUM(F13:F24) -> 939182.1 | G25: =SUM(G13:G24) -> 2352432 | H25: =SUM(H13:H24) -> 48377387 | I25: =SUM(I13:I24) -> 34098469 | J25: =SUM(J13:J24) -> 50226602 | L25: =SUM(L13:L24) -> 1.1173955e+08 | N25: =SUM(N13:N24) -> 4.3559384e+08 | P25: =IF(O25=100%,0,IF(OR(L25<>0,N25),N25-L25)) -> 3.2385429e+08 | Q25: =IF(OR(P25<0,N25),P25/N25,0%) -> 0.74347766 | R25: =SUM(R13:R23) -> 0
B27: Resultado Operativo | D27: =SUM(D8,D10,-D25) -> 0 | E27: =SUM(E8,E10,-E25) -> 0 | F27: =SUM(F8,F10,-F25) -> -939182.1 | G27: =SUM(G8,G10,-G25) -> -2352432 | H27: =SUM(H8,H10,-H25) -> 93029180 | I27: =SUM(I8,I10,-I25) -> 27179919 | J27: =SUM(J8,J10,-J25) -> -50226602 | L27: =SUM(L8,-L25) -> 59561804 | N27: =SUM(N8,-N25) -> -45283042
B28: Resultado Acumulado | D28: =D27 -> 0 | E28: =E27+D28 -> 0 | F28: =F27+E28 -> -939182.1 | G28: =G27+F28 -> -3291614.1 | H28: =H27+G28 -> 89737566 | I28: =I27+H28 -> 1.1691748e+08 | J28: =J27+I28 -> 66690883

Sheet Resumen Pto #2
S1: Actualizado | T1: 46156
B3: OBRA: CHIVILCOY 2171
B4: RESUMEN DE OBRA
D5: 45962 | E5: 45992 | F5: 46023 | G5: 46054 | H5: 46082 | I5: 46113 | J5: 46143 | L5: Acum. Descontado | N5: Previsto | O5: % Cert. Acum. | P5: Saldo Disponible | Q5: Disponible % | R5: Rubro Completado
B6: Ingresos de Obra
B7: Ingresos por certificados | D7: =SUMIFS(Certificados!$E$12:$E$21,Certificados!$A$12:$A$21,">="&DATE(2025,11,1),Certificados!$A$12:$A$21,"<="&DATE(2025,11,30),Certificados!$C$12:$C$21,"Pto. 2") -> 0 | E7: =SUMIFS(Certificados!$E$12:$E$21,Certificados!$A$12:$A$21,">="&DATE(2025,12,1),Certificados!$A$12:$A$21,"<="&DATE(2025,12,31),Certificados!$C$12:$C$21,"Pto. 2") -> 0 | F7: =SUMIFS(Certificados!$E$12:$E$21,Certificados!$A$12:$A$21,">="&DATE(2026,1,1),Certificados!$A$12:$A$21,"<="&DATE(2026,1,31),Certificados!$C$12:$C$21,"Pto. 2") -> 0 | G7: =SUMIFS(Certificados!$E$12:$E$21,Certificados!$A$12:$A$21,">="&DATE(2026,2,1),Certificados!$A$12:$A$21,"<="&DATE(2026,2,29),Certificados!$C$12:$C$21,"Pto. 2") -> 0 | H7: =SUMIFS(Certificados!$E$12:$E$21,Certificados!$A$12:$A$21,">="&DATE(2026,3,1),Certificados!$A$12:$A$21,"<="&DATE(2026,3,31),Certificados!$B$12:$B$21,"Pto 2") -> 0 | I7: =SUMIFS(Certificados!$E$12:$E$21,Certificados!$A$12:$A$21,">="&DATE(2026,4,1),Certificados!$A$12:$A$21,"<="&DATE(2026,4,30),Certificados!$B$12:$B$21,"Pto 2") -> 0 | J7: =SUMIFS(Certificados!$E$12:$E$21,Certificados!$A$12:$A$21,">="&DATE(2026,5,1),Certificados!$A$12:$A$21,"<="&DATE(2026,5,31),Certificados!$B$12:$B$21,"Pto 2") -> 0 | L7: =SUM(D7:K7) -> 0 | N7: =SUM(Facturacion!E5:E5) -> 6.1109415e+08 | P7: =IF(O7=100%,0,IF(OR(L7<>0,N7),N7-L7)) -> 6.1109415e+08 | Q7: =IF(OR(P7<0,N7),P7/N7,0%) -> 1 | R7: =IF(O7=100%,IF(OR(#REF!<>0,N7),N7-#REF!),0) -> 0
B8: Total Ingresos de Obra | D8: =SUM(D7) -> 0 | E8: =SUM(E7) -> 0 | F8: =SUM(F7) -> 0 | G8: =SUM(G7) -> 0 | H8: =SUM(H7) -> 0 | I8: =SUM(I7) -> 0 | J8: =SUM(J7) -> 0 | L8: =SUM(L7) -> 0 | N8: =SUM(N7) -> 6.1109415e+08 | P8: =SUM(P7) -> 6.1109415e+08 | Q8: =IF(OR(P8<0,N8),P8/N8,0%) -> 1 | R8: =SUM(R7) -> 0
B9: Actualización por CAC | D9: =SUMIFS(Certificados!$F$12:$F$21,Certificados!$A$12:$A$21,">="&DATE(2025,11,1),Certificados!$A$12:$A$21,"<="&DATE(2025,11,30),Certificados!$C$12:$C$21,"Pto. 2") -> 0 | E9: =SUMIFS(Certificados!$F$12:$F$21,Certificados!$A$12:$A$21,">="&DATE(2025,12,1),Certificados!$A$12:$A$21,"<="&DATE(2025,12,31),Certificados!$C$12:$C$21,"Pto. 2") -> 0 | F9: =SUMIFS(Certificados!$F$12:$F$21,Certificados!$A$12:$A$21,">="&DATE(2026,1,1),Certificados!$A$12:$A$21,"<="&DATE(2026,1,31),Certificados!$C$12:$C$21,"Pto. 2") -> 0 | G9: =SUMIFS(Certificados!$F$12:$F$21,Certificados!$A$12:$A$21,">="&DATE(2026,2,1),Certificados!$A$12:$A$21,"<="&DATE(2026,2,29),Certificados!$C$12:$C$21,"Pto. 2") -> 0 | H9: =SUMIFS(Certificados!$F$12:$F$21,Certificados!$A$12:$A$21,">="&DATE(2026,3,1),Certificados!$A$12:$A$21,"<="&DATE(2026,3,31),Certificados!$B$12:$B$21,"Pto 2") -> 0 | I9: =SUMIFS(Certificados!$F$12:$F$21,Certificados!$A$12:$A$21,">="&DATE(2026,4,1),Certificados!$A$12:$A$21,"<="&DATE(2026,4,30),Certificados!$B$12:$B$21,"Pto 2") -> 0 | J9: =SUMIFS(Certificados!$F$12:$F$21,Certificados!$A$12:$A$21,">="&DATE(2026,5,1),Certificados!$A$12:$A$21,"<="&DATE(2026,5,31),Certificados!$B$12:$B$21,"Pto 2") -> 0 | L9: =SUM(D9:K9) -> 0 | N9: 0 | O9: 0 | P9: =IF(O9=100%,0,IF(N9=0,N9,N9-L9)) -> 0 | Q9: =IF(OR(P9<0,N9),P9/N9,0%) -> 0 | R9: =IF(O9=100%,IF(OR(#REF!<>0,N9),N9-#REF!),0) -> 0
B10: Total Ingresos por CAC | D10: =SUM(D9) -> 0 | E10: =SUM(E9) -> 0 | F10: =SUM(F9) -> 0 | G10: =SUM(G9) -> 0 | H10: =SUM(H9) -> 0 | I10: =SUM(I9) -> 0 | J10: =SUM(J9) -> 0 | L10: =SUM(L9) -> 0 | N10: =SUM(N9) -> 0 | P10: =SUM(P9) -> 0 | Q10: =IF(OR(P10<0,N10),P10/N10,0%) -> 0 | R10: =SUM(R9) -> 0
B12: Costos de Obra
B13: Supervisión de Obra | D13: =IFERROR(VLOOKUP($B13&$C13,'C. Gestión Pto #2'!$B$4:C$22,MATCH(D$5,'C. Gestión Pto #2'!$B$4:C$4,0),FALSE),0) -> 0 | E13: =IFERROR(VLOOKUP($B13&$C13,'C. Gestión Pto #2'!$B$4:D$22,MATCH(E$5,'C. Gestión Pto #2'!$B$4:D$4,0),FALSE),0) -> 0 | F13: =IFERROR(VLOOKUP($B13&$C13,'C. Gestión Pto #2'!$B$4:E$22,MATCH(F$5,'C. Gestión Pto #2'!$B$4:E$4,0),FALSE),0) -> 0 | G13: =IFERROR(VLOOKUP($B13&$C13,'C. Gestión Pto #2'!$B$4:F$22,MATCH(G$5,'C. Gestión Pto #2'!$B$4:F$4,0),FALSE),0) -> 0 | H13: =IFERROR(VLOOKUP($B13&$C13,'C. Gestión Pto #2'!$B$4:G$22,MATCH(H$5,'C. Gestión Pto #2'!$B$4:G$4,0),FALSE),0) -> 0 | I13: =IFERROR(VLOOKUP($B13&$C13,'C. Gestión Pto #2'!$B$4:H$22,MATCH(I$5,'C. Gestión Pto #2'!$B$4:H$4,0),FALSE),0) -> 0 | J13: =IFERROR(VLOOKUP($B13&$C13,'C. Gestión Pto #2'!$B$4:I$22,MATCH(J$5,'C. Gestión Pto #2'!$B$4:I$4,0),FALSE),0) -> 0 | L13: {=SUMPRODUCT($D13:$K13,TRANSPOSE('Indice CAC'!$E$12:$E$19))} -> 0 | N13: =IF(C13="MAT",SUMIF('Preventivo Costo CH2171 '!$A$61:$A$224,$B13,'Preventivo Costo CH2171 '!$I$61:$I$224),IF(C13="MO",SUMIF('Preventivo Costo CH2171 '!$A$61:$A$224,$B13,'Preventivo Costo CH2171 '!$L$61:$L$224),SUMIF('Preventivo Costo CH2171 '!$A$61:$A$224,$B13,'Preventivo Costo CH2171 '!$N$61:$N$224))) -> 29218580 | P13: =IF(O13=100%,0,IF(OR(L13<>0,N13),N13-L13)) -> 29218580 | Q13: =IF(OR(P13<0,N13),P13/N13,0%) -> 1 | R13: =IF(O13=100%,IF(OR(#REF!<>0,N13),N13-#REF!),0) -> 0
B14: Seguridad e Higiene | D14: =IFERROR(VLOOKUP($B14&$C14,'C. Gestión Pto #2'!$B$4:C$22,MATCH(D$5,'C. Gestión Pto #2'!$B$4:C$4,0),FALSE),0) -> 0 | E14: =IFERROR(VLOOKUP($B14&$C14,'C. Gestión Pto #2'!$B$4:D$22,MATCH(E$5,'C. Gestión Pto #2'!$B$4:D$4,0),FALSE),0) -> 0 | F14: =IFERROR(VLOOKUP($B14&$C14,'C. Gestión Pto #2'!$B$4:E$22,MATCH(F$5,'C. Gestión Pto #2'!$B$4:E$4,0),FALSE),0) -> 0 | G14: =IFERROR(VLOOKUP($B14&$C14,'C. Gestión Pto #2'!$B$4:F$22,MATCH(G$5,'C. Gestión Pto #2'!$B$4:F$4,0),FALSE),0) -> 0 | H14: =IFERROR(VLOOKUP($B14&$C14,'C. Gestión Pto #2'!$B$4:G$22,MATCH(H$5,'C. Gestión Pto #2'!$B$4:G$4,0),FALSE),0) -> 0 | I14: =IFERROR(VLOOKUP($B14&$C14,'C. Gestión Pto #2'!$B$4:H$22,MATCH(I$5,'C. Gestión Pto #2'!$B$4:H$4,0),FALSE),0) -> 0 | J14: =IFERROR(VLOOKUP($B14&$C14,'C. Gestión Pto #2'!$B$4:I$22,MATCH(J$5,'C. Gestión Pto #2'!$B$4:I$4,0),FALSE),0) -> 0 | L14: {=SUMPRODUCT($D14:$K14,TRANSPOSE('Indice CAC'!$E$12:$E$19))} -> 0 | N14: =IF(C14="MAT",SUMIF('Preventivo Costo CH2171 '!$A$61:$A$224,$B14,'Preventivo Costo CH2171 '!$I$61:$I$224),IF(C14="MO",SUMIF('Preventivo Costo CH2171 '!$A$61:$A$224,$B14,'Preventivo Costo CH2171 '!$L$61:$L$224),SUMIF('Preventivo Costo CH2171 '!$A$61:$A$224,$B14,'Preventivo Costo CH2171 '!$N$61:$N$224))) -> 2700000 | P14: =IF(O14=100%,0,IF(OR(L14<>0,N14),N14-L14)) -> 2700000 | Q14: =IF(OR(P14<0,N14),P14/N14,0%) -> 1 | R14: =IF(O14=100%,IF(OR(#REF!<>0,N14),N14-#REF!),0) -> 0
B15: Movilidad | D15: =IFERROR(VLOOKUP($B15&$C15,'C. Gestión Pto #2'!$B$4:C$22,MATCH(D$5,'C. Gestión Pto #2'!$B$4:C$4,0),FALSE),0) -> 0 | E15: =IFERROR(VLOOKUP($B15&$C15,'C. Gestión Pto #2'!$B$4:D$22,MATCH(E$5,'C. Gestión Pto #2'!$B$4:D$4,0),FALSE),0) -> 0 | F15: =IFERROR(VLOOKUP($B15&$C15,'C. Gestión Pto #2'!$B$4:E$22,MATCH(F$5,'C. Gestión Pto #2'!$B$4:E$4,0),FALSE),0) -> 0 | G15: =IFERROR(VLOOKUP($B15&$C15,'C. Gestión Pto #2'!$B$4:F$22,MATCH(G$5,'C. Gestión Pto #2'!$B$4:F$4,0),FALSE),0) -> 0 | H15: =IFERROR(VLOOKUP($B15&$C15,'C. Gestión Pto #2'!$B$4:G$22,MATCH(H$5,'C. Gestión Pto #2'!$B$4:G$4,0),FALSE),0) -> 0 | I15: =IFERROR(VLOOKUP($B15&$C15,'C. Gestión Pto #2'!$B$4:H$22,MATCH(I$5,'C. Gestión Pto #2'!$B$4:H$4,0),FALSE),0) -> 0 | J15: =IFERROR(VLOOKUP($B15&$C15,'C. Gestión Pto #2'!$B$4:I$22,MATCH(J$5,'C. Gestión Pto #2'!$B$4:I$4,0),FALSE),0) -> 0 | L15: {=SUMPRODUCT($D15:$K15,TRANSPOSE('Indice CAC'!$E$12:$E$19))} -> 0 | N15: =IF(C15="MAT",SUMIF('Preventivo Costo CH2171 '!$A$61:$A$224,$B15,'Preventivo Costo CH2171 '!$I$61:$I$224),IF(C15="MO",SUMIF('Preventivo Costo CH2171 '!$A$61:$A$224,$B15,'Preventivo Costo CH2171 '!$L$61:$L$224),SUMIF('Preventivo Costo CH2171 '!$A$61:$A$224,$B15,'Preventivo Costo CH2171 '!$N$61:$N$224))) -> 7200000 | P15: =IF(O15=100%,0,IF(OR(L15<>0,N15),N15-L15)) -> 7200000 | Q15: =IF(OR(P15<0,N15),P15/N15,0%) -> 1 | R15: =IF(O15=100%,IF(OR(#REF!<>0,N15),N15-#REF!),0) -> 0
B16: Albañilería | C16: MAT | D16: =IFERROR(VLOOKUP($B16&$C16,'C. Gestión Pto #2'!$B$4:C$22,MATCH(D$5,'C. Gestión Pto #2'!$B$4:C$4,0),FALSE),0) -> 0 | E16: =IFERROR(VLOOKUP($B16&$C16,'C. Gestión Pto #2'!$B$4:D$22,MATCH(E$5,'C. Gestión Pto #2'!$B$4:D$4,0),FALSE),0) -> 0 | F16: =IFERROR(VLOOKUP($B16&$C16,'C. Gestión Pto #2'!$B$4:E$22,MATCH(F$5,'C. Gestión Pto #2'!$B$4:E$4,0),FALSE),0) -> 0 | G16: =IFERROR(VLOOKUP($B16&$C16,'C. Gestión Pto #2'!$B$4:F$22,MATCH(G$5,'C. Gestión Pto #2'!$B$4:F$4,0),FALSE),0) -> 0 | H16: =IFERROR(VLOOKUP($B16&$C16,'C. Gestión Pto #2'!$B$4:G$22,MATCH(H$5,'C. Gestión Pto #2'!$B$4:G$4,0),FALSE),0) -> 0 | I16: =IFERROR(VLOOKUP($B16&$C16,'C. Gestión Pto #2'!$B$4:H$22,MATCH(I$5,'C. Gestión Pto #2'!$B$4:H$4,0),FALSE),0) -> 0 | J16: =IFERROR(VLOOKUP($B16&$C16,'C. Gestión Pto #2'!$B$4:I$22,MATCH(J$5,'C. Gestión Pto #2'!$B$4:I$4,0),FALSE),0) -> 0 | L16: {=SUMPRODUCT($D16:$K16,TRANSPOSE('Indice CAC'!$E$12:$E$19))} -> 0 | N16: =IF(C16="MAT",SUMIF('Preventivo Costo CH2171 '!$A$61:$A$224,$B16,'Preventivo Costo CH2171 '!$I$61:$I$224),IF(C16="MO",SUMIF('Preventivo Costo CH2171 '!$A$61:$A$224,$B16,'Preventivo Costo CH2171 '!$L$61:$L$224),SUMIF('Preventivo Costo CH2171 '!$A$61:$A$224,$B16,'Preventivo Costo CH2171 '!$N$61:$N$224))) -> 70873304 | P16: =IF(O16=100%,0,IF(OR(L16<>0,N16),N16-L16)) -> 70873304 | Q16: =IF(OR(P16<0,N16),P16/N16,0%) -> 1 | R16: =IF(O16=100%,IF(OR(#REF!<>0,N16),N16-#REF!),0) -> 0
