Workbook
Name \0: #REF!
Name \0: #REF!
Name \0: #REF!
Name \c: #REF!
Name \c: #REF!
Name \E: #REF!
Name \E: #REF!
Name \i: #REF!
Name \j: #REF!
Name \m: #REF!
Name \P: #REF!
Name \P: #REF!
Name \P: #REF!
Name \P: #REF!
Name \P: #REF!
Name \r: #N/A
Name \x: #REF!
Name \z: #REF!
Name __________ben1: #REF!
Name __________ben1: #REF!
Name __________ben1: #REF!
Name __________ben1: #REF!
Name __________ben1: #REF!
Name __________ben1: #REF!
Name __________ben10: #REF!
Name __________ben10: #REF!
Name __________ben10: #REF!
Name __________ben10: #REF!
Name __________ben10: #REF!
Name __________ben15: #REF!
Name __________ben15: #REF!
Name __________ben15: #REF!
Name __________ben15: #REF!
Name __________BEN2: #REF!
Name __________BEN2: #REF!
Name __________BEN2: #REF!
Name __________BEN2: #REF!
Name __________ben20: #REF!
Name __________ben20: #REF!
Name __________ben20: #REF!
Name __________ben20: #REF!
Name __________ben20: #REF!
Name __________ben25: #REF!
Name __________ben25: #REF!
Name __________ben25: #REF!
Name __________ben25: #REF!
Name __________ben25: #REF!
Name __________BEN3: #REF!
Name __________BEN3: #REF!
Name __________BEN3: #REF!
Name __________BEN3: #REF!
Name __________BEN3: #REF!
Name __________BEN4: #REF!
Name __________BEN4: #REF!
Name __________BEN4: #REF!
Name __________BEN4: #REF!
Name __________ben5: #REF!
Name __________ben5: #REF!
Name __________ben5: #REF!
Name __________ben5: #REF!

Sheet AING SALV4140 03
F1: DÓLAR BNA | G1: DÓLAR MEP
F2: =+GGBB!G4 -> 1005 | G2: =+GGBB!H4 -> 1170
F4: 45590
B5: OBRA: EDIFICIO EL SALVADOR 4140
B6: PRESUPUESTO OBRA CIVIL
B7: Descripción | C7: U | D7: Cant | E7: P unit | F7: Subtotal
A8: 1 | B8: TAREAS PRELIMINARES | G8: =SUM(F9:F18) -> 24784163 | H8: =+G8/$G$218 -> 0.018338605
A9: 1.01 | B9: Limpieza y preparación del terreno - No cotiza | C9: gl | D9: 0 | E9: 0 | F9: =+E9*D9 -> 0
A10: 1.02 | B10: Topógrafo - Visita de obra replanteo | C10: un | D10: 3 | E10: 379588 | F10: =+E10*D10 -> 1138764
A11: 1.03 | B11: Cartel de Obra - No cotiza | C11: gl | D11: 0 | E11: 0 | F11: =+E11*D11 -> 0
A12: 1.04 | B12: Cerco de obra perimetral - En chapa C25 + Concertina + Porton corredizo | C12: ml | D12: 11 | E12: 141220 | F12: =+E12*D12 -> 1553420
A13: 1.05 | B13: Obrador colgante, pañol y ducha | C13: gl | D13: 1 | E13: 7548771 | F13: =+E13*D13 -> 7548771
A14: 1.06 | B14: Alquiler de baños quimicos y duchas portatiles | C14: mes | D14: 3 | E14: 392028 | F14: =+E14*D14 -> 1176084
A15: 1.07 | B15: Conexión pilar y luz de obra + Tablero de obra | C15: gl | D15: 1 | E15: 1731320 | F15: =+E15*D15 -> 1731320
A16: 1.08 | B16: Conexión agua de obra, tanque + bomba | C16: gl | D16: 1 | E16: 1405632 | F16: =+E16*D16 -> 1405632
A17: 1.09 | B17: Tramite luz de obra, certificado luz de obra (2) y medición PAT | C17: gl | D17: 1 | E17: 426487 | F17: =+E17*D17 -> 426487
A18: 1.1 | B18: Sistema de depresión de napas | C18: gl | D18: 1 | E18: 9803685 | F18: =+E18*D18 -> 9803685
A19: 2 | B19: MOVIMIENTO DE TIERRA, COMPACTACION Y RELLENO | G19: =SUM(F20:F22) -> 42017464 | H19: =+G19/$G$218 -> 0.031090082
A20: 2.01 | B20: Excavación a maquina para submuración y subsuelo | C20: m3 | D20: 1266 | E20: 33090 | F20: =+E20*D20 -> 41891940
A21: 2.02 | B21: Demolición y retiro de fundaciones existentes - No cotiza | C21: gl | D21: 0 | E21: 0 | F21: =+E21*D21 -> 0
A22: 2.03 | B22: Excavación manual para pozo de achique y bombeo | C22: m3 | D22: 2 | E22: 62762 | F22: =+E22*D22 -> 125524
A23: 3 | B23: ESTRUCTURA RESISTENTE | G23: =SUM(F24:F42) -> 477142865 | H23: =+G23/$G$218 -> 0.35305346
A24: 26.01 | B24: Hierro c/ corte y doblado | C24: kg | D24: 71835 | E24: 1676 | F24: =+E24*D24 -> 120395460
A25: 26.02 | B25: H° - inc hidrofugo, bombeo, piedra 6/12 | C25: m3 | D25: 641 | E25: 161742 | F25: =+E25*D25 -> 103676622
A26: 3.01 | B26: Hormigón de limpieza - e: 10 cm | C26: m3 | D26: 35 | E26: 314478 | F26: =+E26*D26 -> 11006730
A27: 3.02 | B27: Tabique submuración - H30 hidrófugo (95 kg/m3 de hierro) | C27: m3 | D27: 40 | E27: 482909 | F27: =+E27*D27 -> 19316360
A28: 3.03 | B28: Zapata corrida tabique - H30 hidrófugo (120 kg/m3) | C28: m3 | D28: 28 | E28: 394283 | F28: =+E28*D28 -> 11039924
A29: 3.04 | B29: Platea - H30 hidrófugo (95 kg/m3 de hierro) | C29: m3 | D29: 179 | E29: 193197 | F29: =+E29*D29 -> 34582263
A30: 3.05 | B30: Rampa - H30 (120 kg/m3 de hierro) | C30: m3 | D30: 10 | E30: 416850 | F30: =+E30*D30 -> 4168500
A31: 3.06 | B31: Losa maciza - H30 (110 kg/m3 de hierro) | C31: m3 | D31: 177 | E31: 285821 | F31: =+E31*D31 -> 50590317
A32: 3.07 | B32: Vigas - H30 (140 kg/m3 de hierro) | C32: m3 | D32: 65 | E32: 710813 | F32: =+E32*D32 -> 46202845
A33: 3.08 | B33: Vigas de H° visto - H30 (140 kg/m3 de hierro) | C33: m3 | D33: 12 | E33: 826182 | F33: =+E33*D33 -> 9914184
A34: 3.09 | B34: Tabiques - H30 (120 kg/m3 de hierro) | C34: m3 | D34: 28 | E34: 482909 | F34: =+E34*D34 -> 13521452
A35: 3.1 | B35: Columna - H30 (240 Kg/m3 de hierro) | C35: m3 | D35: 54 | E35: 426874 | F35: =+E35*D35 -> 23051196
... A42: 3.17 | B42: Picado de medianeras para columnas y vigas - Cotizado solo para PB y 1P, No contempla picado en SS | C42: m2 | D42: 93 | E42: 24580 | F42: =+E42*D42 -> 2285940
A43: 4 | B43: ALBAÑILERIA | G43: =SUM(F44:F51) -> 54302890 | H43: =+G43/$G$218 -> 0.040180467
A44: 4.01 | B44: Muro tipo 1 (interiores, divisorio de locales) e: 10 cm - Ladrillo hueco 08 x 18 x 33 | C44: m2 | D44: 819 | E44: 18993 | F44: =+E44*D44 -> 15555267
A45: 4.02 | B45: Muro tipo 2 y 3 (medianera, caja de escaleras y ascensor) e: 15 cm - Ladrillo hueco portante 12 x 19 x 33 | C45: m2 | D45: 612 | E45: 25172 | F45: =+E45*D45 -> 15405264
A46: 4.03 | B46: Muro tipo 4 (divisorio de unidades y fachas) e: 15 cm - Ladrillo hueco 12 x 18 x 33 | C46: m2 | D46: 636 | E46: 21109 | F46: =+E46*D46 -> 13425324
A47: 4.04 | B47: Enchape medianeras existentes - Contemplamos picado zonas sueltas y enchape con ladrillo comun para PB | C47: m2 | D47: 195 | E47: 15092 | F47: =+E47*D47 -> 2942940
...

Sheet INFO.
C2: USD | F2: DÓLAR MEP
B3: VALOR ESTIMADO REFERENCIA COSTO | F3: =+GGBB!H4 -> 1170
D4: Coef Complej
C5: m2 | D5: 1 | E5: USD/ m2
B6: SUPERFICIE CUBIERTA | C6: =+F18 -> 1618.5 | D6: =+C3*D5 -> 0 | E6: =+F30 -> 972.38077 | F6: =+E6*F3*C6 -> 1.841344e+09 | G6: Valor estimado precio de venta
B8: Lote | C8: 344 | D8: m2 | E8: 0.75 | F8: SS
B9: Pisada | C9: 284 | D9: m2 | E9: 0.25 | F9: Patios
E10: 0.5 | F10: Balcones y semicubiertos
B11: Superficie | C11: Cubierto | D11: Semicubierto | E11: % | F11: Subtotal
B12: SS | C12: 0 | D12: 344 | E12: =+D12*$E$8 -> 258 | F12: =+C12+E12 -> 258
B13: PB | C13: 214 | D13: 130 | E13: =+D13*$E$9 -> 32.5 | F13: =+C13+E13 -> 246.5
B14: P 1º | C14: 251 | D14: 30 | E14: =+D14*$E$10 -> 15 | F14: =+C14+E14 -> 266 | G14: 2 | H14: planta tipo
B15: P 2° a 3° | C15: =+C14*G14 -> 502 | D15: =+D14*G14 -> 60 | E15: =+D15*$E$10 -> 30 | F15: =+C15+E15 -> 532
B16: P 4º | C16: 234 | D16: 47 | E16: =+D16*$E$10 -> 23.5 | F16: =+C16+E16 -> 257.5
B17: P Azotea | D17: 234 | E17: =+D17*$E$9 -> 58.5 | F17: =+C17+E17 -> 58.5
C18: =SUM(C12:C17) -> 1201 | D18: =SUM(D12:D17) -> 845 | E18: =SUM(E12:E17) -> 417.5 | F18: =SUM(F12:F17) -> 1618.5
H19: usd/m2
B20: OBRA CIVIL | E20: 0.7 | F20: =+'01'!W216 -> 1.1274028e+09 | G20: =+F20/F3 -> 963592.1 | H20: =+G20/C6 -> 595.3612
B21: PROVISIONES | E21: =1-E20 -> 0.3 | F21: =+G21*F20 -> 4.8317261e+08 | G21: =+E21/E20 -> 0.42857143
F22: =+F21+F20 -> 1.6105754e+09
B23: ARQ CLARIN
B24: 45588 | C24: Fecha | J24: Inc. | L24: =1+0.12+0.15 -> 1.27
I25: Electricidad | J25: 0.09 | K25: =+J25*F6 -> 1.6572096e+08 | L25: =+$L$24*K25 -> 2.1046562e+08
B26: (se toma MODELO 6 Vivienda en altura) | C26: m2 | D26: $/ m2 | I26: Sanitaria s/ calef | J26: 0.08 | K26: =+J26*F6 -> 1.4730752e+08 | L26: =+$L$24*K26 -> 1.8708055e+08
B27: VALOR ESTIMADO REFERENCIA COSTO | C27: =+C6 -> 1618.5 | D27: 1625265 | F27: =+D27*C27 -> 2.6304914e+09 | G27: Valor estimado precio de venta
D28: usd/m2 | F28: =+F27/F3 -> 2248283.2 | G28: USD
D29: =+D27/F3 -> 1389.1154 | F29: =+F28/C27 -> 1389.1154 | G29: usd/m2
F30: =+F29*E20 -> 972.38077 | G30: usd/m2 sin provisiones

Sheet 01
F1: OK | G1: Listo | V1: DÓLAR BNA | W1: DÓLAR MEP
F2: IN | G2: Estimado | V2: =+GGBB!G4 -> 1005 | W2: =+GGBB!H4 -> 1170
F3: C | G3: Chekear (Inventado)
F4: R | G4: Sin hacer/revisar | T4: 1 | V4: 45590
C5: OBRA: EDIFICIO EL SALVADOR 4140 | F5: MATERIAL | I5: M. DE OBRA | N5: MATERIAL | P5: M. DE OBRA | T5: =+GGBB!F66 -> 1.2568826
C6: PRESUPUESTO OBRA CIVIL | T6: 1.1
C7: Descripción | D7: U | E7: Cant | F7: Otro | G7: Corralón | H7: Total | I7: Otro | J7: Albañil | K7: Total | L7: EQUIPOS | M7: P.Unit | N7: Otro | O7: Corralón | P7: Otro | Q7: Albañil | R7: EQUIPOS | S7: Total | T7: Subtotal | U7: P unit | V7: Subtotal
A8: 1 | B8: E | C8: TAREAS PRELIMINARES | T8: =SUM(S9:S18) -> 19718747 | W8: =SUM(V9:V18) -> 24784163 | X8: =+W8/$W$216 -> 0.021983415 | Y8: =+W8 -> 24784163
A9: 1.01 | B9: OK | C9: Limpieza y preparación del terreno - No cotiza | D9: gl | E9: 0 | H9: =F9+G9 -> 0 | K9: =I9+J9 -> 0 | M9: =H9+K9+L9 -> 0 | N9: =F9*E9 -> 0 | O9: =G9*E9 -> 0 | P9: =I9*E9 -> 0 | Q9: =J9*E9 -> 0 | R9: =+L9*E9 -> 0 | S9: =SUM(N9:R9) -> 0 | U9: =+ROUNDUP(M9*$T$5,0) -> 0 | V9: =+U9*E9 -> 0
A10: 1.02 | B10: OK | C10: Topógrafo - Visita de obra replanteo | D10: un | E10: 3 | F10: =+Tareas!H8 -> 0 | G10: =+Tareas!I8 -> 41666.667 | H10: =F10+G10 -> 41666.667 | I10: =+Tareas!Q8 -> 172653.21 | J10: =+Tareas!R8 -> 83223.729 | K10: =I10+J10 -> 255876.94 | L10: =+(H10+K10)*0.015 -> 4463.1541 | M10: =H10+K10+L10 -> 302006.76 | N10: =F10*E10 -> 0 | O10: =G10*E10 -> 125000 | P10: =I10*E10 -> 517959.62 | Q10: =J10*E10 -> 249671.19 | R10: =+L10*E10 -> 13389.462 | S10: =SUM(N10:R10) -> 906020.27 | U10: =+ROUNDUP(M10*$T$5,0) -> 379588 | V10: =+U10*E10 -> 1138764
A11: 1.03 | B11: OK | C11: Cartel de Obra - No cotiza | D11: gl | E11: 0 | H11: =F11+G11 -> 0 | K11: =I11+J11 -> 0 | M11: =H11+K11+L11 -> 0 | N11: =F11*E11 -> 0 | O11: =G11*E11 -> 0 | P11: =I11*E11 -> 0 | Q11: =J11*E11 -> 0 | R11: =+L11*E11 -> 0 | S11: =SUM(N11:R11) -> 0 | U11: =+ROUNDUP(M11*$T$5,0) -> 0 | V11: =+U11*E11 -> 0
A12: 1.04 | B12: OK | C12: Cerco de obra perimetral - En chapa C25 + Concertina + Porton corredizo | D12: ml | E12: 11 | F12: =+Tareas!H12 -> 79773.183 | G12: =+Tareas!I12 -> 0 | H12: =F12+G12 -> 79773.183 | I12: =+Tareas!Q12 -> 0 | J12: =+Tareas!R12 -> 30923.374 | K12: =I12+J12 -> 30923.374 | L12: =+(H12+K12)*0.015 -> 1660.4484 | M12: =H12+K12+L12 -> 112357.01 | N12: =F12*E12 -> 877505.01 | O12: =G12*E12 -> 0 | P12: =I12*E12 -> 0 | Q12: =J12*E12 -> 340157.11 | R12: =+L12*E12 -> 18264.932 | S12: =SUM(N12:R12) -> 1235927.1 | U12: =+ROUNDUP(M12*$T$5,0) -> 141220 | V12: =+U12*E12 -> 1553420
A13: 1.05 | B13: OK | C13: Obrador colgante, pañol y ducha | D13: gl | E13: 1 | F13: =+Tareas!H22 -> 2300856.7 | G13: =+Tareas!I22 -> 100000 | H13: =F13+G13 -> 2400856.7 | I13: =+Tareas!Q22 -> 500000 | J13: =+Tareas!R22 -> 3016332.5 | K13: =I13+J13 -> 3516332.5 | L13: =+(H13+K13)*0.015 -> 88757.838 | M13: =H13+K13+L13 -> 6005947 | N13: =F13*E13 -> 2300856.7 | O13: =G13*E13 -> 100000 | P13: =I13*E13 -> 500000 | Q13: =J13*E13 -> 3016332.5 | R13: =+L13*E13 -> 88757.838 | S13: =SUM(N13:R13) -> 6005947 | U13: =+ROUNDUP(M13*$T$5,0) -> 7548771 | V13: =+U13*E13 -> 7548771
A14: 1.06 | B14: OK | C14: Alquiler de baños quimicos y duchas portatiles | D14: mes | E14: 3 | H14: =F14+G14 -> 0 | I14: =+Cotizaciones!D46*4 -> 295488.56 | J14: =+(Cotizaciones!D47*2*2)/'01'!E14 -> 16416.031 | K14: =I14+J14 -> 311904.59 | M14: =H14+K14+L14 -> 311904.59 | N14: =F14*E14 -> 0 | O14: =G14*E14 -> 0 | P14: =I14*E14 -> 886465.68 | Q14: =J14*E14 -> 49248.093 | R14: =+L14*E14 -> 0 | S14: =SUM(N14:R14) -> 935713.77 | U14: =+ROUNDUP(M14*$T$5,0) -> 392028 | V14: =+U14*E14 -> 1176084
A15: 1.07 | B15: OK | C15: Conexión pilar y luz de obra + Tablero de obra | D15: gl | E15: 1 | F15: =+Tareas!H44 -> 795578.51 | G15: =+Tareas!I44 -> 50000 | H15: =F15+G15 -> 845578.51 | I15: =+Tareas!Q44 -> 0 | J15: =+Tareas!R44 -> 511535.56 | K15: =I15+J15 -> 511535.56 | L15: =+(H15+K15)*0.015 -> 20356.711 | M15: =H15+K15+L15 -> 1377470.8 | N15: =F15*E15 -> 795578.51 | O15: =G15*E15 -> 50000 | P15: =I15*E15 -> 0 | Q15: =J15*E15 -> 511535.56 | R15: =+L15*E15 -> 20356.711 | S15: =SUM(N15:R15) -> 1377470.8 | U15: =+ROUNDUP(M15*$T$5,0) -> 1731320 | V15: =+U15*E15 -> 1731320
A16: 1.08 | B16: OK | C16: Conexión agua de obra, tanque + bomba | D16: gl | E16: 1 | F16: =+Tareas!H51 -> 680400 | G16: =+Tareas!I51 -> 0 | H16: =F16+G16 -> 680400 | I16: =+Tareas!Q51 -> 0 | J16: =+Tareas!R51 -> 421419.89 | K16: =I16+J16 -> 421419.89 | L16: =+(H16+K16)*0.015 -> 16527.298 | M16: =H16+K16+L16 -> 1118347.2 | N16: =F16*E16 -> 680400 | O16: =G16*E16 -> 0 | P16: =I16*E16 -> 0 | Q16: =J16*E16 -> 421419.89 | R16: =+L16*E16 -> 16527.298 | S16: =SUM(N16:R16) -> 1118347.2 | U16: =+ROUNDUP(M16*$T$5,0) -> 1405632 | V16: =+U16*E16 -> 1405632
A17: 1.09 | B17: OK | C17: Tramite luz de obra, certificado luz de obra (2) y medición PAT | D17: gl | E17: 1 | F17: =+Tareas!H61 -> 0 | G17: =+Tareas!I61 -> 0 | H17: =F17+G17 -> 0 | I17: =+Tareas!Q61 -> 339320.84 | J17: =+Tareas!R61 -> 0 | K17: =I17+J17 -> 339320.84 | M17: =H17+K17+L17 -> 339320.84 | N17: =F17*E17 -> 0 | O17: =G17*E17 -> 0 | P17: =I17*E17 -> 339320.84 | Q17: =J17*E17 -> 0 | R17: =+L17*E17 -> 0 | S17: =SUM(N17:R17) -> 339320.84 | U17: =+ROUNDUP(M17*$T$5,0) -> 426487 | V17: =+U17*E17 -> 426487
A18: 1.1 | B18: OK | C18: Sistema de depresión de napas | D18: gl | E18: 1 | H18: =F18+G18 -> 0 | I18: =+SUBCONTRATOS!D67 -> 7800000 | K18: =I18+J18 -> 7800000 | M18: =H18+K18+L18 -> 7800000 | N18: =F18*E18 -> 0 | O18: =G18*E18 -> 0 | P18: =I18*E18 -> 7800000 | Q18: =J18*E18 -> 0 | R18: =+L18*E18 -> 0 | S18: =SUM(N18:R18) -> 7800000 | U18: =+ROUNDUP(M18*$T$5,0) -> 9803685 | V18: =+U18*E18 -> 9803685
A19: 2 | C19: MOVIMIENTO DE TIERRA, COMPACTACION Y RELLENO | T19: =SUM(S20:S22) -> 33429552 | W19: =SUM(V20:V22) -> 42017464 | X19: =+W19/$W$216 -> 0.037269258 | Y19: =+W19 -> 42017464
A20: 2.01 | B20: OK | C20: Excavación a maquina para submuración y subsuelo | D20: m3 | E20: =+'H°A° '!H69 -> 1266 | F20: =+Tareas!H66 -> 0 | G20: =+Tareas!I66 -> 0 | H20: =F20+G20 -> 0 | I20: =+Tareas!Q66 -> 18400 | J20: =+Tareas!R66 -> 7809.62 | K20: =I20+J20 -> 26209.62 | L20: =+J20*0.015 -> 117.1443 | M20: =H20+K20+L20 -> 26326.764 | N20: =F20*E20 -> 0 | O20: =G20*E20 -> 0 | P20: =I20*E20 -> 23294400 | Q20: =J20*E20 -> 9886979 | R20: =+L20*E20 -> 148304.68 | S20: =SUM(N20:R20) -> 33329684 | U20: =+ROUNDUP(M20*$T$5,0) -> 33090 | V20: =+U20*E20 -> 41891940
A21: 2.02 | B21: OK | C21: Demolición y retiro de fundaciones existentes - No cotiza | D21: gl | E21: 0 | H21: =F21+G21 -> 0 | K21: =I21+J21 -> 0 | M21: =H21+K21+L21 -> 0 | N21: =F21*E21 -> 0 | O21: =G21*E21 -> 0 | P21: =I21*E21 -> 0 | Q21: =J21*E21 -> 0 | R21: =+L21*E21 -> 0 | S21: =SUM(N21:R21) -> 0 | U21: =+ROUNDUP(M21*$T$5,0) -> 0 | V21: =+U21*E21 -> 0
A22: 2.03 | B22: OK | C22: Excavación manual para pozo de achique y bombeo | D22: m3 | E22: =+'H°A° '!H87 -> 2 | H22: =F22+G22 -> 0 | J22: =+'P.MO 09.24'!B7 -> 49934.237 | K22: =I22+J22 -> 49934.237 | M22: =H22+K22+L22 -> 49934.237 | N22: =F22*E22 -> 0 | O22: =G22*E22 -> 0 | P22: =I22*E22 -> 0 | Q22: =J22*E22 -> 99868.474 | R22: =+L22*E22 -> 0 | S22: =SUM(N22:R22) -> 99868.474 | U22: =+ROUNDUP(M22*$T$5,0) -> 62762 | V22: =+U22*E22 -> 125524 | AB22: m3
A23: 3 | C23: ESTRUCTURA RESISTENTE | T23: =SUM(S24:S40) -> 2.0134759e+08 | W23: =SUM(V24:V40) -> 253070783 | X23: =+W23/$W$216 -> 0.22447238 | Y23: =+W23 -> 253070783 | AA23: =+SUM(P24:Q39)+Q20 -> 1.5859354e+08
A24: 3.01 | B24: OK | C24: Hormigón de limpieza - e: 10 cm | D24: m3 | E24: =+'H°A° '!E93 -> 35 | F24: =+Cotizaciones!D23+Cotizaciones!D27 -> 120430 | G24: =+Cotizaciones!D26*5/'01'!E24 -> 76142.857 | H24: =F24+G24 -> 196572.86 | J24: =+'P.MO 09.24'!B7 -> 49934.237 | K24: =I24+J24 -> 49934.237 | L24: =+(H24+K24)*0.015 -> 3697.6064 | M24: =H24+K24+L24 -> 250204.7 | N24: =F24*E24 -> 4215050 | O24: =G24*E24 -> 2665000 | P24: =I24*E24 -> 0 | Q24: =J24*E24 -> 1747698.3 | R24: =+L24*E24 -> 129416.22 | S24: =SUM(N24:R24) -> 8757164.5 | U24: =+ROUNDUP(M24*$T$5,0) -> 314478 | V24: =+U24*E24 -> 11006730 | Z24: EL SALVADOR 4041 | AA24: =+AA23/Z25 -> 1.0572902e+08 | AB24: 607 | AC24: =+AA24/AB24 -> 174182.91 | AD24: =+AC24/AC26 -> 0.76640478
A25: 3.02 | B25: OK | C25: Tabique submuración - H30 hidrófugo (95 kg/m3 de hierro) | D25: m3 | E25: =+'H°A° '!M5 -> 40 | F25: =+'H°A° '!F47 -> 70843.446 | H25: =F25+G25 -> 70843.446 | I25: =+'MO HA AING'!D72 -> 307690.19 | K25: =I25+J25 -> 307690.19 | L25: =+(H25+K25)*0.015 -> 5678.0046 | M25: =H25+K25+L25 -> 384211.64 | N25: =F25*E25 -> 2833737.8 | O25: =G25*E25 -> 0 | P25: =I25*E25 -> 12307608 | Q25: =J25*E25 -> 0 | R25: =+L25*E25 -> 227120.18 | S25: =SUM(N25:R25) -> 15368466 | U25: =+ROUNDUP(M25*$T$5,0) -> 482909 | V25: =+U25*E25 -> 19316360 | Z25: 1.5
A26: 3.03 | B26: OK | C26: Zapata corrida tabique - H30 hidrófugo (120 kg/m3) | D26: m3 | E26: =+'H°A° '!M7 -> 28 | F26: =+'H°A° '!F46 -> 55068.822 | H26: =F26+G26 -> 55068.822 | I26: =+'MO HA AING'!C6 -> 253994.14 | K26: =I26+J26 -> 253994.14 | L26: =+(H26+K26)*0.015 -> 4635.9445 | M26: =H26+K26+L26 -> 313698.91 | N26: =F26*E26 -> 1541927 | O26: =G26*E26 -> 0 | P26: =I26*E26 -> 7111836 | Q26: =J26*E26 -> 0 | R26: =+L26*E26 -> 129806.45 | S26: =SUM(N26:R26) -> 8783569.5 | U26: =+ROUNDUP(M26*$T$5,0) -> 394283 | V26: =+U26*E26 -> 11039924 | Z26: MNS 2920 | AA26: 75000000 | AB26: 330 | AC26: =+AA26/AB26 -> 227272.73
A27: 3.04 | B27: OK | C27: Platea - H30 hidrófugo (95 kg/m3 de hierro) | D27: m3 | E27: =+'H°A° '!M6 -> 179 | F27: =+'H°A° '!F50 -> 2471.4098 | H27: =F27+G27 -> 2471.4098 | I27: =+'MO HA AING'!C5*0.85 -> 148967.56 | K27: =I27+J27 -> 148967.56 | L27: =+(H27+K27)*0.015 -> 2271.5846 | M27: =H27+K27+L27 -> 153710.56 | N27: =F27*E27 -> 442382.35 | O27: =G27*E27 -> 0 | P27: =I27*E27 -> 26665194 | Q27: =J27*E27 -> 0 | R27: =+L27*E27 -> 406613.65 | S27: =SUM(N27:R27) -> 27514190 | U27: =+ROUNDUP(M27*$T$5,0) -> 193197 | V27: =+U27*E27 -> 34582263
A28: 3.05 | B28: OK | C28: Rampa - H30 (120 kg/m3 de hierro) | D28: m3 | E28: =+'H°A° '!M4 -> 10 | F28: =+'H°A° '!F52 -> 40150.005 | H28: =F28+G28 -> 40150.005 | I28: =+'MO HA AING'!D123 -> 191068.28 | J28: =+I28*0.5 -> 95534.142 | K28: =I28+J28 -> 286602.43 | L28: =+(H28+K28)*0.015 -> 4901.2865 | M28: =H28+K28+L28 -> 331653.72 | N28: =F28*E28 -> 401500.05 | O28: =G28*E28 -> 0 | P28: =I28*E28 -> 1910682.8 | Q28: =J28*E28 -> 955341.42 | R28: =+L28*E28 -> 49012.865 | S28: =SUM(N28:R28) -> 3316537.2 | U28: =+ROUNDUP(M28*$T$5,0) -> 416850 | V28: =+U28*E28 -> 4168500
A29: 3.06 | B29: OK | C29: Losa maciza - H30 (110 kg/m3 de hierro) | D29: m3 | E29: =+'H°A° '!M8 -> 177 | F29: =+'H°A° '!F51 -> 32975.501 | H29: =F29+G29 -> 32975.501 | I29: =+'MO HA AING'!D123 -> 191068.28 | K29: =I29+J29 -> 191068.28 | L29: =+(H29+K29)*0.015 -> 3360.6568 | M29: =H29+K29+L29 -> 227404.44 | N29: =F29*E29 -> 5836663.8 | O29: =G29*E29 -> 0 | P29: =I29*E29 -> 33819086 | Q29: =J29*E29 -> 0 | R29: =+L29*E29 -> 594836.25 | S29: =SUM(N29:R29) -> 40250586 | U29: =+ROUNDUP(M29*$T$5,0) -> 285821 | V29: =+U29*E29 -> 50590317
A30: 3.07 | B30: OK | C30: Vigas - H30 (140 kg/m3 de hierro) | D30: m3 | E30: =+'H°A° '!M9 -> 65 | F30: =+'H°A° '!F53 -> 94228.958 | H30: =F30+G30 -> 94228.958 | I30: =+'MO HA AING'!D99 -> 462949.29 | K30: =I30+J30 -> 462949.29 | L30: =+(H30+K30)*0.015 -> 8357.6737 | M30: =H30+K30+L30 -> 565535.92 | N30: =F30*E30 -> 6124882.3 | O30: =G30*E30 -> 0 | P30: =I30*E30 -> 30091704 | Q30: =J30*E30 -> 0 | R30: =+L30*E30 -> 543248.79 | S30: =SUM(N30:R30) -> 36759835 | U30: =+ROUNDUP(M30*$T$5,0) -> 710813 | V30: =+U30*E30 -> 46202845
A31: 3.08 | B31: OK | C31: Vigas de H° visto - H30 (140 kg/m3 de hierro) | D31: m3 | E31: =+'H°A° '!M13 -> 12 | F31: =+'H°A° '!F54 -> 92072.317 | H31: =F31+G31 -> 92072.317 | I31: =+'MO HA AING'!D99 -> 462949.29 | J31: =+I31*0.2 -> 92589.858 | K31: =I31+J31 -> 555539.15 | L31: =+(H31+K31)*0.015 -> 9714.172 | M31: =H31+K31+L31 -> 657325.64 | N31: =F31*E31 -> 1104867.8 | O31: =G31*E31 -> 0 | P31: =I31*E31 -> 5555391.5 | Q31: =J31*E31 -> 1111078.3 | R31: =+L31*E31 -> 116570.06 | S31: =SUM(N31:R31) -> 7887907.6 | U31: =+ROUNDUP(M31*$T$5,0) -> 826182 | V31: =+U31*E31 -> 9914184
A32: 3.09 | B32: OK | C32: Tabiques - H30 (120 kg/m3 de hierro) | D32: m3 | E32: =+'H°A° '!M10 -> 28 | F32: =+'H°A° '!F55 -> 70843.446 | H32: =F32+G32 -> 70843.446 | I32: =+'MO HA AING'!D72 -> 307690.19 | K32: =I32+J32 -> 307690.19 | L32: =+(H32+K32)*0.015 -> 5678.0046 | M32: =H32+K32+L32 -> 384211.64 | N32: =F32*E32 -> 1983616.5 | O32: =G32*E32 -> 0 | P32: =I32*E32 -> 8615325.4 | Q32: =J32*E32 -> 0 | R32: =+L32*E32 -> 158984.13 | S32: =SUM(N32:R32) -> 10757926 | U32: =+ROUNDUP(M32*$T$5,0) -> 482909 | V32: =+U32*E32 -> 13521452
A33: 3.1 | B33: OK | C33: Columna - H30 (240 Kg/m3 de hierro) | D33: m3 | E33: =+'H°A° '!M11 -> 54 | F33: =+'H°A° '!F57 -> 60951.379 | H33: =F33+G33 -> 60951.379 | I33: =+'MO HA AING'!D47 -> 273658.45 | K33: =I33+J33 -> 273658.45 | L33: =+(H33+K33)*0.015 -> 5019.1474 | M33: =H33+K33+L33 -> 339628.98 | N33: =F33*E33 -> 3291374.5 | O33: =G33*E33 -> 0 | P33: =I33*E33 -> 14777556 | Q33: =J33*E33 -> 0 | R33: =+L33*E33 -> 271033.96 | S33: =SUM(N33:R33) -> 18339965 | U33: =+ROUNDUP(M33*$T$5,0) -> 426874 | V33: =+U33*E33 -> 23051196
A34: 3.11 | B34: OK | C34: Escaleras - H30 (105 kg/m3 de hierro) | D34: m3 | E34: =+'H°A° '!M12 -> 11 | F34: =+'H°A° '!F60 -> 68185.041 | H34: =F34+G34 -> 68185.041 | I34: =+'MO HA AING'!D148 -> 283180.32 | K34: =I34+J34 -> 283180.32 | L34: =+(H34+K34)*0.015 -> 5270.4803 | M34: =H34+K34+L34 -> 356635.84 | N34: =F34*E34 -> 750035.45 | O34: =G34*E34 -> 0 | P34: =I34*E34 -> 3114983.5 | Q34: =J34*E34 -> 0 | R34: =+L34*E34 -> 57975.284 | S34: =SUM(N34:R34) -> 3922994.2 | U34: =+ROUNDUP(M34*$T$5,0) -> 448250 | V34: =+U34*E34 -> 4930750
A35: 3.12 | B35: OK | C35: Tabiques tanques de H° - H30 (120 kg/m3 de hierro) | D35: m3 | E35: =+'H°A° '!M14 -> 3 | F35: =+'H°A° '!F55 -> 70843.446 | H35: =F35+G35 -> 70843.446 | I35: =+'MO HA AING'!D72 -> 307690.19 | K35: =I35+J35 -> 307690.19 | L35: =+(H35+K35)*0.015 -> 5678.0046 | M35: =H35+K35+L35 -> 384211.64 | N35: =F35*E35 -> 212530.34 | O35: =G35*E35 -> 0 | P35: =I35*E35 -> 923070.58 | Q35: =J35*E35 -> 0 | R35: =+L35*E35 -> 17034.014 | S35: =SUM(N35:R35) -> 1152634.9 | U35: =+ROUNDUP(M35*$T$5,0) -> 482909 | V35: =+U35*E35 -> 1448727
A36: 3.13 | B36: OK | C36: Junta de impermeabilización de PVC - Sika Waterbars v15 x 15mts o similar | D36: ml | E36: 240 | F36: =+Cotizaciones!I498 -> 24772.727 | H36: =F36+G36 -> 24772.727 | K36: =I36+J36 -> 0 | M36: =H36+K36+L36 -> 24772.727 | N36: =F36*E36 -> 5945454.5 | O36: =G36*E36 -> 0 | P36: =I36*E36 -> 0 | Q36: =J36*E36 -> 0 | R36: =+L36*E36 -> 0 | S36: =SUM(N36:R36) -> 5945454.5 | U36: =+ROUNDUP(M36*$T$5,0) -> 31137 | V36: =+U36*E36 -> 7472880
A37: 3.14 | B37: OK | C37: Sistema de apuntalamiento y reapuntalamiento | D37: gl | E37: 1 | H37: =F37+G37 -> 0 | K37: =I37+J37 -> 0 | L37: =+'ENCOFRADO '!G148 -> 8822750 | M37: =H37+K37+L37 -> 8822750 | N37: =F37*E37 -> 0 | O37: =G37*E37 -> 0 | P37: =I37*E37 -> 0 | Q37: =J37*E37 -> 0 | R37: =+L37*E37 -> 8822750 | S37: =SUM(N37:R37) -> 8822750 | U37: =+ROUNDUP(M37*$T$5,0) -> 11089161 | V37: =+U37*E37 -> 11089161
A38: 3.15 | B38: OK | C38: Ensayos de Hormigon por etapas de hormigonado | D38: u | E38: =+'H°A° '!P34 -> 14 | F38: =+'H°A° '!T40 -> 123492.86 | H38: =F38+G38 -> 123492.86 | K38: =I38+J38 -> 0 | M38: =H38+K38+L38 -> 123492.86 | N38: =F38*E38 -> 1728900 | O38: =G38*E38 -> 0 | P38: =I38*E38 -> 0 | Q38: =J38*E38 -> 0 | R38: =+L38*E38 -> 0 | S38: =SUM(N38:R38) -> 1728900 | U38: =+ROUNDUP(M38*$T$5,0) -> 155217 | V38: =+U38*E38 -> 2173038
A39: 3.16 | B39: OK | C39: Permiso de estacionamiento de bomba de hormigón a contramano | D39: gl | E39: =+GGBB!R12 -> 4 | F39: 55000 | H39: =F39+G39 -> 55000 | K39: =I39+J39 -> 0 | M39: =H39+K39+L39 -> 55000 | N39: =F39*E39 -> 220000 | O39: =G39*E39 -> 0 | P39: =I39*E39 -> 0 | Q39: =J39*E39 -> 0 | R39: =+L39*E39 -> 0 | S39: =SUM(N39:R39) -> 220000 | U39: =+ROUNDUP(M39*$T$5,0) -> 69129 | V39: =+U39*E39 -> 276516
A40: 3.17 | B40: OK | C40: Picado de medianeras para columnas y vigas - Cotizado solo para PB y 1P, No contempla picado en SS | D40: m2 | E40: =+Computo!F53 -> 93 | F40: =+Tareas!H70 -> 3440.8602 | G40: =+Tareas!I70 -> 1612.9032 | H40: =F40+G40 -> 5053.7634 | I40: =+Tareas!Q70 -> 0 | J40: =+Tareas!R70 -> 14213.223 | K40: =I40+J40 -> 14213.223 | L40: =+(H40+K40)*0.015 -> 289.0048 | M40: =H40+K40+L40 -> 19555.992 | N40: =F40*E40 -> 320000 | O40: =G40*E40 -> 150000 | P40: =I40*E40 -> 0 | Q40: =J40*E40 -> 1321829.8 | R40: =+L40*E40 -> 26877.447 | S40: =SUM(N40:R40) -> 1818707.2 | U40: =+ROUNDUP(M40*$T$5,0) -> 24580 | V40: =+U40*E40 -> 2285940
...

Sheet Tareas
H4: MATERIALES | Q4: MANO DE OBRA
H5: PU | J5: TOTAL | M5: =+'P.MO 09.24'!B4 -> 75113.048 | N5: =+'P.MO 09.24'!B5 -> 65360.248 | O5: =+'P.MO 09.24'!B6 -> 54784.072 | P5: =+'P.MO 09.24'!B7 -> 49934.237 | Q5: PU | S5: TOTAL
C6: Descripción | D6: U | E6: Cant | F6: OTRO | G6: CORRALON | H6: OTRO | I6: CORRALON | J6: OTRO | K6: CORRALON | L6: OTRO | M6: ES | N6: OF | O6: MED | P6: AY | Q6: OTRO | R6: ALB | S6: OTRO | T6: ALB
A7: =+'01'!A8 -> 1 | C7: =+'01'!C8 -> TAREAS PRELIMINARES
A8: =+'01'!A10 -> 1.02 | B8: =+'01'!B10 -> OK | C8: =+'01'!C10 -> Topógrafo - Visita de obra replanteo | D8: =+'01'!D10 -> un | E8: =+'01'!E10 -> 3 | H8: =+J8/E8 -> 0 | I8: =+K8/E8 -> 41666.667 | J8: =SUM(J9:J11) -> 0 | K8: =SUM(K9:K11) -> 125000 | Q8: =+U8/E8 -> 172653.21 | R8: =+V8/E8 -> 83223.729 | U8: =SUM(S9:S11) -> 517959.62 | V8: =SUM(T9:T11) -> 249671.19
C9: M.Obra topografo | D9: d | E9: =+E8 -> 3 | J9: =+F9*E9 -> 0 | K9: =+G9*E9 -> 0 | L9: =+'P.MO 09.24'!B10 -> 172653.21 | S9: =+L9*E9 -> 517959.62 | T9: =(+M9*$M$5+N9*$N$5+O9*$O$5+P9*$P$5)*E9 -> 0
C10: M.Obra ayudante | D10: d | E10: =+E8 -> 3 | J10: =+F10*E10 -> 0 | K10: =+G10*E10 -> 0 | S10: =+L10*E10 -> 0 | T10: =(+M10*$M$5+N10*$N$5+O10*$O$5+P10*$P$5)*E10 -> 0
C11: Consumibles | D11: gl | E11: 5 | G11: 25000 | J11: =+F11*E11 -> 0 | K11: =+G11*E11 -> 125000 | P11: 1 | S11: =+L11*E11 -> 0 | T11: =(+M11*$M$5+N11*$N$5+O11*$O$5+P11*$P$5)*E11 -> 249671.19
A12: =+'01'!A12 -> 1.04 | B12: =+'01'!B12 -> OK | C12: =+'01'!C12 -> Cerco de obra perimetral - En chapa C25 + Concertina + Porton corredizo | D12: =+'01'!D12 -> ml | E12: =+'01'!E12 -> 11 | H12: =+J12/E12 -> 79773.183 | I12: =+K12/E12 -> 0 | J12: =+SUM(J13:J21) -> 877505.01 | K12: =+SUM(K13:K21) -> 0 | Q12: =+U12/E12 -> 0 | R12: =+V12/E12 -> 30923.374 | U12: =SUM(S13:S21) -> 0 | V12: =SUM(T13:T21) -> 340157.11
C13: Chapa acanalada C25 | D13: m2 | E13: =+E12*2.5 -> 27.5 | F13: =+Cotizaciones!D4 -> 10599.983 | J13: =+F13*E13 -> 291499.55 | K13: =+G13*E13 -> 0 | S13: =+L13*E13 -> 0 | T13: =(+M13*$M$5+N13*$N$5+O13*$O$5+P13*$P$5)*E13 -> 0
C14: Perfiles UPN 100 | D14: un | E14: 1 | F14: =+Cotizaciones!D5 -> 267019.02 | J14: =+F14*E14 -> 267019.02 | K14: =+G14*E14 -> 0 | S14: =+L14*E14 -> 0 | T14: =(+M14*$M$5+N14*$N$5+O14*$O$5+P14*$P$5)*E14 -> 0
C15: Bastidor para porton corredizo - Perfil 40 x 40 x 2 | D15: u | E15: 2 | F15: =+Cotizaciones!D6 -> 26250.62 | J15: =+F15*E15 -> 52501.24 | K15: =+G15*E15 -> 0 | S15: =+L15*E15 -> 0 | T15: =(+M15*$M$5+N15*$N$5+O15*$O$5+P15*$P$5)*E15 -> 0
C16: Riel Roma 174 e: 2,1 mm. 53 x 60 x 6000 | D16: u | E16: 1 | F16: =+Cotizaciones!D7 -> 81509.95 | J16: =+F16*E16 -> 81509.95 | K16: =+G16*E16 -> 0 | S16: =+L16*E16 -> 0 | T16: =(+M16*$M$5+N16*$N$5+O16*$O$5+P16*$P$5)*E16 -> 0
C17: Carro acero 174 4 ruedas puertas portones Ø45mm | D17: u | E17: 2 | F17: =+Cotizaciones!D8 -> 12131.562 | J17: =+F17*E17 -> 24263.124 | K17: =+G17*E17 -> 0 | S17: =+L17*E17 -> 0 | T17: =(+M17*$M$5+N17*$N$5+O17*$O$5+P17*$P$5)*E17 -> 0
C18: Autoperforantes punta mecha 14 x 2 | D18: u | E18: =+E13*4.5 -> 123.75 | F18: 120 | J18: =+F18*E18 -> 14850 | K18: =+G18*E18 -> 0 | S18: =+L18*E18 -> 0 | T18: =(+M18*$M$5+N18*$N$5+O18*$O$5+P18*$P$5)*E18 -> 0
C19: Rollo Concertina | D19: rol | E19: 1 | F19: =38000/1.21 -> 31404.959 | J19: =+F19*E19 -> 31404.959 | K19: =+G19*E19 -> 0 | S19: =+L19*E19 -> 0 | T19: =(+M19*$M$5+N19*$N$5+O19*$O$5+P19*$P$5)*E19 -> 0
C20: Consumibles | D20: gl | E20: 0.15 | F20: =+SUM(J13:J19) -> 763047.83 | J20: =+F20*E20 -> 114457.18 | K20: =+G20*E20 -> 0 | S20: =+L20*E20 -> 0 | T20: =(+M20*$M$5+N20*$N$5+O20*$O$5+P20*$P$5)*E20 -> 0
C21: M.Obra | D21: d | E21: 2 | J21: =+F21*E21 -> 0 | K21: =+G21*E21 -> 0 | N21: 1 | O21: 1 | P21: 1 | S21: =+L21*E21 -> 0 | T21: =(+M21*$M$5+N21*$N$5+O21*$O$5+P21*$P$5)*E21 -> 340157.11
A22: =+'01'!A13 -> 1.05 | B22: =+'01'!B13 -> OK | C22: =+'01'!C13 -> Obrador colgante, pañol y ducha | D22: =+'01'!D13 -> gl | E22: =+'01'!E13 -> 1 | H22: =+J22/E22 -> 2300856.7 | I22: =+K22/E22 -> 100000 | J22: =+SUM(J23:J43) -> 2300856.7 | K22: =+SUM(K23:K43) -> 100000 | Q22: =+U22/E22 -> 500000 | R22: =+V22/E22 -> 3016332.5 | U22: =SUM(S23:S43) -> 500000 | V22: =SUM(T23:T43) -> 3016332.5 | AD22: 0.66
C23: Chapa acanalada C25 - Reutilizado (estimado 3 usos) | D23: m2 | E23: 35 | F23: =+Cotizaciones!D4/2 -> 5299.9917 | J23: =+F23*E23 -> 185499.71 | K23: =+G23*E23 -> 0 | S23: =+L23*E23 -> 0 | T23: =(+M23*$M$5+N23*$N$5+O23*$O$5+P23*$P$5)*E23 -> 0 | X23: Largo | Y23: Ancho | Z23: perim | AA23: h | AB23: m2 | AD23: Puntales
C24: Fenolico 1,22 x 2,44 - Reutilizado (estimado 3 usos) | D24: u | E24: =+AB32 -> 33 | F24: =+Cotizaciones!D18/2 -> 13161.34 | J24: =+F24*E24 -> 434324.22 | K24: =+G24*E24 -> 0 | S24: =+L24*E24 -> 0 | T24: =(+M24*$M$5+N24*$N$5+O24*$O$5+P24*$P$5)*E24 -> 0 | W24: Paredes | X24: 10 | Y24: 3.6 | Z24: =+X24 -> 10 | AA24: 2.4 | AB24: =+Z24*AA24 -> 24 | AD24: =+ROUNDUP(X24/$AD$22,0) -> 16 | AE24: =+AD24*AA24 -> 38.4 | AF24: =+ROUNDUP(AE24/3.7,0) -> 11
C25: Puntales 1 x 4 x 3,7 - Reutilizado (estimado 3 usos) | D25: u | E25: =+E26*2 -> 80 | F25: =+Cotizaciones!D20/2 -> 970.974 | J25: =+F25*E25 -> 77677.92 | K25: =+G25*E25 -> 0 | S25: =+L25*E25 -> 0 | T25: =(+M25*$M$5+N25*$N$5+O25*$O$5+P25*$P$5)*E25 -> 0 | W25: Piso | X25: =+X24 -> 10 | Y25: 3.6 | AB25: =+X25*Y25 -> 36 | AD25: =+ROUNDUP(Y25/$AD$22,0) -> 6 | AE25: =+AD25*X25 -> 60 | AF25: =+ROUNDUP(AE25/3.7,0) -> 17
C26: Puntales 3 x 3 x 3,7 - Reutilizado (estimado 3 usos) | D26: u | E26: =+AF27 -> 40 | F26: =+Cotizaciones!D21/2 -> 2184.714 | J26: =+F26*E26 -> 87388.56 | K26: =+G26*E26 -> 0 | S26: =+L26*E26 -> 0 | T26: =(+M26*$M$5+N26*$N$5+O26*$O$5+P26*$P$5)*E26 -> 0 | W26: Paredes interiores | X26: 3 | Y26: 3 | AA26: 2.4 | AB26: =+X26*Y26*AA26 -> 21.6 | AD26: =+ROUNDUP(Y26*3/$AD$22,0) -> 14 | AE26: =+AD26*X26 -> 42 | AF26: =+ROUNDUP(AE26/3.7,0) -> 12
C27: Flechas 3 x 6 x 3,7 - Reutilizado (estimado 3 usos) | D27: u | E27: 20 | F27: =+F26*2 -> 4369.428 | J27: =+F27*E27 -> 87388.56 | K27: =+G27*E27 -> 0 | S27: =+L27*E27 -> 0 | T27: =(+M27*$M$5+N27*$N$5+O27*$O$5+P27*$P$5)*E27 -> 0 | W27: Galeria | AF27: =+SUM(AF24:AF26) -> 40
C28: Escalera | D28: gl | E28: 0.5 | F28: =+SUM(J25:J27) -> 252455.04 | J28: =+F28*E28 -> 126227.52 | K28: =+G28*E28 -> 0 | S28: =+L28*E28 -> 0 | T28: =(+M28*$M$5+N28*$N$5+O28*$O$5+P28*$P$5)*E28 -> 0
C29: Flete madera | D29: u | E29: 2 | J29: =+F29*E29 -> 0 | K29: =+G29*E29 -> 0 | L29: 250000 | S29: =+L29*E29 -> 500000 | T29: =(+M29*$M$5+N29*$N$5+O29*$O$5+P29*$P$5)*E29 -> 0 | AB29: =+SUM(AB24:AB26) -> 81.6
C30: Materiales varios | D30: gl | E30: 1 | G30: 100000 | J30: =+F30*E30 -> 0 | K30: =+G30*E30 -> 100000 | S30: =+L30*E30 -> 0 | T30: =(+M30*$M$5+N30*$N$5+O30*$O$5+P30*$P$5)*E30 -> 0
C31: M.Obra carpinteros | D31: d | E31: 5 | J31: =+F31*E31 -> 0 | K31: =+G31*E31 -> 0 | M31: 1 | N31: 1 | O31: 1 | P31: 1 | S31: =+L31*E31 -> 0 | T31: =(+M31*$M$5+N31*$N$5+O31*$O$5+P31*$P$5)*E31 -> 1225958 | AB31: =1.2*2.4 -> 2.88
C32: Rollo de cable TPR 3 x 2,5 | D32: rol | E32: 1 | F32: =260000/1.21 -> 214876.03 | J32: =+F32*E32 -> 214876.03 | K32: =+G32*E32 -> 0 | S32: =+L32*E32 -> 0 | T32: =(+M32*$M$5+N32*$N$5+O32*$O$5+P32*$P$5)*E32 -> 0 | AB32: =+ROUNDUP(AB29/AB31*1.15,0) -> 33 | AD32: =+SUM(AD24:AD31)*1.15 -> 41.4
C33: Zocalo E27 | D33: u | E33: 10 | F33: =4475/1.21/10 -> 369.83471 | J33: =+F33*E33 -> 3698.3471 | K33: =+G33*E33 -> 0 | S33: =+L33*E33 -> 0 | T33: =(+M33*$M$5+N33*$N$5+O33*$O$5+P33*$P$5)*E33 -> 0
C34: Lampara Led 12 w | D34: u | E34: =+E33 -> 10 | F34: =14300/1.21/5 -> 2363.6364 | J34: =+F34*E34 -> 23636.364 | K34: =+G34*E34 -> 0 | S34: =+L34*E34 -> 0 | T34: =(+M34*$M$5+N34*$N$5+O34*$O$5+P34*$P$5)*E34 -> 0
C35: Mat. Elect. (tomas, enchufes, etc.) | D35: gl | E35: 0.25 | F35: =+SUM(J32:J34) -> 242210.74 | J35: =+F35*E35 -> 60552.686 | K35: =+G35*E35 -> 0 | S35: =+L35*E35 -> 0 | T35: =(+M35*$M$5+N35*$N$5+O35*$O$5+P35*$P$5)*E35 -> 0
C36: M.Obra elect | D36: d | E36: 3 | J36: =+F36*E36 -> 0 | K36: =+G36*E36 -> 0 | M36: 1 | N36: 1 | S36: =+L36*E36 -> 0 | T36: =(+M36*$M$5+N36*$N$5+O36*$O$5+P36*$P$5)*E36 -> 421419.89
C37: Materiales Sanit | D37: gl | E37: 1 | F37: 500000 | J37: =+F37*E37 -> 500000 | K37: =+G37*E37 -> 0 | S37: =+L37*E37 -> 0 | T37: =(+M37*$M$5+N37*$N$5+O37*$O$5+P37*$P$5)*E37 -> 0
C38: Inodoro | D38: u | E38: 2 | F38: 100000 | J38: =+F38*E38 -> 200000 | K38: =+G38*E38 -> 0 | S38: =+L38*E38 -> 0 | T38: =(+M38*$M$5+N38*$N$5+O38*$O$5+P38*$P$5)*E38 -> 0
C39: Mochila plastico | D39: u | E39: 2 | F39: 25000 | J39: =+F39*E39 -> 50000 | K39: =+G39*E39 -> 0 | S39: =+L39*E39 -> 0 | T39: =(+M39*$M$5+N39*$N$5+O39*$O$5+P39*$P$5)*E39 -> 0
C40: Bacha | D40: u | E40: 2 | F40: =30000/1.21 -> 24793.388 | J40: =+F40*E40 -> 49586.777 | K40: =+G40*E40 -> 0 | S40: =+L40*E40 -> 0 | T40: =(+M40*$M$5+N40*$N$5+O40*$O$5+P40*$P$5)*E40 -> 0
C41: Termo electrico 40 lts | D41: u | E41: 1 | F41: 200000 | J41: =+F41*E41 -> 200000 | K41: =+G41*E41 -> 0 | S41: =+L41*E41 -> 0 | T41: =(+M41*$M$5+N41*$N$5+O41*$O$5+P41*$P$5)*E41 -> 0
C42: M.Obra sanit | D42: d | E42: 4 | J42: =+F42*E42 -> 0 | K42: =+G42*E42 -> 0 | M42: 1 | N42: 1 | S42: =+L42*E42 -> 0 | T42: =(+M42*$M$5+N42*$N$5+O42*$O$5+P42*$P$5)*E42 -> 561893.19
C43: Mantenimiento | D43: mes | E43: =+GGBB!F4 -> 14 | J43: =+F43*E43 -> 0 | K43: =+G43*E43 -> 0 | N43: 0.5 | P43: 0.5 | S43: =+L43*E43 -> 0 | T43: =(+M43*$M$5+N43*$N$5+O43*$O$5+P43*$P$5)*E43 -> 807061.4
...

Sheet GGBB
H2: 45590 | O2: 22
F3: MESES | G3: DÓLAR BNA | H3: DÓLAR MEP | M3: Descrip | N3: Mes | O3: Total Dias
B4: GASTOS GENERALES y BENEFICIO | F4: 14 | G4: 1005 | H4: 1170 | M4: Prelim | N4: 0.75 | O4: =+N4*$O$2 -> 16.5 | Q4: Syh permanente
M5: Mov de suelos y excav. + micro | N5: 2.5 | O5: =+N5*$O$2 -> 55 | Q5: =+ROUNDUP(SUM(N4:N5),0) -> 4
B6: Gastos Grales de obra en items | C6: U | D6: Cant | F6: Precio Unit | G6: Subtotal | H6: =SUM(G7:G10) -> 0 | M6: Fundac | N6: 0 | O6: =+N6*$O$2 -> 0
B7: Oficina en obra (6x3 c/AA) | C7: mes | D7: =+$F$4 -> 14 | E7: 0 | F7: =E7*I7+J7 -> 0 | G7: =+F7*D7*E7 -> 0 | M7: Losa sobre PB | N7: 1 | O7: =+N7*$O$2 -> 22
B8: Obrador 6x3 s/AA | C8: mes | D8: =+$F$4 -> 14 | E8: 0 | F8: =E8*I8+J8 -> 0 | G8: =+F8*D8*E8 -> 0 | M8: Losa sobre 1 | N8: 1 | O8: =+N8*$O$2 -> 22
B9: Pañol (6x3) | C9: mes | D9: =+$F$4 -> 14 | E9: 1 | F9: =E9*I9+J9 -> 0 | G9: =+F9*D9*E9 -> 0 | M9: Losa sobre 2 | N9: 0.75 | O9: =+N9*$O$2 -> 16.5
B10: Baños | C10: mes | D10: =+$F$4 -> 14 | E10: 2 | F10: =E10*I10+J10 -> 0 | G10: =+F10*D10*E10 -> 0 | M10: Losa sobre 3 | N10: 0.75 | O10: =+N10*$O$2 -> 16.5 | P10: Inicio mamposteria
B11: Gastos Grales de obra en items | H11: =SUM(G12:G18) -> 16192179 | M11: Losa sobre 4 | N11: 0.75 | O11: =+N11*$O$2 -> 16.5 | Q11: Meses H° | R11: Estacionamiento en contramano
B12: HyS permanente | C12: mes | D12: 4 | E12: 1 | G12: =+F12*D12*E12 -> 0 | J12: =+'P.MO 09.24'!C9 -> 2578960.6 | K12: =+J12*D12*E12 -> 10315842 | M12: Techo escalera y sobrerecorrido | N12: 0.5 | O12: =+N12*$O$2 -> 11 | Q12: =+SUM(N4:N12) -> 8 | R12: =+Q12/2 -> 4
B13: HyS | C13: mes | D13: =+$F$4 -> 14 | E13: 1 | G13: =+F13*D13*E13 -> 0 | J13: 150000 | K13: =+J13*D13*E13 -> 2100000 | M13: Mampostería | N13: 2 | O13: =+N13*$O$2 -> 44
B14: Energía de obra | C14: mes | D14: =+F4 -> 14 | E14: 0.5 | F14: 200000 | G14: =+F14*D14*E14 -> 1400000 | I14: =+G14/$H$4 -> 1196.5812 | M14: Revoques, contrap y carp | N14: 2 | O14: =+N14*$O$2 -> 44 | P14: =+SUM(N13:N14) -> 4
B15: Agua de obra | C15: mes | D15: =+$F$4 -> 14 | E15: 1 | F15: 25000 | G15: =+F15*D15*E15 -> 350000 | M15: Amures | N15: 0 | O15: =+N15*$O$2 -> 0
B16: Alquiler cerco de obra chapa | C16: mes | D16: =+$F$4 -> 14 | E16: 0 | F16: 10000 | G16: =+F16*D16*E16 -> 0 | M16: Colocación | N16: 2 | O16: =+N16*$O$2 -> 44
B17: Proyecto Ejecutivo | C17: mes | D17: =+$F$4 -> 14 | E17: 0 | F17: =+'P.MO 09.24'!C9 -> 2578960.6 | G17: =+F17*D17*E17 -> 0 | M17: Pintura | N17: 2 | O17: =+N17*$O$2 -> 44
B18: Proyecto (50%) | C18: mes | D18: =+$F$4 -> 14 | E18: 0.4 | F18: =+'P.MO 09.24'!C9 -> 2578960.6 | G18: =+F18*D18*E18 -> 14442179 | I18: =+G18/$H$4 -> 12343.743 | M18: Terminaciones | N18: 0 | O18: =+L18*$O$2 -> 0
B19: Gastos Directos | H19: =SUM(G20:G30) -> 38913603 | N19: =SUM(N4:N18) -> 16 | O19: =SUM(O4:O18) -> 352
B20: Coordinacion de obra | C20: mes | D20: =+$F$4 -> 14 | E20: 0.15 | F20: =+'P.MO 09.24'!C11 -> 4680364.1 | G20: =+F20*D20*E20 -> 9828764.6 | I20: =+G20/$H$4 -> 8400.6535
B21: Jefe de obra | C21: mes | D21: =+$F$4 -> 14 | E21: 1 | G21: =+F21*D21*E21 -> 0 | J21: =+'P.MO 09.24'!C10 -> 3798370.6 | K21: =+J21*D21*E21 -> 53177188
B22: Sobrestante | C22: mes | D22: =+$F$4 -> 14 | E22: 0 | F22: =+'P.MO 09.24'!C9 -> 2578960.6 | G22: =+F22*D22*E22 -> 0
B23: Administrativo en obra | C23: mes | D23: =+$F$4 -> 14 | E23: 0 | F23: =+F22 -> 2578960.6 | G23: =+F23*D23*E23 -> 0
B24: Capataz | C24: mes | D24: =+$F$4 -> 14 | E24: 0.5 | F24: =+'P.MO 09.24'!C12 -> 3154977 | G24: =+F24*D24*E24 -> 22084839 | I24: =+G24/$H$4 -> 18875.931
B25: Logistica | C25: mes | D25: =+$F$4 -> 14 | E25: 0.5 | F25: 500000 | G25: =+F25*D25*E25 -> 3500000 | I25: =+G25/$H$4 -> 2991.453
B26: Vehiculo obra | C26: mes | D26: =+$F$4 -> 14 | E26: 0.5 | F26: =F25 -> 500000 | G26: =+F26*D26*E26 -> 3500000 | I26: =+G26/$H$4 -> 2991.453
B27: Mov y viaticos | C27: mes | D27: =+$F$4 -> 14 | E27: 1 | G27: =+F27*D27*E27 -> 0 | J27: =F25 -> 500000 | K27: =+J27*D27*E27 -> 7000000
B28: UOCRA | C28: mes | D28: =+$F$4 -> 14 | E28: 1 | G28: =+F28*D28*E28 -> 0
B29: Pañolero/Sereno | C29: mes | D29: =+$F$4 -> 14 | E29: 1 | J29: =+'P.MO 09.24'!C7 -> 1198421.7 | K29: =+J29*D29*E29 -> 16777904
B31: Equipos | H31: =SUM(G32:G40) -> 0
B32: Bobcat | C32: mes | D32: 0 | F32: 130000 | G32: =+F32*D32 -> 0
B33: Camion limpieza | C33: mes | D33: 0 | F33: 100000 | G33: =+F33*D33 -> 0
B34: Tijera electrica 12 | C34: mes | F34: 33600 | G34: =+F34*D34 -> 0
B35: JLG | C35: mes | F35: 89000 | G35: =+F35*D35 -> 0
B36: Grua 20ton | C36: mes | F36: 70000 | G36: =+F36*D36 -> 0
B41: Gastos Indirectos | H41: =SUM(G42:G47) -> 58713324
B42: Admin (50%Compras - 50%RRHH) | C42: mes | D42: =+$F$4 -> 14 | E42: 0.5 | F42: ='P.MO 09.24'!C9 -> 2578960.6 | G42: =+F42*D42*E42 -> 18052724 | I42: =+G42/$H$4 -> 15429.679
B43: Seguros | C43: gl | D43: =+D42 -> 14 | E43: 1 | F43: 250000 | G43: =+F43*D43 -> 3500000 | I43: =+G43/$H$4 -> 2991.453
B44: IIBB (monto venta obra gris) | C44: gl | D44: 0.04 | E44: 0.6 | F44: 1145000000 | G44: =+F44*D44*E44 -> 27480000 | I44: =+G44/$H$4 -> 23487.179
B45: Imp cheque | C45: gl | D45: =1.2/100 -> 0.012 | E45: =+E44 -> 0.6 | F45: =+F44*1.15 -> 1316750000 | G45: =+F45*D45*E45 -> 9480600 | I45: =+G45/$H$4 -> 8103.0769
B46: Contrato | C46: gl | D46: 1 | E46: 1 | F46: 200000 | G46: =+F46*D46*E46 -> 200000 | I46: =+G46/$H$4 -> 170.94017
...

Sheet Locales
J2: H Promedio | N2: CARPETAS / CONTRAPISOS | AA2: AISLACIONES | AF2: CIELORRASOS | AP2: CARPINTERIAS | BI2: PISOS (m2) | BQ2: ZOCALOS (ml) | CE2: ELECTRICIDAD | CW2: ART SANITARIO | DB2: GRIFERIAS
J3: H a revisar | U3: REVOQUES | AP3: Puertas | AX3: Ventanas | BV3: REV | BX3: PAREDES | CA3: CIELORRASO | CE3: ARTEFACTOS ILUM | CJ3: BOCAS
J4: Revisar | N4: A2 | O4: A3 | Q4: A3 | R4: A4 | S4: A5 | U4: R1 | V4: C | W4: C | X4: R2 | Y4: R5 | AA4: A1 | AD4: A2 | AF4: C1 | AG4: C2 | AH4: C3 | AI4: C4 | AK4: C5 | AL4: C6 | AM4: C7 | AN4: C8 | AP4: P1 | AQ4: P2 | AS4: P3 | AT4: P4 | AV4: P5 | AW4: P5 | AX4: V1 | AY4: V2 | AZ4: V3 | BA4: V4 | BB4: V5 | BC4: V6 | BD4: V7 | BE4: V8 | BF4: V9 | BG4: V10 | BI4: P1 | BJ4: P2 | BK4: P3 | BL4: P4 | BM4: P5 | BN4: P6 | BO4: P7 | BP4: P8 | BQ4: Z1 | BR4: Z2 | BS4: Z3 | BT4: Z4 | BV4: PI3 | BW4: PI4 | BX4: PI1 | BZ4: PI2 | CA4: PCI1 | CB4: PCI2 | CE4: AE1 | CF4: AE2 | CG4: AE3 | CH4: AE4 | CI4: AE5 | CJ4: IL1 | CK4: IL2 | CL4: IL3 | CM4: IL4 | CN4: IL5 | CO4: IL6 | CP4: IL7 | CQ4: IL8 | CR4: IL9 | CS4: IL10 | CT4: IL11 | CU4: IL12
J5: Revisado | N5: MC | O5: MC | Q5: MC | R5: MC | S5: MC | U5: MC | V5: MC | W5: MC | X5: MC | Y5: MC | AA5: MC | AD5: MC | AP5: MC | AQ5: MC | AS5: MC | AT5: MC | AV5: MC | AW5: MC | AX5: MC | AY5: MC | AZ5: MC | BA5: MC | BB5: MC | BC5: MC | BD5: MC | BE5: MC | BF5: MC | BG5: MC | BQ5: MC | BR5: MC | BT5: MC | BV5: MC | BW5: MC | BX5: MC | BZ5: MC | CA5: MC | CB5: MC | CG5: MC | CH5: MC | CI5: MC | CJ5: MC | CL5: MC | CN5: MC | CO5: MC | CP5: MC | CR5: MC | CT5: MC | CU5: MC | CW5: MC | CX5: MC | CY5: MC | DA5: MC | DB5: MC | DC5: MC | DD5: MC | DE5: MC | DF5: MC
C6: EL SALVADOR 4140 | N6: Monolitico e: 6,00 cm | O6: Contrapiso c/ pend. s/azotea | P6: Contrapiso s/ suelo nat | Q6: Contrapiso s/ Platea | R6: Carpeta | S6: Carpeta s/ membrana | U6: Yeso | V6: Aristas | W6: Cantoneras | X6: Bajo revestimiento | Y6: Revoque Grueso y Fino a la cal | AA6: Aislacion Horizontal en Baños | AB6: Aislaciòn sobre contrapiso | AC6: Aislaciòn termica EPS | AD6: Membrana geotextil - Balcones y azotea | AF6: Suspendido placa STD | AG6: Suspendido placa RH | AH6: Buña "Z" Durlock | AI6: Cajòn durlock | AJ6: Garganta | AK6: Yeso aplicado | AL6: Buña | AM6: Arista | AN6: Hormigon visto / Maquillaje | AP6: Puerta placa F30 de 90cm ancho | AQ6: Puerta placa MDF | AR6: Puerta de chapa | AS6: Puerta de chapa F60 | AT6: Puerta de chapa F60 para gabinetes de medidores de gas y luz | AU6: Frente ascensor | AV6: Frente de Baulera | AW6: Frentes de Placard | AX6: Ventana de aluminio anodizado 2,60m | AY6: Ventana de aluminio anodizado 2m | AZ6: Ventana de aluminio anodizado 2,80m | BA6: Ventana de aluminio anodizado 2,10m | BB6: Ventana de aluminio anodizado 2,50m | BC6: Ventana de aluminio anodizado 1,40m | BD6: Ventana de aluminio anodizado 0,50m | BE6: Ventana de aluminio anodizado 0,60m | BF6: Ventana de aluminio anodizado 2,85m | BG6: Ventana de aluminio anodizado 2,25m | BI6: Pavimento | BJ6: Travertino Hall | BK6: Porcelanato en UF | BL6: Porcelanato en baños | BM6: Porcelanato en espacio comun | BN6: Alisado de cemento rodillado | BO6: Sustrato | BP6: Baldosones | BQ6: Madera | BR6: Travertino | BS6: Porcelanato | BT6: Zocalo de material h: 10 cm | BV6: Revestimiento cocina | BW6: Revestimiento baño | BX6: Latex interior blanco s/ enduido | BY6: Latex interior blanco enduido parcial | BZ6: Latex interior blanco enduido completo | CA6: Latex cielorraso blanco s/enduido | CB6: Latex cielorraso blanco enduido parcial | CC6: Latex cielorraso blanco enduido completo | CE6: Extractor | CF6: Fotocelula | CG6: Sensor de movimiento | CH6: Toma de emergencia | CI6: Artefacto en espacio comun y balcon | CJ6: Boca ilum | CK6: Caja para led | CL6: Tecla | CM6: Pulsador timbre | CN6: Tomas simple | CO6: Toma doble | CP6: Toma A/A | CQ6: Termostato | CR6: Boca TV | CS6: Portero elecrico | CT6: Boca cctv | CU6: Tablero TSBT | CW6: Indoro Roca monaco | CX6: Bidet Roca monaco | CY6: Bacha de apoyar roca | CZ6: Bañadera Roca | DA6: Pileta de cocina | DB6: Accesorios de Baño FV alerce o similar | DC6: Griferia de lavarotio FV alerce o similar | DD6: Griferia de bidet 3 agujeros con tapita FV alerce o similar | DE6: Griferia de ducha FV alerce o similar | DF6: Griferia de cocina FV alerce o similar
A7: PLANTA | B7: Nº | C7: LOCAL | D7: Largo | E7: Ancho | F7: SUP | G7: perim unit | H7: vacio | I7: perim real | J7: H | K7: H r | L7: aux | N7: m2 | O7: m2 | P7: m2 | Q7: m2 | R7: m2 | S7: m2 | U7: m2 | V7: ml | W7: u | X7: m2 | Y7: m2 | AA7: m2 | AB7: m2 | AC7: m2 | AD7: m2 | AF7: m2 | AG7: m2 | AH7: ml | AI7: ml | AJ7: ml | AK7: m2 | AL7: ml | AM7: ml | AN7: m2 | AP7: u | AQ7: u | AR7: u | AS7: u | AT7: u | AU7: u | AV7: u | AW7: u | AX7: u | AY7: u | AZ7: u | BA7: u | BB7: u | BC7: u | BD7: u | BE7: u | BF7: u | BG7: u | BI7: m2 | BJ7: m2 | BK7: m2 | BM7: m2 | BN7: m2 | BP7: m2 | BQ7: ml | BR7: ml | BS7: ml | BT7: ml | BV7: m2 | BW7: m2 | BX7: m2 | BY7: m2 | BZ7: m2 | CA7: m2 | CB7: m2 | CC7: m2 | CH7: un | CI7: un | CJ7: un | CL7: un | CW7: un | CX7: un | CY7: un | CZ7: un | DA7: un | DB7: un | DC7: un | DD7: un | DE7: un | DF7: un
A8: Subsuelo | B8: 1 | C8: Cocheras | D8: 0 | E8: 0 | F8: 172.88 | G8: 63.68 | H8: =1.57+3.3 -> 4.87 | I8: =+G8-H8 -> 58.81 | J8: 2.93 | Y8: =$I8*$J8 -> 172.3133 | AN8: =+F8 -> 172.88 | BI8: =$F8 -> 172.88 | BX8: =+I8*J8 -> 172.3133 | CA8: =+F8 -> 172.88 | CG8: 3 | CH8: 5 | CI8: =+CJ8 -> 6 | CJ8: 6 | CN8: 1 | CT8: 1
B9: 2 | C9: Pallier | D9: 0 | E9: 0 | F9: 9.08 | G9: 16.07 | H9: =4.4+1.6 -> 6 | I9: =+G9-H9 -> 10.07 | J9: 2.93 | Q9: =$F9 -> 9.08 | Y9: =$I9*$J9 -> 29.5051 | AN9: =+F9 -> 9.08 | AU9: 1 | BN9: =$F9 -> 9.08 | BX9: =$I9*$J9 -> 29.5051 | CA9: =+F9 -> 9.08 | CG9: 1 | CH9: 1 | CI9: =+CJ9 -> 2 | CJ9: 2
B10: 3 | C10: Pasillo Baulera | D10: 0 | E10: 0 | F10: 32.65 | G10: 42.31 | H10: =+SUM(H11:H20)+1.26 -> 16.44 | I10: =+G10-H10 -> 25.87 | J10: 2.93 | Q10: =$F10 -> 32.65 | Y10: =$I10*$J10 -> 75.7991 | AN10: =+F10 -> 32.65 | BN10: =$F10 -> 32.65 | BX10: =$I10*$J10 -> 75.7991 | CA10: =+F10 -> 32.65 | CG10: 3 | CH10: 2 | CI10: =+CJ10 -> 7 | CJ10: 7 | CN10: 2
B11: 4 | C11: Baulera 1 | D11: 2.19 | E11: 1.41 | F11: =D11*E11 -> 3.0879 | G11: =+D11*2+E11*2 -> 7.2 | H11: 1.41 | I11: =+G11-H11 -> 5.79 | J11: 2.93 | Q11: =$F11 -> 3.0879 | Y11: =$I11*$J11 -> 16.9647 | AN11: =+F11 -> 3.0879 | AV11: 1 | BN11: =$F11 -> 3.0879 | BX11: =$I11*$J11 -> 16.9647 | CA11: =+F11 -> 3.0879
B12: 5 | C12: Baulera 2 | D12: 2.19 | E12: 1.41 | F12: =D12*E12 -> 3.0879 | G12: =+D12*2+E12*2 -> 7.2 | H12: 1.41 | I12: =+G12-H12 -> 5.79 | J12: 2.93 | Q12: =$F12 -> 3.0879 | Y12: =$I12*$J12 -> 16.9647 | AN12: =+F12 -> 3.0879 | AV12: 1 | BN12: =$F12 -> 3.0879 | BX12: =$I12*$J12 -> 16.9647 | CA12: =+F12 -> 3.0879
B13: 6 | C13: Baulera 3 | D13: 2.19 | E13: 1.41 | F13: =D13*E13 -> 3.0879 | G13: =+D13*2+E13*2 -> 7.2 | H13: 1.41 | I13: =+G13-H13 -> 5.79 | J13: 2.93 | Q13: =$F13 -> 3.0879 | Y13: =$I13*$J13 -> 16.9647 | AN13: =+F13 -> 3.0879 | AV13: 1 | BN13: =$F13 -> 3.0879 | BX13: =$I13*$J13 -> 16.9647 | CA13: =+F13 -> 3.0879
B14: 7 | C14: Baulera 4 | D14: 1.95 | E14: 1.59 | F14: =D14*E14 -> 3.1005 | G14: =+D14*2+E14*2 -> 7.08 | H14: 1.59 | I14: =+G14-H14 -> 5.49 | J14: 2.93 | Q14: =$F14 -> 3.1005 | Y14: =$I14*$J14 -> 16.0857 | AN14: =+F14 -> 3.1005 | AV14: 1 | BN14: =$F14 -> 3.1005 | BX14: =$I14*$J14 -> 16.0857 | CA14: =+F14 -> 3.1005
B15: 8 | C15: Baulera 5 | D15: 1.95 | E15: 1.59 | F15: =D15*E15 -> 3.1005 | G15: =+D15*2+E15*2 -> 7.08 | H15: 1.59 | I15: =+G15-H15 -> 5.49 | J15: 2.93 | Q15: =$F15 -> 3.1005 | Y15: =$I15*$J15 -> 16.0857 | AN15: =+F15 -> 3.1005 | AV15: 1 | BN15: =$F15 -> 3.1005 | BX15: =$I15*$J15 -> 16.0857 | CA15: =+F15 -> 3.1005
B16: 9 | C16: Baulera 6 | D16: 1.95 | E16: 1.59 | F16: =D16*E16 -> 3.1005 | G16: =+D16*2+E16*2 -> 7.08 | H16: 1.59 | I16: =+G16-H16 -> 5.49 | J16: 2.93 | Q16: =$F16 -> 3.1005 | Y16: =$I16*$J16 -> 16.0857 | AN16: =+F16 -> 3.1005 | AV16: 1 | BN16: =$F16 -> 3.1005 | BX16: =$I16*$J16 -> 16.0857 | CA16: =+F16 -> 3.1005
B17: 10 | C17: Baulera 7 | D17: 1.95 | E17: 1.59 | F17: =D17*E17 -> 3.1005 | G17: =+D17*2+E17*2 -> 7.08 | H17: 1.95 | I17: =+G17-H17 -> 5.13 | J17: 2.93 | Q17: =$F17 -> 3.1005 | Y17: =$I17*$J17 -> 15.0309 | AN17: =+F17 -> 3.1005 | AV17: 1 | BN17: =$F17 -> 3.1005 | BX17: =$I17*$J17 -> 15.0309 | CA17: =+F17 -> 3.1005
B18: 11 | C18: Baulera 8 | D18: 2.19 | E18: 1.41 | F18: =D18*E18 -> 3.0879 | G18: =+D18*2+E18*2 -> 7.2 | H18: 1.41 | I18: =+G18-H18 -> 5.79 | J18: 2.93 | Q18: =$F18 -> 3.0879 | Y18: =$I18*$J18 -> 16.9647 | AN18: =+F18 -> 3.0879 | AV18: 1 | BN18: =$F18 -> 3.0879 | BX18: =$I18*$J18 -> 16.9647 | CA18: =+F18 -> 3.0879
B19: 12 | C19: Baulera 9 | D19: 2.19 | E19: 1.41 | F19: =D19*E19 -> 3.0879 | G19: =+D19*2+E19*2 -> 7.2 | H19: 1.41 | I19: =+G19-H19 -> 5.79 | J19: 2.93 | Q19: =$F19 -> 3.0879 | Y19: =$I19*$J19 -> 16.9647 | AN19: =+F19 -> 3.0879 | AV19: 1 | BN19: =$F19 -> 3.0879 | BX19: =$I19*$J19 -> 16.9647 | CA19: =+F19 -> 3.0879
B20: 13 | C20: Baulera 10 | D20: 2.19 | E20: 1.41 | F20: =D20*E20 -> 3.0879 | G20: =+D20*2+E20*2 -> 7.2 | H20: 1.41 | I20: =+G20-H20 -> 5.79 | J20: 2.93 | Q20: =$F20 -> 3.0879 | Y20: =$I20*$J20 -> 16.9647 | AN20: =+F20 -> 3.0879 | AV20: 1 | BN20: =$F20 -> 3.0879 | BX20: =$I20*$J20 -> 16.9647 | CA20: =+F20 -> 3.0879
B21: 14 | C21: Auxiliar | D21: 0 | E21: 0 | F21: 9.74 | G21: 14.47 | H21: 0 | I21: =+G21-H21 -> 14.47 | J21: 2.93 | Q21: =$F21 -> 9.74 | Y21: =$I21*$J21 -> 42.3971 | AN21: =+F21 -> 9.74 | AR21: 1 | BM21: =+F21 -> 9.74 | BX21: =$I21*$J21 -> 42.3971 | CA21: =+F21 -> 9.74 | CI21: =+CJ21 -> 2 | CJ21: 2 | CL21: 1 | CO21: 1 | CR21: 1 | CS21: 1 | CT21: 1
B22: 15 | C22: Camara Transformadora | D22: 5 | E22: 3.65 | F22: =D22*E22 -> 18.25 | G22: 17.3 | H22: 0 | I22: =+G22-H22 -> 17.3 | J22: 2.93 | Q22: =$F22 -> 18.25 | Y22: =$I22*$J22 -> 50.689 | AN22: =+F22 -> 18.25 | BN22: =$F22 -> 18.25 | BX22: =$I22*$J22 -> 50.689 | CA22: =+F22 -> 18.25
B23: 16 | C23: Baño | D23: 1.2 | E23: 2.18 | F23: =D23*E23 -> 2.616 | G23: 6.76 | H23: 0 | I23: =+G23-H23 -> 6.76 | J23: 2.2 | K23: 2.2 | Q23: =$F23 -> 2.616 | R23: =$F23 -> 2.616 | X23: =+I23*K23 -> 14.872 | AN23: =+F23 -> 2.616 | AQ23: 1 | BL23: =+F23 -> 2.616 | BW23: =+I23*K23 -> 14.872 | CC23: =+F23 -> 2.616 | CI23: 1 | CJ23: 1 | CL23: 1 | CN23: 1 | CW23: 1 | CY23: 1 | DB23: 1 | DC23: 1
C24: SALA BOMBEO | F24: 7.7 | G24: 14.85 | H24: 3.08 | I24: =+G24-H24 -> 11.77 | J24: 2.93 | Y24: =$I24*$J24 -> 34.4861 | AN24: =+F24 -> 7.7 | BN24: =+F24 -> 7.7 | BX24: =$I24*$J24 -> 34.4861 | CA24: =+F24 -> 7.7 | CH24: 1 | CJ24: 2 | CL24: 1
C25: ESCALERA | F25: 9 | G25: 13.74 | H25: =1.25+1.55 -> 2.8 | I25: =+G25-H25 -> 10.94 | J25: 2.93 | Y25: =$I25*$J25 -> 32.0542 | AN25: =+F25 -> 9 | BT25: =+I25 -> 10.94 | BX25: =$I25*$J25 -> 32.0542 | CA25: =+F25 -> 9 | CG25: 1 | CH25: 1 | CI25: 2 | CJ25: 2
A26: PB | C26: Vereda | D26: 3 | E26: 10 | F26: =D26*E26 -> 30 | G26: =+D26*2+E26*2 -> 26 | H26: =+G26 -> 26 | I26: =+G26-H26 -> 0 | J26: 3.2 | P26: =$F26 -> 30 | AB26: =+F26 -> 30 | AG26: =1.3*9.14 -> 11.882 | AH26: =1.3*2+9.14*2 -> 20.88 | BP26: =+F26 -> 30 | CC26: =+AG26 -> 11.882 | CI26: 3 | CJ26: 3 | CT26: 1
C27: Acceso cocheras | D27: 3.1 | E27: 3.3 | F27: =D27*E27 -> 10.23 | G27: =+D27*2+E27*2 -> 12.8 | H27: =2.85*2 -> 5.7 | I27: =+G27-H27 -> 7.1 | J27: 3.2 | P27: =$F27 -> 10.23 | AB27: =+F27 -> 10.23 | AN27: =+F27 -> 10.23 | BP27: =+F27 -> 10.23 | CA27: =+F27 -> 10.23 | CG27: 1 | CI27: 1 | CJ27: 1 | CT27: 2
B28: 17 | C28: Rampa | D28: 0 | E28: 0 | F28: 52.38 | G28: 39.01 | H28: =2.85*2 -> 5.7 | I28: =+G28-H28 -> 33.31 | J28: =AVERAGE(3,6) -> 4.5 | Y28: =$I28*$J28 -> 149.895 | AN28: =8.52*3.3 -> 28.116 | AT28: 1 | BI28: =+F28 -> 52.38 | BT28: =$G28 -> 39.01 | BX28: =+I28*J28 -> 149.895 | CA28: =8.52*3.3 -> 28.116 | CG28: 1 | CH28: =+CJ28 -> 5 | CJ28: 5
B29: 18 | C29: Entrada | D29: 2.3 | E29: 3 | F29: =D29*E29 -> 6.9 | G29: 11.17 | H29: =(2.05*2) -> 4.1 | I29: =+G29-H29 -> 7.07 | J29: 3.2 | P29: =$F29 -> 6.9 | AB29: =+F29 -> 6.9 | AG29: =+F29 -> 6.9 | AH29: =+G29 -> 11.17 | AT29: 1 | BP29: =+F29 -> 6.9 | CC29: =+F29 -> 6.9 | CI29: 4 | CJ29: 4 | CT29: 2
B30: 19 | C30: Hall ingreso | D30: 0 | E30: 0 | F30: 29.36 | G30: 39.38 | H30: =2.05+1.2 -> 3.25 | I30: =+G30-H30 -> 36.13 | J30: 3.2 | N30: =+F30 -> 29.36 | U30: =$I30*$J30 -> 115.616 | V30: =+W30*J30 -> 22.4 | W30: 7 | AF30: =+F30 -> 29.36 | AH30: =+G30 -> 39.38 | AS30: 1 | AU30: 1 | BJ30: =$F30 -> 29.36 | BR30: =$I30 -> 36.13 | BY30: =+I30*J30 -> 115.616 | CC30: =+F30 -> 29.36 | CG30: 2 | CH30: 2 | CI30: 9 | CJ30: 9 | CK30: 3 | CM30: 1 | CO30: 1 | CT30: 1
C31: ESCALERA | F31: 9 | G31: 13.74 | H31: =1.25+1.55 -> 2.8 | I31: =+G31-H31 -> 10.94 | J31: 3.2 | V31: =+W31*J31 -> 3.2 | W31: 1 | Y31: =+I31*J31 -> 35.008 | AN31: =+F31 -> 9 | BT31: =+I31 -> 10.94 | BY31: =+I31*J31 -> 35.008 | CA31: =+F31 -> 9
B32: 20 | C32: Local Comercial | D32: 10.79 | E32: 3.74 | F32: =D32*E32 -> 40.3546 | G32: 25.05 | H32: 3.54 | I32: =+G32-H32 -> 21.51 | J32: 3.2 | N32: =+F32 -> 40.3546 | U32: =$I32*$J32 -> 68.832 | AF32: =+F32 -> 40.3546 | AH32: =+G32 -> 25.05 | BT32: =$I32 -> 21.51 | BY32: =+I32*J32 -> 68.832 | CC32: =+F32 -> 40.3546 | CJ32: 10 | CL32: 1 | CO32: 9 | CR32: 1 | CT32: 3
B33: 21 | C33: Baño Comercial | D33: 2.94 | E33: 1.52 | F33: =D33*E33 -> 4.4688 | G33: 8.92 | H33: 0 | I33: =+G33-H33 -> 8.92 | J33: 3.2 | K33: 3.2 | R33: =+F33 -> 4.4688 | S33: =+F33 -> 4.4688 | X33: =$I33*$J33 -> 28.544 | AN33: =+F33 -> 4.4688 | AQ33: 1 | BL33: =$F33 -> 4.4688 | BT33: =$I33 -> 8.92 | BW33: =+I33*K33 -> 28.544 | CC33: =+$F33 -> 4.4688 | CJ33: 2 | CL33: 1 | CN33: 1 | CW33: 2 | CY33: 1 | DC33: 1
B34: 22 | C34: Hall Dto. PB | D34: 0 | E34: 0 | F34: 7.06 | G34: 15.39 | H34: =1.2+3.6+2.25 -> 7.05 | I34: =+G34-H34 -> 8.34 | J34: 2.4 | N34: =+F34 -> 7.06 | U34: =$I34*$J34 -> 20.016 | V34: =+W34*J34 -> 4.8 | W34: 2 | AF34: =$F34 -> 7.06 | AH34: =$G34 -> 15.39 | AP34: 1 | BK34: =+F34 -> 7.06 | BQ34: =+I34 -> 8.34 | BY34: =+I34*J34 -> 20.016 | CC34: =+$F34 -> 7.06 | CJ34: 1 | CL34: 1 | CO34: 1 | CP34: 1 | CQ34: 1 | CS34: 1
B35: 23 | C35: Cocina Dto. PB | D35: 0 | E35: 0 | F35: 11.79 | G35: 16.19 | H35: =2.28+1.2 -> 3.48 | I35: =+G35-H35 -> 12.71 | J35: 2.4 | K35: 0.6 | L35: =5.25+3.6 -> 8.85 | N35: =+F35 -> 11.79 | U35: =+I35*J35-X35 -> 9.264 | V35: =+W35*J35 -> 14.4 | W35: 6 | X35: =+L35*J35 -> 21.24 | AF35: =$F35 -> 11.79 | AH35: =$G35 -> 16.19 | AI35: 3.6 | BK35: =+F35 -> 11.79 | BQ35: =+I35 -> 12.71 | BV35: =+K35*L35 -> 5.31 | BY35: =+I35*J35-BV35 -> 25.194 | CC35: =+$F35 -> 11.79 | CJ35: 8 | CK35: 2 | CL35: 2 | CN35: 1 | CO35: 8 | DA35: 1 | DF35: 1
B36: 24 | C36: Lavadero Dto. PB | D36: 2.94 | E36: 1.5 | F36: =D36*E36 -> 4.41 | G36: 9.15 | I36: =+G36-H36 -> 9.15 | J36: 2.4 | K36: 0.6 | L36: =2.7+2.3 -> 5 | N36: =+F36 -> 4.41 | U36: =+I36*J36-X36 -> 9.96 | V36: =+W36*J36 -> 2.4 | W36: 1 | X36: =+L36*J36 -> 12 | AF36: =$F36 -> 4.41 | AH36: =$G36 -> 9.15 | BC36: 1 | BK36: =+F36 -> 4.41 | BQ36: =+I36 -> 9.15 | BV36: =+K36*L36 -> 3 | BY36: =+I36*J36-BV36 -> 18.96 | CC36: =+$F36 -> 4.41 | CJ36: 1 | CL36: 1 | CN36: 2 | CO36: 2
B37: 25 | C37: living Dto. PB | D37: 6.12 | E37: 3.59 | F37: =D37*E37 -> 21.9708 | G37: 19.41 | H37: =3.59 -> 3.59 | I37: =+G37-H37 -> 15.82 | J37: 3 | N37: =+F37 -> 21.9708 | U37: =$I37*$J37 -> 47.46 | V37: =+W37*J37 -> 6 | W37: 2 | AK37: =$F37 -> 21.9708 | AL37: =+G37 -> 19.41 | AX37: 1 | BK37: =+F37 -> 21.9708 | BQ37: =+I37 -> 15.82 | BY37: =+I37*J37 -> 47.46 | CB37: =+$F37 -> 21.9708 | CJ37: 4 | CL37: 2 | CO37: 5 | CR37: 3
B38: 26 | C38: Toillette Dto. PB | D38: 1.17 | E38: 2.43 | F38: =D38*E38 -> 2.8431 | G38: 7.19 | I38: =+G38-H38 -> 7.19 | J38: 2.2 | K38: 2.2 | R38: =+F38 -> 2.8431 | S38: =+F38 -> 2.8431 | X38: =+I38*K38 -> 15.818 | AA38: =+F38 -> 2.8431 | AF38: =$F38 -> 2.8431 | AH38: =+G38 -> 7.19 | AQ38: 1 | BL38: =+F38 -> 2.8431 | BW38: =+I38*K38 -> 15.818 | CC38: =+$F38 -> 2.8431 | CE38: 1 | CJ38: 2 | CL38: 1 | CN38: 1 | CW38: 1 | CY38: 1 | DB38: 1 | DC38: 1
B39: 27 | C39: Paso Dorm Dto. PB | D39: 0 | E39: 0 | F39: 7.85 | G39: 17.63 | I39: =+G39-H39 -> 17.63 | J39: 2.4 | N39: =+F39 -> 7.85 | U39: =$I39*$J39 -> 42.312 | V39: =+W39*J39 -> 9.6 | W39: 4 | AF39: =$F39 -> 7.85 | AH39: =+G39 -> 17.63 | AQ39: 1 | BK39: =+F39 -> 7.85 | BQ39: =+I39 -> 17.63 | BY39: =+I39*J39 -> 42.312 | CC39: =+$F39 -> 7.85 | CJ39: 4 | CL39: 2 | CO39: 2
B40: 28 | C40: Placard Paso Dorm Dto. PB | D40: 1.18 | E40: 0.6 | F40: =D40*E40 -> 0.708 | G40: 3.56 | I40: =+G40-H40 -> 3.56 | J40: 3 | N40: =+F40 -> 0.708 | U40: =$I40*$J40 -> 10.68 | AK40: =$F40 -> 0.708 | AW40: 1 | BK40: =+F40 -> 0.708 | BY40: =+I40*J40 -> 10.68 | CB40: =+$F40 -> 0.708
B41: 29 | C41: Dorm 1 Dto. PB | D41: 2.48 | E41: 3.41 | F41: =D41*E41 -> 8.4568 | G41: 11.78 | I41: =+G41-H41 -> 11.78 | J41: 3 | N41: =+F41 -> 8.4568 | U41: =$I41*$J41 -> 35.34 | V41: =+W41*J41 -> 3 | W41: 1 | AK41: =$F41 -> 8.4568 | AL41: =$G41 -> 11.78 | AQ41: 1 | BA41: 1 | BK41: =+F41 -> 8.4568 | BQ41: =+I41 -> 11.78 | BY41: =+I41*J41 -> 35.34 | CB41: =+$F41 -> 8.4568 | CJ41: 1 | CL41: 2 | CO41: 3 | CP41: 1 | CR41: 1
...

Sheet Computo
B2: Picado de medianeras
C3: Largo | D3: h | E3: m2 | F3: Subtotal | J3: MEDIANERAS enchape | K3: Largo | L3: h | M3: m2
B4: PB | F4: =+SUM(E5:E27) -> 48.3255 | J4: PB | N4: =+SUM(M5:M7) -> 130.248
B5: C01 | C5: 0.75 | D5: 3.3 | E5: =+C5*D5 -> 2.475 | J5: Lado A | K5: 20.22 | L5: 2.7 | M5: =+K5*L5 -> 54.594
B6: C02 | C6: 0.75 | D6: 3.3 | E6: =+C6*D6 -> 2.475 | J6: Lado B | K6: 19.44 | L6: 2.7 | M6: =+K6*L6 -> 52.488
B7: C03 | C7: 0.75 | D7: 3.3 | E7: =+C7*D7 -> 2.475 | J7: Fondo | K7: 8.58 | L7: 2.7 | M7: =+K7*L7 -> 23.166
B8: C04 | C8: 0.75 | D8: 3.3 | E8: =+C8*D8 -> 2.475 | J8: 1P | N8: =+SUM(M9:M11) -> 108.807
B9: C05 | C9: 0.75 | D9: 3.3 | E9: =+C9*D9 -> 2.475 | J9: Lado A | K9: 20.22 | L9: =2.8-0.5 -> 2.3 | M9: =+K9*L9 -> 46.506
B10: C06 | C10: 0.75 | D10: 3.3 | E10: =+C10*D10 -> 2.475 | J10: Lado B | K10: 19.44 | L10: =2.8-0.5 -> 2.3 | M10: =+K10*L10 -> 44.712
B11: C19 | C11: 0.75 | D11: 3.3 | E11: =+C11*D11 -> 2.475 | J11: Fondo | K11: 8.58 | L11: 2.05 | M11: =+K11*L11 -> 17.589
B12: C20 | C12: 0.75 | D12: 3.3 | E12: =+C12*D12 -> 2.475 | M12: =SUM(M4:M11) -> 239.055 | N12: =SUM(N4:N11) -> 239.055
B13: C21 | C13: 0.75 | D13: 3.3 | E13: =+C13*D13 -> 2.475
B14: C22 | C14: 0.75 | D14: 3.3 | E14: =+C14*D14 -> 2.475
B15: C23 | C15: 0.75 | D15: 3.3 | E15: =+C15*D15 -> 2.475
B16: C24 | C16: 0.75 | D16: 3.3 | E16: =+C16*D16 -> 2.475
B17: V201 | C17: 4.3 | D17: 0.45 | E17: =+C17*D17 -> 1.935
B18: V202 | C18: 5.07 | D18: 0.45 | E18: =+C18*D18 -> 2.2815
B19: V203 | C19: 5.1 | D19: 0.45 | E19: =+C19*D19 -> 2.295
B20: V204 | C20: 5 | D20: 0.45 | E20: =+C20*D20 -> 2.25
B21: V205 | C21: 3.8 | D21: 0.45 | E21: =+C21*D21 -> 1.71
B22: V206 | C22: 0.6 | D22: 0.45 | E22: =+C22*D22 -> 0.27
B23: V224 | C23: 4.3 | D23: 0.45 | E23: =+C23*D23 -> 1.935
B24: V225 | C24: 4.44 | D24: 0.45 | E24: =+C24*D24 -> 1.998
... B27: V228 | C27: 0.6 | D27: 0.45 | E27: =+C27*D27 -> 0.27
B28: PB | F28: =+SUM(E29:E57) -> 43.8255
B29: C01 | C29: 0.75 | D29: 2.8 | E29: =+C29*D29 -> 2.1
B30: C02 | C30: 0.75 | D30: 2.8 | E30: =+C30*D30 -> 2.1
B31: C03 | C31: 0.75 | D31: 2.8 | E31: =+C31*D31 -> 2.1
B32: C04 | C32: 0.75 | D32: 2.8 | E32: =+C32*D32 -> 2.1
B33: C05 | C33: 0.75 | D33: 2.8 | E33: =+C33*D33 -> 2.1
B34: C06 | C34: 0.75 | D34: 2.8 | E34: =+C34*D34 -> 2.1
B35: C19 | C35: 0.75 | D35: 2.8 | E35: =+C35*D35 -> 2.1
B36: C20 | C36: 0.75 | D36: 2.8 | E36: =+C36*D36 -> 2.1
B37: C21 | C37: 0.75 | D37: 2.8 | E37: =+C37*D37 -> 2.1
B38: C22 | C38: 0.75 | D38: 2.8 | E38: =+C38*D38 -> 2.1
B39: C23 | C39: 0.75 | D39: 2.8 | E39: =+C39*D39 -> 2.1
B40: C24 | C40: 0.75 | D40: 2.8 | E40: =+C40*D40 -> 2.1
... B51: V327 | C51: 0.6 | D51: 0.45 | E51: =+C51*D51 -> 0.27
F52: =SUM(F4:F51) -> 92.151
F53: =+ROUNDUP(F52,0) -> 93
...

Sheet INCEND
B1: NOTA: CANTIDADES SALEN DE COMPUTO AUXILIAR INCENDIO | F1: 1.05
H2: 0.6 | I2: respecto a VL 572 | L2: =+'P.MO 09.24'!B4 -> 75113.048 | M2: =+'P.MO 09.24'!B5 -> 65360.248 | N2: =+'P.MO 09.24'!B6 -> 54784.072 | O2: =+'P.MO 09.24'!B7 -> 49934.237 | P2: 1.5
B3: Descripción | C3: Un | D3: Cant | E3: P Unit | F3: Punit ACT | G3: Subtotal | J3: TAREA | K3: DIA | L3: ES | M3: OF | N3: MED | O3: AY | P3: GGBB
B4: Por tendido cañeria de incendio - (no incluye gabinetes, manguera, lanza y valvula) | H4: =+SUM(G5:G17)*H2 -> 2093587.4 | J4: Pintura | K4: 2 | O4: 2 | P4: =(+L4*$L$2+M4*$M$2+N4*$N$2+O4*$O$2)*K4 -> 199736.95
