Workbook
Name \0: #REF!
Name \c: #REF!
Name \E: #REF!
Name \i: #REF!
Name \j: #REF!
Name \m: #REF!
Name \P: #REF!
Name \P: #REF!
Name \P: #REF!
Name \P: #REF!
Name \P: #REF!
Name \P: #REF!
Name \P: #REF!
Name \P: #REF!
Name \P: #REF!
Name \P: #REF!
Name \P: #REF!
Name \r: #N/A
Name \x: #REF!
Name \z: #REF!
Name __________ben1: #REF!
Name __________ben1: #REF!
Name __________ben1: #REF!
Name __________ben1: #REF!
Name __________ben1: #REF!
Name __________ben1: #REF!
Name __________ben1: #REF!
Name __________ben1: #REF!
Name __________ben1: #REF!
Name __________ben1: #REF!
Name __________ben1: #REF!
Name __________ben10: #REF!
Name __________ben10: #REF!
Name __________ben10: #REF!
Name __________ben10: #REF!
Name __________ben10: #REF!
Name __________ben10: #REF!
Name __________ben10: #REF!
Name __________ben10: #REF!
Name __________ben10: #REF!
Name __________ben10: #REF!
Name __________ben10: #REF!
Name __________ben15: #REF!
Name __________ben15: #REF!
Name __________ben15: #REF!
Name __________ben15: #REF!
Name __________ben15: #REF!
Name __________ben15: #REF!
Name __________ben15: #REF!
Name __________ben15: #REF!
Name __________ben15: #REF!
Name __________ben15: #REF!
Name __________ben15: #REF!
Name __________BEN2: #REF!
Name __________ben20: #REF!
Name __________ben20: #REF!
Name __________ben20: #REF!
Name __________ben20: #REF!
Name __________ben20: #REF!
Name __________ben20: #REF!

Sheet GDR 3760_Pto. 01_Cert. 01
F1: DÓLAR BNA | G1: DÓLAR MEP
F2: 1066.5 | G2: 1170
F4: 45667 | I4: Certificado | J4: 1 | N4: 45747
B5: OBRA: EDIFICIO GDR 3760
B6: PRESUPUESTO OBRA CIVIL 01 | I6: Avance | L6: Importe
B7: Descripción | C7: U | D7: Cant | E7: P unit | F7: Subtotal | I7: Anterior | J7: Actual | K7: Acumulado | L7: Anterior | M7: Actual | N7: Acumulado
A8: 1 | B8: TAREAS PRELIMINARES | G8: =SUM(F9:F17) -> 19888202 | H8: =+G8/$G$46 -> 0.039704323
A9: 1.01 | B9: Limpieza y preparación del terreno - No cotiza | C9: gl | D9: 1 | E9: 0 | F9: =+E9*D9 -> 0 | K9: =+I9+J9 -> 0 | L9: =+F9*I9 -> 0 | M9: =+F9*J9 -> 0 | N9: =+F9*K9 -> 0
A10: 1.02 | B10: Topógrafo - Visita de obra replanteo | C10: gl | D10: 3 | E10: 384981 | F10: =+E10*D10 -> 1154943 | J10: 0.33 | K10: =+I10+J10 -> 0.33 | L10: =+F10*I10 -> 0 | M10: =+F10*J10 -> 381131.19 | N10: =+F10*K10 -> 381131.19
A11: 1.03 | B11: Cartel de Obra - No cotiza | C11: gl | D11: 1 | E11: 0 | F11: =+E11*D11 -> 0 | K11: =+I11+J11 -> 0 | L11: =+F11*I11 -> 0 | M11: =+F11*J11 -> 0 | N11: =+F11*K11 -> 0
A12: 1.04 | B12: Cerco de obra perimetral - En chapa C25 + Concertina + Porton corredizo | C12: ml | D12: 10 | E12: 256997 | F12: =+E12*D12 -> 2569970 | K12: =+I12+J12 -> 0 | L12: =+F12*I12 -> 0 | M12: =+F12*J12 -> 0 | N12: =+F12*K12 -> 0
A13: 1.05 | B13: Obrador, pañol y ducha. | C13: gl | D13: 1 | E13: 9812332 | F13: =+E13*D13 -> 9812332 | J13: 0.7 | K13: =+I13+J13 -> 0.7 | L13: =+F13*I13 -> 0 | M13: =+F13*J13 -> 6868632.4 | N13: =+F13*K13 -> 6868632.4
A14: 1.06 | B14: Alquiler de baños quimicos y duchas portatiles | C14: mes | D14: 4 | E14: 442847 | F14: =+E14*D14 -> 1771388 | J14: 0.25 | K14: =+I14+J14 -> 0.25 | L14: =+F14*I14 -> 0 | M14: =+F14*J14 -> 442847 | N14: =+F14*K14 -> 442847
A15: 1.07 | B15: Conexión pilar y luz de obra + Tablero de obra | C15: gl | D15: 1 | E15: 2287982 | F15: =+E15*D15 -> 2287982 | J15: 0.5 | K15: =+I15+J15 -> 0.5 | L15: =+F15*I15 -> 0 | M15: =+F15*J15 -> 1143991 | N15: =+F15*K15 -> 1143991
A16: 1.08 | B16: Conexión agua de obra, tanque + bomba | C16: gl | D16: 1 | E16: 1808218 | F16: =+E16*D16 -> 1808218 | J16: 0.2 | K16: =+I16+J16 -> 0.2 | L16: =+F16*I16 -> 0 | M16: =+F16*J16 -> 361643.6 | N16: =+F16*K16 -> 361643.6
A17: 1.09 | B17: Tramite luz de obra, certificado luz de obra (2) y medición PAT | C17: gl | D17: 1 | E17: 483369 | F17: =+E17*D17 -> 483369 | J17: 0.6 | K17: =+I17+J17 -> 0.6 | L17: =+F17*I17 -> 0 | M17: =+F17*J17 -> 290021.4 | N17: =+F17*K17 -> 290021.4
A18: 2 | B18: MOVIMIENTO DE TIERRA, COMPACTACION Y RELLENO | G18: =SUM(F19:F23) -> 29649894 | H18: =+G18/$G$46 -> 0.059192328
A19: 2.01 | B19: Excavación a maquina para submuración, subsuelo y fundaciones | C19: m3 | D19: 308 | E19: 52801 | F19: =+E19*D19 -> 16262708 | J19: 0.35 | K19: =+I19+J19 -> 0.35 | L19: =+F19*I19 -> 0 | M19: =+F19*J19 -> 5691947.8 | N19: =+F19*K19 -> 5691947.8
A20: 2.02 | B20: Perfilado manual de bases. Relleno y compactación de pozos | C20: gl | D20: 1 | E20: 11624716 | F20: =+E20*D20 -> 11624716 | J20: 0.15 | K20: =+I20+J20 -> 0.15 | L20: =+F20*I20 -> 0 | M20: =+F20*J20 -> 1743707.4 | N20: =+F20*K20 -> 1743707.4
A21: 2.03 | B21: Excavación manual para vigas de fundación | C21: m3 | D21: 15 | E21: 117498 | F21: =+E21*D21 -> 1762470 | K21: =+I21+J21 -> 0 | L21: =+F21*I21 -> 0 | M21: =+F21*J21 -> 0 | N21: =+F21*K21 -> 0
A22: 2.04 | B22: Aporte y compactación de suelo seleccionado, e: 40 cm (2 capas de 20 cm) - Cotizado Hº Pobre en item 8,02 | C22: m2 | D22: 0 | E22: 28536 | F22: =+E22*D22 -> 0 | K22: =+I22+J22 -> 0 | L22: =+F22*I22 -> 0 | M22: =+F22*J22 -> 0 | N22: =+F22*K22 -> 0
A23: 2.05 | B23: Demolición de bases existentes - No cotiza | C23: gl | D23: 0 | E23: 0 | F23: =+E23*D23 -> 0 | K23: =+I23+J23 -> 0 | L23: =+F23*I23 -> 0 | M23: =+F23*J23 -> 0 | N23: =+F23*K23 -> 0
A24: 3 | B24: ESTRUCTURA RESISTENTE | G24: =SUM(F25:F45) -> 451369624 | H24: =+G24/$G$46 -> 0.90110335
A25: 3.01 | B25: Hormigón de limpieza - e: 10 cm | C25: m3 | D25: 13 | E25: 293139 | F25: =+E25*D25 -> 3810807 | K25: =+I25+J25 -> 0 | L25: =+F25*I25 -> 0 | M25: =+F25*J25 -> 0 | N25: =+F25*K25 -> 0
A26: 3.02 | B26: Pilotes de tracción Ø 20 cm - (120 kg/m3 de hierro) | C26: u | D26: 18 | E26: 460697 | F26: =+E26*D26 -> 8292546 | J26: 1 | K26: =+I26+J26 -> 1 | L26: =+F26*I26 -> 0 | M26: =+F26*J26 -> 8292546 | N26: =+F26*K26 -> 8292546
A27: 3.03 | B27: Tabique submuración - H35 (95 kg/m3 de hierro) | C27: m3 | D27: 12 | E27: 1027679 | F27: =+E27*D27 -> 12332148 | J27: 0.35 | K27: =+I27+J27 -> 0.35 | L27: =+F27*I27 -> 0 | M27: =+F27*J27 -> 4316251.8 | N27: =+F27*K27 -> 4316251.8
A28: 3.04 | B28: Zapata corrida tabique - H35 (120 kg/m3 de hierro) | C28: m3 | D28: 7 | E28: 960201 | F28: =+E28*D28 -> 6721407 | J28: 0.35 | K28: =+I28+J28 -> 0.35 | L28: =+F28*I28 -> 0 | M28: =+F28*J28 -> 2352492.4 | N28: =+F28*K28 -> 2352492.4
A29: 3.05 | B29: Platea - H35 (95 kg/m3 de hierro) | C29: m3 | D29: 38 | E29: 714274 | F29: =+E29*D29 -> 27142412 | K29: =+I29+J29 -> 0 | L29: =+F29*I29 -> 0 | M29: =+F29*J29 -> 0 | N29: =+F29*K29 -> 0
A30: 3.06 | B30: Bases aisladas - (60 kg/m3 de hierro) | C30: m3 | D30: 51 | E30: 634926 | F30: =+E30*D30 -> 32381226 | K30: =+I30+J30 -> 0 | L30: =+F30*I30 -> 0 | M30: =+F30*J30 -> 0 | N30: =+F30*K30 -> 0
A31: 3.07 | B31: Troncos de columnas - H35 (240 kg/m3 de hierro) | C31: m3 | D31: 16 | E31: 1289285 | F31: =+E31*D31 -> 20628560 | K31: =+I31+J31 -> 0 | L31: =+F31*I31 -> 0 | M31: =+F31*J31 -> 0 | N31: =+F31*K31 -> 0
A32: 3.08 | B32: Viga de encadenado - H35 (180 kg/m3 de hierro) | C32: m3 | D32: 7 | E32: 1096226 | F32: =+E32*D32 -> 7673582 | K32: =+I32+J32 -> 0 | L32: =+F32*I32 -> 0 | M32: =+F32*J32 -> 0 | N32: =+F32*K32 -> 0
A33: 3.09 | B33: Losa maciza - H35 (100 kg/m3 de hierro) | C33: m3 | D33: 90 | E33: 804023 | F33: =+E33*D33 -> 72362070 | K33: =+I33+J33 -> 0 | L33: =+F33*I33 -> 0 | M33: =+F33*J33 -> 0 | N33: =+F33*K33 -> 0
A34: 3.1 | B34: Losa maciza de Hº visto - H35 (100 kg/m3 de hierro) | C34: m3 | D34: 32 | E34: 888733 | F34: =+E34*D34 -> 28439456 | K34: =+I34+J34 -> 0 | L34: =+F34*I34 -> 0 | M34: =+F34*J34 -> 0 | N34: =+F34*K34 -> 0
A35: 3.11 | B35: Vigas - H35 (180 kg/m3 de hierro) | C35: m3 | D35: 46 | E35: 1494687 | F35: =+E35*D35 -> 68755602 | K35: =+I35+J35 -> 0 | L35: =+F35*I35 -> 0 | M35: =+F35*J35 -> 0 | N35: =+F35*K35 -> 0
A36: 3.12 | B36: Vigas de H° visto - H35 (180 kg/m3 de hierro) | C36: m3 | D36: 31 | E36: 1673385 | F36: =+E36*D36 -> 51874935 | K36: =+I36+J36 -> 0 | L36: =+F36*I36 -> 0 | M36: =+F36*J36 -> 0 | N36: =+F36*K36 -> 0
A37: 3.13 | B37: Tabiques - H35 (100 kg/m3 de hierro) | C37: m3 | D37: 24 | E37: 1039014 | F37: =+E37*D37 -> 24936336 | K37: =+I37+J37 -> 0 | L37: =+F37*I37 -> 0 | M37: =+F37*J37 -> 0 | N37: =+F37*K37 -> 0
A38: 3.14 | B38: Columna - H35 (180 Kg/m3 de hierro) | C38: m3 | D38: 39 | E38: 1153260 | F38: =+E38*D38 -> 44977140 | K38: =+I38+J38 -> 0 | L38: =+F38*I38 -> 0 | M38: =+F38*J38 -> 0 | N38: =+F38*K38 -> 0
A39: 3.16 | B39: Columna vista- H35 (180 Kg/m3 de hierro) | C39: m3 | D39: 4 | E39: 1254164 | F39: =+E39*D39 -> 5016656 | K39: =+I39+J39 -> 0 | L39: =+F39*I39 -> 0 | M39: =+F39*J39 -> 0 | N39: =+F39*K39 -> 0
A40: 3.17 | B40: Escaleras de Hº visto - H35 (105 kg/m3 de hierro) | C40: m3 | D40: 10 | E40: 1111535 | F40: =+E40*D40 -> 11115350 | K40: =+I40+J40 -> 0 | L40: =+F40*I40 -> 0 | M40: =+F40*J40 -> 0 | N40: =+F40*K40 -> 0
... A44: 3.21 | B44: Permiso de estacionamiento de bomba de hormigón a contramano | C44: gl | D44: 3 | E44: 68289 | F44: =+E44*D44 -> 204867 | K44: =+I44+J44 -> 0 | L44: =+F44*I44 -> 0 | M44: =+F44*J44 -> 0 | N44: =+F44*K44 -> 0
...

Sheet GDR 3760_Pto. 01_Cert. 02
F1: DÓLAR BNA | G1: DÓLAR MEP
F2: 1066.5 | G2: 1170
F4: 45667 | I4: Certificado | J4: 2 | N4: 45777
B5: OBRA: EDIFICIO GDR 3760
B6: PRESUPUESTO OBRA CIVIL 01 | I6: Avance | L6: Importe
B7: Descripción | C7: U | D7: Cant | E7: P unit | F7: Subtotal | I7: Anterior | J7: Actual | K7: Acumulado | L7: Anterior | M7: Actual | N7: Acumulado
A8: 1 | B8: TAREAS PRELIMINARES | G8: =SUM(F9:F17) -> 19888202 | H8: =+G8/$G$46 -> 0.039704323
A9: 1.01 | B9: Limpieza y preparación del terreno - No cotiza | C9: gl | D9: 1 | E9: 0 | F9: =+E9*D9 -> 0 | I9: ='GDR 3760_Pto. 01_Cert. 01'!K9 -> 0 | K9: =+I9+J9 -> 0 | L9: =+F9*I9 -> 0 | M9: =+F9*J9 -> 0 | N9: =+F9*K9 -> 0
A10: 1.02 | B10: Topógrafo - Visita de obra replanteo | C10: gl | D10: 3 | E10: 384981 | F10: =+E10*D10 -> 1154943 | I10: ='GDR 3760_Pto. 01_Cert. 01'!K10 -> 0.33 | K10: =+I10+J10 -> 0.33 | L10: =+F10*I10 -> 381131.19 | M10: =+F10*J10 -> 0 | N10: =+F10*K10 -> 381131.19
A11: 1.03 | B11: Cartel de Obra - No cotiza | C11: gl | D11: 1 | E11: 0 | F11: =+E11*D11 -> 0 | I11: ='GDR 3760_Pto. 01_Cert. 01'!K11 -> 0 | K11: =+I11+J11 -> 0 | L11: =+F11*I11 -> 0 | M11: =+F11*J11 -> 0 | N11: =+F11*K11 -> 0
A12: 1.04 | B12: Cerco de obra perimetral - En chapa C25 + Concertina + Porton corredizo | C12: ml | D12: 10 | E12: 256997 | F12: =+E12*D12 -> 2569970 | I12: ='GDR 3760_Pto. 01_Cert. 01'!K12 -> 0 | K12: =+I12+J12 -> 0 | L12: =+F12*I12 -> 0 | M12: =+F12*J12 -> 0 | N12: =+F12*K12 -> 0
A13: 1.05 | B13: Obrador, pañol y ducha. | C13: gl | D13: 1 | E13: 9812332 | F13: =+E13*D13 -> 9812332 | I13: ='GDR 3760_Pto. 01_Cert. 01'!K13 -> 0.7 | K13: =+I13+J13 -> 0.7 | L13: =+F13*I13 -> 6868632.4 | M13: =+F13*J13 -> 0 | N13: =+F13*K13 -> 6868632.4
A14: 1.06 | B14: Alquiler de baños quimicos y duchas portatiles | C14: mes | D14: 4 | E14: 442847 | F14: =+E14*D14 -> 1771388 | I14: ='GDR 3760_Pto. 01_Cert. 01'!K14 -> 0.25 | J14: 0.2 | K14: =+I14+J14 -> 0.45 | L14: =+F14*I14 -> 442847 | M14: =+F14*J14 -> 354277.6 | N14: =+F14*K14 -> 797124.6
A15: 1.07 | B15: Conexión pilar y luz de obra + Tablero de obra | C15: gl | D15: 1 | E15: 2287982 | F15: =+E15*D15 -> 2287982 | I15: ='GDR 3760_Pto. 01_Cert. 01'!K15 -> 0.5 | K15: =+I15+J15 -> 0.5 | L15: =+F15*I15 -> 1143991 | M15: =+F15*J15 -> 0 | N15: =+F15*K15 -> 1143991
A16: 1.08 | B16: Conexión agua de obra, tanque + bomba | C16: gl | D16: 1 | E16: 1808218 | F16: =+E16*D16 -> 1808218 | I16: ='GDR 3760_Pto. 01_Cert. 01'!K16 -> 0.2 | K16: =+I16+J16 -> 0.2 | L16: =+F16*I16 -> 361643.6 | M16: =+F16*J16 -> 0 | N16: =+F16*K16 -> 361643.6
A17: 1.09 | B17: Tramite luz de obra, certificado luz de obra (2) y medición PAT | C17: gl | D17: 1 | E17: 483369 | F17: =+E17*D17 -> 483369 | I17: ='GDR 3760_Pto. 01_Cert. 01'!K17 -> 0.6 | K17: =+I17+J17 -> 0.6 | L17: =+F17*I17 -> 290021.4 | M17: =+F17*J17 -> 0 | N17: =+F17*K17 -> 290021.4
A18: 2 | B18: MOVIMIENTO DE TIERRA, COMPACTACION Y RELLENO | G18: =SUM(F19:F23) -> 29649894 | H18: =+G18/$G$46 -> 0.059192328
A19: 2.01 | B19: Excavación a maquina para submuración, subsuelo y fundaciones | C19: m3 | D19: 308 | E19: 52801 | F19: =+E19*D19 -> 16262708 | I19: ='GDR 3760_Pto. 01_Cert. 01'!K19 -> 0.35 | J19: 0.15 | K19: =+I19+J19 -> 0.5 | L19: =+F19*I19 -> 5691947.8 | M19: =+F19*J19 -> 2439406.2 | N19: =+F19*K19 -> 8131354
A20: 2.02 | B20: Perfilado manual de bases. Relleno y compactación de pozos | C20: gl | D20: 1 | E20: 11624716 | F20: =+E20*D20 -> 11624716 | I20: ='GDR 3760_Pto. 01_Cert. 01'!K20 -> 0.15 | J20: 0.25 | K20: =+I20+J20 -> 0.4 | L20: =+F20*I20 -> 1743707.4 | M20: =+F20*J20 -> 2906179 | N20: =+F20*K20 -> 4649886.4
A21: 2.03 | B21: Excavación manual para vigas de fundación | C21: m3 | D21: 15 | E21: 117498 | F21: =+E21*D21 -> 1762470 | I21: ='GDR 3760_Pto. 01_Cert. 01'!K21 -> 0 | K21: =+I21+J21 -> 0 | L21: =+F21*I21 -> 0 | M21: =+F21*J21 -> 0 | N21: =+F21*K21 -> 0
A22: 2.04 | B22: Aporte y compactación de suelo seleccionado, e: 40 cm (2 capas de 20 cm) - Cotizado Hº Pobre en item 8,02 | C22: m2 | D22: 0 | E22: 28536 | F22: =+E22*D22 -> 0 | I22: ='GDR 3760_Pto. 01_Cert. 01'!K22 -> 0 | K22: =+I22+J22 -> 0 | L22: =+F22*I22 -> 0 | M22: =+F22*J22 -> 0 | N22: =+F22*K22 -> 0
A23: 2.05 | B23: Demolición de bases existentes - No cotiza | C23: gl | D23: 0 | E23: 0 | F23: =+E23*D23 -> 0 | I23: ='GDR 3760_Pto. 01_Cert. 01'!K23 -> 0 | K23: =+I23+J23 -> 0 | L23: =+F23*I23 -> 0 | M23: =+F23*J23 -> 0 | N23: =+F23*K23 -> 0
A24: 3 | B24: ESTRUCTURA RESISTENTE | G24: =SUM(F25:F45) -> 451369624 | H24: =+G24/$G$46 -> 0.90110335
A25: 3.01 | B25: Hormigón de limpieza - e: 10 cm | C25: m3 | D25: 13 | E25: 293139 | F25: =+E25*D25 -> 3810807 | I25: ='GDR 3760_Pto. 01_Cert. 01'!K25 -> 0 | J25: 0.33 | K25: =+I25+J25 -> 0.33 | L25: =+F25*I25 -> 0 | M25: =+F25*J25 -> 1257566.3 | N25: =+F25*K25 -> 1257566.3
A26: 3.02 | B26: Pilotes de tracción Ø 20 cm - (120 kg/m3 de hierro) | C26: u | D26: 18 | E26: 460697 | F26: =+E26*D26 -> 8292546 | I26: ='GDR 3760_Pto. 01_Cert. 01'!K26 -> 1 | K26: =+I26+J26 -> 1 | L26: =+F26*I26 -> 8292546 | M26: =+F26*J26 -> 0 | N26: =+F26*K26 -> 8292546
A27: 3.03 | B27: Tabique submuración - H35 (95 kg/m3 de hierro) | C27: m3 | D27: 12 | E27: 1027679 | F27: =+E27*D27 -> 12332148 | I27: ='GDR 3760_Pto. 01_Cert. 01'!K27 -> 0.35 | J27: 0.15 | K27: =+I27+J27 -> 0.5 | L27: =+F27*I27 -> 4316251.8 | M27: =+F27*J27 -> 1849822.2 | N27: =+F27*K27 -> 6166074
A28: 3.04 | B28: Zapata corrida tabique - H35 (120 kg/m3 de hierro) | C28: m3 | D28: 7 | E28: 960201 | F28: =+E28*D28 -> 6721407 | I28: ='GDR 3760_Pto. 01_Cert. 01'!K28 -> 0.35 | J28: 0.15 | K28: =+I28+J28 -> 0.5 | L28: =+F28*I28 -> 2352492.4 | M28: =+F28*J28 -> 1008211 | N28: =+F28*K28 -> 3360703.5
A29: 3.05 | B29: Platea - H35 (95 kg/m3 de hierro) | C29: m3 | D29: 38 | E29: 714274 | F29: =+E29*D29 -> 27142412 | I29: ='GDR 3760_Pto. 01_Cert. 01'!K29 -> 0 | K29: =+I29+J29 -> 0 | L29: =+F29*I29 -> 0 | M29: =+F29*J29 -> 0 | N29: =+F29*K29 -> 0
A30: 3.06 | B30: Bases aisladas - (60 kg/m3 de hierro) | C30: m3 | D30: 51 | E30: 634926 | F30: =+E30*D30 -> 32381226 | I30: ='GDR 3760_Pto. 01_Cert. 01'!K30 -> 0 | J30: 0.33 | K30: =+I30+J30 -> 0.33 | L30: =+F30*I30 -> 0 | M30: =+F30*J30 -> 10685805 | N30: =+F30*K30 -> 10685805
A31: 3.07 | B31: Troncos de columnas - H35 (240 kg/m3 de hierro) | C31: m3 | D31: 16 | E31: 1289285 | F31: =+E31*D31 -> 20628560 | I31: ='GDR 3760_Pto. 01_Cert. 01'!K31 -> 0 | J31: 0.3 | K31: =+I31+J31 -> 0.3 | L31: =+F31*I31 -> 0 | M31: =+F31*J31 -> 6188568 | N31: =+F31*K31 -> 6188568
A32: 3.08 | B32: Viga de encadenado - H35 (180 kg/m3 de hierro) | C32: m3 | D32: 7 | E32: 1096226 | F32: =+E32*D32 -> 7673582 | I32: ='GDR 3760_Pto. 01_Cert. 01'!K32 -> 0 | K32: =+I32+J32 -> 0 | L32: =+F32*I32 -> 0 | M32: =+F32*J32 -> 0 | N32: =+F32*K32 -> 0
A33: 3.09 | B33: Losa maciza - H35 (100 kg/m3 de hierro) | C33: m3 | D33: 90 | E33: 804023 | F33: =+E33*D33 -> 72362070 | I33: ='GDR 3760_Pto. 01_Cert. 01'!K33 -> 0 | K33: =+I33+J33 -> 0 | L33: =+F33*I33 -> 0 | M33: =+F33*J33 -> 0 | N33: =+F33*K33 -> 0
A34: 3.1 | B34: Losa maciza de Hº visto - H35 (100 kg/m3 de hierro) | C34: m3 | D34: 32 | E34: 888733 | F34: =+E34*D34 -> 28439456 | I34: ='GDR 3760_Pto. 01_Cert. 01'!K34 -> 0 | K34: =+I34+J34 -> 0 | L34: =+F34*I34 -> 0 | M34: =+F34*J34 -> 0 | N34: =+F34*K34 -> 0
A35: 3.11 | B35: Vigas - H35 (180 kg/m3 de hierro) | C35: m3 | D35: 46 | E35: 1494687 | F35: =+E35*D35 -> 68755602 | I35: ='GDR 3760_Pto. 01_Cert. 01'!K35 -> 0 | K35: =+I35+J35 -> 0 | L35: =+F35*I35 -> 0 | M35: =+F35*J35 -> 0 | N35: =+F35*K35 -> 0
A36: 3.12 | B36: Vigas de H° visto - H35 (180 kg/m3 de hierro) | C36: m3 | D36: 31 | E36: 1673385 | F36: =+E36*D36 -> 51874935 | I36: ='GDR 3760_Pto. 01_Cert. 01'!K36 -> 0 | K36: =+I36+J36 -> 0 | L36: =+F36*I36 -> 0 | M36: =+F36*J36 -> 0 | N36: =+F36*K36 -> 0
A37: 3.13 | B37: Tabiques - H35 (100 kg/m3 de hierro) | C37: m3 | D37: 24 | E37: 1039014 | F37: =+E37*D37 -> 24936336 | I37: ='GDR 3760_Pto. 01_Cert. 01'!K37 -> 0 | K37: =+I37+J37 -> 0 | L37: =+F37*I37 -> 0 | M37: =+F37*J37 -> 0 | N37: =+F37*K37 -> 0
A38: 3.14 | B38: Columna - H35 (180 Kg/m3 de hierro) | C38: m3 | D38: 39 | E38: 1153260 | F38: =+E38*D38 -> 44977140 | I38: ='GDR 3760_Pto. 01_Cert. 01'!K38 -> 0 | K38: =+I38+J38 -> 0 | L38: =+F38*I38 -> 0 | M38: =+F38*J38 -> 0 | N38: =+F38*K38 -> 0
A39: 3.16 | B39: Columna vista- H35 (180 Kg/m3 de hierro) | C39: m3 | D39: 4 | E39: 1254164 | F39: =+E39*D39 -> 5016656 | I39: ='GDR 3760_Pto. 01_Cert. 01'!K39 -> 0 | K39: =+I39+J39 -> 0 | L39: =+F39*I39 -> 0 | M39: =+F39*J39 -> 0 | N39: =+F39*K39 -> 0
A40: 3.17 | B40: Escaleras de Hº visto - H35 (105 kg/m3 de hierro) | C40: m3 | D40: 10 | E40: 1111535 | F40: =+E40*D40 -> 11115350 | I40: ='GDR 3760_Pto. 01_Cert. 01'!K40 -> 0 | K40: =+I40+J40 -> 0 | L40: =+F40*I40 -> 0 | M40: =+F40*J40 -> 0 | N40: =+F40*K40 -> 0
A41: 3.18 | B41: Tanques de HºAº - H35 (100 kg/m3 de hierro) - Tanque de reserva | C41: m3 | D41: 6 | E41: 1039014 | F41: =+E41*D41 -> 6234084 | I41: ='GDR 3760_Pto. 01_Cert. 01'!K41 -> 0 | K41: =+I41+J41 -> 0 | L41: =+F41*I41 -> 0 | M41: =+F41*J41 -> 0 | N41: =+F41*K41 -> 0
...

Sheet GDR 3760_Pto. 01_Cert. 03
F1: DÓLAR BNA | G1: DÓLAR MEP
F2: 1066.5 | G2: 1170
F4: 45667 | I4: Certificado | J4: 3 | N4: 45808
B5: OBRA: EDIFICIO GDR 3760
B6: PRESUPUESTO OBRA CIVIL 01 | I6: Avance | L6: Importe
B7: Descripción | C7: U | D7: Cant | E7: P unit | F7: Subtotal | I7: Anterior | J7: Actual | K7: Acumulado | L7: Anterior | M7: Actual | N7: Acumulado
A8: 1 | B8: TAREAS PRELIMINARES | G8: =SUM(F9:F17) -> 19888202 | H8: =+G8/$G$46 -> 0.039704323
A9: 1.01 | B9: Limpieza y preparación del terreno - No cotiza | C9: gl | D9: 1 | E9: 0 | F9: =+E9*D9 -> 0 | I9: 0 | K9: =+I9+J9 -> 0 | L9: =+F9*I9 -> 0 | M9: =+F9*J9 -> 0 | N9: =+F9*K9 -> 0
A10: 1.02 | B10: Topógrafo - Visita de obra replanteo | C10: gl | D10: 3 | E10: 384981 | F10: =+E10*D10 -> 1154943 | I10: 0.33 | K10: =+I10+J10 -> 0.33 | L10: =+F10*I10 -> 381131.19 | M10: =+F10*J10 -> 0 | N10: =+F10*K10 -> 381131.19
A11: 1.03 | B11: Cartel de Obra - No cotiza | C11: gl | D11: 1 | E11: 0 | F11: =+E11*D11 -> 0 | I11: 0 | K11: =+I11+J11 -> 0 | L11: =+F11*I11 -> 0 | M11: =+F11*J11 -> 0 | N11: =+F11*K11 -> 0
A12: 1.04 | B12: Cerco de obra perimetral - En chapa C25 + Concertina + Porton corredizo | C12: ml | D12: 10 | E12: 256997 | F12: =+E12*D12 -> 2569970 | I12: 0 | K12: =+I12+J12 -> 0 | L12: =+F12*I12 -> 0 | M12: =+F12*J12 -> 0 | N12: =+F12*K12 -> 0
A13: 1.05 | B13: Obrador, pañol y ducha. | C13: gl | D13: 1 | E13: 9812332 | F13: =+E13*D13 -> 9812332 | I13: 0.7 | K13: =+I13+J13 -> 0.7 | L13: =+F13*I13 -> 6868632.4 | M13: =+F13*J13 -> 0 | N13: =+F13*K13 -> 6868632.4
A14: 1.06 | B14: Alquiler de baños quimicos y duchas portatiles | C14: mes | D14: 4 | E14: 442847 | F14: =+E14*D14 -> 1771388 | I14: 0.45 | J14: 0.25 | K14: =+I14+J14 -> 0.7 | L14: =+F14*I14 -> 797124.6 | M14: =+F14*J14 -> 442847 | N14: =+F14*K14 -> 1239971.6
A15: 1.07 | B15: Conexión pilar y luz de obra + Tablero de obra | C15: gl | D15: 1 | E15: 2287982 | F15: =+E15*D15 -> 2287982 | I15: 0.5 | K15: =+I15+J15 -> 0.5 | L15: =+F15*I15 -> 1143991 | M15: =+F15*J15 -> 0 | N15: =+F15*K15 -> 1143991
A16: 1.08 | B16: Conexión agua de obra, tanque + bomba | C16: gl | D16: 1 | E16: 1808218 | F16: =+E16*D16 -> 1808218 | I16: 0.2 | K16: =+I16+J16 -> 0.2 | L16: =+F16*I16 -> 361643.6 | M16: =+F16*J16 -> 0 | N16: =+F16*K16 -> 361643.6
A17: 1.09 | B17: Tramite luz de obra, certificado luz de obra (2) y medición PAT | C17: gl | D17: 1 | E17: 483369 | F17: =+E17*D17 -> 483369 | I17: 0.6 | K17: =+I17+J17 -> 0.6 | L17: =+F17*I17 -> 290021.4 | M17: =+F17*J17 -> 0 | N17: =+F17*K17 -> 290021.4
A18: 2 | B18: MOVIMIENTO DE TIERRA, COMPACTACION Y RELLENO | G18: =SUM(F19:F23) -> 29649894 | H18: =+G18/$G$46 -> 0.059192328
A19: 2.01 | B19: Excavación a maquina para submuración, subsuelo y fundaciones | C19: m3 | D19: 308 | E19: 52801 | F19: =+E19*D19 -> 16262708 | I19: 0.5 | J19: 0.3 | K19: =+I19+J19 -> 0.8 | L19: =+F19*I19 -> 8131354 | M19: =+F19*J19 -> 4878812.4 | N19: =+F19*K19 -> 13010166
A20: 2.02 | B20: Perfilado manual de bases. Relleno y compactación de pozos | C20: gl | D20: 1 | E20: 11624716 | F20: =+E20*D20 -> 11624716 | I20: 0.4 | J20: 0.25 | K20: =+I20+J20 -> 0.65 | L20: =+F20*I20 -> 4649886.4 | M20: =+F20*J20 -> 2906179 | N20: =+F20*K20 -> 7556065.4
A21: 2.03 | B21: Excavación manual para vigas de fundación | C21: m3 | D21: 15 | E21: 117498 | F21: =+E21*D21 -> 1762470 | I21: 0 | J21: 0.3 | K21: =+I21+J21 -> 0.3 | L21: =+F21*I21 -> 0 | M21: =+F21*J21 -> 528741 | N21: =+F21*K21 -> 528741
A22: 2.04 | B22: Aporte y compactación de suelo seleccionado, e: 40 cm (2 capas de 20 cm) - Cotizado Hº Pobre en item 8,02 | C22: m2 | D22: 0 | E22: 28536 | F22: =+E22*D22 -> 0 | I22: 0 | K22: =+I22+J22 -> 0 | L22: =+F22*I22 -> 0 | M22: =+F22*J22 -> 0 | N22: =+F22*K22 -> 0
A23: 2.05 | B23: Demolición de bases existentes - No cotiza | C23: gl | D23: 0 | E23: 0 | F23: =+E23*D23 -> 0 | I23: 0 | K23: =+I23+J23 -> 0 | L23: =+F23*I23 -> 0 | M23: =+F23*J23 -> 0 | N23: =+F23*K23 -> 0
A24: 3 | B24: ESTRUCTURA RESISTENTE | G24: =SUM(F25:F45) -> 451369624 | H24: =+G24/$G$46 -> 0.90110335
A25: 3.01 | B25: Hormigón de limpieza - e: 10 cm | C25: m3 | D25: 13 | E25: 293139 | F25: =+E25*D25 -> 3810807 | I25: 0.33 | J25: 0.5 | K25: =+I25+J25 -> 0.83 | L25: =+F25*I25 -> 1257566.3 | M25: =+F25*J25 -> 1905403.5 | N25: =+F25*K25 -> 3162969.8
A26: 3.02 | B26: Pilotes de tracción Ø 20 cm - (120 kg/m3 de hierro) | C26: u | D26: 18 | E26: 460697 | F26: =+E26*D26 -> 8292546 | I26: 1 | K26: =+I26+J26 -> 1 | L26: =+F26*I26 -> 8292546 | M26: =+F26*J26 -> 0 | N26: =+F26*K26 -> 8292546
A27: 3.03 | B27: Tabique submuración - H35 (95 kg/m3 de hierro) | C27: m3 | D27: 12 | E27: 1027679 | F27: =+E27*D27 -> 12332148 | I27: 0.5 | J27: 0.4 | K27: =+I27+J27 -> 0.9 | L27: =+F27*I27 -> 6166074 | M27: =+F27*J27 -> 4932859.2 | N27: =+F27*K27 -> 11098933
A28: 3.04 | B28: Zapata corrida tabique - H35 (120 kg/m3 de hierro) | C28: m3 | D28: 7 | E28: 960201 | F28: =+E28*D28 -> 6721407 | I28: 0.5 | J28: 0.4 | K28: =+I28+J28 -> 0.9 | L28: =+F28*I28 -> 3360703.5 | M28: =+F28*J28 -> 2688562.8 | N28: =+F28*K28 -> 6049266.3
A29: 3.05 | B29: Platea - H35 (95 kg/m3 de hierro) | C29: m3 | D29: 38 | E29: 714274 | F29: =+E29*D29 -> 27142412 | I29: 0 | J29: 1 | K29: =+I29+J29 -> 1 | L29: =+F29*I29 -> 0 | M29: =+F29*J29 -> 27142412 | N29: =+F29*K29 -> 27142412
A30: 3.06 | B30: Bases aisladas - (60 kg/m3 de hierro) | C30: m3 | D30: 51 | E30: 634926 | F30: =+E30*D30 -> 32381226 | I30: 0.33 | J30: 0.33 | K30: =+I30+J30 -> 0.66 | L30: =+F30*I30 -> 10685805 | M30: =+F30*J30 -> 10685805 | N30: =+F30*K30 -> 21371609
A31: 3.07 | B31: Troncos de columnas - H35 (240 kg/m3 de hierro) | C31: m3 | D31: 16 | E31: 1289285 | F31: =+E31*D31 -> 20628560 | I31: 0.3 | J31: 0.3 | K31: =+I31+J31 -> 0.6 | L31: =+F31*I31 -> 6188568 | M31: =+F31*J31 -> 6188568 | N31: =+F31*K31 -> 12377136
A32: 3.08 | B32: Viga de encadenado - H35 (180 kg/m3 de hierro) | C32: m3 | D32: 7 | E32: 1096226 | F32: =+E32*D32 -> 7673582 | I32: 0 | J32: 0.3 | K32: =+I32+J32 -> 0.3 | L32: =+F32*I32 -> 0 | M32: =+F32*J32 -> 2302074.6 | N32: =+F32*K32 -> 2302074.6
A33: 3.09 | B33: Losa maciza - H35 (100 kg/m3 de hierro) | C33: m3 | D33: 90 | E33: 804023 | F33: =+E33*D33 -> 72362070 | I33: 0 | K33: =+I33+J33 -> 0 | L33: =+F33*I33 -> 0 | M33: =+F33*J33 -> 0 | N33: =+F33*K33 -> 0
A34: 3.1 | B34: Losa maciza de Hº visto - H35 (100 kg/m3 de hierro) | C34: m3 | D34: 32 | E34: 888733 | F34: =+E34*D34 -> 28439456 | I34: 0 | K34: =+I34+J34 -> 0 | L34: =+F34*I34 -> 0 | M34: =+F34*J34 -> 0 | N34: =+F34*K34 -> 0
A35: 3.11 | B35: Vigas - H35 (180 kg/m3 de hierro) | C35: m3 | D35: 46 | E35: 1494687 | F35: =+E35*D35 -> 68755602 | I35: 0 | K35: =+I35+J35 -> 0 | L35: =+F35*I35 -> 0 | M35: =+F35*J35 -> 0 | N35: =+F35*K35 -> 0
A36: 3.12 | B36: Vigas de H° visto - H35 (180 kg/m3 de hierro) | C36: m3 | D36: 31 | E36: 1673385 | F36: =+E36*D36 -> 51874935 | I36: 0 | K36: =+I36+J36 -> 0 | L36: =+F36*I36 -> 0 | M36: =+F36*J36 -> 0 | N36: =+F36*K36 -> 0
A37: 3.13 | B37: Tabiques - H35 (100 kg/m3 de hierro) | C37: m3 | D37: 24 | E37: 1039014 | F37: =+E37*D37 -> 24936336 | I37: 0 | K37: =+I37+J37 -> 0 | L37: =+F37*I37 -> 0 | M37: =+F37*J37 -> 0 | N37: =+F37*K37 -> 0
A38: 3.14 | B38: Columna - H35 (180 Kg/m3 de hierro) | C38: m3 | D38: 39 | E38: 1153260 | F38: =+E38*D38 -> 44977140 | I38: 0 | K38: =+I38+J38 -> 0 | L38: =+F38*I38 -> 0 | M38: =+F38*J38 -> 0 | N38: =+F38*K38 -> 0
A39: 3.16 | B39: Columna vista- H35 (180 Kg/m3 de hierro) | C39: m3 | D39: 4 | E39: 1254164 | F39: =+E39*D39 -> 5016656 | I39: 0 | K39: =+I39+J39 -> 0 | L39: =+F39*I39 -> 0 | M39: =+F39*J39 -> 0 | N39: =+F39*K39 -> 0
A40: 3.17 | B40: Escaleras de Hº visto - H35 (105 kg/m3 de hierro) | C40: m3 | D40: 10 | E40: 1111535 | F40: =+E40*D40 -> 11115350 | I40: 0 | K40: =+I40+J40 -> 0 | L40: =+F40*I40 -> 0 | M40: =+F40*J40 -> 0 | N40: =+F40*K40 -> 0
A41: 3.18 | B41: Tanques de HºAº - H35 (100 kg/m3 de hierro) - Tanque de reserva | C41: m3 | D41: 6 | E41: 1039014 | F41: =+E41*D41 -> 6234084 | I41: 0 | K41: =+I41+J41 -> 0 | L41: =+F41*I41 -> 0 | M41: =+F41*J41 -> 0 | N41: =+F41*K41 -> 0
...

Sheet GDR 3760_Pto. 01_Cert. 04
F1: DÓLAR BNA | G1: DÓLAR MEP
F2: 1066.5 | G2: 1170
F4: 45667 | I4: Certificado | J4: 4 | N4: 45838
B5: OBRA: EDIFICIO GDR 3760
B6: PRESUPUESTO OBRA CIVIL 01 | I6: Avance | L6: Importe
B7: Descripción | C7: U | D7: Cant | E7: P unit | F7: Subtotal | I7: Anterior | J7: Actual | K7: Acumulado | L7: Anterior | M7: Actual | N7: Acumulado
A8: 1 | B8: TAREAS PRELIMINARES | G8: =SUM(F9:F17) -> 19888202 | H8: =+G8/$G$46 -> 0.039704323
A9: 1.01 | B9: Limpieza y preparación del terreno - No cotiza | C9: gl | D9: 1 | E9: 0 | F9: =+E9*D9 -> 0 | I9: 0 | K9: =+I9+J9 -> 0 | L9: =+F9*I9 -> 0 | M9: =+F9*J9 -> 0 | N9: =+F9*K9 -> 0
A10: 1.02 | B10: Topógrafo - Visita de obra replanteo | C10: gl | D10: 3 | E10: 384981 | F10: =+E10*D10 -> 1154943 | I10: 0.33 | K10: =+I10+J10 -> 0.33 | L10: =+F10*I10 -> 381131.19 | M10: =+F10*J10 -> 0 | N10: =+F10*K10 -> 381131.19
A11: 1.03 | B11: Cartel de Obra - No cotiza | C11: gl | D11: 1 | E11: 0 | F11: =+E11*D11 -> 0 | I11: 0 | K11: =+I11+J11 -> 0 | L11: =+F11*I11 -> 0 | M11: =+F11*J11 -> 0 | N11: =+F11*K11 -> 0
A12: 1.04 | B12: Cerco de obra perimetral - En chapa C25 + Concertina + Porton corredizo | C12: ml | D12: 10 | E12: 256997 | F12: =+E12*D12 -> 2569970 | I12: 0 | K12: =+I12+J12 -> 0 | L12: =+F12*I12 -> 0 | M12: =+F12*J12 -> 0 | N12: =+F12*K12 -> 0
A13: 1.05 | B13: Obrador, pañol y ducha. | C13: gl | D13: 1 | E13: 9812332 | F13: =+E13*D13 -> 9812332 | I13: 0.7 | K13: =+I13+J13 -> 0.7 | L13: =+F13*I13 -> 6868632.4 | M13: =+F13*J13 -> 0 | N13: =+F13*K13 -> 6868632.4
A14: 1.06 | B14: Alquiler de baños quimicos y duchas portatiles | C14: mes | D14: 4 | E14: 442847 | F14: =+E14*D14 -> 1771388 | I14: 0.7 | J14: 0.2 | K14: =+I14+J14 -> 0.9 | L14: =+F14*I14 -> 1239971.6 | M14: =+F14*J14 -> 354277.6 | N14: =+F14*K14 -> 1594249.2
A15: 1.07 | B15: Conexión pilar y luz de obra + Tablero de obra | C15: gl | D15: 1 | E15: 2287982 | F15: =+E15*D15 -> 2287982 | I15: 0.5 | K15: =+I15+J15 -> 0.5 | L15: =+F15*I15 -> 1143991 | M15: =+F15*J15 -> 0 | N15: =+F15*K15 -> 1143991
A16: 1.08 | B16: Conexión agua de obra, tanque + bomba | C16: gl | D16: 1 | E16: 1808218 | F16: =+E16*D16 -> 1808218 | I16: 0.2 | K16: =+I16+J16 -> 0.2 | L16: =+F16*I16 -> 361643.6 | M16: =+F16*J16 -> 0 | N16: =+F16*K16 -> 361643.6
A17: 1.09 | B17: Tramite luz de obra, certificado luz de obra (2) y medición PAT | C17: gl | D17: 1 | E17: 483369 | F17: =+E17*D17 -> 483369 | I17: 0.6 | K17: =+I17+J17 -> 0.6 | L17: =+F17*I17 -> 290021.4 | M17: =+F17*J17 -> 0 | N17: =+F17*K17 -> 290021.4
A18: 2 | B18: MOVIMIENTO DE TIERRA, COMPACTACION Y RELLENO | G18: =SUM(F19:F23) -> 29649894 | H18: =+G18/$G$46 -> 0.059192328
A19: 2.01 | B19: Excavación a maquina para submuración, subsuelo y fundaciones | C19: m3 | D19: 308 | E19: 52801 | F19: =+E19*D19 -> 16262708 | I19: 0.8 | J19: 0.2 | K19: =+I19+J19 -> 1 | L19: =+F19*I19 -> 13010166 | M19: =+F19*J19 -> 3252541.6 | N19: =+F19*K19 -> 16262708
A20: 2.02 | B20: Perfilado manual de bases. Relleno y compactación de pozos | C20: gl | D20: 1 | E20: 11624716 | F20: =+E20*D20 -> 11624716 | I20: 0.65 | J20: 0.35 | K20: =+I20+J20 -> 1 | L20: =+F20*I20 -> 7556065.4 | M20: =+F20*J20 -> 4068650.6 | N20: =+F20*K20 -> 11624716
A21: 2.03 | B21: Excavación manual para vigas de fundación | C21: m3 | D21: 15 | E21: 117498 | F21: =+E21*D21 -> 1762470 | I21: 0.3 | J21: 0.4 | K21: =+I21+J21 -> 0.7 | L21: =+F21*I21 -> 528741 | M21: =+F21*J21 -> 704988 | N21: =+F21*K21 -> 1233729
A22: 2.04 | B22: Aporte y compactación de suelo seleccionado, e: 40 cm (2 capas de 20 cm) - Cotizado Hº Pobre en item 8,02 | C22: m2 | D22: 0 | E22: 28536 | F22: =+E22*D22 -> 0 | I22: 0 | K22: =+I22+J22 -> 0 | L22: =+F22*I22 -> 0 | M22: =+F22*J22 -> 0 | N22: =+F22*K22 -> 0
A23: 2.05 | B23: Demolición de bases existentes - No cotiza | C23: gl | D23: 0 | E23: 0 | F23: =+E23*D23 -> 0 | I23: 0 | K23: =+I23+J23 -> 0 | L23: =+F23*I23 -> 0 | M23: =+F23*J23 -> 0 | N23: =+F23*K23 -> 0
A24: 3 | B24: ESTRUCTURA RESISTENTE | G24: =SUM(F25:F45) -> 451369624 | H24: =+G24/$G$46 -> 0.90110335
A25: 3.01 | B25: Hormigón de limpieza - e: 10 cm | C25: m3 | D25: 13 | E25: 293139 | F25: =+E25*D25 -> 3810807 | I25: 0.83 | J25: 0.17 | K25: =+I25+J25 -> 1 | L25: =+F25*I25 -> 3162969.8 | M25: =+F25*J25 -> 647837.19 | N25: =+F25*K25 -> 3810807
A26: 3.02 | B26: Pilotes de tracción Ø 20 cm - (120 kg/m3 de hierro) | C26: u | D26: 18 | E26: 460697 | F26: =+E26*D26 -> 8292546 | I26: 1 | K26: =+I26+J26 -> 1 | L26: =+F26*I26 -> 8292546 | M26: =+F26*J26 -> 0 | N26: =+F26*K26 -> 8292546
A27: 3.03 | B27: Tabique submuración - H35 (95 kg/m3 de hierro) | C27: m3 | D27: 12 | E27: 1027679 | F27: =+E27*D27 -> 12332148 | I27: 0.9 | J27: 0.1 | K27: =+I27+J27 -> 1 | L27: =+F27*I27 -> 11098933 | M27: =+F27*J27 -> 1233214.8 | N27: =+F27*K27 -> 12332148
A28: 3.04 | B28: Zapata corrida tabique - H35 (120 kg/m3 de hierro) | C28: m3 | D28: 7 | E28: 960201 | F28: =+E28*D28 -> 6721407 | I28: 0.9 | J28: 0.1 | K28: =+I28+J28 -> 1 | L28: =+F28*I28 -> 6049266.3 | M28: =+F28*J28 -> 672140.7 | N28: =+F28*K28 -> 6721407
A29: 3.05 | B29: Platea - H35 (95 kg/m3 de hierro) | C29: m3 | D29: 38 | E29: 714274 | F29: =+E29*D29 -> 27142412 | I29: 1 | K29: =+I29+J29 -> 1 | L29: =+F29*I29 -> 27142412 | M29: =+F29*J29 -> 0 | N29: =+F29*K29 -> 27142412
A30: 3.06 | B30: Bases aisladas - (60 kg/m3 de hierro) | C30: m3 | D30: 51 | E30: 634926 | F30: =+E30*D30 -> 32381226 | I30: 0.66 | J30: 0.34 | K30: =+I30+J30 -> 1 | L30: =+F30*I30 -> 21371609 | M30: =+F30*J30 -> 11009617 | N30: =+F30*K30 -> 32381226
A31: 3.07 | B31: Troncos de columnas - H35 (240 kg/m3 de hierro) | C31: m3 | D31: 16 | E31: 1289285 | F31: =+E31*D31 -> 20628560 | I31: 0.6 | J31: 0.4 | K31: =+I31+J31 -> 1 | L31: =+F31*I31 -> 12377136 | M31: =+F31*J31 -> 8251424 | N31: =+F31*K31 -> 20628560
A32: 3.08 | B32: Viga de encadenado - H35 (180 kg/m3 de hierro) | C32: m3 | D32: 7 | E32: 1096226 | F32: =+E32*D32 -> 7673582 | I32: 0.3 | J32: 0.7 | K32: =+I32+J32 -> 1 | L32: =+F32*I32 -> 2302074.6 | M32: =+F32*J32 -> 5371507.4 | N32: =+F32*K32 -> 7673582
A33: 3.09 | B33: Losa maciza - H35 (100 kg/m3 de hierro) | C33: m3 | D33: 90 | E33: 804023 | F33: =+E33*D33 -> 72362070 | I33: 0 | K33: =+I33+J33 -> 0 | L33: =+F33*I33 -> 0 | M33: =+F33*J33 -> 0 | N33: =+F33*K33 -> 0
A34: 3.1 | B34: Losa maciza de Hº visto - H35 (100 kg/m3 de hierro) | C34: m3 | D34: 32 | E34: 888733 | F34: =+E34*D34 -> 28439456 | I34: 0 | K34: =+I34+J34 -> 0 | L34: =+F34*I34 -> 0 | M34: =+F34*J34 -> 0 | N34: =+F34*K34 -> 0
A35: 3.11 | B35: Vigas - H35 (180 kg/m3 de hierro) | C35: m3 | D35: 46 | E35: 1494687 | F35: =+E35*D35 -> 68755602 | I35: 0 | K35: =+I35+J35 -> 0 | L35: =+F35*I35 -> 0 | M35: =+F35*J35 -> 0 | N35: =+F35*K35 -> 0
A36: 3.12 | B36: Vigas de H° visto - H35 (180 kg/m3 de hierro) | C36: m3 | D36: 31 | E36: 1673385 | F36: =+E36*D36 -> 51874935 | I36: 0 | K36: =+I36+J36 -> 0 | L36: =+F36*I36 -> 0 | M36: =+F36*J36 -> 0 | N36: =+F36*K36 -> 0
A37: 3.13 | B37: Tabiques - H35 (100 kg/m3 de hierro) | C37: m3 | D37: 24 | E37: 1039014 | F37: =+E37*D37 -> 24936336 | I37: 0 | K37: =+I37+J37 -> 0 | L37: =+F37*I37 -> 0 | M37: =+F37*J37 -> 0 | N37: =+F37*K37 -> 0
A38: 3.14 | B38: Columna - H35 (180 Kg/m3 de hierro) | C38: m3 | D38: 39 | E38: 1153260 | F38: =+E38*D38 -> 44977140 | I38: 0 | K38: =+I38+J38 -> 0 | L38: =+F38*I38 -> 0 | M38: =+F38*J38 -> 0 | N38: =+F38*K38 -> 0
A39: 3.16 | B39: Columna vista- H35 (180 Kg/m3 de hierro) | C39: m3 | D39: 4 | E39: 1254164 | F39: =+E39*D39 -> 5016656 | I39: 0 | K39: =+I39+J39 -> 0 | L39: =+F39*I39 -> 0 | M39: =+F39*J39 -> 0 | N39: =+F39*K39 -> 0
A40: 3.17 | B40: Escaleras de Hº visto - H35 (105 kg/m3 de hierro) | C40: m3 | D40: 10 | E40: 1111535 | F40: =+E40*D40 -> 11115350 | I40: 0 | K40: =+I40+J40 -> 0 | L40: =+F40*I40 -> 0 | M40: =+F40*J40 -> 0 | N40: =+F40*K40 -> 0
A41: 3.18 | B41: Tanques de HºAº - H35 (100 kg/m3 de hierro) - Tanque de reserva | C41: m3 | D41: 6 | E41: 1039014 | F41: =+E41*D41 -> 6234084 | I41: 0 | K41: =+I41+J41 -> 0 | L41: =+F41*I41 -> 0 | M41: =+F41*J41 -> 0 | N41: =+F41*K41 -> 0
...

Sheet GDR 3760_Pto. 01_Cert. 05
F1: DÓLAR BNA | G1: DÓLAR MEP
F2: 1066.5 | G2: 1170
F4: 45667 | I4: Certificado | J4: 5 | N4: 45869
B5: OBRA: EDIFICIO GDR 3760
B6: PRESUPUESTO OBRA CIVIL 01 | I6: Avance | L6: Importe
B7: Descripción | C7: U | D7: Cant | E7: P unit | F7: Subtotal | I7: Anterior | J7: Actual | K7: Acumulado | L7: Anterior | M7: Actual | N7: Acumulado
A8: 1 | B8: TAREAS PRELIMINARES | G8: =SUM(F9:F17) -> 19888202 | H8: =+G8/$G$46 -> 0.039704323
A9: 1.01 | B9: Limpieza y preparación del terreno - No cotiza | C9: gl | D9: 1 | E9: 0 | F9: =+E9*D9 -> 0 | I9: 0 | K9: =+I9+J9 -> 0 | L9: =+F9*I9 -> 0 | M9: =+F9*J9 -> 0 | N9: =+F9*K9 -> 0
A10: 1.02 | B10: Topógrafo - Visita de obra replanteo | C10: gl | D10: 3 | E10: 384981 | F10: =+E10*D10 -> 1154943 | I10: 0.33 | K10: =+I10+J10 -> 0.33 | L10: =+F10*I10 -> 381131.19 | M10: =+F10*J10 -> 0 | N10: =+F10*K10 -> 381131.19
A11: 1.03 | B11: Cartel de Obra - No cotiza | C11: gl | D11: 1 | E11: 0 | F11: =+E11*D11 -> 0 | I11: 0 | K11: =+I11+J11 -> 0 | L11: =+F11*I11 -> 0 | M11: =+F11*J11 -> 0 | N11: =+F11*K11 -> 0
A12: 1.04 | B12: Cerco de obra perimetral - En chapa C25 + Concertina + Porton corredizo | C12: ml | D12: 10 | E12: 256997 | F12: =+E12*D12 -> 2569970 | I12: 0 | K12: =+I12+J12 -> 0 | L12: =+F12*I12 -> 0 | M12: =+F12*J12 -> 0 | N12: =+F12*K12 -> 0
A13: 1.05 | B13: Obrador, pañol y ducha. | C13: gl | D13: 1 | E13: 9812332 | F13: =+E13*D13 -> 9812332 | I13: 0.7 | K13: =+I13+J13 -> 0.7 | L13: =+F13*I13 -> 6868632.4 | M13: =+F13*J13 -> 0 | N13: =+F13*K13 -> 6868632.4
A14: 1.06 | B14: Alquiler de baños quimicos y duchas portatiles | C14: mes | D14: 4 | E14: 442847 | F14: =+E14*D14 -> 1771388 | I14: 0.9 | J14: 0.1 | K14: =+I14+J14 -> 1 | L14: =+F14*I14 -> 1594249.2 | M14: =+F14*J14 -> 177138.8 | N14: =+F14*K14 -> 1771388
A15: 1.07 | B15: Conexión pilar y luz de obra + Tablero de obra | C15: gl | D15: 1 | E15: 2287982 | F15: =+E15*D15 -> 2287982 | I15: 0.5 | J15: 0.3 | K15: =+I15+J15 -> 0.8 | L15: =+F15*I15 -> 1143991 | M15: =+F15*J15 -> 686394.6 | N15: =+F15*K15 -> 1830385.6
A16: 1.08 | B16: Conexión agua de obra, tanque + bomba | C16: gl | D16: 1 | E16: 1808218 | F16: =+E16*D16 -> 1808218 | I16: 0.2 | K16: =+I16+J16 -> 0.2 | L16: =+F16*I16 -> 361643.6 | M16: =+F16*J16 -> 0 | N16: =+F16*K16 -> 361643.6
A17: 1.09 | B17: Tramite luz de obra, certificado luz de obra (2) y medición PAT | C17: gl | D17: 1 | E17: 483369 | F17: =+E17*D17 -> 483369 | I17: 0.6 | J17: 0.1 | K17: =+I17+J17 -> 0.7 | L17: =+F17*I17 -> 290021.4 | M17: =+F17*J17 -> 48336.9 | N17: =+F17*K17 -> 338358.3
A18: 2 | B18: MOVIMIENTO DE TIERRA, COMPACTACION Y RELLENO | G18: =SUM(F19:F23) -> 29649894 | H18: =+G18/$G$46 -> 0.059192328
A19: 2.01 | B19: Excavación a maquina para submuración, subsuelo y fundaciones | C19: m3 | D19: 308 | E19: 52801 | F19: =+E19*D19 -> 16262708 | I19: 1 | K19: =+I19+J19 -> 1 | L19: =+F19*I19 -> 16262708 | M19: =+F19*J19 -> 0 | N19: =+F19*K19 -> 16262708
A20: 2.02 | B20: Perfilado manual de bases. Relleno y compactación de pozos | C20: gl | D20: 1 | E20: 11624716 | F20: =+E20*D20 -> 11624716 | I20: 1 | K20: =+I20+J20 -> 1 | L20: =+F20*I20 -> 11624716 | M20: =+F20*J20 -> 0 | N20: =+F20*K20 -> 11624716
A21: 2.03 | B21: Excavación manual para vigas de fundación | C21: m3 | D21: 15 | E21: 117498 | F21: =+E21*D21 -> 1762470 | I21: 0.7 | J21: 0.3 | K21: =+I21+J21 -> 1 | L21: =+F21*I21 -> 1233729 | M21: =+F21*J21 -> 528741 | N21: =+F21*K21 -> 1762470
A22: 2.04 | B22: Aporte y compactación de suelo seleccionado, e: 40 cm (2 capas de 20 cm) - Cotizado Hº Pobre en item 8,02 | C22: m2 | D22: 0 | E22: 28536 | F22: =+E22*D22 -> 0 | I22: 0 | K22: =+I22+J22 -> 0 | L22: =+F22*I22 -> 0 | M22: =+F22*J22 -> 0 | N22: =+F22*K22 -> 0
A23: 2.05 | B23: Demolición de bases existentes - No cotiza | C23: gl | D23: 0 | E23: 0 | F23: =+E23*D23 -> 0 | I23: 0 | K23: =+I23+J23 -> 0 | L23: =+F23*I23 -> 0 | M23: =+F23*J23 -> 0 | N23: =+F23*K23 -> 0
A24: 3 | B24: ESTRUCTURA RESISTENTE | G24: =SUM(F25:F45) -> 451369624 | H24: =+G24/$G$46 -> 0.90110335
A25: 3.01 | B25: Hormigón de limpieza - e: 10 cm | C25: m3 | D25: 13 | E25: 293139 | F25: =+E25*D25 -> 3810807 | I25: 1 | K25: =+I25+J25 -> 1 | L25: =+F25*I25 -> 3810807 | M25: =+F25*J25 -> 0 | N25: =+F25*K25 -> 3810807
A26: 3.02 | B26: Pilotes de tracción Ø 20 cm - (120 kg/m3 de hierro) | C26: u | D26: 18 | E26: 460697 | F26: =+E26*D26 -> 8292546 | I26: 1 | K26: =+I26+J26 -> 1 | L26: =+F26*I26 -> 8292546 | M26: =+F26*J26 -> 0 | N26: =+F26*K26 -> 8292546
A27: 3.03 | B27: Tabique submuración - H35 (95 kg/m3 de hierro) | C27: m3 | D27: 12 | E27: 1027679 | F27: =+E27*D27 -> 12332148 | I27: 1 | K27: =+I27+J27 -> 1 | L27: =+F27*I27 -> 12332148 | M27: =+F27*J27 -> 0 | N27: =+F27*K27 -> 12332148
A28: 3.04 | B28: Zapata corrida tabique - H35 (120 kg/m3 de hierro) | C28: m3 | D28: 7 | E28: 960201 | F28: =+E28*D28 -> 6721407 | I28: 1 | K28: =+I28+J28 -> 1 | L28: =+F28*I28 -> 6721407 | M28: =+F28*J28 -> 0 | N28: =+F28*K28 -> 6721407
A29: 3.05 | B29: Platea - H35 (95 kg/m3 de hierro) | C29: m3 | D29: 38 | E29: 714274 | F29: =+E29*D29 -> 27142412 | I29: 1 | K29: =+I29+J29 -> 1 | L29: =+F29*I29 -> 27142412 | M29: =+F29*J29 -> 0 | N29: =+F29*K29 -> 27142412
A30: 3.06 | B30: Bases aisladas - (60 kg/m3 de hierro) | C30: m3 | D30: 51 | E30: 634926 | F30: =+E30*D30 -> 32381226 | I30: 1 | K30: =+I30+J30 -> 1 | L30: =+F30*I30 -> 32381226 | M30: =+F30*J30 -> 0 | N30: =+F30*K30 -> 32381226
A31: 3.07 | B31: Troncos de columnas - H35 (240 kg/m3 de hierro) | C31: m3 | D31: 16 | E31: 1289285 | F31: =+E31*D31 -> 20628560 | I31: 1 | K31: =+I31+J31 -> 1 | L31: =+F31*I31 -> 20628560 | M31: =+F31*J31 -> 0 | N31: =+F31*K31 -> 20628560
A32: 3.08 | B32: Viga de encadenado - H35 (180 kg/m3 de hierro) | C32: m3 | D32: 7 | E32: 1096226 | F32: =+E32*D32 -> 7673582 | I32: 1 | K32: =+I32+J32 -> 1 | L32: =+F32*I32 -> 7673582 | M32: =+F32*J32 -> 0 | N32: =+F32*K32 -> 7673582
A33: 3.09 | B33: Losa maciza - H35 (100 kg/m3 de hierro) | C33: m3 | D33: 90 | E33: 804023 | F33: =+E33*D33 -> 72362070 | I33: 0 | J33: 0.1333 | K33: =+I33+J33 -> 0.1333 | L33: =+F33*I33 -> 0 | M33: =+F33*J33 -> 9645863.9 | N33: =+F33*K33 -> 9645863.9
A34: 3.1 | B34: Losa maciza de Hº visto - H35 (100 kg/m3 de hierro) | C34: m3 | D34: 32 | E34: 888733 | F34: =+E34*D34 -> 28439456 | I34: 0 | J34: 0.2328 | K34: =+I34+J34 -> 0.2328 | L34: =+F34*I34 -> 0 | M34: =+F34*J34 -> 6620705.4 | N34: =+F34*K34 -> 6620705.4
A35: 3.11 | B35: Vigas - H35 (180 kg/m3 de hierro) | C35: m3 | D35: 46 | E35: 1494687 | F35: =+E35*D35 -> 68755602 | I35: 0 | J35: 0.3744 | K35: =+I35+J35 -> 0.3744 | L35: =+F35*I35 -> 0 | M35: =+F35*J35 -> 25742097 | N35: =+F35*K35 -> 25742097
A36: 3.12 | B36: Vigas de H° visto - H35 (180 kg/m3 de hierro) | C36: m3 | D36: 31 | E36: 1673385 | F36: =+E36*D36 -> 51874935 | I36: 0 | J36: 0.5138 | K36: =+I36+J36 -> 0.5138 | L36: =+F36*I36 -> 0 | M36: =+F36*J36 -> 26653342 | N36: =+F36*K36 -> 26653342
A37: 3.13 | B37: Tabiques - H35 (100 kg/m3 de hierro) | C37: m3 | D37: 24 | E37: 1039014 | F37: =+E37*D37 -> 24936336 | I37: 0 | J37: 0.2629 | K37: =+I37+J37 -> 0.2629 | L37: =+F37*I37 -> 0 | M37: =+F37*J37 -> 6555762.7 | N37: =+F37*K37 -> 6555762.7
A38: 3.14 | B38: Columna - H35 (180 Kg/m3 de hierro) | C38: m3 | D38: 39 | E38: 1153260 | F38: =+E38*D38 -> 44977140 | I38: 0 | J38: 0.2672 | K38: =+I38+J38 -> 0.2672 | L38: =+F38*I38 -> 0 | M38: =+F38*J38 -> 12017892 | N38: =+F38*K38 -> 12017892
A39: 3.16 | B39: Columna vista- H35 (180 Kg/m3 de hierro) | C39: m3 | D39: 4 | E39: 1254164 | F39: =+E39*D39 -> 5016656 | I39: 0 | J39: 0.1925 | K39: =+I39+J39 -> 0.1925 | L39: =+F39*I39 -> 0 | M39: =+F39*J39 -> 965706.28 | N39: =+F39*K39 -> 965706.28
A40: 3.17 | B40: Escaleras de Hº visto - H35 (105 kg/m3 de hierro) | C40: m3 | D40: 10 | E40: 1111535 | F40: =+E40*D40 -> 11115350 | I40: 0 | K40: =+I40+J40 -> 0 | L40: =+F40*I40 -> 0 | M40: =+F40*J40 -> 0 | N40: =+F40*K40 -> 0
A41: 3.18 | B41: Tanques de HºAº - H35 (100 kg/m3 de hierro) - Tanque de reserva | C41: m3 | D41: 6 | E41: 1039014 | F41: =+E41*D41 -> 6234084 | I41: 0 | K41: =+I41+J41 -> 0 | L41: =+F41*I41 -> 0 | M41: =+F41*J41 -> 0 | N41: =+F41*K41 -> 0
...

Sheet GDR 3760_Pto. 01_Cert. 06
F1: DÓLAR BNA | G1: DÓLAR MEP
F2: 1066.5 | G2: 1170
F4: 45667 | I4: Certificado | J4: 6 | N4: 45900
B5: OBRA: EDIFICIO GDR 3760
B6: PRESUPUESTO OBRA CIVIL 01 | I6: Avance | L6: Importe
B7: Descripción | C7: U | D7: Cant | E7: P unit | F7: Subtotal | I7: Anterior | J7: Actual | K7: Acumulado | L7: Anterior | M7: Actual | N7: Acumulado
A8: 1 | B8: TAREAS PRELIMINARES | G8: =SUM(F9:F17) -> 19888202 | H8: =+G8/$G$46 -> 0.039704323
A9: 1.01 | B9: Limpieza y preparación del terreno - No cotiza | C9: gl | D9: 1 | E9: 0 | F9: =+E9*D9 -> 0 | I9: 0 | K9: =+I9+J9 -> 0 | L9: =+F9*I9 -> 0 | M9: =+F9*J9 -> 0 | N9: =+F9*K9 -> 0
A10: 1.02 | B10: Topógrafo - Visita de obra replanteo | C10: gl | D10: 3 | E10: 384981 | F10: =+E10*D10 -> 1154943 | I10: 0.33 | K10: =+I10+J10 -> 0.33 | L10: =+F10*I10 -> 381131.19 | M10: =+F10*J10 -> 0 | N10: =+F10*K10 -> 381131.19
A11: 1.03 | B11: Cartel de Obra - No cotiza | C11: gl | D11: 1 | E11: 0 | F11: =+E11*D11 -> 0 | I11: 0 | K11: =+I11+J11 -> 0 | L11: =+F11*I11 -> 0 | M11: =+F11*J11 -> 0 | N11: =+F11*K11 -> 0
A12: 1.04 | B12: Cerco de obra perimetral - En chapa C25 + Concertina + Porton corredizo | C12: ml | D12: 10 | E12: 256997 | F12: =+E12*D12 -> 2569970 | I12: 0 | K12: =+I12+J12 -> 0 | L12: =+F12*I12 -> 0 | M12: =+F12*J12 -> 0 | N12: =+F12*K12 -> 0
A13: 1.05 | B13: Obrador, pañol y ducha. | C13: gl | D13: 1 | E13: 9812332 | F13: =+E13*D13 -> 9812332 | I13: 0.7 | K13: =+I13+J13 -> 0.7 | L13: =+F13*I13 -> 6868632.4 | M13: =+F13*J13 -> 0 | N13: =+F13*K13 -> 6868632.4
A14: 1.06 | B14: Alquiler de baños quimicos y duchas portatiles | C14: mes | D14: 4 | E14: 442847 | F14: =+E14*D14 -> 1771388 | I14: 1 | K14: =+I14+J14 -> 1 | L14: =+F14*I14 -> 1771388 | M14: =+F14*J14 -> 0 | N14: =+F14*K14 -> 1771388
A15: 1.07 | B15: Conexión pilar y luz de obra + Tablero de obra | C15: gl | D15: 1 | E15: 2287982 | F15: =+E15*D15 -> 2287982 | I15: 0.8 | K15: =+I15+J15 -> 0.8 | L15: =+F15*I15 -> 1830385.6 | M15: =+F15*J15 -> 0 | N15: =+F15*K15 -> 1830385.6
A16: 1.08 | B16: Conexión agua de obra, tanque + bomba | C16: gl | D16: 1 | E16: 1808218 | F16: =+E16*D16 -> 1808218 | I16: 0.2 | K16: =+I16+J16 -> 0.2 | L16: =+F16*I16 -> 361643.6 | M16: =+F16*J16 -> 0 | N16: =+F16*K16 -> 361643.6
A17: 1.09 | B17: Tramite luz de obra, certificado luz de obra (2) y medición PAT | C17: gl | D17: 1 | E17: 483369 | F17: =+E17*D17 -> 483369 | I17: 0.7 | K17: =+I17+J17 -> 0.7 | L17: =+F17*I17 -> 338358.3 | M17: =+F17*J17 -> 0 | N17: =+F17*K17 -> 338358.3
A18: 2 | B18: MOVIMIENTO DE TIERRA, COMPACTACION Y RELLENO | G18: =SUM(F19:F23) -> 29649894 | H18: =+G18/$G$46 -> 0.059192328
A19: 2.01 | B19: Excavación a maquina para submuración, subsuelo y fundaciones | C19: m3 | D19: 308 | E19: 52801 | F19: =+E19*D19 -> 16262708 | I19: 1 | K19: =+I19+J19 -> 1 | L19: =+F19*I19 -> 16262708 | M19: =+F19*J19 -> 0 | N19: =+F19*K19 -> 16262708
A20: 2.02 | B20: Perfilado manual de bases. Relleno y compactación de pozos | C20: gl | D20: 1 | E20: 11624716 | F20: =+E20*D20 -> 11624716 | I20: 1 | K20: =+I20+J20 -> 1 | L20: =+F20*I20 -> 11624716 | M20: =+F20*J20 -> 0 | N20: =+F20*K20 -> 11624716
A21: 2.03 | B21: Excavación manual para vigas de fundación | C21: m3 | D21: 15 | E21: 117498 | F21: =+E21*D21 -> 1762470 | I21: 1 | K21: =+I21+J21 -> 1 | L21: =+F21*I21 -> 1762470 | M21: =+F21*J21 -> 0 | N21: =+F21*K21 -> 1762470
A22: 2.04 | B22: Aporte y compactación de suelo seleccionado, e: 40 cm (2 capas de 20 cm) - Cotizado Hº Pobre en item 8,02 | C22: m2 | D22: 0 | E22: 28536 | F22: =+E22*D22 -> 0 | I22: 0 | K22: =+I22+J22 -> 0 | L22: =+F22*I22 -> 0 | M22: =+F22*J22 -> 0 | N22: =+F22*K22 -> 0
A23: 2.05 | B23: Demolición de bases existentes - No cotiza | C23: gl | D23: 0 | E23: 0 | F23: =+E23*D23 -> 0 | I23: 0 | K23: =+I23+J23 -> 0 | L23: =+F23*I23 -> 0 | M23: =+F23*J23 -> 0 | N23: =+F23*K23 -> 0
A24: 3 | B24: ESTRUCTURA RESISTENTE | G24: =SUM(F25:F45) -> 451369624 | H24: =+G24/$G$46 -> 0.90110335
A25: 3.01 | B25: Hormigón de limpieza - e: 10 cm | C25: m3 | D25: 13 | E25: 293139 | F25: =+E25*D25 -> 3810807 | I25: 1 | K25: =+I25+J25 -> 1 | L25: =+F25*I25 -> 3810807 | M25: =+F25*J25 -> 0 | N25: =+F25*K25 -> 3810807
A26: 3.02 | B26: Pilotes de tracción Ø 20 cm - (120 kg/m3 de hierro) | C26: u | D26: 18 | E26: 460697 | F26: =+E26*D26 -> 8292546 | I26: 1 | K26: =+I26+J26 -> 1 | L26: =+F26*I26 -> 8292546 | M26: =+F26*J26 -> 0 | N26: =+F26*K26 -> 8292546
A27: 3.03 | B27: Tabique submuración - H35 (95 kg/m3 de hierro) | C27: m3 | D27: 12 | E27: 1027679 | F27: =+E27*D27 -> 12332148 | I27: 1 | K27: =+I27+J27 -> 1 | L27: =+F27*I27 -> 12332148 | M27: =+F27*J27 -> 0 | N27: =+F27*K27 -> 12332148
A28: 3.04 | B28: Zapata corrida tabique - H35 (120 kg/m3 de hierro) | C28: m3 | D28: 7 | E28: 960201 | F28: =+E28*D28 -> 6721407 | I28: 1 | K28: =+I28+J28 -> 1 | L28: =+F28*I28 -> 6721407 | M28: =+F28*J28 -> 0 | N28: =+F28*K28 -> 6721407
A29: 3.05 | B29: Platea - H35 (95 kg/m3 de hierro) | C29: m3 | D29: 38 | E29: 714274 | F29: =+E29*D29 -> 27142412 | I29: 1 | K29: =+I29+J29 -> 1 | L29: =+F29*I29 -> 27142412 | M29: =+F29*J29 -> 0 | N29: =+F29*K29 -> 27142412
A30: 3.06 | B30: Bases aisladas - (60 kg/m3 de hierro) | C30: m3 | D30: 51 | E30: 634926 | F30: =+E30*D30 -> 32381226 | I30: 1 | K30: =+I30+J30 -> 1 | L30: =+F30*I30 -> 32381226 | M30: =+F30*J30 -> 0 | N30: =+F30*K30 -> 32381226
A31: 3.07 | B31: Troncos de columnas - H35 (240 kg/m3 de hierro) | C31: m3 | D31: 16 | E31: 1289285 | F31: =+E31*D31 -> 20628560 | I31: 1 | K31: =+I31+J31 -> 1 | L31: =+F31*I31 -> 20628560 | M31: =+F31*J31 -> 0 | N31: =+F31*K31 -> 20628560
A32: 3.08 | B32: Viga de encadenado - H35 (180 kg/m3 de hierro) | C32: m3 | D32: 7 | E32: 1096226 | F32: =+E32*D32 -> 7673582 | I32: 1 | K32: =+I32+J32 -> 1 | L32: =+F32*I32 -> 7673582 | M32: =+F32*J32 -> 0 | N32: =+F32*K32 -> 7673582
A33: 3.09 | B33: Losa maciza - H35 (100 kg/m3 de hierro) | C33: m3 | D33: 90 | E33: 804023 | F33: =+E33*D33 -> 72362070 | I33: 0.1333 | J33: 0 | K33: =+I33+J33 -> 0.1333 | L33: =+F33*I33 -> 9645863.9 | M33: =+F33*J33 -> 0 | N33: =+F33*K33 -> 9645863.9
A34: 3.1 | B34: Losa maciza de Hº visto - H35 (100 kg/m3 de hierro) | C34: m3 | D34: 32 | E34: 888733 | F34: =+E34*D34 -> 28439456 | I34: 0.2328 | J34: 0.7672 | K34: =+I34+J34 -> 1 | L34: =+F34*I34 -> 6620705.4 | M34: =+F34*J34 -> 21818751 | N34: =+F34*K34 -> 28439456
A35: 3.11 | B35: Vigas - H35 (180 kg/m3 de hierro) | C35: m3 | D35: 46 | E35: 1494687 | F35: =+E35*D35 -> 68755602 | I35: 0.3744 | J35: 0.069 | K35: =+I35+J35 -> 0.4434 | L35: =+F35*I35 -> 25742097 | M35: =+F35*J35 -> 4744136.5 | N35: =+F35*K35 -> 30486234
A36: 3.12 | B36: Vigas de H° visto - H35 (180 kg/m3 de hierro) | C36: m3 | D36: 31 | E36: 1673385 | F36: =+E36*D36 -> 51874935 | I36: 0.5138 | J36: 0.2358 | K36: =+I36+J36 -> 0.7496 | L36: =+F36*I36 -> 26653342 | M36: =+F36*J36 -> 12232110 | N36: =+F36*K36 -> 38885451
A37: 3.13 | B37: Tabiques - H35 (100 kg/m3 de hierro) | C37: m3 | D37: 24 | E37: 1039014 | F37: =+E37*D37 -> 24936336 | I37: 0.2629 | J37: 0.1295 | K37: =+I37+J37 -> 0.3924 | L37: =+F37*I37 -> 6555762.7 | M37: =+F37*J37 -> 3229255.5 | N37: =+F37*K37 -> 9785018.2
A38: 3.14 | B38: Columna - H35 (180 Kg/m3 de hierro) | C38: m3 | D38: 39 | E38: 1153260 | F38: =+E38*D38 -> 44977140 | I38: 0.2672 | J38: 0.1859 | K38: =+I38+J38 -> 0.4531 | L38: =+F38*I38 -> 12017892 | M38: =+F38*J38 -> 8361250.3 | N38: =+F38*K38 -> 20379142
A39: 3.16 | B39: Columna vista- H35 (180 Kg/m3 de hierro) | C39: m3 | D39: 4 | E39: 1254164 | F39: =+E39*D39 -> 5016656 | I39: 0.1925 | J39: 0.145 | K39: =+I39+J39 -> 0.3375 | L39: =+F39*I39 -> 965706.28 | M39: =+F39*J39 -> 727415.12 | N39: =+F39*K39 -> 1693121.4
A40: 3.17 | B40: Escaleras de Hº visto - H35 (105 kg/m3 de hierro) | C40: m3 | D40: 10 | E40: 1111535 | F40: =+E40*D40 -> 11115350 | I40: 0 | J40: 0.184 | K40: =+I40+J40 -> 0.184 | L40: =+F40*I40 -> 0 | M40: =+F40*J40 -> 2045224.4 | N40: =+F40*K40 -> 2045224.4
A41: 3.18 | B41: Tanques de HºAº - H35 (100 kg/m3 de hierro) - Tanque de reserva | C41: m3 | D41: 6 | E41: 1039014 | F41: =+E41*D41 -> 6234084 | I41: 0 | J41: 0 | K41: =+I41+J41 -> 0 | L41: =+F41*I41 -> 0 | M41: =+F41*J41 -> 0 | N41: =+F41*K41 -> 0
...

Sheet GDR 3760_Pto. 01_Cert. 07
F1: DÓLAR BNA | G1: DÓLAR MEP
F2: 1066.5 | G2: 1170
F4: 45667 | I4: Certificado | J4: 7 | N4: 45930
B5: OBRA: EDIFICIO GDR 3760
B6: PRESUPUESTO OBRA CIVIL 01 | I6: Avance | L6: Importe
B7: Descripción | C7: U | D7: Cant | E7: P unit | F7: Subtotal | I7: Anterior | J7: Actual | K7: Acumulado | L7: Anterior | M7: Actual | N7: Acumulado
A8: 1 | B8: TAREAS PRELIMINARES | G8: =SUM(F9:F17) -> 19888202 | H8: =+G8/$G$46 -> 0.039704323
A9: 1.01 | B9: Limpieza y preparación del terreno - No cotiza | C9: gl | D9: 1 | E9: 0 | F9: =+E9*D9 -> 0 | I9: 0 | K9: =+I9+J9 -> 0 | L9: =+F9*I9 -> 0 | M9: =+F9*J9 -> 0 | N9: =+F9*K9 -> 0
A10: 1.02 | B10: Topógrafo - Visita de obra replanteo | C10: gl | D10: 3 | E10: 384981 | F10: =+E10*D10 -> 1154943 | I10: 0.33 | K10: =+I10+J10 -> 0.33 | L10: =+F10*I10 -> 381131.19 | M10: =+F10*J10 -> 0 | N10: =+F10*K10 -> 381131.19
A11: 1.03 | B11: Cartel de Obra - No cotiza | C11: gl | D11: 1 | E11: 0 | F11: =+E11*D11 -> 0 | I11: 0 | K11: =+I11+J11 -> 0 | L11: =+F11*I11 -> 0 | M11: =+F11*J11 -> 0 | N11: =+F11*K11 -> 0
A12: 1.04 | B12: Cerco de obra perimetral - En chapa C25 + Concertina + Porton corredizo | C12: ml | D12: 10 | E12: 256997 | F12: =+E12*D12 -> 2569970 | I12: 0 | K12: =+I12+J12 -> 0 | L12: =+F12*I12 -> 0 | M12: =+F12*J12 -> 0 | N12: =+F12*K12 -> 0
A13: 1.05 | B13: Obrador, pañol y ducha. | C13: gl | D13: 1 | E13: 9812332 | F13: =+E13*D13 -> 9812332 | I13: 0.7 | K13: =+I13+J13 -> 0.7 | L13: =+F13*I13 -> 6868632.4 | M13: =+F13*J13 -> 0 | N13: =+F13*K13 -> 6868632.4
A14: 1.06 | B14: Alquiler de baños quimicos y duchas portatiles | C14: mes | D14: 4 | E14: 442847 | F14: =+E14*D14 -> 1771388 | I14: 1 | K14: =+I14+J14 -> 1 | L14: =+F14*I14 -> 1771388 | M14: =+F14*J14 -> 0 | N14: =+F14*K14 -> 1771388
A15: 1.07 | B15: Conexión pilar y luz de obra + Tablero de obra | C15: gl | D15: 1 | E15: 2287982 | F15: =+E15*D15 -> 2287982 | I15: 0.8 | K15: =+I15+J15 -> 0.8 | L15: =+F15*I15 -> 1830385.6 | M15: =+F15*J15 -> 0 | N15: =+F15*K15 -> 1830385.6
A16: 1.08 | B16: Conexión agua de obra, tanque + bomba | C16: gl | D16: 1 | E16: 1808218 | F16: =+E16*D16 -> 1808218 | I16: 0.2 | K16: =+I16+J16 -> 0.2 | L16: =+F16*I16 -> 361643.6 | M16: =+F16*J16 -> 0 | N16: =+F16*K16 -> 361643.6
A17: 1.09 | B17: Tramite luz de obra, certificado luz de obra (2) y medición PAT | C17: gl | D17: 1 | E17: 483369 | F17: =+E17*D17 -> 483369 | I17: 0.7 | K17: =+I17+J17 -> 0.7 | L17: =+F17*I17 -> 338358.3 | M17: =+F17*J17 -> 0 | N17: =+F17*K17 -> 338358.3
A18: 2 | B18: MOVIMIENTO DE TIERRA, COMPACTACION Y RELLENO | G18: =SUM(F19:F23) -> 29649894 | H18: =+G18/$G$46 -> 0.059192328
A19: 2.01 | B19: Excavación a maquina para submuración, subsuelo y fundaciones | C19: m3 | D19: 308 | E19: 52801 | F19: =+E19*D19 -> 16262708 | I19: 1 | K19: =+I19+J19 -> 1 | L19: =+F19*I19 -> 16262708 | M19: =+F19*J19 -> 0 | N19: =+F19*K19 -> 16262708
A20: 2.02 | B20: Perfilado manual de bases. Relleno y compactación de pozos | C20: gl | D20: 1 | E20: 11624716 | F20: =+E20*D20 -> 11624716 | I20: 1 | K20: =+I20+J20 -> 1 | L20: =+F20*I20 -> 11624716 | M20: =+F20*J20 -> 0 | N20: =+F20*K20 -> 11624716
A21: 2.03 | B21: Excavación manual para vigas de fundación | C21: m3 | D21: 15 | E21: 117498 | F21: =+E21*D21 -> 1762470 | I21: 1 | K21: =+I21+J21 -> 1 | L21: =+F21*I21 -> 1762470 | M21: =+F21*J21 -> 0 | N21: =+F21*K21 -> 1762470
A22: 2.04 | B22: Aporte y compactación de suelo seleccionado, e: 40 cm (2 capas de 20 cm) - Cotizado Hº Pobre en item 8,02 | C22: m2 | D22: 0 | E22: 28536 | F22: =+E22*D22 -> 0 | I22: 0 | K22: =+I22+J22 -> 0 | L22: =+F22*I22 -> 0 | M22: =+F22*J22 -> 0 | N22: =+F22*K22 -> 0
A23: 2.05 | B23: Demolición de bases existentes - No cotiza | C23: gl | D23: 0 | E23: 0 | F23: =+E23*D23 -> 0 | I23: 0 | K23: =+I23+J23 -> 0 | L23: =+F23*I23 -> 0 | M23: =+F23*J23 -> 0 | N23: =+F23*K23 -> 0
A24: 3 | B24: ESTRUCTURA RESISTENTE | G24: =SUM(F25:F45) -> 451369624 | H24: =+G24/$G$46 -> 0.90110335
A25: 3.01 | B25: Hormigón de limpieza - e: 10 cm | C25: m3 | D25: 13 | E25: 293139 | F25: =+E25*D25 -> 3810807 | I25: 1 | K25: =+I25+J25 -> 1 | L25: =+F25*I25 -> 3810807 | M25: =+F25*J25 -> 0 | N25: =+F25*K25 -> 3810807
A26: 3.02 | B26: Pilotes de tracción Ø 20 cm - (120 kg/m3 de hierro) | C26: u | D26: 18 | E26: 460697 | F26: =+E26*D26 -> 8292546 | I26: 1 | K26: =+I26+J26 -> 1 | L26: =+F26*I26 -> 8292546 | M26: =+F26*J26 -> 0 | N26: =+F26*K26 -> 8292546
A27: 3.03 | B27: Tabique submuración - H35 (95 kg/m3 de hierro) | C27: m3 | D27: 12 | E27: 1027679 | F27: =+E27*D27 -> 12332148 | I27: 1 | K27: =+I27+J27 -> 1 | L27: =+F27*I27 -> 12332148 | M27: =+F27*J27 -> 0 | N27: =+F27*K27 -> 12332148
A28: 3.04 | B28: Zapata corrida tabique - H35 (120 kg/m3 de hierro) | C28: m3 | D28: 7 | E28: 960201 | F28: =+E28*D28 -> 6721407 | I28: 1 | K28: =+I28+J28 -> 1 | L28: =+F28*I28 -> 6721407 | M28: =+F28*J28 -> 0 | N28: =+F28*K28 -> 6721407
A29: 3.05 | B29: Platea - H35 (95 kg/m3 de hierro) | C29: m3 | D29: 38 | E29: 714274 | F29: =+E29*D29 -> 27142412 | I29: 1 | K29: =+I29+J29 -> 1 | L29: =+F29*I29 -> 27142412 | M29: =+F29*J29 -> 0 | N29: =+F29*K29 -> 27142412
A30: 3.06 | B30: Bases aisladas - (60 kg/m3 de hierro) | C30: m3 | D30: 51 | E30: 634926 | F30: =+E30*D30 -> 32381226 | I30: 1 | K30: =+I30+J30 -> 1 | L30: =+F30*I30 -> 32381226 | M30: =+F30*J30 -> 0 | N30: =+F30*K30 -> 32381226
A31: 3.07 | B31: Troncos de columnas - H35 (240 kg/m3 de hierro) | C31: m3 | D31: 16 | E31: 1289285 | F31: =+E31*D31 -> 20628560 | I31: 1 | K31: =+I31+J31 -> 1 | L31: =+F31*I31 -> 20628560 | M31: =+F31*J31 -> 0 | N31: =+F31*K31 -> 20628560
A32: 3.08 | B32: Viga de encadenado - H35 (180 kg/m3 de hierro) | C32: m3 | D32: 7 | E32: 1096226 | F32: =+E32*D32 -> 7673582 | I32: 1 | K32: =+I32+J32 -> 1 | L32: =+F32*I32 -> 7673582 | M32: =+F32*J32 -> 0 | N32: =+F32*K32 -> 7673582
A33: 3.09 | B33: Losa maciza - H35 (100 kg/m3 de hierro) | C33: m3 | D33: 90 | E33: 804023 | F33: =+E33*D33 -> 72362070 | I33: 0.1333 | J33: 0 | K33: =+I33+J33 -> 0.1333 | L33: =+F33*I33 -> 9645863.9 | M33: =+F33*J33 -> 0 | N33: =+F33*K33 -> 9645863.9
A34: 3.1 | B34: Losa maciza de Hº visto - H35 (100 kg/m3 de hierro) | C34: m3 | D34: 32 | E34: 888733 | F34: =+E34*D34 -> 28439456 | I34: 1.0028 | J34: 0 | K34: =+I34+J34 -> 1.0028 | L34: =+F34*I34 -> 28519086 | M34: =+F34*J34 -> 0 | N34: =+F34*K34 -> 28519086
A35: 3.11 | B35: Vigas - H35 (180 kg/m3 de hierro) | C35: m3 | D35: 46 | E35: 1494687 | F35: =+E35*D35 -> 68755602 | I35: 0.4434 | J35: 0.069 | K35: =+I35+J35 -> 0.5124 | L35: =+F35*I35 -> 30486234 | M35: =+F35*J35 -> 4744136.5 | N35: =+F35*K35 -> 35230370
A36: 3.12 | B36: Vigas de H° visto - H35 (180 kg/m3 de hierro) | C36: m3 | D36: 31 | E36: 1673385 | F36: =+E36*D36 -> 51874935 | I36: 0.7496 | J36: 0.235 | K36: =+I36+J36 -> 0.9846 | L36: =+F36*I36 -> 38885451 | M36: =+F36*J36 -> 12190610 | N36: =+F36*K36 -> 51076061
A37: 3.13 | B37: Tabiques - H35 (100 kg/m3 de hierro) | C37: m3 | D37: 24 | E37: 1039014 | F37: =+E37*D37 -> 24936336 | I37: 0.3924 | J37: 0.1295 | K37: =+I37+J37 -> 0.5219 | L37: =+F37*I37 -> 9785018.2 | M37: =+F37*J37 -> 3229255.5 | N37: =+F37*K37 -> 13014274
A38: 3.14 | B38: Columna - H35 (180 Kg/m3 de hierro) | C38: m3 | D38: 39 | E38: 1153260 | F38: =+E38*D38 -> 44977140 | I38: 0.4531 | J38: 0.1858 | K38: =+I38+J38 -> 0.6389 | L38: =+F38*I38 -> 20379142 | M38: =+F38*J38 -> 8356752.6 | N38: =+F38*K38 -> 28735895
A39: 3.16 | B39: Columna vista- H35 (180 Kg/m3 de hierro) | C39: m3 | D39: 4 | E39: 1254164 | F39: =+E39*D39 -> 5016656 | I39: 0.3375 | J39: 0.145 | K39: =+I39+J39 -> 0.4825 | L39: =+F39*I39 -> 1693121.4 | M39: =+F39*J39 -> 727415.12 | N39: =+F39*K39 -> 2420536.5
A40: 3.17 | B40: Escaleras de Hº visto - H35 (105 kg/m3 de hierro) | C40: m3 | D40: 10 | E40: 1111535 | F40: =+E40*D40 -> 11115350 | I40: 0.184 | J40: 0.2 | K40: =+I40+J40 -> 0.384 | L40: =+F40*I40 -> 2045224.4 | M40: =+F40*J40 -> 2223070 | N40: =+F40*K40 -> 4268294.4
A41: 3.18 | B41: Tanques de HºAº - H35 (100 kg/m3 de hierro) - Tanque de reserva | C41: m3 | D41: 6 | E41: 1039014 | F41: =+E41*D41 -> 6234084 | I41: 0 | J41: 0 | K41: =+I41+J41 -> 0 | L41: =+F41*I41 -> 0 | M41: =+F41*J41 -> 0 | N41: =+F41*K41 -> 0
...

Sheet GDR 3760_Pto. 01_Cert. 08
F1: DÓLAR BNA | G1: DÓLAR MEP
F2: 1066.5 | G2: 1170
F4: 45667 | I4: Certificado | J4: 8 | N4: 45958
B5: OBRA: EDIFICIO GDR 3760
B6: PRESUPUESTO OBRA CIVIL 01 | I6: Avance | L6: Importe
B7: Descripción | C7: U | D7: Cant | E7: P unit | F7: Subtotal | I7: Anterior | J7: Actual | K7: Acumulado | L7: Anterior | M7: Actual | N7: Acumulado
A8: 1 | B8: TAREAS PRELIMINARES | G8: =SUM(F9:F17) -> 19888202 | H8: =+G8/$G$46 -> 0.039704323
A9: 1.01 | B9: Limpieza y preparación del terreno - No cotiza | C9: gl | D9: 1 | E9: 0 | F9: =+E9*D9 -> 0 | I9: 0 | K9: =+I9+J9 -> 0 | L9: =+F9*I9 -> 0 | M9: =+F9*J9 -> 0 | N9: =+F9*K9 -> 0
A10: 1.02 | B10: Topógrafo - Visita de obra replanteo | C10: gl | D10: 3 | E10: 384981 | F10: =+E10*D10 -> 1154943 | I10: 0.33 | K10: =+I10+J10 -> 0.33 | L10: =+F10*I10 -> 381131.19 | M10: =+F10*J10 -> 0 | N10: =+F10*K10 -> 381131.19
A11: 1.03 | B11: Cartel de Obra - No cotiza | C11: gl | D11: 1 | E11: 0 | F11: =+E11*D11 -> 0 | I11: 0 | K11: =+I11+J11 -> 0 | L11: =+F11*I11 -> 0 | M11: =+F11*J11 -> 0 | N11: =+F11*K11 -> 0
A12: 1.04 | B12: Cerco de obra perimetral - En chapa C25 + Concertina + Porton corredizo | C12: ml | D12: 10 | E12: 256997 | F12: =+E12*D12 -> 2569970 | I12: 0 | J12: 0.75 | K12: =+I12+J12 -> 0.75 | L12: =+F12*I12 -> 0 | M12: =+F12*J12 -> 1927477.5 | N12: =+F12*K12 -> 1927477.5
