Workbook
Name \0: #REF!
Name \0: #REF!
Name \0: #REF!
Name \c: #REF!
Name \c: #REF!
Name \E: #REF!
Name \E: #REF!
Name \i: #REF!
Name \j: #REF!
Name \m: #REF!
Name \P: #REF!
Name \P: #REF!
Name \P: #REF!
Name \P: #REF!
Name \P: #REF!
Name \P: #REF!
Name \P: #REF!
Name \P: #REF!
Name \P: #REF!
Name \P: #REF!
Name \P: #REF!
Name \P: #REF!
Name \P: #REF!
Name \P: #REF!
Name \P: #REF!
Name \P: #REF!
Name \P: #REF!
Name \P: #REF!
Name \P: #REF!
Name \P: #REF!
Name \r: #N/A
Name \x: #REF!
Name \z: #REF!
Name \z: #REF!
Name \z: #REF!
Name __________ben1: #REF!
Name __________ben1: #REF!
Name __________ben1: #REF!
Name __________ben1: #REF!
Name __________ben1: #REF!
Name __________ben1: #REF!
Name __________ben1: #REF!
Name __________ben1: #REF!
Name __________ben1: #REF!
Name __________ben1: #REF!
Name __________ben1: #REF!
Name __________ben1: #REF!
Name __________ben1: #REF!
Name __________ben1: #REF!
Name __________ben1: #REF!
Name __________ben1: #REF!
Name __________ben1: #REF!
Name __________ben1: #REF!
Name __________ben1: #REF!
Name __________ben1: #REF!
Name __________ben1: #REF!
Name __________ben10: #REF!
Name __________ben10: #REF!
Name __________ben10: #REF!
Name __________ben10: #REF!

Sheet HOJA DE OBRA
D1: OBRA: Edificio El Salvador 4140
A6: Cliente / Comitente:
A7: Facturacion
A8: Dirección / Jefe de la Obra:
A11: Fecha de Inicio : | D11: Duracion de Obra: | E11: 18 meses
A13: Presupuesto Aprobado : | D13: Fecha de Aprobacion:
A14: Orden de Compra CL : | D14: Nota de Pedido ARQ:
A16: Anticipo : | D16: Condiciones de Pago:
A17: Certifiaciones : | D17: Forma de Pago:
A18: Actualización CAC:
A20: Seguros :
A21: Caucion Anticipo
A22: Caucion Ejecucion
A23: Resp. Civil
A25: Programa S&H :
A26: Aviso de Obra :
A28: Descripcion de Tareas
A33: Contactos del cliente:
A34: Nombre | B34: TEL | C34: Rubro | D34: Mail de contacto
A39: Subcontratistas | B39: Rubro | C39: Inicio | D39: Presupuesto Aprobado | E39: Cerrado / Estimado
A44: Cuadrilla de Obra | B44: Categoría | D44: Observación
A52: Observaciones Particulares

Sheet Resumen General
AE1: Actualizado | AF1: 46133
B3: OBRA: GDR 3760
B4: RESUMEN DE OBRA
D5: 45627 | E5: 45658 | F5: 45689 | G5: 45717 | H5: 45748 | I5: 45778 | J5: 45809 | K5: 45839 | L5: 45870 | M5: 45901 | N5: 45931 | O5: 45962 | P5: 45992 | Q5: 46023 | R5: 46054 | S5: 46082 | T5: 46113 | V5: Acum. Descontado | X5: Presupuesto #1 | Y5: Presupuesto #2 | Z5: Previsto | AA5: % Cert. Acum. | AB5: Saldo Disponible | AC5: Disponible % | AD5: Rubro Completado
B6: Ingresos de Obra
B7: Ingresos por Certificados | D7: =SUM(VLOOKUP($B7,'Resumen Pto #1'!$B$5:$U$10,MATCH('Resumen General'!D$5,'Resumen Pto #1'!$B$5:$U$5,0),0),VLOOKUP($B7,'Resumen Pto #2'!$B$5:$U$10,MATCH('Resumen General'!D$5,'Resumen Pto #2'!$B$5:$U$5,0),0)) -> 0 | E7: =SUM(VLOOKUP($B7,'Resumen Pto #1'!$B$5:$U$10,MATCH('Resumen General'!E$5,'Resumen Pto #1'!$B$5:$U$5,0),0),VLOOKUP($B7,'Resumen Pto #2'!$B$5:$U$10,MATCH('Resumen General'!E$5,'Resumen Pto #2'!$B$5:$U$5,0),0)) -> 0 | F7: =SUM(VLOOKUP($B7,'Resumen Pto #1'!$B$5:$U$10,MATCH('Resumen General'!F$5,'Resumen Pto #1'!$B$5:$U$5,0),0),VLOOKUP($B7,'Resumen Pto #2'!$B$5:$U$10,MATCH('Resumen General'!F$5,'Resumen Pto #2'!$B$5:$U$5,0),0)) -> 2.8484761e+08 | G7: =SUM(VLOOKUP($B7,'Resumen Pto #1'!$B$5:$U$10,MATCH('Resumen General'!G$5,'Resumen Pto #1'!$B$5:$U$5,0),0),VLOOKUP($B7,'Resumen Pto #2'!$B$5:$U$10,MATCH('Resumen General'!G$5,'Resumen Pto #2'!$B$5:$U$5,0),0)) -> 27616485 | H7: =SUM(VLOOKUP($B7,'Resumen Pto #1'!$B$5:$U$10,MATCH('Resumen General'!H$5,'Resumen Pto #1'!$B$5:$U$5,0),0),VLOOKUP($B7,'Resumen Pto #2'!$B$5:$U$10,MATCH('Resumen General'!H$5,'Resumen Pto #2'!$B$5:$U$5,0),0)) -> 24319183 | I7: =SUM(VLOOKUP($B7,'Resumen Pto #1'!$B$5:$U$10,MATCH('Resumen General'!I$5,'Resumen Pto #1'!$B$5:$U$5,0),0),VLOOKUP($B7,'Resumen Pto #2'!$B$5:$U$10,MATCH('Resumen General'!I$5,'Resumen Pto #2'!$B$5:$U$5,0),0)) -> 47861818 | J7: =SUM(VLOOKUP($B7,'Resumen Pto #1'!$B$5:$U$10,MATCH('Resumen General'!J$5,'Resumen Pto #1'!$B$5:$U$5,0),0),VLOOKUP($B7,'Resumen Pto #2'!$B$5:$U$10,MATCH('Resumen General'!J$5,'Resumen Pto #2'!$B$5:$U$5,0),0)) -> 29875785 | K7: =SUM(VLOOKUP($B7,'Resumen Pto #1'!$B$5:$U$10,MATCH('Resumen General'!K$5,'Resumen Pto #1'!$B$5:$U$5,0),0),VLOOKUP($B7,'Resumen Pto #2'!$B$5:$U$10,MATCH('Resumen General'!K$5,'Resumen Pto #2'!$B$5:$U$5,0),0)) -> 67092674 | ... T7: =SUM(VLOOKUP($B7,'Resumen Pto #1'!$B$5:$U$10,MATCH('Resumen General'!T$5,'Resumen Pto #1'!$B$5:$U$5,0),0),VLOOKUP($B7,'Resumen Pto #2'!$B$5:$U$10,MATCH('Resumen General'!T$5,'Resumen Pto #2'!$B$5:$U$5,0),0)) -> 0 | V7: =SUM(D7:U7) -> 7.458795e+08 | X7: ='Resumen Pto #1'!X7 -> 500907720 | Y7: ='Resumen Pto #2'!X7 -> 8.4484525e+08 | Z7: =SUM(X7:Y7) -> 1345752968 | AA7: =SUM('Cert. Pto. 01'!V46,'Cert. Pto. 02'!V195)/SUM('Cert. Pto. 02'!L195+'Cert. Pto. 01'!L46) -> 0.57722683 | AB7: =IF(AA7=100%,0,IF(OR(V7<>0,Z7),Z7-V7)) -> 5.9987347e+08 | AC7: =IF(OR(AB7<0,Z7),AB7/Z7,0%) -> 0.44575303 | AD7: =IF(AA7=100%,IF(OR(U7<>0,Z7),Z7-U7),0) -> 0
B8: Total Ingresos de Obra | D8: =SUM(D7) -> 0 | E8: =SUM(E7) -> 0 | F8: =SUM(F7) -> 2.8484761e+08 | G8: =SUM(G7) -> 27616485 | H8: =SUM(H7) -> 24319183 | I8: =SUM(I7) -> 47861818 | J8: =SUM(J7) -> 29875785 | K8: =SUM(K7) -> 67092674 | ... T8: =SUM(T7) -> 0 | V8: =SUM(V7) -> 7.458795e+08 | X8: =SUM(X7) -> 500907720 | Y8: =SUM(Y7) -> 8.4484525e+08 | Z8: =SUM(Z7) -> 1345752968 | AB8: =SUM(AB7) -> 5.9987347e+08 | AC8: =IF(OR(AB8<0,Z8),AB8/Z8,0%) -> 0.44575303 | AD8: =SUM(AD7) -> 0
B9: Actualización por CAC | D9: =SUM(VLOOKUP($B9,'Resumen Pto #1'!$B$5:$U$10,MATCH('Resumen General'!D$5,'Resumen Pto #1'!$B$5:$U$5,0),0),VLOOKUP($B9,'Resumen Pto #2'!$B$5:$U$10,MATCH('Resumen General'!D$5,'Resumen Pto #2'!$B$5:$U$5,0),0)) -> 0 | E9: =SUM(VLOOKUP($B9,'Resumen Pto #1'!$B$5:$U$10,MATCH('Resumen General'!E$5,'Resumen Pto #1'!$B$5:$U$5,0),0),VLOOKUP($B9,'Resumen Pto #2'!$B$5:$U$10,MATCH('Resumen General'!E$5,'Resumen Pto #2'!$B$5:$U$5,0),0)) -> 0 | F9: =SUM(VLOOKUP($B9,'Resumen Pto #1'!$B$5:$U$10,MATCH('Resumen General'!F$5,'Resumen Pto #1'!$B$5:$U$5,0),0),VLOOKUP($B9,'Resumen Pto #2'!$B$5:$U$10,MATCH('Resumen General'!F$5,'Resumen Pto #2'!$B$5:$U$5,0),0)) -> 9200360.5 | G9: =SUM(VLOOKUP($B9,'Resumen Pto #1'!$B$5:$U$10,MATCH('Resumen General'!G$5,'Resumen Pto #1'!$B$5:$U$5,0),0),VLOOKUP($B9,'Resumen Pto #2'!$B$5:$U$10,MATCH('Resumen General'!G$5,'Resumen Pto #2'!$B$5:$U$5,0),0)) -> 891991.37 | H9: =SUM(VLOOKUP($B9,'Resumen Pto #1'!$B$5:$U$10,MATCH('Resumen General'!H$5,'Resumen Pto #1'!$B$5:$U$5,0),0),VLOOKUP($B9,'Resumen Pto #2'!$B$5:$U$10,MATCH('Resumen General'!H$5,'Resumen Pto #2'!$B$5:$U$5,0),0)) -> 1011953.2 | I9: =SUM(VLOOKUP($B9,'Resumen Pto #1'!$B$5:$U$10,MATCH('Resumen General'!I$5,'Resumen Pto #1'!$B$5:$U$5,0),0),VLOOKUP($B9,'Resumen Pto #2'!$B$5:$U$10,MATCH('Resumen General'!I$5,'Resumen Pto #2'!$B$5:$U$5,0),0)) -> 2796022.3 | J9: =SUM(VLOOKUP($B9,'Resumen Pto #1'!$B$5:$U$10,MATCH('Resumen General'!J$5,'Resumen Pto #1'!$B$5:$U$5,0),0),VLOOKUP($B9,'Resumen Pto #2'!$B$5:$U$10,MATCH('Resumen General'!J$5,'Resumen Pto #2'!$B$5:$U$5,0),0)) -> 2266306 | K9: =SUM(VLOOKUP($B9,'Resumen Pto #1'!$B$5:$U$10,MATCH('Resumen General'!K$5,'Resumen Pto #1'!$B$5:$U$5,0),0),VLOOKUP($B9,'Resumen Pto #2'!$B$5:$U$10,MATCH('Resumen General'!K$5,'Resumen Pto #2'!$B$5:$U$5,0),0)) -> 5622949.4 | ... T9: =SUM(VLOOKUP($B9,'Resumen Pto #1'!$B$5:$U$10,MATCH('Resumen General'!T$5,'Resumen Pto #1'!$B$5:$U$5,0),0),VLOOKUP($B9,'Resumen Pto #2'!$B$5:$U$10,MATCH('Resumen General'!T$5,'Resumen Pto #2'!$B$5:$U$5,0),0)) -> 0 | V9: =SUM(D9:U9) -> 79119888 | X9: ='Resumen Pto #1'!X9 -> 0 | Y9: ='Resumen Pto #2'!X9 -> 0 | Z9: =SUM(X9:Y9) -> 0 | AB9: =IF(AA9=100%,0,IF(Z9=0,Z9,Z9-V9)) -> 0 | AC9: =IF(OR(AB9<0,Z9),AB9/Z9,0%) -> 0 | AD9: =IF(AA9=100%,IF(OR(U9<>0,Z9),Z9-U9),0) -> 0
B10: Total Ingresos de Obra | D10: =SUM(D9) -> 0 | E10: =SUM(E9) -> 0 | F10: =SUM(F9) -> 9200360.5 | G10: =SUM(G9) -> 891991.37 | H10: =SUM(H9) -> 1011953.2 | I10: =SUM(I9) -> 2796022.3 | J10: =SUM(J9) -> 2266306 | K10: =SUM(K9) -> 5622949.4 | ... T10: =SUM(T9) -> 0 | V10: =SUM(V9) -> 79119888 | X10: =SUM(X9) -> 0 | Y10: =SUM(Y9) -> 0 | Z10: =SUM(Z9) -> 0 | AB10: =SUM(AB9) -> 0 | AC10: =IF(OR(AB10<0,Z10),AB10/Z10,0%) -> 0 | AD10: =SUM(AD9) -> 0
B12: Costos de Obra
B13: Seguridad e Higiene | D13: ='Resumen Pto #2'!D14 -> 0 | E13: ='Resumen Pto #2'!E14 -> 0 | F13: ='Resumen Pto #2'!F14 -> 240000 | G13: ='Resumen Pto #2'!G14 -> 1706000 | H13: ='Resumen Pto #2'!H14 -> 446700 | I13: ='Resumen Pto #2'!I14 -> 1707000 | J13: ='Resumen Pto #2'!J14 -> 3102500 | K13: ='Resumen Pto #2'!K14 -> 535650 | ... T13: ='Resumen Pto #2'!T14 -> 790000 | V13: {=SUMPRODUCT($D13:$U13,TRANSPOSE('Indice CAC'!$D$2:$D$19))} -> 13132520 | X13: 0 | Y13: ='Resumen Pto #2'!X14 -> 8568681.2 | Z13: =SUM(X13:Y13) -> 8568681.2 | AA13: =IF($C13="MAT",SUMIF('Cert. Pto. 02'!$A$10:$A$194,$B13,'Cert. Pto. 02'!$T$10:$T$194),IF($C13="MO",SUMIF('Cert. Pto. 02'!$A$10:$A$194,$B13,'Cert. Pto. 02'!$U$10:$U$194),SUMIF('Cert. Pto. 02'!$A$10:$A$194,$B13,'Cert. Pto. 02'!$V$10:$V$194)))/IF($C13="MAT",SUMIF('Cert. Pto. 02'!$A$10:$A$194,$B13,'Cert. Pto. 02'!$I$10:$I$194),IF('Resumen Pto #2'!$C13="MO",SUMIF('Cert. Pto. 02'!$A$10:$A$194,$B13,'Cert. Pto. 02'!$J$10:$J$194),SUMIF('Cert. Pto. 02'!$A$10:$A$194,$B13,'Cert. Pto. 02'!$K$10:$K$194))) -> 0.89584131 | AB13: =IF(AA13=100%,0,IF(OR(V13<>0,Z13),Z13-V13)) -> -4563838.8 | AC13: =IF(OR(AB13<0,Z13),AB13/Z13,0%) -> -0.53261859 | AD13: =IF(AA13=100%,IF(OR(V13<>0,Z13),Z13-V13),0) -> 0
B14: Supervisión de Obra | D14: ='Resumen Pto #2'!D13 -> 2128206 | E14: ='Resumen Pto #2'!E13 -> 2503867.6 | F14: ='Resumen Pto #2'!F13 -> 2666306.9 | G14: ='Resumen Pto #2'!G13 -> 2632626 | H14: ='Resumen Pto #2'!H13 -> 2612626 | I14: ='Resumen Pto #2'!I13 -> 2612626 | J14: ='Resumen Pto #2'!J13 -> 2770864 | K14: ='Resumen Pto #2'!K13 -> 2921847.5 | ... T14: ='Resumen Pto #2'!T13 -> 0 | V14: {=SUMPRODUCT($D14:$U14,TRANSPOSE('Indice CAC'!$D$2:$D$19))} -> 42358438 | X14: 0 | Y14: ='Resumen Pto #2'!X13 -> 74327580 | Z14: =SUM(X14:Y14) -> 74327580 | AA14: =IF($C14="MAT",SUMIF('Cert. Pto. 02'!$A$10:$A$194,$B14,'Cert. Pto. 02'!$T$10:$T$194),IF($C14="MO",SUMIF('Cert. Pto. 02'!$A$10:$A$194,$B14,'Cert. Pto. 02'!$U$10:$U$194),SUMIF('Cert. Pto. 02'!$A$10:$A$194,$B14,'Cert. Pto. 02'!$V$10:$V$194)))/IF($C14="MAT",SUMIF('Cert. Pto. 02'!$A$10:$A$194,$B14,'Cert. Pto. 02'!$I$10:$I$194),IF('Resumen Pto #2'!$C14="MO",SUMIF('Cert. Pto. 02'!$A$10:$A$194,$B14,'Cert. Pto. 02'!$J$10:$J$194),SUMIF('Cert. Pto. 02'!$A$10:$A$194,$B14,'Cert. Pto. 02'!$K$10:$K$194))) -> 0.65 | AB14: =IF(AA14=100%,0,IF(OR(V14<>0,Z14),Z14-V14)) -> 31969142 | AC14: =IF(OR(AB14<0,Z14),AB14/Z14,0%) -> 0.43011144 | AD14: =IF(AA14=100%,IF(OR(V14<>0,Z14),Z14-V14),0) -> 0
B15: Movilidad | D15: ='Resumen Pto #2'!D15 -> 0 | E15: ='Resumen Pto #2'!E15 -> 320000 | F15: ='Resumen Pto #2'!F15 -> 14684.62 | G15: ='Resumen Pto #2'!G15 -> 181198.83 | H15: ='Resumen Pto #2'!H15 -> 217418.9 | I15: ='Resumen Pto #2'!I15 -> 263908.65 | J15: ='Resumen Pto #2'!J15 -> 162641.49 | K15: ='Resumen Pto #2'!K15 -> 614099.15 | ... T15: ='Resumen Pto #2'!T15 -> 432348.34 | V15: {=SUMPRODUCT($D15:$U15,TRANSPOSE('Indice CAC'!$D$2:$D$19))} -> 7606944 | X15: 0 | Y15: ='Resumen Pto #2'!X15 -> 13600000 | Z15: =SUM(X15:Y15) -> 13600000 | AA15: =IF($C15="MAT",SUMIF('Cert. Pto. 02'!$A$10:$A$194,$B15,'Cert. Pto. 02'!$T$10:$T$194),IF($C15="MO",SUMIF('Cert. Pto. 02'!$A$10:$A$194,$B15,'Cert. Pto. 02'!$U$10:$U$194),SUMIF('Cert. Pto. 02'!$A$10:$A$194,$B15,'Cert. Pto. 02'!$V$10:$V$194)))/IF($C15="MAT",SUMIF('Cert. Pto. 02'!$A$10:$A$194,$B15,'Cert. Pto. 02'!$I$10:$I$194),IF('Resumen Pto #2'!$C15="MO",SUMIF('Cert. Pto. 02'!$A$10:$A$194,$B15,'Cert. Pto. 02'!$J$10:$J$194),SUMIF('Cert. Pto. 02'!$A$10:$A$194,$B15,'Cert. Pto. 02'!$K$10:$K$194))) -> 0.65 | AB15: =IF(AA15=100%,0,IF(OR(V15<>0,Z15),Z15-V15)) -> 5993056 | AC15: =IF(OR(AB15<0,Z15),AB15/Z15,0%) -> 0.44066588 | AD15: =IF(AA15=100%,IF(OR(V15<>0,Z15),Z15-V15),0) -> 0
B16: Preliminares | D16: ='Resumen Pto #1'!D13 -> 0 | E16: ='Resumen Pto #1'!E13 -> 0 | F16: ='Resumen Pto #1'!F13 -> 6949796.9 | G16: ='Resumen Pto #1'!G13 -> 4182183.8 | H16: ='Resumen Pto #1'!H13 -> 163926.85 | I16: ='Resumen Pto #1'!I13 -> 459869.25 | J16: ='Resumen Pto #1'!J13 -> 92816.22 | K16: ='Resumen Pto #1'!K13 -> 14628.44 | ... T16: ='Resumen Pto #1'!T13 -> 0 | V16: {=SUMPRODUCT($D16:$U16,TRANSPOSE('Indice CAC'!$D$2:$D$19))} -> 12879112 | X16: ='Resumen Pto #1'!X13 -> 12544454 | Y16: 0 | Z16: =SUM(X16:Y16) -> 12544454 | AA16: =IF($C16="MAT",SUMIF('Cert. Pto. 01'!$A$9:$A$45,$B16,'Cert. Pto. 01'!$T$9:$T$45),IF($C16="MO",SUMIF('Cert. Pto. 01'!$A$9:$A$45,$B16,'Cert. Pto. 01'!$U$9:$U$45),SUMIF('Cert. Pto. 01'!$A$9:$A$45,$B16,'Cert. Pto. 01'!$V$9:$V$45)))/IF($C16="MAT",SUMIF('Cert. Pto. 01'!$A$9:$A$45,$B16,'Cert. Pto. 01'!$I$9:$I$45),IF($C16="MO",SUMIF('Cert. Pto. 01'!$A$9:$A$45,$B16,'Cert. Pto. 01'!$J$9:$J$45),SUMIF('Cert. Pto. 01'!$A$9:$A$45,$B16,'Cert. Pto. 01'!$K$9:$K$45))) -> 1 | AB16: =IF(AA16=100%,0,IF(OR(V16<>0,Z16),Z16-V16)) -> 0 | AC16: =IF(OR(AB16<0,Z16),AB16/Z16,0%) -> 0 | AD16: =IF(AA16=100%,IF(OR(V16<>0,Z16),Z16-V16),0) -> -334657.85
B17: Agrimensura | D17: ='Resumen Pto #1'!D14 -> 110000 | E17: ='Resumen Pto #1'!E14 -> 0 | F17: ='Resumen Pto #1'!F14 -> 0 | G17: ='Resumen Pto #1'!G14 -> 0 | H17: ='Resumen Pto #1'!H14 -> 0 | I17: ='Resumen Pto #1'!I14 -> 0 | J17: ='Resumen Pto #1'!J14 -> 0 | K17: ='Resumen Pto #1'!K14 -> 0 | ... T17: ='Resumen Pto #1'!T14 -> 0 | V17: {=SUMPRODUCT($D17:$U17,TRANSPOSE('Indice CAC'!$D$2:$D$19))} -> 110000 | X17: ='Resumen Pto #1'!X14 -> 853792.28 | Y17: 0 | Z17: =SUM(X17:Y17) -> 853792.28 | AA17: =IF($C17="MAT",SUMIF('Cert. Pto. 01'!$A$9:$A$45,$B17,'Cert. Pto. 01'!$T$9:$T$45),IF($C17="MO",SUMIF('Cert. Pto. 01'!$A$9:$A$45,$B17,'Cert. Pto. 01'!$U$9:$U$45),SUMIF('Cert. Pto. 01'!$A$9:$A$45,$B17,'Cert. Pto. 01'!$V$9:$V$45)))/IF($C17="MAT",SUMIF('Cert. Pto. 01'!$A$9:$A$45,$B17,'Cert. Pto. 01'!$I$9:$I$45),IF($C17="MO",SUMIF('Cert. Pto. 01'!$A$9:$A$45,$B17,'Cert. Pto. 01'!$J$9:$J$45),SUMIF('Cert. Pto. 01'!$A$9:$A$45,$B17,'Cert. Pto. 01'!$K$9:$K$45))) -> 1 | AB17: =IF(AA17=100%,0,IF(OR(V17<>0,Z17),Z17-V17)) -> 0 | AC17: =IF(OR(AB17<0,Z17),AB17/Z17,0%) -> 0 | AD17: =IF(AA17=100%,IF(OR(V17<>0,Z17),Z17-V17),0) -> 743792.28
B18: Excavación y Mov. de Suelos | D18: ='Resumen Pto #1'!D15 -> 0 | E18: ='Resumen Pto #1'!E15 -> 0 | F18: ='Resumen Pto #1'!F15 -> 0 | G18: ='Resumen Pto #1'!G15 -> 1580000 | H18: ='Resumen Pto #1'!H15 -> 1580000 | I18: ='Resumen Pto #1'!I15 -> 2974000 | J18: ='Resumen Pto #1'!J15 -> 3640000 | K18: ='Resumen Pto #1'!K15 -> 1416000 | ... T18: ='Resumen Pto #1'!T15 -> 0 | V18: {=SUMPRODUCT($D18:$U18,TRANSPOSE('Indice CAC'!$D$2:$D$19))} -> 10416172 | X18: ='Resumen Pto #1'!X15 -> 22068905 | Y18: 0 | Z18: =SUM(X18:Y18) -> 22068905 | AA18: =IF($C18="MAT",SUMIF('Cert. Pto. 01'!$A$9:$A$45,$B18,'Cert. Pto. 01'!$T$9:$T$45),IF($C18="MO",SUMIF('Cert. Pto. 01'!$A$9:$A$45,$B18,'Cert. Pto. 01'!$U$9:$U$45),SUMIF('Cert. Pto. 01'!$A$9:$A$45,$B18,'Cert. Pto. 01'!$V$9:$V$45)))/IF($C18="MAT",SUMIF('Cert. Pto. 01'!$A$9:$A$45,$B18,'Cert. Pto. 01'!$I$9:$I$45),IF($C18="MO",SUMIF('Cert. Pto. 01'!$A$9:$A$45,$B18,'Cert. Pto. 01'!$J$9:$J$45),SUMIF('Cert. Pto. 01'!$A$9:$A$45,$B18,'Cert. Pto. 01'!$K$9:$K$45))) -> 1 | AB18: =IF(AA18=100%,0,IF(OR(V18<>0,Z18),Z18-V18)) -> 0 | AC18: =IF(OR(AB18<0,Z18),AB18/Z18,0%) -> 0 | AD18: =IF(AA18=100%,IF(OR(V18<>0,Z18),Z18-V18),0) -> 11652732
B19: Hormigón | C19: MAT | D19: ='Resumen Pto #1'!D16 -> 0 | E19: ='Resumen Pto #1'!E16 -> 0 | F19: ='Resumen Pto #1'!F16 -> 1227898.4 | G19: ='Resumen Pto #1'!G16 -> 21854353 | H19: ='Resumen Pto #1'!H16 -> 64397545 | I19: ='Resumen Pto #1'!I16 -> 43287475 | J19: ='Resumen Pto #1'!J16 -> 1606135.8 | K19: ='Resumen Pto #1'!K16 -> 33701586 | ... T19: ='Resumen Pto #1'!T16 -> 0 | V19: {=SUMPRODUCT($D19:$U19,TRANSPOSE('Indice CAC'!$D$2:$D$19))} -> 1.8021717e+08 | X19: ='Resumen Pto #1'!X16 -> 1.8107277e+08 | Y19: 0 | Z19: =SUM(X19:Y19) -> 1.8107277e+08 | AA19: =IF($C19="MAT",SUMIF('Cert. Pto. 01'!$A$9:$A$45,$B19,'Cert. Pto. 01'!$T$9:$T$45),IF('Resumen Pto #1'!$C19="MO",SUMIF('Cert. Pto. 01'!$A$9:$A$45,$B19,'Cert. Pto. 01'!$U$9:$U$45),SUMIF('Cert. Pto. 01'!$A$9:$A$45,$B19,'Cert. Pto. 01'!$V$9:$V$45)))/IF($C19="MAT",SUMIF('Cert. Pto. 01'!$A$9:$A$45,$B19,'Cert. Pto. 01'!$I$9:$I$45),IF('Resumen Pto #1'!$C19="MO",SUMIF('Cert. Pto. 01'!$A$9:$A$45,$B19,'Cert. Pto. 01'!$J$9:$J$45),SUMIF('Cert. Pto. 01'!$A$9:$A$45,'Resumen Pto #1'!$B19,'Cert. Pto. 01'!$K$9:$K$45))) -> 1 | AB19: =IF(AA19=100%,0,IF(OR(V19<>0,Z19),Z19-V19)) -> 0 | AC19: =IF(OR(AB19<0,Z19),AB19/Z19,0%) -> 0 | AD19: =IF(AA19=100%,IF(OR(V19<>0,Z19),Z19-V19),0) -> 855599.54
B20: Hormigón | C20: MO | D20: ='Resumen Pto #1'!D17 -> 0 | E20: ='Resumen Pto #1'!E17 -> 0 | F20: ='Resumen Pto #1'!F17 -> 2411850 | G20: ='Resumen Pto #1'!G17 -> 9206862.2 | H20: ='Resumen Pto #1'!H17 -> 10965040 | I20: ='Resumen Pto #1'!I17 -> 9710066.5 | J20: ='Resumen Pto #1'!J17 -> 8357133.4 | K20: ='Resumen Pto #1'!K17 -> 20959356 | ... T20: ='Resumen Pto #1'!T17 -> 0 | V20: {=SUMPRODUCT($D20:$U20,TRANSPOSE('Indice CAC'!$D$2:$D$19))} -> 1.0530015e+08 | X20: ='Resumen Pto #1'!X17 -> 1.4437802e+08 | Y20: 0 | Z20: =SUM(X20:Y20) -> 1.4437802e+08 | AA20: =IF($C20="MAT",SUMIF('Cert. Pto. 01'!$A$9:$A$45,$B20,'Cert. Pto. 01'!$T$9:$T$45),IF($C20="MO",SUMIF('Cert. Pto. 01'!$A$9:$A$45,$B20,'Cert. Pto. 01'!$U$9:$U$45),SUMIF('Cert. Pto. 01'!$A$9:$A$45,$B20,'Cert. Pto. 01'!$V$9:$V$45)))/IF($C20="MAT",SUMIF('Cert. Pto. 01'!$A$9:$A$45,$B20,'Cert. Pto. 01'!$I$9:$I$45),IF($C20="MO",SUMIF('Cert. Pto. 01'!$A$9:$A$45,$B20,'Cert. Pto. 01'!$J$9:$J$45),SUMIF('Cert. Pto. 01'!$A$9:$A$45,$B20,'Cert. Pto. 01'!$K$9:$K$45))) -> 1 | AB20: =IF(AA20=100%,0,IF(OR(V20<>0,Z20),Z20-V20)) -> 0 | AC20: =IF(OR(AB20<0,Z20),AB20/Z20,0%) -> 0 | AD20: =IF(AA20=100%,IF(OR(V20<>0,Z20),Z20-V20),0) -> 39077870
B21: Albañilería | C21: MAT | D21: 0 | E21: ='Resumen Pto #2'!E16 -> 0 | F21: ='Resumen Pto #2'!F16 -> 0 | G21: ='Resumen Pto #2'!G16 -> 0 | H21: ='Resumen Pto #2'!H16 -> 0 | I21: ='Resumen Pto #2'!I16 -> 0 | J21: ='Resumen Pto #2'!J16 -> 43528.94 | K21: ='Resumen Pto #2'!K16 -> 493967.79 | L21: ='Resumen Pto #2'!L16 -> 503642.81 | ... T21: ='Resumen Pto #2'!T16 -> 1587335.5 | V21: {=SUMPRODUCT($D21:$U21,TRANSPOSE('Indice CAC'!$D$2:$D$19))} -> 30259046 | X21: 0 | Y21: ='Resumen Pto #2'!X16 -> 65392825 | Z21: =SUM(X21:Y21) -> 65392825 | AA21: =IF($C21="MAT",SUMIF('Cert. Pto. 02'!$A$10:$A$194,$B21,'Cert. Pto. 02'!$T$10:$T$194),IF($C21="MO",SUMIF('Cert. Pto. 02'!$A$10:$A$194,$B21,'Cert. Pto. 02'!$U$10:$U$194),SUMIF('Cert. Pto. 02'!$A$10:$A$194,$B21,'Cert. Pto. 02'!$V$10:$V$194)))/IF($C21="MAT",SUMIF('Cert. Pto. 02'!$A$10:$A$194,$B21,'Cert. Pto. 02'!$I$10:$I$194),IF($C21="MO",SUMIF('Cert. Pto. 02'!$A$10:$A$194,$B21,'Cert. Pto. 02'!$J$10:$J$194),SUMIF('Cert. Pto. 02'!$A$10:$A$194,$B21,'Cert. Pto. 02'!$K$10:$K$194))) -> 0.31906124 | AB21: =IF(AA21=100%,0,IF(OR(V21<>0,Z21),Z21-V21)) -> 35133778 | AC21: =IF(OR(AB21<0,Z21),AB21/Z21,0%) -> 0.53727268 | AD21: =IF(AA21=100%,IF(OR(V21<>0,Z21),Z21-V21),0) -> 0
B22: Albañilería | C22: MO | D22: ='Resumen Pto #2'!D17 -> 0 | E22: ='Resumen Pto #2'!E17 -> 0 | F22: ='Resumen Pto #2'!F17 -> 725487 | G22: ='Resumen Pto #2'!G17 -> 3309015.8 | H22: ='Resumen Pto #2'!H17 -> 3592574 | I22: ='Resumen Pto #2'!I17 -> 3991998.7 | J22: ='Resumen Pto #2'!J17 -> 4723373.5 | K22: ='Resumen Pto #2'!K17 -> 6711151 | ... T22: ='Resumen Pto #2'!T17 -> 1829165 | V22: {=SUMPRODUCT($D22:$U22,TRANSPOSE('Indice CAC'!$D$2:$D$19))} -> 1.2817618e+08 | X22: 0 | Y22: ='Resumen Pto #2'!X17 -> 1.3257367e+08 | Z22: =SUM(X22:Y22) -> 1.3257367e+08 | AA22: =IF($C22="MAT",SUMIF('Cert. Pto. 02'!$A$10:$A$194,$B22,'Cert. Pto. 02'!$T$10:$T$194),IF($C22="MO",SUMIF('Cert. Pto. 02'!$A$10:$A$194,$B22,'Cert. Pto. 02'!$U$10:$U$194),SUMIF('Cert. Pto. 02'!$A$10:$A$194,$B22,'Cert. Pto. 02'!$V$10:$V$194)))/IF($C22="MAT",SUMIF('Cert. Pto. 02'!$A$10:$A$194,$B22,'Cert. Pto. 02'!$I$10:$I$194),IF($C22="MO",SUMIF('Cert. Pto. 02'!$A$10:$A$194,$B22,'Cert. Pto. 02'!$J$10:$J$194),SUMIF('Cert. Pto. 02'!$A$10:$A$194,$B22,'Cert. Pto. 02'!$K$10:$K$194))) -> 0.42958142 | AB22: =IF(AA22=100%,0,IF(OR(V22<>0,Z22),Z22-V22)) -> 4397491.4 | AC22: =IF(OR(AB22<0,Z22),AB22/Z22,0%) -> 0.033170172 | AD22: =IF(AA22=100%,IF(OR(V22<>0,Z22),Z22-V22),0) -> 0
B23: Durlock | C23: MAT | D23: 0 | E23: ='Resumen Pto #2'!E18 -> 0 | F23: ='Resumen Pto #2'!F18 -> 0 | G23: ='Resumen Pto #2'!G18 -> 0 | H23: ='Resumen Pto #2'!H18 -> 0 | I23: ='Resumen Pto #2'!I18 -> 0 | J23: ='Resumen Pto #2'!J18 -> 0 | K23: ='Resumen Pto #2'!K18 -> 0 | L23: ='Resumen Pto #2'!L18 -> 0 | ... T23: ='Resumen Pto #2'!T18 -> 0 | V23: {=SUMPRODUCT($D23:$U23,TRANSPOSE('Indice CAC'!$D$2:$D$19))} -> 7552799.6 | X23: 0 | Y23: ='Resumen Pto #2'!X18 -> 13489970 | Z23: =SUM(X23:Y23) -> 13489970 | AA23: =IF($C23="MAT",SUMIF('Cert. Pto. 02'!$A$10:$A$194,$B23,'Cert. Pto. 02'!$T$10:$T$194),IF($C23="MO",SUMIF('Cert. Pto. 02'!$A$10:$A$194,$B23,'Cert. Pto. 02'!$U$10:$U$194),SUMIF('Cert. Pto. 02'!$A$10:$A$194,$B23,'Cert. Pto. 02'!$V$10:$V$194)))/IF($C23="MAT",SUMIF('Cert. Pto. 02'!$A$10:$A$194,$B23,'Cert. Pto. 02'!$I$10:$I$194),IF($C23="MO",SUMIF('Cert. Pto. 02'!$A$10:$A$194,$B23,'Cert. Pto. 02'!$J$10:$J$194),SUMIF('Cert. Pto. 02'!$A$10:$A$194,$B23,'Cert. Pto. 02'!$K$10:$K$194))) -> 0.091870848 | AB23: =IF(AA23=100%,0,IF(OR(V23<>0,Z23),Z23-V23)) -> 5937170.7 | AC23: =IF(OR(AB23<0,Z23),AB23/Z23,0%) -> 0.4401174 | AD23: =IF(AA23=100%,IF(OR(V23<>0,Z23),Z23-V23),0) -> 0
B24: Durlock | C24: MO | D24: 0 | E24: ='Resumen Pto #2'!E19 -> 0 | F24: ='Resumen Pto #2'!F19 -> 0 | G24: ='Resumen Pto #2'!G19 -> 0 | H24: ='Resumen Pto #2'!H19 -> 0 | I24: ='Resumen Pto #2'!I19 -> 0 | J24: ='Resumen Pto #2'!J19 -> 0 | K24: ='Resumen Pto #2'!K19 -> 0 | L24: ='Resumen Pto #2'!L19 -> 0 | ... T24: ='Resumen Pto #2'!T19 -> 3175584 | V24: {=SUMPRODUCT($D24:$U24,TRANSPOSE('Indice CAC'!$D$2:$D$19))} -> 10896814 | X24: 0 | Y24: ='Resumen Pto #2'!X19 -> 38496186 | Z24: =SUM(X24:Y24) -> 38496186 | AA24: =IF($C24="MAT",SUMIF('Cert. Pto. 02'!$A$10:$A$194,$B24,'Cert. Pto. 02'!$T$10:$T$194),IF($C24="MO",SUMIF('Cert. Pto. 02'!$A$10:$A$194,$B24,'Cert. Pto. 02'!$U$10:$U$194),SUMIF('Cert. Pto. 02'!$A$10:$A$194,$B24,'Cert. Pto. 02'!$V$10:$V$194)))/IF($C24="MAT",SUMIF('Cert. Pto. 02'!$A$10:$A$194,$B24,'Cert. Pto. 02'!$I$10:$I$194),IF($C24="MO",SUMIF('Cert. Pto. 02'!$A$10:$A$194,$B24,'Cert. Pto. 02'!$J$10:$J$194),SUMIF('Cert. Pto. 02'!$A$10:$A$194,$B24,'Cert. Pto. 02'!$K$10:$K$194))) -> 0.045566874 | AB24: =IF(AA24=100%,0,IF(OR(V24<>0,Z24),Z24-V24)) -> 27599372 | AC24: =IF(OR(AB24<0,Z24),AB24/Z24,0%) -> 0.71693783 | AD24: =IF(AA24=100%,IF(OR(V24<>0,Z24),Z24-V24),0) -> 0
B25: Pintura | C25: MAT | D25: 0 | E25: ='Resumen Pto #2'!E20 -> 0 | F25: ='Resumen Pto #2'!F20 -> 0 | G25: ='Resumen Pto #2'!G20 -> 0 | H25: ='Resumen Pto #2'!H20 -> 0 | I25: ='Resumen Pto #2'!I20 -> 0 | J25: ='Resumen Pto #2'!J20 -> 0 | K25: ='Resumen Pto #2'!K20 -> 0 | L25: ='Resumen Pto #2'!L20 -> 0 | ... T25: ='Resumen Pto #2'!T20 -> 0 | V25: {=SUMPRODUCT($D25:$U25,TRANSPOSE('Indice CAC'!$D$2:$D$19))} -> 132350.95 | X25: 0 | Y25: ='Resumen Pto #2'!X20 -> 19488570 | Z25: =SUM(X25:Y25) -> 19488570 | AA25: =IF($C25="MAT",SUMIF('Cert. Pto. 02'!$A$10:$A$194,$B25,'Cert. Pto. 02'!$T$10:$T$194),IF($C25="MO",SUMIF('Cert. Pto. 02'!$A$10:$A$194,$B25,'Cert. Pto. 02'!$U$10:$U$194),SUMIF('Cert. Pto. 02'!$A$10:$A$194,$B25,'Cert. Pto. 02'!$V$10:$V$194)))/IF($C25="MAT",SUMIF('Cert. Pto. 02'!$A$10:$A$194,$B25,'Cert. Pto. 02'!$I$10:$I$194),IF($C25="MO",SUMIF('Cert. Pto. 02'!$A$10:$A$194,$B25,'Cert. Pto. 02'!$J$10:$J$194),SUMIF('Cert. Pto. 02'!$A$10:$A$194,$B25,'Cert. Pto. 02'!$K$10:$K$194))) -> 0 | AB25: =IF(AA25=100%,0,IF(OR(V25<>0,Z25),Z25-V25)) -> 19356219 | AC25: =IF(OR(AB25<0,Z25),AB25/Z25,0%) -> 0.99320879 | AD25: =IF(AA25=100%,IF(OR(V25<>0,Z25),Z25-V25),0) -> 0
B26: Pintura | C26: MO | D26: 0 | E26: ='Resumen Pto #2'!E21 -> 0 | F26: ='Resumen Pto #2'!F21 -> 0 | G26: ='Resumen Pto #2'!G21 -> 0 | H26: ='Resumen Pto #2'!H21 -> 0 | I26: ='Resumen Pto #2'!I21 -> 0 | J26: ='Resumen Pto #2'!J21 -> 0 | K26: ='Resumen Pto #2'!K21 -> 0 | L26: ='Resumen Pto #2'!L21 -> 0 | ... T26: ='Resumen Pto #2'!T21 -> 0 | V26: {=SUMPRODUCT($D26:$U26,TRANSPOSE('Indice CAC'!$D$2:$D$19))} -> 0 | X26: 0 | Y26: ='Resumen Pto #2'!X21 -> 40879545 | Z26: =SUM(X26:Y26) -> 40879545 | AA26: =IF($C26="MAT",SUMIF('Cert. Pto. 02'!$A$10:$A$194,$B26,'Cert. Pto. 02'!$T$10:$T$194),IF($C26="MO",SUMIF('Cert. Pto. 02'!$A$10:$A$194,$B26,'Cert. Pto. 02'!$U$10:$U$194),SUMIF('Cert. Pto. 02'!$A$10:$A$194,$B26,'Cert. Pto. 02'!$V$10:$V$194)))/IF($C26="MAT",SUMIF('Cert. Pto. 02'!$A$10:$A$194,$B26,'Cert. Pto. 02'!$I$10:$I$194),IF($C26="MO",SUMIF('Cert. Pto. 02'!$A$10:$A$194,$B26,'Cert. Pto. 02'!$J$10:$J$194),SUMIF('Cert. Pto. 02'!$A$10:$A$194,$B26,'Cert. Pto. 02'!$K$10:$K$194))) -> 0 | AB26: =IF(AA26=100%,0,IF(OR(V26<>0,Z26),Z26-V26)) -> 40879545 | AC26: =IF(OR(AB26<0,Z26),AB26/Z26,0%) -> 1 | AD26: =IF(AA26=100%,IF(OR(V26<>0,Z26),Z26-V26),0) -> 0
B27: Revestimiento | C27: MAT | D27: 0 | E27: ='Resumen Pto #2'!E22 -> 0 | F27: ='Resumen Pto #2'!F22 -> 0 | G27: ='Resumen Pto #2'!G22 -> 0 | H27: ='Resumen Pto #2'!H22 -> 0 | I27: ='Resumen Pto #2'!I22 -> 0 | J27: ='Resumen Pto #2'!J22 -> 0 | K27: ='Resumen Pto #2'!K22 -> 0 | L27: ='Resumen Pto #2'!L22 -> 0 | ... T27: ='Resumen Pto #2'!T22 -> 0 | V27: {=SUMPRODUCT($D27:$U27,TRANSPOSE('Indice CAC'!$D$2:$D$19))} -> 1690828.7 | X27: 0 | Y27: ='Resumen Pto #2'!X22 -> 13983960 | Z27: =SUM(X27:Y27) -> 13983960 | AA27: =IF($C27="MAT",SUMIF('Cert. Pto. 02'!$A$10:$A$194,$B27,'Cert. Pto. 02'!$T$10:$T$194),IF($C27="MO",SUMIF('Cert. Pto. 02'!$A$10:$A$194,$B27,'Cert. Pto. 02'!$U$10:$U$194),SUMIF('Cert. Pto. 02'!$A$10:$A$194,$B27,'Cert. Pto. 02'!$V$10:$V$194)))/IF($C27="MAT",SUMIF('Cert. Pto. 02'!$A$10:$A$194,$B27,'Cert. Pto. 02'!$I$10:$I$194),IF($C27="MO",SUMIF('Cert. Pto. 02'!$A$10:$A$194,$B27,'Cert. Pto. 02'!$J$10:$J$194),SUMIF('Cert. Pto. 02'!$A$10:$A$194,$B27,'Cert. Pto. 02'!$K$10:$K$194))) -> 0 | AB27: =IF(AA27=100%,0,IF(OR(V27<>0,Z27),Z27-V27)) -> 12293132 | AC27: =IF(OR(AB27<0,Z27),AB27/Z27,0%) -> 0.87908799 | AD27: =IF(AA27=100%,IF(OR(V27<>0,Z27),Z27-V27),0) -> 0
B28: Revestimiento | C28: MO | D28: 0 | E28: ='Resumen Pto #2'!E23 -> 0 | F28: ='Resumen Pto #2'!F23 -> 0 | G28: ='Resumen Pto #2'!G23 -> 0 | H28: ='Resumen Pto #2'!H23 -> 0 | I28: ='Resumen Pto #2'!I23 -> 0 | J28: ='Resumen Pto #2'!J23 -> 0 | K28: ='Resumen Pto #2'!K23 -> 0 | L28: ='Resumen Pto #2'!L23 -> 0 | ... T28: ='Resumen Pto #2'!T23 -> 0 | V28: {=SUMPRODUCT($D28:$U28,TRANSPOSE('Indice CAC'!$D$2:$D$19))} -> 1531929.8 | X28: 0 | Y28: ='Resumen Pto #2'!X23 -> 26733574 | Z28: =SUM(X28:Y28) -> 26733574 | AA28: =IF($C28="MAT",SUMIF('Cert. Pto. 02'!$A$10:$A$194,$B28,'Cert. Pto. 02'!$T$10:$T$194),IF($C28="MO",SUMIF('Cert. Pto. 02'!$A$10:$A$194,$B28,'Cert. Pto. 02'!$U$10:$U$194),SUMIF('Cert. Pto. 02'!$A$10:$A$194,$B28,'Cert. Pto. 02'!$V$10:$V$194)))/IF($C28="MAT",SUMIF('Cert. Pto. 02'!$A$10:$A$194,$B28,'Cert. Pto. 02'!$I$10:$I$194),IF($C28="MO",SUMIF('Cert. Pto. 02'!$A$10:$A$194,$B28,'Cert. Pto. 02'!$J$10:$J$194),SUMIF('Cert. Pto. 02'!$A$10:$A$194,$B28,'Cert. Pto. 02'!$K$10:$K$194))) -> 0 | AB28: =IF(AA28=100%,0,IF(OR(V28<>0,Z28),Z28-V28)) -> 25201645 | AC28: =IF(OR(AB28<0,Z28),AB28/Z28,0%) -> 0.94269641 | AD28: =IF(AA28=100%,IF(OR(V28<>0,Z28),Z28-V28),0) -> 0
B29: Eléctrico | C29: MAT | D29: 0 | E29: ='Resumen Pto #2'!E24 -> 0 | F29: ='Resumen Pto #2'!F24 -> 0 | G29: ='Resumen Pto #2'!G24 -> 0 | H29: ='Resumen Pto #2'!H24 -> 0 | I29: ='Resumen Pto #2'!I24 -> 0 | J29: ='Resumen Pto #2'!J24 -> 0 | K29: ='Resumen Pto #2'!K24 -> 299136.83 | L29: ='Resumen Pto #2'!L24 -> 1111962.1 | ... T29: ='Resumen Pto #2'!T24 -> 76388.01 | V29: {=SUMPRODUCT($D29:$U29,TRANSPOSE('Indice CAC'!$D$2:$D$19))} -> 4965352.9 | X29: 0 | Y29: ='Resumen Pto #2'!X24 -> 25092460 | Z29: =SUM(X29:Y29) -> 25092460 | AA29: =IF($C29="MAT",SUMIF('Cert. Pto. 02'!$A$10:$A$194,$B29,'Cert. Pto. 02'!$T$10:$T$194),IF($C29="MO",SUMIF('Cert. Pto. 02'!$A$10:$A$194,$B29,'Cert. Pto. 02'!$U$10:$U$194),SUMIF('Cert. Pto. 02'!$A$10:$A$194,$B29,'Cert. Pto. 02'!$V$10:$V$194)))/IF($C29="MAT",SUMIF('Cert. Pto. 02'!$A$10:$A$194,$B29,'Cert. Pto. 02'!$I$10:$I$194),IF($C29="MO",SUMIF('Cert. Pto. 02'!$A$10:$A$194,$B29,'Cert. Pto. 02'!$J$10:$J$194),SUMIF('Cert. Pto. 02'!$A$10:$A$194,$B29,'Cert. Pto. 02'!$K$10:$K$194))) -> 0.28984006 | AB29: =IF(AA29=100%,0,IF(OR(V29<>0,Z29),Z29-V29)) -> 20127107 | AC29: =IF(OR(AB29<0,Z29),AB29/Z29,0%) -> 0.80211773 | AD29: =IF(AA29=100%,IF(OR(V29<>0,Z29),Z29-V29),0) -> 0
B30: Eléctrico | C30: MO | D30: 0 | E30: ='Resumen Pto #2'!E25 -> 0 | F30: ='Resumen Pto #2'!F25 -> 0 | G30: ='Resumen Pto #2'!G25 -> 0 | H30: ='Resumen Pto #2'!H25 -> 0 | I30: ='Resumen Pto #2'!I25 -> 0 | J30: ='Resumen Pto #2'!J25 -> 0 | K30: ='Resumen Pto #2'!K25 -> 500000 | L30: ='Resumen Pto #2'!L25 -> 450000 | ... T30: ='Resumen Pto #2'!T25 -> 0 | V30: {=SUMPRODUCT($D30:$U30,TRANSPOSE('Indice CAC'!$D$2:$D$19))} -> 17814883 | X30: 0 | Y30: ='Resumen Pto #2'!X25 -> 41278489 | Z30: =SUM(X30:Y30) -> 41278489 | AA30: =IF($C30="MAT",SUMIF('Cert. Pto. 02'!$A$10:$A$194,$B30,'Cert. Pto. 02'!$T$10:$T$194),IF($C30="MO",SUMIF('Cert. Pto. 02'!$A$10:$A$194,$B30,'Cert. Pto. 02'!$U$10:$U$194),SUMIF('Cert. Pto. 02'!$A$10:$A$194,$B30,'Cert. Pto. 02'!$V$10:$V$194)))/IF($C30="MAT",SUMIF('Cert. Pto. 02'!$A$10:$A$194,$B30,'Cert. Pto. 02'!$I$10:$I$194),IF($C30="MO",SUMIF('Cert. Pto. 02'!$A$10:$A$194,$B30,'Cert. Pto. 02'!$J$10:$J$194),SUMIF('Cert. Pto. 02'!$A$10:$A$194,$B30,'Cert. Pto. 02'!$K$10:$K$194))) -> 0.33069101 | AB30: =IF(AA30=100%,0,IF(OR(V30<>0,Z30),Z30-V30)) -> 23463605 | AC30: =IF(OR(AB30<0,Z30),AB30/Z30,0%) -> 0.5684221 | AD30: =IF(AA30=100%,IF(OR(V30<>0,Z30),Z30-V30),0) -> 0
B31: Sanitaria | C31: MAT | D31: 0 | E31: ='Resumen Pto #2'!E26 -> 0 | F31: ='Resumen Pto #2'!F26 -> 0 | G31: ='Resumen Pto #2'!G26 -> 0 | H31: ='Resumen Pto #2'!H26 -> 0 | I31: ='Resumen Pto #2'!I26 -> 0 | J31: ='Resumen Pto #2'!J26 -> 0 | K31: ='Resumen Pto #2'!K26 -> 7851.24 | L31: ='Resumen Pto #2'!L26 -> 0 | ... T31: ='Resumen Pto #2'!T26 -> 633057 | V31: {=SUMPRODUCT($D31:$U31,TRANSPOSE('Indice CAC'!$D$2:$D$19))} -> 6425159.6 | X31: 0 | Y31: ='Resumen Pto #2'!X26 -> 32568315 | Z31: =SUM(X31:Y31) -> 32568315 | AA31: =IF($C31="MAT",SUMIF('Cert. Pto. 02'!$A$10:$A$194,$B31,'Cert. Pto. 02'!$T$10:$T$194),IF($C31="MO",SUMIF('Cert. Pto. 02'!$A$10:$A$194,$B31,'Cert. Pto. 02'!$U$10:$U$194),SUMIF('Cert. Pto. 02'!$A$10:$A$194,$B31,'Cert. Pto. 02'!$V$10:$V$194)))/IF($C31="MAT",SUMIF('Cert. Pto. 02'!$A$10:$A$194,$B31,'Cert. Pto. 02'!$I$10:$I$194),IF($C31="MO",SUMIF('Cert. Pto. 02'!$A$10:$A$194,$B31,'Cert. Pto. 02'!$J$10:$J$194),SUMIF('Cert. Pto. 02'!$A$10:$A$194,$B31,'Cert. Pto. 02'!$K$10:$K$194))) -> 0.21719598 | AB31: =IF(AA31=100%,0,IF(OR(V31<>0,Z31),Z31-V31)) -> 26143156 | AC31: =IF(OR(AB31<0,Z31),AB31/Z31,0%) -> 0.80271747 | AD31: =IF(AA31=100%,IF(OR(V31<>0,Z31),Z31-V31),0) -> 0
B32: Sanitaria | C32: MO | D32: 0 | E32: ='Resumen Pto #2'!E27 -> 0 | F32: ='Resumen Pto #2'!F27 -> 0 | G32: ='Resumen Pto #2'!G27 -> 0 | H32: ='Resumen Pto #2'!H27 -> 0 | I32: ='Resumen Pto #2'!I27 -> 0 | J32: ='Resumen Pto #2'!J27 -> 0 | K32: ='Resumen Pto #2'!K27 -> 0 | L32: ='Resumen Pto #2'!L27 -> 0 | ... T32: ='Resumen Pto #2'!T27 -> 0 | V32: {=SUMPRODUCT($D32:$U32,TRANSPOSE('Indice CAC'!$D$2:$D$19))} -> 16085672 | X32: 0 | Y32: ='Resumen Pto #2'!X27 -> 75115078 | Z32: =SUM(X32:Y32) -> 75115078 | AA32: =IF($C32="MAT",SUMIF('Cert. Pto. 02'!$A$10:$A$194,$B32,'Cert. Pto. 02'!$T$10:$T$194),IF($C32="MO",SUMIF('Cert. Pto. 02'!$A$10:$A$194,$B32,'Cert. Pto. 02'!$U$10:$U$194),SUMIF('Cert. Pto. 02'!$A$10:$A$194,$B32,'Cert. Pto. 02'!$V$10:$V$194)))/IF($C32="MAT",SUMIF('Cert. Pto. 02'!$A$10:$A$194,$B32,'Cert. Pto. 02'!$I$10:$I$194),IF($C32="MO",SUMIF('Cert. Pto. 02'!$A$10:$A$194,$B32,'Cert. Pto. 02'!$J$10:$J$194),SUMIF('Cert. Pto. 02'!$A$10:$A$194,$B32,'Cert. Pto. 02'!$K$10:$K$194))) -> 0.25606992 | AB32: =IF(AA32=100%,0,IF(OR(V32<>0,Z32),Z32-V32)) -> 59029405 | AC32: =IF(OR(AB32<0,Z32),AB32/Z32,0%) -> 0.78585295 | AD32: =IF(AA32=100%,IF(OR(V32<>0,Z32),Z32-V32),0) -> 0
B33: Equipos | D33: ='Resumen Pto #1'!D18 -> 58271.121 | E33: ='Resumen Pto #1'!E18+'Resumen Pto #2'!E28 -> 59559.523 | F33: ='Resumen Pto #1'!F18+'Resumen Pto #2'!F28 -> 64331.918 | G33: ='Resumen Pto #1'!G18+'Resumen Pto #2'!G28 -> 287221.2 | H33: ='Resumen Pto #1'!H18+'Resumen Pto #2'!H28 -> 290739.63 | I33: ='Resumen Pto #1'!I18+'Resumen Pto #2'!I28 -> 296307.18 | J33: ='Resumen Pto #1'!J18+'Resumen Pto #2'!J28 -> 346009.64 | K33: ='Resumen Pto #1'!K18+'Resumen Pto #2'!K28 -> 799574.25 | L33: ='Resumen Pto #1'!L18+'Resumen Pto #2'!L28 -> 631705.98 | ... T33: ='Resumen Pto #1'!T18+'Resumen Pto #2'!T28 -> 0 | V33: {=SUMPRODUCT($D33:$U33,TRANSPOSE('Indice CAC'!$D$2:$D$19))} -> 6788085.2 | X33: ='Resumen Pto #1'!X18 -> 13604196 | Y33: ='Resumen Pto #2'!X28 -> 7890286.6 | Z33: =SUM(X33:Y33) -> 21494483 | AA33: =AVERAGE('Cert. Pto. 01'!S48,'Cert. Pto. 02'!S196) -> 0.66328256 | AB33: =IF(AA33=100%,0,IF(OR(V33<>0,Z33),Z33-V33)) -> 14706398 | AC33: =IF(OR(AB33<0,Z33),AB33/Z33,0%) -> 0.68419407 | AD33: =IF(AA33=100%,IF(OR(V33<>0,Z33),Z33-V33),0) -> 0
B34: Gastos Generales Obra | D34: ='Resumen Pto #1'!D19 -> 12905.63 | E34: ='Resumen Pto #1'!E19 -> 0 | F34: ='Resumen Pto #1'!F19 -> 90000 | G34: ='Resumen Pto #1'!G19 -> 180000 | H34: ='Resumen Pto #1'!H19 -> 80000 | I34: ='Resumen Pto #1'!I19 -> 80000 | J34: ='Resumen Pto #1'!J19 -> 380000 | K34: ='Resumen Pto #1'!K19 -> 160000 | ... T34: ='Resumen Pto #1'!T19 -> 0 | V34: {=SUMPRODUCT($D34:$U34,TRANSPOSE('Indice CAC'!$D$2:$D$19))} -> 3563879 | X34: ='Resumen Pto #1'!X19 -> 5763772 | Y34: 0 | Z34: =SUM(X34:Y34) -> 5763772 | AA34: =IF($C34="MAT",SUMIF('Cert. Pto. 01'!$A$9:$A$45,$B34,'Cert. Pto. 01'!$T$9:$T$45),IF($C34="MO",SUMIF('Cert. Pto. 01'!$A$9:$A$45,$B34,'Cert. Pto. 01'!$U$9:$U$45),SUMIF('Cert. Pto. 01'!$A$9:$A$45,$B34,'Cert. Pto. 01'!$V$9:$V$45)))/IF($C34="MAT",SUMIF('Cert. Pto. 01'!$A$9:$A$45,$B34,'Cert. Pto. 01'!$I$9:$I$45),IF($C34="MO",SUMIF('Cert. Pto. 01'!$A$9:$A$45,$B34,'Cert. Pto. 01'!$J$9:$J$45),SUMIF('Cert. Pto. 01'!$A$9:$A$45,$B34,'Cert. Pto. 01'!$K$9:$K$45))) -> 1 | AB34: =IF(AA34=100%,0,IF(OR(V34<>0,Z34),Z34-V34)) -> 0 | AC34: =IF(OR(AB34<0,Z34),AB34/Z34,0%) -> 0 | AD34: =IF(AA34=100%,IF(OR(V34<>0,Z34),Z34-V34),0) -> 2199893
B35: Total Egresos de Obra | D35: =SUM(D13:D34) -> 2309382.8 | E35: =SUM(E13:E34) -> 2883427.1 | F35: =SUM(F13:F34) -> 14390356 | G35: =SUM(G13:G34) -> 45119461 | H35: =SUM(H13:H34) -> 84346570 | I35: =SUM(I13:I34) -> 65383252 | J35: =SUM(J13:J34) -> 25225003 | K35: =SUM(K13:K34) -> 69134848 | ... T35: =SUM(T13:T34) -> 8523877.9 | V35: =SUM(V13:V34) -> 6.0790348e+08 | X35: =SUM(X13:X34) -> 3.8028591e+08 | Y35: =SUM(Y13:Y34) -> 6.2947919e+08 | Z35: =SUM(Z13:Z34) -> 1.0097651e+09 | AA35: =SUM('Cert. Pto. 01'!V46,'Cert. Pto. 02'!V195)/SUM('Cert. Pto. 01'!L46,'Cert. Pto. 02'!L195) -> 0.57722683 | AB35: =IF(AA35=100%,0,IF(OR(V35<>0,Z35),Z35-V35)) -> 4.0186161e+08 | AC35: =IF(OR(AB35<0,Z35),AB35/Z35,0%) -> 0.39797535 | AD35: =SUM(AD13:AD34) -> 54195229
B37: Gastos Generales
B38: Gastos Directos | D38: =SUM('Resumen Pto #1'!D$23,'Resumen Pto #2'!D$32) -> 3175204.8 | E38: =SUM('Resumen Pto #1'!E$23,'Resumen Pto #2'!E$32) -> 2020935.7 | F38: =SUM('Resumen Pto #1'!F$23,'Resumen Pto #2'!F$32) -> 2883500.7 | G38: =SUM('Resumen Pto #1'!G$23,'Resumen Pto #2'!G$32) -> 2286455.7 | H38: =SUM('Resumen Pto #1'!H$23,'Resumen Pto #2'!H$32) -> 6273647.6 | I38: =SUM('Resumen Pto #1'!I$23,'Resumen Pto #2'!I$32) -> 1963509.9 | J38: =SUM('Resumen Pto #1'!J$23,'Resumen Pto #2'!J$32) -> 2816808 | K38: =SUM('Resumen Pto #1'!K$23,'Resumen Pto #2'!K$32) -> 2808099.8 | ... T38: =SUM('Resumen Pto #1'!T$23,'Resumen Pto #2'!T$32) -> 0 | V38: {=SUMPRODUCT($D38:$U38,TRANSPOSE('Indice CAC'!$D$2:$D$19))} -> 45619359 | X38: ='Resumen Pto #1'!X23 -> 60150532 | Y38: ='Resumen Pto #2'!X32 -> 32809381 | Z38: =SUM(X38:Y38) -> 92959913 | AA38: =AVERAGE('Cert. Pto. 01'!S48,'Cert. Pto. 02'!S196) -> 0.66328256 | AB38: =IF(AA38=100%,0,IF(OR(V38<>0,Z38),Z38-V38)) -> 47340554 | AC38: =IF(OR(AB38<0,Z38),AB38/Z38,0%) -> 0.50925772 | AD38: =IF(AA38=100%,IF(OR(V38<>0,Z38),Z38-V38),0) -> 0
B39: Gastos Indirectos | D39: =SUM('Resumen Pto #1'!D$24,'Resumen Pto #2'!D$33) -> 639132.78 | E39: =SUM('Resumen Pto #1'!E$24,'Resumen Pto #2'!E$33) -> 1825790.3 | F39: =SUM('Resumen Pto #1'!F$24,'Resumen Pto #2'!F$33) -> 1406464.9 | G39: =SUM('Resumen Pto #1'!G$24,'Resumen Pto #2'!G$33) -> 2714187.3 | H39: =SUM('Resumen Pto #1'!H$24,'Resumen Pto #2'!H$33) -> 2169029.3 | I39: =SUM('Resumen Pto #1'!I$24,'Resumen Pto #2'!I$33) -> 1800256.2 | J39: =SUM('Resumen Pto #1'!J$24,'Resumen Pto #2'!J$33) -> 2949259.1 | K39: =SUM('Resumen Pto #1'!K$24,'Resumen Pto #2'!K$33) -> 4175013.8 | ... T39: =SUM('Resumen Pto #1'!T$24,'Resumen Pto #2'!T$33) -> 0 | V39: {=SUMPRODUCT($D39:$U39,TRANSPOSE('Indice CAC'!$D$2:$D$19))} -> 38502555 | X39: ='Resumen Pto #1'!X24 -> 53546314 | Y39: ='Resumen Pto #2'!X33 -> 29207081 | Z39: =SUM(X39:Y39) -> 82753395 | AA39: =AVERAGE('Cert. Pto. 01'!S48,'Cert. Pto. 02'!S196) -> 0.66328256 | AB39: =IF(AA39=100%,0,IF(OR(V39<>0,Z39),Z39-V39)) -> 44250840 | AC39: =IF(OR(AB39<0,Z39),AB39/Z39,0%) -> 0.53473141 | AD39: =IF(AA39=100%,IF(OR(V39<>0,Z39),Z39-V39),0) -> 0
B40: Total Gastos Generales | D40: =SUM(D38:D39) -> 3814337.6 | E40: =SUM(E38:E39) -> 3846726 | F40: =SUM(F38:F39) -> 4289965.6 | G40: =SUM(G38:G39) -> 5000643 | H40: =SUM(H38:H39) -> 8442676.9 | I40: =SUM(I38:I39) -> 3763766.1 | J40: =SUM(J38:J39) -> 5766067.1 | K40: =SUM(K38:K39) -> 6983113.6 | ... T40: =SUM(T38:T39) -> 0 | V40: =SUM(V38:V39) -> 84121914 | X40: =SUM(X38:X39) -> 1.1369685e+08 | Y40: =SUM(Y38:Y39) -> 62016462 | Z40: =SUM(Z38:Z39) -> 1.7571331e+08 | AB40: =IF(AA40=100%,0,IF(OR(V40<>0,Z40),Z40-V40)) -> 91591394 | AC40: =IF(OR(AB40<0,Z40),AB40/Z40,0%) -> 0.52125473 | AD40: =SUM(AD38:AD39) -> 0
B42: Total Egresos | D42: =D35+D40 -> 6123720.3 | E42: =E35+E40 -> 6730153.1 | F42: =F35+F40 -> 18680321 | G42: =G35+G40 -> 50120104 | H42: =H35+H40 -> 92789247 | I42: =I35+I40 -> 69147018 | J42: =J35+J40 -> 30991070 | K42: =K35+K40 -> 76117962 | ... T42: =T35+T40 -> 8523877.9 | V42: =V35+V40 -> 6.920254e+08 | X42: =X35+X40 -> 4.9398275e+08 | Y42: =Y35+Y40 -> 6.9149565e+08 | Z42: =Z35+Z40 -> 1.1854784e+09
B44: Resultado Operativo | D44: =SUM(D8,D10,-D42) -> -6123720.3 | E44: =SUM(E8,E10,-E42) -> -6730153.1 | F44: =SUM(F8,F10,-F42) -> 2.7536765e+08 | G44: =SUM(G8,G10,-G42) -> -21611627 | H44: =SUM(H8,H10,-H42) -> -67458111 | I44: =SUM(I8,I10,-I42) -> -18489177 | J44: =SUM(J8,J10,-J42) -> 1151020.9 | K44: =SUM(K8,K10,-K42) -> -3402338 | ... T44: =SUM(T8,T10,-T42) -> -8523877.9 | V44: =V8-V42 -> 53854106 | Z44: =Z8-Z42 -> 1.6027457e+08
B45: Resultado Acumulado | D45: =D44 -> -6123720.3 | E45: =D45+E44 -> -12853873 | F45: =E45+F44 -> 2.6251378e+08 | G45: =F45+G44 -> 2.4090215e+08 | H45: =G45+H44 -> 1.7344404e+08 | I45: =H45+I44 -> 1.5495486e+08 | J45: =I45+J44 -> 1.5610588e+08 | K45: =J45+K44 -> 1.5270355e+08 | L45: =K45+L44 -> 1.6960522e+08 | ... T45: =S45+T44 -> 37288390
...

Sheet Resumen Pto #1
AC1: Actualizado | AD1: 46133
B3: OBRA: GDR 3760
B4: RESUMEN DE OBRA
D5: 45627 | E5: 45658 | F5: 45689 | G5: 45717 | H5: 45748 | I5: 45778 | J5: 45809 | K5: 45839 | L5: 45870 | M5: 45901 | N5: 45931 | O5: 45962 | P5: 45992 | Q5: 46023 | R5: 46054 | S5: 46082 | T5: 46113 | V5: Acum. Descontado | X5: Previsto | Y5: % Cert. Acum. | Z5: Saldo Disponible | AA5: Disponible % | AB5: Rubro Completado
B6: Ingresos de Obra
B7: Ingresos por certificados | D7: =SUMIFS(Certificados!$E$12:$E$80,Certificados!$A$12:$A$80,">="&DATE(2024,12,1),Certificados!$A$12:$A$80,"<="&DATE(2024,12,31),Certificados!$C$12:$C$80,"Pto. 1") -> 0 | E7: =SUMIFS(Certificados!$E$12:$E$80,Certificados!$A$12:$A$80,">="&DATE(2025,1,1),Certificados!$A$12:$A$80,"<="&DATE(2025,1,31),Certificados!$C$12:$C$80,"Pto. 1") -> 0 | F7: =SUMIFS(Certificados!$E$12:$E$80,Certificados!$A$12:$A$80,">="&DATE(2025,2,1),Certificados!$A$12:$A$80,"<="&DATE(2025,2,28),Certificados!$C$12:$C$80,"Pto. 1") -> 200363088 | G7: =SUMIFS(Certificados!$E$12:$E$80,Certificados!$A$12:$A$80,">="&DATE(2025,3,1),Certificados!$A$12:$A$80,"<="&DATE(2025,3,31),Certificados!$C$12:$C$80,"Pto. 1") -> 19603686 | H7: =SUMIFS(Certificados!$E$12:$E$80,Certificados!$A$12:$A$80,">="&DATE(2025,4,1),Certificados!$A$12:$A$80,"<="&DATE(2025,4,30),Certificados!$C$12:$C$80,"Pto. 1") -> 16465959 | I7: =SUMIFS(Certificados!$E$12:$E$80,Certificados!$A$12:$A$80,">="&DATE(2025,5,1),Certificados!$A$12:$A$80,"<="&DATE(2025,5,31),Certificados!$C$12:$C$80,"Pto. 1") -> 38898523 | J7: =SUMIFS(Certificados!$E$12:$E$80,Certificados!$A$12:$A$80,">="&DATE(2025,6,1),Certificados!$A$12:$A$80,"<="&DATE(2025,6,30),Certificados!$C$12:$C$80,"Pto. 1") -> 21634404 | K7: =SUMIFS(Certificados!$E$12:$E$80,Certificados!$A$12:$A$80,">="&DATE(2025,7,1),Certificados!$A$12:$A$80,"<="&DATE(2025,7,31),Certificados!$C$12:$C$80,"Pto. 1") -> 56374940 | L7: =SUMIFS(Certificados!$E$12:$E$80,Certificados!$A$12:$A$80,">="&DATE(2025,8,1),Certificados!$A$12:$A$80,"<="&DATE(2025,8,31),Certificados!$C$12:$C$80,"Pto. 1") -> 33566952 | M7: =SUMIFS(Certificados!$E$12:$E$80,Certificados!$A$12:$A$80,">="&DATE(2025,9,1),Certificados!$A$12:$A$80,"<="&DATE(2025,9,30),Certificados!$C$12:$C$80,"Pto. 1") -> 20270753 | N7: =SUMIFS(Certificados!$E$12:$E$80,Certificados!$A$12:$A$80,">="&DATE(2025,10,1),Certificados!$A$12:$A$80,"<="&DATE(2025,10,30),Certificados!$C$12:$C$80,"Pto. 1") -> 15191867 | O7: =SUMIFS(Certificados!$E$12:$E$80,Certificados!$A$12:$A$80,">="&DATE(2025,11,1),Certificados!$A$12:$A$80,"<="&DATE(2025,11,30),Certificados!$C$12:$C$80,"Pto. 1") -> -9282491.1 | P7: =SUMIFS(Certificados!$E$12:$E$80,Certificados!$A$12:$A$80,">="&DATE(2025,12,1),Certificados!$A$12:$A$80,"<="&DATE(2025,12,31),Certificados!$C$12:$C$80,"Pto. 1") -> 0 | Q7: =SUMIFS(Certificados!$E$12:$E$80,Certificados!$A$12:$A$80,">="&DATE(2026,1,1),Certificados!$A$12:$A$80,"<="&DATE(2026,1,31),Certificados!$C$12:$C$80,"Pto. 1") -> 0 | R7: =SUMIFS(Certificados!$E$12:$E$80,Certificados!$A$12:$A$80,">="&DATE(2026,2,1),Certificados!$A$12:$A$80,"<="&DATE(2026,2,28),Certificados!$C$12:$C$80,"Pto. 1") -> 0 | S7: =SUMIFS(Certificados!$E$12:$E$80,Certificados!$A$12:$A$80,">="&DATE(2026,3,1),Certificados!$A$12:$A$80,"<="&DATE(2026,3,31),Certificados!$C$12:$C$80,"Pto. 1") -> 0 | T7: =SUMIFS(Certificados!$E$12:$E$80,Certificados!$A$12:$A$80,">="&DATE(2026,4,1),Certificados!$A$12:$A$80,"<="&DATE(2026,4,30),Certificados!$C$12:$C$80,"Pto. 1") -> 0 | V7: =SUM(D7:U7) -> 4.1308768e+08 | X7: =SUM(Facturacion!E4:E5) -> 500907720 | Y7: ='Cert. Pto. 01'!S46/'Cert. Pto. 01'!L46 -> 1 | Z7: =IF(Y7=100%,0,IF(OR(V7<>0,X7),X7-V7)) -> 0 | AA7: =IF(OR(Z7<0,X7),Z7/X7,0%) -> 0 | AB7: =IF(Y7=100%,IF(OR(V7<>0,X7),X7-V7),0) -> 87820039
B8: Total Ingresos de Obra | D8: =SUM(D7) -> 0 | E8: =SUM(E7) -> 0 | F8: =SUM(F7) -> 200363088 | G8: =SUM(G7) -> 19603686 | H8: =SUM(H7) -> 16465959 | I8: =SUM(I7) -> 38898523 | J8: =SUM(J7) -> 21634404 | K8: =SUM(K7) -> 56374940 | ... T8: =SUM(T7) -> 0 | V8: =SUM(V7) -> 4.1308768e+08 | X8: =SUM(X7) -> 500907720 | Z8: =SUM(Z7) -> 0 | AA8: =IF(OR(Z8<0,X8),Z8/X8,0%) -> 0 | AB8: =SUM(AB7) -> 87820039
B9: Actualización por CAC | D9: =SUMIFS(Certificados!$F$12:$F$80,Certificados!$A$12:$A$80,">="&DATE(2024,12,1),Certificados!$A$12:$A$80,"<="&DATE(2024,12,31),Certificados!$C$12:$C$80,"Pto. 1") -> 0 | E9: =SUMIFS(Certificados!$F$12:$F$80,Certificados!$A$12:$A$80,">="&DATE(2025,1,1),Certificados!$A$12:$A$80,"<="&DATE(2025,1,31),Certificados!$C$12:$C$80,"Pto. 1") -> 0 | F9: =SUMIFS(Certificados!$F$12:$F$80,Certificados!$A$12:$A$80,">="&DATE(2025,2,1),Certificados!$A$12:$A$80,"<="&DATE(2025,2,28),Certificados!$C$12:$C$80,"Pto. 1") -> 6471574.8 | G9: =SUMIFS(Certificados!$F$12:$F$80,Certificados!$A$12:$A$80,">="&DATE(2025,3,1),Certificados!$A$12:$A$80,"<="&DATE(2025,3,31),Certificados!$C$12:$C$80,"Pto. 1") -> 633184.08 | H9: =SUMIFS(Certificados!$F$12:$F$80,Certificados!$A$12:$A$80,">="&DATE(2025,4,1),Certificados!$A$12:$A$80,"<="&DATE(2025,4,30),Certificados!$C$12:$C$80,"Pto. 1") -> 685170.23 | I9: =SUMIFS(Certificados!$F$12:$F$80,Certificados!$A$12:$A$80,">="&DATE(2025,5,1),Certificados!$A$12:$A$80,"<="&DATE(2025,5,31),Certificados!$C$12:$C$80,"Pto. 1") -> 2272398.8 | J9: =SUMIFS(Certificados!$F$12:$F$80,Certificados!$A$12:$A$80,">="&DATE(2025,6,1),Certificados!$A$12:$A$80,"<="&DATE(2025,6,30),Certificados!$C$12:$C$80,"Pto. 1") -> 1641134.4 | K9: =SUMIFS(Certificados!$F$12:$F$80,Certificados!$A$12:$A$80,">="&DATE(2025,7,1),Certificados!$A$12:$A$80,"<="&DATE(2025,7,31),Certificados!$C$12:$C$80,"Pto. 1") -> 4724710 | L9: =SUMIFS(Certificados!$F$12:$F$80,Certificados!$A$12:$A$80,">="&DATE(2025,8,1),Certificados!$A$12:$A$80,"<="&DATE(2025,8,31),Certificados!$C$12:$C$80,"Pto. 1") -> 3460436.2 | M9: =SUMIFS(Certificados!$F$12:$F$80,Certificados!$A$12:$A$80,">="&DATE(2025,9,1),Certificados!$A$12:$A$80,"<="&DATE(2025,9,30),Certificados!$C$12:$C$80,"Pto. 1") -> 2417220.4 | N9: =SUMIFS(Certificados!$F$12:$F$80,Certificados!$A$12:$A$80,">="&DATE(2025,10,1),Certificados!$A$12:$A$80,"<="&DATE(2025,10,30),Certificados!$C$12:$C$80,"Pto. 1") -> 2380122 | O9: =SUMIFS(Certificados!$F$12:$F$80,Certificados!$A$12:$A$80,">="&DATE(2025,11,1),Certificados!$A$12:$A$80,"<="&DATE(2025,11,30),Certificados!$C$12:$C$80,"Pto. 1") -> 4748892.9 | P9: =SUMIFS(Certificados!$F$12:$F$80,Certificados!$A$12:$A$80,">="&DATE(2025,12,1),Certificados!$A$12:$A$80,"<="&DATE(2025,12,31),Certificados!$C$12:$C$80,"Pto. 1") -> 0 | Q9: =SUMIFS(Certificados!$F$12:$F$80,Certificados!$A$12:$A$80,">="&DATE(2026,1,1),Certificados!$A$12:$A$80,"<="&DATE(2026,1,31),Certificados!$C$12:$C$80,"Pto. 1") -> 0 | R9: =SUMIFS(Certificados!$F$12:$F$80,Certificados!$A$12:$A$80,">="&DATE(2026,2,1),Certificados!$A$12:$A$80,"<="&DATE(2026,2,28),Certificados!$C$12:$C$80,"Pto. 1") -> 0 | S9: =SUMIFS(Certificados!$F$12:$F$80,Certificados!$A$12:$A$80,">="&DATE(2026,3,1),Certificados!$A$12:$A$80,"<="&DATE(2026,3,31),Certificados!$C$12:$C$80,"Pto. 1") -> 0 | T9: =SUMIFS(Certificados!$F$12:$F$80,Certificados!$A$12:$A$80,">="&DATE(2026,4,1),Certificados!$A$12:$A$80,"<="&DATE(2026,4,30),Certificados!$C$12:$C$80,"Pto. 1") -> 0 | V9: =SUM(D9:U9) -> 29434844 | X9: 0 | Y9: 0 | Z9: =IF(Y9=100%,0,IF(X9=0,X9,X9-V9)) -> 0 | AA9: =IF(OR(Z9<0,X9),Z9/X9,0%) -> 0 | AB9: =IF(Y9=100%,IF(OR(V9<>0,X9),X9-V9),0) -> 0
B10: Total Ingresos por CAC | D10: =SUM(D9) -> 0 | E10: =SUM(E9) -> 0 | F10: =SUM(F9) -> 6471574.8 | G10: =SUM(G9) -> 633184.08 | H10: =SUM(H9) -> 685170.23 | I10: =SUM(I9) -> 2272398.8 | J10: =SUM(J9) -> 1641134.4 | K10: =SUM(K9) -> 4724710 | ... T10: =SUM(T9) -> 0 | V10: =SUM(V9) -> 29434844 | X10: =SUM(X9) -> 0 | Z10: =SUM(Z9) -> 0 | AA10: =IF(OR(Z10<0,X10),Z10/X10,0%) -> 0 | AB10: =SUM(AB9) -> 0
B12: Costos de Obra
B13: Preliminares | D13: =IFERROR(VLOOKUP($B13&$C13,'C. Gestión Pto #1'!$B$4:C$11,MATCH(D$5,'C. Gestión Pto #1'!$B$4:C$4,0),FALSE),0) -> 0 | E13: =IFERROR(VLOOKUP($B13&$C13,'C. Gestión Pto #1'!$B$4:D$11,MATCH(E$5,'C. Gestión Pto #1'!$B$4:D$4,0),FALSE),0) -> 0 | F13: =IFERROR(VLOOKUP($B13&$C13,'C. Gestión Pto #1'!$B$4:E$11,MATCH(F$5,'C. Gestión Pto #1'!$B$4:E$4,0),FALSE),0) -> 6949796.9 | G13: =IFERROR(VLOOKUP($B13&$C13,'C. Gestión Pto #1'!$B$4:F$11,MATCH(G$5,'C. Gestión Pto #1'!$B$4:F$4,0),FALSE),0) -> 4182183.8 | H13: =IFERROR(VLOOKUP($B13&$C13,'C. Gestión Pto #1'!$B$4:G$11,MATCH(H$5,'C. Gestión Pto #1'!$B$4:G$4,0),FALSE),0) -> 163926.85 | I13: =IFERROR(VLOOKUP($B13&$C13,'C. Gestión Pto #1'!$B$4:H$11,MATCH(I$5,'C. Gestión Pto #1'!$B$4:H$4,0),FALSE),0) -> 459869.25 | J13: =IFERROR(VLOOKUP($B13&$C13,'C. Gestión Pto #1'!$B$4:I$11,MATCH(J$5,'C. Gestión Pto #1'!$B$4:I$4,0),FALSE),0) -> 92816.22 | K13: =IFERROR(VLOOKUP($B13&$C13,'C. Gestión Pto #1'!$B$4:J$11,MATCH(K$5,'C. Gestión Pto #1'!$B$4:J$4,0),FALSE),0) -> 14628.44 | ... T13: =IFERROR(VLOOKUP($B13&$C13,'C. Gestión Pto #1'!$B$4:S$11,MATCH(T$5,'C. Gestión Pto #1'!$B$4:S$4,0),FALSE),0) -> 0 | V13: {=SUMPRODUCT($D13:$U13,TRANSPOSE('Indice CAC'!$D$2:$D$19))} -> 12879112 | X13: =IF($C13="MAT",SUMIF('P. Costo'!$A$8:$A$58,$B13,'P. Costo'!$I$8:$I$58),IF($C13="MO",SUMIF('P. Costo'!$A$8:$A$58,$B13,'P. Costo'!$L$8:$L$58),SUMIF('P. Costo'!$A$8:$A$58,$B13,'P. Costo'!$N$8:$N$58))) -> 12544454 | Y13: =IF($C13="MAT",SUMIF('Cert. Pto. 01'!$A$9:$A$45,'Resumen Pto #1'!$B13,'Cert. Pto. 01'!$T$9:$T$45),IF('Resumen Pto #1'!$C13="MO",SUMIF('Cert. Pto. 01'!$A$9:$A$45,'Resumen Pto #1'!$B13,'Cert. Pto. 01'!$U$9:$U$45),SUMIF('Cert. Pto. 01'!$A$9:$A$45,'Resumen Pto #1'!$B13,'Cert. Pto. 01'!$V$9:$V$45)))/IF($C13="MAT",SUMIF('Cert. Pto. 01'!$A$9:$A$45,'Resumen Pto #1'!$B13,'Cert. Pto. 01'!$I$9:$I$45),IF('Resumen Pto #1'!$C13="MO",SUMIF('Cert. Pto. 01'!$A$9:$A$45,'Resumen Pto #1'!$B13,'Cert. Pto. 01'!$J$9:$J$45),SUMIF('Cert. Pto. 01'!$A$9:$A$45,'Resumen Pto #1'!$B13,'Cert. Pto. 01'!$K$9:$K$45))) -> 1 | Z13: =IF(Y13=100%,0,IF(OR(V13<>0,X13),X13-V13)) -> 0 | AA13: =IF(OR(Z13<0,X13),Z13/X13,0%) -> 0 | AB13: =IF(Y13=100%,IF(OR(V13<>0,X13),X13-V13),0) -> -334657.85
B14: Agrimensura | D14: =IFERROR(VLOOKUP($B14&$C14,'C. Gestión Pto #1'!$B$4:C$11,MATCH(D$5,'C. Gestión Pto #1'!$B$4:C$4,0),FALSE),0) -> 110000 | E14: =IFERROR(VLOOKUP($B14&$C14,'C. Gestión Pto #1'!$B$4:D$11,MATCH(E$5,'C. Gestión Pto #1'!$B$4:D$4,0),FALSE),0) -> 0 | F14: =IFERROR(VLOOKUP($B14&$C14,'C. Gestión Pto #1'!$B$4:E$11,MATCH(F$5,'C. Gestión Pto #1'!$B$4:E$4,0),FALSE),0) -> 0 | G14: =IFERROR(VLOOKUP($B14&$C14,'C. Gestión Pto #1'!$B$4:F$11,MATCH(G$5,'C. Gestión Pto #1'!$B$4:F$4,0),FALSE),0) -> 0 | H14: =IFERROR(VLOOKUP($B14&$C14,'C. Gestión Pto #1'!$B$4:G$11,MATCH(H$5,'C. Gestión Pto #1'!$B$4:G$4,0),FALSE),0) -> 0 | I14: =IFERROR(VLOOKUP($B14&$C14,'C. Gestión Pto #1'!$B$4:H$11,MATCH(I$5,'C. Gestión Pto #1'!$B$4:H$4,0),FALSE),0) -> 0 | J14: =IFERROR(VLOOKUP($B14&$C14,'C. Gestión Pto #1'!$B$4:I$11,MATCH(J$5,'C. Gestión Pto #1'!$B$4:I$4,0),FALSE),0) -> 0 | K14: =IFERROR(VLOOKUP($B14&$C14,'C. Gestión Pto #1'!$B$4:J$11,MATCH(K$5,'C. Gestión Pto #1'!$B$4:J$4,0),FALSE),0) -> 0 | ... T14: =IFERROR(VLOOKUP($B14&$C14,'C. Gestión Pto #1'!$B$4:S$11,MATCH(T$5,'C. Gestión Pto #1'!$B$4:S$4,0),FALSE),0) -> 0 | V14: {=SUMPRODUCT($D14:$U14,TRANSPOSE('Indice CAC'!$D$2:$D$19))} -> 110000 | X14: =IF($C14="MAT",SUMIF('P. Costo'!$A$8:$A$58,$B14,'P. Costo'!$I$8:$I$58),IF($C14="MO",SUMIF('P. Costo'!$A$8:$A$58,$B14,'P. Costo'!$L$8:$L$58),SUMIF('P. Costo'!$A$8:$A$58,$B14,'P. Costo'!$N$8:$N$58))) -> 853792.28 | Y14: =IF($C14="MAT",SUMIF('Cert. Pto. 01'!$A$9:$A$45,'Resumen Pto #1'!$B14,'Cert. Pto. 01'!$T$9:$T$45),IF('Resumen Pto #1'!$C14="MO",SUMIF('Cert. Pto. 01'!$A$9:$A$45,'Resumen Pto #1'!$B14,'Cert. Pto. 01'!$U$9:$U$45),SUMIF('Cert. Pto. 01'!$A$9:$A$45,'Resumen Pto #1'!$B14,'Cert. Pto. 01'!$V$9:$V$45)))/IF($C14="MAT",SUMIF('Cert. Pto. 01'!$A$9:$A$45,'Resumen Pto #1'!$B14,'Cert. Pto. 01'!$I$9:$I$45),IF('Resumen Pto #1'!$C14="MO",SUMIF('Cert. Pto. 01'!$A$9:$A$45,'Resumen Pto #1'!$B14,'Cert. Pto. 01'!$J$9:$J$45),SUMIF('Cert. Pto. 01'!$A$9:$A$45,'Resumen Pto #1'!$B14,'Cert. Pto. 01'!$K$9:$K$45))) -> 1 | Z14: =IF(Y14=100%,0,IF(OR(V14<>0,X14),X14-V14)) -> 0 | AA14: =IF(OR(Z14<0,X14),Z14/X14,0%) -> 0 | AB14: =IF(Y14=100%,IF(OR(V14<>0,X14),X14-V14),0) -> 743792.28
B15: Excavación y Mov. de Suelos | D15: =IFERROR(VLOOKUP($B15&$C15,'C. Gestión Pto #1'!$B$4:C$11,MATCH(D$5,'C. Gestión Pto #1'!$B$4:C$4,0),FALSE),0) -> 0 | E15: =IFERROR(VLOOKUP($B15&$C15,'C. Gestión Pto #1'!$B$4:D$11,MATCH(E$5,'C. Gestión Pto #1'!$B$4:D$4,0),FALSE),0) -> 0 | F15: =IFERROR(VLOOKUP($B15&$C15,'C. Gestión Pto #1'!$B$4:E$11,MATCH(F$5,'C. Gestión Pto #1'!$B$4:E$4,0),FALSE),0) -> 0 | G15: =IFERROR(VLOOKUP($B15&$C15,'C. Gestión Pto #1'!$B$4:F$11,MATCH(G$5,'C. Gestión Pto #1'!$B$4:F$4,0),FALSE),0) -> 1580000 | H15: =IFERROR(VLOOKUP($B15&$C15,'C. Gestión Pto #1'!$B$4:G$11,MATCH(H$5,'C. Gestión Pto #1'!$B$4:G$4,0),FALSE),0) -> 1580000 | I15: =IFERROR(VLOOKUP($B15&$C15,'C. Gestión Pto #1'!$B$4:H$11,MATCH(I$5,'C. Gestión Pto #1'!$B$4:H$4,0),FALSE),0) -> 2974000 | J15: =IFERROR(VLOOKUP($B15&$C15,'C. Gestión Pto #1'!$B$4:I$11,MATCH(J$5,'C. Gestión Pto #1'!$B$4:I$4,0),FALSE),0) -> 3640000 | K15: =IFERROR(VLOOKUP($B15&$C15,'C. Gestión Pto #1'!$B$4:J$11,MATCH(K$5,'C. Gestión Pto #1'!$B$4:J$4,0),FALSE),0) -> 1416000 | ... T15: =IFERROR(VLOOKUP($B15&$C15,'C. Gestión Pto #1'!$B$4:S$11,MATCH(T$5,'C. Gestión Pto #1'!$B$4:S$4,0),FALSE),0) -> 0 | V15: {=SUMPRODUCT($D15:$U15,TRANSPOSE('Indice CAC'!$D$2:$D$19))} -> 10416172 | X15: =IF($C15="MAT",SUMIF('P. Costo'!$A$8:$A$58,$B15,'P. Costo'!$I$8:$I$58),IF($C15="MO",SUMIF('P. Costo'!$A$8:$A$58,$B15,'P. Costo'!$L$8:$L$58),SUMIF('P. Costo'!$A$8:$A$58,$B15,'P. Costo'!$N$8:$N$58))) -> 22068905 | Y15: =IF($C15="MAT",SUMIF('Cert. Pto. 01'!$A$9:$A$45,'Resumen Pto #1'!$B15,'Cert. Pto. 01'!$T$9:$T$45),IF('Resumen Pto #1'!$C15="MO",SUMIF('Cert. Pto. 01'!$A$9:$A$45,'Resumen Pto #1'!$B15,'Cert. Pto. 01'!$U$9:$U$45),SUMIF('Cert. Pto. 01'!$A$9:$A$45,'Resumen Pto #1'!$B15,'Cert. Pto. 01'!$V$9:$V$45)))/IF($C15="MAT",SUMIF('Cert. Pto. 01'!$A$9:$A$45,'Resumen Pto #1'!$B15,'Cert. Pto. 01'!$I$9:$I$45),IF('Resumen Pto #1'!$C15="MO",SUMIF('Cert. Pto. 01'!$A$9:$A$45,'Resumen Pto #1'!$B15,'Cert. Pto. 01'!$J$9:$J$45),SUMIF('Cert. Pto. 01'!$A$9:$A$45,'Resumen Pto #1'!$B15,'Cert. Pto. 01'!$K$9:$K$45))) -> 1 | Z15: =IF(Y15=100%,0,IF(OR(V15<>0,X15),X15-V15)) -> 0 | AA15: =IF(OR(Z15<0,X15),Z15/X15,0%) -> 0 | AB15: =IF(Y15=100%,IF(OR(V15<>0,X15),X15-V15),0) -> 11652732
B16: Hormigón | C16: MAT | D16: =IFERROR(VLOOKUP($B16&$C16,'C. Gestión Pto #1'!$B$4:C$11,MATCH(D$5,'C. Gestión Pto #1'!$B$4:C$4,0),FALSE),0) -> 0 | E16: =IFERROR(VLOOKUP($B16&$C16,'C. Gestión Pto #1'!$B$4:D$11,MATCH(E$5,'C. Gestión Pto #1'!$B$4:D$4,0),FALSE),0) -> 0 | F16: =IFERROR(VLOOKUP($B16&$C16,'C. Gestión Pto #1'!$B$4:E$11,MATCH(F$5,'C. Gestión Pto #1'!$B$4:E$4,0),FALSE),0) -> 1227898.4 | G16: =IFERROR(VLOOKUP($B16&$C16,'C. Gestión Pto #1'!$B$4:F$11,MATCH(G$5,'C. Gestión Pto #1'!$B$4:F$4,0),FALSE),0) -> 21854353 | H16: =IFERROR(VLOOKUP($B16&$C16,'C. Gestión Pto #1'!$B$4:G$11,MATCH(H$5,'C. Gestión Pto #1'!$B$4:G$4,0),FALSE),0) -> 64397545 | I16: =IFERROR(VLOOKUP($B16&$C16,'C. Gestión Pto #1'!$B$4:H$11,MATCH(I$5,'C. Gestión Pto #1'!$B$4:H$4,0),FALSE),0) -> 43287475 | J16: =IFERROR(VLOOKUP($B16&$C16,'C. Gestión Pto #1'!$B$4:I$11,MATCH(J$5,'C. Gestión Pto #1'!$B$4:I$4,0),FALSE),0) -> 1606135.8 | K16: =IFERROR(VLOOKUP($B16&$C16,'C. Gestión Pto #1'!$B$4:J$11,MATCH(K$5,'C. Gestión Pto #1'!$B$4:J$4,0),FALSE),0) -> 33701586 | ... T16: =IFERROR(VLOOKUP($B16&$C16,'C. Gestión Pto #1'!$B$4:S$11,MATCH(T$5,'C. Gestión Pto #1'!$B$4:S$4,0),FALSE),0) -> 0 | V16: {=SUMPRODUCT($D16:$U16,TRANSPOSE('Indice CAC'!$D$2:$D$19))} -> 1.8021717e+08 | X16: =IF($C16="MAT",SUMIF('P. Costo'!$A$8:$A$58,$B16,'P. Costo'!$I$8:$I$58),IF($C16="MO",SUMIF('P. Costo'!$A$8:$A$58,$B16,'P. Costo'!$L$8:$L$58),SUMIF('P. Costo'!$A$8:$A$58,$B16,'P. Costo'!$N$8:$N$58))) -> 1.8107277e+08 | Y16: =IF($C16="MAT",SUMIF('Cert. Pto. 01'!$A$9:$A$45,'Resumen Pto #1'!$B16,'Cert. Pto. 01'!$T$9:$T$45),IF('Resumen Pto #1'!$C16="MO",SUMIF('Cert. Pto. 01'!$A$9:$A$45,'Resumen Pto #1'!$B16,'Cert. Pto. 01'!$U$9:$U$45),SUMIF('Cert. Pto. 01'!$A$9:$A$45,'Resumen Pto #1'!$B16,'Cert. Pto. 01'!$V$9:$V$45)))/IF($C16="MAT",SUMIF('Cert. Pto. 01'!$A$9:$A$45,'Resumen Pto #1'!$B16,'Cert. Pto. 01'!$I$9:$I$45),IF('Resumen Pto #1'!$C16="MO",SUMIF('Cert. Pto. 01'!$A$9:$A$45,'Resumen Pto #1'!$B16,'Cert. Pto. 01'!$J$9:$J$45),SUMIF('Cert. Pto. 01'!$A$9:$A$45,'Resumen Pto #1'!$B16,'Cert. Pto. 01'!$K$9:$K$45))) -> 1 | Z16: =IF(Y16=100%,0,IF(OR(V16<>0,X16),X16-V16)) -> 0 | AA16: =IF(OR(Z16<0,X16),Z16/X16,0%) -> 0 | AB16: =IF(Y16=100%,IF(OR(V16<>0,X16),X16-V16),0) -> 855599.54
B17: Hormigón | C17: MO | D17: =IFERROR(VLOOKUP($B17&$C17,'C. Gestión Pto #1'!$B$4:C$11,MATCH(D$5,'C. Gestión Pto #1'!$B$4:C$4,0),FALSE),0) -> 0 | E17: =IFERROR(VLOOKUP($B17&$C17,'C. Gestión Pto #1'!$B$4:D$11,MATCH(E$5,'C. Gestión Pto #1'!$B$4:D$4,0),FALSE),0) -> 0 | F17: =IFERROR(VLOOKUP($B17&$C17,'C. Gestión Pto #1'!$B$4:E$11,MATCH(F$5,'C. Gestión Pto #1'!$B$4:E$4,0),FALSE),0) -> 2411850 | G17: =IFERROR(VLOOKUP($B17&$C17,'C. Gestión Pto #1'!$B$4:F$11,MATCH(G$5,'C. Gestión Pto #1'!$B$4:F$4,0),FALSE),0) -> 9206862.2 | H17: =IFERROR(VLOOKUP($B17&$C17,'C. Gestión Pto #1'!$B$4:G$11,MATCH(H$5,'C. Gestión Pto #1'!$B$4:G$4,0),FALSE),0) -> 10965040 | I17: =IFERROR(VLOOKUP($B17&$C17,'C. Gestión Pto #1'!$B$4:H$11,MATCH(I$5,'C. Gestión Pto #1'!$B$4:H$4,0),FALSE),0) -> 9710066.5 | J17: =IFERROR(VLOOKUP($B17&$C17,'C. Gestión Pto #1'!$B$4:I$11,MATCH(J$5,'C. Gestión Pto #1'!$B$4:I$4,0),FALSE),0) -> 8357133.4 | K17: =IFERROR(VLOOKUP($B17&$C17,'C. Gestión Pto #1'!$B$4:J$11,MATCH(K$5,'C. Gestión Pto #1'!$B$4:J$4,0),FALSE),0) -> 20959356 | ... T17: =IFERROR(VLOOKUP($B17&$C17,'C. Gestión Pto #1'!$B$4:S$11,MATCH(T$5,'C. Gestión Pto #1'!$B$4:S$4,0),FALSE),0) -> 0 | V17: {=SUMPRODUCT($D17:$U17,TRANSPOSE('Indice CAC'!$D$2:$D$19))} -> 1.0530015e+08 | X17: =IF($C17="MAT",SUMIF('P. Costo'!$A$8:$A$58,$B17,'P. Costo'!$I$8:$I$58),IF($C17="MO",SUMIF('P. Costo'!$A$8:$A$58,$B17,'P. Costo'!$L$8:$L$58),SUMIF('P. Costo'!$A$8:$A$58,$B17,'P. Costo'!$N$8:$N$58))) -> 1.4437802e+08 | Y17: =IF($C17="MAT",SUMIF('Cert. Pto. 01'!$A$9:$A$45,'Resumen Pto #1'!$B17,'Cert. Pto. 01'!$T$9:$T$45),IF('Resumen Pto #1'!$C17="MO",SUMIF('Cert. Pto. 01'!$A$9:$A$45,'Resumen Pto #1'!$B17,'Cert. Pto. 01'!$U$9:$U$45),SUMIF('Cert. Pto. 01'!$A$9:$A$45,'Resumen Pto #1'!$B17,'Cert. Pto. 01'!$V$9:$V$45)))/IF($C17="MAT",SUMIF('Cert. Pto. 01'!$A$9:$A$45,'Resumen Pto #1'!$B17,'Cert. Pto. 01'!$I$9:$I$45),IF('Resumen Pto #1'!$C17="MO",SUMIF('Cert. Pto. 01'!$A$9:$A$45,'Resumen Pto #1'!$B17,'Cert. Pto. 01'!$J$9:$J$45),SUMIF('Cert. Pto. 01'!$A$9:$A$45,'Resumen Pto #1'!$B17,'Cert. Pto. 01'!$K$9:$K$45))) -> 1 | Z17: =IF(Y17=100%,0,IF(OR(V17<>0,X17),X17-V17)) -> 0 | AA17: =IF(OR(Z17<0,X17),Z17/X17,0%) -> 0 | AB17: =IF(Y17=100%,IF(OR(V17<>0,X17),X17-V17),0) -> 39077870
B18: Equipos | D18: =IFERROR(VLOOKUP($B18&$C18,'C. Gestión Pto #1'!$B$4:C$11,MATCH(D$5,'C. Gestión Pto #1'!$B$4:C$4,0),FALSE),0) -> 58271.121 | E18: =IFERROR(VLOOKUP($B18&$C18,'C. Gestión Pto #1'!$B$4:D$11,MATCH(E$5,'C. Gestión Pto #1'!$B$4:D$4,0),FALSE),0) -> 59559.523 | F18: =IFERROR(VLOOKUP($B18&$C18,'C. Gestión Pto #1'!$B$4:E$11,MATCH(F$5,'C. Gestión Pto #1'!$B$4:E$4,0),FALSE),0) -> 64331.918 | G18: =IFERROR(VLOOKUP($B18&$C18,'C. Gestión Pto #1'!$B$4:F$11,MATCH(G$5,'C. Gestión Pto #1'!$B$4:F$4,0),FALSE),0) -> 287221.2 | H18: =IFERROR(VLOOKUP($B18&$C18,'C. Gestión Pto #1'!$B$4:G$11,MATCH(H$5,'C. Gestión Pto #1'!$B$4:G$4,0),FALSE),0) -> 290739.63 | I18: =IFERROR(VLOOKUP($B18&$C18,'C. Gestión Pto #1'!$B$4:H$11,MATCH(I$5,'C. Gestión Pto #1'!$B$4:H$4,0),FALSE),0) -> 296307.18 | J18: =IFERROR(VLOOKUP($B18&$C18,'C. Gestión Pto #1'!$B$4:I$11,MATCH(J$5,'C. Gestión Pto #1'!$B$4:I$4,0),FALSE),0) -> 346009.64 | K18: =IFERROR(VLOOKUP($B18&$C18,'C. Gestión Pto #1'!$B$4:J$11,MATCH(K$5,'C. Gestión Pto #1'!$B$4:J$4,0),FALSE),0) -> 799574.25 | ... T18: =IFERROR(VLOOKUP($B18&$C18,'C. Gestión Pto #1'!$B$4:S$11,MATCH(T$5,'C. Gestión Pto #1'!$B$4:S$4,0),FALSE),0) -> 0 | V18: {=SUMPRODUCT($D18:$U18,TRANSPOSE('Indice CAC'!$D$2:$D$19))} -> 3783726.2 | X18: =IF($C18="MAT",SUMIF('P. Costo'!$A$8:$A$58,$B18,'P. Costo'!$I$8:$I$58),IF($C18="MO",SUMIF('P. Costo'!$A$8:$A$58,$B18,'P. Costo'!$L$8:$L$58),SUM('P. Costo'!M59,-SUM('P. Costo'!M19:M27)))) -> 13604196 | Y18: ='Cert. Pto. 01'!S48 -> 1 | Z18: =IF(Y18=100%,0,IF(OR(V18<>0,X18),X18-V18)) -> 0 | AA18: =IF(OR(Z18<0,X18),Z18/X18,0%) -> 0 | AB18: =IF(Y18=100%,IF(OR(V18<>0,X18),X18-V18),0) -> 9820470.1
