Workbook
Name \0: #REF!
Name \c: #REF!
Name \E: #REF!
Name \i: #REF!
Name \j: #REF!
Name \m: #REF!
Name \P: #REF!
Name \P: #REF!
Name \P: #REF!
Name \P: #REF!
Name \P: #REF!
Name \P: #REF!
Name \P: #REF!
Name \P: #REF!
Name \P: #REF!
Name \P: #REF!
Name \P: #REF!
Name \P: #REF!
Name \P: #REF!
Name \P: #REF!
Name \P: #REF!
Name \P: #REF!
Name \r: #N/A
Name \x: #REF!
Name \z: #REF!
Name __________ben1: #REF!
Name __________ben1: #REF!
Name __________ben1: #REF!
Name __________ben1: #REF!
Name __________ben1: #REF!
Name __________ben1: #REF!
Name __________ben1: #REF!
Name __________ben1: #REF!
Name __________ben1: #REF!
Name __________ben1: #REF!
Name __________ben1: #REF!
Name __________ben1: #REF!
Name __________ben1: #REF!
Name __________ben1: #REF!
Name __________ben1: #REF!
Name __________ben1: #REF!
Name __________ben10: #REF!
Name __________ben10: #REF!
Name __________ben10: #REF!
Name __________ben10: #REF!
Name __________ben10: #REF!
Name __________ben10: #REF!
Name __________ben10: #REF!
Name __________ben10: #REF!
Name __________ben10: #REF!
Name __________ben10: #REF!
Name __________ben10: #REF!
Name __________ben10: #REF!
Name __________ben10: #REF!
Name __________ben10: #REF!
Name __________ben10: #REF!
Name __________ben10: #REF!
Name __________ben15: #REF!
Name __________ben15: #REF!
Name __________ben15: #REF!

Sheet GDR 3760_Pto. 02_Cert. 01
F1: DÓLAR BNA | G1: DÓLAR MEP
F2: 1066.5 | G2: 1170
F4: 45667
B5: OBRA: EDIFICIO GDR 3760 | I5: Certificado | J5: 1 | N5: 45747
B6: PRESUPUESTO OBRA CIVIL
B7: PRESUPUESTO 02 - ALBANILERIA, INSTALACIONES Y TERMINACIONES | I7: Avance | L7: Importe
B8: Descripción | C8: U | D8: Cant | E8: P unit | F8: Subtotal | I8: Anterior | J8: Actual | K8: Acumulado | L8: Anterior | M8: Actual | N8: Acumulado
A9: 4 | B9: MAMPOSTERÍA | G9: =+SUM(F10:F23) -> 51045774 | H9: =+G9/$G$195 -> 0.060420265
A10: 4.01 | B10: Muro tipo 1 - Ladrillo hueco 8 x 18 x 33 | C10: m2 | D10: 621 | E10: 22140 | F10: =+E10*D10 -> 13748940 | K10: =+I10+J10 -> 0 | L10: =+F10*I10 -> 0 | M10: =+F10*J10 -> 0 | N10: =+F10*K10 -> 0
A11: 4.02 | B11: Muro tipo 2 - Ladrillo hueco 12 x 18 x 33 | C11: m2 | D11: 780 | E11: 24437 | F11: =+E11*D11 -> 19060860 | K11: =+I11+J11 -> 0 | L11: =+F11*I11 -> 0 | M11: =+F11*J11 -> 0 | N11: =+F11*K11 -> 0
A12: 4.03 | B12: Muro tipo 3 - Ladrillo comun en panderete | C12: m2 | D12: 56 | E12: 23248 | F12: =+E12*D12 -> 1301888 | K12: =+I12+J12 -> 0 | L12: =+F12*I12 -> 0 | M12: =+F12*J12 -> 0 | N12: =+F12*K12 -> 0
A13: 4.04 | B13: Muro tipo 4 - Ladrillo hueco portante 12 x 18 x 33 | C13: m2 | D13: 42 | E13: 28746 | F13: =+E13*D13 -> 1207332 | K13: =+I13+J13 -> 0 | L13: =+F13*I13 -> 0 | M13: =+F13*J13 -> 0 | N13: =+F13*K13 -> 0
A14: 4.05 | B14: Muro tipo 5 - Bloque HCCA e: 7,5 cm | C14: m2 | D14: 70 | E14: 36933 | F14: =+E14*D14 -> 2585310 | K14: =+I14+J14 -> 0 | L14: =+F14*I14 -> 0 | M14: =+F14*J14 -> 0 | N14: =+F14*K14 -> 0
A15: 4.06 | B15: Muro tipo 6 - Ladrillo hueco 18 x 18 x 33 | C15: m2 | D15: 5 | E15: 28672 | F15: =+E15*D15 -> 143360 | K15: =+I15+J15 -> 0 | L15: =+F15*I15 -> 0 | M15: =+F15*J15 -> 0 | N15: =+F15*K15 -> 0
A16: 4.07 | B16: Enchape de medianeras existentes - Contemplamos picado zonas sueltas y enchape con ladrillo comun para PB | C16: m2 | D16: 193 | E16: 18611 | F16: =+E16*D16 -> 3591923 | K16: =+I16+J16 -> 0 | L16: =+F16*I16 -> 0 | M16: =+F16*J16 -> 0 | N16: =+F16*K16 -> 0
A17: 4.08 | B17: Cordón de hormigón en umbrales carpinterías | C17: ml | D17: 61 | E17: 28578 | F17: =+E17*D17 -> 1743258 | K17: =+I17+J17 -> 0 | L17: =+F17*I17 -> 0 | M17: =+F17*J17 -> 0 | N17: =+F17*K17 -> 0
A18: 4.09 | B18: Banquina Sala tanque de bombeo | C18: gl | D18: 1 | E18: 280823 | F18: =+E18*D18 -> 280823 | K18: =+I18+J18 -> 0 | L18: =+F18*I18 -> 0 | M18: =+F18*J18 -> 0 | N18: =+F18*K18 -> 0
A19: 4.1 | B19: Banquina en parrillas | C19: gl | D19: 1 | E19: 801214 | F19: =+E19*D19 -> 801214 | K19: =+I19+J19 -> 0 | L19: =+F19*I19 -> 0 | M19: =+F19*J19 -> 0 | N19: =+F19*K19 -> 0
A20: 4.11 | B20: Excavación y amurado con Hº tanque de recuperación de agua de lluvia | C20: gl | D20: 1 | E20: 525234 | F20: =+E20*D20 -> 525234 | K20: =+I20+J20 -> 0 | L20: =+F20*I20 -> 0 | M20: =+F20*J20 -> 0 | N20: =+F20*K20 -> 0
A21: 4.12 | B21: Provisión y amurado de tapas de inspección para tanque de reserva | C21: u | D21: 3 | E21: 237784 | F21: =+E21*D21 -> 713352 | K21: =+I21+J21 -> 0 | L21: =+F21*I21 -> 0 | M21: =+F21*J21 -> 0 | N21: =+F21*K21 -> 0
... A23: 4.14 | B23: Amurado de bañera | C23: u | D23: 8 | E23: 177655 | F23: =+E23*D23 -> 1421240 | K23: =+I23+J23 -> 0 | L23: =+F23*I23 -> 0 | M23: =+F23*J23 -> 0 | N23: =+F23*K23 -> 0
A24: 5 | B24: AISLACIONES | G24: =+SUM(F25:F31) -> 19239698 | H24: =+G24/$G$195 -> 0.022773044
A25: 5.01 | B25: Cajón hidrofugo | C25: ml | D25: 136 | E25: 6496 | F25: =+E25*D25 -> 883456 | K25: =+I25+J25 -> 0 | L25: =+F25*I25 -> 0 | M25: =+F25*J25 -> 0 | N25: =+F25*K25 -> 0
A26: 5.02 | B26: Aislación hidrófuga horizontal (baños) - Inc. membrana geotextil y 35% en concepto de babetas | C26: m2 | D26: 77 | E26: 33270 | F26: =+E26*D26 -> 2561790 | K26: =+I26+J26 -> 0 | L26: =+F26*I26 -> 0 | M26: =+F26*J26 -> 0 | N26: =+F26*K26 -> 0
A27: 5.03 | B27: Azotado hidrófugo - Contrapiso de PB | C27: m2 | D27: 107 | E27: 6496 | F27: =+E27*D27 -> 695072 | K27: =+I27+J27 -> 0 | L27: =+F27*I27 -> 0 | M27: =+F27*J27 -> 0 | N27: =+F27*K27 -> 0
A28: 5.04 | B28: Aislación térmica en terrazas, eps e:2,00 cm | C28: m2 | D28: 186 | E28: 4832 | F28: =+E28*D28 -> 898752 | K28: =+I28+J28 -> 0 | L28: =+F28*I28 -> 0 | M28: =+F28*J28 -> 0 | N28: =+F28*K28 -> 0
A29: 5.05 | B29: Barrera de vapor | C29: m2 | D29: 186 | E29: 4134 | F29: =+E29*D29 -> 768924 | K29: =+I29+J29 -> 0 | L29: =+F29*I29 -> 0 | M29: =+F29*J29 -> 0 | N29: =+F29*K29 -> 0
A30: 5.06 | B30: Membrana asfáltica geotextil 4mm - Balcones y azotea - Inc. 20% en concepto de babetas | C30: m2 | D30: 390 | E30: 28187 | F30: =+E30*D30 -> 10992930 | K30: =+I30+J30 -> 0 | L30: =+F30*I30 -> 0 | M30: =+F30*J30 -> 0 | N30: =+F30*K30 -> 0
A31: 5.07 | B31: Impermeabilización de tanque de reserva de HºAº | C31: gl | D31: 1 | E31: 2438774 | F31: =+E31*D31 -> 2438774 | K31: =+I31+J31 -> 0 | L31: =+F31*I31 -> 0 | M31: =+F31*J31 -> 0 | N31: =+F31*K31 -> 0
A32: 6 | B32: CUBIERTAS | G32: =+SUM(F33) -> 1722875 | H32: =+G32/$G$195 -> 0.0020392788
A33: 6.02 | B33: Babeta de chapa galvanizada en medianeras | C33: ml | D33: 55 | E33: 31325 | F33: =+E33*D33 -> 1722875 | K33: =+I33+J33 -> 0 | L33: =+F33*I33 -> 0 | M33: =+F33*J33 -> 0 | N33: =+F33*K33 -> 0
A34: 7 | B34: REVOQUES | G34: =+SUM(F35:F40) -> 92324467 | H34: =+G34/$G$195 -> 0.10927974
A35: 7.01 | B35: Revoque Grueso Impermeable Exterior | C35: m2 | D35: 879 | E35: 19943 | F35: =+E35*D35 -> 17529897 | K35: =+I35+J35 -> 0 | L35: =+F35*I35 -> 0 | M35: =+F35*J35 -> 0 | N35: =+F35*K35 -> 0
A36: 7.02 | B36: Revoque Grueso Impermeable Exterior a mas de 3m - Medianero y fachadas | C36: m2 | D36: 716 | E36: 26767 | F36: =+E36*D36 -> 19165172 | K36: =+I36+J36 -> 0 | L36: =+F36*I36 -> 0 | M36: =+F36*J36 -> 0 | N36: =+F36*K36 -> 0
A37: 7.03 | B37: Yeso interior | C37: m2 | D37: 1439 | E37: 22963 | F37: =+E37*D37 -> 33043757 | K37: =+I37+J37 -> 0 | L37: =+F37*I37 -> 0 | M37: =+F37*J37 -> 0 | N37: =+F37*K37 -> 0
A38: 7.04 | B38: Arista en yeso | C38: ml | D38: 347 | E38: 16909 | F38: =+E38*D38 -> 5867423 | K38: =+I38+J38 -> 0 | L38: =+F38*I38 -> 0 | M38: =+F38*J38 -> 0 | N38: =+F38*K38 -> 0
A39: 7.05 | B39: Provisión y colocación de guardacanto yesero | C39: un | D39: 132 | E39: 19384 | F39: =+E39*D39 -> 2558688 | K39: =+I39+J39 -> 0 | L39: =+F39*I39 -> 0 | M39: =+F39*J39 -> 0 | N39: =+F39*K39 -> 0
A40: 7.06 | B40: Revoque Grueso Impermeable Interior b/ revestimiento | C40: m2 | D40: 710 | E40: 19943 | F40: =+E40*D40 -> 14159530 | K40: =+I40+J40 -> 0 | L40: =+F40*I40 -> 0 | M40: =+F40*J40 -> 0 | N40: =+F40*K40 -> 0
A41: 8 | B41: CONTRAPISOS Y CARPETAS | G41: =+SUM(F42:F49) -> 49520833 | H41: =+G41/$G$195 -> 0.058615271
A42: 8.01 | B42: Contrapiso de Hº armado e: 18 cm, incluye malla Ø 6 mm y film 200 mic. | C42: m2 | D42: 107 | E42: 58580 | F42: =+E42*D42 -> 6268060 | K42: =+I42+J42 -> 0 | L42: =+F42*I42 -> 0 | M42: =+F42*J42 -> 0 | N42: =+F42*K42 -> 0
...

Sheet GDR 3760_Pto. 02_Cert. 02
F1: DÓLAR BNA | G1: DÓLAR MEP
F2: 1066.5 | G2: 1170
F4: 45667
B5: OBRA: EDIFICIO GDR 3760 | I5: Certificado | J5: 2 | N5: 45777
B6: PRESUPUESTO OBRA CIVIL
B7: PRESUPUESTO 02 - ALBANILERIA, INSTALACIONES Y TERMINACIONES | I7: Avance | L7: Importe
B8: Descripción | C8: U | D8: Cant | E8: P unit | F8: Subtotal | I8: Anterior | J8: Actual | K8: Acumulado | L8: Anterior | M8: Actual | N8: Acumulado
A9: 4 | B9: MAMPOSTERÍA | G9: =+SUM(F10:F23) -> 51045774 | H9: =+G9/$G$195 -> 0.060420265
A10: 4.01 | B10: Muro tipo 1 - Ladrillo hueco 8 x 18 x 33 | C10: m2 | D10: 621 | E10: 22140 | F10: =+E10*D10 -> 13748940 | I10: ='GDR 3760_Pto. 02_Cert. 01'!K10 -> 0 | K10: =+I10+J10 -> 0 | L10: =+F10*I10 -> 0 | M10: =+F10*J10 -> 0 | N10: =+F10*K10 -> 0
A11: 4.02 | B11: Muro tipo 2 - Ladrillo hueco 12 x 18 x 33 | C11: m2 | D11: 780 | E11: 24437 | F11: =+E11*D11 -> 19060860 | I11: ='GDR 3760_Pto. 02_Cert. 01'!K11 -> 0 | K11: =+I11+J11 -> 0 | L11: =+F11*I11 -> 0 | M11: =+F11*J11 -> 0 | N11: =+F11*K11 -> 0
A12: 4.03 | B12: Muro tipo 3 - Ladrillo comun en panderete | C12: m2 | D12: 56 | E12: 23248 | F12: =+E12*D12 -> 1301888 | I12: ='GDR 3760_Pto. 02_Cert. 01'!K12 -> 0 | K12: =+I12+J12 -> 0 | L12: =+F12*I12 -> 0 | M12: =+F12*J12 -> 0 | N12: =+F12*K12 -> 0
A13: 4.04 | B13: Muro tipo 4 - Ladrillo hueco portante 12 x 18 x 33 | C13: m2 | D13: 42 | E13: 28746 | F13: =+E13*D13 -> 1207332 | I13: ='GDR 3760_Pto. 02_Cert. 01'!K13 -> 0 | K13: =+I13+J13 -> 0 | L13: =+F13*I13 -> 0 | M13: =+F13*J13 -> 0 | N13: =+F13*K13 -> 0
A14: 4.05 | B14: Muro tipo 5 - Bloque HCCA e: 7,5 cm | C14: m2 | D14: 70 | E14: 36933 | F14: =+E14*D14 -> 2585310 | I14: ='GDR 3760_Pto. 02_Cert. 01'!K14 -> 0 | K14: =+I14+J14 -> 0 | L14: =+F14*I14 -> 0 | M14: =+F14*J14 -> 0 | N14: =+F14*K14 -> 0
A15: 4.06 | B15: Muro tipo 6 - Ladrillo hueco 18 x 18 x 33 | C15: m2 | D15: 5 | E15: 28672 | F15: =+E15*D15 -> 143360 | I15: ='GDR 3760_Pto. 02_Cert. 01'!K15 -> 0 | K15: =+I15+J15 -> 0 | L15: =+F15*I15 -> 0 | M15: =+F15*J15 -> 0 | N15: =+F15*K15 -> 0
A16: 4.07 | B16: Enchape de medianeras existentes - Contemplamos picado zonas sueltas y enchape con ladrillo comun para PB | C16: m2 | D16: 193 | E16: 18611 | F16: =+E16*D16 -> 3591923 | I16: ='GDR 3760_Pto. 02_Cert. 01'!K16 -> 0 | K16: =+I16+J16 -> 0 | L16: =+F16*I16 -> 0 | M16: =+F16*J16 -> 0 | N16: =+F16*K16 -> 0
A17: 4.08 | B17: Cordón de hormigón en umbrales carpinterías | C17: ml | D17: 61 | E17: 28578 | F17: =+E17*D17 -> 1743258 | I17: ='GDR 3760_Pto. 02_Cert. 01'!K17 -> 0 | K17: =+I17+J17 -> 0 | L17: =+F17*I17 -> 0 | M17: =+F17*J17 -> 0 | N17: =+F17*K17 -> 0
A18: 4.09 | B18: Banquina Sala tanque de bombeo | C18: gl | D18: 1 | E18: 280823 | F18: =+E18*D18 -> 280823 | I18: ='GDR 3760_Pto. 02_Cert. 01'!K18 -> 0 | K18: =+I18+J18 -> 0 | L18: =+F18*I18 -> 0 | M18: =+F18*J18 -> 0 | N18: =+F18*K18 -> 0
A19: 4.1 | B19: Banquina en parrillas | C19: gl | D19: 1 | E19: 801214 | F19: =+E19*D19 -> 801214 | I19: ='GDR 3760_Pto. 02_Cert. 01'!K19 -> 0 | K19: =+I19+J19 -> 0 | L19: =+F19*I19 -> 0 | M19: =+F19*J19 -> 0 | N19: =+F19*K19 -> 0
A20: 4.11 | B20: Excavación y amurado con Hº tanque de recuperación de agua de lluvia | C20: gl | D20: 1 | E20: 525234 | F20: =+E20*D20 -> 525234 | I20: ='GDR 3760_Pto. 02_Cert. 01'!K20 -> 0 | K20: =+I20+J20 -> 0 | L20: =+F20*I20 -> 0 | M20: =+F20*J20 -> 0 | N20: =+F20*K20 -> 0
A21: 4.12 | B21: Provisión y amurado de tapas de inspección para tanque de reserva | C21: u | D21: 3 | E21: 237784 | F21: =+E21*D21 -> 713352 | I21: ='GDR 3760_Pto. 02_Cert. 01'!K21 -> 0 | K21: =+I21+J21 -> 0 | L21: =+F21*I21 -> 0 | M21: =+F21*J21 -> 0 | N21: =+F21*K21 -> 0
... A23: 4.14 | B23: Amurado de bañera | C23: u | D23: 8 | E23: 177655 | F23: =+E23*D23 -> 1421240 | I23: ='GDR 3760_Pto. 02_Cert. 01'!K23 -> 0 | K23: =+I23+J23 -> 0 | L23: =+F23*I23 -> 0 | M23: =+F23*J23 -> 0 | N23: =+F23*K23 -> 0
A24: 5 | B24: AISLACIONES | G24: =+SUM(F25:F31) -> 19239698 | H24: =+G24/$G$195 -> 0.022773044
A25: 5.01 | B25: Cajón hidrofugo | C25: ml | D25: 136 | E25: 6496 | F25: =+E25*D25 -> 883456 | I25: ='GDR 3760_Pto. 02_Cert. 01'!K25 -> 0 | K25: =+I25+J25 -> 0 | L25: =+F25*I25 -> 0 | M25: =+F25*J25 -> 0 | N25: =+F25*K25 -> 0
A26: 5.02 | B26: Aislación hidrófuga horizontal (baños) - Inc. membrana geotextil y 35% en concepto de babetas | C26: m2 | D26: 77 | E26: 33270 | F26: =+E26*D26 -> 2561790 | I26: ='GDR 3760_Pto. 02_Cert. 01'!K26 -> 0 | K26: =+I26+J26 -> 0 | L26: =+F26*I26 -> 0 | M26: =+F26*J26 -> 0 | N26: =+F26*K26 -> 0
A27: 5.03 | B27: Azotado hidrófugo - Contrapiso de PB | C27: m2 | D27: 107 | E27: 6496 | F27: =+E27*D27 -> 695072 | I27: ='GDR 3760_Pto. 02_Cert. 01'!K27 -> 0 | K27: =+I27+J27 -> 0 | L27: =+F27*I27 -> 0 | M27: =+F27*J27 -> 0 | N27: =+F27*K27 -> 0
A28: 5.04 | B28: Aislación térmica en terrazas, eps e:2,00 cm | C28: m2 | D28: 186 | E28: 4832 | F28: =+E28*D28 -> 898752 | I28: ='GDR 3760_Pto. 02_Cert. 01'!K28 -> 0 | K28: =+I28+J28 -> 0 | L28: =+F28*I28 -> 0 | M28: =+F28*J28 -> 0 | N28: =+F28*K28 -> 0
A29: 5.05 | B29: Barrera de vapor | C29: m2 | D29: 186 | E29: 4134 | F29: =+E29*D29 -> 768924 | I29: ='GDR 3760_Pto. 02_Cert. 01'!K29 -> 0 | K29: =+I29+J29 -> 0 | L29: =+F29*I29 -> 0 | M29: =+F29*J29 -> 0 | N29: =+F29*K29 -> 0
A30: 5.06 | B30: Membrana asfáltica geotextil 4mm - Balcones y azotea - Inc. 20% en concepto de babetas | C30: m2 | D30: 390 | E30: 28187 | F30: =+E30*D30 -> 10992930 | I30: ='GDR 3760_Pto. 02_Cert. 01'!K30 -> 0 | K30: =+I30+J30 -> 0 | L30: =+F30*I30 -> 0 | M30: =+F30*J30 -> 0 | N30: =+F30*K30 -> 0
A31: 5.07 | B31: Impermeabilización de tanque de reserva de HºAº | C31: gl | D31: 1 | E31: 2438774 | F31: =+E31*D31 -> 2438774 | I31: ='GDR 3760_Pto. 02_Cert. 01'!K31 -> 0 | K31: =+I31+J31 -> 0 | L31: =+F31*I31 -> 0 | M31: =+F31*J31 -> 0 | N31: =+F31*K31 -> 0
A32: 6 | B32: CUBIERTAS | G32: =+SUM(F33) -> 1722875 | H32: =+G32/$G$195 -> 0.0020392788
A33: 6.02 | B33: Babeta de chapa galvanizada en medianeras | C33: ml | D33: 55 | E33: 31325 | F33: =+E33*D33 -> 1722875 | I33: ='GDR 3760_Pto. 02_Cert. 01'!K33 -> 0 | K33: =+I33+J33 -> 0 | L33: =+F33*I33 -> 0 | M33: =+F33*J33 -> 0 | N33: =+F33*K33 -> 0
A34: 7 | B34: REVOQUES | G34: =+SUM(F35:F40) -> 92324467 | H34: =+G34/$G$195 -> 0.10927974
A35: 7.01 | B35: Revoque Grueso Impermeable Exterior | C35: m2 | D35: 879 | E35: 19943 | F35: =+E35*D35 -> 17529897 | I35: ='GDR 3760_Pto. 02_Cert. 01'!K35 -> 0 | K35: =+I35+J35 -> 0 | L35: =+F35*I35 -> 0 | M35: =+F35*J35 -> 0 | N35: =+F35*K35 -> 0
A36: 7.02 | B36: Revoque Grueso Impermeable Exterior a mas de 3m - Medianero y fachadas | C36: m2 | D36: 716 | E36: 26767 | F36: =+E36*D36 -> 19165172 | I36: ='GDR 3760_Pto. 02_Cert. 01'!K36 -> 0 | K36: =+I36+J36 -> 0 | L36: =+F36*I36 -> 0 | M36: =+F36*J36 -> 0 | N36: =+F36*K36 -> 0
A37: 7.03 | B37: Yeso interior | C37: m2 | D37: 1439 | E37: 22963 | F37: =+E37*D37 -> 33043757 | I37: ='GDR 3760_Pto. 02_Cert. 01'!K37 -> 0 | K37: =+I37+J37 -> 0 | L37: =+F37*I37 -> 0 | M37: =+F37*J37 -> 0 | N37: =+F37*K37 -> 0
A38: 7.04 | B38: Arista en yeso | C38: ml | D38: 347 | E38: 16909 | F38: =+E38*D38 -> 5867423 | I38: ='GDR 3760_Pto. 02_Cert. 01'!K38 -> 0 | K38: =+I38+J38 -> 0 | L38: =+F38*I38 -> 0 | M38: =+F38*J38 -> 0 | N38: =+F38*K38 -> 0
A39: 7.05 | B39: Provisión y colocación de guardacanto yesero | C39: un | D39: 132 | E39: 19384 | F39: =+E39*D39 -> 2558688 | I39: ='GDR 3760_Pto. 02_Cert. 01'!K39 -> 0 | K39: =+I39+J39 -> 0 | L39: =+F39*I39 -> 0 | M39: =+F39*J39 -> 0 | N39: =+F39*K39 -> 0
A40: 7.06 | B40: Revoque Grueso Impermeable Interior b/ revestimiento | C40: m2 | D40: 710 | E40: 19943 | F40: =+E40*D40 -> 14159530 | I40: ='GDR 3760_Pto. 02_Cert. 01'!K40 -> 0 | K40: =+I40+J40 -> 0 | L40: =+F40*I40 -> 0 | M40: =+F40*J40 -> 0 | N40: =+F40*K40 -> 0
A41: 8 | B41: CONTRAPISOS Y CARPETAS | G41: =+SUM(F42:F49) -> 49520833 | H41: =+G41/$G$195 -> 0.058615271
A42: 8.01 | B42: Contrapiso de Hº armado e: 18 cm, incluye malla Ø 6 mm y film 200 mic. | C42: m2 | D42: 107 | E42: 58580 | F42: =+E42*D42 -> 6268060 | I42: ='GDR 3760_Pto. 02_Cert. 01'!K42 -> 0 | K42: =+I42+J42 -> 0 | L42: =+F42*I42 -> 0 | M42: =+F42*J42 -> 0 | N42: =+F42*K42 -> 0
...

Sheet GDR 3760_Pto. 02_Cert. 03
F1: DÓLAR BNA | G1: DÓLAR MEP
F2: 1066.5 | G2: 1170
F4: 45667
B5: OBRA: EDIFICIO GDR 3760 | I5: Certificado | J5: 3 | N5: 45808
B6: PRESUPUESTO OBRA CIVIL
B7: PRESUPUESTO 02 - ALBANILERIA, INSTALACIONES Y TERMINACIONES | I7: Avance | L7: Importe
B8: Descripción | C8: U | D8: Cant | E8: P unit | F8: Subtotal | I8: Anterior | J8: Actual | K8: Acumulado | L8: Anterior | M8: Actual | N8: Acumulado
A9: 4 | B9: MAMPOSTERÍA | G9: =+SUM(F10:F23) -> 51045774 | H9: =+G9/$G$195 -> 0.060420265
A10: 4.01 | B10: Muro tipo 1 - Ladrillo hueco 8 x 18 x 33 | C10: m2 | D10: 621 | E10: 22140 | F10: =+E10*D10 -> 13748940 | I10: 0 | K10: =+I10+J10 -> 0 | L10: =+F10*I10 -> 0 | M10: =+F10*J10 -> 0 | N10: =+F10*K10 -> 0
A11: 4.02 | B11: Muro tipo 2 - Ladrillo hueco 12 x 18 x 33 | C11: m2 | D11: 780 | E11: 24437 | F11: =+E11*D11 -> 19060860 | I11: 0 | K11: =+I11+J11 -> 0 | L11: =+F11*I11 -> 0 | M11: =+F11*J11 -> 0 | N11: =+F11*K11 -> 0
A12: 4.03 | B12: Muro tipo 3 - Ladrillo comun en panderete | C12: m2 | D12: 56 | E12: 23248 | F12: =+E12*D12 -> 1301888 | I12: 0 | K12: =+I12+J12 -> 0 | L12: =+F12*I12 -> 0 | M12: =+F12*J12 -> 0 | N12: =+F12*K12 -> 0
A13: 4.04 | B13: Muro tipo 4 - Ladrillo hueco portante 12 x 18 x 33 | C13: m2 | D13: 42 | E13: 28746 | F13: =+E13*D13 -> 1207332 | I13: 0 | K13: =+I13+J13 -> 0 | L13: =+F13*I13 -> 0 | M13: =+F13*J13 -> 0 | N13: =+F13*K13 -> 0
A14: 4.05 | B14: Muro tipo 5 - Bloque HCCA e: 7,5 cm | C14: m2 | D14: 70 | E14: 36933 | F14: =+E14*D14 -> 2585310 | I14: 0 | K14: =+I14+J14 -> 0 | L14: =+F14*I14 -> 0 | M14: =+F14*J14 -> 0 | N14: =+F14*K14 -> 0
A15: 4.06 | B15: Muro tipo 6 - Ladrillo hueco 18 x 18 x 33 | C15: m2 | D15: 5 | E15: 28672 | F15: =+E15*D15 -> 143360 | I15: 0 | K15: =+I15+J15 -> 0 | L15: =+F15*I15 -> 0 | M15: =+F15*J15 -> 0 | N15: =+F15*K15 -> 0
A16: 4.07 | B16: Enchape de medianeras existentes - Contemplamos picado zonas sueltas y enchape con ladrillo comun para PB | C16: m2 | D16: 193 | E16: 18611 | F16: =+E16*D16 -> 3591923 | I16: 0 | K16: =+I16+J16 -> 0 | L16: =+F16*I16 -> 0 | M16: =+F16*J16 -> 0 | N16: =+F16*K16 -> 0
A17: 4.08 | B17: Cordón de hormigón en umbrales carpinterías | C17: ml | D17: 61 | E17: 28578 | F17: =+E17*D17 -> 1743258 | I17: 0 | K17: =+I17+J17 -> 0 | L17: =+F17*I17 -> 0 | M17: =+F17*J17 -> 0 | N17: =+F17*K17 -> 0
A18: 4.09 | B18: Banquina Sala tanque de bombeo | C18: gl | D18: 1 | E18: 280823 | F18: =+E18*D18 -> 280823 | I18: 0 | K18: =+I18+J18 -> 0 | L18: =+F18*I18 -> 0 | M18: =+F18*J18 -> 0 | N18: =+F18*K18 -> 0
A19: 4.1 | B19: Banquina en parrillas | C19: gl | D19: 1 | E19: 801214 | F19: =+E19*D19 -> 801214 | I19: 0 | K19: =+I19+J19 -> 0 | L19: =+F19*I19 -> 0 | M19: =+F19*J19 -> 0 | N19: =+F19*K19 -> 0
A20: 4.11 | B20: Excavación y amurado con Hº tanque de recuperación de agua de lluvia | C20: gl | D20: 1 | E20: 525234 | F20: =+E20*D20 -> 525234 | I20: 0 | K20: =+I20+J20 -> 0 | L20: =+F20*I20 -> 0 | M20: =+F20*J20 -> 0 | N20: =+F20*K20 -> 0
A21: 4.12 | B21: Provisión y amurado de tapas de inspección para tanque de reserva | C21: u | D21: 3 | E21: 237784 | F21: =+E21*D21 -> 713352 | I21: 0 | K21: =+I21+J21 -> 0 | L21: =+F21*I21 -> 0 | M21: =+F21*J21 -> 0 | N21: =+F21*K21 -> 0
... A23: 4.14 | B23: Amurado de bañera | C23: u | D23: 8 | E23: 177655 | F23: =+E23*D23 -> 1421240 | I23: 0 | K23: =+I23+J23 -> 0 | L23: =+F23*I23 -> 0 | M23: =+F23*J23 -> 0 | N23: =+F23*K23 -> 0
A24: 5 | B24: AISLACIONES | G24: =+SUM(F25:F31) -> 19239698 | H24: =+G24/$G$195 -> 0.022773044
A25: 5.01 | B25: Cajón hidrofugo | C25: ml | D25: 136 | E25: 6496 | F25: =+E25*D25 -> 883456 | I25: 0 | K25: =+I25+J25 -> 0 | L25: =+F25*I25 -> 0 | M25: =+F25*J25 -> 0 | N25: =+F25*K25 -> 0
A26: 5.02 | B26: Aislación hidrófuga horizontal (baños) - Inc. membrana geotextil y 35% en concepto de babetas | C26: m2 | D26: 77 | E26: 33270 | F26: =+E26*D26 -> 2561790 | I26: 0 | K26: =+I26+J26 -> 0 | L26: =+F26*I26 -> 0 | M26: =+F26*J26 -> 0 | N26: =+F26*K26 -> 0
A27: 5.03 | B27: Azotado hidrófugo - Contrapiso de PB | C27: m2 | D27: 107 | E27: 6496 | F27: =+E27*D27 -> 695072 | I27: 0 | K27: =+I27+J27 -> 0 | L27: =+F27*I27 -> 0 | M27: =+F27*J27 -> 0 | N27: =+F27*K27 -> 0
A28: 5.04 | B28: Aislación térmica en terrazas, eps e:2,00 cm | C28: m2 | D28: 186 | E28: 4832 | F28: =+E28*D28 -> 898752 | I28: 0 | K28: =+I28+J28 -> 0 | L28: =+F28*I28 -> 0 | M28: =+F28*J28 -> 0 | N28: =+F28*K28 -> 0
A29: 5.05 | B29: Barrera de vapor | C29: m2 | D29: 186 | E29: 4134 | F29: =+E29*D29 -> 768924 | I29: 0 | K29: =+I29+J29 -> 0 | L29: =+F29*I29 -> 0 | M29: =+F29*J29 -> 0 | N29: =+F29*K29 -> 0
A30: 5.06 | B30: Membrana asfáltica geotextil 4mm - Balcones y azotea - Inc. 20% en concepto de babetas | C30: m2 | D30: 390 | E30: 28187 | F30: =+E30*D30 -> 10992930 | I30: 0 | K30: =+I30+J30 -> 0 | L30: =+F30*I30 -> 0 | M30: =+F30*J30 -> 0 | N30: =+F30*K30 -> 0
A31: 5.07 | B31: Impermeabilización de tanque de reserva de HºAº | C31: gl | D31: 1 | E31: 2438774 | F31: =+E31*D31 -> 2438774 | I31: 0 | K31: =+I31+J31 -> 0 | L31: =+F31*I31 -> 0 | M31: =+F31*J31 -> 0 | N31: =+F31*K31 -> 0
A32: 6 | B32: CUBIERTAS | G32: =+SUM(F33) -> 1722875 | H32: =+G32/$G$195 -> 0.0020392788
A33: 6.02 | B33: Babeta de chapa galvanizada en medianeras | C33: ml | D33: 55 | E33: 31325 | F33: =+E33*D33 -> 1722875 | I33: 0 | K33: =+I33+J33 -> 0 | L33: =+F33*I33 -> 0 | M33: =+F33*J33 -> 0 | N33: =+F33*K33 -> 0
A34: 7 | B34: REVOQUES | G34: =+SUM(F35:F40) -> 92324467 | H34: =+G34/$G$195 -> 0.10927974
A35: 7.01 | B35: Revoque Grueso Impermeable Exterior | C35: m2 | D35: 879 | E35: 19943 | F35: =+E35*D35 -> 17529897 | I35: 0 | K35: =+I35+J35 -> 0 | L35: =+F35*I35 -> 0 | M35: =+F35*J35 -> 0 | N35: =+F35*K35 -> 0
A36: 7.02 | B36: Revoque Grueso Impermeable Exterior a mas de 3m - Medianero y fachadas | C36: m2 | D36: 716 | E36: 26767 | F36: =+E36*D36 -> 19165172 | I36: 0 | K36: =+I36+J36 -> 0 | L36: =+F36*I36 -> 0 | M36: =+F36*J36 -> 0 | N36: =+F36*K36 -> 0
A37: 7.03 | B37: Yeso interior | C37: m2 | D37: 1439 | E37: 22963 | F37: =+E37*D37 -> 33043757 | I37: 0 | K37: =+I37+J37 -> 0 | L37: =+F37*I37 -> 0 | M37: =+F37*J37 -> 0 | N37: =+F37*K37 -> 0
A38: 7.04 | B38: Arista en yeso | C38: ml | D38: 347 | E38: 16909 | F38: =+E38*D38 -> 5867423 | I38: 0 | K38: =+I38+J38 -> 0 | L38: =+F38*I38 -> 0 | M38: =+F38*J38 -> 0 | N38: =+F38*K38 -> 0
A39: 7.05 | B39: Provisión y colocación de guardacanto yesero | C39: un | D39: 132 | E39: 19384 | F39: =+E39*D39 -> 2558688 | I39: 0 | K39: =+I39+J39 -> 0 | L39: =+F39*I39 -> 0 | M39: =+F39*J39 -> 0 | N39: =+F39*K39 -> 0
A40: 7.06 | B40: Revoque Grueso Impermeable Interior b/ revestimiento | C40: m2 | D40: 710 | E40: 19943 | F40: =+E40*D40 -> 14159530 | I40: 0 | K40: =+I40+J40 -> 0 | L40: =+F40*I40 -> 0 | M40: =+F40*J40 -> 0 | N40: =+F40*K40 -> 0
A41: 8 | B41: CONTRAPISOS Y CARPETAS | G41: =+SUM(F42:F49) -> 49520833 | H41: =+G41/$G$195 -> 0.058615271
A42: 8.01 | B42: Contrapiso de Hº armado e: 18 cm, incluye malla Ø 6 mm y film 200 mic. | C42: m2 | D42: 107 | E42: 58580 | F42: =+E42*D42 -> 6268060 | I42: 0 | K42: =+I42+J42 -> 0 | L42: =+F42*I42 -> 0 | M42: =+F42*J42 -> 0 | N42: =+F42*K42 -> 0
...

Sheet GDR 3760_Pto. 02_Cert. 04
F1: DÓLAR BNA | G1: DÓLAR MEP
F2: 1066.5 | G2: 1170
F4: 45667
B5: OBRA: EDIFICIO GDR 3760 | I5: Certificado | J5: 4 | N5: 45838
B6: PRESUPUESTO OBRA CIVIL
B7: PRESUPUESTO 02 - ALBANILERIA, INSTALACIONES Y TERMINACIONES | I7: Avance | L7: Importe
B8: Descripción | C8: U | D8: Cant | E8: P unit | F8: Subtotal | I8: Anterior | J8: Actual | K8: Acumulado | L8: Anterior | M8: Actual | N8: Acumulado
A9: 4 | B9: MAMPOSTERÍA | G9: =+SUM(F10:F23) -> 51045774 | H9: =+G9/$G$195 -> 0.060420265
A10: 4.01 | B10: Muro tipo 1 - Ladrillo hueco 8 x 18 x 33 | C10: m2 | D10: 621 | E10: 22140 | F10: =+E10*D10 -> 13748940 | I10: 0 | K10: =+I10+J10 -> 0 | L10: =+F10*I10 -> 0 | M10: =+F10*J10 -> 0 | N10: =+F10*K10 -> 0
A11: 4.02 | B11: Muro tipo 2 - Ladrillo hueco 12 x 18 x 33 | C11: m2 | D11: 780 | E11: 24437 | F11: =+E11*D11 -> 19060860 | I11: 0 | K11: =+I11+J11 -> 0 | L11: =+F11*I11 -> 0 | M11: =+F11*J11 -> 0 | N11: =+F11*K11 -> 0
A12: 4.03 | B12: Muro tipo 3 - Ladrillo comun en panderete | C12: m2 | D12: 56 | E12: 23248 | F12: =+E12*D12 -> 1301888 | I12: 0 | K12: =+I12+J12 -> 0 | L12: =+F12*I12 -> 0 | M12: =+F12*J12 -> 0 | N12: =+F12*K12 -> 0
A13: 4.04 | B13: Muro tipo 4 - Ladrillo hueco portante 12 x 18 x 33 | C13: m2 | D13: 42 | E13: 28746 | F13: =+E13*D13 -> 1207332 | I13: 0 | K13: =+I13+J13 -> 0 | L13: =+F13*I13 -> 0 | M13: =+F13*J13 -> 0 | N13: =+F13*K13 -> 0
A14: 4.05 | B14: Muro tipo 5 - Bloque HCCA e: 7,5 cm | C14: m2 | D14: 70 | E14: 36933 | F14: =+E14*D14 -> 2585310 | I14: 0 | K14: =+I14+J14 -> 0 | L14: =+F14*I14 -> 0 | M14: =+F14*J14 -> 0 | N14: =+F14*K14 -> 0
A15: 4.06 | B15: Muro tipo 6 - Ladrillo hueco 18 x 18 x 33 | C15: m2 | D15: 5 | E15: 28672 | F15: =+E15*D15 -> 143360 | I15: 0 | K15: =+I15+J15 -> 0 | L15: =+F15*I15 -> 0 | M15: =+F15*J15 -> 0 | N15: =+F15*K15 -> 0
A16: 4.07 | B16: Enchape de medianeras existentes - Contemplamos picado zonas sueltas y enchape con ladrillo comun para PB | C16: m2 | D16: 193 | E16: 18611 | F16: =+E16*D16 -> 3591923 | I16: 0 | K16: =+I16+J16 -> 0 | L16: =+F16*I16 -> 0 | M16: =+F16*J16 -> 0 | N16: =+F16*K16 -> 0
A17: 4.08 | B17: Cordón de hormigón en umbrales carpinterías | C17: ml | D17: 61 | E17: 28578 | F17: =+E17*D17 -> 1743258 | I17: 0 | K17: =+I17+J17 -> 0 | L17: =+F17*I17 -> 0 | M17: =+F17*J17 -> 0 | N17: =+F17*K17 -> 0
A18: 4.09 | B18: Banquina Sala tanque de bombeo | C18: gl | D18: 1 | E18: 280823 | F18: =+E18*D18 -> 280823 | I18: 0 | K18: =+I18+J18 -> 0 | L18: =+F18*I18 -> 0 | M18: =+F18*J18 -> 0 | N18: =+F18*K18 -> 0
A19: 4.1 | B19: Banquina en parrillas | C19: gl | D19: 1 | E19: 801214 | F19: =+E19*D19 -> 801214 | I19: 0 | K19: =+I19+J19 -> 0 | L19: =+F19*I19 -> 0 | M19: =+F19*J19 -> 0 | N19: =+F19*K19 -> 0
A20: 4.11 | B20: Excavación y amurado con Hº tanque de recuperación de agua de lluvia | C20: gl | D20: 1 | E20: 525234 | F20: =+E20*D20 -> 525234 | I20: 0 | K20: =+I20+J20 -> 0 | L20: =+F20*I20 -> 0 | M20: =+F20*J20 -> 0 | N20: =+F20*K20 -> 0
A21: 4.12 | B21: Provisión y amurado de tapas de inspección para tanque de reserva | C21: u | D21: 3 | E21: 237784 | F21: =+E21*D21 -> 713352 | I21: 0 | K21: =+I21+J21 -> 0 | L21: =+F21*I21 -> 0 | M21: =+F21*J21 -> 0 | N21: =+F21*K21 -> 0
... A23: 4.14 | B23: Amurado de bañera | C23: u | D23: 8 | E23: 177655 | F23: =+E23*D23 -> 1421240 | I23: 0 | K23: =+I23+J23 -> 0 | L23: =+F23*I23 -> 0 | M23: =+F23*J23 -> 0 | N23: =+F23*K23 -> 0
A24: 5 | B24: AISLACIONES | G24: =+SUM(F25:F31) -> 19239698 | H24: =+G24/$G$195 -> 0.022773044
A25: 5.01 | B25: Cajón hidrofugo | C25: ml | D25: 136 | E25: 6496 | F25: =+E25*D25 -> 883456 | I25: 0 | K25: =+I25+J25 -> 0 | L25: =+F25*I25 -> 0 | M25: =+F25*J25 -> 0 | N25: =+F25*K25 -> 0
A26: 5.02 | B26: Aislación hidrófuga horizontal (baños) - Inc. membrana geotextil y 35% en concepto de babetas | C26: m2 | D26: 77 | E26: 33270 | F26: =+E26*D26 -> 2561790 | I26: 0 | K26: =+I26+J26 -> 0 | L26: =+F26*I26 -> 0 | M26: =+F26*J26 -> 0 | N26: =+F26*K26 -> 0
A27: 5.03 | B27: Azotado hidrófugo - Contrapiso de PB | C27: m2 | D27: 107 | E27: 6496 | F27: =+E27*D27 -> 695072 | I27: 0 | K27: =+I27+J27 -> 0 | L27: =+F27*I27 -> 0 | M27: =+F27*J27 -> 0 | N27: =+F27*K27 -> 0
A28: 5.04 | B28: Aislación térmica en terrazas, eps e:2,00 cm | C28: m2 | D28: 186 | E28: 4832 | F28: =+E28*D28 -> 898752 | I28: 0 | K28: =+I28+J28 -> 0 | L28: =+F28*I28 -> 0 | M28: =+F28*J28 -> 0 | N28: =+F28*K28 -> 0
A29: 5.05 | B29: Barrera de vapor | C29: m2 | D29: 186 | E29: 4134 | F29: =+E29*D29 -> 768924 | I29: 0 | K29: =+I29+J29 -> 0 | L29: =+F29*I29 -> 0 | M29: =+F29*J29 -> 0 | N29: =+F29*K29 -> 0
A30: 5.06 | B30: Membrana asfáltica geotextil 4mm - Balcones y azotea - Inc. 20% en concepto de babetas | C30: m2 | D30: 390 | E30: 28187 | F30: =+E30*D30 -> 10992930 | I30: 0 | K30: =+I30+J30 -> 0 | L30: =+F30*I30 -> 0 | M30: =+F30*J30 -> 0 | N30: =+F30*K30 -> 0
A31: 5.07 | B31: Impermeabilización de tanque de reserva de HºAº | C31: gl | D31: 1 | E31: 2438774 | F31: =+E31*D31 -> 2438774 | I31: 0 | K31: =+I31+J31 -> 0 | L31: =+F31*I31 -> 0 | M31: =+F31*J31 -> 0 | N31: =+F31*K31 -> 0
A32: 6 | B32: CUBIERTAS | G32: =+SUM(F33) -> 1722875 | H32: =+G32/$G$195 -> 0.0020392788
A33: 6.02 | B33: Babeta de chapa galvanizada en medianeras | C33: ml | D33: 55 | E33: 31325 | F33: =+E33*D33 -> 1722875 | I33: 0 | K33: =+I33+J33 -> 0 | L33: =+F33*I33 -> 0 | M33: =+F33*J33 -> 0 | N33: =+F33*K33 -> 0
A34: 7 | B34: REVOQUES | G34: =+SUM(F35:F40) -> 92324467 | H34: =+G34/$G$195 -> 0.10927974
A35: 7.01 | B35: Revoque Grueso Impermeable Exterior | C35: m2 | D35: 879 | E35: 19943 | F35: =+E35*D35 -> 17529897 | I35: 0 | K35: =+I35+J35 -> 0 | L35: =+F35*I35 -> 0 | M35: =+F35*J35 -> 0 | N35: =+F35*K35 -> 0
A36: 7.02 | B36: Revoque Grueso Impermeable Exterior a mas de 3m - Medianero y fachadas | C36: m2 | D36: 716 | E36: 26767 | F36: =+E36*D36 -> 19165172 | I36: 0 | K36: =+I36+J36 -> 0 | L36: =+F36*I36 -> 0 | M36: =+F36*J36 -> 0 | N36: =+F36*K36 -> 0
A37: 7.03 | B37: Yeso interior | C37: m2 | D37: 1439 | E37: 22963 | F37: =+E37*D37 -> 33043757 | I37: 0 | K37: =+I37+J37 -> 0 | L37: =+F37*I37 -> 0 | M37: =+F37*J37 -> 0 | N37: =+F37*K37 -> 0
A38: 7.04 | B38: Arista en yeso | C38: ml | D38: 347 | E38: 16909 | F38: =+E38*D38 -> 5867423 | I38: 0 | K38: =+I38+J38 -> 0 | L38: =+F38*I38 -> 0 | M38: =+F38*J38 -> 0 | N38: =+F38*K38 -> 0
A39: 7.05 | B39: Provisión y colocación de guardacanto yesero | C39: un | D39: 132 | E39: 19384 | F39: =+E39*D39 -> 2558688 | I39: 0 | K39: =+I39+J39 -> 0 | L39: =+F39*I39 -> 0 | M39: =+F39*J39 -> 0 | N39: =+F39*K39 -> 0
A40: 7.06 | B40: Revoque Grueso Impermeable Interior b/ revestimiento | C40: m2 | D40: 710 | E40: 19943 | F40: =+E40*D40 -> 14159530 | I40: 0 | K40: =+I40+J40 -> 0 | L40: =+F40*I40 -> 0 | M40: =+F40*J40 -> 0 | N40: =+F40*K40 -> 0
A41: 8 | B41: CONTRAPISOS Y CARPETAS | G41: =+SUM(F42:F49) -> 49520833 | H41: =+G41/$G$195 -> 0.058615271
A42: 8.01 | B42: Contrapiso de Hº armado e: 18 cm, incluye malla Ø 6 mm y film 200 mic. | C42: m2 | D42: 107 | E42: 58580 | F42: =+E42*D42 -> 6268060 | I42: 0 | K42: =+I42+J42 -> 0 | L42: =+F42*I42 -> 0 | M42: =+F42*J42 -> 0 | N42: =+F42*K42 -> 0
...

Sheet GDR 3760_Pto. 02_Cert. 05
F1: DÓLAR BNA | G1: DÓLAR MEP
F2: 1066.5 | G2: 1170
F4: 45667
B5: OBRA: EDIFICIO GDR 3760 | I5: Certificado | J5: 5 | N5: 45869
B6: PRESUPUESTO OBRA CIVIL
B7: PRESUPUESTO 02 - ALBANILERIA, INSTALACIONES Y TERMINACIONES | I7: Avance | L7: Importe
B8: Descripción | C8: U | D8: Cant | E8: P unit | F8: Subtotal | I8: Anterior | J8: Actual | K8: Acumulado | L8: Anterior | M8: Actual | N8: Acumulado
A9: 4 | B9: MAMPOSTERÍA | G9: =+SUM(F10:F23) -> 51045774 | H9: =+G9/$G$195 -> 0.060420265
A10: 4.01 | B10: Muro tipo 1 - Ladrillo hueco 8 x 18 x 33 | C10: m2 | D10: 621 | E10: 22140 | F10: =+E10*D10 -> 13748940 | I10: 0 | K10: =+I10+J10 -> 0 | L10: =+F10*I10 -> 0 | M10: =+F10*J10 -> 0 | N10: =+F10*K10 -> 0
A11: 4.02 | B11: Muro tipo 2 - Ladrillo hueco 12 x 18 x 33 | C11: m2 | D11: 780 | E11: 24437 | F11: =+E11*D11 -> 19060860 | I11: 0 | K11: =+I11+J11 -> 0 | L11: =+F11*I11 -> 0 | M11: =+F11*J11 -> 0 | N11: =+F11*K11 -> 0
A12: 4.03 | B12: Muro tipo 3 - Ladrillo comun en panderete | C12: m2 | D12: 56 | E12: 23248 | F12: =+E12*D12 -> 1301888 | I12: 0 | K12: =+I12+J12 -> 0 | L12: =+F12*I12 -> 0 | M12: =+F12*J12 -> 0 | N12: =+F12*K12 -> 0
A13: 4.04 | B13: Muro tipo 4 - Ladrillo hueco portante 12 x 18 x 33 | C13: m2 | D13: 42 | E13: 28746 | F13: =+E13*D13 -> 1207332 | I13: 0 | K13: =+I13+J13 -> 0 | L13: =+F13*I13 -> 0 | M13: =+F13*J13 -> 0 | N13: =+F13*K13 -> 0
A14: 4.05 | B14: Muro tipo 5 - Bloque HCCA e: 7,5 cm | C14: m2 | D14: 70 | E14: 36933 | F14: =+E14*D14 -> 2585310 | I14: 0 | K14: =+I14+J14 -> 0 | L14: =+F14*I14 -> 0 | M14: =+F14*J14 -> 0 | N14: =+F14*K14 -> 0
A15: 4.06 | B15: Muro tipo 6 - Ladrillo hueco 18 x 18 x 33 | C15: m2 | D15: 5 | E15: 28672 | F15: =+E15*D15 -> 143360 | I15: 0 | K15: =+I15+J15 -> 0 | L15: =+F15*I15 -> 0 | M15: =+F15*J15 -> 0 | N15: =+F15*K15 -> 0
A16: 4.07 | B16: Enchape de medianeras existentes - Contemplamos picado zonas sueltas y enchape con ladrillo comun para PB | C16: m2 | D16: 193 | E16: 18611 | F16: =+E16*D16 -> 3591923 | I16: 0 | K16: =+I16+J16 -> 0 | L16: =+F16*I16 -> 0 | M16: =+F16*J16 -> 0 | N16: =+F16*K16 -> 0
A17: 4.08 | B17: Cordón de hormigón en umbrales carpinterías | C17: ml | D17: 61 | E17: 28578 | F17: =+E17*D17 -> 1743258 | I17: 0 | K17: =+I17+J17 -> 0 | L17: =+F17*I17 -> 0 | M17: =+F17*J17 -> 0 | N17: =+F17*K17 -> 0
A18: 4.09 | B18: Banquina Sala tanque de bombeo | C18: gl | D18: 1 | E18: 280823 | F18: =+E18*D18 -> 280823 | I18: 0 | K18: =+I18+J18 -> 0 | L18: =+F18*I18 -> 0 | M18: =+F18*J18 -> 0 | N18: =+F18*K18 -> 0
A19: 4.1 | B19: Banquina en parrillas | C19: gl | D19: 1 | E19: 801214 | F19: =+E19*D19 -> 801214 | I19: 0 | K19: =+I19+J19 -> 0 | L19: =+F19*I19 -> 0 | M19: =+F19*J19 -> 0 | N19: =+F19*K19 -> 0
A20: 4.11 | B20: Excavación y amurado con Hº tanque de recuperación de agua de lluvia | C20: gl | D20: 1 | E20: 525234 | F20: =+E20*D20 -> 525234 | I20: 0 | K20: =+I20+J20 -> 0 | L20: =+F20*I20 -> 0 | M20: =+F20*J20 -> 0 | N20: =+F20*K20 -> 0
A21: 4.12 | B21: Provisión y amurado de tapas de inspección para tanque de reserva | C21: u | D21: 3 | E21: 237784 | F21: =+E21*D21 -> 713352 | I21: 0 | K21: =+I21+J21 -> 0 | L21: =+F21*I21 -> 0 | M21: =+F21*J21 -> 0 | N21: =+F21*K21 -> 0
... A23: 4.14 | B23: Amurado de bañera | C23: u | D23: 8 | E23: 177655 | F23: =+E23*D23 -> 1421240 | I23: 0 | K23: =+I23+J23 -> 0 | L23: =+F23*I23 -> 0 | M23: =+F23*J23 -> 0 | N23: =+F23*K23 -> 0
A24: 5 | B24: AISLACIONES | G24: =+SUM(F25:F31) -> 19239698 | H24: =+G24/$G$195 -> 0.022773044
A25: 5.01 | B25: Cajón hidrofugo | C25: ml | D25: 136 | E25: 6496 | F25: =+E25*D25 -> 883456 | I25: 0 | K25: =+I25+J25 -> 0 | L25: =+F25*I25 -> 0 | M25: =+F25*J25 -> 0 | N25: =+F25*K25 -> 0
A26: 5.02 | B26: Aislación hidrófuga horizontal (baños) - Inc. membrana geotextil y 35% en concepto de babetas | C26: m2 | D26: 77 | E26: 33270 | F26: =+E26*D26 -> 2561790 | I26: 0 | K26: =+I26+J26 -> 0 | L26: =+F26*I26 -> 0 | M26: =+F26*J26 -> 0 | N26: =+F26*K26 -> 0
A27: 5.03 | B27: Azotado hidrófugo - Contrapiso de PB | C27: m2 | D27: 107 | E27: 6496 | F27: =+E27*D27 -> 695072 | I27: 0 | K27: =+I27+J27 -> 0 | L27: =+F27*I27 -> 0 | M27: =+F27*J27 -> 0 | N27: =+F27*K27 -> 0
A28: 5.04 | B28: Aislación térmica en terrazas, eps e:2,00 cm | C28: m2 | D28: 186 | E28: 4832 | F28: =+E28*D28 -> 898752 | I28: 0 | K28: =+I28+J28 -> 0 | L28: =+F28*I28 -> 0 | M28: =+F28*J28 -> 0 | N28: =+F28*K28 -> 0
A29: 5.05 | B29: Barrera de vapor | C29: m2 | D29: 186 | E29: 4134 | F29: =+E29*D29 -> 768924 | I29: 0 | K29: =+I29+J29 -> 0 | L29: =+F29*I29 -> 0 | M29: =+F29*J29 -> 0 | N29: =+F29*K29 -> 0
A30: 5.06 | B30: Membrana asfáltica geotextil 4mm - Balcones y azotea - Inc. 20% en concepto de babetas | C30: m2 | D30: 390 | E30: 28187 | F30: =+E30*D30 -> 10992930 | I30: 0 | K30: =+I30+J30 -> 0 | L30: =+F30*I30 -> 0 | M30: =+F30*J30 -> 0 | N30: =+F30*K30 -> 0
A31: 5.07 | B31: Impermeabilización de tanque de reserva de HºAº | C31: gl | D31: 1 | E31: 2438774 | F31: =+E31*D31 -> 2438774 | I31: 0 | K31: =+I31+J31 -> 0 | L31: =+F31*I31 -> 0 | M31: =+F31*J31 -> 0 | N31: =+F31*K31 -> 0
A32: 6 | B32: CUBIERTAS | G32: =+SUM(F33) -> 1722875 | H32: =+G32/$G$195 -> 0.0020392788
A33: 6.02 | B33: Babeta de chapa galvanizada en medianeras | C33: ml | D33: 55 | E33: 31325 | F33: =+E33*D33 -> 1722875 | I33: 0 | K33: =+I33+J33 -> 0 | L33: =+F33*I33 -> 0 | M33: =+F33*J33 -> 0 | N33: =+F33*K33 -> 0
A34: 7 | B34: REVOQUES | G34: =+SUM(F35:F40) -> 92324467 | H34: =+G34/$G$195 -> 0.10927974
A35: 7.01 | B35: Revoque Grueso Impermeable Exterior | C35: m2 | D35: 879 | E35: 19943 | F35: =+E35*D35 -> 17529897 | I35: 0 | K35: =+I35+J35 -> 0 | L35: =+F35*I35 -> 0 | M35: =+F35*J35 -> 0 | N35: =+F35*K35 -> 0
A36: 7.02 | B36: Revoque Grueso Impermeable Exterior a mas de 3m - Medianero y fachadas | C36: m2 | D36: 716 | E36: 26767 | F36: =+E36*D36 -> 19165172 | I36: 0 | K36: =+I36+J36 -> 0 | L36: =+F36*I36 -> 0 | M36: =+F36*J36 -> 0 | N36: =+F36*K36 -> 0
A37: 7.03 | B37: Yeso interior | C37: m2 | D37: 1439 | E37: 22963 | F37: =+E37*D37 -> 33043757 | I37: 0 | K37: =+I37+J37 -> 0 | L37: =+F37*I37 -> 0 | M37: =+F37*J37 -> 0 | N37: =+F37*K37 -> 0
A38: 7.04 | B38: Arista en yeso | C38: ml | D38: 347 | E38: 16909 | F38: =+E38*D38 -> 5867423 | I38: 0 | K38: =+I38+J38 -> 0 | L38: =+F38*I38 -> 0 | M38: =+F38*J38 -> 0 | N38: =+F38*K38 -> 0
A39: 7.05 | B39: Provisión y colocación de guardacanto yesero | C39: un | D39: 132 | E39: 19384 | F39: =+E39*D39 -> 2558688 | I39: 0 | K39: =+I39+J39 -> 0 | L39: =+F39*I39 -> 0 | M39: =+F39*J39 -> 0 | N39: =+F39*K39 -> 0
A40: 7.06 | B40: Revoque Grueso Impermeable Interior b/ revestimiento | C40: m2 | D40: 710 | E40: 19943 | F40: =+E40*D40 -> 14159530 | I40: 0 | K40: =+I40+J40 -> 0 | L40: =+F40*I40 -> 0 | M40: =+F40*J40 -> 0 | N40: =+F40*K40 -> 0
A41: 8 | B41: CONTRAPISOS Y CARPETAS | G41: =+SUM(F42:F49) -> 49520833 | H41: =+G41/$G$195 -> 0.058615271
A42: 8.01 | B42: Contrapiso de Hº armado e: 18 cm, incluye malla Ø 6 mm y film 200 mic. | C42: m2 | D42: 107 | E42: 58580 | F42: =+E42*D42 -> 6268060 | I42: 0 | K42: =+I42+J42 -> 0 | L42: =+F42*I42 -> 0 | M42: =+F42*J42 -> 0 | N42: =+F42*K42 -> 0
...

Sheet GDR 3760_Pto. 02_Cert. 06
F1: DÓLAR BNA | G1: DÓLAR MEP
F2: 1066.5 | G2: 1170
F4: 45667
B5: OBRA: EDIFICIO GDR 3760 | I5: Certificado | J5: 6 | N5: 45900
B6: PRESUPUESTO OBRA CIVIL
B7: PRESUPUESTO 02 - ALBANILERIA, INSTALACIONES Y TERMINACIONES | I7: Avance | L7: Importe
B8: Descripción | C8: U | D8: Cant | E8: P unit | F8: Subtotal | I8: Anterior | J8: Actual | K8: Acumulado | L8: Anterior | M8: Actual | N8: Acumulado
A9: 4 | B9: MAMPOSTERÍA | G9: =+SUM(F10:F23) -> 51045774 | H9: =+G9/$G$195 -> 0.060420265
A10: 4.01 | B10: Muro tipo 1 - Ladrillo hueco 8 x 18 x 33 | C10: m2 | D10: 621 | E10: 22140 | F10: =+E10*D10 -> 13748940 | I10: 0 | K10: =+I10+J10 -> 0 | L10: =+F10*I10 -> 0 | M10: =+F10*J10 -> 0 | N10: =+F10*K10 -> 0
A11: 4.02 | B11: Muro tipo 2 - Ladrillo hueco 12 x 18 x 33 | C11: m2 | D11: 780 | E11: 24437 | F11: =+E11*D11 -> 19060860 | I11: 0 | K11: =+I11+J11 -> 0 | L11: =+F11*I11 -> 0 | M11: =+F11*J11 -> 0 | N11: =+F11*K11 -> 0
A12: 4.03 | B12: Muro tipo 3 - Ladrillo comun en panderete | C12: m2 | D12: 56 | E12: 23248 | F12: =+E12*D12 -> 1301888 | I12: 0 | K12: =+I12+J12 -> 0 | L12: =+F12*I12 -> 0 | M12: =+F12*J12 -> 0 | N12: =+F12*K12 -> 0
A13: 4.04 | B13: Muro tipo 4 - Ladrillo hueco portante 12 x 18 x 33 | C13: m2 | D13: 42 | E13: 28746 | F13: =+E13*D13 -> 1207332 | I13: 0 | K13: =+I13+J13 -> 0 | L13: =+F13*I13 -> 0 | M13: =+F13*J13 -> 0 | N13: =+F13*K13 -> 0
A14: 4.05 | B14: Muro tipo 5 - Bloque HCCA e: 7,5 cm | C14: m2 | D14: 70 | E14: 36933 | F14: =+E14*D14 -> 2585310 | I14: 0 | K14: =+I14+J14 -> 0 | L14: =+F14*I14 -> 0 | M14: =+F14*J14 -> 0 | N14: =+F14*K14 -> 0
A15: 4.06 | B15: Muro tipo 6 - Ladrillo hueco 18 x 18 x 33 | C15: m2 | D15: 5 | E15: 28672 | F15: =+E15*D15 -> 143360 | I15: 0 | K15: =+I15+J15 -> 0 | L15: =+F15*I15 -> 0 | M15: =+F15*J15 -> 0 | N15: =+F15*K15 -> 0
A16: 4.07 | B16: Enchape de medianeras existentes - Contemplamos picado zonas sueltas y enchape con ladrillo comun para PB | C16: m2 | D16: 193 | E16: 18611 | F16: =+E16*D16 -> 3591923 | I16: 0 | K16: =+I16+J16 -> 0 | L16: =+F16*I16 -> 0 | M16: =+F16*J16 -> 0 | N16: =+F16*K16 -> 0
A17: 4.08 | B17: Cordón de hormigón en umbrales carpinterías | C17: ml | D17: 61 | E17: 28578 | F17: =+E17*D17 -> 1743258 | I17: 0 | K17: =+I17+J17 -> 0 | L17: =+F17*I17 -> 0 | M17: =+F17*J17 -> 0 | N17: =+F17*K17 -> 0
A18: 4.09 | B18: Banquina Sala tanque de bombeo | C18: gl | D18: 1 | E18: 280823 | F18: =+E18*D18 -> 280823 | I18: 0 | K18: =+I18+J18 -> 0 | L18: =+F18*I18 -> 0 | M18: =+F18*J18 -> 0 | N18: =+F18*K18 -> 0
A19: 4.1 | B19: Banquina en parrillas | C19: gl | D19: 1 | E19: 801214 | F19: =+E19*D19 -> 801214 | I19: 0 | K19: =+I19+J19 -> 0 | L19: =+F19*I19 -> 0 | M19: =+F19*J19 -> 0 | N19: =+F19*K19 -> 0
A20: 4.11 | B20: Excavación y amurado con Hº tanque de recuperación de agua de lluvia | C20: gl | D20: 1 | E20: 525234 | F20: =+E20*D20 -> 525234 | I20: 0 | K20: =+I20+J20 -> 0 | L20: =+F20*I20 -> 0 | M20: =+F20*J20 -> 0 | N20: =+F20*K20 -> 0
A21: 4.12 | B21: Provisión y amurado de tapas de inspección para tanque de reserva | C21: u | D21: 3 | E21: 237784 | F21: =+E21*D21 -> 713352 | I21: 0 | K21: =+I21+J21 -> 0 | L21: =+F21*I21 -> 0 | M21: =+F21*J21 -> 0 | N21: =+F21*K21 -> 0
... A23: 4.14 | B23: Amurado de bañera | C23: u | D23: 8 | E23: 177655 | F23: =+E23*D23 -> 1421240 | I23: 0 | K23: =+I23+J23 -> 0 | L23: =+F23*I23 -> 0 | M23: =+F23*J23 -> 0 | N23: =+F23*K23 -> 0
A24: 5 | B24: AISLACIONES | G24: =+SUM(F25:F31) -> 19239698 | H24: =+G24/$G$195 -> 0.022773044
A25: 5.01 | B25: Cajón hidrofugo | C25: ml | D25: 136 | E25: 6496 | F25: =+E25*D25 -> 883456 | I25: 0 | K25: =+I25+J25 -> 0 | L25: =+F25*I25 -> 0 | M25: =+F25*J25 -> 0 | N25: =+F25*K25 -> 0
A26: 5.02 | B26: Aislación hidrófuga horizontal (baños) - Inc. membrana geotextil y 35% en concepto de babetas | C26: m2 | D26: 77 | E26: 33270 | F26: =+E26*D26 -> 2561790 | I26: 0 | K26: =+I26+J26 -> 0 | L26: =+F26*I26 -> 0 | M26: =+F26*J26 -> 0 | N26: =+F26*K26 -> 0
A27: 5.03 | B27: Azotado hidrófugo - Contrapiso de PB | C27: m2 | D27: 107 | E27: 6496 | F27: =+E27*D27 -> 695072 | I27: 0 | K27: =+I27+J27 -> 0 | L27: =+F27*I27 -> 0 | M27: =+F27*J27 -> 0 | N27: =+F27*K27 -> 0
A28: 5.04 | B28: Aislación térmica en terrazas, eps e:2,00 cm | C28: m2 | D28: 186 | E28: 4832 | F28: =+E28*D28 -> 898752 | I28: 0 | K28: =+I28+J28 -> 0 | L28: =+F28*I28 -> 0 | M28: =+F28*J28 -> 0 | N28: =+F28*K28 -> 0
A29: 5.05 | B29: Barrera de vapor | C29: m2 | D29: 186 | E29: 4134 | F29: =+E29*D29 -> 768924 | I29: 0 | K29: =+I29+J29 -> 0 | L29: =+F29*I29 -> 0 | M29: =+F29*J29 -> 0 | N29: =+F29*K29 -> 0
A30: 5.06 | B30: Membrana asfáltica geotextil 4mm - Balcones y azotea - Inc. 20% en concepto de babetas | C30: m2 | D30: 390 | E30: 28187 | F30: =+E30*D30 -> 10992930 | I30: 0 | K30: =+I30+J30 -> 0 | L30: =+F30*I30 -> 0 | M30: =+F30*J30 -> 0 | N30: =+F30*K30 -> 0
A31: 5.07 | B31: Impermeabilización de tanque de reserva de HºAº | C31: gl | D31: 1 | E31: 2438774 | F31: =+E31*D31 -> 2438774 | I31: 0 | K31: =+I31+J31 -> 0 | L31: =+F31*I31 -> 0 | M31: =+F31*J31 -> 0 | N31: =+F31*K31 -> 0
A32: 6 | B32: CUBIERTAS | G32: =+SUM(F33) -> 1722875 | H32: =+G32/$G$195 -> 0.0020392788
A33: 6.02 | B33: Babeta de chapa galvanizada en medianeras | C33: ml | D33: 55 | E33: 31325 | F33: =+E33*D33 -> 1722875 | I33: 0 | K33: =+I33+J33 -> 0 | L33: =+F33*I33 -> 0 | M33: =+F33*J33 -> 0 | N33: =+F33*K33 -> 0
A34: 7 | B34: REVOQUES | G34: =+SUM(F35:F40) -> 92324467 | H34: =+G34/$G$195 -> 0.10927974
A35: 7.01 | B35: Revoque Grueso Impermeable Exterior | C35: m2 | D35: 879 | E35: 19943 | F35: =+E35*D35 -> 17529897 | I35: 0 | K35: =+I35+J35 -> 0 | L35: =+F35*I35 -> 0 | M35: =+F35*J35 -> 0 | N35: =+F35*K35 -> 0
A36: 7.02 | B36: Revoque Grueso Impermeable Exterior a mas de 3m - Medianero y fachadas | C36: m2 | D36: 716 | E36: 26767 | F36: =+E36*D36 -> 19165172 | I36: 0 | K36: =+I36+J36 -> 0 | L36: =+F36*I36 -> 0 | M36: =+F36*J36 -> 0 | N36: =+F36*K36 -> 0
A37: 7.03 | B37: Yeso interior | C37: m2 | D37: 1439 | E37: 22963 | F37: =+E37*D37 -> 33043757 | I37: 0 | K37: =+I37+J37 -> 0 | L37: =+F37*I37 -> 0 | M37: =+F37*J37 -> 0 | N37: =+F37*K37 -> 0
A38: 7.04 | B38: Arista en yeso | C38: ml | D38: 347 | E38: 16909 | F38: =+E38*D38 -> 5867423 | I38: 0 | K38: =+I38+J38 -> 0 | L38: =+F38*I38 -> 0 | M38: =+F38*J38 -> 0 | N38: =+F38*K38 -> 0
A39: 7.05 | B39: Provisión y colocación de guardacanto yesero | C39: un | D39: 132 | E39: 19384 | F39: =+E39*D39 -> 2558688 | I39: 0 | K39: =+I39+J39 -> 0 | L39: =+F39*I39 -> 0 | M39: =+F39*J39 -> 0 | N39: =+F39*K39 -> 0
A40: 7.06 | B40: Revoque Grueso Impermeable Interior b/ revestimiento | C40: m2 | D40: 710 | E40: 19943 | F40: =+E40*D40 -> 14159530 | I40: 0 | K40: =+I40+J40 -> 0 | L40: =+F40*I40 -> 0 | M40: =+F40*J40 -> 0 | N40: =+F40*K40 -> 0
A41: 8 | B41: CONTRAPISOS Y CARPETAS | G41: =+SUM(F42:F49) -> 49520833 | H41: =+G41/$G$195 -> 0.058615271
A42: 8.01 | B42: Contrapiso de Hº armado e: 18 cm, incluye malla Ø 6 mm y film 200 mic. | C42: m2 | D42: 107 | E42: 58580 | F42: =+E42*D42 -> 6268060 | I42: 0 | K42: =+I42+J42 -> 0 | L42: =+F42*I42 -> 0 | M42: =+F42*J42 -> 0 | N42: =+F42*K42 -> 0
...

Sheet GDR 3760_Pto. 02_Cert. 07
F1: DÓLAR BNA | G1: DÓLAR MEP
F2: 1066.5 | G2: 1170
F4: 45667
B5: OBRA: EDIFICIO GDR 3760 | I5: Certificado | J5: 7 | N5: 45930
B6: PRESUPUESTO OBRA CIVIL
B7: PRESUPUESTO 02 - ALBANILERIA, INSTALACIONES Y TERMINACIONES | I7: Avance | L7: Importe
B8: Descripción | C8: U | D8: Cant | E8: P unit | F8: Subtotal | I8: Anterior | J8: Actual | K8: Acumulado | L8: Anterior | M8: Actual | N8: Acumulado
A9: 4 | B9: MAMPOSTERÍA | G9: =+SUM(F10:F23) -> 51045774 | H9: =+G9/$G$195 -> 0.060420265
A10: 4.01 | B10: Muro tipo 1 - Ladrillo hueco 8 x 18 x 33 | C10: m2 | D10: 621 | E10: 22140 | F10: =+E10*D10 -> 13748940 | I10: 0 | K10: =+I10+J10 -> 0 | L10: =+F10*I10 -> 0 | M10: =+F10*J10 -> 0 | N10: =+F10*K10 -> 0
A11: 4.02 | B11: Muro tipo 2 - Ladrillo hueco 12 x 18 x 33 | C11: m2 | D11: 780 | E11: 24437 | F11: =+E11*D11 -> 19060860 | I11: 0 | K11: =+I11+J11 -> 0 | L11: =+F11*I11 -> 0 | M11: =+F11*J11 -> 0 | N11: =+F11*K11 -> 0
A12: 4.03 | B12: Muro tipo 3 - Ladrillo comun en panderete | C12: m2 | D12: 56 | E12: 23248 | F12: =+E12*D12 -> 1301888 | I12: 0 | K12: =+I12+J12 -> 0 | L12: =+F12*I12 -> 0 | M12: =+F12*J12 -> 0 | N12: =+F12*K12 -> 0
A13: 4.04 | B13: Muro tipo 4 - Ladrillo hueco portante 12 x 18 x 33 | C13: m2 | D13: 42 | E13: 28746 | F13: =+E13*D13 -> 1207332 | I13: 0 | K13: =+I13+J13 -> 0 | L13: =+F13*I13 -> 0 | M13: =+F13*J13 -> 0 | N13: =+F13*K13 -> 0
A14: 4.05 | B14: Muro tipo 5 - Bloque HCCA e: 7,5 cm | C14: m2 | D14: 70 | E14: 36933 | F14: =+E14*D14 -> 2585310 | I14: 0 | K14: =+I14+J14 -> 0 | L14: =+F14*I14 -> 0 | M14: =+F14*J14 -> 0 | N14: =+F14*K14 -> 0
A15: 4.06 | B15: Muro tipo 6 - Ladrillo hueco 18 x 18 x 33 | C15: m2 | D15: 5 | E15: 28672 | F15: =+E15*D15 -> 143360 | I15: 0 | K15: =+I15+J15 -> 0 | L15: =+F15*I15 -> 0 | M15: =+F15*J15 -> 0 | N15: =+F15*K15 -> 0
A16: 4.07 | B16: Enchape de medianeras existentes - Contemplamos picado zonas sueltas y enchape con ladrillo comun para PB | C16: m2 | D16: 193 | E16: 18611 | F16: =+E16*D16 -> 3591923 | I16: 0 | K16: =+I16+J16 -> 0 | L16: =+F16*I16 -> 0 | M16: =+F16*J16 -> 0 | N16: =+F16*K16 -> 0
A17: 4.08 | B17: Cordón de hormigón en umbrales carpinterías | C17: ml | D17: 61 | E17: 28578 | F17: =+E17*D17 -> 1743258 | I17: 0 | K17: =+I17+J17 -> 0 | L17: =+F17*I17 -> 0 | M17: =+F17*J17 -> 0 | N17: =+F17*K17 -> 0
A18: 4.09 | B18: Banquina Sala tanque de bombeo | C18: gl | D18: 1 | E18: 280823 | F18: =+E18*D18 -> 280823 | I18: 0 | K18: =+I18+J18 -> 0 | L18: =+F18*I18 -> 0 | M18: =+F18*J18 -> 0 | N18: =+F18*K18 -> 0
A19: 4.1 | B19: Banquina en parrillas | C19: gl | D19: 1 | E19: 801214 | F19: =+E19*D19 -> 801214 | I19: 0 | K19: =+I19+J19 -> 0 | L19: =+F19*I19 -> 0 | M19: =+F19*J19 -> 0 | N19: =+F19*K19 -> 0
A20: 4.11 | B20: Excavación y amurado con Hº tanque de recuperación de agua de lluvia | C20: gl | D20: 1 | E20: 525234 | F20: =+E20*D20 -> 525234 | I20: 0 | K20: =+I20+J20 -> 0 | L20: =+F20*I20 -> 0 | M20: =+F20*J20 -> 0 | N20: =+F20*K20 -> 0
A21: 4.12 | B21: Provisión y amurado de tapas de inspección para tanque de reserva | C21: u | D21: 3 | E21: 237784 | F21: =+E21*D21 -> 713352 | I21: 0 | K21: =+I21+J21 -> 0 | L21: =+F21*I21 -> 0 | M21: =+F21*J21 -> 0 | N21: =+F21*K21 -> 0
... A23: 4.14 | B23: Amurado de bañera | C23: u | D23: 8 | E23: 177655 | F23: =+E23*D23 -> 1421240 | I23: 0 | K23: =+I23+J23 -> 0 | L23: =+F23*I23 -> 0 | M23: =+F23*J23 -> 0 | N23: =+F23*K23 -> 0
A24: 5 | B24: AISLACIONES | G24: =+SUM(F25:F31) -> 19239698 | H24: =+G24/$G$195 -> 0.022773044
A25: 5.01 | B25: Cajón hidrofugo | C25: ml | D25: 136 | E25: 6496 | F25: =+E25*D25 -> 883456 | I25: 0 | K25: =+I25+J25 -> 0 | L25: =+F25*I25 -> 0 | M25: =+F25*J25 -> 0 | N25: =+F25*K25 -> 0
A26: 5.02 | B26: Aislación hidrófuga horizontal (baños) - Inc. membrana geotextil y 35% en concepto de babetas | C26: m2 | D26: 77 | E26: 33270 | F26: =+E26*D26 -> 2561790 | I26: 0 | K26: =+I26+J26 -> 0 | L26: =+F26*I26 -> 0 | M26: =+F26*J26 -> 0 | N26: =+F26*K26 -> 0
A27: 5.03 | B27: Azotado hidrófugo - Contrapiso de PB | C27: m2 | D27: 107 | E27: 6496 | F27: =+E27*D27 -> 695072 | I27: 0 | K27: =+I27+J27 -> 0 | L27: =+F27*I27 -> 0 | M27: =+F27*J27 -> 0 | N27: =+F27*K27 -> 0
A28: 5.04 | B28: Aislación térmica en terrazas, eps e:2,00 cm | C28: m2 | D28: 186 | E28: 4832 | F28: =+E28*D28 -> 898752 | I28: 0 | K28: =+I28+J28 -> 0 | L28: =+F28*I28 -> 0 | M28: =+F28*J28 -> 0 | N28: =+F28*K28 -> 0
A29: 5.05 | B29: Barrera de vapor | C29: m2 | D29: 186 | E29: 4134 | F29: =+E29*D29 -> 768924 | I29: 0 | K29: =+I29+J29 -> 0 | L29: =+F29*I29 -> 0 | M29: =+F29*J29 -> 0 | N29: =+F29*K29 -> 0
A30: 5.06 | B30: Membrana asfáltica geotextil 4mm - Balcones y azotea - Inc. 20% en concepto de babetas | C30: m2 | D30: 390 | E30: 28187 | F30: =+E30*D30 -> 10992930 | I30: 0 | K30: =+I30+J30 -> 0 | L30: =+F30*I30 -> 0 | M30: =+F30*J30 -> 0 | N30: =+F30*K30 -> 0
A31: 5.07 | B31: Impermeabilización de tanque de reserva de HºAº | C31: gl | D31: 1 | E31: 2438774 | F31: =+E31*D31 -> 2438774 | I31: 0 | K31: =+I31+J31 -> 0 | L31: =+F31*I31 -> 0 | M31: =+F31*J31 -> 0 | N31: =+F31*K31 -> 0
A32: 6 | B32: CUBIERTAS | G32: =+SUM(F33) -> 1722875 | H32: =+G32/$G$195 -> 0.0020392788
A33: 6.02 | B33: Babeta de chapa galvanizada en medianeras | C33: ml | D33: 55 | E33: 31325 | F33: =+E33*D33 -> 1722875 | I33: 0 | K33: =+I33+J33 -> 0 | L33: =+F33*I33 -> 0 | M33: =+F33*J33 -> 0 | N33: =+F33*K33 -> 0
A34: 7 | B34: REVOQUES | G34: =+SUM(F35:F40) -> 92324467 | H34: =+G34/$G$195 -> 0.10927974
A35: 7.01 | B35: Revoque Grueso Impermeable Exterior | C35: m2 | D35: 879 | E35: 19943 | F35: =+E35*D35 -> 17529897 | I35: 0 | K35: =+I35+J35 -> 0 | L35: =+F35*I35 -> 0 | M35: =+F35*J35 -> 0 | N35: =+F35*K35 -> 0
A36: 7.02 | B36: Revoque Grueso Impermeable Exterior a mas de 3m - Medianero y fachadas | C36: m2 | D36: 716 | E36: 26767 | F36: =+E36*D36 -> 19165172 | I36: 0 | K36: =+I36+J36 -> 0 | L36: =+F36*I36 -> 0 | M36: =+F36*J36 -> 0 | N36: =+F36*K36 -> 0
A37: 7.03 | B37: Yeso interior | C37: m2 | D37: 1439 | E37: 22963 | F37: =+E37*D37 -> 33043757 | I37: 0 | K37: =+I37+J37 -> 0 | L37: =+F37*I37 -> 0 | M37: =+F37*J37 -> 0 | N37: =+F37*K37 -> 0
A38: 7.04 | B38: Arista en yeso | C38: ml | D38: 347 | E38: 16909 | F38: =+E38*D38 -> 5867423 | I38: 0 | K38: =+I38+J38 -> 0 | L38: =+F38*I38 -> 0 | M38: =+F38*J38 -> 0 | N38: =+F38*K38 -> 0
A39: 7.05 | B39: Provisión y colocación de guardacanto yesero | C39: un | D39: 132 | E39: 19384 | F39: =+E39*D39 -> 2558688 | I39: 0 | K39: =+I39+J39 -> 0 | L39: =+F39*I39 -> 0 | M39: =+F39*J39 -> 0 | N39: =+F39*K39 -> 0
A40: 7.06 | B40: Revoque Grueso Impermeable Interior b/ revestimiento | C40: m2 | D40: 710 | E40: 19943 | F40: =+E40*D40 -> 14159530 | I40: 0 | K40: =+I40+J40 -> 0 | L40: =+F40*I40 -> 0 | M40: =+F40*J40 -> 0 | N40: =+F40*K40 -> 0
A41: 8 | B41: CONTRAPISOS Y CARPETAS | G41: =+SUM(F42:F49) -> 49520833 | H41: =+G41/$G$195 -> 0.058615271
A42: 8.01 | B42: Contrapiso de Hº armado e: 18 cm, incluye malla Ø 6 mm y film 200 mic. | C42: m2 | D42: 107 | E42: 58580 | F42: =+E42*D42 -> 6268060 | I42: 0 | K42: =+I42+J42 -> 0 | L42: =+F42*I42 -> 0 | M42: =+F42*J42 -> 0 | N42: =+F42*K42 -> 0
...

Sheet GDR 3760_Pto. 02_Cert. 08
F1: DÓLAR BNA | G1: DÓLAR MEP
F2: 1066.5 | G2: 1170
F4: 45667
B5: OBRA: EDIFICIO GDR 3760 | I5: Certificado | J5: 8 | N5: 45958
B6: PRESUPUESTO OBRA CIVIL
B7: PRESUPUESTO 02 - ALBANILERIA, INSTALACIONES Y TERMINACIONES | I7: Avance | L7: Importe
B8: Descripción | C8: U | D8: Cant | E8: P unit | F8: Subtotal | I8: Anterior | J8: Actual | K8: Acumulado | L8: Anterior | M8: Actual | N8: Acumulado
A9: 4 | B9: MAMPOSTERÍA | G9: =+SUM(F10:F23) -> 51045774 | H9: =+G9/$G$195 -> 0.060420265
A10: 4.01 | B10: Muro tipo 1 - Ladrillo hueco 8 x 18 x 33 | C10: m2 | D10: 621 | E10: 22140 | F10: =+E10*D10 -> 13748940 | I10: 0 | K10: =+I10+J10 -> 0 | L10: =+F10*I10 -> 0 | M10: =+F10*J10 -> 0 | N10: =+F10*K10 -> 0
A11: 4.02 | B11: Muro tipo 2 - Ladrillo hueco 12 x 18 x 33 | C11: m2 | D11: 780 | E11: 24437 | F11: =+E11*D11 -> 19060860 | I11: 0 | K11: =+I11+J11 -> 0 | L11: =+F11*I11 -> 0 | M11: =+F11*J11 -> 0 | N11: =+F11*K11 -> 0
A12: 4.03 | B12: Muro tipo 3 - Ladrillo comun en panderete | C12: m2 | D12: 56 | E12: 23248 | F12: =+E12*D12 -> 1301888 | I12: 0 | K12: =+I12+J12 -> 0 | L12: =+F12*I12 -> 0 | M12: =+F12*J12 -> 0 | N12: =+F12*K12 -> 0
A13: 4.04 | B13: Muro tipo 4 - Ladrillo hueco portante 12 x 18 x 33 | C13: m2 | D13: 42 | E13: 28746 | F13: =+E13*D13 -> 1207332 | I13: 0 | K13: =+I13+J13 -> 0 | L13: =+F13*I13 -> 0 | M13: =+F13*J13 -> 0 | N13: =+F13*K13 -> 0
A14: 4.05 | B14: Muro tipo 5 - Bloque HCCA e: 7,5 cm | C14: m2 | D14: 70 | E14: 36933 | F14: =+E14*D14 -> 2585310 | I14: 0 | K14: =+I14+J14 -> 0 | L14: =+F14*I14 -> 0 | M14: =+F14*J14 -> 0 | N14: =+F14*K14 -> 0
A15: 4.06 | B15: Muro tipo 6 - Ladrillo hueco 18 x 18 x 33 | C15: m2 | D15: 5 | E15: 28672 | F15: =+E15*D15 -> 143360 | I15: 0 | K15: =+I15+J15 -> 0 | L15: =+F15*I15 -> 0 | M15: =+F15*J15 -> 0 | N15: =+F15*K15 -> 0
A16: 4.07 | B16: Enchape de medianeras existentes - Contemplamos picado zonas sueltas y enchape con ladrillo comun para PB | C16: m2 | D16: 193 | E16: 18611 | F16: =+E16*D16 -> 3591923 | I16: 0 | K16: =+I16+J16 -> 0 | L16: =+F16*I16 -> 0 | M16: =+F16*J16 -> 0 | N16: =+F16*K16 -> 0
A17: 4.08 | B17: Cordón de hormigón en umbrales carpinterías | C17: ml | D17: 61 | E17: 28578 | F17: =+E17*D17 -> 1743258 | I17: 0 | K17: =+I17+J17 -> 0 | L17: =+F17*I17 -> 0 | M17: =+F17*J17 -> 0 | N17: =+F17*K17 -> 0
A18: 4.09 | B18: Banquina Sala tanque de bombeo | C18: gl | D18: 1 | E18: 280823 | F18: =+E18*D18 -> 280823 | I18: 0 | K18: =+I18+J18 -> 0 | L18: =+F18*I18 -> 0 | M18: =+F18*J18 -> 0 | N18: =+F18*K18 -> 0
A19: 4.1 | B19: Banquina en parrillas | C19: gl | D19: 1 | E19: 801214 | F19: =+E19*D19 -> 801214 | I19: 0 | K19: =+I19+J19 -> 0 | L19: =+F19*I19 -> 0 | M19: =+F19*J19 -> 0 | N19: =+F19*K19 -> 0
A20: 4.11 | B20: Excavación y amurado con Hº tanque de recuperación de agua de lluvia | C20: gl | D20: 1 | E20: 525234 | F20: =+E20*D20 -> 525234 | I20: 0 | K20: =+I20+J20 -> 0 | L20: =+F20*I20 -> 0 | M20: =+F20*J20 -> 0 | N20: =+F20*K20 -> 0
A21: 4.12 | B21: Provisión y amurado de tapas de inspección para tanque de reserva | C21: u | D21: 3 | E21: 237784 | F21: =+E21*D21 -> 713352 | I21: 0 | K21: =+I21+J21 -> 0 | L21: =+F21*I21 -> 0 | M21: =+F21*J21 -> 0 | N21: =+F21*K21 -> 0
... A23: 4.14 | B23: Amurado de bañera | C23: u | D23: 8 | E23: 177655 | F23: =+E23*D23 -> 1421240 | I23: 0 | K23: =+I23+J23 -> 0 | L23: =+F23*I23 -> 0 | M23: =+F23*J23 -> 0 | N23: =+F23*K23 -> 0
A24: 5 | B24: AISLACIONES | G24: =+SUM(F25:F31) -> 19239698 | H24: =+G24/$G$195 -> 0.022773044
A25: 5.01 | B25: Cajón hidrofugo | C25: ml | D25: 136 | E25: 6496 | F25: =+E25*D25 -> 883456 | I25: 0 | K25: =+I25+J25 -> 0 | L25: =+F25*I25 -> 0 | M25: =+F25*J25 -> 0 | N25: =+F25*K25 -> 0
A26: 5.02 | B26: Aislación hidrófuga horizontal (baños) - Inc. membrana geotextil y 35% en concepto de babetas | C26: m2 | D26: 77 | E26: 33270 | F26: =+E26*D26 -> 2561790 | I26: 0 | K26: =+I26+J26 -> 0 | L26: =+F26*I26 -> 0 | M26: =+F26*J26 -> 0 | N26: =+F26*K26 -> 0
A27: 5.03 | B27: Azotado hidrófugo - Contrapiso de PB | C27: m2 | D27: 107 | E27: 6496 | F27: =+E27*D27 -> 695072 | I27: 0 | K27: =+I27+J27 -> 0 | L27: =+F27*I27 -> 0 | M27: =+F27*J27 -> 0 | N27: =+F27*K27 -> 0
A28: 5.04 | B28: Aislación térmica en terrazas, eps e:2,00 cm | C28: m2 | D28: 186 | E28: 4832 | F28: =+E28*D28 -> 898752 | I28: 0 | K28: =+I28+J28 -> 0 | L28: =+F28*I28 -> 0 | M28: =+F28*J28 -> 0 | N28: =+F28*K28 -> 0
A29: 5.05 | B29: Barrera de vapor | C29: m2 | D29: 186 | E29: 4134 | F29: =+E29*D29 -> 768924 | I29: 0 | K29: =+I29+J29 -> 0 | L29: =+F29*I29 -> 0 | M29: =+F29*J29 -> 0 | N29: =+F29*K29 -> 0
A30: 5.06 | B30: Membrana asfáltica geotextil 4mm - Balcones y azotea - Inc. 20% en concepto de babetas | C30: m2 | D30: 390 | E30: 28187 | F30: =+E30*D30 -> 10992930 | I30: 0 | K30: =+I30+J30 -> 0 | L30: =+F30*I30 -> 0 | M30: =+F30*J30 -> 0 | N30: =+F30*K30 -> 0
A31: 5.07 | B31: Impermeabilización de tanque de reserva de HºAº | C31: gl | D31: 1 | E31: 2438774 | F31: =+E31*D31 -> 2438774 | I31: 0 | K31: =+I31+J31 -> 0 | L31: =+F31*I31 -> 0 | M31: =+F31*J31 -> 0 | N31: =+F31*K31 -> 0
A32: 6 | B32: CUBIERTAS | G32: =+SUM(F33) -> 1722875 | H32: =+G32/$G$195 -> 0.0020392788
A33: 6.02 | B33: Babeta de chapa galvanizada en medianeras | C33: ml | D33: 55 | E33: 31325 | F33: =+E33*D33 -> 1722875 | I33: 0 | K33: =+I33+J33 -> 0 | L33: =+F33*I33 -> 0 | M33: =+F33*J33 -> 0 | N33: =+F33*K33 -> 0
A34: 7 | B34: REVOQUES | G34: =+SUM(F35:F40) -> 92324467 | H34: =+G34/$G$195 -> 0.10927974
A35: 7.01 | B35: Revoque Grueso Impermeable Exterior | C35: m2 | D35: 879 | E35: 19943 | F35: =+E35*D35 -> 17529897 | I35: 0 | K35: =+I35+J35 -> 0 | L35: =+F35*I35 -> 0 | M35: =+F35*J35 -> 0 | N35: =+F35*K35 -> 0
A36: 7.02 | B36: Revoque Grueso Impermeable Exterior a mas de 3m - Medianero y fachadas | C36: m2 | D36: 716 | E36: 26767 | F36: =+E36*D36 -> 19165172 | I36: 0 | K36: =+I36+J36 -> 0 | L36: =+F36*I36 -> 0 | M36: =+F36*J36 -> 0 | N36: =+F36*K36 -> 0
A37: 7.03 | B37: Yeso interior | C37: m2 | D37: 1439 | E37: 22963 | F37: =+E37*D37 -> 33043757 | I37: 0 | K37: =+I37+J37 -> 0 | L37: =+F37*I37 -> 0 | M37: =+F37*J37 -> 0 | N37: =+F37*K37 -> 0
A38: 7.04 | B38: Arista en yeso | C38: ml | D38: 347 | E38: 16909 | F38: =+E38*D38 -> 5867423 | I38: 0 | K38: =+I38+J38 -> 0 | L38: =+F38*I38 -> 0 | M38: =+F38*J38 -> 0 | N38: =+F38*K38 -> 0
A39: 7.05 | B39: Provisión y colocación de guardacanto yesero | C39: un | D39: 132 | E39: 19384 | F39: =+E39*D39 -> 2558688 | I39: 0 | K39: =+I39+J39 -> 0 | L39: =+F39*I39 -> 0 | M39: =+F39*J39 -> 0 | N39: =+F39*K39 -> 0
A40: 7.06 | B40: Revoque Grueso Impermeable Interior b/ revestimiento | C40: m2 | D40: 710 | E40: 19943 | F40: =+E40*D40 -> 14159530 | I40: 0 | K40: =+I40+J40 -> 0 | L40: =+F40*I40 -> 0 | M40: =+F40*J40 -> 0 | N40: =+F40*K40 -> 0
A41: 8 | B41: CONTRAPISOS Y CARPETAS | G41: =+SUM(F42:F49) -> 49520833 | H41: =+G41/$G$195 -> 0.058615271
A42: 8.01 | B42: Contrapiso de Hº armado e: 18 cm, incluye malla Ø 6 mm y film 200 mic. | C42: m2 | D42: 107 | E42: 58580 | F42: =+E42*D42 -> 6268060 | I42: 0 | K42: =+I42+J42 -> 0 | L42: =+F42*I42 -> 0 | M42: =+F42*J42 -> 0 | N42: =+F42*K42 -> 0
...

Sheet GDR 3760_Pto. 02_Cert. 09)
F1: DÓLAR BNA | G1: DÓLAR MEP
F2: 1066.5 | G2: 1170
F4: 45667
B5: OBRA: EDIFICIO GDR 3760 | I5: Certificado | J5: 9 | N5: 45988
B6: PRESUPUESTO OBRA CIVIL
B7: PRESUPUESTO 02 - ALBANILERIA, INSTALACIONES Y TERMINACIONES | I7: Avance | L7: Importe
B8: Descripción | C8: U | D8: Cant | E8: P unit | F8: Subtotal | I8: Anterior | J8: Actual | K8: Acumulado | L8: Anterior | M8: Actual | N8: Acumulado
A9: 4 | B9: MAMPOSTERÍA | G9: =+SUM(F10:F23) -> 51045774 | H9: =+G9/$G$195 -> 0.060420265
A10: 4.01 | B10: Muro tipo 1 - Ladrillo hueco 8 x 18 x 33 | C10: m2 | D10: 621 | E10: 22140 | F10: =+E10*D10 -> 13748940 | I10: 0 | J10: 0.15 | K10: =+I10+J10 -> 0.15 | L10: =+F10*I10 -> 0 | M10: =+F10*J10 -> 2062341 | N10: =+F10*K10 -> 2062341
