Workbook
Name \0: #REF!
Name \0: #REF!
Name \0: #REF!
Name \0: #REF!
Name \0: #REF!
Name \0: #REF!
Name \c: #REF!
Name \c: #REF!
Name \c: #REF!
Name \c: #REF!
Name \E: #REF!
Name \E: #REF!
Name \E: #REF!
Name \E: #REF!
Name \i: #REF!
Name \j: #REF!
Name \m: #REF!
Name \P: #REF!
Name \P: #REF!
Name \P: #REF!
Name \P: #REF!
Name \P: #REF!
Name \P: #REF!
Name \P: #REF!
Name \P: #REF!
Name \P: #REF!
Name \P: #REF!
Name \P: #REF!
Name \P: #REF!
Name \P: #REF!
Name \P: #REF!
Name \P: #REF!
Name \P: #REF!
Name \P: #REF!
Name \P: #REF!
Name \P: #REF!
Name \r: #N/A
Name \x: #REF!
Name \z: #REF!
Name \z: #REF!
Name \z: #REF!
Name \z: #REF!
Name \z: #REF!
Name \z: #REF!
Name __________ben1: #REF!
Name __________ben1: #REF!
Name __________ben1: #REF!
Name __________ben1: #REF!
Name __________ben1: #REF!
Name __________ben1: #REF!
Name __________ben1: #REF!
Name __________ben1: #REF!
Name __________ben1: #REF!
Name __________ben1: #REF!
Name __________ben1: #REF!
Name __________ben1: #REF!
Name __________ben1: #REF!
Name __________ben1: #REF!
Name __________ben1: #REF!
Name __________ben1: #REF!

Sheet HOJA DE OBRA
D1: OBRA: Edificio El Salvador 4140
A6: Cliente / Comitente:
A7: Facturacion
A8: Dirección / Jefe de la Obra:
A11: Fecha de Inicio : | D11: Duracion de Obra: | E11: 18 meses
A13: Presupuesto Aprobado : | D13: Fecha de Aprobacion:
A14: Orden de Compra CL : | D14: Nota de Pedido ARQ:
A16: Anticipo : | D16: Condiciones de Pago:
A17: Certifiaciones : | D17: Forma de Pago:
A18: Actualización CAC:
A20: Seguros :
A21: Caucion Anticipo
A22: Caucion Ejecucion
A23: Resp. Civil
A25: Programa S&H :
A26: Aviso de Obra :
A28: Descripcion de Tareas
A33: Contactos del cliente:
A34: Nombre | B34: TEL | C34: Rubro | D34: Mail de contacto
A39: Subcontratistas | B39: Rubro | C39: Inicio | D39: Presupuesto Aprobado | E39: Cerrado / Estimado
A44: Cuadrilla de Obra | B44: Categoría | D44: Observación
A52: Observaciones Particulares

Sheet Resumen General
AE1: Actualizado | AF1: 46174
B3: OBRA: SVD 4140
B4: RESUMEN DE OBRA
D5: 45658 | E5: 45689 | F5: 45717 | G5: 45748 | H5: 45778 | I5: 45809 | J5: 45839 | K5: 45870 | L5: 45901 | M5: 45931 | N5: 45962 | O5: 45992 | P5: 46023 | Q5: 46054 | R5: 46082 | S5: 46113 | T5: 46143 | V5: Acum. Descontado | X5: Presupuesto #1 Act. | Y5: Presupuesto #2 Act. | Z5: Previsto | AA5: % Cert. Acum. | AB5: Saldo Disponible | AC5: Disponible % | AD5: Rubro Completado
B6: Ingresos de Obra
B7: Ingresos por Certificados | D7: =SUM(VLOOKUP($B7,'Resumen Pto #1'!$B$5:$U$10,MATCH('Resumen General'!D$5,'Resumen Pto #1'!$B$5:$U$5,0),0)) -> 0 | E7: =SUM(VLOOKUP($B7,'Resumen Pto #1'!$B$5:$U$10,MATCH('Resumen General'!E$5,'Resumen Pto #1'!$B$5:$U$5,0),0)) -> 11515000 | F7: =SUM(VLOOKUP($B7,'Resumen Pto #1'!$B$5:$U$10,MATCH('Resumen General'!F$5,'Resumen Pto #1'!$B$5:$U$5,0),0)) -> 72746210 | G7: =SUM(VLOOKUP($B7,'Resumen Pto #1'!$B$5:$U$10,MATCH('Resumen General'!G$5,'Resumen Pto #1'!$B$5:$U$5,0),0)) -> 28390040 | H7: =SUM(VLOOKUP($B7,'Resumen Pto #1'!$B$5:$U$10,MATCH('Resumen General'!H$5,'Resumen Pto #1'!$B$5:$U$5,0),0)) -> 28932600 | I7: =SUM(VLOOKUP($B7,'Resumen Pto #1'!$B$5:$U$10,MATCH('Resumen General'!I$5,'Resumen Pto #1'!$B$5:$U$5,0),0)) -> 23665294 | J7: =SUM(VLOOKUP($B7,'Resumen Pto #1'!$B$5:$U$10,MATCH('Resumen General'!J$5,'Resumen Pto #1'!$B$5:$U$5,0),0),VLOOKUP($B7,'Resumen Pto #2'!$B$5:$Q$10,MATCH('Resumen General'!J$5,'Resumen Pto #2'!$B$5:$O$5,0),0)) -> 24611609 | K7: =SUM(VLOOKUP($B7,'Resumen Pto #1'!$B$5:$U$10,MATCH('Resumen General'!K$5,'Resumen Pto #1'!$B$5:$U$5,0),0),VLOOKUP($B7,'Resumen Pto #2'!$B$5:$Q$10,MATCH('Resumen General'!K$5,'Resumen Pto #2'!$B$5:$O$5,0),0)) -> 32566741 | L7: =SUM(VLOOKUP($B7,'Resumen Pto #1'!$B$5:$U$10,MATCH('Resumen General'!L$5,'Resumen Pto #1'!$B$5:$U$5,0),0),VLOOKUP($B7,'Resumen Pto #2'!$B$5:$Q$10,MATCH('Resumen General'!L$5,'Resumen Pto #2'!$B$5:$O$5,0),0)) -> 48704739 | M7: =SUM(VLOOKUP($B7,'Resumen Pto #1'!$B$5:$U$10,MATCH('Resumen General'!M$5,'Resumen Pto #1'!$B$5:$U$5,0),0),VLOOKUP($B7,'Resumen Pto #2'!$B$5:$Q$10,MATCH('Resumen General'!M$5,'Resumen Pto #2'!$B$5:$O$5,0),0)) -> 3.2988773e+08 | N7: =SUM(VLOOKUP($B7,'Resumen Pto #1'!$B$5:$U$10,MATCH('Resumen General'!N$5,'Resumen Pto #1'!$B$5:$U$5,0),0),VLOOKUP($B7,'Resumen Pto #2'!$B$5:$Q$10,MATCH('Resumen General'!N$5,'Resumen Pto #2'!$B$5:$O$5,0),0)) -> 52221423 | O7: =SUM(VLOOKUP($B7,'Resumen Pto #1'!$B$5:$U$10,MATCH('Resumen General'!O$5,'Resumen Pto #1'!$B$5:$U$5,0),0),VLOOKUP($B7,'Resumen Pto #2'!$B$5:$Q$10,MATCH('Resumen General'!O$5,'Resumen Pto #2'!$B$5:$O$5,0),0)) -> 58087412 | P7: =SUM(VLOOKUP($B7,'Resumen Pto #1'!$B$5:$U$10,MATCH('Resumen General'!P$5,'Resumen Pto #1'!$B$5:$U$5,0),0),VLOOKUP($B7,'Resumen Pto #2'!$B$5:$Q$10,MATCH('Resumen General'!P$5,'Resumen Pto #2'!$B$5:$O$5,0),0)) -> 27947358 | Q7: =SUM(VLOOKUP($B7,'Resumen Pto #1'!$B$5:$U$10,MATCH('Resumen General'!Q$5,'Resumen Pto #1'!$B$5:$U$5,0),0),VLOOKUP($B7,'Resumen Pto #2'!$B$5:$Q$10,MATCH('Resumen General'!Q$5,'Resumen Pto #2'!$B$5:$O$5,0),0)) -> 40981161 | ... T7: =SUM(VLOOKUP($B7,'Resumen Pto #1'!$B$5:$U$10,MATCH('Resumen General'!T$5,'Resumen Pto #1'!$B$5:$U$5,0),0),VLOOKUP($B7,'Resumen Pto #2'!$B$5:$Q$10,MATCH('Resumen General'!T$5,'Resumen Pto #2'!$B$5:$O$5,0),0)) -> 41422349 | V7: =SUM(D7:U7) -> 8.71161e+08 | X7: ='Resumen Pto #1'!X7 -> 421306052 | Y7: ='Resumen Pto #2'!R7 -> 7.3685713e+08 | Z7: =SUM(X7:Y7) -> 1.1581632e+09 | AA7: =SUM('Pto. 01 Cert.'!$S$58,'Pto. 02 Cert.'!$S$186)/SUM('Pto. 01 Cert.'!$L$58,'Pto. Vta.'!$L$239) -> 0.64279413 | AB7: =IF(AA7=100%,0,IF(OR(V7<>0,Z7),Z7-V7)) -> 2.8700219e+08 | AC7: =IF(OR(AB7<0,Z7),AB7/Z7,0%) -> 0.24780807 | AD7: =IF(AA7=100%,IF(OR(V7<>0,Z7),Z7-V7),0) -> 0
B8: Total Ingresos de Obra | D8: =SUM(D7) -> 0 | E8: =SUM(E7) -> 11515000 | F8: =SUM(F7) -> 72746210 | G8: =SUM(G7) -> 28390040 | H8: =SUM(H7) -> 28932600 | I8: =SUM(I7) -> 23665294 | J8: =SUM(J7) -> 24611609 | K8: =SUM(K7) -> 32566741 | ... T8: =SUM(T7) -> 41422349 | V8: =SUM(V7) -> 8.71161e+08 | X8: =SUM(X7) -> 421306052 | Y8: =SUM(Y7) -> 7.3685713e+08 | Z8: =SUM(Z7) -> 1.1581632e+09 | AB8: =SUM(AB7) -> 2.8700219e+08 | AC8: =IF(OR(AB8<0,Z8),AB8/Z8,0%) -> 0.24780807 | AD8: =IF(OR(V8<>0,Z8),Z8-V8,) -> 2.8700219e+08
B9: Actualización por CAC | D9: =SUM(VLOOKUP($B9,'Resumen Pto #1'!$B$5:$U$10,MATCH('Resumen General'!D$5,'Resumen Pto #1'!$B$5:$U$5,0),0)) -> 0 | E9: =SUM(VLOOKUP($B9,'Resumen Pto #1'!$B$5:$U$10,MATCH('Resumen General'!E$5,'Resumen Pto #1'!$B$5:$U$5,0),0)) -> 735000 | F9: =SUM(VLOOKUP($B9,'Resumen Pto #1'!$B$5:$U$10,MATCH('Resumen General'!F$5,'Resumen Pto #1'!$B$5:$U$5,0),0)) -> 5068372.2 | G9: =SUM(VLOOKUP($B9,'Resumen Pto #1'!$B$5:$U$10,MATCH('Resumen General'!G$5,'Resumen Pto #1'!$B$5:$U$5,0),0)) -> 2935456.1 | H9: =SUM(VLOOKUP($B9,'Resumen Pto #1'!$B$5:$U$10,MATCH('Resumen General'!H$5,'Resumen Pto #1'!$B$5:$U$5,0),0)) -> 3370711.7 | I9: =SUM(VLOOKUP($B9,'Resumen Pto #1'!$B$5:$U$10,MATCH('Resumen General'!I$5,'Resumen Pto #1'!$B$5:$U$5,0),0)) -> 3338429.3 | J9: =SUM(VLOOKUP($B9,'Resumen Pto #1'!$B$5:$U$10,MATCH('Resumen General'!J$5,'Resumen Pto #1'!$B$5:$U$5,0),0),VLOOKUP($B9,'Resumen Pto #2'!$B$5:$Q$10,MATCH('Resumen General'!J$5,'Resumen Pto #2'!$B$5:$O$5,0),0)) -> 3690653.5 | K9: =SUM(VLOOKUP($B9,'Resumen Pto #1'!$B$5:$U$10,MATCH('Resumen General'!K$5,'Resumen Pto #1'!$B$5:$U$5,0),0),VLOOKUP($B9,'Resumen Pto #2'!$B$5:$Q$10,MATCH('Resumen General'!K$5,'Resumen Pto #2'!$B$5:$O$5,0),0)) -> 5160346.8 | L9: =SUM(VLOOKUP($B9,'Resumen Pto #1'!$B$5:$U$10,MATCH('Resumen General'!L$5,'Resumen Pto #1'!$B$5:$U$5,0),0),VLOOKUP($B9,'Resumen Pto #2'!$B$5:$Q$10,MATCH('Resumen General'!L$5,'Resumen Pto #2'!$B$5:$O$5,0),0)) -> 8721283.8 | M9: =SUM(VLOOKUP($B9,'Resumen Pto #1'!$B$5:$U$10,MATCH('Resumen General'!M$5,'Resumen Pto #1'!$B$5:$U$5,0),0),VLOOKUP($B9,'Resumen Pto #2'!$B$5:$Q$10,MATCH('Resumen General'!M$5,'Resumen Pto #2'!$B$5:$O$5,0),0)) -> 59686343 | N9: =SUM(VLOOKUP($B9,'Resumen Pto #1'!$B$5:$U$10,MATCH('Resumen General'!N$5,'Resumen Pto #1'!$B$5:$U$5,0),0),VLOOKUP($B9,'Resumen Pto #2'!$B$5:$Q$10,MATCH('Resumen General'!N$5,'Resumen Pto #2'!$B$5:$O$5,0),0)) -> 12249470 | O9: =SUM(VLOOKUP($B9,'Resumen Pto #1'!$B$5:$U$10,MATCH('Resumen General'!O$5,'Resumen Pto #1'!$B$5:$U$5,0),0),VLOOKUP($B9,'Resumen Pto #2'!$B$5:$Q$10,MATCH('Resumen General'!O$5,'Resumen Pto #2'!$B$5:$O$5,0),0)) -> 14332314 | P9: =SUM(VLOOKUP($B9,'Resumen Pto #1'!$B$5:$U$10,MATCH('Resumen General'!P$5,'Resumen Pto #1'!$B$5:$U$5,0),0),VLOOKUP($B9,'Resumen Pto #2'!$B$5:$Q$10,MATCH('Resumen General'!P$5,'Resumen Pto #2'!$B$5:$O$5,0),0)) -> 8107844.3 | Q9: =SUM(VLOOKUP($B9,'Resumen Pto #1'!$B$5:$U$10,MATCH('Resumen General'!Q$5,'Resumen Pto #1'!$B$5:$U$5,0),0),VLOOKUP($B9,'Resumen Pto #2'!$B$5:$Q$10,MATCH('Resumen General'!Q$5,'Resumen Pto #2'!$B$5:$O$5,0),0)) -> 12717755 | ... T9: =SUM(VLOOKUP($B9,'Resumen Pto #1'!$B$5:$U$10,MATCH('Resumen General'!T$5,'Resumen Pto #1'!$B$5:$U$5,0),0),VLOOKUP($B9,'Resumen Pto #2'!$B$5:$Q$10,MATCH('Resumen General'!T$5,'Resumen Pto #2'!$B$5:$O$5,0),0)) -> 15732588 | V9: =SUM(D9:U9) -> 1.7298624e+08 | X9: ='Resumen Pto #1'!Y9 -> 0 | Y9: ='Resumen Pto #2'!T9 -> 0 | Z9: 0 | AA9: 0 | AB9: =IF(AA9=100%,0,IF(Z9=0,Z9,Z9-V9)) -> 0 | AC9: =IF(OR(AB9<0,Z9),AB9/Z9,0%) -> 0 | AD9: =IF(AA9=100%,IF(OR(U9<>0,Z9),Z9-U9),0) -> 0
B10: Total Ingresos por CAC | D10: =SUM(D9) -> 0 | E10: =SUM(E9) -> 735000 | F10: =SUM(F9) -> 5068372.2 | G10: =SUM(G9) -> 2935456.1 | H10: =SUM(H9) -> 3370711.7 | I10: =SUM(I9) -> 3338429.3 | J10: =SUM(J9) -> 3690653.5 | K10: =SUM(K9) -> 5160346.8 | ... T10: =SUM(T9) -> 15732588 | V10: =SUM(V9) -> 1.7298624e+08 | X10: =SUM(X9) -> 0 | Y10: =SUM(Y9) -> 0 | Z10: =SUM(Z9) -> 0 | AB10: =SUM(AB9) -> 0 | AC10: =IF(OR(AB10<0,Z10),AB10/Z10,0%) -> 0 | AD10: =SUM(AD9) -> 0
B12: Costos de Obra
B13: Seguridad e Higiene | D13: =IFERROR(SUM(VLOOKUP($B13&$C13,'C. Gestión Pto #1'!$B$4:C$17,MATCH(D$5,'C. Gestión Pto #1'!$B$4:C$4,0),FALSE),0),0) -> 0 | E13: =IFERROR(SUM(VLOOKUP($B13&$C13,'C. Gestión Pto #1'!$B$4:D$17,MATCH(E$5,'C. Gestión Pto #1'!$B$4:D$4,0),FALSE),0),0) -> 0 | F13: =IFERROR(SUM(VLOOKUP($B13&$C13,'C. Gestión Pto #1'!$B$4:E$17,MATCH(F$5,'C. Gestión Pto #1'!$B$4:E$4,0),FALSE),0),0) -> 964000 | G13: =IFERROR(SUM(VLOOKUP($B13&$C13,'C. Gestión Pto #1'!$B$4:F$17,MATCH(G$5,'C. Gestión Pto #1'!$B$4:F$4,0),FALSE),0),0) -> 1763514.1 | H13: =IFERROR(SUM(VLOOKUP($B13&$C13,'C. Gestión Pto #1'!$B$4:G$17,MATCH(H$5,'C. Gestión Pto #1'!$B$4:G$4,0),FALSE),0),0) -> 1757000 | I13: =IFERROR(SUM(VLOOKUP($B13&$C13,'C. Gestión Pto #1'!$B$4:H$17,MATCH(I$5,'C. Gestión Pto #1'!$B$4:H$4,0),FALSE),0),0) -> 1902500 | J13: =SUM(IFERROR(VLOOKUP($B13&$C13,'C. Gestión Pto #1'!$B$4:I$17,MATCH(J$5,'C. Gestión Pto #1'!$B$4:I$4,0),FALSE),0),IFERROR(VLOOKUP($B13&$C13,'C. Gestión Pto #2'!$B$4:C$23,MATCH(J$5,'C. Gestión Pto #2'!$B$4:C$4,0),FALSE),0)) -> 1961406 | K13: =SUM(IFERROR(VLOOKUP($B13&$C13,'C. Gestión Pto #1'!$B$4:J$17,MATCH(K$5,'C. Gestión Pto #1'!$B$4:J$4,0),FALSE),0),IFERROR(VLOOKUP($B13&$C13,'C. Gestión Pto #2'!$B$4:D$23,MATCH(K$5,'C. Gestión Pto #2'!$B$4:D$4,0),FALSE),0)) -> 1951450 | L13: =SUM(IFERROR(VLOOKUP($B13&$C13,'C. Gestión Pto #1'!$B$4:K$17,MATCH(L$5,'C. Gestión Pto #1'!$B$4:K$4,0),FALSE),0),IFERROR(VLOOKUP($B13&$C13,'C. Gestión Pto #2'!$B$4:E$23,MATCH(L$5,'C. Gestión Pto #2'!$B$4:E$4,0),FALSE),0)) -> 853846 | M13: =SUM(IFERROR(VLOOKUP($B13&$C13,'C. Gestión Pto #1'!$B$4:L$17,MATCH(M$5,'C. Gestión Pto #1'!$B$4:L$4,0),FALSE),0),IFERROR(VLOOKUP($B13&$C13,'C. Gestión Pto #2'!$B$4:F$23,MATCH(M$5,'C. Gestión Pto #2'!$B$4:F$4,0),FALSE),0)) -> 622493.01 | N13: =SUM(IFERROR(VLOOKUP($B13&$C13,'C. Gestión Pto #1'!$B$4:M$17,MATCH(N$5,'C. Gestión Pto #1'!$B$4:M$4,0),FALSE),0),IFERROR(VLOOKUP($B13&$C13,'C. Gestión Pto #2'!$B$4:G$23,MATCH(N$5,'C. Gestión Pto #2'!$B$4:G$4,0),FALSE),0)) -> 907500 | O13: =SUM(IFERROR(VLOOKUP($B13&$C13,'C. Gestión Pto #1'!$B$4:N$17,MATCH(O$5,'C. Gestión Pto #1'!$B$4:N$4,0),FALSE),0),IFERROR(VLOOKUP($B13&$C13,'C. Gestión Pto #2'!$B$4:H$23,MATCH(O$5,'C. Gestión Pto #2'!$B$4:H$4,0),FALSE),0)) -> 625825 | P13: =SUM(IFERROR(VLOOKUP($B13&$C13,'C. Gestión Pto #1'!$B$4:O$17,MATCH(P$5,'C. Gestión Pto #1'!$B$4:O$4,0),FALSE),0),IFERROR(VLOOKUP($B13&$C13,'C. Gestión Pto #2'!$B$4:I$23,MATCH(P$5,'C. Gestión Pto #2'!$B$4:I$4,0),FALSE),0)) -> 1020778 | Q13: =SUM(IFERROR(VLOOKUP($B13&$C13,'C. Gestión Pto #1'!$B$4:P$17,MATCH(Q$5,'C. Gestión Pto #1'!$B$4:P$4,0),FALSE),0),IFERROR(VLOOKUP($B13&$C13,'C. Gestión Pto #2'!$B$4:J$23,MATCH(Q$5,'C. Gestión Pto #2'!$B$4:J$4,0),FALSE),0)) -> 659001 | ... T13: =SUM(IFERROR(VLOOKUP($B13&$C13,'C. Gestión Pto #1'!$B$4:S$17,MATCH(T$5,'C. Gestión Pto #1'!$B$4:S$4,0),FALSE),0),IFERROR(VLOOKUP($B13&$C13,'C. Gestión Pto #2'!$B$4:M$23,MATCH(T$5,'C. Gestión Pto #2'!$B$4:M$4,0),FALSE),0)) -> 1407000 | V13: {=SUMPRODUCT($D13:$U13,TRANSPOSE('Indice CAC'!$C$10:$C$27))} -> 15129875 | X13: ='Resumen Pto #1'!X13 -> 7389505.4 | Y13: ='Resumen Pto #2'!R13 -> 900000 | Z13: =SUM(X13:Y13) -> 8289505.4 | AA13: =SUM(IF(C13="MAT",SUMIF('Pto. 01 Cert.'!$A$10:$A$57,$B13,'Pto. 01 Cert.'!$T$10:$T$57),IF(C13="MO",SUMIF('Pto. 01 Cert.'!$A$10:$A$57,$B13,'Pto. 01 Cert.'!$U$10:$U$57),SUMIF('Pto. 01 Cert.'!$A$10:$A$57,$B13,'Pto. 01 Cert.'!$V$10:$V$57))),IF(C13="MAT",SUMIF('Pto. 02 Cert.'!$A$10:$A$185,$B13,'Pto. 02 Cert.'!$T$10:$T$185),IF(C13="MO",SUMIF('Pto. 02 Cert.'!$A$10:$A$185,$B13,'Pto. 02 Cert.'!$U$10:$U$185),SUMIF('Pto. 02 Cert.'!$A$10:$A$185,$B13,'Pto. 02 Cert.'!$V$10:$V$185))))/SUM(IF(C13="MAT",SUMIF('Pto. 01 Cert.'!$A$10:$A$57,$B13,'Pto. 01 Cert.'!$I$10:$I$57),IF(C13="MO",SUMIF('Pto. 01 Cert.'!$A$10:$A$57,$B13,'Pto. 01 Cert.'!$J$10:$J$57),SUMIF('Pto. 01 Cert.'!$A$10:$A$57,$B13,'Pto. 01 Cert.'!$K$10:$K$57))),IF(C13="MAT",SUMIF('Pto. 02 Cert.'!$A$10:$A$185,$B13,'Pto. 02 Cert.'!$I$10:$I$185),IF(C13="MO",SUMIF('Pto. 02 Cert.'!$A$10:$A$185,$B13,'Pto. 02 Cert.'!$J$10:$J$185),SUMIF('Pto. 02 Cert.'!$A$10:$A$185,$B13,'Pto. 02 Cert.'!$K$10:$K$185)))) -> 0.94571437 | AB13: =IF(AA13=100%,0,IF(OR(V13<>0,Z13),Z13-V13)) -> -6840369.8 | AC13: =IF(OR(AB13<0,Z13),AB13/Z13,0%) -> -0.82518431 | AD13: =IF(AA13=100%,IF(OR(V13<>0,Z13),Z13-V13),0) -> 0
B14: Supervisión de Obra | D14: =IFERROR(SUM(VLOOKUP($B14&$C14,'C. Gestión Pto #1'!$B$4:C$17,MATCH(D$5,'C. Gestión Pto #1'!$B$4:C$4,0),FALSE),0),0) -> 2240048.4 | E14: =IFERROR(SUM(VLOOKUP($B14&$C14,'C. Gestión Pto #1'!$B$4:D$17,MATCH(E$5,'C. Gestión Pto #1'!$B$4:D$4,0),FALSE),0),0) -> 1806402.8 | F14: =IFERROR(SUM(VLOOKUP($B14&$C14,'C. Gestión Pto #1'!$B$4:E$17,MATCH(F$5,'C. Gestión Pto #1'!$B$4:E$4,0),FALSE),0),0) -> 2447085 | G14: =IFERROR(SUM(VLOOKUP($B14&$C14,'C. Gestión Pto #1'!$B$4:F$17,MATCH(G$5,'C. Gestión Pto #1'!$B$4:F$4,0),FALSE),0),0) -> 2817108 | H14: =IFERROR(SUM(VLOOKUP($B14&$C14,'C. Gestión Pto #1'!$B$4:G$17,MATCH(H$5,'C. Gestión Pto #1'!$B$4:G$4,0),FALSE),0),0) -> 2817108 | I14: =IFERROR(SUM(VLOOKUP($B14&$C14,'C. Gestión Pto #1'!$B$4:H$17,MATCH(I$5,'C. Gestión Pto #1'!$B$4:H$4,0),FALSE),0),0) -> 2987662.5 | J14: =SUM(IFERROR(VLOOKUP($B14&$C14,'C. Gestión Pto #1'!$B$4:I$17,MATCH(J$5,'C. Gestión Pto #1'!$B$4:I$4,0),FALSE),0),IFERROR(VLOOKUP($B14&$C14,'C. Gestión Pto #2'!$B$4:C$23,MATCH(J$5,'C. Gestión Pto #2'!$B$4:C$4,0),FALSE),0)) -> 3018848 | K14: =SUM(IFERROR(VLOOKUP($B14&$C14,'C. Gestión Pto #1'!$B$4:J$17,MATCH(K$5,'C. Gestión Pto #1'!$B$4:J$4,0),FALSE),0),IFERROR(VLOOKUP($B14&$C14,'C. Gestión Pto #2'!$B$4:D$23,MATCH(K$5,'C. Gestión Pto #2'!$B$4:D$4,0),FALSE),0)) -> 3253763 | L14: =SUM(IFERROR(VLOOKUP($B14&$C14,'C. Gestión Pto #1'!$B$4:K$17,MATCH(L$5,'C. Gestión Pto #1'!$B$4:K$4,0),FALSE),0),IFERROR(VLOOKUP($B14&$C14,'C. Gestión Pto #2'!$B$4:E$23,MATCH(L$5,'C. Gestión Pto #2'!$B$4:E$4,0),FALSE),0)) -> 3252503 | M14: =SUM(IFERROR(VLOOKUP($B14&$C14,'C. Gestión Pto #1'!$B$4:L$17,MATCH(M$5,'C. Gestión Pto #1'!$B$4:L$4,0),FALSE),0),IFERROR(VLOOKUP($B14&$C14,'C. Gestión Pto #2'!$B$4:F$23,MATCH(M$5,'C. Gestión Pto #2'!$B$4:F$4,0),FALSE),0)) -> 3374035.3 | N14: =SUM(IFERROR(VLOOKUP($B14&$C14,'C. Gestión Pto #1'!$B$4:M$17,MATCH(N$5,'C. Gestión Pto #1'!$B$4:M$4,0),FALSE),0),IFERROR(VLOOKUP($B14&$C14,'C. Gestión Pto #2'!$B$4:G$23,MATCH(N$5,'C. Gestión Pto #2'!$B$4:G$4,0),FALSE),0)) -> 3275352.8 | O14: =SUM(IFERROR(VLOOKUP($B14&$C14,'C. Gestión Pto #1'!$B$4:N$17,MATCH(O$5,'C. Gestión Pto #1'!$B$4:N$4,0),FALSE),0),IFERROR(VLOOKUP($B14&$C14,'C. Gestión Pto #2'!$B$4:H$23,MATCH(O$5,'C. Gestión Pto #2'!$B$4:H$4,0),FALSE),0)) -> 4921623.7 | P14: =SUM(IFERROR(VLOOKUP($B14&$C14,'C. Gestión Pto #1'!$B$4:O$17,MATCH(P$5,'C. Gestión Pto #1'!$B$4:O$4,0),FALSE),0),IFERROR(VLOOKUP($B14&$C14,'C. Gestión Pto #2'!$B$4:I$23,MATCH(P$5,'C. Gestión Pto #2'!$B$4:I$4,0),FALSE),0)) -> 3399806.5 | Q14: =SUM(IFERROR(VLOOKUP($B14&$C14,'C. Gestión Pto #1'!$B$4:P$17,MATCH(Q$5,'C. Gestión Pto #1'!$B$4:P$4,0),FALSE),0),IFERROR(VLOOKUP($B14&$C14,'C. Gestión Pto #2'!$B$4:J$23,MATCH(Q$5,'C. Gestión Pto #2'!$B$4:J$4,0),FALSE),0)) -> 3458743.6 | ... T14: =SUM(IFERROR(VLOOKUP($B14&$C14,'C. Gestión Pto #1'!$B$4:S$17,MATCH(T$5,'C. Gestión Pto #1'!$B$4:S$4,0),FALSE),0),IFERROR(VLOOKUP($B14&$C14,'C. Gestión Pto #2'!$B$4:M$23,MATCH(T$5,'C. Gestión Pto #2'!$B$4:M$4,0),FALSE),0)) -> 3838186.8 | V14: {=SUMPRODUCT($D14:$U14,TRANSPOSE('Indice CAC'!$C$10:$C$27))} -> 43333786 | X14: ='Resumen Pto #1'!X14 -> 30386965 | Y14: ='Resumen Pto #2'!R14 -> 22790223 | Z14: =SUM(X14:Y14) -> 53177188 | AA14: =SUM(IF(C14="MAT",SUMIF('Pto. 01 Cert.'!$A$10:$A$57,$B14,'Pto. 01 Cert.'!$T$10:$T$57),IF(C14="MO",SUMIF('Pto. 01 Cert.'!$A$10:$A$57,$B14,'Pto. 01 Cert.'!$U$10:$U$57),SUMIF('Pto. 01 Cert.'!$A$10:$A$57,$B14,'Pto. 01 Cert.'!$V$10:$V$57))),IF(C14="MAT",SUMIF('Pto. 02 Cert.'!$A$10:$A$185,$B14,'Pto. 02 Cert.'!$T$10:$T$185),IF(C14="MO",SUMIF('Pto. 02 Cert.'!$A$10:$A$185,$B14,'Pto. 02 Cert.'!$U$10:$U$185),SUMIF('Pto. 02 Cert.'!$A$10:$A$185,$B14,'Pto. 02 Cert.'!$V$10:$V$185))))/SUM(IF(C14="MAT",SUMIF('Pto. 01 Cert.'!$A$10:$A$57,$B14,'Pto. 01 Cert.'!$I$10:$I$57),IF(C14="MO",SUMIF('Pto. 01 Cert.'!$A$10:$A$57,$B14,'Pto. 01 Cert.'!$J$10:$J$57),SUMIF('Pto. 01 Cert.'!$A$10:$A$57,$B14,'Pto. 01 Cert.'!$K$10:$K$57))),IF(C14="MAT",SUMIF('Pto. 02 Cert.'!$A$10:$A$185,$B14,'Pto. 02 Cert.'!$I$10:$I$185),IF(C14="MO",SUMIF('Pto. 02 Cert.'!$A$10:$A$185,$B14,'Pto. 02 Cert.'!$J$10:$J$185),SUMIF('Pto. 02 Cert.'!$A$10:$A$185,$B14,'Pto. 02 Cert.'!$K$10:$K$185)))) -> 0.78571429 | AB14: =IF(AA14=100%,0,IF(OR(V14<>0,Z14),Z14-V14)) -> 9843402.5 | AC14: =IF(OR(AB14<0,Z14),AB14/Z14,0%) -> 0.18510574 | AD14: =IF(AA14=100%,IF(OR(V14<>0,Z14),Z14-V14),0) -> 0
B15: Movilidad | D15: =IFERROR(SUM(VLOOKUP($B15&$C15,'C. Gestión Pto #1'!$B$4:C$17,MATCH(D$5,'C. Gestión Pto #1'!$B$4:C$4,0),FALSE),0),0) -> 83133.29 | E15: =IFERROR(SUM(VLOOKUP($B15&$C15,'C. Gestión Pto #1'!$B$4:D$17,MATCH(E$5,'C. Gestión Pto #1'!$B$4:D$4,0),FALSE),0),0) -> 108153.67 | F15: =IFERROR(SUM(VLOOKUP($B15&$C15,'C. Gestión Pto #1'!$B$4:E$17,MATCH(F$5,'C. Gestión Pto #1'!$B$4:E$4,0),FALSE),0),0) -> 111838.73 | G15: =IFERROR(SUM(VLOOKUP($B15&$C15,'C. Gestión Pto #1'!$B$4:F$17,MATCH(G$5,'C. Gestión Pto #1'!$B$4:F$4,0),FALSE),0),0) -> 273194.46 | H15: =IFERROR(SUM(VLOOKUP($B15&$C15,'C. Gestión Pto #1'!$B$4:G$17,MATCH(H$5,'C. Gestión Pto #1'!$B$4:G$4,0),FALSE),0),0) -> 382880.04 | I15: =IFERROR(SUM(VLOOKUP($B15&$C15,'C. Gestión Pto #1'!$B$4:H$17,MATCH(I$5,'C. Gestión Pto #1'!$B$4:H$4,0),FALSE),0),0) -> 245052.89 | J15: =SUM(IFERROR(VLOOKUP($B15&$C15,'C. Gestión Pto #1'!$B$4:I$17,MATCH(J$5,'C. Gestión Pto #1'!$B$4:I$4,0),FALSE),0),IFERROR(VLOOKUP($B15&$C15,'C. Gestión Pto #2'!$B$4:C$23,MATCH(J$5,'C. Gestión Pto #2'!$B$4:C$4,0),FALSE),0)) -> 567556.66 | K15: =SUM(IFERROR(VLOOKUP($B15&$C15,'C. Gestión Pto #1'!$B$4:J$17,MATCH(K$5,'C. Gestión Pto #1'!$B$4:J$4,0),FALSE),0),IFERROR(VLOOKUP($B15&$C15,'C. Gestión Pto #2'!$B$4:D$23,MATCH(K$5,'C. Gestión Pto #2'!$B$4:D$4,0),FALSE),0)) -> 322994.82 | L15: =SUM(IFERROR(VLOOKUP($B15&$C15,'C. Gestión Pto #1'!$B$4:K$17,MATCH(L$5,'C. Gestión Pto #1'!$B$4:K$4,0),FALSE),0),IFERROR(VLOOKUP($B15&$C15,'C. Gestión Pto #2'!$B$4:E$23,MATCH(L$5,'C. Gestión Pto #2'!$B$4:E$4,0),FALSE),0)) -> 567394.82 | M15: =SUM(IFERROR(VLOOKUP($B15&$C15,'C. Gestión Pto #1'!$B$4:L$17,MATCH(M$5,'C. Gestión Pto #1'!$B$4:L$4,0),FALSE),0),IFERROR(VLOOKUP($B15&$C15,'C. Gestión Pto #2'!$B$4:F$23,MATCH(M$5,'C. Gestión Pto #2'!$B$4:F$4,0),FALSE),0)) -> 603374.92 | N15: =SUM(IFERROR(VLOOKUP($B15&$C15,'C. Gestión Pto #1'!$B$4:M$17,MATCH(N$5,'C. Gestión Pto #1'!$B$4:M$4,0),FALSE),0),IFERROR(VLOOKUP($B15&$C15,'C. Gestión Pto #2'!$B$4:G$23,MATCH(N$5,'C. Gestión Pto #2'!$B$4:G$4,0),FALSE),0)) -> 447563.68 | O15: =SUM(IFERROR(VLOOKUP($B15&$C15,'C. Gestión Pto #1'!$B$4:N$17,MATCH(O$5,'C. Gestión Pto #1'!$B$4:N$4,0),FALSE),0),IFERROR(VLOOKUP($B15&$C15,'C. Gestión Pto #2'!$B$4:H$23,MATCH(O$5,'C. Gestión Pto #2'!$B$4:H$4,0),FALSE),0)) -> 881403.34 | P15: =SUM(IFERROR(VLOOKUP($B15&$C15,'C. Gestión Pto #1'!$B$4:O$17,MATCH(P$5,'C. Gestión Pto #1'!$B$4:O$4,0),FALSE),0),IFERROR(VLOOKUP($B15&$C15,'C. Gestión Pto #2'!$B$4:I$23,MATCH(P$5,'C. Gestión Pto #2'!$B$4:I$4,0),FALSE),0)) -> 667797.87 | Q15: =SUM(IFERROR(VLOOKUP($B15&$C15,'C. Gestión Pto #1'!$B$4:P$17,MATCH(Q$5,'C. Gestión Pto #1'!$B$4:P$4,0),FALSE),0),IFERROR(VLOOKUP($B15&$C15,'C. Gestión Pto #2'!$B$4:J$23,MATCH(Q$5,'C. Gestión Pto #2'!$B$4:J$4,0),FALSE),0)) -> 1489831.9 | ... T15: =SUM(IFERROR(VLOOKUP($B15&$C15,'C. Gestión Pto #1'!$B$4:S$17,MATCH(T$5,'C. Gestión Pto #1'!$B$4:S$4,0),FALSE),0),IFERROR(VLOOKUP($B15&$C15,'C. Gestión Pto #2'!$B$4:M$23,MATCH(T$5,'C. Gestión Pto #2'!$B$4:M$4,0),FALSE),0)) -> 324436.07 | V15: {=SUMPRODUCT($D15:$U15,TRANSPOSE('Indice CAC'!$C$10:$C$27))} -> 6699010.2 | X15: ='Resumen Pto #1'!X15 -> 6000000 | Y15: ='Resumen Pto #2'!R15 -> 4500000 | Z15: =SUM(X15:Y15) -> 10500000 | AA15: =SUM(IF(C15="MAT",SUMIF('Pto. 01 Cert.'!$A$10:$A$57,$B15,'Pto. 01 Cert.'!$T$10:$T$57),IF(C15="MO",SUMIF('Pto. 01 Cert.'!$A$10:$A$57,$B15,'Pto. 01 Cert.'!$U$10:$U$57),SUMIF('Pto. 01 Cert.'!$A$10:$A$57,$B15,'Pto. 01 Cert.'!$V$10:$V$57))),IF(C15="MAT",SUMIF('Pto. 02 Cert.'!$A$10:$A$185,$B15,'Pto. 02 Cert.'!$T$10:$T$185),IF(C15="MO",SUMIF('Pto. 02 Cert.'!$A$10:$A$185,$B15,'Pto. 02 Cert.'!$U$10:$U$185),SUMIF('Pto. 02 Cert.'!$A$10:$A$185,$B15,'Pto. 02 Cert.'!$V$10:$V$185))))/SUM(IF(C15="MAT",SUMIF('Pto. 01 Cert.'!$A$10:$A$57,$B15,'Pto. 01 Cert.'!$I$10:$I$57),IF(C15="MO",SUMIF('Pto. 01 Cert.'!$A$10:$A$57,$B15,'Pto. 01 Cert.'!$J$10:$J$57),SUMIF('Pto. 01 Cert.'!$A$10:$A$57,$B15,'Pto. 01 Cert.'!$K$10:$K$57))),IF(C15="MAT",SUMIF('Pto. 02 Cert.'!$A$10:$A$185,$B15,'Pto. 02 Cert.'!$I$10:$I$185),IF(C15="MO",SUMIF('Pto. 02 Cert.'!$A$10:$A$185,$B15,'Pto. 02 Cert.'!$J$10:$J$185),SUMIF('Pto. 02 Cert.'!$A$10:$A$185,$B15,'Pto. 02 Cert.'!$K$10:$K$185)))) -> 0.77142857 | AB15: =IF(AA15=100%,0,IF(OR(V15<>0,Z15),Z15-V15)) -> 3800989.8 | AC15: =IF(OR(AB15<0,Z15),AB15/Z15,0%) -> 0.36199903 | AD15: =IF(AA15=100%,IF(OR(V15<>0,Z15),Z15-V15),0) -> 0
B16: Preliminares | D16: =IFERROR(SUM(VLOOKUP($B16&$C16,'C. Gestión Pto #1'!$B$4:C$17,MATCH(D$5,'C. Gestión Pto #1'!$B$4:C$4,0),FALSE),0),0) -> 0 | E16: =IFERROR(SUM(VLOOKUP($B16&$C16,'C. Gestión Pto #1'!$B$4:D$17,MATCH(E$5,'C. Gestión Pto #1'!$B$4:D$4,0),FALSE),0),0) -> 3076445.8 | F16: =IFERROR(SUM(VLOOKUP($B16&$C16,'C. Gestión Pto #1'!$B$4:E$17,MATCH(F$5,'C. Gestión Pto #1'!$B$4:E$4,0),FALSE),0),0) -> 4065955.3 | G16: =IFERROR(SUM(VLOOKUP($B16&$C16,'C. Gestión Pto #1'!$B$4:F$17,MATCH(G$5,'C. Gestión Pto #1'!$B$4:F$4,0),FALSE),0),0) -> 2170465.8 | H16: =IFERROR(SUM(VLOOKUP($B16&$C16,'C. Gestión Pto #1'!$B$4:G$17,MATCH(H$5,'C. Gestión Pto #1'!$B$4:G$4,0),FALSE),0),0) -> 452739.93 | I16: =IFERROR(SUM(VLOOKUP($B16&$C16,'C. Gestión Pto #1'!$B$4:H$17,MATCH(I$5,'C. Gestión Pto #1'!$B$4:H$4,0),FALSE),0),0) -> 333787.7 | J16: =SUM(IFERROR(VLOOKUP($B16&$C16,'C. Gestión Pto #1'!$B$4:I$17,MATCH(J$5,'C. Gestión Pto #1'!$B$4:I$4,0),FALSE),0),IFERROR(VLOOKUP($B16&$C16,'C. Gestión Pto #2'!$B$4:C$23,MATCH(J$5,'C. Gestión Pto #2'!$B$4:C$4,0),FALSE),0)) -> 0 | K16: =SUM(IFERROR(VLOOKUP($B16&$C16,'C. Gestión Pto #1'!$B$4:J$17,MATCH(K$5,'C. Gestión Pto #1'!$B$4:J$4,0),FALSE),0),IFERROR(VLOOKUP($B16&$C16,'C. Gestión Pto #2'!$B$4:D$23,MATCH(K$5,'C. Gestión Pto #2'!$B$4:D$4,0),FALSE),0)) -> 0 | L16: =SUM(IFERROR(VLOOKUP($B16&$C16,'C. Gestión Pto #1'!$B$4:K$17,MATCH(L$5,'C. Gestión Pto #1'!$B$4:K$4,0),FALSE),0),IFERROR(VLOOKUP($B16&$C16,'C. Gestión Pto #2'!$B$4:E$23,MATCH(L$5,'C. Gestión Pto #2'!$B$4:E$4,0),FALSE),0)) -> 0 | M16: =SUM(IFERROR(VLOOKUP($B16&$C16,'C. Gestión Pto #1'!$B$4:L$17,MATCH(M$5,'C. Gestión Pto #1'!$B$4:L$4,0),FALSE),0),IFERROR(VLOOKUP($B16&$C16,'C. Gestión Pto #2'!$B$4:F$23,MATCH(M$5,'C. Gestión Pto #2'!$B$4:F$4,0),FALSE),0)) -> 562822.2 | N16: =SUM(IFERROR(VLOOKUP($B16&$C16,'C. Gestión Pto #1'!$B$4:M$17,MATCH(N$5,'C. Gestión Pto #1'!$B$4:M$4,0),FALSE),0),IFERROR(VLOOKUP($B16&$C16,'C. Gestión Pto #2'!$B$4:G$23,MATCH(N$5,'C. Gestión Pto #2'!$B$4:G$4,0),FALSE),0)) -> 202741.83 | O16: =SUM(IFERROR(VLOOKUP($B16&$C16,'C. Gestión Pto #1'!$B$4:N$17,MATCH(O$5,'C. Gestión Pto #1'!$B$4:N$4,0),FALSE),0),IFERROR(VLOOKUP($B16&$C16,'C. Gestión Pto #2'!$B$4:H$23,MATCH(O$5,'C. Gestión Pto #2'!$B$4:H$4,0),FALSE),0)) -> 0 | P16: =SUM(IFERROR(VLOOKUP($B16&$C16,'C. Gestión Pto #1'!$B$4:O$17,MATCH(P$5,'C. Gestión Pto #1'!$B$4:O$4,0),FALSE),0),IFERROR(VLOOKUP($B16&$C16,'C. Gestión Pto #2'!$B$4:I$23,MATCH(P$5,'C. Gestión Pto #2'!$B$4:I$4,0),FALSE),0)) -> 0 | Q16: =SUM(IFERROR(VLOOKUP($B16&$C16,'C. Gestión Pto #1'!$B$4:P$17,MATCH(Q$5,'C. Gestión Pto #1'!$B$4:P$4,0),FALSE),0),IFERROR(VLOOKUP($B16&$C16,'C. Gestión Pto #2'!$B$4:J$23,MATCH(Q$5,'C. Gestión Pto #2'!$B$4:J$4,0),FALSE),0)) -> 0 | ... T16: =SUM(IFERROR(VLOOKUP($B16&$C16,'C. Gestión Pto #1'!$B$4:S$17,MATCH(T$5,'C. Gestión Pto #1'!$B$4:S$4,0),FALSE),0),IFERROR(VLOOKUP($B16&$C16,'C. Gestión Pto #2'!$B$4:M$23,MATCH(T$5,'C. Gestión Pto #2'!$B$4:M$4,0),FALSE),0)) -> 0 | V16: {=SUMPRODUCT($D16:$U16,TRANSPOSE('Indice CAC'!$C$10:$C$27))} -> 9642624.1 | X16: ='Resumen Pto #1'!X16 -> 9593785.3 | Y16: 0 | Z16: =SUM(X16:Y16) -> 9593785.3 | AA16: =IF(C16="MAT",SUMIF('Pto. 01 Cert.'!$A$10:$A$57,$B16,'Pto. 01 Cert.'!$T$10:$T$57),IF(C16="MO",SUMIF('Pto. 01 Cert.'!$A$10:$A$57,$B16,'Pto. 01 Cert.'!$U$10:$U$57),SUMIF('Pto. 01 Cert.'!$A$10:$A$57,$B16,'Pto. 01 Cert.'!$V$10:$V$57)))/IF(C16="MAT",SUMIF('Pto. 01 Cert.'!$A$10:$A$57,$B16,'Pto. 01 Cert.'!$I$10:$I$57),IF(C16="MO",SUMIF('Pto. 01 Cert.'!$A$10:$A$57,$B16,'Pto. 01 Cert.'!$J$10:$J$57),SUMIF('Pto. 01 Cert.'!$A$10:$A$57,$B16,'Pto. 01 Cert.'!$K$10:$K$57))) -> 1 | AB16: =IF(AA16=100%,0,IF(OR(V16<>0,Z16),Z16-V16)) -> 0 | AC16: =IF(OR(AB16<0,Z16),AB16/Z16,0%) -> 0 | AD16: =IF(AA16=100%,IF(OR(V16<>0,Z16),Z16-V16),0) -> -48838.787
B17: Depresion de napas | D17: =IFERROR(SUM(VLOOKUP($B17&$C17,'C. Gestión Pto #1'!$B$4:C$17,MATCH(D$5,'C. Gestión Pto #1'!$B$4:C$4,0),FALSE),0),0) -> 0 | E17: =IFERROR(SUM(VLOOKUP($B17&$C17,'C. Gestión Pto #1'!$B$4:D$17,MATCH(E$5,'C. Gestión Pto #1'!$B$4:D$4,0),FALSE),0),0) -> 3900000 | F17: =IFERROR(SUM(VLOOKUP($B17&$C17,'C. Gestión Pto #1'!$B$4:E$17,MATCH(F$5,'C. Gestión Pto #1'!$B$4:E$4,0),FALSE),0),0) -> 3900000 | G17: =IFERROR(SUM(VLOOKUP($B17&$C17,'C. Gestión Pto #1'!$B$4:F$17,MATCH(G$5,'C. Gestión Pto #1'!$B$4:F$4,0),FALSE),0),0) -> 0 | H17: =IFERROR(SUM(VLOOKUP($B17&$C17,'C. Gestión Pto #1'!$B$4:G$17,MATCH(H$5,'C. Gestión Pto #1'!$B$4:G$4,0),FALSE),0),0) -> 0 | I17: =IFERROR(SUM(VLOOKUP($B17&$C17,'C. Gestión Pto #1'!$B$4:H$17,MATCH(I$5,'C. Gestión Pto #1'!$B$4:H$4,0),FALSE),0),0) -> 0 | J17: =SUM(IFERROR(VLOOKUP($B17&$C17,'C. Gestión Pto #1'!$B$4:I$17,MATCH(J$5,'C. Gestión Pto #1'!$B$4:I$4,0),FALSE),0),IFERROR(VLOOKUP($B17&$C17,'C. Gestión Pto #2'!$B$4:C$23,MATCH(J$5,'C. Gestión Pto #2'!$B$4:C$4,0),FALSE),0)) -> 0 | K17: =SUM(IFERROR(VLOOKUP($B17&$C17,'C. Gestión Pto #1'!$B$4:J$17,MATCH(K$5,'C. Gestión Pto #1'!$B$4:J$4,0),FALSE),0),IFERROR(VLOOKUP($B17&$C17,'C. Gestión Pto #2'!$B$4:D$23,MATCH(K$5,'C. Gestión Pto #2'!$B$4:D$4,0),FALSE),0)) -> 0 | L17: =SUM(IFERROR(VLOOKUP($B17&$C17,'C. Gestión Pto #1'!$B$4:K$17,MATCH(L$5,'C. Gestión Pto #1'!$B$4:K$4,0),FALSE),0),IFERROR(VLOOKUP($B17&$C17,'C. Gestión Pto #2'!$B$4:E$23,MATCH(L$5,'C. Gestión Pto #2'!$B$4:E$4,0),FALSE),0)) -> 0 | M17: =SUM(IFERROR(VLOOKUP($B17&$C17,'C. Gestión Pto #1'!$B$4:L$17,MATCH(M$5,'C. Gestión Pto #1'!$B$4:L$4,0),FALSE),0),IFERROR(VLOOKUP($B17&$C17,'C. Gestión Pto #2'!$B$4:F$23,MATCH(M$5,'C. Gestión Pto #2'!$B$4:F$4,0),FALSE),0)) -> 0 | N17: =SUM(IFERROR(VLOOKUP($B17&$C17,'C. Gestión Pto #1'!$B$4:M$17,MATCH(N$5,'C. Gestión Pto #1'!$B$4:M$4,0),FALSE),0),IFERROR(VLOOKUP($B17&$C17,'C. Gestión Pto #2'!$B$4:G$23,MATCH(N$5,'C. Gestión Pto #2'!$B$4:G$4,0),FALSE),0)) -> 0 | O17: =SUM(IFERROR(VLOOKUP($B17&$C17,'C. Gestión Pto #1'!$B$4:N$17,MATCH(O$5,'C. Gestión Pto #1'!$B$4:N$4,0),FALSE),0),IFERROR(VLOOKUP($B17&$C17,'C. Gestión Pto #2'!$B$4:H$23,MATCH(O$5,'C. Gestión Pto #2'!$B$4:H$4,0),FALSE),0)) -> 0 | P17: =SUM(IFERROR(VLOOKUP($B17&$C17,'C. Gestión Pto #1'!$B$4:O$17,MATCH(P$5,'C. Gestión Pto #1'!$B$4:O$4,0),FALSE),0),IFERROR(VLOOKUP($B17&$C17,'C. Gestión Pto #2'!$B$4:I$23,MATCH(P$5,'C. Gestión Pto #2'!$B$4:I$4,0),FALSE),0)) -> 0 | Q17: =SUM(IFERROR(VLOOKUP($B17&$C17,'C. Gestión Pto #1'!$B$4:P$17,MATCH(Q$5,'C. Gestión Pto #1'!$B$4:P$4,0),FALSE),0),IFERROR(VLOOKUP($B17&$C17,'C. Gestión Pto #2'!$B$4:J$23,MATCH(Q$5,'C. Gestión Pto #2'!$B$4:J$4,0),FALSE),0)) -> 0 | ... T17: =SUM(IFERROR(VLOOKUP($B17&$C17,'C. Gestión Pto #1'!$B$4:S$17,MATCH(T$5,'C. Gestión Pto #1'!$B$4:S$4,0),FALSE),0),IFERROR(VLOOKUP($B17&$C17,'C. Gestión Pto #2'!$B$4:M$23,MATCH(T$5,'C. Gestión Pto #2'!$B$4:M$4,0),FALSE),0)) -> 0 | V17: {=SUMPRODUCT($D17:$U17,TRANSPOSE('Indice CAC'!$C$10:$C$27))} -> 7037477 | X17: ='Resumen Pto #1'!X17 -> 7800000 | Y17: 0 | Z17: =SUM(X17:Y17) -> 7800000 | AA17: =IF(C17="MAT",SUMIF('Pto. 01 Cert.'!$A$10:$A$57,$B17,'Pto. 01 Cert.'!$T$10:$T$57),IF(C17="MO",SUMIF('Pto. 01 Cert.'!$A$10:$A$57,$B17,'Pto. 01 Cert.'!$U$10:$U$57),SUMIF('Pto. 01 Cert.'!$A$10:$A$57,$B17,'Pto. 01 Cert.'!$V$10:$V$57)))/IF(C17="MAT",SUMIF('Pto. 01 Cert.'!$A$10:$A$57,$B17,'Pto. 01 Cert.'!$I$10:$I$57),IF(C17="MO",SUMIF('Pto. 01 Cert.'!$A$10:$A$57,$B17,'Pto. 01 Cert.'!$J$10:$J$57),SUMIF('Pto. 01 Cert.'!$A$10:$A$57,$B17,'Pto. 01 Cert.'!$K$10:$K$57))) -> 1 | AB17: =IF(AA17=100%,0,IF(OR(V17<>0,Z17),Z17-V17)) -> 0 | AC17: =IF(OR(AB17<0,Z17),AB17/Z17,0%) -> 0 | AD17: =IF(AA17=100%,IF(OR(V17<>0,Z17),Z17-V17),0) -> 762523.04
B18: Agrimensura | D18: =IFERROR(SUM(VLOOKUP($B18&$C18,'C. Gestión Pto #1'!$B$4:C$17,MATCH(D$5,'C. Gestión Pto #1'!$B$4:C$4,0),FALSE),0),0) -> 150000 | E18: =IFERROR(SUM(VLOOKUP($B18&$C18,'C. Gestión Pto #1'!$B$4:D$17,MATCH(E$5,'C. Gestión Pto #1'!$B$4:D$4,0),FALSE),0),0) -> 0 | F18: =IFERROR(SUM(VLOOKUP($B18&$C18,'C. Gestión Pto #1'!$B$4:E$17,MATCH(F$5,'C. Gestión Pto #1'!$B$4:E$4,0),FALSE),0),0) -> 150000 | G18: =IFERROR(SUM(VLOOKUP($B18&$C18,'C. Gestión Pto #1'!$B$4:F$17,MATCH(G$5,'C. Gestión Pto #1'!$B$4:F$4,0),FALSE),0),0) -> 0 | H18: =IFERROR(SUM(VLOOKUP($B18&$C18,'C. Gestión Pto #1'!$B$4:G$17,MATCH(H$5,'C. Gestión Pto #1'!$B$4:G$4,0),FALSE),0),0) -> 0 | I18: =IFERROR(SUM(VLOOKUP($B18&$C18,'C. Gestión Pto #1'!$B$4:H$17,MATCH(I$5,'C. Gestión Pto #1'!$B$4:H$4,0),FALSE),0),0) -> 0 | J18: =SUM(IFERROR(VLOOKUP($B18&$C18,'C. Gestión Pto #1'!$B$4:I$17,MATCH(J$5,'C. Gestión Pto #1'!$B$4:I$4,0),FALSE),0),IFERROR(VLOOKUP($B18&$C18,'C. Gestión Pto #2'!$B$4:C$23,MATCH(J$5,'C. Gestión Pto #2'!$B$4:C$4,0),FALSE),0)) -> 0 | K18: =SUM(IFERROR(VLOOKUP($B18&$C18,'C. Gestión Pto #1'!$B$4:J$17,MATCH(K$5,'C. Gestión Pto #1'!$B$4:J$4,0),FALSE),0),IFERROR(VLOOKUP($B18&$C18,'C. Gestión Pto #2'!$B$4:D$23,MATCH(K$5,'C. Gestión Pto #2'!$B$4:D$4,0),FALSE),0)) -> 0 | L18: =SUM(IFERROR(VLOOKUP($B18&$C18,'C. Gestión Pto #1'!$B$4:K$17,MATCH(L$5,'C. Gestión Pto #1'!$B$4:K$4,0),FALSE),0),IFERROR(VLOOKUP($B18&$C18,'C. Gestión Pto #2'!$B$4:E$23,MATCH(L$5,'C. Gestión Pto #2'!$B$4:E$4,0),FALSE),0)) -> 0 | M18: =SUM(IFERROR(VLOOKUP($B18&$C18,'C. Gestión Pto #1'!$B$4:L$17,MATCH(M$5,'C. Gestión Pto #1'!$B$4:L$4,0),FALSE),0),IFERROR(VLOOKUP($B18&$C18,'C. Gestión Pto #2'!$B$4:F$23,MATCH(M$5,'C. Gestión Pto #2'!$B$4:F$4,0),FALSE),0)) -> 0 | N18: =SUM(IFERROR(VLOOKUP($B18&$C18,'C. Gestión Pto #1'!$B$4:M$17,MATCH(N$5,'C. Gestión Pto #1'!$B$4:M$4,0),FALSE),0),IFERROR(VLOOKUP($B18&$C18,'C. Gestión Pto #2'!$B$4:G$23,MATCH(N$5,'C. Gestión Pto #2'!$B$4:G$4,0),FALSE),0)) -> 0 | O18: =SUM(IFERROR(VLOOKUP($B18&$C18,'C. Gestión Pto #1'!$B$4:N$17,MATCH(O$5,'C. Gestión Pto #1'!$B$4:N$4,0),FALSE),0),IFERROR(VLOOKUP($B18&$C18,'C. Gestión Pto #2'!$B$4:H$23,MATCH(O$5,'C. Gestión Pto #2'!$B$4:H$4,0),FALSE),0)) -> 0 | P18: =SUM(IFERROR(VLOOKUP($B18&$C18,'C. Gestión Pto #1'!$B$4:O$17,MATCH(P$5,'C. Gestión Pto #1'!$B$4:O$4,0),FALSE),0),IFERROR(VLOOKUP($B18&$C18,'C. Gestión Pto #2'!$B$4:I$23,MATCH(P$5,'C. Gestión Pto #2'!$B$4:I$4,0),FALSE),0)) -> 0 | Q18: =SUM(IFERROR(VLOOKUP($B18&$C18,'C. Gestión Pto #1'!$B$4:P$17,MATCH(Q$5,'C. Gestión Pto #1'!$B$4:P$4,0),FALSE),0),IFERROR(VLOOKUP($B18&$C18,'C. Gestión Pto #2'!$B$4:J$23,MATCH(Q$5,'C. Gestión Pto #2'!$B$4:J$4,0),FALSE),0)) -> 0 | ... T18: =SUM(IFERROR(VLOOKUP($B18&$C18,'C. Gestión Pto #1'!$B$4:S$17,MATCH(T$5,'C. Gestión Pto #1'!$B$4:S$4,0),FALSE),0),IFERROR(VLOOKUP($B18&$C18,'C. Gestión Pto #2'!$B$4:M$23,MATCH(T$5,'C. Gestión Pto #2'!$B$4:M$4,0),FALSE),0)) -> 0 | V18: {=SUMPRODUCT($D18:$U18,TRANSPOSE('Indice CAC'!$C$10:$C$27))} -> 272938.14 | X18: ='Resumen Pto #1'!X18 -> 892630.81 | Y18: 0 | Z18: =SUM(X18:Y18) -> 892630.81 | AA18: =IF(C18="MAT",SUMIF('Pto. 01 Cert.'!$A$10:$A$57,$B18,'Pto. 01 Cert.'!$T$10:$T$57),IF(C18="MO",SUMIF('Pto. 01 Cert.'!$A$10:$A$57,$B18,'Pto. 01 Cert.'!$U$10:$U$57),SUMIF('Pto. 01 Cert.'!$A$10:$A$57,$B18,'Pto. 01 Cert.'!$V$10:$V$57)))/IF(C18="MAT",SUMIF('Pto. 01 Cert.'!$A$10:$A$57,$B18,'Pto. 01 Cert.'!$I$10:$I$57),IF(C18="MO",SUMIF('Pto. 01 Cert.'!$A$10:$A$57,$B18,'Pto. 01 Cert.'!$J$10:$J$57),SUMIF('Pto. 01 Cert.'!$A$10:$A$57,$B18,'Pto. 01 Cert.'!$K$10:$K$57))) -> 1 | AB18: =IF(AA18=100%,0,IF(OR(V18<>0,Z18),Z18-V18)) -> 0 | AC18: =IF(OR(AB18<0,Z18),AB18/Z18,0%) -> 0 | AD18: =IF(AA18=100%,IF(OR(V18<>0,Z18),Z18-V18),0) -> 619692.67
B19: Excavación y Mov. de Suelos | D19: =IFERROR(SUM(VLOOKUP($B19&$C19,'C. Gestión Pto #1'!$B$4:C$17,MATCH(D$5,'C. Gestión Pto #1'!$B$4:C$4,0),FALSE),0),0) -> 0 | E19: =IFERROR(SUM(VLOOKUP($B19&$C19,'C. Gestión Pto #1'!$B$4:D$17,MATCH(E$5,'C. Gestión Pto #1'!$B$4:D$4,0),FALSE),0),0) -> 2555627 | F19: =IFERROR(SUM(VLOOKUP($B19&$C19,'C. Gestión Pto #1'!$B$4:E$17,MATCH(F$5,'C. Gestión Pto #1'!$B$4:E$4,0),FALSE),0),0) -> 0 | G19: =IFERROR(SUM(VLOOKUP($B19&$C19,'C. Gestión Pto #1'!$B$4:F$17,MATCH(G$5,'C. Gestión Pto #1'!$B$4:F$4,0),FALSE),0),0) -> 5000000 | H19: =IFERROR(SUM(VLOOKUP($B19&$C19,'C. Gestión Pto #1'!$B$4:G$17,MATCH(H$5,'C. Gestión Pto #1'!$B$4:G$4,0),FALSE),0),0) -> 5000000 | I19: =IFERROR(SUM(VLOOKUP($B19&$C19,'C. Gestión Pto #1'!$B$4:H$17,MATCH(I$5,'C. Gestión Pto #1'!$B$4:H$4,0),FALSE),0),0) -> 5812500 | J19: =SUM(IFERROR(VLOOKUP($B19&$C19,'C. Gestión Pto #1'!$B$4:I$17,MATCH(J$5,'C. Gestión Pto #1'!$B$4:I$4,0),FALSE),0),IFERROR(VLOOKUP($B19&$C19,'C. Gestión Pto #2'!$B$4:C$23,MATCH(J$5,'C. Gestión Pto #2'!$B$4:C$4,0),FALSE),0)) -> 0 | K19: =SUM(IFERROR(VLOOKUP($B19&$C19,'C. Gestión Pto #1'!$B$4:J$17,MATCH(K$5,'C. Gestión Pto #1'!$B$4:J$4,0),FALSE),0),IFERROR(VLOOKUP($B19&$C19,'C. Gestión Pto #2'!$B$4:D$23,MATCH(K$5,'C. Gestión Pto #2'!$B$4:D$4,0),FALSE),0)) -> 6430886.4 | L19: =SUM(IFERROR(VLOOKUP($B19&$C19,'C. Gestión Pto #1'!$B$4:K$17,MATCH(L$5,'C. Gestión Pto #1'!$B$4:K$4,0),FALSE),0),IFERROR(VLOOKUP($B19&$C19,'C. Gestión Pto #2'!$B$4:E$23,MATCH(L$5,'C. Gestión Pto #2'!$B$4:E$4,0),FALSE),0)) -> 0 | M19: =SUM(IFERROR(VLOOKUP($B19&$C19,'C. Gestión Pto #1'!$B$4:L$17,MATCH(M$5,'C. Gestión Pto #1'!$B$4:L$4,0),FALSE),0),IFERROR(VLOOKUP($B19&$C19,'C. Gestión Pto #2'!$B$4:F$23,MATCH(M$5,'C. Gestión Pto #2'!$B$4:F$4,0),FALSE),0)) -> 0 | N19: =SUM(IFERROR(VLOOKUP($B19&$C19,'C. Gestión Pto #1'!$B$4:M$17,MATCH(N$5,'C. Gestión Pto #1'!$B$4:M$4,0),FALSE),0),IFERROR(VLOOKUP($B19&$C19,'C. Gestión Pto #2'!$B$4:G$23,MATCH(N$5,'C. Gestión Pto #2'!$B$4:G$4,0),FALSE),0)) -> 0 | O19: =SUM(IFERROR(VLOOKUP($B19&$C19,'C. Gestión Pto #1'!$B$4:N$17,MATCH(O$5,'C. Gestión Pto #1'!$B$4:N$4,0),FALSE),0),IFERROR(VLOOKUP($B19&$C19,'C. Gestión Pto #2'!$B$4:H$23,MATCH(O$5,'C. Gestión Pto #2'!$B$4:H$4,0),FALSE),0)) -> 0 | P19: =SUM(IFERROR(VLOOKUP($B19&$C19,'C. Gestión Pto #1'!$B$4:O$17,MATCH(P$5,'C. Gestión Pto #1'!$B$4:O$4,0),FALSE),0),IFERROR(VLOOKUP($B19&$C19,'C. Gestión Pto #2'!$B$4:I$23,MATCH(P$5,'C. Gestión Pto #2'!$B$4:I$4,0),FALSE),0)) -> 0 | Q19: =SUM(IFERROR(VLOOKUP($B19&$C19,'C. Gestión Pto #1'!$B$4:P$17,MATCH(Q$5,'C. Gestión Pto #1'!$B$4:P$4,0),FALSE),0),IFERROR(VLOOKUP($B19&$C19,'C. Gestión Pto #2'!$B$4:J$23,MATCH(Q$5,'C. Gestión Pto #2'!$B$4:J$4,0),FALSE),0)) -> 0 | ... T19: =SUM(IFERROR(VLOOKUP($B19&$C19,'C. Gestión Pto #1'!$B$4:S$17,MATCH(T$5,'C. Gestión Pto #1'!$B$4:S$4,0),FALSE),0),IFERROR(VLOOKUP($B19&$C19,'C. Gestión Pto #2'!$B$4:M$23,MATCH(T$5,'C. Gestión Pto #2'!$B$4:M$4,0),FALSE),0)) -> 0 | V19: {=SUMPRODUCT($D19:$U19,TRANSPOSE('Indice CAC'!$C$10:$C$27))} -> 21476728 | X19: ='Resumen Pto #1'!X19 -> 23294400 | Y19: 0 | Z19: =SUM(X19:Y19) -> 23294400 | AA19: =IF(C19="MAT",SUMIF('Pto. 01 Cert.'!$A$10:$A$57,$B19,'Pto. 01 Cert.'!$T$10:$T$57),IF(C19="MO",SUMIF('Pto. 01 Cert.'!$A$10:$A$57,$B19,'Pto. 01 Cert.'!$U$10:$U$57),SUMIF('Pto. 01 Cert.'!$A$10:$A$57,$B19,'Pto. 01 Cert.'!$V$10:$V$57)))/IF(C19="MAT",SUMIF('Pto. 01 Cert.'!$A$10:$A$57,$B19,'Pto. 01 Cert.'!$I$10:$I$57),IF(C19="MO",SUMIF('Pto. 01 Cert.'!$A$10:$A$57,$B19,'Pto. 01 Cert.'!$J$10:$J$57),SUMIF('Pto. 01 Cert.'!$A$10:$A$57,$B19,'Pto. 01 Cert.'!$K$10:$K$57))) -> 1 | AB19: =IF(AA19=100%,0,IF(OR(V19<>0,Z19),Z19-V19)) -> 0 | AC19: =IF(OR(AB19<0,Z19),AB19/Z19,0%) -> 0 | AD19: =IF(AA19=100%,IF(OR(V19<>0,Z19),Z19-V19),0) -> 1817672.1
B20: Hormigón | C20: MAT | D20: =IFERROR(SUM(VLOOKUP($B20&$C20,'C. Gestión Pto #1'!$B$4:C$17,MATCH(D$5,'C. Gestión Pto #1'!$B$4:C$4,0),FALSE),0),0) -> 0 | E20: =IFERROR(SUM(VLOOKUP($B20&$C20,'C. Gestión Pto #1'!$B$4:D$17,MATCH(E$5,'C. Gestión Pto #1'!$B$4:D$4,0),FALSE),0),0) -> 7421307.2 | F20: =IFERROR(SUM(VLOOKUP($B20&$C20,'C. Gestión Pto #1'!$B$4:E$17,MATCH(F$5,'C. Gestión Pto #1'!$B$4:E$4,0),FALSE),0),0) -> 934481.37 | G20: =IFERROR(SUM(VLOOKUP($B20&$C20,'C. Gestión Pto #1'!$B$4:F$17,MATCH(G$5,'C. Gestión Pto #1'!$B$4:F$4,0),FALSE),0),0) -> 6221403.1 | H20: =IFERROR(SUM(VLOOKUP($B20&$C20,'C. Gestión Pto #1'!$B$4:G$17,MATCH(H$5,'C. Gestión Pto #1'!$B$4:G$4,0),FALSE),0),0) -> 3385750.4 | I20: =IFERROR(SUM(VLOOKUP($B20&$C20,'C. Gestión Pto #1'!$B$4:H$17,MATCH(I$5,'C. Gestión Pto #1'!$B$4:H$4,0),FALSE),0),0) -> 3530590.8 | J20: =SUM(IFERROR(VLOOKUP($B20&$C20,'C. Gestión Pto #1'!$B$4:I$17,MATCH(J$5,'C. Gestión Pto #1'!$B$4:I$4,0),FALSE),0),IFERROR(VLOOKUP($B20&$C20,'C. Gestión Pto #2'!$B$4:C$23,MATCH(J$5,'C. Gestión Pto #2'!$B$4:C$4,0),FALSE),0)) -> 0 | K20: =SUM(IFERROR(VLOOKUP($B20&$C20,'C. Gestión Pto #1'!$B$4:J$17,MATCH(K$5,'C. Gestión Pto #1'!$B$4:J$4,0),FALSE),0),IFERROR(VLOOKUP($B20&$C20,'C. Gestión Pto #2'!$B$4:D$23,MATCH(K$5,'C. Gestión Pto #2'!$B$4:D$4,0),FALSE),0)) -> 3744037.3 | L20: =SUM(IFERROR(VLOOKUP($B20&$C20,'C. Gestión Pto #1'!$B$4:K$17,MATCH(L$5,'C. Gestión Pto #1'!$B$4:K$4,0),FALSE),0),IFERROR(VLOOKUP($B20&$C20,'C. Gestión Pto #2'!$B$4:E$23,MATCH(L$5,'C. Gestión Pto #2'!$B$4:E$4,0),FALSE),0)) -> 1646601.2 | M20: =SUM(IFERROR(VLOOKUP($B20&$C20,'C. Gestión Pto #1'!$B$4:L$17,MATCH(M$5,'C. Gestión Pto #1'!$B$4:L$4,0),FALSE),0),IFERROR(VLOOKUP($B20&$C20,'C. Gestión Pto #2'!$B$4:F$23,MATCH(M$5,'C. Gestión Pto #2'!$B$4:F$4,0),FALSE),0)) -> 4258986.7 | N20: =SUM(IFERROR(VLOOKUP($B20&$C20,'C. Gestión Pto #1'!$B$4:M$17,MATCH(N$5,'C. Gestión Pto #1'!$B$4:M$4,0),FALSE),0),IFERROR(VLOOKUP($B20&$C20,'C. Gestión Pto #2'!$B$4:G$23,MATCH(N$5,'C. Gestión Pto #2'!$B$4:G$4,0),FALSE),0)) -> 1572093.6 | O20: =SUM(IFERROR(VLOOKUP($B20&$C20,'C. Gestión Pto #1'!$B$4:N$17,MATCH(O$5,'C. Gestión Pto #1'!$B$4:N$4,0),FALSE),0),IFERROR(VLOOKUP($B20&$C20,'C. Gestión Pto #2'!$B$4:H$23,MATCH(O$5,'C. Gestión Pto #2'!$B$4:H$4,0),FALSE),0)) -> 190000 | P20: =SUM(IFERROR(VLOOKUP($B20&$C20,'C. Gestión Pto #1'!$B$4:O$17,MATCH(P$5,'C. Gestión Pto #1'!$B$4:O$4,0),FALSE),0),IFERROR(VLOOKUP($B20&$C20,'C. Gestión Pto #2'!$B$4:I$23,MATCH(P$5,'C. Gestión Pto #2'!$B$4:I$4,0),FALSE),0)) -> 475000 | Q20: =SUM(IFERROR(VLOOKUP($B20&$C20,'C. Gestión Pto #1'!$B$4:P$17,MATCH(Q$5,'C. Gestión Pto #1'!$B$4:P$4,0),FALSE),0),IFERROR(VLOOKUP($B20&$C20,'C. Gestión Pto #2'!$B$4:J$23,MATCH(Q$5,'C. Gestión Pto #2'!$B$4:J$4,0),FALSE),0)) -> 0 | ... T20: =SUM(IFERROR(VLOOKUP($B20&$C20,'C. Gestión Pto #1'!$B$4:S$17,MATCH(T$5,'C. Gestión Pto #1'!$B$4:S$4,0),FALSE),0),IFERROR(VLOOKUP($B20&$C20,'C. Gestión Pto #2'!$B$4:M$23,MATCH(T$5,'C. Gestión Pto #2'!$B$4:M$4,0),FALSE),0)) -> 0 | V20: {=SUMPRODUCT($D20:$U20,TRANSPOSE('Indice CAC'!$C$10:$C$27))} -> 28825229 | X20: ='Resumen Pto #1'!X20 -> 39767922 | Y20: 0 | Z20: =SUM(X20:Y20) -> 39767922 | AA20: =IF(C20="MAT",SUMIF('Pto. 01 Cert.'!$A$10:$A$57,$B20,'Pto. 01 Cert.'!$T$10:$T$57),IF(C20="MO",SUMIF('Pto. 01 Cert.'!$A$10:$A$57,$B20,'Pto. 01 Cert.'!$U$10:$U$57),SUMIF('Pto. 01 Cert.'!$A$10:$A$57,$B20,'Pto. 01 Cert.'!$V$10:$V$57)))/IF(C20="MAT",SUMIF('Pto. 01 Cert.'!$A$10:$A$57,$B20,'Pto. 01 Cert.'!$I$10:$I$57),IF(C20="MO",SUMIF('Pto. 01 Cert.'!$A$10:$A$57,$B20,'Pto. 01 Cert.'!$J$10:$J$57),SUMIF('Pto. 01 Cert.'!$A$10:$A$57,$B20,'Pto. 01 Cert.'!$K$10:$K$57))) -> 1 | AB20: =IF(AA20=100%,0,IF(OR(V20<>0,Z20),Z20-V20)) -> 0 | AC20: =IF(OR(AB20<0,Z20),AB20/Z20,0%) -> 0 | AD20: =IF(AA20=100%,IF(OR(V20<>0,Z20),Z20-V20),0) -> 10942694
B21: Hormigón | C21: MO | D21: =IFERROR(SUM(VLOOKUP($B21&$C21,'C. Gestión Pto #1'!$B$4:C$17,MATCH(D$5,'C. Gestión Pto #1'!$B$4:C$4,0),FALSE),0),0) -> 0 | E21: =IFERROR(SUM(VLOOKUP($B21&$C21,'C. Gestión Pto #1'!$B$4:D$17,MATCH(E$5,'C. Gestión Pto #1'!$B$4:D$4,0),FALSE),0),0) -> 0 | F21: =IFERROR(SUM(VLOOKUP($B21&$C21,'C. Gestión Pto #1'!$B$4:E$17,MATCH(F$5,'C. Gestión Pto #1'!$B$4:E$4,0),FALSE),0),0) -> 2102991.6 | G21: =IFERROR(SUM(VLOOKUP($B21&$C21,'C. Gestión Pto #1'!$B$4:F$17,MATCH(G$5,'C. Gestión Pto #1'!$B$4:F$4,0),FALSE),0),0) -> 17862837 | H21: =IFERROR(SUM(VLOOKUP($B21&$C21,'C. Gestión Pto #1'!$B$4:G$17,MATCH(H$5,'C. Gestión Pto #1'!$B$4:G$4,0),FALSE),0),0) -> 18399394 | I21: =IFERROR(SUM(VLOOKUP($B21&$C21,'C. Gestión Pto #1'!$B$4:H$17,MATCH(I$5,'C. Gestión Pto #1'!$B$4:H$4,0),FALSE),0),0) -> 21489375 | J21: =SUM(IFERROR(VLOOKUP($B21&$C21,'C. Gestión Pto #1'!$B$4:I$17,MATCH(J$5,'C. Gestión Pto #1'!$B$4:I$4,0),FALSE),0),IFERROR(VLOOKUP($B21&$C21,'C. Gestión Pto #2'!$B$4:C$23,MATCH(J$5,'C. Gestión Pto #2'!$B$4:C$4,0),FALSE),0)) -> 26401198 | K21: =SUM(IFERROR(VLOOKUP($B21&$C21,'C. Gestión Pto #1'!$B$4:J$17,MATCH(K$5,'C. Gestión Pto #1'!$B$4:J$4,0),FALSE),0),IFERROR(VLOOKUP($B21&$C21,'C. Gestión Pto #2'!$B$4:D$23,MATCH(K$5,'C. Gestión Pto #2'!$B$4:D$4,0),FALSE),0)) -> 22702901 | L21: =SUM(IFERROR(VLOOKUP($B21&$C21,'C. Gestión Pto #1'!$B$4:K$17,MATCH(L$5,'C. Gestión Pto #1'!$B$4:K$4,0),FALSE),0),IFERROR(VLOOKUP($B21&$C21,'C. Gestión Pto #2'!$B$4:E$23,MATCH(L$5,'C. Gestión Pto #2'!$B$4:E$4,0),FALSE),0)) -> 26719160 | M21: =SUM(IFERROR(VLOOKUP($B21&$C21,'C. Gestión Pto #1'!$B$4:L$17,MATCH(M$5,'C. Gestión Pto #1'!$B$4:L$4,0),FALSE),0),IFERROR(VLOOKUP($B21&$C21,'C. Gestión Pto #2'!$B$4:F$23,MATCH(M$5,'C. Gestión Pto #2'!$B$4:F$4,0),FALSE),0)) -> 31168841 | N21: =SUM(IFERROR(VLOOKUP($B21&$C21,'C. Gestión Pto #1'!$B$4:M$17,MATCH(N$5,'C. Gestión Pto #1'!$B$4:M$4,0),FALSE),0),IFERROR(VLOOKUP($B21&$C21,'C. Gestión Pto #2'!$B$4:G$23,MATCH(N$5,'C. Gestión Pto #2'!$B$4:G$4,0),FALSE),0)) -> 30645862 | O21: =SUM(IFERROR(VLOOKUP($B21&$C21,'C. Gestión Pto #1'!$B$4:N$17,MATCH(O$5,'C. Gestión Pto #1'!$B$4:N$4,0),FALSE),0),IFERROR(VLOOKUP($B21&$C21,'C. Gestión Pto #2'!$B$4:H$23,MATCH(O$5,'C. Gestión Pto #2'!$B$4:H$4,0),FALSE),0)) -> 29665403 | P21: =SUM(IFERROR(VLOOKUP($B21&$C21,'C. Gestión Pto #1'!$B$4:O$17,MATCH(P$5,'C. Gestión Pto #1'!$B$4:O$4,0),FALSE),0),IFERROR(VLOOKUP($B21&$C21,'C. Gestión Pto #2'!$B$4:I$23,MATCH(P$5,'C. Gestión Pto #2'!$B$4:I$4,0),FALSE),0)) -> 26268531 | Q21: =SUM(IFERROR(VLOOKUP($B21&$C21,'C. Gestión Pto #1'!$B$4:P$17,MATCH(Q$5,'C. Gestión Pto #1'!$B$4:P$4,0),FALSE),0),IFERROR(VLOOKUP($B21&$C21,'C. Gestión Pto #2'!$B$4:J$23,MATCH(Q$5,'C. Gestión Pto #2'!$B$4:J$4,0),FALSE),0)) -> 17271364 | ... T21: =SUM(IFERROR(VLOOKUP($B21&$C21,'C. Gestión Pto #1'!$B$4:S$17,MATCH(T$5,'C. Gestión Pto #1'!$B$4:S$4,0),FALSE),0),IFERROR(VLOOKUP($B21&$C21,'C. Gestión Pto #2'!$B$4:M$23,MATCH(T$5,'C. Gestión Pto #2'!$B$4:M$4,0),FALSE),0)) -> 7793473.3 | V21: {=SUMPRODUCT($D21:$U21,TRANSPOSE('Indice CAC'!$C$10:$C$27))} -> 2.381807e+08 | X21: ='Resumen Pto #1'!X21 -> 1.6001523e+08 | Y21: 0 | Z21: =SUM(X21:Y21) -> 1.6001523e+08 | AA21: =IF(C21="MAT",SUMIF('Pto. 01 Cert.'!$A$10:$A$57,$B21,'Pto. 01 Cert.'!$T$10:$T$57),IF(C21="MO",SUMIF('Pto. 01 Cert.'!$A$10:$A$57,$B21,'Pto. 01 Cert.'!$U$10:$U$57),SUMIF('Pto. 01 Cert.'!$A$10:$A$57,$B21,'Pto. 01 Cert.'!$V$10:$V$57)))/IF(C21="MAT",SUMIF('Pto. 01 Cert.'!$A$10:$A$57,$B21,'Pto. 01 Cert.'!$I$10:$I$57),IF(C21="MO",SUMIF('Pto. 01 Cert.'!$A$10:$A$57,$B21,'Pto. 01 Cert.'!$J$10:$J$57),SUMIF('Pto. 01 Cert.'!$A$10:$A$57,$B21,'Pto. 01 Cert.'!$K$10:$K$57))) -> 1 | AB21: =IF(AA21=100%,0,IF(OR(V21<>0,Z21),Z21-V21)) -> 0 | AC21: =IF(OR(AB21<0,Z21),AB21/Z21,0%) -> 0 | AD21: =IF(AA21=100%,IF(OR(V21<>0,Z21),Z21-V21),0) -> -78165468
B22: Albañilería | C22: MAT | D22: =IFERROR(SUM(VLOOKUP($B22&$C22,'C. Gestión Pto #1'!$B$4:C$17,MATCH(D$5,'C. Gestión Pto #1'!$B$4:C$4,0),FALSE),0),0) -> 22000 | E22: =IFERROR(SUM(VLOOKUP($B22&$C22,'C. Gestión Pto #1'!$B$4:D$17,MATCH(E$5,'C. Gestión Pto #1'!$B$4:D$4,0),FALSE),0),0) -> 0 | F22: =IFERROR(SUM(VLOOKUP($B22&$C22,'C. Gestión Pto #1'!$B$4:E$17,MATCH(F$5,'C. Gestión Pto #1'!$B$4:E$4,0),FALSE),0),0) -> 0 | G22: =IFERROR(SUM(VLOOKUP($B22&$C22,'C. Gestión Pto #1'!$B$4:F$17,MATCH(G$5,'C. Gestión Pto #1'!$B$4:F$4,0),FALSE),0),0) -> 0 | H22: =IFERROR(SUM(VLOOKUP($B22&$C22,'C. Gestión Pto #1'!$B$4:G$17,MATCH(H$5,'C. Gestión Pto #1'!$B$4:G$4,0),FALSE),0),0) -> 0 | I22: =IFERROR(SUM(VLOOKUP($B22&$C22,'C. Gestión Pto #1'!$B$4:H$17,MATCH(I$5,'C. Gestión Pto #1'!$B$4:H$4,0),FALSE),0),0) -> 0 | J22: =SUM(IFERROR(VLOOKUP($B22&$C22,'C. Gestión Pto #1'!$B$4:I$17,MATCH(J$5,'C. Gestión Pto #1'!$B$4:I$4,0),FALSE),0),IFERROR(VLOOKUP($B22&$C22,'C. Gestión Pto #2'!$B$4:C$23,MATCH(J$5,'C. Gestión Pto #2'!$B$4:C$4,0),FALSE),0)) -> 203018.11 | K22: =SUM(IFERROR(VLOOKUP($B22&$C22,'C. Gestión Pto #1'!$B$4:J$17,MATCH(K$5,'C. Gestión Pto #1'!$B$4:J$4,0),FALSE),0),IFERROR(VLOOKUP($B22&$C22,'C. Gestión Pto #2'!$B$4:D$23,MATCH(K$5,'C. Gestión Pto #2'!$B$4:D$4,0),FALSE),0)) -> 955956.22 | L22: =SUM(IFERROR(VLOOKUP($B22&$C22,'C. Gestión Pto #1'!$B$4:K$17,MATCH(L$5,'C. Gestión Pto #1'!$B$4:K$4,0),FALSE),0),IFERROR(VLOOKUP($B22&$C22,'C. Gestión Pto #2'!$B$4:E$23,MATCH(L$5,'C. Gestión Pto #2'!$B$4:E$4,0),FALSE),0)) -> 404650.26 | M22: =SUM(IFERROR(VLOOKUP($B22&$C22,'C. Gestión Pto #1'!$B$4:L$17,MATCH(M$5,'C. Gestión Pto #1'!$B$4:L$4,0),FALSE),0),IFERROR(VLOOKUP($B22&$C22,'C. Gestión Pto #2'!$B$4:F$23,MATCH(M$5,'C. Gestión Pto #2'!$B$4:F$4,0),FALSE),0)) -> 21548948 | N22: =SUM(IFERROR(VLOOKUP($B22&$C22,'C. Gestión Pto #1'!$B$4:M$17,MATCH(N$5,'C. Gestión Pto #1'!$B$4:M$4,0),FALSE),0),IFERROR(VLOOKUP($B22&$C22,'C. Gestión Pto #2'!$B$4:G$23,MATCH(N$5,'C. Gestión Pto #2'!$B$4:G$4,0),FALSE),0)) -> 5653260.9 | O22: =SUM(IFERROR(VLOOKUP($B22&$C22,'C. Gestión Pto #1'!$B$4:N$17,MATCH(O$5,'C. Gestión Pto #1'!$B$4:N$4,0),FALSE),0),IFERROR(VLOOKUP($B22&$C22,'C. Gestión Pto #2'!$B$4:H$23,MATCH(O$5,'C. Gestión Pto #2'!$B$4:H$4,0),FALSE),0)) -> 524503.91 | P22: =SUM(IFERROR(VLOOKUP($B22&$C22,'C. Gestión Pto #1'!$B$4:O$17,MATCH(P$5,'C. Gestión Pto #1'!$B$4:O$4,0),FALSE),0),IFERROR(VLOOKUP($B22&$C22,'C. Gestión Pto #2'!$B$4:I$23,MATCH(P$5,'C. Gestión Pto #2'!$B$4:I$4,0),FALSE),0)) -> 4059472.8 | Q22: =SUM(IFERROR(VLOOKUP($B22&$C22,'C. Gestión Pto #1'!$B$4:P$17,MATCH(Q$5,'C. Gestión Pto #1'!$B$4:P$4,0),FALSE),0),IFERROR(VLOOKUP($B22&$C22,'C. Gestión Pto #2'!$B$4:J$23,MATCH(Q$5,'C. Gestión Pto #2'!$B$4:J$4,0),FALSE),0)) -> 3330609.2 | ... T22: =SUM(IFERROR(VLOOKUP($B22&$C22,'C. Gestión Pto #1'!$B$4:S$17,MATCH(T$5,'C. Gestión Pto #1'!$B$4:S$4,0),FALSE),0),IFERROR(VLOOKUP($B22&$C22,'C. Gestión Pto #2'!$B$4:M$23,MATCH(T$5,'C. Gestión Pto #2'!$B$4:M$4,0),FALSE),0)) -> 23833774 | V22: {=SUMPRODUCT($D22:$U22,TRANSPOSE('Indice CAC'!$C$10:$C$27))} -> 63183132 | X22: ='Resumen Pto #1'!X22 -> 2988097.3 | Y22: ='Resumen Pto #2'!R16 -> 61725811 | Z22: =SUM(X22:Y22) -> 64713908 | AA22: =SUM(IF(C22="MAT",SUMIF('Pto. 01 Cert.'!$A$10:$A$57,$B22,'Pto. 01 Cert.'!$T$10:$T$57),IF(C22="MO",SUMIF('Pto. 01 Cert.'!$A$10:$A$57,$B22,'Pto. 01 Cert.'!$U$10:$U$57),SUMIF('Pto. 01 Cert.'!$A$10:$A$57,$B22,'Pto. 01 Cert.'!$V$10:$V$57))),IF(C22="MAT",SUMIF('Pto. 02 Cert.'!$A$10:$A$185,$B22,'Pto. 02 Cert.'!$T$10:$T$185),IF(C22="MO",SUMIF('Pto. 02 Cert.'!$A$10:$A$185,$B22,'Pto. 02 Cert.'!$U$10:$U$185),SUMIF('Pto. 02 Cert.'!$A$10:$A$185,$B22,'Pto. 02 Cert.'!$V$10:$V$185))))/SUM(IF(C22="MAT",SUMIF('Pto. 01 Cert.'!$A$10:$A$57,$B22,'Pto. 01 Cert.'!$I$10:$I$57),IF(C22="MO",SUMIF('Pto. 01 Cert.'!$A$10:$A$57,$B22,'Pto. 01 Cert.'!$J$10:$J$57),SUMIF('Pto. 01 Cert.'!$A$10:$A$57,$B22,'Pto. 01 Cert.'!$K$10:$K$57))),IF(C22="MAT",SUMIF('Pto. 02 Cert.'!$A$10:$A$185,$B22,'Pto. 02 Cert.'!$I$10:$I$185),IF(C22="MO",SUMIF('Pto. 02 Cert.'!$A$10:$A$185,$B22,'Pto. 02 Cert.'!$J$10:$J$185),SUMIF('Pto. 02 Cert.'!$A$10:$A$185,$B22,'Pto. 02 Cert.'!$K$10:$K$185)))) -> 0.48486163 | AB22: =IF(AA22=100%,0,IF(OR(V22<>0,Z22),Z22-V22)) -> 1530776.1 | AC22: =IF(OR(AB22<0,Z22),AB22/Z22,0%) -> 0.023654515 | AD22: =IF(AA22=100%,IF(OR(V22<>0,Z22),Z22-V22),0) -> 0
B23: Albañilería | C23: MO | D23: =IFERROR(SUM(VLOOKUP($B23&$C23,'C. Gestión Pto #1'!$B$4:C$17,MATCH(D$5,'C. Gestión Pto #1'!$B$4:C$4,0),FALSE),0),0) -> 0 | E23: =IFERROR(SUM(VLOOKUP($B23&$C23,'C. Gestión Pto #1'!$B$4:D$17,MATCH(E$5,'C. Gestión Pto #1'!$B$4:D$4,0),FALSE),0),0) -> 0 | F23: =IFERROR(SUM(VLOOKUP($B23&$C23,'C. Gestión Pto #1'!$B$4:E$17,MATCH(F$5,'C. Gestión Pto #1'!$B$4:E$4,0),FALSE),0),0) -> 67000 | G23: =IFERROR(SUM(VLOOKUP($B23&$C23,'C. Gestión Pto #1'!$B$4:F$17,MATCH(G$5,'C. Gestión Pto #1'!$B$4:F$4,0),FALSE),0),0) -> 240500 | H23: =IFERROR(SUM(VLOOKUP($B23&$C23,'C. Gestión Pto #1'!$B$4:G$17,MATCH(H$5,'C. Gestión Pto #1'!$B$4:G$4,0),FALSE),0),0) -> 497357.68 | I23: =IFERROR(SUM(VLOOKUP($B23&$C23,'C. Gestión Pto #1'!$B$4:H$17,MATCH(I$5,'C. Gestión Pto #1'!$B$4:H$4,0),FALSE),0),0) -> 100000 | J23: =SUM(IFERROR(VLOOKUP($B23&$C23,'C. Gestión Pto #1'!$B$4:I$17,MATCH(J$5,'C. Gestión Pto #1'!$B$4:I$4,0),FALSE),0),IFERROR(VLOOKUP($B23&$C23,'C. Gestión Pto #2'!$B$4:C$23,MATCH(J$5,'C. Gestión Pto #2'!$B$4:C$4,0),FALSE),0)) -> 0 | K23: =SUM(IFERROR(VLOOKUP($B23&$C23,'C. Gestión Pto #1'!$B$4:J$17,MATCH(K$5,'C. Gestión Pto #1'!$B$4:J$4,0),FALSE),0),IFERROR(VLOOKUP($B23&$C23,'C. Gestión Pto #2'!$B$4:D$23,MATCH(K$5,'C. Gestión Pto #2'!$B$4:D$4,0),FALSE),0)) -> 0 | L23: =SUM(IFERROR(VLOOKUP($B23&$C23,'C. Gestión Pto #1'!$B$4:K$17,MATCH(L$5,'C. Gestión Pto #1'!$B$4:K$4,0),FALSE),0),IFERROR(VLOOKUP($B23&$C23,'C. Gestión Pto #2'!$B$4:E$23,MATCH(L$5,'C. Gestión Pto #2'!$B$4:E$4,0),FALSE),0)) -> 2134429.8 | M23: =SUM(IFERROR(VLOOKUP($B23&$C23,'C. Gestión Pto #1'!$B$4:L$17,MATCH(M$5,'C. Gestión Pto #1'!$B$4:L$4,0),FALSE),0),IFERROR(VLOOKUP($B23&$C23,'C. Gestión Pto #2'!$B$4:F$23,MATCH(M$5,'C. Gestión Pto #2'!$B$4:F$4,0),FALSE),0)) -> 10224408 | N23: =SUM(IFERROR(VLOOKUP($B23&$C23,'C. Gestión Pto #1'!$B$4:M$17,MATCH(N$5,'C. Gestión Pto #1'!$B$4:M$4,0),FALSE),0),IFERROR(VLOOKUP($B23&$C23,'C. Gestión Pto #2'!$B$4:G$23,MATCH(N$5,'C. Gestión Pto #2'!$B$4:G$4,0),FALSE),0)) -> 9687819.9 | O23: =SUM(IFERROR(VLOOKUP($B23&$C23,'C. Gestión Pto #1'!$B$4:N$17,MATCH(O$5,'C. Gestión Pto #1'!$B$4:N$4,0),FALSE),0),IFERROR(VLOOKUP($B23&$C23,'C. Gestión Pto #2'!$B$4:H$23,MATCH(O$5,'C. Gestión Pto #2'!$B$4:H$4,0),FALSE),0)) -> 15241735 | P23: =SUM(IFERROR(VLOOKUP($B23&$C23,'C. Gestión Pto #1'!$B$4:O$17,MATCH(P$5,'C. Gestión Pto #1'!$B$4:O$4,0),FALSE),0),IFERROR(VLOOKUP($B23&$C23,'C. Gestión Pto #2'!$B$4:I$23,MATCH(P$5,'C. Gestión Pto #2'!$B$4:I$4,0),FALSE),0)) -> 23120863 | Q23: =SUM(IFERROR(VLOOKUP($B23&$C23,'C. Gestión Pto #1'!$B$4:P$17,MATCH(Q$5,'C. Gestión Pto #1'!$B$4:P$4,0),FALSE),0),IFERROR(VLOOKUP($B23&$C23,'C. Gestión Pto #2'!$B$4:J$23,MATCH(Q$5,'C. Gestión Pto #2'!$B$4:J$4,0),FALSE),0)) -> 23725839 | ... T23: =SUM(IFERROR(VLOOKUP($B23&$C23,'C. Gestión Pto #1'!$B$4:S$17,MATCH(T$5,'C. Gestión Pto #1'!$B$4:S$4,0),FALSE),0),IFERROR(VLOOKUP($B23&$C23,'C. Gestión Pto #2'!$B$4:M$23,MATCH(T$5,'C. Gestión Pto #2'!$B$4:M$4,0),FALSE),0)) -> 34129760 | V23: {=SUMPRODUCT($D23:$U23,TRANSPOSE('Indice CAC'!$C$10:$C$27))} -> 1.30033e+08 | X23: ='Resumen Pto #1'!X23 -> 13017986 | Y23: ='Resumen Pto #2'!R17 -> 1.2838306e+08 | Z23: =SUM(X23:Y23) -> 1.4140104e+08 | AA23: =SUM(IF(C23="MAT",SUMIF('Pto. 01 Cert.'!$A$10:$A$57,$B23,'Pto. 01 Cert.'!$T$10:$T$57),IF(C23="MO",SUMIF('Pto. 01 Cert.'!$A$10:$A$57,$B23,'Pto. 01 Cert.'!$U$10:$U$57),SUMIF('Pto. 01 Cert.'!$A$10:$A$57,$B23,'Pto. 01 Cert.'!$V$10:$V$57))),IF(C23="MAT",SUMIF('Pto. 02 Cert.'!$A$10:$A$185,$B23,'Pto. 02 Cert.'!$T$10:$T$185),IF(C23="MO",SUMIF('Pto. 02 Cert.'!$A$10:$A$185,$B23,'Pto. 02 Cert.'!$U$10:$U$185),SUMIF('Pto. 02 Cert.'!$A$10:$A$185,$B23,'Pto. 02 Cert.'!$V$10:$V$185))))/SUM(IF(C23="MAT",SUMIF('Pto. 01 Cert.'!$A$10:$A$57,$B23,'Pto. 01 Cert.'!$I$10:$I$57),IF(C23="MO",SUMIF('Pto. 01 Cert.'!$A$10:$A$57,$B23,'Pto. 01 Cert.'!$J$10:$J$57),SUMIF('Pto. 01 Cert.'!$A$10:$A$57,$B23,'Pto. 01 Cert.'!$K$10:$K$57))),IF(C23="MAT",SUMIF('Pto. 02 Cert.'!$A$10:$A$185,$B23,'Pto. 02 Cert.'!$I$10:$I$185),IF(C23="MO",SUMIF('Pto. 02 Cert.'!$A$10:$A$185,$B23,'Pto. 02 Cert.'!$J$10:$J$185),SUMIF('Pto. 02 Cert.'!$A$10:$A$185,$B23,'Pto. 02 Cert.'!$K$10:$K$185)))) -> 0.57339098 | AB23: =IF(AA23=100%,0,IF(OR(V23<>0,Z23),Z23-V23)) -> 11368046 | AC23: =IF(OR(AB23<0,Z23),AB23/Z23,0%) -> 0.080395771 | AD23: =IF(AA23=100%,IF(OR(V23<>0,Z23),Z23-V23),0) -> 0
B24: Durlock | C24: MAT | D24: =IFERROR(SUM(VLOOKUP($B24&$C24,'C. Gestión Pto #1'!$B$4:C$17,MATCH(D$5,'C. Gestión Pto #1'!$B$4:C$4,0),FALSE),0),0) -> 0 | E24: =IFERROR(SUM(VLOOKUP($B24&$C24,'C. Gestión Pto #1'!$B$4:D$17,MATCH(E$5,'C. Gestión Pto #1'!$B$4:D$4,0),FALSE),0),0) -> 0 | F24: =IFERROR(SUM(VLOOKUP($B24&$C24,'C. Gestión Pto #1'!$B$4:E$17,MATCH(F$5,'C. Gestión Pto #1'!$B$4:E$4,0),FALSE),0),0) -> 0 | G24: =IFERROR(SUM(VLOOKUP($B24&$C24,'C. Gestión Pto #1'!$B$4:F$17,MATCH(G$5,'C. Gestión Pto #1'!$B$4:F$4,0),FALSE),0),0) -> 0 | H24: =IFERROR(SUM(VLOOKUP($B24&$C24,'C. Gestión Pto #1'!$B$4:G$17,MATCH(H$5,'C. Gestión Pto #1'!$B$4:G$4,0),FALSE),0),0) -> 0 | I24: =IFERROR(SUM(VLOOKUP($B24&$C24,'C. Gestión Pto #1'!$B$4:H$17,MATCH(I$5,'C. Gestión Pto #1'!$B$4:H$4,0),FALSE),0),0) -> 0 | J24: =SUM(IFERROR(VLOOKUP($B24&$C24,'C. Gestión Pto #1'!$B$4:I$17,MATCH(J$5,'C. Gestión Pto #1'!$B$4:I$4,0),FALSE),0),IFERROR(VLOOKUP($B24&$C24,'C. Gestión Pto #2'!$B$4:C$23,MATCH(J$5,'C. Gestión Pto #2'!$B$4:C$4,0),FALSE),0)) -> 0 | K24: =SUM(IFERROR(VLOOKUP($B24&$C24,'C. Gestión Pto #1'!$B$4:J$17,MATCH(K$5,'C. Gestión Pto #1'!$B$4:J$4,0),FALSE),0),IFERROR(VLOOKUP($B24&$C24,'C. Gestión Pto #2'!$B$4:D$23,MATCH(K$5,'C. Gestión Pto #2'!$B$4:D$4,0),FALSE),0)) -> 0 | L24: =SUM(IFERROR(VLOOKUP($B24&$C24,'C. Gestión Pto #1'!$B$4:K$17,MATCH(L$5,'C. Gestión Pto #1'!$B$4:K$4,0),FALSE),0),IFERROR(VLOOKUP($B24&$C24,'C. Gestión Pto #2'!$B$4:E$23,MATCH(L$5,'C. Gestión Pto #2'!$B$4:E$4,0),FALSE),0)) -> 14055.62 | M24: =SUM(IFERROR(VLOOKUP($B24&$C24,'C. Gestión Pto #1'!$B$4:L$17,MATCH(M$5,'C. Gestión Pto #1'!$B$4:L$4,0),FALSE),0),IFERROR(VLOOKUP($B24&$C24,'C. Gestión Pto #2'!$B$4:F$23,MATCH(M$5,'C. Gestión Pto #2'!$B$4:F$4,0),FALSE),0)) -> 0 | N24: =SUM(IFERROR(VLOOKUP($B24&$C24,'C. Gestión Pto #1'!$B$4:M$17,MATCH(N$5,'C. Gestión Pto #1'!$B$4:M$4,0),FALSE),0),IFERROR(VLOOKUP($B24&$C24,'C. Gestión Pto #2'!$B$4:G$23,MATCH(N$5,'C. Gestión Pto #2'!$B$4:G$4,0),FALSE),0)) -> 0 | O24: =SUM(IFERROR(VLOOKUP($B24&$C24,'C. Gestión Pto #1'!$B$4:N$17,MATCH(O$5,'C. Gestión Pto #1'!$B$4:N$4,0),FALSE),0),IFERROR(VLOOKUP($B24&$C24,'C. Gestión Pto #2'!$B$4:H$23,MATCH(O$5,'C. Gestión Pto #2'!$B$4:H$4,0),FALSE),0)) -> 0 | P24: =SUM(IFERROR(VLOOKUP($B24&$C24,'C. Gestión Pto #1'!$B$4:O$17,MATCH(P$5,'C. Gestión Pto #1'!$B$4:O$4,0),FALSE),0),IFERROR(VLOOKUP($B24&$C24,'C. Gestión Pto #2'!$B$4:I$23,MATCH(P$5,'C. Gestión Pto #2'!$B$4:I$4,0),FALSE),0)) -> 0 | Q24: =SUM(IFERROR(VLOOKUP($B24&$C24,'C. Gestión Pto #1'!$B$4:P$17,MATCH(Q$5,'C. Gestión Pto #1'!$B$4:P$4,0),FALSE),0),IFERROR(VLOOKUP($B24&$C24,'C. Gestión Pto #2'!$B$4:J$23,MATCH(Q$5,'C. Gestión Pto #2'!$B$4:J$4,0),FALSE),0)) -> 6856283.7 | ... T24: =SUM(IFERROR(VLOOKUP($B24&$C24,'C. Gestión Pto #1'!$B$4:S$17,MATCH(T$5,'C. Gestión Pto #1'!$B$4:S$4,0),FALSE),0),IFERROR(VLOOKUP($B24&$C24,'C. Gestión Pto #2'!$B$4:M$23,MATCH(T$5,'C. Gestión Pto #2'!$B$4:M$4,0),FALSE),0)) -> 12647943 | V24: {=SUMPRODUCT($D24:$U24,TRANSPOSE('Indice CAC'!$C$10:$C$27))} -> 15079861 | X24: 0 | Y24: ='Resumen Pto #2'!R18 -> 24596469 | Z24: =SUM(X24:Y24) -> 24596469 | AA24: =IF(C24="MAT",SUMIF('Pto. 02 Cert.'!$A$10:$A$185,$B24,'Pto. 02 Cert.'!$T$10:$T$185),IF(C24="MO",SUMIF('Pto. 02 Cert.'!$A$10:$A$185,$B24,'Pto. 02 Cert.'!$U$10:$U$185),SUMIF('Pto. 02 Cert.'!$A$10:$A$185,$B24,'Pto. 02 Cert.'!$V$10:$V$185)))/IF(C24="MAT",SUMIF('Pto. 02 Cert.'!$A$10:$A$185,$B24,'Pto. 02 Cert.'!$I$10:$I$185),IF(C24="MO",SUMIF('Pto. 02 Cert.'!$A$10:$A$185,$B24,'Pto. 02 Cert.'!$J$10:$J$185),SUMIF('Pto. 02 Cert.'!$A$10:$A$185,$B24,'Pto. 02 Cert.'!$K$10:$K$185))) -> 0.56143986 | AB24: =IF(AA24=100%,0,IF(OR(V24<>0,Z24),Z24-V24)) -> 9516608.9 | AC24: =IF(OR(AB24<0,Z24),AB24/Z24,0%) -> 0.38690955 | AD24: =IF(AA24=100%,IF(OR(V24<>0,Z24),Z24-V24),0) -> 0
