Workbook
Name \0: #REF!
Name \c: #REF!
Name \E: #REF!
Name \i: #REF!
Name \j: #REF!
Name \m: #REF!
Name \P: #REF!
Name \P: #REF!
Name \P: #REF!
Name \P: #REF!
Name \P: #REF!
Name \P: #REF!
Name \P: #REF!
Name \P: #REF!
Name \P: #REF!
Name \P: #REF!
Name \P: #REF!
Name \P: #REF!
Name \P: #REF!
Name \r: #N/A
Name \x: #REF!
Name \z: #REF!
Name __________ben1: #REF!
Name __________ben1: #REF!
Name __________ben1: #REF!
Name __________ben1: #REF!
Name __________ben1: #REF!
Name __________ben1: #REF!
Name __________ben1: #REF!
Name __________ben1: #REF!
Name __________ben1: #REF!
Name __________ben1: #REF!
Name __________ben1: #REF!
Name __________ben1: #REF!
Name __________ben1: #REF!
Name __________ben10: #REF!
Name __________ben10: #REF!
Name __________ben10: #REF!
Name __________ben10: #REF!
Name __________ben10: #REF!
Name __________ben10: #REF!
Name __________ben10: #REF!
Name __________ben10: #REF!
Name __________ben10: #REF!
Name __________ben10: #REF!
Name __________ben10: #REF!
Name __________ben10: #REF!
Name __________ben10: #REF!
Name __________ben15: #REF!
Name __________ben15: #REF!
Name __________ben15: #REF!
Name __________ben15: #REF!
Name __________ben15: #REF!
Name __________ben15: #REF!
Name __________ben15: #REF!
Name __________ben15: #REF!
Name __________ben15: #REF!
Name __________ben15: #REF!
Name __________ben15: #REF!
Name __________ben15: #REF!

Sheet SVD 4140_Pto. 01_Cert. 01
G2: DÓLAR BNA | H2: DÓLAR MEP
F3: cotiz oct24 | G3: 1005 | H3: 1170
G5: 45628
C6: OBRA: EDIFICIO EL SALVADOR 4140 | J6: Certificado | K6: 1 | O6: 45747
C7: PRESUPUESTO OBRA CIVIL
C8: Descripción | D8: U | E8: Cant | F8: P unit | G8: Subtotal | J8: Avance | M8: Importe
C9: PRESUPUESTO 01 - PRELIMINARES + MOV SUELO + HORMIGON | J9: Anterior | K9: Actual | L9: Acumulado | M9: Anterior | N9: Actual | O9: Acumulado
B10: 1 | C10: TAREAS PRELIMINARES | H10: =SUM(G11:G20) -> 24784163 | I10: =+H10/$H$57 -> 0.058826981
B11: 1.01 | C11: Limpieza y preparación del terreno - No cotiza | D11: gl | E11: 0 | F11: 0 | G11: =+F11*E11 -> 0 | L11: =+J11+K11 -> 0 | M11: =+G11*J11 -> 0 | N11: =+G11*K11 -> 0 | O11: =+G11*L11 -> 0
B12: 1.02 | C12: Topógrafo - Visita de obra replanteo | D12: un | E12: 3 | F12: 379588 | G12: =+F12*E12 -> 1138764 | K12: 0.65 | L12: =+J12+K12 -> 0.65 | M12: =+G12*J12 -> 0 | N12: =+G12*K12 -> 740196.6 | O12: =+G12*L12 -> 740196.6
B13: 1.03 | C13: Cartel de Obra - No cotiza | D13: gl | E13: 0 | F13: 0 | G13: =+F13*E13 -> 0 | L13: =+J13+K13 -> 0 | M13: =+G13*J13 -> 0 | N13: =+G13*K13 -> 0 | O13: =+G13*L13 -> 0
B14: 1.04 | C14: Cerco de obra perimetral - En chapa C25 + Concertina + Porton corredizo | D14: ml | E14: 11 | F14: 141220 | G14: =+F14*E14 -> 1553420 | L14: =+J14+K14 -> 0 | M14: =+G14*J14 -> 0 | N14: =+G14*K14 -> 0 | O14: =+G14*L14 -> 0
B15: 1.05 | C15: Obrador colgante, pañol y ducha | D15: gl | E15: 1 | F15: 7548771 | G15: =+F15*E15 -> 7548771 | K15: 0.5 | L15: =+J15+K15 -> 0.5 | M15: =+G15*J15 -> 0 | N15: =+G15*K15 -> 3774385.5 | O15: =+G15*L15 -> 3774385.5
B16: 1.06 | C16: Alquiler de baños quimicos y duchas portatiles | D16: mes | E16: 3 | F16: 392028 | G16: =+F16*E16 -> 1176084 | K16: 0.3 | L16: =+J16+K16 -> 0.3 | M16: =+G16*J16 -> 0 | N16: =+G16*K16 -> 352825.2 | O16: =+G16*L16 -> 352825.2
B17: 1.07 | C17: Conexión pilar y luz de obra + Tablero de obra | D17: gl | E17: 1 | F17: 1731320 | G17: =+F17*E17 -> 1731320 | K17: 0.5 | L17: =+J17+K17 -> 0.5 | M17: =+G17*J17 -> 0 | N17: =+G17*K17 -> 865660 | O17: =+G17*L17 -> 865660
B18: 1.08 | C18: Conexión agua de obra, tanque + bomba | D18: gl | E18: 1 | F18: 1405632 | G18: =+F18*E18 -> 1405632 | L18: =+J18+K18 -> 0 | M18: =+G18*J18 -> 0 | N18: =+G18*K18 -> 0 | O18: =+G18*L18 -> 0
B19: 1.09 | C19: Tramite luz de obra, certificado luz de obra (2) y medición PAT | D19: gl | E19: 1 | F19: 426487 | G19: =+F19*E19 -> 426487 | K19: 0.5 | L19: =+J19+K19 -> 0.5 | M19: =+G19*J19 -> 0 | N19: =+G19*K19 -> 213243.5 | O19: =+G19*L19 -> 213243.5
B20: 1.1 | C20: Sistema de depresión de napas | D20: gl | E20: 1 | F20: 9803685 | G20: =+F20*E20 -> 9803685 | K20: 1 | L20: =+J20+K20 -> 1 | M20: =+G20*J20 -> 0 | N20: =+G20*K20 -> 9803685 | O20: =+G20*L20 -> 9803685
B21: 2 | C21: MOVIMIENTO DE TIERRA, COMPACTACION Y RELLENO | H21: =SUM(G22:G24) -> 42017464 | I21: =+H21/$H$57 -> 0.099731451
B22: 2.01 | C22: Excavación a maquina para submuración y subsuelo | D22: m3 | E22: 1266 | F22: 33090 | G22: =+F22*E22 -> 41891940 | K22: 0.35 | L22: =+J22+K22 -> 0.35 | M22: =+G22*J22 -> 0 | N22: =+G22*K22 -> 14662179 | O22: =+G22*L22 -> 14662179
B23: 2.02 | C23: Demolición y retiro de fundaciones existentes - No cotiza | D23: gl | E23: 0 | F23: 0 | G23: =+F23*E23 -> 0 | L23: =+J23+K23 -> 0 | M23: =+G23*J23 -> 0 | N23: =+G23*K23 -> 0 | O23: =+G23*L23 -> 0
B24: 2.03 | C24: Excavación manual para pozo de achique y bombeo | D24: m3 | E24: 2 | F24: 62762 | G24: =+F24*E24 -> 125524 | L24: =+J24+K24 -> 0 | M24: =+G24*J24 -> 0 | N24: =+G24*K24 -> 0 | O24: =+G24*L24 -> 0
B25: 3 | C25: ESTRUCTURA RESISTENTE - sin provision de hierro y hormigon (incluye corte y doblado en obra) | H25: =SUM(G26:G42) -> 277149875 | I25: =+H25/$H$57 -> 0.65783502
B26: 3.01 | C26: Hormigón de limpieza - e: 10 cm | D26: m3 | E26: 35 | F26: 314478 | G26: =+F26*E26 -> 11006730 | L26: =+J26+K26 -> 0 | M26: =+G26*J26 -> 0 | N26: =+G26*K26 -> 0 | O26: =+G26*L26 -> 0
B27: 3.02 | C27: Tabique submuración - H30 hidrófugo (95 kg/m3 de hierro) | D27: m3 | E27: 40 | F27: 536061.6 | G27: =+F27*E27 -> 21442464 | L27: =+J27+K27 -> 0 | M27: =+G27*J27 -> 0 | N27: =+G27*K27 -> 0 | O27: =+G27*L27 -> 0
B28: 3.03 | C28: Zapata corrida tabique - H30 hidrófugo (120 kg/m3) | D28: m3 | E28: 28 | F28: 437680.76 | G28: =+F28*E28 -> 12255061 | L28: =+J28+K28 -> 0 | M28: =+G28*J28 -> 0 | N28: =+G28*K28 -> 0 | O28: =+G28*L28 -> 0
B29: 3.04 | C29: Platea - H30 hidrófugo (95 kg/m3 de hierro) | D29: m3 | E29: 179 | F29: 214461.72 | G29: =+F29*E29 -> 38388648 | L29: =+J29+K29 -> 0 | M29: =+G29*J29 -> 0 | N29: =+G29*K29 -> 0 | O29: =+G29*L29 -> 0
B30: 3.05 | C30: Rampa - H30 (120 kg/m3 de hierro) | D30: m3 | E30: 10 | F30: 462731.65 | G30: =+F30*E30 -> 4627316.5 | L30: =+J30+K30 -> 0 | M30: =+G30*J30 -> 0 | N30: =+G30*K30 -> 0 | O30: =+G30*L30 -> 0
B31: 3.06 | C31: Losa maciza - H30 (110 kg/m3 de hierro) | D31: m3 | E31: 177 | F31: 317280.61 | G31: =+F31*E31 -> 56158669 | L31: =+J31+K31 -> 0 | M31: =+G31*J31 -> 0 | N31: =+G31*K31 -> 0 | O31: =+G31*L31 -> 0
B32: 3.07 | C32: Vigas - H30 (140 kg/m3 de hierro) | D32: m3 | E32: 65 | F32: 789050.44 | G32: =+F32*E32 -> 51288278 | L32: =+J32+K32 -> 0 | M32: =+G32*J32 -> 0 | N32: =+G32*K32 -> 0 | O32: =+G32*L32 -> 0
B33: 3.08 | C33: Vigas de H° visto - H30 (140 kg/m3 de hierro) | D33: m3 | E33: 12 | F33: 917117.82 | G33: =+F33*E33 -> 11005414 | L33: =+J33+K33 -> 0 | M33: =+G33*J33 -> 0 | N33: =+G33*K33 -> 0 | O33: =+G33*L33 -> 0
B34: 3.09 | C34: Tabiques - H30 (120 kg/m3 de hierro) | D34: m3 | E34: 28 | F34: 536061.6 | G34: =+F34*E34 -> 15009725 | L34: =+J34+K34 -> 0 | M34: =+G34*J34 -> 0 | N34: =+G34*K34 -> 0 | O34: =+G34*L34 -> 0
B35: 3.1 | C35: Columna - H30 (240 Kg/m3 de hierro) | D35: m3 | E35: 54 | F35: 473858.97 | G35: =+F35*E35 -> 25588384 | L35: =+J35+K35 -> 0 | M35: =+G35*J35 -> 0 | N35: =+G35*K35 -> 0 | O35: =+G35*L35 -> 0
B36: 3.11 | C36: Escaleras - H30 (105 kg/m3 de hierro) | D36: m3 | E36: 11 | F36: 497587.77 | G36: =+F36*E36 -> 5473465.5 | L36: =+J36+K36 -> 0 | M36: =+G36*J36 -> 0 | N36: =+G36*K36 -> 0 | O36: =+G36*L36 -> 0
B37: 3.12 | C37: Tabiques tanques de H° - H30 (120 kg/m3 de hierro) | D37: m3 | E37: 3 | F37: 536061.6 | G37: =+F37*E37 -> 1608184.8 | L37: =+J37+K37 -> 0 | M37: =+G37*J37 -> 0 | N37: =+G37*K37 -> 0 | O37: =+G37*L37 -> 0
... B42: 3.17 | C42: Picado de medianeras para columnas y vigas - Cotizado solo para PB y 1P, No contempla picado en SS | D42: m2 | E42: 93 | F42: 24580 | G42: =+F42*E42 -> 2285940 | L42: =+J42+K42 -> 0 | M42: =+G42*J42 -> 0 | N42: =+G42*K42 -> 0 | O42: =+G42*L42 -> 0
B43: 24 | C43: AYUDA DE GREMIOS | H43: =SUM(G44:G53) -> 34134166 | I43: =+H43/$H$57 -> 0.081019881
B44: 24.01 | C44: Sereno | D44: mes | E44: 8 | F44: 753138 | G44: =+F44*E44 -> 6025104 | K44: 0.1 | L44: =+J44+K44 -> 0.1 | M44: =+G44*J44 -> 0 | N44: =+G44*K44 -> 602510.4 | O44: =+G44*L44 -> 602510.4
B45: 24.02 | C45: Tecnico de seguridad & higiene permanente en Obra | D45: mes | E45: 4 | F45: 1944871 | G45: =+F45*E45 -> 7779484 | L45: =+J45+K45 -> 0 | M45: =+G45*J45 -> 0 | N45: =+G45*K45 -> 0 | O45: =+G45*L45 -> 0
B46: 24.03 | C46: Higiene y seguridad Res 51 | D46: mes | E46: 8 | F46: 188533 | G46: =+F46*E46 -> 1508264 | K46: 0.1 | L46: =+J46+K46 -> 0.1 | M46: =+G46*J46 -> 0 | N46: =+G46*K46 -> 150826.4 | O46: =+G46*L46 -> 150826.4
...

Sheet SVD 4140_Pto. 01_Cert. 2
G2: DÓLAR BNA | H2: DÓLAR MEP
G3: 1005 | H3: 1170
G5: 45628
C6: OBRA: EDIFICIO EL SALVADOR 4140 | J6: Certificado | K6: 2 | O6: 45777
C7: PRESUPUESTO OBRA CIVIL
C8: Descripción | D8: U | E8: Cant | F8: P unit | G8: Subtotal | J8: Avance | M8: Importe
C9: PRESUPUESTO 01 - PRELIMINARES + MOV SUELO + HORMIGON | J9: Anterior | K9: Actual | L9: Acumulado | M9: Anterior | N9: Actual | O9: Acumulado
B10: 1 | C10: TAREAS PRELIMINARES | H10: =SUM(G11:G20) -> 24784163 | I10: =+H10/$H$57 -> 0.058826981
B11: 1.01 | C11: Limpieza y preparación del terreno - No cotiza | D11: gl | E11: 0 | F11: 0 | G11: =+F11*E11 -> 0 | J11: =+'SVD 4140_Pto. 01_Cert. 01'!L11 -> 0 | L11: =+J11+K11 -> 0 | M11: =+G11*J11 -> 0 | N11: =+G11*K11 -> 0 | O11: =+G11*L11 -> 0
B12: 1.02 | C12: Topógrafo - Visita de obra replanteo | D12: un | E12: 3 | F12: 379588 | G12: =+F12*E12 -> 1138764 | J12: =+'SVD 4140_Pto. 01_Cert. 01'!L12 -> 0.65 | L12: =+J12+K12 -> 0.65 | M12: =+G12*J12 -> 740196.6 | N12: =+G12*K12 -> 0 | O12: =+G12*L12 -> 740196.6
B13: 1.03 | C13: Cartel de Obra - No cotiza | D13: gl | E13: 0 | F13: 0 | G13: =+F13*E13 -> 0 | J13: =+'SVD 4140_Pto. 01_Cert. 01'!L13 -> 0 | L13: =+J13+K13 -> 0 | M13: =+G13*J13 -> 0 | N13: =+G13*K13 -> 0 | O13: =+G13*L13 -> 0
B14: 1.04 | C14: Cerco de obra perimetral - En chapa C25 + Concertina + Porton corredizo | D14: ml | E14: 11 | F14: 141220 | G14: =+F14*E14 -> 1553420 | J14: =+'SVD 4140_Pto. 01_Cert. 01'!L14 -> 0 | L14: =+J14+K14 -> 0 | M14: =+G14*J14 -> 0 | N14: =+G14*K14 -> 0 | O14: =+G14*L14 -> 0
B15: 1.05 | C15: Obrador colgante, pañol y ducha | D15: gl | E15: 1 | F15: 7548771 | G15: =+F15*E15 -> 7548771 | J15: =+'SVD 4140_Pto. 01_Cert. 01'!L15 -> 0.5 | L15: =+J15+K15 -> 0.5 | M15: =+G15*J15 -> 3774385.5 | N15: =+G15*K15 -> 0 | O15: =+G15*L15 -> 3774385.5
B16: 1.06 | C16: Alquiler de baños quimicos y duchas portatiles | D16: mes | E16: 3 | F16: 392028 | G16: =+F16*E16 -> 1176084 | J16: =+'SVD 4140_Pto. 01_Cert. 01'!L16 -> 0.3 | K16: 0.2 | L16: =+J16+K16 -> 0.5 | M16: =+G16*J16 -> 352825.2 | N16: =+G16*K16 -> 235216.8 | O16: =+G16*L16 -> 588042
B17: 1.07 | C17: Conexión pilar y luz de obra + Tablero de obra | D17: gl | E17: 1 | F17: 1731320 | G17: =+F17*E17 -> 1731320 | J17: =+'SVD 4140_Pto. 01_Cert. 01'!L17 -> 0.5 | K17: 0.2 | L17: =+J17+K17 -> 0.7 | M17: =+G17*J17 -> 865660 | N17: =+G17*K17 -> 346264 | O17: =+G17*L17 -> 1211924
B18: 1.08 | C18: Conexión agua de obra, tanque + bomba | D18: gl | E18: 1 | F18: 1405632 | G18: =+F18*E18 -> 1405632 | J18: =+'SVD 4140_Pto. 01_Cert. 01'!L18 -> 0 | L18: =+J18+K18 -> 0 | M18: =+G18*J18 -> 0 | N18: =+G18*K18 -> 0 | O18: =+G18*L18 -> 0
B19: 1.09 | C19: Tramite luz de obra, certificado luz de obra (2) y medición PAT | D19: gl | E19: 1 | F19: 426487 | G19: =+F19*E19 -> 426487 | J19: =+'SVD 4140_Pto. 01_Cert. 01'!L19 -> 0.5 | L19: =+J19+K19 -> 0.5 | M19: =+G19*J19 -> 213243.5 | N19: =+G19*K19 -> 0 | O19: =+G19*L19 -> 213243.5
B20: 1.1 | C20: Sistema de depresión de napas | D20: gl | E20: 1 | F20: 9803685 | G20: =+F20*E20 -> 9803685 | J20: =+'SVD 4140_Pto. 01_Cert. 01'!L20 -> 1 | L20: =+J20+K20 -> 1 | M20: =+G20*J20 -> 9803685 | N20: =+G20*K20 -> 0 | O20: =+G20*L20 -> 9803685
B21: 2 | C21: MOVIMIENTO DE TIERRA, COMPACTACION Y RELLENO | H21: =SUM(G22:G24) -> 42017464 | I21: =+H21/$H$57 -> 0.099731451
B22: 2.01 | C22: Excavación a maquina para submuración y subsuelo | D22: m3 | E22: 1266 | F22: 33090 | G22: =+F22*E22 -> 41891940 | J22: =+'SVD 4140_Pto. 01_Cert. 01'!L22 -> 0.35 | L22: =+J22+K22 -> 0.35 | M22: =+G22*J22 -> 14662179 | N22: =+G22*K22 -> 0 | O22: =+G22*L22 -> 14662179
B23: 2.02 | C23: Demolición y retiro de fundaciones existentes - No cotiza | D23: gl | E23: 0 | F23: 0 | G23: =+F23*E23 -> 0 | J23: =+'SVD 4140_Pto. 01_Cert. 01'!L23 -> 0 | L23: =+J23+K23 -> 0 | M23: =+G23*J23 -> 0 | N23: =+G23*K23 -> 0 | O23: =+G23*L23 -> 0
B24: 2.03 | C24: Excavación manual para pozo de achique y bombeo | D24: m3 | E24: 2 | F24: 62762 | G24: =+F24*E24 -> 125524 | J24: =+'SVD 4140_Pto. 01_Cert. 01'!L24 -> 0 | L24: =+J24+K24 -> 0 | M24: =+G24*J24 -> 0 | N24: =+G24*K24 -> 0 | O24: =+G24*L24 -> 0
B25: 3 | C25: ESTRUCTURA RESISTENTE - sin provision de hierro y hormigon (incluye corte y doblado en obra) | H25: =SUM(G26:G42) -> 277149875 | I25: =+H25/$H$57 -> 0.65783502
B26: 3.01 | C26: Hormigón de limpieza - e: 10 cm | D26: m3 | E26: 35 | F26: 314478 | G26: =+F26*E26 -> 11006730 | J26: =+'SVD 4140_Pto. 01_Cert. 01'!L26 -> 0 | K26: 0.15 | L26: =+J26+K26 -> 0.15 | M26: =+G26*J26 -> 0 | N26: =+G26*K26 -> 1651009.5 | O26: =+G26*L26 -> 1651009.5
B27: 3.02 | C27: Tabique submuración - H30 hidrófugo (95 kg/m3 de hierro) | D27: m3 | E27: 40 | F27: 536061.6 | G27: =+F27*E27 -> 21442464 | J27: =+'SVD 4140_Pto. 01_Cert. 01'!L27 -> 0 | K27: 0.25 | L27: =+J27+K27 -> 0.25 | M27: =+G27*J27 -> 0 | N27: =+G27*K27 -> 5360616 | O27: =+G27*L27 -> 5360616
B28: 3.03 | C28: Zapata corrida tabique - H30 hidrófugo (120 kg/m3) | D28: m3 | E28: 28 | F28: 437680.76 | G28: =+F28*E28 -> 12255061 | J28: =+'SVD 4140_Pto. 01_Cert. 01'!L28 -> 0 | K28: 0.25 | L28: =+J28+K28 -> 0.25 | M28: =+G28*J28 -> 0 | N28: =+G28*K28 -> 3063765.3 | O28: =+G28*L28 -> 3063765.3
B29: 3.04 | C29: Platea - H30 hidrófugo (95 kg/m3 de hierro) | D29: m3 | E29: 179 | F29: 214461.72 | G29: =+F29*E29 -> 38388648 | J29: =+'SVD 4140_Pto. 01_Cert. 01'!L29 -> 0 | K29: 0.15 | L29: =+J29+K29 -> 0.15 | M29: =+G29*J29 -> 0 | N29: =+G29*K29 -> 5758297.1 | O29: =+G29*L29 -> 5758297.1
B30: 3.05 | C30: Rampa - H30 (120 kg/m3 de hierro) | D30: m3 | E30: 10 | F30: 462731.65 | G30: =+F30*E30 -> 4627316.5 | J30: =+'SVD 4140_Pto. 01_Cert. 01'!L30 -> 0 | L30: =+J30+K30 -> 0 | M30: =+G30*J30 -> 0 | N30: =+G30*K30 -> 0 | O30: =+G30*L30 -> 0
B31: 3.06 | C31: Losa maciza - H30 (110 kg/m3 de hierro) | D31: m3 | E31: 177 | F31: 317280.61 | G31: =+F31*E31 -> 56158669 | J31: =+'SVD 4140_Pto. 01_Cert. 01'!L31 -> 0 | L31: =+J31+K31 -> 0 | M31: =+G31*J31 -> 0 | N31: =+G31*K31 -> 0 | O31: =+G31*L31 -> 0
B32: 3.07 | C32: Vigas - H30 (140 kg/m3 de hierro) | D32: m3 | E32: 65 | F32: 789050.44 | G32: =+F32*E32 -> 51288278 | J32: =+'SVD 4140_Pto. 01_Cert. 01'!L32 -> 0 | L32: =+J32+K32 -> 0 | M32: =+G32*J32 -> 0 | N32: =+G32*K32 -> 0 | O32: =+G32*L32 -> 0
B33: 3.08 | C33: Vigas de H° visto - H30 (140 kg/m3 de hierro) | D33: m3 | E33: 12 | F33: 917117.82 | G33: =+F33*E33 -> 11005414 | J33: =+'SVD 4140_Pto. 01_Cert. 01'!L33 -> 0 | L33: =+J33+K33 -> 0 | M33: =+G33*J33 -> 0 | N33: =+G33*K33 -> 0 | O33: =+G33*L33 -> 0
B34: 3.09 | C34: Tabiques - H30 (120 kg/m3 de hierro) | D34: m3 | E34: 28 | F34: 536061.6 | G34: =+F34*E34 -> 15009725 | J34: =+'SVD 4140_Pto. 01_Cert. 01'!L34 -> 0 | L34: =+J34+K34 -> 0 | M34: =+G34*J34 -> 0 | N34: =+G34*K34 -> 0 | O34: =+G34*L34 -> 0
B35: 3.1 | C35: Columna - H30 (240 Kg/m3 de hierro) | D35: m3 | E35: 54 | F35: 473858.97 | G35: =+F35*E35 -> 25588384 | J35: =+'SVD 4140_Pto. 01_Cert. 01'!L35 -> 0 | L35: =+J35+K35 -> 0 | M35: =+G35*J35 -> 0 | N35: =+G35*K35 -> 0 | O35: =+G35*L35 -> 0
B36: 3.11 | C36: Escaleras - H30 (105 kg/m3 de hierro) | D36: m3 | E36: 11 | F36: 497587.77 | G36: =+F36*E36 -> 5473465.5 | J36: =+'SVD 4140_Pto. 01_Cert. 01'!L36 -> 0 | L36: =+J36+K36 -> 0 | M36: =+G36*J36 -> 0 | N36: =+G36*K36 -> 0 | O36: =+G36*L36 -> 0
B37: 3.12 | C37: Tabiques tanques de H° - H30 (120 kg/m3 de hierro) | D37: m3 | E37: 3 | F37: 536061.6 | G37: =+F37*E37 -> 1608184.8 | J37: =+'SVD 4140_Pto. 01_Cert. 01'!L37 -> 0 | L37: =+J37+K37 -> 0 | M37: =+G37*J37 -> 0 | N37: =+G37*K37 -> 0 | O37: =+G37*L37 -> 0
B38: 3.13 | C38: Junta de impermeabilización de PVC - Sika Waterbars v15 x 15mts o similar | D38: ml | E38: 240 | F38: 31137 | G38: =+F38*E38 -> 7472880 | J38: =+'SVD 4140_Pto. 01_Cert. 01'!L38 -> 0 | K38: 0.15 | L38: =+J38+K38 -> 0.15 | M38: =+G38*J38 -> 0 | N38: =+G38*K38 -> 1120932 | O38: =+G38*L38 -> 1120932
B39: 3.14 | C39: Sistema de apuntalamiento y reapuntalamiento | D39: gl | E39: 1 | F39: 11089161 | G39: =+F39*E39 -> 11089161 | J39: =+'SVD 4140_Pto. 01_Cert. 01'!L39 -> 0 | L39: =+J39+K39 -> 0 | M39: =+G39*J39 -> 0 | N39: =+G39*K39 -> 0 | O39: =+G39*L39 -> 0
B40: 3.15 | C40: Ensayos de Hormigon por etapas de hormigonado | D40: u | E40: 14 | F40: 155217 | G40: =+F40*E40 -> 2173038 | J40: =+'SVD 4140_Pto. 01_Cert. 01'!L40 -> 0 | K40: 0.05 | L40: =+J40+K40 -> 0.05 | M40: =+G40*J40 -> 0 | N40: =+G40*K40 -> 108651.9 | O40: =+G40*L40 -> 108651.9
B41: 3.16 | C41: Permiso de estacionamiento de bomba de hormigón a contramano | D41: gl | E41: 4 | F41: 69129 | G41: =+F41*E41 -> 276516 | J41: =+'SVD 4140_Pto. 01_Cert. 01'!L41 -> 0 | K41: 0.25 | L41: =+J41+K41 -> 0.25 | M41: =+G41*J41 -> 0 | N41: =+G41*K41 -> 69129 | O41: =+G41*L41 -> 69129
B42: 3.17 | C42: Picado de medianeras para columnas y vigas - Cotizado solo para PB y 1P, No contempla picado en SS | D42: m2 | E42: 93 | F42: 24580 | G42: =+F42*E42 -> 2285940 | J42: =+'SVD 4140_Pto. 01_Cert. 01'!L42 -> 0 | L42: =+J42+K42 -> 0 | M42: =+G42*J42 -> 0 | N42: =+G42*K42 -> 0 | O42: =+G42*L42 -> 0
...

Sheet SVD 4140_Pto. 01_Cert. 3
G2: DÓLAR BNA | H2: DÓLAR MEP
G3: 1005 | H3: 1170
G5: 45628
C6: OBRA: EDIFICIO EL SALVADOR 4140 | J6: Certificado | K6: 3 | O6: 45807
C7: PRESUPUESTO OBRA CIVIL
C8: Descripción | D8: U | E8: Cant | F8: P unit | G8: Subtotal | J8: Avance | M8: Importe
C9: PRESUPUESTO 01 - PRELIMINARES + MOV SUELO + HORMIGON | J9: Anterior | K9: Actual | L9: Acumulado | M9: Anterior | N9: Actual | O9: Acumulado
B10: 1 | C10: TAREAS PRELIMINARES | H10: =SUM(G11:G20) -> 24784163 | I10: =+H10/$H$57 -> 0.058826981
B11: 1.01 | C11: Limpieza y preparación del terreno - No cotiza | D11: gl | E11: 0 | F11: 0 | G11: =+F11*E11 -> 0 | J11: =+'SVD 4140_Pto. 01_Cert. 2'!L11 -> 0 | L11: =+J11+K11 -> 0 | M11: =+G11*J11 -> 0 | N11: =+G11*K11 -> 0 | O11: =+G11*L11 -> 0
B12: 1.02 | C12: Topógrafo - Visita de obra replanteo | D12: un | E12: 3 | F12: 379588 | G12: =+F12*E12 -> 1138764 | J12: =+'SVD 4140_Pto. 01_Cert. 2'!L12 -> 0.65 | L12: =+J12+K12 -> 0.65 | M12: =+G12*J12 -> 740196.6 | N12: =+G12*K12 -> 0 | O12: =+G12*L12 -> 740196.6
B13: 1.03 | C13: Cartel de Obra - No cotiza | D13: gl | E13: 0 | F13: 0 | G13: =+F13*E13 -> 0 | J13: =+'SVD 4140_Pto. 01_Cert. 2'!L13 -> 0 | L13: =+J13+K13 -> 0 | M13: =+G13*J13 -> 0 | N13: =+G13*K13 -> 0 | O13: =+G13*L13 -> 0
B14: 1.04 | C14: Cerco de obra perimetral - En chapa C25 + Concertina + Porton corredizo | D14: ml | E14: 11 | F14: 141220 | G14: =+F14*E14 -> 1553420 | J14: =+'SVD 4140_Pto. 01_Cert. 2'!L14 -> 0 | L14: =+J14+K14 -> 0 | M14: =+G14*J14 -> 0 | N14: =+G14*K14 -> 0 | O14: =+G14*L14 -> 0
B15: 1.05 | C15: Obrador colgante, pañol y ducha | D15: gl | E15: 1 | F15: 7548771 | G15: =+F15*E15 -> 7548771 | J15: =+'SVD 4140_Pto. 01_Cert. 2'!L15 -> 0.5 | L15: =+J15+K15 -> 0.5 | M15: =+G15*J15 -> 3774385.5 | N15: =+G15*K15 -> 0 | O15: =+G15*L15 -> 3774385.5
B16: 1.06 | C16: Alquiler de baños quimicos y duchas portatiles | D16: mes | E16: 3 | F16: 392028 | G16: =+F16*E16 -> 1176084 | J16: =+'SVD 4140_Pto. 01_Cert. 2'!L16 -> 0.5 | K16: 0.25 | L16: =+J16+K16 -> 0.75 | M16: =+G16*J16 -> 588042 | N16: =+G16*K16 -> 294021 | O16: =+G16*L16 -> 882063
B17: 1.07 | C17: Conexión pilar y luz de obra + Tablero de obra | D17: gl | E17: 1 | F17: 1731320 | G17: =+F17*E17 -> 1731320 | J17: =+'SVD 4140_Pto. 01_Cert. 2'!L17 -> 0.7 | L17: =+J17+K17 -> 0.7 | M17: =+G17*J17 -> 1211924 | N17: =+G17*K17 -> 0 | O17: =+G17*L17 -> 1211924
B18: 1.08 | C18: Conexión agua de obra, tanque + bomba | D18: gl | E18: 1 | F18: 1405632 | G18: =+F18*E18 -> 1405632 | J18: =+'SVD 4140_Pto. 01_Cert. 2'!L18 -> 0 | L18: =+J18+K18 -> 0 | M18: =+G18*J18 -> 0 | N18: =+G18*K18 -> 0 | O18: =+G18*L18 -> 0
B19: 1.09 | C19: Tramite luz de obra, certificado luz de obra (2) y medición PAT | D19: gl | E19: 1 | F19: 426487 | G19: =+F19*E19 -> 426487 | J19: =+'SVD 4140_Pto. 01_Cert. 2'!L19 -> 0.5 | L19: =+J19+K19 -> 0.5 | M19: =+G19*J19 -> 213243.5 | N19: =+G19*K19 -> 0 | O19: =+G19*L19 -> 213243.5
B20: 1.1 | C20: Sistema de depresión de napas | D20: gl | E20: 1 | F20: 9803685 | G20: =+F20*E20 -> 9803685 | J20: =+'SVD 4140_Pto. 01_Cert. 2'!L20 -> 1 | L20: =+J20+K20 -> 1 | M20: =+G20*J20 -> 9803685 | N20: =+G20*K20 -> 0 | O20: =+G20*L20 -> 9803685
B21: 2 | C21: MOVIMIENTO DE TIERRA, COMPACTACION Y RELLENO | H21: =SUM(G22:G24) -> 42017464 | I21: =+H21/$H$57 -> 0.099731451
B22: 2.01 | C22: Excavación a maquina para submuración y subsuelo | D22: m3 | E22: 1266 | F22: 33090 | G22: =+F22*E22 -> 41891940 | J22: =+'SVD 4140_Pto. 01_Cert. 2'!L22 -> 0.35 | K22: 0.15 | L22: =+J22+K22 -> 0.5 | M22: =+G22*J22 -> 14662179 | N22: =+G22*K22 -> 6283791 | O22: =+G22*L22 -> 20945970
B23: 2.02 | C23: Demolición y retiro de fundaciones existentes - No cotiza | D23: gl | E23: 0 | F23: 0 | G23: =+F23*E23 -> 0 | J23: =+'SVD 4140_Pto. 01_Cert. 2'!L23 -> 0 | L23: =+J23+K23 -> 0 | M23: =+G23*J23 -> 0 | N23: =+G23*K23 -> 0 | O23: =+G23*L23 -> 0
B24: 2.03 | C24: Excavación manual para pozo de achique y bombeo | D24: m3 | E24: 2 | F24: 62762 | G24: =+F24*E24 -> 125524 | J24: =+'SVD 4140_Pto. 01_Cert. 2'!L24 -> 0 | L24: =+J24+K24 -> 0 | M24: =+G24*J24 -> 0 | N24: =+G24*K24 -> 0 | O24: =+G24*L24 -> 0
B25: 3 | C25: ESTRUCTURA RESISTENTE - sin provision de hierro y hormigon (incluye corte y doblado en obra) | H25: =SUM(G26:G42) -> 277149875 | I25: =+H25/$H$57 -> 0.65783502
B26: 3.01 | C26: Hormigón de limpieza - e: 10 cm | D26: m3 | E26: 35 | F26: 314478 | G26: =+F26*E26 -> 11006730 | J26: =+'SVD 4140_Pto. 01_Cert. 2'!L26 -> 0.15 | K26: 0.1 | L26: =+J26+K26 -> 0.25 | M26: =+G26*J26 -> 1651009.5 | N26: =+G26*K26 -> 1100673 | O26: =+G26*L26 -> 2751682.5
B27: 3.02 | C27: Tabique submuración - H30 hidrófugo (95 kg/m3 de hierro) | D27: m3 | E27: 40 | F27: 536061.6 | G27: =+F27*E27 -> 21442464 | J27: =+'SVD 4140_Pto. 01_Cert. 2'!L27 -> 0.25 | K27: 0.2 | L27: =+J27+K27 -> 0.45 | M27: =+G27*J27 -> 5360616 | N27: =+G27*K27 -> 4288492.8 | O27: =+G27*L27 -> 9649108.9
B28: 3.03 | C28: Zapata corrida tabique - H30 hidrófugo (120 kg/m3) | D28: m3 | E28: 28 | F28: 437680.76 | G28: =+F28*E28 -> 12255061 | J28: =+'SVD 4140_Pto. 01_Cert. 2'!L28 -> 0.25 | K28: 0.2 | L28: =+J28+K28 -> 0.45 | M28: =+G28*J28 -> 3063765.3 | N28: =+G28*K28 -> 2451012.3 | O28: =+G28*L28 -> 5514777.6
B29: 3.04 | C29: Platea - H30 hidrófugo (95 kg/m3 de hierro) | D29: m3 | E29: 179 | F29: 214461.72 | G29: =+F29*E29 -> 38388648 | J29: =+'SVD 4140_Pto. 01_Cert. 2'!L29 -> 0.15 | K29: 0.15 | L29: =+J29+K29 -> 0.3 | M29: =+G29*J29 -> 5758297.1 | N29: =+G29*K29 -> 5758297.1 | O29: =+G29*L29 -> 11516594
B30: 3.05 | C30: Rampa - H30 (120 kg/m3 de hierro) | D30: m3 | E30: 10 | F30: 462731.65 | G30: =+F30*E30 -> 4627316.5 | J30: =+'SVD 4140_Pto. 01_Cert. 2'!L30 -> 0 | L30: =+J30+K30 -> 0 | M30: =+G30*J30 -> 0 | N30: =+G30*K30 -> 0 | O30: =+G30*L30 -> 0
B31: 3.06 | C31: Losa maciza - H30 (110 kg/m3 de hierro) | D31: m3 | E31: 177 | F31: 317280.61 | G31: =+F31*E31 -> 56158669 | J31: =+'SVD 4140_Pto. 01_Cert. 2'!L31 -> 0 | L31: =+J31+K31 -> 0 | M31: =+G31*J31 -> 0 | N31: =+G31*K31 -> 0 | O31: =+G31*L31 -> 0
B32: 3.07 | C32: Vigas - H30 (140 kg/m3 de hierro) | D32: m3 | E32: 65 | F32: 789050.44 | G32: =+F32*E32 -> 51288278 | J32: =+'SVD 4140_Pto. 01_Cert. 2'!L32 -> 0 | L32: =+J32+K32 -> 0 | M32: =+G32*J32 -> 0 | N32: =+G32*K32 -> 0 | O32: =+G32*L32 -> 0
B33: 3.08 | C33: Vigas de H° visto - H30 (140 kg/m3 de hierro) | D33: m3 | E33: 12 | F33: 917117.82 | G33: =+F33*E33 -> 11005414 | J33: =+'SVD 4140_Pto. 01_Cert. 2'!L33 -> 0 | L33: =+J33+K33 -> 0 | M33: =+G33*J33 -> 0 | N33: =+G33*K33 -> 0 | O33: =+G33*L33 -> 0
B34: 3.09 | C34: Tabiques - H30 (120 kg/m3 de hierro) | D34: m3 | E34: 28 | F34: 536061.6 | G34: =+F34*E34 -> 15009725 | J34: =+'SVD 4140_Pto. 01_Cert. 2'!L34 -> 0 | L34: =+J34+K34 -> 0 | M34: =+G34*J34 -> 0 | N34: =+G34*K34 -> 0 | O34: =+G34*L34 -> 0
B35: 3.1 | C35: Columna - H30 (240 Kg/m3 de hierro) | D35: m3 | E35: 54 | F35: 473858.97 | G35: =+F35*E35 -> 25588384 | J35: =+'SVD 4140_Pto. 01_Cert. 2'!L35 -> 0 | L35: =+J35+K35 -> 0 | M35: =+G35*J35 -> 0 | N35: =+G35*K35 -> 0 | O35: =+G35*L35 -> 0
B36: 3.11 | C36: Escaleras - H30 (105 kg/m3 de hierro) | D36: m3 | E36: 11 | F36: 497587.77 | G36: =+F36*E36 -> 5473465.5 | J36: =+'SVD 4140_Pto. 01_Cert. 2'!L36 -> 0 | L36: =+J36+K36 -> 0 | M36: =+G36*J36 -> 0 | N36: =+G36*K36 -> 0 | O36: =+G36*L36 -> 0
B37: 3.12 | C37: Tabiques tanques de H° - H30 (120 kg/m3 de hierro) | D37: m3 | E37: 3 | F37: 536061.6 | G37: =+F37*E37 -> 1608184.8 | J37: =+'SVD 4140_Pto. 01_Cert. 2'!L37 -> 0 | L37: =+J37+K37 -> 0 | M37: =+G37*J37 -> 0 | N37: =+G37*K37 -> 0 | O37: =+G37*L37 -> 0
B38: 3.13 | C38: Junta de impermeabilización de PVC - Sika Waterbars v15 x 15mts o similar | D38: ml | E38: 240 | F38: 31137 | G38: =+F38*E38 -> 7472880 | J38: =+'SVD 4140_Pto. 01_Cert. 2'!L38 -> 0.15 | K38: 0.3 | L38: =+J38+K38 -> 0.45 | M38: =+G38*J38 -> 1120932 | N38: =+G38*K38 -> 2241864 | O38: =+G38*L38 -> 3362796
B39: 3.14 | C39: Sistema de apuntalamiento y reapuntalamiento | D39: gl | E39: 1 | F39: 11089161 | G39: =+F39*E39 -> 11089161 | J39: =+'SVD 4140_Pto. 01_Cert. 2'!L39 -> 0 | L39: =+J39+K39 -> 0 | M39: =+G39*J39 -> 0 | N39: =+G39*K39 -> 0 | O39: =+G39*L39 -> 0
B40: 3.15 | C40: Ensayos de Hormigon por etapas de hormigonado | D40: u | E40: 14 | F40: 155217 | G40: =+F40*E40 -> 2173038 | J40: =+'SVD 4140_Pto. 01_Cert. 2'!L40 -> 0.05 | K40: 0.1 | L40: =+J40+K40 -> 0.15 | M40: =+G40*J40 -> 108651.9 | N40: =+G40*K40 -> 217303.8 | O40: =+G40*L40 -> 325955.7
B41: 3.16 | C41: Permiso de estacionamiento de bomba de hormigón a contramano | D41: gl | E41: 4 | F41: 69129 | G41: =+F41*E41 -> 276516 | J41: =+'SVD 4140_Pto. 01_Cert. 2'!L41 -> 0.25 | L41: =+J41+K41 -> 0.25 | M41: =+G41*J41 -> 69129 | N41: =+G41*K41 -> 0 | O41: =+G41*L41 -> 69129
B42: 3.17 | C42: Picado de medianeras para columnas y vigas - Cotizado solo para PB y 1P, No contempla picado en SS | D42: m2 | E42: 93 | F42: 24580 | G42: =+F42*E42 -> 2285940 | J42: =+'SVD 4140_Pto. 01_Cert. 2'!L42 -> 0 | L42: =+J42+K42 -> 0 | M42: =+G42*J42 -> 0 | N42: =+G42*K42 -> 0 | O42: =+G42*L42 -> 0
...

Sheet SVD 4140_Pto. 01_Cert. 4
G2: DÓLAR BNA | H2: DÓLAR MEP
G3: 1005 | H3: 1170
G5: 45628
C6: OBRA: EDIFICIO EL SALVADOR 4140 | J6: Certificado | K6: 4 | O6: 45835
C7: PRESUPUESTO OBRA CIVIL
C8: Descripción | D8: U | E8: Cant | F8: P unit | G8: Subtotal | J8: Avance | M8: Importe
C9: PRESUPUESTO 01 - PRELIMINARES + MOV SUELO + HORMIGON | J9: Anterior | K9: Actual | L9: Acumulado | M9: Anterior | N9: Actual | O9: Acumulado
B10: 1 | C10: TAREAS PRELIMINARES | H10: =SUM(G11:G20) -> 24784163 | I10: =+H10/$H$57 -> 0.058826981
B11: 1.01 | C11: Limpieza y preparación del terreno - No cotiza | D11: gl | E11: 0 | F11: 0 | G11: =+F11*E11 -> 0 | J11: =+'SVD 4140_Pto. 01_Cert. 3'!L11 -> 0 | L11: =+J11+K11 -> 0 | M11: =+G11*J11 -> 0 | N11: =+G11*K11 -> 0 | O11: =+G11*L11 -> 0
B12: 1.02 | C12: Topógrafo - Visita de obra replanteo | D12: un | E12: 3 | F12: 379588 | G12: =+F12*E12 -> 1138764 | J12: =+'SVD 4140_Pto. 01_Cert. 3'!L12 -> 0.65 | L12: =+J12+K12 -> 0.65 | M12: =+G12*J12 -> 740196.6 | N12: =+G12*K12 -> 0 | O12: =+G12*L12 -> 740196.6
B13: 1.03 | C13: Cartel de Obra - No cotiza | D13: gl | E13: 0 | F13: 0 | G13: =+F13*E13 -> 0 | J13: =+'SVD 4140_Pto. 01_Cert. 3'!L13 -> 0 | L13: =+J13+K13 -> 0 | M13: =+G13*J13 -> 0 | N13: =+G13*K13 -> 0 | O13: =+G13*L13 -> 0
B14: 1.04 | C14: Cerco de obra perimetral - En chapa C25 + Concertina + Porton corredizo | D14: ml | E14: 11 | F14: 141220 | G14: =+F14*E14 -> 1553420 | J14: =+'SVD 4140_Pto. 01_Cert. 3'!L14 -> 0 | L14: =+J14+K14 -> 0 | M14: =+G14*J14 -> 0 | N14: =+G14*K14 -> 0 | O14: =+G14*L14 -> 0
B15: 1.05 | C15: Obrador colgante, pañol y ducha | D15: gl | E15: 1 | F15: 7548771 | G15: =+F15*E15 -> 7548771 | J15: =+'SVD 4140_Pto. 01_Cert. 3'!L15 -> 0.5 | L15: =+J15+K15 -> 0.5 | M15: =+G15*J15 -> 3774385.5 | N15: =+G15*K15 -> 0 | O15: =+G15*L15 -> 3774385.5
B16: 1.06 | C16: Alquiler de baños quimicos y duchas portatiles | D16: mes | E16: 3 | F16: 392028 | G16: =+F16*E16 -> 1176084 | J16: =+'SVD 4140_Pto. 01_Cert. 3'!L16 -> 0.75 | K16: 0.25 | L16: =+J16+K16 -> 1 | M16: =+G16*J16 -> 882063 | N16: =+G16*K16 -> 294021 | O16: =+G16*L16 -> 1176084
B17: 1.07 | C17: Conexión pilar y luz de obra + Tablero de obra | D17: gl | E17: 1 | F17: 1731320 | G17: =+F17*E17 -> 1731320 | J17: =+'SVD 4140_Pto. 01_Cert. 3'!L17 -> 0.7 | L17: =+J17+K17 -> 0.7 | M17: =+G17*J17 -> 1211924 | N17: =+G17*K17 -> 0 | O17: =+G17*L17 -> 1211924
B18: 1.08 | C18: Conexión agua de obra, tanque + bomba | D18: gl | E18: 1 | F18: 1405632 | G18: =+F18*E18 -> 1405632 | J18: =+'SVD 4140_Pto. 01_Cert. 3'!L18 -> 0 | L18: =+J18+K18 -> 0 | M18: =+G18*J18 -> 0 | N18: =+G18*K18 -> 0 | O18: =+G18*L18 -> 0
B19: 1.09 | C19: Tramite luz de obra, certificado luz de obra (2) y medición PAT | D19: gl | E19: 1 | F19: 426487 | G19: =+F19*E19 -> 426487 | J19: =+'SVD 4140_Pto. 01_Cert. 3'!L19 -> 0.5 | L19: =+J19+K19 -> 0.5 | M19: =+G19*J19 -> 213243.5 | N19: =+G19*K19 -> 0 | O19: =+G19*L19 -> 213243.5
B20: 1.1 | C20: Sistema de depresión de napas | D20: gl | E20: 1 | F20: 9803685 | G20: =+F20*E20 -> 9803685 | J20: =+'SVD 4140_Pto. 01_Cert. 3'!L20 -> 1 | L20: =+J20+K20 -> 1 | M20: =+G20*J20 -> 9803685 | N20: =+G20*K20 -> 0 | O20: =+G20*L20 -> 9803685
B21: 2 | C21: MOVIMIENTO DE TIERRA, COMPACTACION Y RELLENO | H21: =SUM(G22:G24) -> 42017464 | I21: =+H21/$H$57 -> 0.099731451
B22: 2.01 | C22: Excavación a maquina para submuración y subsuelo | D22: m3 | E22: 1266 | F22: 33090 | G22: =+F22*E22 -> 41891940 | J22: =+'SVD 4140_Pto. 01_Cert. 3'!L22 -> 0.5 | K22: 0.2 | L22: =+J22+K22 -> 0.7 | M22: =+G22*J22 -> 20945970 | N22: =+G22*K22 -> 8378388 | O22: =+G22*L22 -> 29324358
B23: 2.02 | C23: Demolición y retiro de fundaciones existentes - No cotiza | D23: gl | E23: 0 | F23: 0 | G23: =+F23*E23 -> 0 | J23: =+'SVD 4140_Pto. 01_Cert. 3'!L23 -> 0 | L23: =+J23+K23 -> 0 | M23: =+G23*J23 -> 0 | N23: =+G23*K23 -> 0 | O23: =+G23*L23 -> 0
B24: 2.03 | C24: Excavación manual para pozo de achique y bombeo | D24: m3 | E24: 2 | F24: 62762 | G24: =+F24*E24 -> 125524 | J24: =+'SVD 4140_Pto. 01_Cert. 3'!L24 -> 0 | L24: =+J24+K24 -> 0 | M24: =+G24*J24 -> 0 | N24: =+G24*K24 -> 0 | O24: =+G24*L24 -> 0
B25: 3 | C25: ESTRUCTURA RESISTENTE - sin provision de hierro y hormigon (incluye corte y doblado en obra) | H25: =SUM(G26:G42) -> 277149875 | I25: =+H25/$H$57 -> 0.65783502
B26: 3.01 | C26: Hormigón de limpieza - e: 10 cm | D26: m3 | E26: 35 | F26: 314478 | G26: =+F26*E26 -> 11006730 | J26: =+'SVD 4140_Pto. 01_Cert. 3'!L26 -> 0.25 | K26: 0.35 | L26: =+J26+K26 -> 0.6 | M26: =+G26*J26 -> 2751682.5 | N26: =+G26*K26 -> 3852355.5 | O26: =+G26*L26 -> 6604038
B27: 3.02 | C27: Tabique submuración - H30 hidrófugo (95 kg/m3 de hierro) | D27: m3 | E27: 40 | F27: 536061.6 | G27: =+F27*E27 -> 21442464 | J27: =+'SVD 4140_Pto. 01_Cert. 3'!L27 -> 0.45 | K27: 0.15 | L27: =+J27+K27 -> 0.6 | M27: =+G27*J27 -> 9649108.9 | N27: =+G27*K27 -> 3216369.6 | O27: =+G27*L27 -> 12865479
B28: 3.03 | C28: Zapata corrida tabique - H30 hidrófugo (120 kg/m3) | D28: m3 | E28: 28 | F28: 437680.76 | G28: =+F28*E28 -> 12255061 | J28: =+'SVD 4140_Pto. 01_Cert. 3'!L28 -> 0.45 | K28: 0.15 | L28: =+J28+K28 -> 0.6 | M28: =+G28*J28 -> 5514777.6 | N28: =+G28*K28 -> 1838259.2 | O28: =+G28*L28 -> 7353036.8
B29: 3.04 | C29: Platea - H30 hidrófugo (95 kg/m3 de hierro) | D29: m3 | E29: 179 | F29: 214461.72 | G29: =+F29*E29 -> 38388648 | J29: =+'SVD 4140_Pto. 01_Cert. 3'!L29 -> 0.3 | K29: 0.3 | L29: =+J29+K29 -> 0.6 | M29: =+G29*J29 -> 11516594 | N29: =+G29*K29 -> 11516594 | O29: =+G29*L29 -> 23033189
B30: 3.05 | C30: Rampa - H30 (120 kg/m3 de hierro) | D30: m3 | E30: 10 | F30: 462731.65 | G30: =+F30*E30 -> 4627316.5 | J30: =+'SVD 4140_Pto. 01_Cert. 3'!L30 -> 0 | L30: =+J30+K30 -> 0 | M30: =+G30*J30 -> 0 | N30: =+G30*K30 -> 0 | O30: =+G30*L30 -> 0
B31: 3.06 | C31: Losa maciza - H30 (110 kg/m3 de hierro) | D31: m3 | E31: 177 | F31: 317280.61 | G31: =+F31*E31 -> 56158669 | J31: =+'SVD 4140_Pto. 01_Cert. 3'!L31 -> 0 | L31: =+J31+K31 -> 0 | M31: =+G31*J31 -> 0 | N31: =+G31*K31 -> 0 | O31: =+G31*L31 -> 0
B32: 3.07 | C32: Vigas - H30 (140 kg/m3 de hierro) | D32: m3 | E32: 65 | F32: 789050.44 | G32: =+F32*E32 -> 51288278 | J32: =+'SVD 4140_Pto. 01_Cert. 3'!L32 -> 0 | L32: =+J32+K32 -> 0 | M32: =+G32*J32 -> 0 | N32: =+G32*K32 -> 0 | O32: =+G32*L32 -> 0
B33: 3.08 | C33: Vigas de H° visto - H30 (140 kg/m3 de hierro) | D33: m3 | E33: 12 | F33: 917117.82 | G33: =+F33*E33 -> 11005414 | J33: =+'SVD 4140_Pto. 01_Cert. 3'!L33 -> 0 | L33: =+J33+K33 -> 0 | M33: =+G33*J33 -> 0 | N33: =+G33*K33 -> 0 | O33: =+G33*L33 -> 0
B34: 3.09 | C34: Tabiques - H30 (120 kg/m3 de hierro) | D34: m3 | E34: 28 | F34: 536061.6 | G34: =+F34*E34 -> 15009725 | J34: =+'SVD 4140_Pto. 01_Cert. 3'!L34 -> 0 | K34: 0.05 | L34: =+J34+K34 -> 0.05 | M34: =+G34*J34 -> 0 | N34: =+G34*K34 -> 750486.25 | O34: =+G34*L34 -> 750486.25
B35: 3.1 | C35: Columna - H30 (240 Kg/m3 de hierro) | D35: m3 | E35: 54 | F35: 473858.97 | G35: =+F35*E35 -> 25588384 | J35: =+'SVD 4140_Pto. 01_Cert. 3'!L35 -> 0 | L35: =+J35+K35 -> 0 | M35: =+G35*J35 -> 0 | N35: =+G35*K35 -> 0 | O35: =+G35*L35 -> 0
B36: 3.11 | C36: Escaleras - H30 (105 kg/m3 de hierro) | D36: m3 | E36: 11 | F36: 497587.77 | G36: =+F36*E36 -> 5473465.5 | J36: =+'SVD 4140_Pto. 01_Cert. 3'!L36 -> 0 | L36: =+J36+K36 -> 0 | M36: =+G36*J36 -> 0 | N36: =+G36*K36 -> 0 | O36: =+G36*L36 -> 0
B37: 3.12 | C37: Tabiques tanques de H° - H30 (120 kg/m3 de hierro) | D37: m3 | E37: 3 | F37: 536061.6 | G37: =+F37*E37 -> 1608184.8 | J37: =+'SVD 4140_Pto. 01_Cert. 3'!L37 -> 0 | L37: =+J37+K37 -> 0 | M37: =+G37*J37 -> 0 | N37: =+G37*K37 -> 0 | O37: =+G37*L37 -> 0
B38: 3.13 | C38: Junta de impermeabilización de PVC - Sika Waterbars v15 x 15mts o similar | D38: ml | E38: 240 | F38: 31137 | G38: =+F38*E38 -> 7472880 | J38: =+'SVD 4140_Pto. 01_Cert. 3'!L38 -> 0.45 | K38: 0.25 | L38: =+J38+K38 -> 0.7 | M38: =+G38*J38 -> 3362796 | N38: =+G38*K38 -> 1868220 | O38: =+G38*L38 -> 5231016
B39: 3.14 | C39: Sistema de apuntalamiento y reapuntalamiento | D39: gl | E39: 1 | F39: 11089161 | G39: =+F39*E39 -> 11089161 | J39: =+'SVD 4140_Pto. 01_Cert. 3'!L39 -> 0 | L39: =+J39+K39 -> 0 | M39: =+G39*J39 -> 0 | N39: =+G39*K39 -> 0 | O39: =+G39*L39 -> 0
B40: 3.15 | C40: Ensayos de Hormigon por etapas de hormigonado | D40: u | E40: 14 | F40: 155217 | G40: =+F40*E40 -> 2173038 | J40: =+'SVD 4140_Pto. 01_Cert. 3'!L40 -> 0.15 | L40: =+J40+K40 -> 0.15 | M40: =+G40*J40 -> 325955.7 | N40: =+G40*K40 -> 0 | O40: =+G40*L40 -> 325955.7
B41: 3.16 | C41: Permiso de estacionamiento de bomba de hormigón a contramano | D41: gl | E41: 4 | F41: 69129 | G41: =+F41*E41 -> 276516 | J41: =+'SVD 4140_Pto. 01_Cert. 3'!L41 -> 0.25 | L41: =+J41+K41 -> 0.25 | M41: =+G41*J41 -> 69129 | N41: =+G41*K41 -> 0 | O41: =+G41*L41 -> 69129
B42: 3.17 | C42: Picado de medianeras para columnas y vigas - Cotizado solo para PB y 1P, No contempla picado en SS | D42: m2 | E42: 93 | F42: 24580 | G42: =+F42*E42 -> 2285940 | J42: =+'SVD 4140_Pto. 01_Cert. 3'!L42 -> 0 | L42: =+J42+K42 -> 0 | M42: =+G42*J42 -> 0 | N42: =+G42*K42 -> 0 | O42: =+G42*L42 -> 0
...

Sheet SVD 4140_Pto. 01_Cert. 5
G2: DÓLAR BNA | H2: DÓLAR MEP
G3: 1005 | H3: 1170
G5: 45628
C6: OBRA: EDIFICIO EL SALVADOR 4140 | J6: Certificado | K6: 5 | O6: 45861
C7: PRESUPUESTO OBRA CIVIL
C8: Descripción | D8: U | E8: Cant | F8: P unit | G8: Subtotal | J8: Avance | M8: Importe
C9: PRESUPUESTO 01 - PRELIMINARES + MOV SUELO + HORMIGON | J9: Anterior | K9: Actual | L9: Acumulado | M9: Anterior | N9: Actual | O9: Acumulado
B10: 1 | C10: TAREAS PRELIMINARES | H10: =SUM(G11:G20) -> 24784163 | I10: =+H10/$H$57 -> 0.058826981
B11: 1.01 | C11: Limpieza y preparación del terreno - No cotiza | D11: gl | E11: 0 | F11: 0 | G11: =+F11*E11 -> 0 | J11: =+'SVD 4140_Pto. 01_Cert. 4'!L11 -> 0 | L11: =+J11+K11 -> 0 | M11: =+G11*J11 -> 0 | N11: =+G11*K11 -> 0 | O11: =+G11*L11 -> 0
B12: 1.02 | C12: Topógrafo - Visita de obra replanteo | D12: un | E12: 3 | F12: 379588 | G12: =+F12*E12 -> 1138764 | J12: =+'SVD 4140_Pto. 01_Cert. 4'!L12 -> 0.65 | L12: =+J12+K12 -> 0.65 | M12: =+G12*J12 -> 740196.6 | N12: =+G12*K12 -> 0 | O12: =+G12*L12 -> 740196.6
B13: 1.03 | C13: Cartel de Obra - No cotiza | D13: gl | E13: 0 | F13: 0 | G13: =+F13*E13 -> 0 | J13: =+'SVD 4140_Pto. 01_Cert. 4'!L13 -> 0 | L13: =+J13+K13 -> 0 | M13: =+G13*J13 -> 0 | N13: =+G13*K13 -> 0 | O13: =+G13*L13 -> 0
B14: 1.04 | C14: Cerco de obra perimetral - En chapa C25 + Concertina + Porton corredizo | D14: ml | E14: 11 | F14: 141220 | G14: =+F14*E14 -> 1553420 | J14: =+'SVD 4140_Pto. 01_Cert. 4'!L14 -> 0 | L14: =+J14+K14 -> 0 | M14: =+G14*J14 -> 0 | N14: =+G14*K14 -> 0 | O14: =+G14*L14 -> 0
B15: 1.05 | C15: Obrador colgante, pañol y ducha | D15: gl | E15: 1 | F15: 7548771 | G15: =+F15*E15 -> 7548771 | J15: =+'SVD 4140_Pto. 01_Cert. 4'!L15 -> 0.5 | K15: 0.3 | L15: =+J15+K15 -> 0.8 | M15: =+G15*J15 -> 3774385.5 | N15: =+G15*K15 -> 2264631.3 | O15: =+G15*L15 -> 6039016.8
B16: 1.06 | C16: Alquiler de baños quimicos y duchas portatiles | D16: mes | E16: 3 | F16: 392028 | G16: =+F16*E16 -> 1176084 | J16: =+'SVD 4140_Pto. 01_Cert. 4'!L16 -> 1 | L16: =+J16+K16 -> 1 | M16: =+G16*J16 -> 1176084 | N16: =+G16*K16 -> 0 | O16: =+G16*L16 -> 1176084
B17: 1.07 | C17: Conexión pilar y luz de obra + Tablero de obra | D17: gl | E17: 1 | F17: 1731320 | G17: =+F17*E17 -> 1731320 | J17: =+'SVD 4140_Pto. 01_Cert. 4'!L17 -> 0.7 | L17: =+J17+K17 -> 0.7 | M17: =+G17*J17 -> 1211924 | N17: =+G17*K17 -> 0 | O17: =+G17*L17 -> 1211924
B18: 1.08 | C18: Conexión agua de obra, tanque + bomba | D18: gl | E18: 1 | F18: 1405632 | G18: =+F18*E18 -> 1405632 | J18: =+'SVD 4140_Pto. 01_Cert. 4'!L18 -> 0 | L18: =+J18+K18 -> 0 | M18: =+G18*J18 -> 0 | N18: =+G18*K18 -> 0 | O18: =+G18*L18 -> 0
B19: 1.09 | C19: Tramite luz de obra, certificado luz de obra (2) y medición PAT | D19: gl | E19: 1 | F19: 426487 | G19: =+F19*E19 -> 426487 | J19: =+'SVD 4140_Pto. 01_Cert. 4'!L19 -> 0.5 | L19: =+J19+K19 -> 0.5 | M19: =+G19*J19 -> 213243.5 | N19: =+G19*K19 -> 0 | O19: =+G19*L19 -> 213243.5
B20: 1.1 | C20: Sistema de depresión de napas | D20: gl | E20: 1 | F20: 9803685 | G20: =+F20*E20 -> 9803685 | J20: =+'SVD 4140_Pto. 01_Cert. 4'!L20 -> 1 | L20: =+J20+K20 -> 1 | M20: =+G20*J20 -> 9803685 | N20: =+G20*K20 -> 0 | O20: =+G20*L20 -> 9803685
B21: 2 | C21: MOVIMIENTO DE TIERRA, COMPACTACION Y RELLENO | H21: =SUM(G22:G24) -> 42017464 | I21: =+H21/$H$57 -> 0.099731451
B22: 2.01 | C22: Excavación a maquina para submuración y subsuelo | D22: m3 | E22: 1266 | F22: 33090 | G22: =+F22*E22 -> 41891940 | J22: =+'SVD 4140_Pto. 01_Cert. 4'!L22 -> 0.7 | K22: 0.2 | L22: =+J22+K22 -> 0.9 | M22: =+G22*J22 -> 29324358 | N22: =+G22*K22 -> 8378388 | O22: =+G22*L22 -> 37702746
B23: 2.02 | C23: Demolición y retiro de fundaciones existentes - No cotiza | D23: gl | E23: 0 | F23: 0 | G23: =+F23*E23 -> 0 | J23: =+'SVD 4140_Pto. 01_Cert. 4'!L23 -> 0 | L23: =+J23+K23 -> 0 | M23: =+G23*J23 -> 0 | N23: =+G23*K23 -> 0 | O23: =+G23*L23 -> 0
B24: 2.03 | C24: Excavación manual para pozo de achique y bombeo | D24: m3 | E24: 2 | F24: 62762 | G24: =+F24*E24 -> 125524 | J24: =+'SVD 4140_Pto. 01_Cert. 4'!L24 -> 0 | L24: =+J24+K24 -> 0 | M24: =+G24*J24 -> 0 | N24: =+G24*K24 -> 0 | O24: =+G24*L24 -> 0
B25: 3 | C25: ESTRUCTURA RESISTENTE - sin provision de hierro y hormigon (incluye corte y doblado en obra) | H25: =SUM(G26:G42) -> 277149875 | I25: =+H25/$H$57 -> 0.65783502
B26: 3.01 | C26: Hormigón de limpieza - e: 10 cm | D26: m3 | E26: 35 | F26: 314478 | G26: =+F26*E26 -> 11006730 | J26: =+'SVD 4140_Pto. 01_Cert. 4'!L26 -> 0.6 | L26: =+J26+K26 -> 0.6 | M26: =+G26*J26 -> 6604038 | N26: =+G26*K26 -> 0 | O26: =+G26*L26 -> 6604038
B27: 3.02 | C27: Tabique submuración - H30 hidrófugo (95 kg/m3 de hierro) | D27: m3 | E27: 40 | F27: 536061.6 | G27: =+F27*E27 -> 21442464 | J27: =+'SVD 4140_Pto. 01_Cert. 4'!L27 -> 0.6 | L27: =+J27+K27 -> 0.6 | M27: =+G27*J27 -> 12865479 | N27: =+G27*K27 -> 0 | O27: =+G27*L27 -> 12865479
B28: 3.03 | C28: Zapata corrida tabique - H30 hidrófugo (120 kg/m3) | D28: m3 | E28: 28 | F28: 437680.76 | G28: =+F28*E28 -> 12255061 | J28: =+'SVD 4140_Pto. 01_Cert. 4'!L28 -> 0.6 | L28: =+J28+K28 -> 0.6 | M28: =+G28*J28 -> 7353036.8 | N28: =+G28*K28 -> 0 | O28: =+G28*L28 -> 7353036.8
B29: 3.04 | C29: Platea - H30 hidrófugo (95 kg/m3 de hierro) | D29: m3 | E29: 179 | F29: 214461.72 | G29: =+F29*E29 -> 38388648 | J29: =+'SVD 4140_Pto. 01_Cert. 4'!L29 -> 0.6 | L29: =+J29+K29 -> 0.6 | M29: =+G29*J29 -> 23033189 | N29: =+G29*K29 -> 0 | O29: =+G29*L29 -> 23033189
B30: 3.05 | C30: Rampa - H30 (120 kg/m3 de hierro) | D30: m3 | E30: 10 | F30: 462731.65 | G30: =+F30*E30 -> 4627316.5 | J30: =+'SVD 4140_Pto. 01_Cert. 4'!L30 -> 0 | L30: =+J30+K30 -> 0 | M30: =+G30*J30 -> 0 | N30: =+G30*K30 -> 0 | O30: =+G30*L30 -> 0
B31: 3.06 | C31: Losa maciza - H30 (110 kg/m3 de hierro) | D31: m3 | E31: 177 | F31: 317280.61 | G31: =+F31*E31 -> 56158669 | J31: =+'SVD 4140_Pto. 01_Cert. 4'!L31 -> 0 | K31: 0.1 | L31: =+J31+K31 -> 0.1 | M31: =+G31*J31 -> 0 | N31: =+G31*K31 -> 5615866.9 | O31: =+G31*L31 -> 5615866.9
B32: 3.07 | C32: Vigas - H30 (140 kg/m3 de hierro) | D32: m3 | E32: 65 | F32: 789050.44 | G32: =+F32*E32 -> 51288278 | J32: =+'SVD 4140_Pto. 01_Cert. 4'!L32 -> 0 | K32: 0.22 | L32: =+J32+K32 -> 0.22 | M32: =+G32*J32 -> 0 | N32: =+G32*K32 -> 11283421 | O32: =+G32*L32 -> 11283421
B33: 3.08 | C33: Vigas de H° visto - H30 (140 kg/m3 de hierro) | D33: m3 | E33: 12 | F33: 917117.82 | G33: =+F33*E33 -> 11005414 | J33: =+'SVD 4140_Pto. 01_Cert. 4'!L33 -> 0 | L33: =+J33+K33 -> 0 | M33: =+G33*J33 -> 0 | N33: =+G33*K33 -> 0 | O33: =+G33*L33 -> 0
B34: 3.09 | C34: Tabiques - H30 (120 kg/m3 de hierro) | D34: m3 | E34: 28 | F34: 536061.6 | G34: =+F34*E34 -> 15009725 | J34: =+'SVD 4140_Pto. 01_Cert. 4'!L34 -> 0.05 | K34: 0.05 | L34: =+J34+K34 -> 0.1 | M34: =+G34*J34 -> 750486.25 | N34: =+G34*K34 -> 750486.25 | O34: =+G34*L34 -> 1500972.5
B35: 3.1 | C35: Columna - H30 (240 Kg/m3 de hierro) | D35: m3 | E35: 54 | F35: 473858.97 | G35: =+F35*E35 -> 25588384 | J35: =+'SVD 4140_Pto. 01_Cert. 4'!L35 -> 0 | K35: 0.1 | L35: =+J35+K35 -> 0.1 | M35: =+G35*J35 -> 0 | N35: =+G35*K35 -> 2558838.4 | O35: =+G35*L35 -> 2558838.4
B36: 3.11 | C36: Escaleras - H30 (105 kg/m3 de hierro) | D36: m3 | E36: 11 | F36: 497587.77 | G36: =+F36*E36 -> 5473465.5 | J36: =+'SVD 4140_Pto. 01_Cert. 4'!L36 -> 0 | L36: =+J36+K36 -> 0 | M36: =+G36*J36 -> 0 | N36: =+G36*K36 -> 0 | O36: =+G36*L36 -> 0
B37: 3.12 | C37: Tabiques tanques de H° - H30 (120 kg/m3 de hierro) | D37: m3 | E37: 3 | F37: 536061.6 | G37: =+F37*E37 -> 1608184.8 | J37: =+'SVD 4140_Pto. 01_Cert. 4'!L37 -> 0 | L37: =+J37+K37 -> 0 | M37: =+G37*J37 -> 0 | N37: =+G37*K37 -> 0 | O37: =+G37*L37 -> 0
B38: 3.13 | C38: Junta de impermeabilización de PVC - Sika Waterbars v15 x 15mts o similar | D38: ml | E38: 240 | F38: 31137 | G38: =+F38*E38 -> 7472880 | J38: =+'SVD 4140_Pto. 01_Cert. 4'!L38 -> 0.7 | L38: =+J38+K38 -> 0.7 | M38: =+G38*J38 -> 5231016 | N38: =+G38*K38 -> 0 | O38: =+G38*L38 -> 5231016
B39: 3.14 | C39: Sistema de apuntalamiento y reapuntalamiento | D39: gl | E39: 1 | F39: 11089161 | G39: =+F39*E39 -> 11089161 | J39: =+'SVD 4140_Pto. 01_Cert. 4'!L39 -> 0 | K39: 0.15 | L39: =+J39+K39 -> 0.15 | M39: =+G39*J39 -> 0 | N39: =+G39*K39 -> 1663374.1 | O39: =+G39*L39 -> 1663374.1
B40: 3.15 | C40: Ensayos de Hormigon por etapas de hormigonado | D40: u | E40: 14 | F40: 155217 | G40: =+F40*E40 -> 2173038 | J40: =+'SVD 4140_Pto. 01_Cert. 4'!L40 -> 0.15 | K40: 0.2 | L40: =+J40+K40 -> 0.35 | M40: =+G40*J40 -> 325955.7 | N40: =+G40*K40 -> 434607.6 | O40: =+G40*L40 -> 760563.3
B41: 3.16 | C41: Permiso de estacionamiento de bomba de hormigón a contramano | D41: gl | E41: 4 | F41: 69129 | G41: =+F41*E41 -> 276516 | J41: =+'SVD 4140_Pto. 01_Cert. 4'!L41 -> 0.25 | K41: 0.25 | L41: =+J41+K41 -> 0.5 | M41: =+G41*J41 -> 69129 | N41: =+G41*K41 -> 69129 | O41: =+G41*L41 -> 138258
B42: 3.17 | C42: Picado de medianeras para columnas y vigas - Cotizado solo para PB y 1P, No contempla picado en SS | D42: m2 | E42: 93 | F42: 24580 | G42: =+F42*E42 -> 2285940 | J42: =+'SVD 4140_Pto. 01_Cert. 4'!L42 -> 0 | L42: =+J42+K42 -> 0 | M42: =+G42*J42 -> 0 | N42: =+G42*K42 -> 0 | O42: =+G42*L42 -> 0
...

Sheet SVD 4140_Pto. 01_Cert. 6
G2: DÓLAR BNA | H2: DÓLAR MEP
G3: 1005 | H3: 1170
G5: 45628
C6: OBRA: EDIFICIO EL SALVADOR 4140 | J6: Certificado | K6: 6 | O6: 45898
C7: PRESUPUESTO OBRA CIVIL
C8: Descripción | D8: U | E8: Cant | F8: P unit | G8: Subtotal | J8: Avance | M8: Importe
C9: PRESUPUESTO 01 - PRELIMINARES + MOV SUELO + HORMIGON | J9: Anterior | K9: Actual | L9: Acumulado | M9: Anterior | N9: Actual | O9: Acumulado
B10: 1 | C10: TAREAS PRELIMINARES | H10: =SUM(G11:G20) -> 24784163 | I10: =+H10/$H$57 -> 0.058826981
B11: 1.01 | C11: Limpieza y preparación del terreno - No cotiza | D11: gl | E11: 0 | F11: 0 | G11: =+F11*E11 -> 0 | J11: =+'SVD 4140_Pto. 01_Cert. 5'!L11 -> 0 | L11: =+J11+K11 -> 0 | M11: =+G11*J11 -> 0 | N11: =+G11*K11 -> 0 | O11: =+G11*L11 -> 0
B12: 1.02 | C12: Topógrafo - Visita de obra replanteo | D12: un | E12: 3 | F12: 379588 | G12: =+F12*E12 -> 1138764 | J12: =+'SVD 4140_Pto. 01_Cert. 5'!L12 -> 0.65 | L12: =+J12+K12 -> 0.65 | M12: =+G12*J12 -> 740196.6 | N12: =+G12*K12 -> 0 | O12: =+G12*L12 -> 740196.6
B13: 1.03 | C13: Cartel de Obra - No cotiza | D13: gl | E13: 0 | F13: 0 | G13: =+F13*E13 -> 0 | J13: =+'SVD 4140_Pto. 01_Cert. 5'!L13 -> 0 | L13: =+J13+K13 -> 0 | M13: =+G13*J13 -> 0 | N13: =+G13*K13 -> 0 | O13: =+G13*L13 -> 0
B14: 1.04 | C14: Cerco de obra perimetral - En chapa C25 + Concertina + Porton corredizo | D14: ml | E14: 11 | F14: 141220 | G14: =+F14*E14 -> 1553420 | J14: =+'SVD 4140_Pto. 01_Cert. 5'!L14 -> 0 | L14: =+J14+K14 -> 0 | M14: =+G14*J14 -> 0 | N14: =+G14*K14 -> 0 | O14: =+G14*L14 -> 0
B15: 1.05 | C15: Obrador colgante, pañol y ducha | D15: gl | E15: 1 | F15: 7548771 | G15: =+F15*E15 -> 7548771 | J15: =+'SVD 4140_Pto. 01_Cert. 5'!L15 -> 0.8 | L15: =+J15+K15 -> 0.8 | M15: =+G15*J15 -> 6039016.8 | N15: =+G15*K15 -> 0 | O15: =+G15*L15 -> 6039016.8
B16: 1.06 | C16: Alquiler de baños quimicos y duchas portatiles | D16: mes | E16: 3 | F16: 392028 | G16: =+F16*E16 -> 1176084 | J16: =+'SVD 4140_Pto. 01_Cert. 5'!L16 -> 1 | L16: =+J16+K16 -> 1 | M16: =+G16*J16 -> 1176084 | N16: =+G16*K16 -> 0 | O16: =+G16*L16 -> 1176084
B17: 1.07 | C17: Conexión pilar y luz de obra + Tablero de obra | D17: gl | E17: 1 | F17: 1731320 | G17: =+F17*E17 -> 1731320 | J17: =+'SVD 4140_Pto. 01_Cert. 5'!L17 -> 0.7 | K17: 0.3 | L17: =+J17+K17 -> 1 | M17: =+G17*J17 -> 1211924 | N17: =+G17*K17 -> 519396 | O17: =+G17*L17 -> 1731320
B18: 1.08 | C18: Conexión agua de obra, tanque + bomba | D18: gl | E18: 1 | F18: 1405632 | G18: =+F18*E18 -> 1405632 | J18: =+'SVD 4140_Pto. 01_Cert. 5'!L18 -> 0 | L18: =+J18+K18 -> 0 | M18: =+G18*J18 -> 0 | N18: =+G18*K18 -> 0 | O18: =+G18*L18 -> 0
B19: 1.09 | C19: Tramite luz de obra, certificado luz de obra (2) y medición PAT | D19: gl | E19: 1 | F19: 426487 | G19: =+F19*E19 -> 426487 | J19: =+'SVD 4140_Pto. 01_Cert. 5'!L19 -> 0.5 | K19: 0.15 | L19: =+J19+K19 -> 0.65 | M19: =+G19*J19 -> 213243.5 | N19: =+G19*K19 -> 63973.05 | O19: =+G19*L19 -> 277216.55
B20: 1.1 | C20: Sistema de depresión de napas | D20: gl | E20: 1 | F20: 9803685 | G20: =+F20*E20 -> 9803685 | J20: =+'SVD 4140_Pto. 01_Cert. 5'!L20 -> 1 | L20: =+J20+K20 -> 1 | M20: =+G20*J20 -> 9803685 | N20: =+G20*K20 -> 0 | O20: =+G20*L20 -> 9803685
B21: 2 | C21: MOVIMIENTO DE TIERRA, COMPACTACION Y RELLENO | H21: =SUM(G22:G24) -> 42017464 | I21: =+H21/$H$57 -> 0.099731451
B22: 2.01 | C22: Excavación a maquina para submuración y subsuelo | D22: m3 | E22: 1266 | F22: 33090 | G22: =+F22*E22 -> 41891940 | J22: =+'SVD 4140_Pto. 01_Cert. 5'!L22 -> 0.9 | K22: 0.1 | L22: =+J22+K22 -> 1 | M22: =+G22*J22 -> 37702746 | N22: =+G22*K22 -> 4189194 | O22: =+G22*L22 -> 41891940
B23: 2.02 | C23: Demolición y retiro de fundaciones existentes - No cotiza | D23: gl | E23: 0 | F23: 0 | G23: =+F23*E23 -> 0 | J23: =+'SVD 4140_Pto. 01_Cert. 5'!L23 -> 0 | L23: =+J23+K23 -> 0 | M23: =+G23*J23 -> 0 | N23: =+G23*K23 -> 0 | O23: =+G23*L23 -> 0
B24: 2.03 | C24: Excavación manual para pozo de achique y bombeo | D24: m3 | E24: 2 | F24: 62762 | G24: =+F24*E24 -> 125524 | J24: =+'SVD 4140_Pto. 01_Cert. 5'!L24 -> 0 | K24: 1 | L24: =+J24+K24 -> 1 | M24: =+G24*J24 -> 0 | N24: =+G24*K24 -> 125524 | O24: =+G24*L24 -> 125524
B25: 3 | C25: ESTRUCTURA RESISTENTE - sin provision de hierro y hormigon (incluye corte y doblado en obra) | H25: =SUM(G26:G42) -> 277149875 | I25: =+H25/$H$57 -> 0.65783502
B26: 3.01 | C26: Hormigón de limpieza - e: 10 cm | D26: m3 | E26: 35 | F26: 314478 | G26: =+F26*E26 -> 11006730 | J26: =+'SVD 4140_Pto. 01_Cert. 5'!L26 -> 0.6 | K26: 0.4 | L26: =+J26+K26 -> 1 | M26: =+G26*J26 -> 6604038 | N26: =+G26*K26 -> 4402692 | O26: =+G26*L26 -> 11006730
B27: 3.02 | C27: Tabique submuración - H30 hidrófugo (95 kg/m3 de hierro) | D27: m3 | E27: 40 | F27: 536061.6 | G27: =+F27*E27 -> 21442464 | J27: =+'SVD 4140_Pto. 01_Cert. 5'!L27 -> 0.6 | K27: 0.4 | L27: =+J27+K27 -> 1 | M27: =+G27*J27 -> 12865479 | N27: =+G27*K27 -> 8576985.7 | O27: =+G27*L27 -> 21442464
B28: 3.03 | C28: Zapata corrida tabique - H30 hidrófugo (120 kg/m3) | D28: m3 | E28: 28 | F28: 437680.76 | G28: =+F28*E28 -> 12255061 | J28: =+'SVD 4140_Pto. 01_Cert. 5'!L28 -> 0.6 | K28: 0.4 | L28: =+J28+K28 -> 1 | M28: =+G28*J28 -> 7353036.8 | N28: =+G28*K28 -> 4902024.5 | O28: =+G28*L28 -> 12255061
B29: 3.04 | C29: Platea - H30 hidrófugo (95 kg/m3 de hierro) | D29: m3 | E29: 179 | F29: 214461.72 | G29: =+F29*E29 -> 38388648 | J29: =+'SVD 4140_Pto. 01_Cert. 5'!L29 -> 0.6 | K29: 0.4 | L29: =+J29+K29 -> 1 | M29: =+G29*J29 -> 23033189 | N29: =+G29*K29 -> 15355459 | O29: =+G29*L29 -> 38388648
B30: 3.05 | C30: Rampa - H30 (120 kg/m3 de hierro) | D30: m3 | E30: 10 | F30: 462731.65 | G30: =+F30*E30 -> 4627316.5 | J30: =+'SVD 4140_Pto. 01_Cert. 5'!L30 -> 0 | K30: 0.05 | L30: =+J30+K30 -> 0.05 | M30: =+G30*J30 -> 0 | N30: =+G30*K30 -> 231365.83 | O30: =+G30*L30 -> 231365.83
B31: 3.06 | C31: Losa maciza - H30 (110 kg/m3 de hierro) | D31: m3 | E31: 177 | F31: 317280.61 | G31: =+F31*E31 -> 56158669 | J31: =+'SVD 4140_Pto. 01_Cert. 5'!L31 -> 0.1 | K31: 0.05 | L31: =+J31+K31 -> 0.15 | M31: =+G31*J31 -> 5615866.9 | N31: =+G31*K31 -> 2807933.4 | O31: =+G31*L31 -> 8423800.3
B32: 3.07 | C32: Vigas - H30 (140 kg/m3 de hierro) | D32: m3 | E32: 65 | F32: 789050.44 | G32: =+F32*E32 -> 51288278 | J32: =+'SVD 4140_Pto. 01_Cert. 5'!L32 -> 0.22 | K32: 0.08 | L32: =+J32+K32 -> 0.3 | M32: =+G32*J32 -> 11283421 | N32: =+G32*K32 -> 4103062.3 | O32: =+G32*L32 -> 15386484
B33: 3.08 | C33: Vigas de H° visto - H30 (140 kg/m3 de hierro) | D33: m3 | E33: 12 | F33: 917117.82 | G33: =+F33*E33 -> 11005414 | J33: =+'SVD 4140_Pto. 01_Cert. 5'!L33 -> 0 | L33: =+J33+K33 -> 0 | M33: =+G33*J33 -> 0 | N33: =+G33*K33 -> 0 | O33: =+G33*L33 -> 0
B34: 3.09 | C34: Tabiques - H30 (120 kg/m3 de hierro) | D34: m3 | E34: 28 | F34: 536061.6 | G34: =+F34*E34 -> 15009725 | J34: =+'SVD 4140_Pto. 01_Cert. 5'!L34 -> 0.1 | K34: 0.05 | L34: =+J34+K34 -> 0.15 | M34: =+G34*J34 -> 1500972.5 | N34: =+G34*K34 -> 750486.25 | O34: =+G34*L34 -> 2251458.7
B35: 3.1 | C35: Columna - H30 (240 Kg/m3 de hierro) | D35: m3 | E35: 54 | F35: 473858.97 | G35: =+F35*E35 -> 25588384 | J35: =+'SVD 4140_Pto. 01_Cert. 5'!L35 -> 0.1 | K35: 0.1 | L35: =+J35+K35 -> 0.2 | M35: =+G35*J35 -> 2558838.4 | N35: =+G35*K35 -> 2558838.4 | O35: =+G35*L35 -> 5117676.9
B36: 3.11 | C36: Escaleras - H30 (105 kg/m3 de hierro) | D36: m3 | E36: 11 | F36: 497587.77 | G36: =+F36*E36 -> 5473465.5 | J36: =+'SVD 4140_Pto. 01_Cert. 5'!L36 -> 0 | L36: =+J36+K36 -> 0 | M36: =+G36*J36 -> 0 | N36: =+G36*K36 -> 0 | O36: =+G36*L36 -> 0
B37: 3.12 | C37: Tabiques tanques de H° - H30 (120 kg/m3 de hierro) | D37: m3 | E37: 3 | F37: 536061.6 | G37: =+F37*E37 -> 1608184.8 | J37: =+'SVD 4140_Pto. 01_Cert. 5'!L37 -> 0 | L37: =+J37+K37 -> 0 | M37: =+G37*J37 -> 0 | N37: =+G37*K37 -> 0 | O37: =+G37*L37 -> 0
B38: 3.13 | C38: Junta de impermeabilización de PVC - Sika Waterbars v15 x 15mts o similar | D38: ml | E38: 240 | F38: 31137 | G38: =+F38*E38 -> 7472880 | J38: =+'SVD 4140_Pto. 01_Cert. 5'!L38 -> 0.7 | K38: 0.3 | L38: =+J38+K38 -> 1 | M38: =+G38*J38 -> 5231016 | N38: =+G38*K38 -> 2241864 | O38: =+G38*L38 -> 7472880
B39: 3.14 | C39: Sistema de apuntalamiento y reapuntalamiento | D39: gl | E39: 1 | F39: 11089161 | G39: =+F39*E39 -> 11089161 | J39: =+'SVD 4140_Pto. 01_Cert. 5'!L39 -> 0.15 | K39: 0.05 | L39: =+J39+K39 -> 0.2 | M39: =+G39*J39 -> 1663374.1 | N39: =+G39*K39 -> 554458.05 | O39: =+G39*L39 -> 2217832.2
B40: 3.15 | C40: Ensayos de Hormigon por etapas de hormigonado | D40: u | E40: 14 | F40: 155217 | G40: =+F40*E40 -> 2173038 | J40: =+'SVD 4140_Pto. 01_Cert. 5'!L40 -> 0.35 | K40: 0.05 | L40: =+J40+K40 -> 0.4 | M40: =+G40*J40 -> 760563.3 | N40: =+G40*K40 -> 108651.9 | O40: =+G40*L40 -> 869215.2
B41: 3.16 | C41: Permiso de estacionamiento de bomba de hormigón a contramano | D41: gl | E41: 4 | F41: 69129 | G41: =+F41*E41 -> 276516 | J41: =+'SVD 4140_Pto. 01_Cert. 5'!L41 -> 0.5 | L41: =+J41+K41 -> 0.5 | M41: =+G41*J41 -> 138258 | N41: =+G41*K41 -> 0 | O41: =+G41*L41 -> 138258
B42: 3.17 | C42: Picado de medianeras para columnas y vigas - Cotizado solo para PB y 1P, No contempla picado en SS | D42: m2 | E42: 93 | F42: 24580 | G42: =+F42*E42 -> 2285940 | J42: =+'SVD 4140_Pto. 01_Cert. 5'!L42 -> 0 | K42: 0.1 | L42: =+J42+K42 -> 0.1 | M42: =+G42*J42 -> 0 | N42: =+G42*K42 -> 228594 | O42: =+G42*L42 -> 228594
...

Sheet SVD 4140_Pto. 01_Cert. 7
G2: DÓLAR BNA | H2: DÓLAR MEP
G3: 1005 | H3: 1170
G5: 45628
C6: OBRA: EDIFICIO EL SALVADOR 4140 | J6: Certificado | K6: 7 | O6: 45931
C7: PRESUPUESTO OBRA CIVIL
C8: Descripción | D8: U | E8: Cant | F8: P unit | G8: Subtotal | J8: Avance | M8: Importe
C9: PRESUPUESTO 01 - PRELIMINARES + MOV SUELO + HORMIGON | J9: Anterior | K9: Actual | L9: Acumulado | M9: Anterior | N9: Actual | O9: Acumulado
B10: 1 | C10: TAREAS PRELIMINARES | H10: =SUM(G11:G20) -> 24784163 | I10: =+H10/$H$57 -> 0.058826981
B11: 1.01 | C11: Limpieza y preparación del terreno - No cotiza | D11: gl | E11: 0 | F11: 0 | G11: =+F11*E11 -> 0 | J11: =+'SVD 4140_Pto. 01_Cert. 6'!L11 -> 0 | L11: =+J11+K11 -> 0 | M11: =+G11*J11 -> 0 | N11: =+G11*K11 -> 0 | O11: =+G11*L11 -> 0
B12: 1.02 | C12: Topógrafo - Visita de obra replanteo | D12: un | E12: 3 | F12: 379588 | G12: =+F12*E12 -> 1138764 | J12: =+'SVD 4140_Pto. 01_Cert. 6'!L12 -> 0.65 | L12: =+J12+K12 -> 0.65 | M12: =+G12*J12 -> 740196.6 | N12: =+G12*K12 -> 0 | O12: =+G12*L12 -> 740196.6
B13: 1.03 | C13: Cartel de Obra - No cotiza | D13: gl | E13: 0 | F13: 0 | G13: =+F13*E13 -> 0 | J13: =+'SVD 4140_Pto. 01_Cert. 6'!L13 -> 0 | L13: =+J13+K13 -> 0 | M13: =+G13*J13 -> 0 | N13: =+G13*K13 -> 0 | O13: =+G13*L13 -> 0
B14: 1.04 | C14: Cerco de obra perimetral - En chapa C25 + Concertina + Porton corredizo | D14: ml | E14: 11 | F14: 141220 | G14: =+F14*E14 -> 1553420 | J14: =+'SVD 4140_Pto. 01_Cert. 6'!L14 -> 0 | L14: =+J14+K14 -> 0 | M14: =+G14*J14 -> 0 | N14: =+G14*K14 -> 0 | O14: =+G14*L14 -> 0
B15: 1.05 | C15: Obrador colgante, pañol y ducha | D15: gl | E15: 1 | F15: 7548771 | G15: =+F15*E15 -> 7548771 | J15: =+'SVD 4140_Pto. 01_Cert. 6'!L15 -> 0.8 | L15: =+J15+K15 -> 0.8 | M15: =+G15*J15 -> 6039016.8 | N15: =+G15*K15 -> 0 | O15: =+G15*L15 -> 6039016.8
B16: 1.06 | C16: Alquiler de baños quimicos y duchas portatiles | D16: mes | E16: 3 | F16: 392028 | G16: =+F16*E16 -> 1176084 | J16: =+'SVD 4140_Pto. 01_Cert. 6'!L16 -> 1 | L16: =+J16+K16 -> 1 | M16: =+G16*J16 -> 1176084 | N16: =+G16*K16 -> 0 | O16: =+G16*L16 -> 1176084
B17: 1.07 | C17: Conexión pilar y luz de obra + Tablero de obra | D17: gl | E17: 1 | F17: 1731320 | G17: =+F17*E17 -> 1731320 | J17: =+'SVD 4140_Pto. 01_Cert. 6'!L17 -> 1 | L17: =+J17+K17 -> 1 | M17: =+G17*J17 -> 1731320 | N17: =+G17*K17 -> 0 | O17: =+G17*L17 -> 1731320
B18: 1.08 | C18: Conexión agua de obra, tanque + bomba | D18: gl | E18: 1 | F18: 1405632 | G18: =+F18*E18 -> 1405632 | J18: =+'SVD 4140_Pto. 01_Cert. 6'!L18 -> 0 | L18: =+J18+K18 -> 0 | M18: =+G18*J18 -> 0 | N18: =+G18*K18 -> 0 | O18: =+G18*L18 -> 0
B19: 1.09 | C19: Tramite luz de obra, certificado luz de obra (2) y medición PAT | D19: gl | E19: 1 | F19: 426487 | G19: =+F19*E19 -> 426487 | J19: =+'SVD 4140_Pto. 01_Cert. 6'!L19 -> 0.65 | L19: =+J19+K19 -> 0.65 | M19: =+G19*J19 -> 277216.55 | N19: =+G19*K19 -> 0 | O19: =+G19*L19 -> 277216.55
B20: 1.1 | C20: Sistema de depresión de napas | D20: gl | E20: 1 | F20: 9803685 | G20: =+F20*E20 -> 9803685 | J20: =+'SVD 4140_Pto. 01_Cert. 6'!L20 -> 1 | L20: =+J20+K20 -> 1 | M20: =+G20*J20 -> 9803685 | N20: =+G20*K20 -> 0 | O20: =+G20*L20 -> 9803685
B21: 2 | C21: MOVIMIENTO DE TIERRA, COMPACTACION Y RELLENO | H21: =SUM(G22:G24) -> 42017464 | I21: =+H21/$H$57 -> 0.099731451
B22: 2.01 | C22: Excavación a maquina para submuración y subsuelo | D22: m3 | E22: 1266 | F22: 33090 | G22: =+F22*E22 -> 41891940 | J22: =+'SVD 4140_Pto. 01_Cert. 6'!L22 -> 1 | L22: =+J22+K22 -> 1 | M22: =+G22*J22 -> 41891940 | N22: =+G22*K22 -> 0 | O22: =+G22*L22 -> 41891940
B23: 2.02 | C23: Demolición y retiro de fundaciones existentes - No cotiza | D23: gl | E23: 0 | F23: 0 | G23: =+F23*E23 -> 0 | J23: =+'SVD 4140_Pto. 01_Cert. 6'!L23 -> 0 | L23: =+J23+K23 -> 0 | M23: =+G23*J23 -> 0 | N23: =+G23*K23 -> 0 | O23: =+G23*L23 -> 0
B24: 2.03 | C24: Excavación manual para pozo de achique y bombeo | D24: m3 | E24: 2 | F24: 62762 | G24: =+F24*E24 -> 125524 | J24: =+'SVD 4140_Pto. 01_Cert. 6'!L24 -> 1 | L24: =+J24+K24 -> 1 | M24: =+G24*J24 -> 125524 | N24: =+G24*K24 -> 0 | O24: =+G24*L24 -> 125524
B25: 3 | C25: ESTRUCTURA RESISTENTE - sin provision de hierro y hormigon (incluye corte y doblado en obra) | H25: =SUM(G26:G42) -> 277149875 | I25: =+H25/$H$57 -> 0.65783502
B26: 3.01 | C26: Hormigón de limpieza - e: 10 cm | D26: m3 | E26: 35 | F26: 314478 | G26: =+F26*E26 -> 11006730 | J26: =+'SVD 4140_Pto. 01_Cert. 6'!L26 -> 1 | L26: =+J26+K26 -> 1 | M26: =+G26*J26 -> 11006730 | N26: =+G26*K26 -> 0 | O26: =+G26*L26 -> 11006730
B27: 3.02 | C27: Tabique submuración - H30 hidrófugo (95 kg/m3 de hierro) | D27: m3 | E27: 40 | F27: 536061.6 | G27: =+F27*E27 -> 21442464 | J27: =+'SVD 4140_Pto. 01_Cert. 6'!L27 -> 1 | L27: =+J27+K27 -> 1 | M27: =+G27*J27 -> 21442464 | N27: =+G27*K27 -> 0 | O27: =+G27*L27 -> 21442464
B28: 3.03 | C28: Zapata corrida tabique - H30 hidrófugo (120 kg/m3) | D28: m3 | E28: 28 | F28: 437680.76 | G28: =+F28*E28 -> 12255061 | J28: =+'SVD 4140_Pto. 01_Cert. 6'!L28 -> 1 | L28: =+J28+K28 -> 1 | M28: =+G28*J28 -> 12255061 | N28: =+G28*K28 -> 0 | O28: =+G28*L28 -> 12255061
B29: 3.04 | C29: Platea - H30 hidrófugo (95 kg/m3 de hierro) | D29: m3 | E29: 179 | F29: 214461.72 | G29: =+F29*E29 -> 38388648 | J29: =+'SVD 4140_Pto. 01_Cert. 6'!L29 -> 1 | L29: =+J29+K29 -> 1 | M29: =+G29*J29 -> 38388648 | N29: =+G29*K29 -> 0 | O29: =+G29*L29 -> 38388648
B30: 3.05 | C30: Rampa - H30 (120 kg/m3 de hierro) | D30: m3 | E30: 10 | F30: 462731.65 | G30: =+F30*E30 -> 4627316.5 | J30: =+'SVD 4140_Pto. 01_Cert. 6'!L30 -> 0.05 | K30: 0.95 | L30: =+J30+K30 -> 1 | M30: =+G30*J30 -> 231365.83 | N30: =+G30*K30 -> 4395950.7 | O30: =+G30*L30 -> 4627316.5
