Workbook
Name \0: #REF!
Name \c: #REF!
Name \E: #REF!
Name \i: #REF!
Name \j: #REF!
Name \m: #REF!
Name \P: #REF!
Name \P: #REF!
Name \P: #REF!
Name \P: #REF!
Name \P: #REF!
Name \P: #REF!
Name \P: #REF!
Name \P: #REF!
Name \P: #REF!
Name \r: #N/A
Name \x: #REF!
Name \z: #REF!
Name __________ben1: #REF!
Name __________ben1: #REF!
Name __________ben1: #REF!
Name __________ben1: #REF!
Name __________ben1: #REF!
Name __________ben1: #REF!
Name __________ben1: #REF!
Name __________ben1: #REF!
Name __________ben1: #REF!
Name __________ben10: #REF!
Name __________ben10: #REF!
Name __________ben10: #REF!
Name __________ben10: #REF!
Name __________ben10: #REF!
Name __________ben10: #REF!
Name __________ben10: #REF!
Name __________ben10: #REF!
Name __________ben10: #REF!
Name __________ben15: #REF!
Name __________ben15: #REF!
Name __________ben15: #REF!
Name __________ben15: #REF!
Name __________ben15: #REF!
Name __________ben15: #REF!
Name __________ben15: #REF!
Name __________ben15: #REF!
Name __________ben15: #REF!
Name __________BEN2: #REF!
Name __________ben20: #REF!
Name __________ben20: #REF!
Name __________ben20: #REF!
Name __________ben20: #REF!
Name __________ben20: #REF!
Name __________ben20: #REF!
Name __________ben20: #REF!
Name __________ben20: #REF!
Name __________ben20: #REF!
Name __________ben25: #REF!
Name __________ben25: #REF!
Name __________ben25: #REF!
Name __________ben25: #REF!
Name __________ben25: #REF!

Sheet SVD 4140_Pto. 01_Cert. 01
F1: DÓLAR BNA | G1: DÓLAR MEP
F2: 1005 | G2: 1170
F4: 45628
B5: OBRA: EDIFICIO EL SALVADOR 4140 | I5: Certificado | J5: 1 | N5: 45958
B6: PRESUPUESTO OBRA CIVIL
B7: Descripción | C7: U | D7: Cant | E7: P unit | F7: Subtotal | I7: Avance | L7: Importe
B8: PRESUPUESTO 02 - ALBANILERIA + INSTALACIONES + TERMINACIONES | I8: Anterior | J8: Actual | K8: Acumulado | L8: Anterior | M8: Actual | N8: Acumulado
A9: 4 | B9: ALBAÑILERIA | G9: =+SUM(F10:F17) -> 54302890 | H9: =+G9/$G$185 -> 0.073815487
A10: 4.01 | B10: Muro tipo 1 (interiores, divisorio de locales) e: 10 cm - Ladrillo hueco 08 x 18 x 33 | C10: m2 | D10: 819 | E10: 18993 | F10: =+D10*E10 -> 15555267 | K10: =+I10+J10 -> 0 | L10: =+F10*I10 -> 0 | M10: =+F10*J10 -> 0 | N10: =+F10*K10 -> 0
A11: 4.02 | B11: Muro tipo 2 y 3 (medianera, caja de escaleras y ascensor) e: 15 cm - Ladrillo hueco portante 12 x 19 x 33 | C11: m2 | D11: 612 | E11: 25172 | F11: =+D11*E11 -> 15405264 | K11: =+I11+J11 -> 0 | L11: =+F11*I11 -> 0 | M11: =+F11*J11 -> 0 | N11: =+F11*K11 -> 0
A12: 4.03 | B12: Muro tipo 4 (divisorio de unidades y fachas) e: 15 cm - Ladrillo hueco 12 x 18 x 33 | C12: m2 | D12: 636 | E12: 21109 | F12: =+D12*E12 -> 13425324 | K12: =+I12+J12 -> 0 | L12: =+F12*I12 -> 0 | M12: =+F12*J12 -> 0 | N12: =+F12*K12 -> 0
A13: 4.04 | B13: Enchape medianeras existentes - Contemplamos picado zonas sueltas y enchape con ladrillo comun para PB | C13: m2 | D13: 195 | E13: 15092 | F13: =+D13*E13 -> 2942940 | K13: =+I13+J13 -> 0 | L13: =+F13*I13 -> 0 | M13: =+F13*J13 -> 0 | N13: =+F13*K13 -> 0
A14: 4.05 | B14: Mamposteria cribada de ladrillo visto en balcones | C14: m2 | D14: 30.054 | E14: 67420 | F14: =+D14*E14 -> 2026240.7 | K14: =+I14+J14 -> 0 | L14: =+F14*I14 -> 0 | M14: =+F14*J14 -> 0 | N14: =+F14*K14 -> 0
A15: 4.06 | B15: Bloque de H° con masillado de hormigon | C15: m2 | D15: 24 | E15: 54908 | F15: =+D15*E15 -> 1317792 | K15: =+I15+J15 -> 0 | L15: =+F15*I15 -> 0 | M15: =+F15*J15 -> 0 | N15: =+F15*K15 -> 0
A16: 4.07 | B16: Cordón de hormigón en umbrales carpinterías | C16: ml | D16: 81 | E16: 30989 | F16: =+D16*E16 -> 2510109 | K16: =+I16+J16 -> 0 | L16: =+F16*I16 -> 0 | M16: =+F16*J16 -> 0 | N16: =+F16*K16 -> 0
A17: 4.08 | B17: Pozo de bombeo pluvial y cloacal | C17: gl | D17: 1 | E17: 1119953 | F17: =+D17*E17 -> 1119953 | K17: =+I17+J17 -> 0 | L17: =+F17*I17 -> 0 | M17: =+F17*J17 -> 0 | N17: =+F17*K17 -> 0
A18: 5 | B18: AISLACIONES | G18: =+SUM(F19:F25) -> 35966419 | H18: =+G18/$G$185 -> 0.048890193
A19: 5.01 | B19: Aislación hidrófuga horizontal (baños) - Inc. membrana geotextil y 35% en concepto de babetas | C19: m2 | D19: 139.05 | E19: 21800 | F19: =+D19*E19 -> 3031290 | K19: =+I19+J19 -> 0 | L19: =+F19*I19 -> 0 | M19: =+F19*J19 -> 0 | N19: =+F19*K19 -> 0
A20: 5.02 | B20: Azotado hidrofugo - Sobre medianeras existentes | C20: m2 | D20: 300 | E20: 5376 | F20: =+D20*E20 -> 1612800 | K20: =+I20+J20 -> 0 | L20: =+F20*I20 -> 0 | M20: =+F20*J20 -> 0 | N20: =+F20*K20 -> 0
A21: 5.03 | B21: Azotado hidrofugo - Contrapiso de vereda | C21: m2 | D21: 48 | E21: 5376 | F21: =+D21*E21 -> 258048 | K21: =+I21+J21 -> 0 | L21: =+F21*I21 -> 0 | M21: =+F21*J21 -> 0 | N21: =+F21*K21 -> 0
A22: 5.04 | B22: Aislación térmica en terrazas, eps e:2,00 cm | C22: m2 | D22: 262 | E22: 4403 | F22: =+D22*E22 -> 1153586 | K22: =+I22+J22 -> 0 | L22: =+F22*I22 -> 0 | M22: =+F22*J22 -> 0 | N22: =+F22*K22 -> 0
A23: 5.05 | B23: Barrera de vapor | C23: m2 | D23: 510 | E23: 3578 | F23: =+D23*E23 -> 1824780 | K23: =+I23+J23 -> 0 | L23: =+F23*I23 -> 0 | M23: =+F23*J23 -> 0 | N23: =+F23*K23 -> 0
A24: 5.06 | B24: Membrana asfaltica geotextil 4mm - Balcones y azotea - Inc. 20% en concepto de babetas | C24: m2 | D24: 510 | E24: 21800 | F24: =+D24*E24 -> 11118000 | K24: =+I24+J24 -> 0 | L24: =+F24*I24 -> 0 | M24: =+F24*J24 -> 0 | N24: =+F24*K24 -> 0
A25: 5.07 | B25: Impermeabilización de subsuelo | C25: gl | D25: 1 | E25: 16967915 | F25: =+D25*E25 -> 16967915 | J25: 1 | K25: =+I25+J25 -> 1 | L25: =+F25*I25 -> 0 | M25: =+F25*J25 -> 16967915 | N25: =+F25*K25 -> 16967915
A26: 6 | B26: CUBIERTAS | G26: =+SUM(F27) -> 2433900 | H26: =+G26/$G$185 -> 0.0033084706
A27: 6.02 | B27: Babeta de chapa galvanizada en medianeras | C27: ml | D27: 60 | E27: 40565 | F27: =+D27*E27 -> 2433900 | K27: =+I27+J27 -> 0 | L27: =+F27*I27 -> 0 | M27: =+F27*J27 -> 0 | N27: =+F27*K27 -> 0
A28: 7 | B28: REVOQUES | G28: =+SUM(F29:F36) -> 1.3639056e+08 | H28: =+G28/$G$185 -> 0.18539962
A29: 7.01 | B29: Revoque Grueso Impermeable Exterior proyectable | C29: m2 | D29: 678.252 | E29: 16571 | F29: =+D29*E29 -> 11239314 | K29: =+I29+J29 -> 0 | L29: =+F29*I29 -> 0 | M29: =+F29*J29 -> 0 | N29: =+F29*K29 -> 0
A30: 7.02 | B30: Revoque Grueso Impermeable Exterior a mas de 3m proyectable - Medianero y fachadas | C30: m2 | D30: 876.0812 | E30: 22183 | F30: =+D30*E30 -> 19434109 | K30: =+I30+J30 -> 0 | L30: =+F30*I30 -> 0 | M30: =+F30*J30 -> 0 | N30: =+F30*K30 -> 0
A31: 7.03 | B31: Buña en revoque | C31: ml | D31: 182 | E31: 10806 | F31: =+D31*E31 -> 1966692 | K31: =+I31+J31 -> 0 | L31: =+F31*I31 -> 0 | M31: =+F31*J31 -> 0 | N31: =+F31*K31 -> 0
A32: 7.04 | B32: Revoque Grueso Interior + fino | C32: m2 | D32: 995.8511 | E32: 26530 | F32: =+D32*E32 -> 26419930 | K32: =+I32+J32 -> 0 | L32: =+F32*I32 -> 0 | M32: =+F32*J32 -> 0 | N32: =+F32*K32 -> 0
A33: 7.05 | B33: Yeso interior | C33: m2 | D33: 2514.897 | E33: 22566 | F33: =+D33*E33 -> 56751166 | K33: =+I33+J33 -> 0 | L33: =+F33*I33 -> 0 | M33: =+F33*J33 -> 0 | N33: =+F33*K33 -> 0
A34: 7.06 | B34: Arista en yeso | C34: ml | D34: 509.9 | E34: 12771 | F34: =+D34*E34 -> 6511932.9 | K34: =+I34+J34 -> 0 | L34: =+F34*I34 -> 0 | M34: =+F34*J34 -> 0 | N34: =+F34*K34 -> 0
A35: 7.07 | B35: Provisión y colocación de guardacanto yesero | C35: u | D35: 198 | E35: 14947 | F35: =+D35*E35 -> 2959506 | K35: =+I35+J35 -> 0 | L35: =+F35*I35 -> 0 | M35: =+F35*J35 -> 0 | N35: =+F35*K35 -> 0
A36: 7.08 | B36: Revoque Grueso Impermeable Interior b/ revestimiento | C36: m2 | D36: 670.322 | E36: 16571 | F36: =+D36*E36 -> 11107906 | K36: =+I36+J36 -> 0 | L36: =+F36*I36 -> 0 | M36: =+F36*J36 -> 0 | N36: =+F36*K36 -> 0
A37: 8 | B37: CONTRAPISOS Y CARPETAS | G37: =+SUM(F38:F45) -> 44788107 | H37: =+G37/$G$185 -> 0.060881768
A38: 8.01 | B38: Contrapiso de cascotes en SS e: 15 cm | C38: m2 | D38: 104 | E38: 31920 | F38: =+D38*E38 -> 3319680 | J38: 0.5 | K38: =+I38+J38 -> 0.5 | L38: =+F38*I38 -> 0 | M38: =+F38*J38 -> 1659840 | N38: =+F38*K38 -> 1659840
A39: 8.02 | B39: Contrapiso de cascote s/terreno natural e: 20 cm - Incluye film de polietileno | C39: m2 | D39: 48 | E39: 37268 | F39: =+D39*E39 -> 1788864 | K39: =+I39+J39 -> 0 | L39: =+F39*I39 -> 0 | M39: =+F39*J39 -> 0 | N39: =+F39*K39 -> 0
A40: 8.03 | B40: Contrapiso de cascotes en azoteas c/pendiente e: 15 cm | C40: m2 | D40: 235 | E40: 32410 | F40: =+D40*E40 -> 7616350 | K40: =+I40+J40 -> 0 | L40: =+F40*I40 -> 0 | M40: =+F40*J40 -> 0 | N40: =+F40*K40 -> 0
A41: 8.04 | B41: Contrapiso - Carpeta monolitico e: 7 cm | C41: m2 | D41: 878 | E41: 19006 | F41: =+D41*E41 -> 16687268 | K41: =+I41+J41 -> 0 | L41: =+F41*I41 -> 0 | M41: =+F41*J41 -> 0 | N41: =+F41*K41 -> 0
...

Sheet SVD 4140_Pto. 01_Cert. 02
F1: DÓLAR BNA | G1: DÓLAR MEP
F2: 1005 | G2: 1170
F4: 45628
B5: OBRA: EDIFICIO EL SALVADOR 4140 | I5: Certificado | J5: 2 | N5: 45988
B6: PRESUPUESTO OBRA CIVIL
B7: Descripción | C7: U | D7: Cant | E7: P unit | F7: Subtotal | I7: Avance | L7: Importe
B8: PRESUPUESTO 02 - ALBANILERIA + INSTALACIONES + TERMINACIONES | I8: Anterior | J8: Actual | K8: Acumulado | L8: Anterior | M8: Actual | N8: Acumulado
A9: 4 | B9: ALBAÑILERIA | G9: =+SUM(F10:F17) -> 54302890 | H9: =+G9/$G$185 -> 0.073815487
A10: 4.01 | B10: Muro tipo 1 (interiores, divisorio de locales) e: 10 cm - Ladrillo hueco 08 x 18 x 33 | C10: m2 | D10: 819 | E10: 18993 | F10: =+D10*E10 -> 15555267 | I10: =+'SVD 4140_Pto. 01_Cert. 01'!K10 -> 0 | J10: 0.15 | K10: =+I10+J10 -> 0.15 | L10: =+F10*I10 -> 0 | M10: =+F10*J10 -> 2333290 | N10: =+F10*K10 -> 2333290
A11: 4.02 | B11: Muro tipo 2 y 3 (medianera, caja de escaleras y ascensor) e: 15 cm - Ladrillo hueco portante 12 x 19 x 33 | C11: m2 | D11: 612 | E11: 25172 | F11: =+D11*E11 -> 15405264 | I11: =+'SVD 4140_Pto. 01_Cert. 01'!K11 -> 0 | J11: 0.05 | K11: =+I11+J11 -> 0.05 | L11: =+F11*I11 -> 0 | M11: =+F11*J11 -> 770263.2 | N11: =+F11*K11 -> 770263.2
A12: 4.03 | B12: Muro tipo 4 (divisorio de unidades y fachas) e: 15 cm - Ladrillo hueco 12 x 18 x 33 | C12: m2 | D12: 636 | E12: 21109 | F12: =+D12*E12 -> 13425324 | I12: =+'SVD 4140_Pto. 01_Cert. 01'!K12 -> 0 | J12: 0.1 | K12: =+I12+J12 -> 0.1 | L12: =+F12*I12 -> 0 | M12: =+F12*J12 -> 1342532.4 | N12: =+F12*K12 -> 1342532.4
A13: 4.04 | B13: Enchape medianeras existentes - Contemplamos picado zonas sueltas y enchape con ladrillo comun para PB | C13: m2 | D13: 195 | E13: 15092 | F13: =+D13*E13 -> 2942940 | I13: =+'SVD 4140_Pto. 01_Cert. 01'!K13 -> 0 | K13: =+I13+J13 -> 0 | L13: =+F13*I13 -> 0 | M13: =+F13*J13 -> 0 | N13: =+F13*K13 -> 0
A14: 4.05 | B14: Mamposteria cribada de ladrillo visto en balcones | C14: m2 | D14: 30.054 | E14: 67420 | F14: =+D14*E14 -> 2026240.7 | I14: =+'SVD 4140_Pto. 01_Cert. 01'!K14 -> 0 | K14: =+I14+J14 -> 0 | L14: =+F14*I14 -> 0 | M14: =+F14*J14 -> 0 | N14: =+F14*K14 -> 0
A15: 4.06 | B15: Bloque de H° con masillado de hormigon | C15: m2 | D15: 24 | E15: 54908 | F15: =+D15*E15 -> 1317792 | I15: =+'SVD 4140_Pto. 01_Cert. 01'!K15 -> 0 | K15: =+I15+J15 -> 0 | L15: =+F15*I15 -> 0 | M15: =+F15*J15 -> 0 | N15: =+F15*K15 -> 0
A16: 4.07 | B16: Cordón de hormigón en umbrales carpinterías | C16: ml | D16: 81 | E16: 30989 | F16: =+D16*E16 -> 2510109 | I16: =+'SVD 4140_Pto. 01_Cert. 01'!K16 -> 0 | K16: =+I16+J16 -> 0 | L16: =+F16*I16 -> 0 | M16: =+F16*J16 -> 0 | N16: =+F16*K16 -> 0
A17: 4.08 | B17: Pozo de bombeo pluvial y cloacal | C17: gl | D17: 1 | E17: 1119953 | F17: =+D17*E17 -> 1119953 | I17: =+'SVD 4140_Pto. 01_Cert. 01'!K17 -> 0 | J17: 0.5 | K17: =+I17+J17 -> 0.5 | L17: =+F17*I17 -> 0 | M17: =+F17*J17 -> 559976.5 | N17: =+F17*K17 -> 559976.5
A18: 5 | B18: AISLACIONES | G18: =+SUM(F19:F25) -> 35966419 | H18: =+G18/$G$185 -> 0.048890193
A19: 5.01 | B19: Aislación hidrófuga horizontal (baños) - Inc. membrana geotextil y 35% en concepto de babetas | C19: m2 | D19: 139.05 | E19: 21800 | F19: =+D19*E19 -> 3031290 | I19: =+'SVD 4140_Pto. 01_Cert. 01'!K19 -> 0 | K19: =+I19+J19 -> 0 | L19: =+F19*I19 -> 0 | M19: =+F19*J19 -> 0 | N19: =+F19*K19 -> 0
A20: 5.02 | B20: Azotado hidrofugo - Sobre medianeras existentes | C20: m2 | D20: 300 | E20: 5376 | F20: =+D20*E20 -> 1612800 | I20: =+'SVD 4140_Pto. 01_Cert. 01'!K20 -> 0 | K20: =+I20+J20 -> 0 | L20: =+F20*I20 -> 0 | M20: =+F20*J20 -> 0 | N20: =+F20*K20 -> 0
A21: 5.03 | B21: Azotado hidrofugo - Contrapiso de vereda | C21: m2 | D21: 48 | E21: 5376 | F21: =+D21*E21 -> 258048 | I21: =+'SVD 4140_Pto. 01_Cert. 01'!K21 -> 0 | K21: =+I21+J21 -> 0 | L21: =+F21*I21 -> 0 | M21: =+F21*J21 -> 0 | N21: =+F21*K21 -> 0
A22: 5.04 | B22: Aislación térmica en terrazas, eps e:2,00 cm | C22: m2 | D22: 262 | E22: 4403 | F22: =+D22*E22 -> 1153586 | I22: =+'SVD 4140_Pto. 01_Cert. 01'!K22 -> 0 | K22: =+I22+J22 -> 0 | L22: =+F22*I22 -> 0 | M22: =+F22*J22 -> 0 | N22: =+F22*K22 -> 0
A23: 5.05 | B23: Barrera de vapor | C23: m2 | D23: 510 | E23: 3578 | F23: =+D23*E23 -> 1824780 | I23: =+'SVD 4140_Pto. 01_Cert. 01'!K23 -> 0 | K23: =+I23+J23 -> 0 | L23: =+F23*I23 -> 0 | M23: =+F23*J23 -> 0 | N23: =+F23*K23 -> 0
A24: 5.06 | B24: Membrana asfaltica geotextil 4mm - Balcones y azotea - Inc. 20% en concepto de babetas | C24: m2 | D24: 510 | E24: 21800 | F24: =+D24*E24 -> 11118000 | I24: =+'SVD 4140_Pto. 01_Cert. 01'!K24 -> 0 | K24: =+I24+J24 -> 0 | L24: =+F24*I24 -> 0 | M24: =+F24*J24 -> 0 | N24: =+F24*K24 -> 0
A25: 5.07 | B25: Impermeabilización de subsuelo | C25: gl | D25: 1 | E25: 16967915 | F25: =+D25*E25 -> 16967915 | I25: =+'SVD 4140_Pto. 01_Cert. 01'!K25 -> 1 | K25: =+I25+J25 -> 1 | L25: =+F25*I25 -> 16967915 | M25: =+F25*J25 -> 0 | N25: =+F25*K25 -> 16967915
A26: 6 | B26: CUBIERTAS | G26: =+SUM(F27) -> 2433900 | H26: =+G26/$G$185 -> 0.0033084706
A27: 6.02 | B27: Babeta de chapa galvanizada en medianeras | C27: ml | D27: 60 | E27: 40565 | F27: =+D27*E27 -> 2433900 | I27: =+'SVD 4140_Pto. 01_Cert. 01'!K27 -> 0 | K27: =+I27+J27 -> 0 | L27: =+F27*I27 -> 0 | M27: =+F27*J27 -> 0 | N27: =+F27*K27 -> 0
A28: 7 | B28: REVOQUES | G28: =+SUM(F29:F36) -> 1.3639056e+08 | H28: =+G28/$G$185 -> 0.18539962 | I28: =+'SVD 4140_Pto. 01_Cert. 01'!K28 -> 0
A29: 7.01 | B29: Revoque Grueso Impermeable Exterior proyectable | C29: m2 | D29: 678.252 | E29: 16571 | F29: =+D29*E29 -> 11239314 | I29: =+'SVD 4140_Pto. 01_Cert. 01'!K29 -> 0 | K29: =+I29+J29 -> 0 | L29: =+F29*I29 -> 0 | M29: =+F29*J29 -> 0 | N29: =+F29*K29 -> 0
A30: 7.02 | B30: Revoque Grueso Impermeable Exterior a mas de 3m proyectable - Medianero y fachadas | C30: m2 | D30: 876.0812 | E30: 22183 | F30: =+D30*E30 -> 19434109 | I30: =+'SVD 4140_Pto. 01_Cert. 01'!K30 -> 0 | K30: =+I30+J30 -> 0 | L30: =+F30*I30 -> 0 | M30: =+F30*J30 -> 0 | N30: =+F30*K30 -> 0
A31: 7.03 | B31: Buña en revoque | C31: ml | D31: 182 | E31: 10806 | F31: =+D31*E31 -> 1966692 | I31: =+'SVD 4140_Pto. 01_Cert. 01'!K31 -> 0 | K31: =+I31+J31 -> 0 | L31: =+F31*I31 -> 0 | M31: =+F31*J31 -> 0 | N31: =+F31*K31 -> 0
A32: 7.04 | B32: Revoque Grueso Interior + fino | C32: m2 | D32: 995.8511 | E32: 26530 | F32: =+D32*E32 -> 26419930 | I32: =+'SVD 4140_Pto. 01_Cert. 01'!K32 -> 0 | K32: =+I32+J32 -> 0 | L32: =+F32*I32 -> 0 | M32: =+F32*J32 -> 0 | N32: =+F32*K32 -> 0
A33: 7.05 | B33: Yeso interior | C33: m2 | D33: 2514.897 | E33: 22566 | F33: =+D33*E33 -> 56751166 | I33: =+'SVD 4140_Pto. 01_Cert. 01'!K33 -> 0 | K33: =+I33+J33 -> 0 | L33: =+F33*I33 -> 0 | M33: =+F33*J33 -> 0 | N33: =+F33*K33 -> 0
A34: 7.06 | B34: Arista en yeso | C34: ml | D34: 509.9 | E34: 12771 | F34: =+D34*E34 -> 6511932.9 | I34: =+'SVD 4140_Pto. 01_Cert. 01'!K34 -> 0 | K34: =+I34+J34 -> 0 | L34: =+F34*I34 -> 0 | M34: =+F34*J34 -> 0 | N34: =+F34*K34 -> 0
A35: 7.07 | B35: Provisión y colocación de guardacanto yesero | C35: u | D35: 198 | E35: 14947 | F35: =+D35*E35 -> 2959506 | I35: =+'SVD 4140_Pto. 01_Cert. 01'!K35 -> 0 | K35: =+I35+J35 -> 0 | L35: =+F35*I35 -> 0 | M35: =+F35*J35 -> 0 | N35: =+F35*K35 -> 0
A36: 7.08 | B36: Revoque Grueso Impermeable Interior b/ revestimiento | C36: m2 | D36: 670.322 | E36: 16571 | F36: =+D36*E36 -> 11107906 | I36: =+'SVD 4140_Pto. 01_Cert. 01'!K36 -> 0 | K36: =+I36+J36 -> 0 | L36: =+F36*I36 -> 0 | M36: =+F36*J36 -> 0 | N36: =+F36*K36 -> 0
A37: 8 | B37: CONTRAPISOS Y CARPETAS | G37: =+SUM(F38:F45) -> 44788107 | H37: =+G37/$G$185 -> 0.060881768
A38: 8.01 | B38: Contrapiso de cascotes en SS e: 15 cm | C38: m2 | D38: 104 | E38: 31920 | F38: =+D38*E38 -> 3319680 | I38: =+'SVD 4140_Pto. 01_Cert. 01'!K38 -> 0.5 | J38: 0.5 | K38: =+I38+J38 -> 1 | L38: =+F38*I38 -> 1659840 | M38: =+F38*J38 -> 1659840 | N38: =+F38*K38 -> 3319680
A39: 8.02 | B39: Contrapiso de cascote s/terreno natural e: 20 cm - Incluye film de polietileno | C39: m2 | D39: 48 | E39: 37268 | F39: =+D39*E39 -> 1788864 | I39: =+'SVD 4140_Pto. 01_Cert. 01'!K39 -> 0 | K39: =+I39+J39 -> 0 | L39: =+F39*I39 -> 0 | M39: =+F39*J39 -> 0 | N39: =+F39*K39 -> 0
A40: 8.03 | B40: Contrapiso de cascotes en azoteas c/pendiente e: 15 cm | C40: m2 | D40: 235 | E40: 32410 | F40: =+D40*E40 -> 7616350 | I40: =+'SVD 4140_Pto. 01_Cert. 01'!K40 -> 0 | K40: =+I40+J40 -> 0 | L40: =+F40*I40 -> 0 | M40: =+F40*J40 -> 0 | N40: =+F40*K40 -> 0
A41: 8.04 | B41: Contrapiso - Carpeta monolitico e: 7 cm | C41: m2 | D41: 878 | E41: 19006 | F41: =+D41*E41 -> 16687268 | I41: =+'SVD 4140_Pto. 01_Cert. 01'!K41 -> 0 | K41: =+I41+J41 -> 0 | L41: =+F41*I41 -> 0 | M41: =+F41*J41 -> 0 | N41: =+F41*K41 -> 0
...

Sheet SVD 4140_Pto. 01_Cert. 03
F1: DÓLAR BNA | G1: DÓLAR MEP
F2: 1005 | G2: 1170
F4: 45628
B5: OBRA: EDIFICIO EL SALVADOR 4140 | I5: Certificado | J5: 3 | N5: 46020
B6: PRESUPUESTO OBRA CIVIL
B7: Descripción | C7: U | D7: Cant | E7: P unit | F7: Subtotal | I7: Avance | L7: Importe
B8: PRESUPUESTO 02 - ALBANILERIA + INSTALACIONES + TERMINACIONES | I8: Anterior | J8: Actual | K8: Acumulado | L8: Anterior | M8: Actual | N8: Acumulado
A9: 4 | B9: ALBAÑILERIA | G9: =+SUM(F10:F17) -> 54302890 | H9: =+G9/$G$185 -> 0.073815487
A10: 4.01 | B10: Muro tipo 1 (interiores, divisorio de locales) e: 10 cm - Ladrillo hueco 08 x 18 x 33 | C10: m2 | D10: 819 | E10: 18993 | F10: =+D10*E10 -> 15555267 | I10: =+'SVD 4140_Pto. 01_Cert. 02'!K10 -> 0.15 | J10: 0.2 | K10: =+I10+J10 -> 0.35 | L10: =+F10*I10 -> 2333290 | M10: =+F10*J10 -> 3111053.4 | N10: =+F10*K10 -> 5444343.4
A11: 4.02 | B11: Muro tipo 2 y 3 (medianera, caja de escaleras y ascensor) e: 15 cm - Ladrillo hueco portante 12 x 19 x 33 | C11: m2 | D11: 612 | E11: 25172 | F11: =+D11*E11 -> 15405264 | I11: =+'SVD 4140_Pto. 01_Cert. 02'!K11 -> 0.05 | J11: 0.2 | K11: =+I11+J11 -> 0.25 | L11: =+F11*I11 -> 770263.2 | M11: =+F11*J11 -> 3081052.8 | N11: =+F11*K11 -> 3851316
A12: 4.03 | B12: Muro tipo 4 (divisorio de unidades y fachas) e: 15 cm - Ladrillo hueco 12 x 18 x 33 | C12: m2 | D12: 636 | E12: 21109 | F12: =+D12*E12 -> 13425324 | I12: =+'SVD 4140_Pto. 01_Cert. 02'!K12 -> 0.1 | J12: 0.25 | K12: =+I12+J12 -> 0.35 | L12: =+F12*I12 -> 1342532.4 | M12: =+F12*J12 -> 3356331 | N12: =+F12*K12 -> 4698863.4
A13: 4.04 | B13: Enchape medianeras existentes - Contemplamos picado zonas sueltas y enchape con ladrillo comun para PB | C13: m2 | D13: 195 | E13: 15092 | F13: =+D13*E13 -> 2942940 | I13: =+'SVD 4140_Pto. 01_Cert. 02'!K13 -> 0 | J13: 0.15 | K13: =+I13+J13 -> 0.15 | L13: =+F13*I13 -> 0 | M13: =+F13*J13 -> 441441 | N13: =+F13*K13 -> 441441
A14: 4.05 | B14: Mamposteria cribada de ladrillo visto en balcones | C14: m2 | D14: 30.054 | E14: 67420 | F14: =+D14*E14 -> 2026240.7 | I14: =+'SVD 4140_Pto. 01_Cert. 02'!K14 -> 0 | K14: =+I14+J14 -> 0 | L14: =+F14*I14 -> 0 | M14: =+F14*J14 -> 0 | N14: =+F14*K14 -> 0
A15: 4.06 | B15: Bloque de H° con masillado de hormigon | C15: m2 | D15: 24 | E15: 54908 | F15: =+D15*E15 -> 1317792 | I15: =+'SVD 4140_Pto. 01_Cert. 02'!K15 -> 0 | K15: =+I15+J15 -> 0 | L15: =+F15*I15 -> 0 | M15: =+F15*J15 -> 0 | N15: =+F15*K15 -> 0
A16: 4.07 | B16: Cordón de hormigón en umbrales carpinterías | C16: ml | D16: 81 | E16: 30989 | F16: =+D16*E16 -> 2510109 | I16: =+'SVD 4140_Pto. 01_Cert. 02'!K16 -> 0 | K16: =+I16+J16 -> 0 | L16: =+F16*I16 -> 0 | M16: =+F16*J16 -> 0 | N16: =+F16*K16 -> 0
A17: 4.08 | B17: Pozo de bombeo pluvial y cloacal | C17: gl | D17: 1 | E17: 1119953 | F17: =+D17*E17 -> 1119953 | I17: =+'SVD 4140_Pto. 01_Cert. 02'!K17 -> 0.5 | K17: =+I17+J17 -> 0.5 | L17: =+F17*I17 -> 559976.5 | M17: =+F17*J17 -> 0 | N17: =+F17*K17 -> 559976.5
A18: 5 | B18: AISLACIONES | G18: =+SUM(F19:F25) -> 35966419 | H18: =+G18/$G$185 -> 0.048890193
A19: 5.01 | B19: Aislación hidrófuga horizontal (baños) - Inc. membrana geotextil y 35% en concepto de babetas | C19: m2 | D19: 139.05 | E19: 21800 | F19: =+D19*E19 -> 3031290 | I19: =+'SVD 4140_Pto. 01_Cert. 02'!K19 -> 0 | K19: =+I19+J19 -> 0 | L19: =+F19*I19 -> 0 | M19: =+F19*J19 -> 0 | N19: =+F19*K19 -> 0
A20: 5.02 | B20: Azotado hidrofugo - Sobre medianeras existentes | C20: m2 | D20: 300 | E20: 5376 | F20: =+D20*E20 -> 1612800 | I20: =+'SVD 4140_Pto. 01_Cert. 02'!K20 -> 0 | K20: =+I20+J20 -> 0 | L20: =+F20*I20 -> 0 | M20: =+F20*J20 -> 0 | N20: =+F20*K20 -> 0
A21: 5.03 | B21: Azotado hidrofugo - Contrapiso de vereda | C21: m2 | D21: 48 | E21: 5376 | F21: =+D21*E21 -> 258048 | I21: =+'SVD 4140_Pto. 01_Cert. 02'!K21 -> 0 | K21: =+I21+J21 -> 0 | L21: =+F21*I21 -> 0 | M21: =+F21*J21 -> 0 | N21: =+F21*K21 -> 0
A22: 5.04 | B22: Aislación térmica en terrazas, eps e:2,00 cm | C22: m2 | D22: 262 | E22: 4403 | F22: =+D22*E22 -> 1153586 | I22: =+'SVD 4140_Pto. 01_Cert. 02'!K22 -> 0 | K22: =+I22+J22 -> 0 | L22: =+F22*I22 -> 0 | M22: =+F22*J22 -> 0 | N22: =+F22*K22 -> 0
A23: 5.05 | B23: Barrera de vapor | C23: m2 | D23: 510 | E23: 3578 | F23: =+D23*E23 -> 1824780 | I23: =+'SVD 4140_Pto. 01_Cert. 02'!K23 -> 0 | K23: =+I23+J23 -> 0 | L23: =+F23*I23 -> 0 | M23: =+F23*J23 -> 0 | N23: =+F23*K23 -> 0
A24: 5.06 | B24: Membrana asfaltica geotextil 4mm - Balcones y azotea - Inc. 20% en concepto de babetas | C24: m2 | D24: 510 | E24: 21800 | F24: =+D24*E24 -> 11118000 | I24: =+'SVD 4140_Pto. 01_Cert. 02'!K24 -> 0 | K24: =+I24+J24 -> 0 | L24: =+F24*I24 -> 0 | M24: =+F24*J24 -> 0 | N24: =+F24*K24 -> 0
A25: 5.07 | B25: Impermeabilización de subsuelo | C25: gl | D25: 1 | E25: 16967915 | F25: =+D25*E25 -> 16967915 | I25: =+'SVD 4140_Pto. 01_Cert. 02'!K25 -> 1 | K25: =+I25+J25 -> 1 | L25: =+F25*I25 -> 16967915 | M25: =+F25*J25 -> 0 | N25: =+F25*K25 -> 16967915
A26: 6 | B26: CUBIERTAS | G26: =+SUM(F27) -> 2433900 | H26: =+G26/$G$185 -> 0.0033084706
A27: 6.02 | B27: Babeta de chapa galvanizada en medianeras | C27: ml | D27: 60 | E27: 40565 | F27: =+D27*E27 -> 2433900 | I27: =+'SVD 4140_Pto. 01_Cert. 02'!K27 -> 0 | K27: =+I27+J27 -> 0 | L27: =+F27*I27 -> 0 | M27: =+F27*J27 -> 0 | N27: =+F27*K27 -> 0
A28: 7 | B28: REVOQUES | G28: =+SUM(F29:F36) -> 1.3639056e+08 | H28: =+G28/$G$185 -> 0.18539962
A29: 7.01 | B29: Revoque Grueso Impermeable Exterior proyectable | C29: m2 | D29: 678.252 | E29: 16571 | F29: =+D29*E29 -> 11239314 | I29: =+'SVD 4140_Pto. 01_Cert. 02'!K29 -> 0 | K29: =+I29+J29 -> 0 | L29: =+F29*I29 -> 0 | M29: =+F29*J29 -> 0 | N29: =+F29*K29 -> 0
A30: 7.02 | B30: Revoque Grueso Impermeable Exterior a mas de 3m proyectable - Medianero y fachadas | C30: m2 | D30: 876.0812 | E30: 22183 | F30: =+D30*E30 -> 19434109 | I30: =+'SVD 4140_Pto. 01_Cert. 02'!K30 -> 0 | K30: =+I30+J30 -> 0 | L30: =+F30*I30 -> 0 | M30: =+F30*J30 -> 0 | N30: =+F30*K30 -> 0
A31: 7.03 | B31: Buña en revoque | C31: ml | D31: 182 | E31: 10806 | F31: =+D31*E31 -> 1966692 | I31: =+'SVD 4140_Pto. 01_Cert. 02'!K31 -> 0 | K31: =+I31+J31 -> 0 | L31: =+F31*I31 -> 0 | M31: =+F31*J31 -> 0 | N31: =+F31*K31 -> 0
A32: 7.04 | B32: Revoque Grueso Interior + fino | C32: m2 | D32: 995.8511 | E32: 26530 | F32: =+D32*E32 -> 26419930 | I32: =+'SVD 4140_Pto. 01_Cert. 02'!K32 -> 0 | K32: =+I32+J32 -> 0 | L32: =+F32*I32 -> 0 | M32: =+F32*J32 -> 0 | N32: =+F32*K32 -> 0
A33: 7.05 | B33: Yeso interior | C33: m2 | D33: 2514.897 | E33: 22566 | F33: =+D33*E33 -> 56751166 | I33: =+'SVD 4140_Pto. 01_Cert. 02'!K33 -> 0 | K33: =+I33+J33 -> 0 | L33: =+F33*I33 -> 0 | M33: =+F33*J33 -> 0 | N33: =+F33*K33 -> 0
A34: 7.06 | B34: Arista en yeso | C34: ml | D34: 509.9 | E34: 12771 | F34: =+D34*E34 -> 6511932.9 | I34: =+'SVD 4140_Pto. 01_Cert. 02'!K34 -> 0 | K34: =+I34+J34 -> 0 | L34: =+F34*I34 -> 0 | M34: =+F34*J34 -> 0 | N34: =+F34*K34 -> 0
A35: 7.07 | B35: Provisión y colocación de guardacanto yesero | C35: u | D35: 198 | E35: 14947 | F35: =+D35*E35 -> 2959506 | I35: =+'SVD 4140_Pto. 01_Cert. 02'!K35 -> 0 | K35: =+I35+J35 -> 0 | L35: =+F35*I35 -> 0 | M35: =+F35*J35 -> 0 | N35: =+F35*K35 -> 0
A36: 7.08 | B36: Revoque Grueso Impermeable Interior b/ revestimiento | C36: m2 | D36: 670.322 | E36: 16571 | F36: =+D36*E36 -> 11107906 | I36: =+'SVD 4140_Pto. 01_Cert. 02'!K36 -> 0 | K36: =+I36+J36 -> 0 | L36: =+F36*I36 -> 0 | M36: =+F36*J36 -> 0 | N36: =+F36*K36 -> 0
A37: 8 | B37: CONTRAPISOS Y CARPETAS | G37: =+SUM(F38:F45) -> 44788107 | H37: =+G37/$G$185 -> 0.060881768
A38: 8.01 | B38: Contrapiso de cascotes en SS e: 15 cm | C38: m2 | D38: 104 | E38: 31920 | F38: =+D38*E38 -> 3319680 | I38: =+'SVD 4140_Pto. 01_Cert. 02'!K38 -> 1 | K38: =+I38+J38 -> 1 | L38: =+F38*I38 -> 3319680 | M38: =+F38*J38 -> 0 | N38: =+F38*K38 -> 3319680
A39: 8.02 | B39: Contrapiso de cascote s/terreno natural e: 20 cm - Incluye film de polietileno | C39: m2 | D39: 48 | E39: 37268 | F39: =+D39*E39 -> 1788864 | I39: =+'SVD 4140_Pto. 01_Cert. 02'!K39 -> 0 | K39: =+I39+J39 -> 0 | L39: =+F39*I39 -> 0 | M39: =+F39*J39 -> 0 | N39: =+F39*K39 -> 0
A40: 8.03 | B40: Contrapiso de cascotes en azoteas c/pendiente e: 15 cm | C40: m2 | D40: 235 | E40: 32410 | F40: =+D40*E40 -> 7616350 | I40: =+'SVD 4140_Pto. 01_Cert. 02'!K40 -> 0 | K40: =+I40+J40 -> 0 | L40: =+F40*I40 -> 0 | M40: =+F40*J40 -> 0 | N40: =+F40*K40 -> 0
A41: 8.04 | B41: Contrapiso - Carpeta monolitico e: 7 cm | C41: m2 | D41: 878 | E41: 19006 | F41: =+D41*E41 -> 16687268 | I41: =+'SVD 4140_Pto. 01_Cert. 02'!K41 -> 0 | K41: =+I41+J41 -> 0 | L41: =+F41*I41 -> 0 | M41: =+F41*J41 -> 0 | N41: =+F41*K41 -> 0
...

Sheet SVD 4140_Pto. 01_Cert. 04
F1: DÓLAR BNA | G1: DÓLAR MEP
F2: 1005 | G2: 1170
F4: 45628
B5: OBRA: EDIFICIO EL SALVADOR 4140 | I5: Certificado | J5: 4 | N5: 46050
B6: PRESUPUESTO OBRA CIVIL
B7: Descripción | C7: U | D7: Cant | E7: P unit | F7: Subtotal | I7: Avance | L7: Importe
B8: PRESUPUESTO 02 - ALBANILERIA + INSTALACIONES + TERMINACIONES | I8: Anterior | J8: Actual | K8: Acumulado | L8: Anterior | M8: Actual | N8: Acumulado
A9: 4 | B9: ALBAÑILERIA | G9: =+SUM(F10:F17) -> 54302890 | H9: =+G9/$G$185 -> 0.073815487
A10: 4.01 | B10: Muro tipo 1 (interiores, divisorio de locales) e: 10 cm - Ladrillo hueco 08 x 18 x 33 | C10: m2 | D10: 819 | E10: 18993 | F10: =+D10*E10 -> 15555267 | I10: =+'SVD 4140_Pto. 01_Cert. 03'!K10 -> 0.35 | J10: 0.2 | K10: =+I10+J10 -> 0.55 | L10: =+F10*I10 -> 5444343.4 | M10: =+F10*J10 -> 3111053.4 | N10: =+F10*K10 -> 8555396.9
A11: 4.02 | B11: Muro tipo 2 y 3 (medianera, caja de escaleras y ascensor) e: 15 cm - Ladrillo hueco portante 12 x 19 x 33 | C11: m2 | D11: 612 | E11: 25172 | F11: =+D11*E11 -> 15405264 | I11: =+'SVD 4140_Pto. 01_Cert. 03'!K11 -> 0.25 | J11: 0.25 | K11: =+I11+J11 -> 0.5 | L11: =+F11*I11 -> 3851316 | M11: =+F11*J11 -> 3851316 | N11: =+F11*K11 -> 7702632
A12: 4.03 | B12: Muro tipo 4 (divisorio de unidades y fachas) e: 15 cm - Ladrillo hueco 12 x 18 x 33 | C12: m2 | D12: 636 | E12: 21109 | F12: =+D12*E12 -> 13425324 | I12: =+'SVD 4140_Pto. 01_Cert. 03'!K12 -> 0.35 | J12: 0.2 | K12: =+I12+J12 -> 0.55 | L12: =+F12*I12 -> 4698863.4 | M12: =+F12*J12 -> 2685064.8 | N12: =+F12*K12 -> 7383928.2
A13: 4.04 | B13: Enchape medianeras existentes - Contemplamos picado zonas sueltas y enchape con ladrillo comun para PB | C13: m2 | D13: 195 | E13: 15092 | F13: =+D13*E13 -> 2942940 | I13: =+'SVD 4140_Pto. 01_Cert. 03'!K13 -> 0.15 | K13: =+I13+J13 -> 0.15 | L13: =+F13*I13 -> 441441 | M13: =+F13*J13 -> 0 | N13: =+F13*K13 -> 441441
A14: 4.05 | B14: Mamposteria cribada de ladrillo visto en balcones | C14: m2 | D14: 30.054 | E14: 67420 | F14: =+D14*E14 -> 2026240.7 | I14: =+'SVD 4140_Pto. 01_Cert. 03'!K14 -> 0 | K14: =+I14+J14 -> 0 | L14: =+F14*I14 -> 0 | M14: =+F14*J14 -> 0 | N14: =+F14*K14 -> 0
A15: 4.06 | B15: Bloque de H° con masillado de hormigon | C15: m2 | D15: 24 | E15: 54908 | F15: =+D15*E15 -> 1317792 | I15: =+'SVD 4140_Pto. 01_Cert. 03'!K15 -> 0 | K15: =+I15+J15 -> 0 | L15: =+F15*I15 -> 0 | M15: =+F15*J15 -> 0 | N15: =+F15*K15 -> 0
A16: 4.07 | B16: Cordón de hormigón en umbrales carpinterías | C16: ml | D16: 81 | E16: 30989 | F16: =+D16*E16 -> 2510109 | I16: =+'SVD 4140_Pto. 01_Cert. 03'!K16 -> 0 | K16: =+I16+J16 -> 0 | L16: =+F16*I16 -> 0 | M16: =+F16*J16 -> 0 | N16: =+F16*K16 -> 0
A17: 4.08 | B17: Pozo de bombeo pluvial y cloacal | C17: gl | D17: 1 | E17: 1119953 | F17: =+D17*E17 -> 1119953 | I17: =+'SVD 4140_Pto. 01_Cert. 03'!K17 -> 0.5 | K17: =+I17+J17 -> 0.5 | L17: =+F17*I17 -> 559976.5 | M17: =+F17*J17 -> 0 | N17: =+F17*K17 -> 559976.5
A18: 5 | B18: AISLACIONES | G18: =+SUM(F19:F25) -> 35966419 | H18: =+G18/$G$185 -> 0.048890193
A19: 5.01 | B19: Aislación hidrófuga horizontal (baños) - Inc. membrana geotextil y 35% en concepto de babetas | C19: m2 | D19: 139.05 | E19: 21800 | F19: =+D19*E19 -> 3031290 | I19: =+'SVD 4140_Pto. 01_Cert. 03'!K19 -> 0 | K19: =+I19+J19 -> 0 | L19: =+F19*I19 -> 0 | M19: =+F19*J19 -> 0 | N19: =+F19*K19 -> 0
A20: 5.02 | B20: Azotado hidrofugo - Sobre medianeras existentes | C20: m2 | D20: 300 | E20: 5376 | F20: =+D20*E20 -> 1612800 | I20: =+'SVD 4140_Pto. 01_Cert. 03'!K20 -> 0 | K20: =+I20+J20 -> 0 | L20: =+F20*I20 -> 0 | M20: =+F20*J20 -> 0 | N20: =+F20*K20 -> 0
A21: 5.03 | B21: Azotado hidrofugo - Contrapiso de vereda | C21: m2 | D21: 48 | E21: 5376 | F21: =+D21*E21 -> 258048 | I21: =+'SVD 4140_Pto. 01_Cert. 03'!K21 -> 0 | K21: =+I21+J21 -> 0 | L21: =+F21*I21 -> 0 | M21: =+F21*J21 -> 0 | N21: =+F21*K21 -> 0
A22: 5.04 | B22: Aislación térmica en terrazas, eps e:2,00 cm | C22: m2 | D22: 262 | E22: 4403 | F22: =+D22*E22 -> 1153586 | I22: =+'SVD 4140_Pto. 01_Cert. 03'!K22 -> 0 | K22: =+I22+J22 -> 0 | L22: =+F22*I22 -> 0 | M22: =+F22*J22 -> 0 | N22: =+F22*K22 -> 0
A23: 5.05 | B23: Barrera de vapor | C23: m2 | D23: 510 | E23: 3578 | F23: =+D23*E23 -> 1824780 | I23: =+'SVD 4140_Pto. 01_Cert. 03'!K23 -> 0 | K23: =+I23+J23 -> 0 | L23: =+F23*I23 -> 0 | M23: =+F23*J23 -> 0 | N23: =+F23*K23 -> 0
A24: 5.06 | B24: Membrana asfaltica geotextil 4mm - Balcones y azotea - Inc. 20% en concepto de babetas | C24: m2 | D24: 510 | E24: 21800 | F24: =+D24*E24 -> 11118000 | I24: =+'SVD 4140_Pto. 01_Cert. 03'!K24 -> 0 | K24: =+I24+J24 -> 0 | L24: =+F24*I24 -> 0 | M24: =+F24*J24 -> 0 | N24: =+F24*K24 -> 0
A25: 5.07 | B25: Impermeabilización de subsuelo | C25: gl | D25: 1 | E25: 16967915 | F25: =+D25*E25 -> 16967915 | I25: =+'SVD 4140_Pto. 01_Cert. 03'!K25 -> 1 | K25: =+I25+J25 -> 1 | L25: =+F25*I25 -> 16967915 | M25: =+F25*J25 -> 0 | N25: =+F25*K25 -> 16967915
A26: 6 | B26: CUBIERTAS | G26: =+SUM(F27) -> 2433900 | H26: =+G26/$G$185 -> 0.0033084706
A27: 6.02 | B27: Babeta de chapa galvanizada en medianeras | C27: ml | D27: 60 | E27: 40565 | F27: =+D27*E27 -> 2433900 | I27: =+'SVD 4140_Pto. 01_Cert. 03'!K27 -> 0 | K27: =+I27+J27 -> 0 | L27: =+F27*I27 -> 0 | M27: =+F27*J27 -> 0 | N27: =+F27*K27 -> 0
A28: 7 | B28: REVOQUES | G28: =+SUM(F29:F36) -> 1.3639056e+08 | H28: =+G28/$G$185 -> 0.18539962
A29: 7.01 | B29: Revoque Grueso Impermeable Exterior proyectable | C29: m2 | D29: 678.252 | E29: 16571 | F29: =+D29*E29 -> 11239314 | I29: =+'SVD 4140_Pto. 01_Cert. 03'!K29 -> 0 | K29: =+I29+J29 -> 0 | L29: =+F29*I29 -> 0 | M29: =+F29*J29 -> 0 | N29: =+F29*K29 -> 0
A30: 7.02 | B30: Revoque Grueso Impermeable Exterior a mas de 3m proyectable - Medianero y fachadas | C30: m2 | D30: 876.0812 | E30: 22183 | F30: =+D30*E30 -> 19434109 | I30: =+'SVD 4140_Pto. 01_Cert. 03'!K30 -> 0 | K30: =+I30+J30 -> 0 | L30: =+F30*I30 -> 0 | M30: =+F30*J30 -> 0 | N30: =+F30*K30 -> 0
A31: 7.03 | B31: Buña en revoque | C31: ml | D31: 182 | E31: 10806 | F31: =+D31*E31 -> 1966692 | I31: =+'SVD 4140_Pto. 01_Cert. 03'!K31 -> 0 | K31: =+I31+J31 -> 0 | L31: =+F31*I31 -> 0 | M31: =+F31*J31 -> 0 | N31: =+F31*K31 -> 0
A32: 7.04 | B32: Revoque Grueso Interior + fino | C32: m2 | D32: 995.8511 | E32: 26530 | F32: =+D32*E32 -> 26419930 | I32: =+'SVD 4140_Pto. 01_Cert. 03'!K32 -> 0 | J32: 0.45 | K32: =+I32+J32 -> 0.45 | L32: =+F32*I32 -> 0 | M32: =+F32*J32 -> 11888968 | N32: =+F32*K32 -> 11888968
A33: 7.05 | B33: Yeso interior | C33: m2 | D33: 2514.897 | E33: 22566 | F33: =+D33*E33 -> 56751166 | I33: =+'SVD 4140_Pto. 01_Cert. 03'!K33 -> 0 | K33: =+I33+J33 -> 0 | L33: =+F33*I33 -> 0 | M33: =+F33*J33 -> 0 | N33: =+F33*K33 -> 0
A34: 7.06 | B34: Arista en yeso | C34: ml | D34: 509.9 | E34: 12771 | F34: =+D34*E34 -> 6511932.9 | I34: =+'SVD 4140_Pto. 01_Cert. 03'!K34 -> 0 | K34: =+I34+J34 -> 0 | L34: =+F34*I34 -> 0 | M34: =+F34*J34 -> 0 | N34: =+F34*K34 -> 0
A35: 7.07 | B35: Provisión y colocación de guardacanto yesero | C35: u | D35: 198 | E35: 14947 | F35: =+D35*E35 -> 2959506 | I35: =+'SVD 4140_Pto. 01_Cert. 03'!K35 -> 0 | K35: =+I35+J35 -> 0 | L35: =+F35*I35 -> 0 | M35: =+F35*J35 -> 0 | N35: =+F35*K35 -> 0
A36: 7.08 | B36: Revoque Grueso Impermeable Interior b/ revestimiento | C36: m2 | D36: 670.322 | E36: 16571 | F36: =+D36*E36 -> 11107906 | I36: =+'SVD 4140_Pto. 01_Cert. 03'!K36 -> 0 | K36: =+I36+J36 -> 0 | L36: =+F36*I36 -> 0 | M36: =+F36*J36 -> 0 | N36: =+F36*K36 -> 0
A37: 8 | B37: CONTRAPISOS Y CARPETAS | G37: =+SUM(F38:F45) -> 44788107 | H37: =+G37/$G$185 -> 0.060881768
A38: 8.01 | B38: Contrapiso de cascotes en SS e: 15 cm | C38: m2 | D38: 104 | E38: 31920 | F38: =+D38*E38 -> 3319680 | I38: =+'SVD 4140_Pto. 01_Cert. 03'!K38 -> 1 | K38: =+I38+J38 -> 1 | L38: =+F38*I38 -> 3319680 | M38: =+F38*J38 -> 0 | N38: =+F38*K38 -> 3319680
A39: 8.02 | B39: Contrapiso de cascote s/terreno natural e: 20 cm - Incluye film de polietileno | C39: m2 | D39: 48 | E39: 37268 | F39: =+D39*E39 -> 1788864 | I39: =+'SVD 4140_Pto. 01_Cert. 03'!K39 -> 0 | K39: =+I39+J39 -> 0 | L39: =+F39*I39 -> 0 | M39: =+F39*J39 -> 0 | N39: =+F39*K39 -> 0
A40: 8.03 | B40: Contrapiso de cascotes en azoteas c/pendiente e: 15 cm | C40: m2 | D40: 235 | E40: 32410 | F40: =+D40*E40 -> 7616350 | I40: =+'SVD 4140_Pto. 01_Cert. 03'!K40 -> 0 | K40: =+I40+J40 -> 0 | L40: =+F40*I40 -> 0 | M40: =+F40*J40 -> 0 | N40: =+F40*K40 -> 0
A41: 8.04 | B41: Contrapiso - Carpeta monolitico e: 7 cm | C41: m2 | D41: 878 | E41: 19006 | F41: =+D41*E41 -> 16687268 | I41: =+'SVD 4140_Pto. 01_Cert. 03'!K41 -> 0 | K41: =+I41+J41 -> 0 | L41: =+F41*I41 -> 0 | M41: =+F41*J41 -> 0 | N41: =+F41*K41 -> 0
...

Sheet SVD 4140_Pto. 01_Cert. 05
F1: DÓLAR BNA | G1: DÓLAR MEP
F2: 1005 | G2: 1170
F4: 45628
B5: OBRA: EDIFICIO EL SALVADOR 4140 | I5: Certificado | J5: 5 | N5: 46080
B6: PRESUPUESTO OBRA CIVIL
B7: Descripción | C7: U | D7: Cant | E7: P unit | F7: Subtotal | I7: Avance | L7: Importe
B8: PRESUPUESTO 02 - ALBANILERIA + INSTALACIONES + TERMINACIONES | I8: Anterior | J8: Actual | K8: Acumulado | L8: Anterior | M8: Actual | N8: Acumulado
A9: 4 | B9: ALBAÑILERIA | G9: =+SUM(F10:F17) -> 54302890 | H9: =+G9/$G$185 -> 0.073815487
A10: 4.01 | B10: Muro tipo 1 (interiores, divisorio de locales) e: 10 cm - Ladrillo hueco 08 x 18 x 33 | C10: m2 | D10: 819 | E10: 18993 | F10: =+D10*E10 -> 15555267 | I10: =+'SVD 4140_Pto. 01_Cert. 04'!K10 -> 0.55 | J10: 0.15 | K10: =+I10+J10 -> 0.7 | L10: =+F10*I10 -> 8555396.9 | M10: =+F10*J10 -> 2333290 | N10: =+F10*K10 -> 10888687 | P10: 1041
A11: 4.02 | B11: Muro tipo 2 y 3 (medianera, caja de escaleras y ascensor) e: 15 cm - Ladrillo hueco portante 12 x 19 x 33 | C11: m2 | D11: 612 | E11: 25172 | F11: =+D11*E11 -> 15405264 | I11: =+'SVD 4140_Pto. 01_Cert. 04'!K11 -> 0.5 | J11: 0.1 | K11: =+I11+J11 -> 0.6 | L11: =+F11*I11 -> 7702632 | M11: =+F11*J11 -> 1540526.4 | N11: =+F11*K11 -> 9243158.4
A12: 4.03 | B12: Muro tipo 4 (divisorio de unidades y fachas) e: 15 cm - Ladrillo hueco 12 x 18 x 33 | C12: m2 | D12: 636 | E12: 21109 | F12: =+D12*E12 -> 13425324 | I12: =+'SVD 4140_Pto. 01_Cert. 04'!K12 -> 0.55 | J12: 0.15 | K12: =+I12+J12 -> 0.7 | L12: =+F12*I12 -> 7383928.2 | M12: =+F12*J12 -> 2013798.6 | N12: =+F12*K12 -> 9397726.8
A13: 4.04 | B13: Enchape medianeras existentes - Contemplamos picado zonas sueltas y enchape con ladrillo comun para PB | C13: m2 | D13: 195 | E13: 15092 | F13: =+D13*E13 -> 2942940 | I13: =+'SVD 4140_Pto. 01_Cert. 04'!K13 -> 0.15 | J13: 0 | K13: =+I13+J13 -> 0.15 | L13: =+F13*I13 -> 441441 | M13: =+F13*J13 -> 0 | N13: =+F13*K13 -> 441441
A14: 4.05 | B14: Mamposteria cribada de ladrillo visto en balcones | C14: m2 | D14: 30.054 | E14: 67420 | F14: =+D14*E14 -> 2026240.7 | I14: =+'SVD 4140_Pto. 01_Cert. 04'!K14 -> 0 | K14: =+I14+J14 -> 0 | L14: =+F14*I14 -> 0 | M14: =+F14*J14 -> 0 | N14: =+F14*K14 -> 0
A15: 4.06 | B15: Bloque de H° con masillado de hormigon | C15: m2 | D15: 24 | E15: 54908 | F15: =+D15*E15 -> 1317792 | I15: =+'SVD 4140_Pto. 01_Cert. 04'!K15 -> 0 | K15: =+I15+J15 -> 0 | L15: =+F15*I15 -> 0 | M15: =+F15*J15 -> 0 | N15: =+F15*K15 -> 0
A16: 4.07 | B16: Cordón de hormigón en umbrales carpinterías | C16: ml | D16: 81 | E16: 30989 | F16: =+D16*E16 -> 2510109 | I16: =+'SVD 4140_Pto. 01_Cert. 04'!K16 -> 0 | K16: =+I16+J16 -> 0 | L16: =+F16*I16 -> 0 | M16: =+F16*J16 -> 0 | N16: =+F16*K16 -> 0
A17: 4.08 | B17: Pozo de bombeo pluvial y cloacal | C17: gl | D17: 1 | E17: 1119953 | F17: =+D17*E17 -> 1119953 | I17: =+'SVD 4140_Pto. 01_Cert. 04'!K17 -> 0.5 | K17: =+I17+J17 -> 0.5 | L17: =+F17*I17 -> 559976.5 | M17: =+F17*J17 -> 0 | N17: =+F17*K17 -> 559976.5
A18: 5 | B18: AISLACIONES | G18: =+SUM(F19:F25) -> 35966419 | H18: =+G18/$G$185 -> 0.048890193
A19: 5.01 | B19: Aislación hidrófuga horizontal (baños) - Inc. membrana geotextil y 35% en concepto de babetas | C19: m2 | D19: 139.05 | E19: 21800 | F19: =+D19*E19 -> 3031290 | I19: 0 | K19: =+I19+J19 -> 0 | L19: =+F19*I19 -> 0 | M19: =+F19*J19 -> 0 | N19: =+F19*K19 -> 0
A20: 5.02 | B20: Azotado hidrofugo - Sobre medianeras existentes | C20: m2 | D20: 300 | E20: 5376 | F20: =+D20*E20 -> 1612800 | I20: 0 | K20: =+I20+J20 -> 0 | L20: =+F20*I20 -> 0 | M20: =+F20*J20 -> 0 | N20: =+F20*K20 -> 0
A21: 5.03 | B21: Azotado hidrofugo - Contrapiso de vereda | C21: m2 | D21: 48 | E21: 5376 | F21: =+D21*E21 -> 258048 | I21: 0 | K21: =+I21+J21 -> 0 | L21: =+F21*I21 -> 0 | M21: =+F21*J21 -> 0 | N21: =+F21*K21 -> 0
A22: 5.04 | B22: Aislación térmica en terrazas, eps e:2,00 cm | C22: m2 | D22: 262 | E22: 4403 | F22: =+D22*E22 -> 1153586 | I22: 0 | K22: =+I22+J22 -> 0 | L22: =+F22*I22 -> 0 | M22: =+F22*J22 -> 0 | N22: =+F22*K22 -> 0
A23: 5.05 | B23: Barrera de vapor | C23: m2 | D23: 510 | E23: 3578 | F23: =+D23*E23 -> 1824780 | I23: 0 | K23: =+I23+J23 -> 0 | L23: =+F23*I23 -> 0 | M23: =+F23*J23 -> 0 | N23: =+F23*K23 -> 0
A24: 5.06 | B24: Membrana asfaltica geotextil 4mm - Balcones y azotea - Inc. 20% en concepto de babetas | C24: m2 | D24: 510 | E24: 21800 | F24: =+D24*E24 -> 11118000 | I24: 0 | K24: =+I24+J24 -> 0 | L24: =+F24*I24 -> 0 | M24: =+F24*J24 -> 0 | N24: =+F24*K24 -> 0
A25: 5.07 | B25: Impermeabilización de subsuelo | C25: gl | D25: 1 | E25: 16967915 | F25: =+D25*E25 -> 16967915 | I25: 1 | K25: =+I25+J25 -> 1 | L25: =+F25*I25 -> 16967915 | M25: =+F25*J25 -> 0 | N25: =+F25*K25 -> 16967915
A26: 6 | B26: CUBIERTAS | G26: =+SUM(F27) -> 2433900 | H26: =+G26/$G$185 -> 0.0033084706
A27: 6.02 | B27: Babeta de chapa galvanizada en medianeras | C27: ml | D27: 60 | E27: 40565 | F27: =+D27*E27 -> 2433900 | I27: =+'SVD 4140_Pto. 01_Cert. 04'!K27 -> 0 | K27: =+I27+J27 -> 0 | L27: =+F27*I27 -> 0 | M27: =+F27*J27 -> 0 | N27: =+F27*K27 -> 0
A28: 7 | B28: REVOQUES | G28: =+SUM(F29:F36) -> 1.3639056e+08 | H28: =+G28/$G$185 -> 0.18539962
A29: 7.01 | B29: Revoque Grueso Impermeable Exterior proyectable | C29: m2 | D29: 678.252 | E29: 16571 | F29: =+D29*E29 -> 11239314 | I29: =+'SVD 4140_Pto. 01_Cert. 04'!K29 -> 0 | K29: =+I29+J29 -> 0 | L29: =+F29*I29 -> 0 | M29: =+F29*J29 -> 0 | N29: =+F29*K29 -> 0
A30: 7.02 | B30: Revoque Grueso Impermeable Exterior a mas de 3m proyectable - Medianero y fachadas | C30: m2 | D30: 876.0812 | E30: 22183 | F30: =+D30*E30 -> 19434109 | I30: =+'SVD 4140_Pto. 01_Cert. 04'!K30 -> 0 | K30: =+I30+J30 -> 0 | L30: =+F30*I30 -> 0 | M30: =+F30*J30 -> 0 | N30: =+F30*K30 -> 0
A31: 7.03 | B31: Buña en revoque | C31: ml | D31: 182 | E31: 10806 | F31: =+D31*E31 -> 1966692 | I31: =+'SVD 4140_Pto. 01_Cert. 04'!K31 -> 0 | K31: =+I31+J31 -> 0 | L31: =+F31*I31 -> 0 | M31: =+F31*J31 -> 0 | N31: =+F31*K31 -> 0
A32: 7.04 | B32: Revoque Grueso Interior + fino | C32: m2 | D32: 995.8511 | E32: 26530 | F32: =+D32*E32 -> 26419930 | I32: =+'SVD 4140_Pto. 01_Cert. 04'!K32 -> 0.45 | K32: =+I32+J32 -> 0.45 | L32: =+F32*I32 -> 11888968 | M32: =+F32*J32 -> 0 | N32: =+F32*K32 -> 11888968
A33: 7.05 | B33: Yeso interior | C33: m2 | D33: 2514.897 | E33: 22566 | F33: =+D33*E33 -> 56751166 | I33: =+'SVD 4140_Pto. 01_Cert. 04'!K33 -> 0 | J33: 0.05 | K33: =+I33+J33 -> 0.05 | L33: =+F33*I33 -> 0 | M33: =+F33*J33 -> 2837558.3 | N33: =+F33*K33 -> 2837558.3
A34: 7.06 | B34: Arista en yeso | C34: ml | D34: 509.9 | E34: 12771 | F34: =+D34*E34 -> 6511932.9 | I34: =+'SVD 4140_Pto. 01_Cert. 04'!K34 -> 0 | J34: 0.05 | K34: =+I34+J34 -> 0.05 | L34: =+F34*I34 -> 0 | M34: =+F34*J34 -> 325596.65 | N34: =+F34*K34 -> 325596.65
A35: 7.07 | B35: Provisión y colocación de guardacanto yesero | C35: u | D35: 198 | E35: 14947 | F35: =+D35*E35 -> 2959506 | I35: =+'SVD 4140_Pto. 01_Cert. 04'!K35 -> 0 | K35: =+I35+J35 -> 0 | L35: =+F35*I35 -> 0 | M35: =+F35*J35 -> 0 | N35: =+F35*K35 -> 0
A36: 7.08 | B36: Revoque Grueso Impermeable Interior b/ revestimiento | C36: m2 | D36: 670.322 | E36: 16571 | F36: =+D36*E36 -> 11107906 | I36: =+'SVD 4140_Pto. 01_Cert. 04'!K36 -> 0 | K36: =+I36+J36 -> 0 | L36: =+F36*I36 -> 0 | M36: =+F36*J36 -> 0 | N36: =+F36*K36 -> 0
A37: 8 | B37: CONTRAPISOS Y CARPETAS | G37: =+SUM(F38:F45) -> 44788107 | H37: =+G37/$G$185 -> 0.060881768
A38: 8.01 | B38: Contrapiso de cascotes en SS e: 15 cm | C38: m2 | D38: 104 | E38: 31920 | F38: =+D38*E38 -> 3319680 | I38: =+'SVD 4140_Pto. 01_Cert. 04'!K38 -> 1 | K38: =+I38+J38 -> 1 | L38: =+F38*I38 -> 3319680 | M38: =+F38*J38 -> 0 | N38: =+F38*K38 -> 3319680
A39: 8.02 | B39: Contrapiso de cascote s/terreno natural e: 20 cm - Incluye film de polietileno | C39: m2 | D39: 48 | E39: 37268 | F39: =+D39*E39 -> 1788864 | I39: =+'SVD 4140_Pto. 01_Cert. 04'!K39 -> 0 | K39: =+I39+J39 -> 0 | L39: =+F39*I39 -> 0 | M39: =+F39*J39 -> 0 | N39: =+F39*K39 -> 0
A40: 8.03 | B40: Contrapiso de cascotes en azoteas c/pendiente e: 15 cm | C40: m2 | D40: 235 | E40: 32410 | F40: =+D40*E40 -> 7616350 | I40: =+'SVD 4140_Pto. 01_Cert. 04'!K40 -> 0 | K40: =+I40+J40 -> 0 | L40: =+F40*I40 -> 0 | M40: =+F40*J40 -> 0 | N40: =+F40*K40 -> 0
A41: 8.04 | B41: Contrapiso - Carpeta monolitico e: 7 cm | C41: m2 | D41: 878 | E41: 19006 | F41: =+D41*E41 -> 16687268 | I41: =+'SVD 4140_Pto. 01_Cert. 04'!K41 -> 0 | K41: =+I41+J41 -> 0 | L41: =+F41*I41 -> 0 | M41: =+F41*J41 -> 0 | N41: =+F41*K41 -> 0
...

Sheet SVD 4140_Pto. 01_Cert. 06
F1: DÓLAR BNA | G1: DÓLAR MEP
F2: 1005 | G2: 1170
F4: 45628
B5: OBRA: EDIFICIO EL SALVADOR 4140 | I5: Certificado | J5: 6 | N5: 46108
B6: PRESUPUESTO OBRA CIVIL
B7: Descripción | C7: U | D7: Cant | E7: P unit | F7: Subtotal | I7: Avance | L7: Importe
B8: PRESUPUESTO 02 - ALBANILERIA + INSTALACIONES + TERMINACIONES | I8: Anterior | J8: Actual | K8: Acumulado | L8: Anterior | M8: Actual | N8: Acumulado
A9: 4 | B9: ALBAÑILERIA | G9: =+SUM(F10:F17) -> 54302890 | H9: =+G9/$G$185 -> 0.073815487
A10: 4.01 | B10: Muro tipo 1 (interiores, divisorio de locales) e: 10 cm - Ladrillo hueco 08 x 18 x 33 | C10: m2 | D10: 819 | E10: 18993 | F10: =+D10*E10 -> 15555267 | I10: =+'SVD 4140_Pto. 01_Cert. 04'!K10 -> 0.55 | J10: 0.3 | K10: =+I10+J10 -> 0.85 | L10: =+F10*I10 -> 8555396.9 | M10: =+F10*J10 -> 4666580.1 | N10: =+F10*K10 -> 13221977
A11: 4.02 | B11: Muro tipo 2 y 3 (medianera, caja de escaleras y ascensor) e: 15 cm - Ladrillo hueco portante 12 x 19 x 33 | C11: m2 | D11: 612 | E11: 25172 | F11: =+D11*E11 -> 15405264 | I11: =+'SVD 4140_Pto. 01_Cert. 04'!K11 -> 0.5 | J11: 0.35 | K11: =+I11+J11 -> 0.85 | L11: =+F11*I11 -> 7702632 | M11: =+F11*J11 -> 5391842.4 | N11: =+F11*K11 -> 13094474
A12: 4.03 | B12: Muro tipo 4 (divisorio de unidades y fachas) e: 15 cm - Ladrillo hueco 12 x 18 x 33 | C12: m2 | D12: 636 | E12: 21109 | F12: =+D12*E12 -> 13425324 | I12: =+'SVD 4140_Pto. 01_Cert. 04'!K12 -> 0.55 | J12: 0.3 | K12: =+I12+J12 -> 0.85 | L12: =+F12*I12 -> 7383928.2 | M12: =+F12*J12 -> 4027597.2 | N12: =+F12*K12 -> 11411525
A13: 4.04 | B13: Enchape medianeras existentes - Contemplamos picado zonas sueltas y enchape con ladrillo comun para PB | C13: m2 | D13: 195 | E13: 15092 | F13: =+D13*E13 -> 2942940 | I13: =+'SVD 4140_Pto. 01_Cert. 04'!K13 -> 0.15 | K13: =+I13+J13 -> 0.15 | L13: =+F13*I13 -> 441441 | M13: =+F13*J13 -> 0 | N13: =+F13*K13 -> 441441
A14: 4.05 | B14: Mamposteria cribada de ladrillo visto en balcones | C14: m2 | D14: 30.054 | E14: 67420 | F14: =+D14*E14 -> 2026240.7 | I14: =+'SVD 4140_Pto. 01_Cert. 05'!K14 -> 0 | K14: =+I14+J14 -> 0 | L14: =+F14*I14 -> 0 | M14: =+F14*J14 -> 0 | N14: =+F14*K14 -> 0
A15: 4.06 | B15: Bloque de H° con masillado de hormigon | C15: m2 | D15: 24 | E15: 54908 | F15: =+D15*E15 -> 1317792 | I15: =+'SVD 4140_Pto. 01_Cert. 05'!K15 -> 0 | J15: 1 | K15: =+I15+J15 -> 1 | L15: =+F15*I15 -> 0 | M15: =+F15*J15 -> 1317792 | N15: =+F15*K15 -> 1317792
A16: 4.07 | B16: Cordón de hormigón en umbrales carpinterías | C16: ml | D16: 81 | E16: 30989 | F16: =+D16*E16 -> 2510109 | I16: =+'SVD 4140_Pto. 01_Cert. 05'!K16 -> 0 | J16: 0.75 | K16: =+I16+J16 -> 0.75 | L16: =+F16*I16 -> 0 | M16: =+F16*J16 -> 1882581.8 | N16: =+F16*K16 -> 1882581.8
A17: 4.08 | B17: Pozo de bombeo pluvial y cloacal | C17: gl | D17: 1 | E17: 1119953 | F17: =+D17*E17 -> 1119953 | I17: =+'SVD 4140_Pto. 01_Cert. 05'!K17 -> 0.5 | K17: =+I17+J17 -> 0.5 | L17: =+F17*I17 -> 559976.5 | M17: =+F17*J17 -> 0 | N17: =+F17*K17 -> 559976.5
A18: 5 | B18: AISLACIONES | G18: =+SUM(F19:F25) -> 35966419 | H18: =+G18/$G$185 -> 0.048890193
A19: 5.01 | B19: Aislación hidrófuga horizontal (baños) - Inc. membrana geotextil y 35% en concepto de babetas | C19: m2 | D19: 139.05 | E19: 21800 | F19: =+D19*E19 -> 3031290 | I19: =+'SVD 4140_Pto. 01_Cert. 05'!K19 -> 0 | K19: =+I19+J19 -> 0 | L19: =+F19*I19 -> 0 | M19: =+F19*J19 -> 0 | N19: =+F19*K19 -> 0
A20: 5.02 | B20: Azotado hidrofugo - Sobre medianeras existentes | C20: m2 | D20: 300 | E20: 5376 | F20: =+D20*E20 -> 1612800 | I20: =+'SVD 4140_Pto. 01_Cert. 05'!K20 -> 0 | J20: 0.5 | K20: =+I20+J20 -> 0.5 | L20: =+F20*I20 -> 0 | M20: =+F20*J20 -> 806400 | N20: =+F20*K20 -> 806400
A21: 5.03 | B21: Azotado hidrofugo - Contrapiso de vereda | C21: m2 | D21: 48 | E21: 5376 | F21: =+D21*E21 -> 258048 | I21: =+'SVD 4140_Pto. 01_Cert. 05'!K21 -> 0 | K21: =+I21+J21 -> 0 | L21: =+F21*I21 -> 0 | M21: =+F21*J21 -> 0 | N21: =+F21*K21 -> 0
A22: 5.04 | B22: Aislación térmica en terrazas, eps e:2,00 cm | C22: m2 | D22: 262 | E22: 4403 | F22: =+D22*E22 -> 1153586 | I22: =+'SVD 4140_Pto. 01_Cert. 05'!K22 -> 0 | K22: =+I22+J22 -> 0 | L22: =+F22*I22 -> 0 | M22: =+F22*J22 -> 0 | N22: =+F22*K22 -> 0
A23: 5.05 | B23: Barrera de vapor | C23: m2 | D23: 510 | E23: 3578 | F23: =+D23*E23 -> 1824780 | I23: =+'SVD 4140_Pto. 01_Cert. 05'!K23 -> 0 | K23: =+I23+J23 -> 0 | L23: =+F23*I23 -> 0 | M23: =+F23*J23 -> 0 | N23: =+F23*K23 -> 0
A24: 5.06 | B24: Membrana asfaltica geotextil 4mm - Balcones y azotea - Inc. 20% en concepto de babetas | C24: m2 | D24: 510 | E24: 21800 | F24: =+D24*E24 -> 11118000 | I24: =+'SVD 4140_Pto. 01_Cert. 05'!K24 -> 0 | K24: =+I24+J24 -> 0 | L24: =+F24*I24 -> 0 | M24: =+F24*J24 -> 0 | N24: =+F24*K24 -> 0
A25: 5.07 | B25: Impermeabilización de subsuelo | C25: gl | D25: 1 | E25: 16967915 | F25: =+D25*E25 -> 16967915 | I25: =+'SVD 4140_Pto. 01_Cert. 05'!K25 -> 1 | K25: =+I25+J25 -> 1 | L25: =+F25*I25 -> 16967915 | M25: =+F25*J25 -> 0 | N25: =+F25*K25 -> 16967915
A26: 6 | B26: CUBIERTAS | G26: =+SUM(F27) -> 2433900 | H26: =+G26/$G$185 -> 0.0033084706
A27: 6.02 | B27: Babeta de chapa galvanizada en medianeras | C27: ml | D27: 60 | E27: 40565 | F27: =+D27*E27 -> 2433900 | I27: =+'SVD 4140_Pto. 01_Cert. 05'!K27 -> 0 | K27: =+I27+J27 -> 0 | L27: =+F27*I27 -> 0 | M27: =+F27*J27 -> 0 | N27: =+F27*K27 -> 0
A28: 7 | B28: REVOQUES | G28: =+SUM(F29:F36) -> 1.3639056e+08 | H28: =+G28/$G$185 -> 0.18539962
A29: 7.01 | B29: Revoque Grueso Impermeable Exterior proyectable | C29: m2 | D29: 678.252 | E29: 16571 | F29: =+D29*E29 -> 11239314 | I29: =+'SVD 4140_Pto. 01_Cert. 05'!K29 -> 0 | K29: =+I29+J29 -> 0 | L29: =+F29*I29 -> 0 | M29: =+F29*J29 -> 0 | N29: =+F29*K29 -> 0
A30: 7.02 | B30: Revoque Grueso Impermeable Exterior a mas de 3m proyectable - Medianero y fachadas | C30: m2 | D30: 876.0812 | E30: 22183 | F30: =+D30*E30 -> 19434109 | I30: =+'SVD 4140_Pto. 01_Cert. 05'!K30 -> 0 | K30: =+I30+J30 -> 0 | L30: =+F30*I30 -> 0 | M30: =+F30*J30 -> 0 | N30: =+F30*K30 -> 0
A31: 7.03 | B31: Buña en revoque | C31: ml | D31: 182 | E31: 10806 | F31: =+D31*E31 -> 1966692 | I31: =+'SVD 4140_Pto. 01_Cert. 05'!K31 -> 0 | K31: =+I31+J31 -> 0 | L31: =+F31*I31 -> 0 | M31: =+F31*J31 -> 0 | N31: =+F31*K31 -> 0
A32: 7.04 | B32: Revoque Grueso Interior + fino | C32: m2 | D32: 995.8511 | E32: 26530 | F32: =+D32*E32 -> 26419930 | I32: =+'SVD 4140_Pto. 01_Cert. 05'!K32 -> 0.45 | K32: =+I32+J32 -> 0.45 | L32: =+F32*I32 -> 11888968 | M32: =+F32*J32 -> 0 | N32: =+F32*K32 -> 11888968
A33: 7.05 | B33: Yeso interior | C33: m2 | D33: 2514.897 | E33: 22566 | F33: =+D33*E33 -> 56751166 | I33: =+'SVD 4140_Pto. 01_Cert. 05'!K33 -> 0.05 | K33: =+I33+J33 -> 0.05 | L33: =+F33*I33 -> 2837558.3 | M33: =+F33*J33 -> 0 | N33: =+F33*K33 -> 2837558.3
A34: 7.06 | B34: Arista en yeso | C34: ml | D34: 509.9 | E34: 12771 | F34: =+D34*E34 -> 6511932.9 | I34: =+'SVD 4140_Pto. 01_Cert. 05'!K34 -> 0.05 | K34: =+I34+J34 -> 0.05 | L34: =+F34*I34 -> 325596.65 | M34: =+F34*J34 -> 0 | N34: =+F34*K34 -> 325596.65
A35: 7.07 | B35: Provisión y colocación de guardacanto yesero | C35: u | D35: 198 | E35: 14947 | F35: =+D35*E35 -> 2959506 | I35: =+'SVD 4140_Pto. 01_Cert. 05'!K35 -> 0 | K35: =+I35+J35 -> 0 | L35: =+F35*I35 -> 0 | M35: =+F35*J35 -> 0 | N35: =+F35*K35 -> 0
A36: 7.08 | B36: Revoque Grueso Impermeable Interior b/ revestimiento | C36: m2 | D36: 670.322 | E36: 16571 | F36: =+D36*E36 -> 11107906 | I36: =+'SVD 4140_Pto. 01_Cert. 05'!K36 -> 0 | K36: =+I36+J36 -> 0 | L36: =+F36*I36 -> 0 | M36: =+F36*J36 -> 0 | N36: =+F36*K36 -> 0
A37: 8 | B37: CONTRAPISOS Y CARPETAS | G37: =+SUM(F38:F45) -> 44788107 | H37: =+G37/$G$185 -> 0.060881768
A38: 8.01 | B38: Contrapiso de cascotes en SS e: 15 cm | C38: m2 | D38: 104 | E38: 31920 | F38: =+D38*E38 -> 3319680 | I38: =+'SVD 4140_Pto. 01_Cert. 05'!K38 -> 1 | K38: =+I38+J38 -> 1 | L38: =+F38*I38 -> 3319680 | M38: =+F38*J38 -> 0 | N38: =+F38*K38 -> 3319680
A39: 8.02 | B39: Contrapiso de cascote s/terreno natural e: 20 cm - Incluye film de polietileno | C39: m2 | D39: 48 | E39: 37268 | F39: =+D39*E39 -> 1788864 | I39: =+'SVD 4140_Pto. 01_Cert. 05'!K39 -> 0 | K39: =+I39+J39 -> 0 | L39: =+F39*I39 -> 0 | M39: =+F39*J39 -> 0 | N39: =+F39*K39 -> 0
A40: 8.03 | B40: Contrapiso de cascotes en azoteas c/pendiente e: 15 cm | C40: m2 | D40: 235 | E40: 32410 | F40: =+D40*E40 -> 7616350 | I40: =+'SVD 4140_Pto. 01_Cert. 05'!K40 -> 0 | K40: =+I40+J40 -> 0 | L40: =+F40*I40 -> 0 | M40: =+F40*J40 -> 0 | N40: =+F40*K40 -> 0
A41: 8.04 | B41: Contrapiso - Carpeta monolitico e: 7 cm | C41: m2 | D41: 878 | E41: 19006 | F41: =+D41*E41 -> 16687268 | I41: =+'SVD 4140_Pto. 01_Cert. 05'!K41 -> 0 | K41: =+I41+J41 -> 0 | L41: =+F41*I41 -> 0 | M41: =+F41*J41 -> 0 | N41: =+F41*K41 -> 0
...

Sheet SVD 4140_Pto. 01_Cert. 07
F1: DÓLAR BNA | G1: DÓLAR MEP
F2: 1005 | G2: 1170
F4: 45628
B5: OBRA: EDIFICIO EL SALVADOR 4140 | I5: Certificado | J5: 7 | N5: 46141
B6: PRESUPUESTO OBRA CIVIL
B7: Descripción | C7: U | D7: Cant | E7: P unit | F7: Subtotal | I7: Avance | L7: Importe
B8: PRESUPUESTO 02 - ALBANILERIA + INSTALACIONES + TERMINACIONES | I8: Anterior | J8: Actual | K8: Acumulado | L8: Anterior | M8: Actual | N8: Acumulado
A9: 4 | B9: ALBAÑILERIA | G9: =+SUM(F10:F17) -> 54302890 | H9: =+G9/$G$185 -> 0.073815487
A10: 4.01 | B10: Muro tipo 1 (interiores, divisorio de locales) e: 10 cm - Ladrillo hueco 08 x 18 x 33 | C10: m2 | D10: 819 | E10: 18993 | F10: =+D10*E10 -> 15555267 | I10: =+'SVD 4140_Pto. 01_Cert. 06'!K10 -> 0.85 | K10: =+I10+J10 -> 0.85 | L10: =+F10*I10 -> 13221977 | M10: =+F10*J10 -> 0 | N10: =+F10*K10 -> 13221977
A11: 4.02 | B11: Muro tipo 2 y 3 (medianera, caja de escaleras y ascensor) e: 15 cm - Ladrillo hueco portante 12 x 19 x 33 | C11: m2 | D11: 612 | E11: 25172 | F11: =+D11*E11 -> 15405264 | I11: =+'SVD 4140_Pto. 01_Cert. 06'!K11 -> 0.85 | K11: =+I11+J11 -> 0.85 | L11: =+F11*I11 -> 13094474 | M11: =+F11*J11 -> 0 | N11: =+F11*K11 -> 13094474
A12: 4.03 | B12: Muro tipo 4 (divisorio de unidades y fachas) e: 15 cm - Ladrillo hueco 12 x 18 x 33 | C12: m2 | D12: 636 | E12: 21109 | F12: =+D12*E12 -> 13425324 | I12: =+'SVD 4140_Pto. 01_Cert. 06'!K12 -> 0.85 | K12: =+I12+J12 -> 0.85 | L12: =+F12*I12 -> 11411525 | M12: =+F12*J12 -> 0 | N12: =+F12*K12 -> 11411525
A13: 4.04 | B13: Enchape medianeras existentes - Contemplamos picado zonas sueltas y enchape con ladrillo comun para PB | C13: m2 | D13: 195 | E13: 15092 | F13: =+D13*E13 -> 2942940 | I13: =+'SVD 4140_Pto. 01_Cert. 06'!K13 -> 0.15 | K13: =+I13+J13 -> 0.15 | L13: =+F13*I13 -> 441441 | M13: =+F13*J13 -> 0 | N13: =+F13*K13 -> 441441
A14: 4.05 | B14: Mamposteria cribada de ladrillo visto en balcones | C14: m2 | D14: 30.054 | E14: 67420 | F14: =+D14*E14 -> 2026240.7 | I14: =+'SVD 4140_Pto. 01_Cert. 06'!K14 -> 0 | K14: =+I14+J14 -> 0 | L14: =+F14*I14 -> 0 | M14: =+F14*J14 -> 0 | N14: =+F14*K14 -> 0
A15: 4.06 | B15: Bloque de H° con masillado de hormigon | C15: m2 | D15: 24 | E15: 54908 | F15: =+D15*E15 -> 1317792 | I15: =+'SVD 4140_Pto. 01_Cert. 06'!K15 -> 1 | K15: =+I15+J15 -> 1 | L15: =+F15*I15 -> 1317792 | M15: =+F15*J15 -> 0 | N15: =+F15*K15 -> 1317792
A16: 4.07 | B16: Cordón de hormigón en umbrales carpinterías | C16: ml | D16: 81 | E16: 30989 | F16: =+D16*E16 -> 2510109 | I16: =+'SVD 4140_Pto. 01_Cert. 06'!K16 -> 0.75 | J16: 0.15 | K16: =+I16+J16 -> 0.9 | L16: =+F16*I16 -> 1882581.8 | M16: =+F16*J16 -> 376516.35 | N16: =+F16*K16 -> 2259098.1
A17: 4.08 | B17: Pozo de bombeo pluvial y cloacal | C17: gl | D17: 1 | E17: 1119953 | F17: =+D17*E17 -> 1119953 | I17: =+'SVD 4140_Pto. 01_Cert. 06'!K17 -> 0.5 | K17: =+I17+J17 -> 0.5 | L17: =+F17*I17 -> 559976.5 | M17: =+F17*J17 -> 0 | N17: =+F17*K17 -> 559976.5
A18: 5 | B18: AISLACIONES | G18: =+SUM(F19:F25) -> 35966419 | H18: =+G18/$G$185 -> 0.048890193
A19: 5.01 | B19: Aislación hidrófuga horizontal (baños) - Inc. membrana geotextil y 35% en concepto de babetas | C19: m2 | D19: 139.05 | E19: 21800 | F19: =+D19*E19 -> 3031290 | I19: =+'SVD 4140_Pto. 01_Cert. 06'!K19 -> 0 | K19: =+I19+J19 -> 0 | L19: =+F19*I19 -> 0 | M19: =+F19*J19 -> 0 | N19: =+F19*K19 -> 0
A20: 5.02 | B20: Azotado hidrofugo - Sobre medianeras existentes | C20: m2 | D20: 300 | E20: 5376 | F20: =+D20*E20 -> 1612800 | I20: =+'SVD 4140_Pto. 01_Cert. 06'!K20 -> 0.5 | J20: 0.25 | K20: =+I20+J20 -> 0.75 | L20: =+F20*I20 -> 806400 | M20: =+F20*J20 -> 403200 | N20: =+F20*K20 -> 1209600
A21: 5.03 | B21: Azotado hidrofugo - Contrapiso de vereda | C21: m2 | D21: 48 | E21: 5376 | F21: =+D21*E21 -> 258048 | I21: =+'SVD 4140_Pto. 01_Cert. 06'!K21 -> 0 | K21: =+I21+J21 -> 0 | L21: =+F21*I21 -> 0 | M21: =+F21*J21 -> 0 | N21: =+F21*K21 -> 0
A22: 5.04 | B22: Aislación térmica en terrazas, eps e:2,00 cm | C22: m2 | D22: 262 | E22: 4403 | F22: =+D22*E22 -> 1153586 | I22: =+'SVD 4140_Pto. 01_Cert. 06'!K22 -> 0 | K22: =+I22+J22 -> 0 | L22: =+F22*I22 -> 0 | M22: =+F22*J22 -> 0 | N22: =+F22*K22 -> 0
A23: 5.05 | B23: Barrera de vapor | C23: m2 | D23: 510 | E23: 3578 | F23: =+D23*E23 -> 1824780 | I23: =+'SVD 4140_Pto. 01_Cert. 06'!K23 -> 0 | K23: =+I23+J23 -> 0 | L23: =+F23*I23 -> 0 | M23: =+F23*J23 -> 0 | N23: =+F23*K23 -> 0
A24: 5.06 | B24: Membrana asfaltica geotextil 4mm - Balcones y azotea - Inc. 20% en concepto de babetas | C24: m2 | D24: 510 | E24: 21800 | F24: =+D24*E24 -> 11118000 | I24: =+'SVD 4140_Pto. 01_Cert. 06'!K24 -> 0 | K24: =+I24+J24 -> 0 | L24: =+F24*I24 -> 0 | M24: =+F24*J24 -> 0 | N24: =+F24*K24 -> 0
A25: 5.07 | B25: Impermeabilización de subsuelo | C25: gl | D25: 1 | E25: 16967915 | F25: =+D25*E25 -> 16967915 | I25: =+'SVD 4140_Pto. 01_Cert. 06'!K25 -> 1 | K25: =+I25+J25 -> 1 | L25: =+F25*I25 -> 16967915 | M25: =+F25*J25 -> 0 | N25: =+F25*K25 -> 16967915
A26: 6 | B26: CUBIERTAS | G26: =+SUM(F27) -> 2433900 | H26: =+G26/$G$185 -> 0.0033084706
A27: 6.02 | B27: Babeta de chapa galvanizada en medianeras | C27: ml | D27: 60 | E27: 40565 | F27: =+D27*E27 -> 2433900 | I27: =+'SVD 4140_Pto. 01_Cert. 06'!K27 -> 0 | K27: =+I27+J27 -> 0 | L27: =+F27*I27 -> 0 | M27: =+F27*J27 -> 0 | N27: =+F27*K27 -> 0
A28: 7 | B28: REVOQUES | G28: =+SUM(F29:F36) -> 1.3639056e+08 | H28: =+G28/$G$185 -> 0.18539962
A29: 7.01 | B29: Revoque Grueso Impermeable Exterior proyectable | C29: m2 | D29: 678.252 | E29: 16571 | F29: =+D29*E29 -> 11239314 | I29: =+'SVD 4140_Pto. 01_Cert. 06'!K29 -> 0 | J29: 0.05 | K29: =+I29+J29 -> 0.05 | L29: =+F29*I29 -> 0 | M29: =+F29*J29 -> 561965.69 | N29: =+F29*K29 -> 561965.69
A30: 7.02 | B30: Revoque Grueso Impermeable Exterior a mas de 3m proyectable - Medianero y fachadas | C30: m2 | D30: 876.0812 | E30: 22183 | F30: =+D30*E30 -> 19434109 | I30: =+'SVD 4140_Pto. 01_Cert. 06'!K30 -> 0 | J30: 0.5 | K30: =+I30+J30 -> 0.5 | L30: =+F30*I30 -> 0 | M30: =+F30*J30 -> 9717054.6 | N30: =+F30*K30 -> 9717054.6
A31: 7.03 | B31: Buña en revoque | C31: ml | D31: 182 | E31: 10806 | F31: =+D31*E31 -> 1966692 | I31: =+'SVD 4140_Pto. 01_Cert. 06'!K31 -> 0 | J31: 0.5 | K31: =+I31+J31 -> 0.5 | L31: =+F31*I31 -> 0 | M31: =+F31*J31 -> 983346 | N31: =+F31*K31 -> 983346
A32: 7.04 | B32: Revoque Grueso Interior + fino | C32: m2 | D32: 995.8511 | E32: 26530 | F32: =+D32*E32 -> 26419930 | I32: =+'SVD 4140_Pto. 01_Cert. 06'!K32 -> 0.45 | K32: =+I32+J32 -> 0.45 | L32: =+F32*I32 -> 11888968 | M32: =+F32*J32 -> 0 | N32: =+F32*K32 -> 11888968
A33: 7.05 | B33: Yeso interior | C33: m2 | D33: 2514.897 | E33: 22566 | F33: =+D33*E33 -> 56751166 | I33: =+'SVD 4140_Pto. 01_Cert. 06'!K33 -> 0.05 | J33: 0.15 | K33: =+I33+J33 -> 0.2 | L33: =+F33*I33 -> 2837558.3 | M33: =+F33*J33 -> 8512674.9 | N33: =+F33*K33 -> 11350233
A34: 7.06 | B34: Arista en yeso | C34: ml | D34: 509.9 | E34: 12771 | F34: =+D34*E34 -> 6511932.9 | I34: =+'SVD 4140_Pto. 01_Cert. 06'!K34 -> 0.05 | J34: 0.15 | K34: =+I34+J34 -> 0.2 | L34: =+F34*I34 -> 325596.65 | M34: =+F34*J34 -> 976789.93 | N34: =+F34*K34 -> 1302386.6
A35: 7.07 | B35: Provisión y colocación de guardacanto yesero | C35: u | D35: 198 | E35: 14947 | F35: =+D35*E35 -> 2959506 | I35: =+'SVD 4140_Pto. 01_Cert. 06'!K35 -> 0 | J35: 0.15 | K35: =+I35+J35 -> 0.15 | L35: =+F35*I35 -> 0 | M35: =+F35*J35 -> 443925.9 | N35: =+F35*K35 -> 443925.9
A36: 7.08 | B36: Revoque Grueso Impermeable Interior b/ revestimiento | C36: m2 | D36: 670.322 | E36: 16571 | F36: =+D36*E36 -> 11107906 | I36: =+'SVD 4140_Pto. 01_Cert. 06'!K36 -> 0 | J36: 0.15 | K36: =+I36+J36 -> 0.15 | L36: =+F36*I36 -> 0 | M36: =+F36*J36 -> 1666185.9 | N36: =+F36*K36 -> 1666185.9
A37: 8 | B37: CONTRAPISOS Y CARPETAS | G37: =+SUM(F38:F45) -> 44788107 | H37: =+G37/$G$185 -> 0.060881768
A38: 8.01 | B38: Contrapiso de cascotes en SS e: 15 cm | C38: m2 | D38: 104 | E38: 31920 | F38: =+D38*E38 -> 3319680 | I38: =+'SVD 4140_Pto. 01_Cert. 06'!K38 -> 1 | K38: =+I38+J38 -> 1 | L38: =+F38*I38 -> 3319680 | M38: =+F38*J38 -> 0 | N38: =+F38*K38 -> 3319680
A39: 8.02 | B39: Contrapiso de cascote s/terreno natural e: 20 cm - Incluye film de polietileno | C39: m2 | D39: 48 | E39: 37268 | F39: =+D39*E39 -> 1788864 | I39: =+'SVD 4140_Pto. 01_Cert. 06'!K39 -> 0 | K39: =+I39+J39 -> 0 | L39: =+F39*I39 -> 0 | M39: =+F39*J39 -> 0 | N39: =+F39*K39 -> 0
