Workbook

Sheet CONFIG
A1: CONFIGURACIÓN DEL APU
A3: Parámetro | B3: Valor | C3: Notas
A4: Mes de referencia | B4: Junio | C4: Mes de precios del APU
A5: Año de referencia | B5: 2025
A6: Versión | B6: v3.0 — APU Chivilcoy 06-25
A7: GG% | B7: 0 | C7: 0 = se aplica en presupuesto de obra
A8: BB% | B8: 0
A9: Tipo Cambio USD (MEP) | B9: 1200 | C9: Pesos por dólar
A10: Revisado por | B10: MC
A11: Mes base CAC | B11: Junio 2025
A12: CAC base (valor) | B12: 16000 | C12: Referencial
A14: TABLA DE CARGAS MO
A15: Componente | B15: Tipo | C15: Valor | D15: Fuente
A16: Cargas patronales | B16: % | C16: 0.42 | D16: Convenio UOCRA (est.)
A17: ART | B17: % | C17: 0.085 | D17: Aseguradora (est.)
A18: Ropa de trabajo | B18: $/mes | C18: 85000 | D18: Compras (est.)
A19: Viáticos | B19: $/día | C19: 3200 | D19: Convenio UOCRA (est.)
A20: Vacaciones + SAC | B20: % | C20: 0.15 | D20: Cálculo legal (est.)
A22: COEFICIENTE FINAL | B22: multiplicador | C22: =1+C16+C17+C20+(C18/78291/22)+(C19/78291) -> 1.7452228
A24: Última corrección | B24: 2026-05-14
A25: Hallazgos aplicados | B25: H-002, H-003, H-004, H-005, H-006, H-007 (v3.1)
A26: Hallazgos pendientes | B26: H-001, H-008, H-009, H-010, H-011

Sheet MATERIALES
A1: Código | B1: Descripción | C1: Unidad | D1: Precio $ | E1: Proveedor | F1: Fecha Cotiz. | G1: Categoría | H1: Cód. Original | I1: Nota
A2: ACE-001 | B2: Barra de Acero Aleteado - 6mm x 12m | D2: 3620.13 | G2: Corralón
A3: ACE-016 | B3: ACERO ESTRUCTURAL POR KILO | D3: 1338.79 | G3: Corralón
A4: AGR-001 | B4: ARENA LAVADA | D4: 32620.38 | G4: Corralón
A5: AGR-004 | B5: Cemento Portland x 50kg | D5: 7891.74 | G5: Corralón
A6: AGR-005 | B6: Cal Comun x 25kg | D6: 3927.28 | G6: Corralón
A7: AIS-001 | B7: Aditivo Hidrofugo en pasta - Ceresita x 1kg | D7: 1363.95 | G7: Impermeabilizantes
A8: CER-005 | B8: Ladrillo Comun 12.5 x 5.5 x 25 | D8: 148.05 | G8: Corralón
A9: ACE-015 | B9: CLAVOS DE 21/2" X 12 | D9: 2647.2225 | G9: Corralón
A10: ACE-010 | B10: Alambre de fardo | D10: 2660.68 | G10: Corralón
A11: OTR-031 | B11: FENOLICO 18MM. COMUN 1.22 x 2.40 | D11: 20401.25 | G11: Corralón
A12: OTR-033 | B12: tirante 3x3 para puntal 3.66 | D12: 1270.4832 | G12: Corralón
A13: OTR-034 | B13: tirante 3x6 3.66 | D13: 4649.9685 | G13: Corralón
A14: MAT-CONS | B14: CONSUMIBLES (varios) | C14: gl | D14: 1 | G14: Consumibles
A15: OTR-032 | B15: FENOLICO 18MM. LAMINADO MELAMINICO | D15: 49748.25 | G15: Corralón
A16: CER-002 | B16: LADRILLO CERAMICO 8 x 18 x 33 cm | D16: 506.52 | G16: Corralón
A17: CER-003 | B17: LADRILLO CERAMICO 12 x 18 x 33 cm | D17: 624.96 | G17: Corralón
A18: CER-004 | B18: LADRILLO CERAMICO 18 x 18 x 33 cm | D18: 894.6 | G18: Corralón
A19: CER-006 | B19: Ladrillo hueco ceramico 12x19x33 - Portante | D19: 977.76 | G19: Corralón
A20: PIN-008 | B20: Pintura Asfaltica Asfasol x18ts | D20: 35525.95 | G20: Pinturas
A21: ELE-001 | B21: Recuplast Tradicional Blanco x 20 lts | D21: 106809.92 | G21: Eléctricos
A22: PIN-001 | B22: Latex Loxon Interior Sherwin Williams Mate Bco x 20lts | D22: 143389.26 | G22: Pinturas
A23: PIN-007 | B23: Enduido Interior x 20lts | D23: 41314.05 | G23: Pinturas
A24: OTR-023 | B24: Lija 180 al agua x 10u | D24: 7917.3554 | G24: Pinturas
A25: OTR-024 | B25: Cinta de Papel 36 mm x 40m | D25: 5885.9504 | G25: Pinturas
A26: OTR-025 | B26: Trapo | D26: 1182.6446 | G26: Pinturas
... A29: OTR-022 | B29: Aguarras Hydrarras Hydra x 18lts | D29: 58016.529 | G29: Pinturas
A30: OTR-PTO002 | B30: Chapa acanalada C25 | C30: u | D30: 10861.769 | G30: Carpintería metálica
A31: OTR-PTO003 | B31: Perfiles UPN 100 | C31: u | D31: 271144.89 | G31: Carpintería metálica
A32: OTR-PTO004 | B32: Bastidor para porton corredizo - Perfil 40 x 40 x 2 | C32: u | D32: 23523.752 | G32: Carpintería metálica
A33: OTR-PTO005 | B33: Riel Roma 174 e: 2,1 mm. 53 x 60 x 6000 | C33: u | D33: 85391.38 | G33: Carpintería metálica
A34: OTR-PTO006 | B34: Carro acero 174 4 ruedas puertas portones Ø45mm | C34: u | D34: 11534.744 | G34: Carpintería metálica
A35: OTR-PTO007 | B35: Autoperforantes punta mecha 14 x 2 | C35: u | D35: 120 | G35: Ferretería
A36: OTR-PTO008 | B36: Rollo Concertina | C36: u | D36: 41322.314 | G36: Carpintería metálica
A37: OTR-PTO9000 | B37: Puntales 3 x 3 x 3,7 | C37: u | D37: 4992.1647 | G37: Encofrados
A38: OTR-PTO009 | B38: Chapa acanalada C25 - Reutilizado (estimado 3 usos) | C38: u | D38: 5430.8843 | G38: Encofrados
A39: OTR-PTO010 | B39: Fenolico 1,22 x 2,44 - Reutilizado (estimado 3 usos) | C39: u | D39: 13196.9 | G39: Encofrados
A40: OTR-PTO011 | B40: Puntales 1 x 4 x 3,7 - Reutilizado (estimado 3 usos) | C40: u | D40: 1109.369 | G40: Encofrados
A41: OTR-PTO012 | B41: Puntales 3 x 3 x 3,7 - Reutilizado (estimado 3 usos) | C41: u | D41: 2496.0823 | G41: Encofrados
... A187: OTR-PTO159 | B187: ELECT — Módulo completo TV/RED marca Cambre línea SXX | C187: u | D187: 2203.1709 | G187: Eléctricos
...

Sheet EQUIPOS
A1: Código | B1: Descripción | C1: Costo Total $ | D1: Vida (años) | E1: Vida (días) | F1: $/día | G1: Categoría
A2: EQ-ESCALE | B2: ESCALERA GLOSS ALUMINIO ARTICULADA 4 X 4 ESCALONES HASTA 150KG | C2: 219427.59 | D2: 4 | E2: =D2*360 -> 1440 | F2: =IF(E2=0,0,C2/E2) -> 152.38027 | G2: Equipo propio
A3: EQ-ANDAM0 | B3: ANDAMIO TUBULAR DE UNO A TRES CUERPOS | C3: 1117459.4 | D3: 5 | E3: =D3*360 -> 1800 | F3: =IF(E3=0,0,C3/E3) -> 620.81078 | G3: Equipo propio
A4: EQ-BALANC | B4: Balancin | C4: 12170160 | D4: 10 | E4: =D4*360 -> 3600 | F4: =IF(E4=0,0,C4/E4) -> 3380.6 | G4: Equipo propio
A5: EQ-CORTA | B5: CORTADORA CERAMICA PROFESIONAL 1200MM (PORCELANATO HASTA 16MM) | C5: 583838.42 | D5: 5 | E5: =D5*360 -> 1800 | F5: =IF(E5=0,0,C5/E5) -> 324.35468 | G5: Equipo propio
A6: EQ-EQALBA | B6: EQUIPO DE ALBAÑILERIA, carpetas, ladrillo | C6: 2684740.7 | D6: 3 | E6: =D6*360 -> 1080 | F6: =IF(E6=0,0,C6/E6) -> 2485.871 | G6: Equipo propio
A7: EQ-EQCERA | B7: EQUIPO PARA COLOCACION DE CERAMICA | C7: 1547796.6 | D7: 1.5 | E7: =D7*360 -> 540 | F7: =IF(E7=0,0,C7/E7) -> 2866.29 | G7: Equipo propio
A8: EQ-EQPLOM | B8: EQUIPO PARA PLOMERIA | C8: 2237101.1 | D8: 2 | E8: =D8*360 -> 720 | F8: =IF(E8=0,0,C8/E8) -> 3107.0849 | G8: Equipo propio
A9: EQ-EQUIP0 | B9: EQUIPO PARA INSTALACION ELECTRICA | C9: 2971641.8 | D9: 1.5 | E9: =D9*360 -> 540 | F9: =IF(E9=0,0,C9/E9) -> 5503.0404 | G9: Equipo propio
A10: EQ-EQUIPI | B10: EQUIPO PARA PINTAR | C10: 1348845.4 | D10: 2 | E10: =D10*360 -> 720 | F10: =IF(E10=0,0,C10/E10) -> 1873.3964 | G10: Equipo propio
A11: EQ-HORMI | B11: EQUIPO PARA HORMIGON | C11: 4064822.7 | D11: 1.5 | E11: =D11*360 -> 540 | F11: =IF(E11=0,0,C11/E11) -> 7527.4494 | G11: Equipo propio
A12: EQ-PTO001 | B12: Herramientas — Topógrafo - Visita de obra replanteo | C12: 4599.5184 | D12: 1 | E12: 1 | F12: =IF(E12=0,0,C12/E12) -> 4599.5184 | G12: Herramientas — Preliminares
A13: EQ-PTO002 | B13: Herramientas — Cerco de obra perimetral - En chapa C25 | C13: 3162.1221 | D13: 1 | E13: 1 | F13: =IF(E13=0,0,C13/E13) -> 3162.1221 | G13: Herramientas — Preliminares
A14: EQ-PTO003 | B14: Herramientas — Obrador, pañol y ducha | C14: 128918.42 | D14: 1 | E14: 1 | F14: =IF(E14=0,0,C14/E14) -> 128918.42 | G14: Herramientas — Preliminares
A15: EQ-PTO004 | B15: Herramientas — Conexión pilar y luz de obra + Tablero d | C15: 30769.28 | D15: 1 | E15: 1 | F15: =IF(E15=0,0,C15/E15) -> 30769.28 | G15: Herramientas — Preliminares
A16: EQ-PTO005 | B16: Herramientas — Conexión agua de obra, tanque + bomba | C16: 22085.534 | D16: 1 | E16: 1 | F16: =IF(E16=0,0,C16/E16) -> 22085.534 | G16: Herramientas — Preliminares
A17: EQ-PTO006 | B17: Herramientas — Excavación para cámara transformadora | C17: 467.46075 | D17: 1 | E17: 1 | F17: =IF(E17=0,0,C17/E17) -> 467.46075 | G17: Herramientas — Preliminares
A18: EQ-PTO007 | B18: Herramientas — Hormigón de limpieza - e: 10 cm | C18: 4132.0683 | D18: 1 | E18: 1 | F18: =IF(E18=0,0,C18/E18) -> 4132.0683 | G18: Herramientas — Hormigón
A19: EQ-PTO008 | B19: Herramientas — Micropilotes Ø 20 cm | C19: 718505.14 | D19: 1 | E19: 1 | F19: =IF(E19=0,0,C19/E19) -> 718505.14 | G19: Herramientas — Hormigón
A20: EQ-PTO009 | B20: Herramientas — Platea - H30 (110 kg/m3 de hierro) | C20: 8701.1119 | D20: 1 | E20: 1 | F20: =IF(E20=0,0,C20/E20) -> 8701.1119 | G20: Herramientas — Hormigón
A21: EQ-PTO010 | B21: Herramientas — Zapata corrida tabique - H30 (180 kg/m3 | C21: 12913.459 | D21: 1 | E21: 1 | F21: =IF(E21=0,0,C21/E21) -> 12913.459 | G21: Herramientas — Hormigón
A22: EQ-PTO011 | B22: Herramientas — Bases aisladas - H30 (110 kg/m3 de hierr | C22: 8701.1119 | D22: 1 | E22: 1 | F22: =IF(E22=0,0,C22/E22) -> 8701.1119 | G22: Herramientas — Hormigón
A23: EQ-PTO012 | B23: Herramientas — Cabezales - H30 (130 kg/m3 de hierro) | C23: 9232.7119 | D23: 1 | E23: 1 | F23: =IF(E23=0,0,C23/E23) -> 9232.7119 | G23: Herramientas — Hormigón
... A97: EQ-PTO086 | B97: Herramientas — Volquetes | C97: 4008.6075 | D97: 1 | E97: 1 | F97: =IF(E97=0,0,C97/E97) -> 4008.6075 | G97: Herramientas — Instalaciones
A98: EQ-SILLET | B98: Kit Complementario Silleta Descensor Conector Soga X 50 Mts | C98: 743114.75 | D98: 1 | E98: =D98*360 -> 360 | F98: =IF(E98=0,0,C98/E98) -> 2064.2076 | G98: Equipo propio
A99: EQ-SOLD00 | B99: Soldador Soplete A Gas Techista Membrana 10 Kg Boca 50mm | C99: 629576.14 | D99: 2 | E99: =D99*360 -> 720 | F99: =IF(E99=0,0,C99/E99) -> 874.41131 | G99: Equipo propio
A100: EQ-TROMPO | B100: Hormigonera De 150 Litros 1hp Con Rueda Maciza | C100: 749110.64 | D100: 2 | E100: =D100*360 -> 720 | F100: =IF(E100=0,0,C100/E100) -> 1040.4314 | G100: Equipo propio
A101: EQ-PTO026 | B101: Escalera madera pintor 8 escalones | C101: 78355.295 | D101: 1 | E101: =D101*360 -> 360 | F101: =IF(E101=0,0,C101/E101) -> 217.6536 | G101: Equipo propio
A102: EQ-PTO087 | B102: Equipos viales — Pala/retro 310J + Camión volcador 170E22 + Compactador pata cabra 612H | C102: 1005000 | D102: 0.0027777778 | E102: =D102*360 -> 1 | F102: =IF(E102=0,0,C102/E102) -> 1005000 | G102: Alquiler diario
A103: EQ-PTO024 | B103: EQUIPO DE CONSTRUCCION EN SECO | C103: 1850947.1 | D103: 2 | E103: =D103*360 -> 720 | F103: =IF(E103=0,0,C103/E103) -> 2570.7599 | G103: Equipo propio
A104: EQ-REVOC | B104: Máquina revocadora Yeso/Revoque 3-en-1 | C104: 1230000 | D104: 0.083333333 | E104: =D104*360 -> 30 | F104: =IF(E104=0,0,C104/E104) -> 41000 | G104: Equipo propio

Sheet SUBCONTRATOS_PRY
A1: Código | B1: Descripción | C1: Ud | D1: Precio Unitario ($) | E1: Categoría | F1: Notas
A2: SUB-PTO001 | B2: M.Obra topografo | C2: d | D2: 214394.06 | E2: Varios
A3: SUB-PTO002 | B3: Flete madera | C3: u | D3: 250000 | E3: Varios
A4: SUB-PTO003 | B4: Alquiler de baños quimico | C4: mes | D4: 80000 | E4: Varios
A5: SUB-PTO004 | B5: Limpieza adicional | C5: mes | D5: 80000 | E5: Varios
A6: SUB-PTO005 | B6: Alquiler de modulo de ducha | C6: mes | D6: 80000 | E6: Varios
A7: SUB-PTO006 | B7: Fletes de entrega y retiro | C7: u | D7: 20000 | E7: Varios
A8: SUB-PTO007 | B8: Gestion suministro luz de obra | C8: u | D8: 157327.46 | E8: Electricidad — Gestión
A9: SUB-PTO008 | B9: Luz de Obra | C9: u | D9: 113275.77 | E9: Electricidad — Gestión
A10: SUB-PTO009 | B10: Medicion PAT luz de obra | C10: u | D10: 99116.3 | E10: Electricidad — Gestión
A11: SUB-PTO010 | B11: Desmonte y aporte de tosca | C11: m2 | D11: 23552.222 | E11: Movimiento de suelos
A12: SUB-PTO011 | B12: Maquina 6 tn | C12: d | D12: 528000 | E12: Movimiento de suelos
A13: SUB-PTO012 | B13: Viajes camión | C13: u | D13: 140000 | E13: Movimiento de suelos
... A93: SUB-PTO093 | B93: Gestor Gas — Final | C93: gl | D93: 400000 | E93: Gas
A94: SUB-PTO094 | B94: MO — Zócalo de concreto en escalera | C94: ml | D94: =4324.04776527307*28 -> 121073.34 | E94: Revestimientos y yesos
A95: SUB-PTO095 | B95: MO — Revestimiento plástico a llana tipo Quimtex en altura - Aire luz y balcones | C95: m2 | D95: 4940.3619 | E95: Revestimientos y yesos

Sheet MANO_DE_OBRA
A1: Código | B1: Descripción | C1: Salario/día $ | D1: Coef. Cargas | E1: Costo Jornal $ | F1: Tipo | G1: Cód. Original
A2: MO-EAYUD | B2: AYUDANTE | C2: 67240.499 | D2: =CONFIG!C22 -> 1.7452228 | E2: =C2*D2 -> 117349.65 | F2: Operativo
A3: MO-EMEDI | B3: MEDIO OFICIAL | C3: 72132.138 | D3: =CONFIG!C22 -> 1.7452228 | E3: =C3*D3 -> 125886.66 | F3: Operativo
A4: MO-EOFIC | B4: OFICIAL | C4: 84612.513 | D4: =CONFIG!C22 -> 1.7452228 | E4: =C4*D4 -> 147667.69 | F4: Operativo
A5: MO-EESPE | B5: ESPECIALIZADO | C5: 94177.138 | D5: =CONFIG!C22 -> 1.7452228 | E5: =C5*D5 -> 164360.09 | F5: Operativo
A6: MO-ESOBR | B6: SOBRESTANTE | C6: 147568.59 | D6: =CONFIG!C22 -> 1.7452228 | E6: =C6*D6 -> 257540.07 | F6: Gerencial
A7: MO-ECAPA | B7: CAPATAZ | C7: 161430.42 | D7: =CONFIG!C22 -> 1.7452228 | E7: =C7*D7 -> 281732.06 | F7: Gerencial
A8: MO-TOP | B8: TOPOGRAFO | C8: 188354.28 | D8: =CONFIG!C22 -> 1.7452228 | E8: =C8*D8 -> 328720.18 | F8: Operativo
A9: MO-EJEFE | B9: JEFE DE OBRA | C9: 214394.06 | D9: =CONFIG!C22 -> 1.7452228 | E9: =C9*D9 -> 374165.41 | F9: Gerencial
A10: MO-ECOOR | B10: COORD OBRAS | C10: 258581.93 | D10: =CONFIG!C22 -> 1.7452228 | E10: =C10*D10 -> 451283.09 | F10: Gerencial
A11: MO-ALBVHV | B11: MO Albañilería complementaria — Viga H°V (25% MO H°A°) | C11: 157396.09 | D11: =CONFIG!C22 -> 1.7452228 | E11: =C11*D11 -> 274691.25 | F11: Operativo
A12: MO-ALBLHV | B12: MO Albañilería complementaria — Losa H°V (25% MO H°A°) | C12: 63408.113 | D12: =CONFIG!C22 -> 1.7452228 | E12: =C12*D12 -> 110661.29 | F12: Operativo

Sheet COMPOSICIÓN
A1: Partida | B1: Tipo | C1: Subtipo | D1: Cod_Insumo | E1: Descripción | F1: Unidad de medida | G1: Cant | H1: %Desp | I1: Precio | J1: Costo | K1: Clave | L1: Count | M1: Clave2 | N1: Rend. Part. | O1: Cant MO/ALB Unit | P1: Cant. Ej. Part. | Q1: Cant MO/ALB Total | R1: en PPTO?
A2: APU-101 | B2: MO | C2: ALB | D2: MO-EESPE | E2: =IFERROR(VLOOKUP(D2,MANO_DE_OBRA!A:B,2,FALSE()),"?") -> ESPECIALIZADO | F2: j | G2: 1 | H2: 0 | I2: =IFERROR(VLOOKUP(D2,MANO_DE_OBRA!A:C,3,FALSE()),0) -> 94177.138 | J2: =G2*I2 -> 94177.138 | K2: =A2&"|"&B2 -> APU-101|MO | L2: =COUNTIFS($K$2:K2,K2) -> 1 | M2: =K2&"|"&L2 -> APU-101|MO|1 | N2: =IFERROR(VLOOKUP(A2,PARTIDAS!A:F,6,FALSE()),0) -> 1 | O2: =+IF(C2="ALB",G2/N2,0) -> 1 | P2: =+_xlfn.XLOOKUP(A2,PPTO_GENERADOR!Q:Q,PPTO_GENERADOR!E:E,"-",0) -> - | Q2: =IFERROR(P2*O2,0) -> 0 | R2: =+_xlfn.XLOOKUP(A2,PPTO_GENERADOR!$Q:$Q,PPTO_GENERADOR!A:A,"-",0) -> -
A3: APU-101 | B3: MO | C3: ALB | D3: MO-EAYUD | E3: =IFERROR(VLOOKUP(D3,MANO_DE_OBRA!A:B,2,FALSE()),"?") -> AYUDANTE | F3: j | G3: 1 | H3: 0 | I3: =IFERROR(VLOOKUP(D3,MANO_DE_OBRA!A:C,3,FALSE()),0) -> 67240.499 | J3: =G3*I3 -> 67240.499 | K3: =A3&"|"&B3 -> APU-101|MO | L3: =COUNTIFS($K$2:K3,K3) -> 2 | M3: =K3&"|"&L3 -> APU-101|MO|2 | N3: =IFERROR(VLOOKUP(A3,PARTIDAS!A:F,6,FALSE()),0) -> 1 | O3: =+IF(C3="ALB",G3/N3,0) -> 1 | P3: =+_xlfn.XLOOKUP(A3,PPTO_GENERADOR!Q:Q,PPTO_GENERADOR!E:E,"-",0) -> - | Q3: =IFERROR(P3*O3,0) -> 0 | R3: =+_xlfn.XLOOKUP(A3,PPTO_GENERADOR!$Q:$Q,PPTO_GENERADOR!A:A,"-",0) -> -
A4: BAN-106 | B4: MO | C4: ALB | D4: MO-EESPE | E4: =IFERROR(VLOOKUP(D4,MANO_DE_OBRA!A:B,2,FALSE()),"?") -> ESPECIALIZADO | F4: j | G4: 1 | H4: 0 | I4: =IFERROR(VLOOKUP(D4,MANO_DE_OBRA!A:C,3,FALSE()),0) -> 94177.138 | J4: =G4*I4 -> 94177.138 | K4: =A4&"|"&B4 -> BAN-106|MO | L4: =COUNTIFS($K$2:K4,K4) -> 1 | M4: =K4&"|"&L4 -> BAN-106|MO|1 | N4: =IFERROR(VLOOKUP(A4,PARTIDAS!A:F,6,FALSE()),0) -> 3.8 | O4: =+IF(C4="ALB",G4/N4,0) -> 0.26315789 | P4: =+_xlfn.XLOOKUP(A4,PPTO_GENERADOR!Q:Q,PPTO_GENERADOR!E:E,"-",0) -> - | Q4: =IFERROR(P4*O4,0) -> 0 | R4: =+_xlfn.XLOOKUP(A4,PPTO_GENERADOR!$Q:$Q,PPTO_GENERADOR!A:A,"-",0) -> -
A5: BAN-106 | B5: MO | C5: ALB | D5: MO-EAYUD | E5: =IFERROR(VLOOKUP(D5,MANO_DE_OBRA!A:B,2,FALSE()),"?") -> AYUDANTE | F5: j | G5: 1 | H5: 0 | I5: =IFERROR(VLOOKUP(D5,MANO_DE_OBRA!A:C,3,FALSE()),0) -> 67240.499 | J5: =G5*I5 -> 67240.499 | K5: =A5&"|"&B5 -> BAN-106|MO | L5: =COUNTIFS($K$2:K5,K5) -> 2 | M5: =K5&"|"&L5 -> BAN-106|MO|2 | N5: =IFERROR(VLOOKUP(A5,PARTIDAS!A:F,6,FALSE()),0) -> 3.8 | O5: =+IF(C5="ALB",G5/N5,0) -> 0.26315789 | P5: =+_xlfn.XLOOKUP(A5,PPTO_GENERADOR!Q:Q,PPTO_GENERADOR!E:E,"-",0) -> - | Q5: =IFERROR(P5*O5,0) -> 0 | R5: =+_xlfn.XLOOKUP(A5,PPTO_GENERADOR!$Q:$Q,PPTO_GENERADOR!A:A,"-",0) -> -
A6: ALB-110 | B6: MO | C6: ALB | D6: MO-EESPE | E6: =IFERROR(VLOOKUP(D6,MANO_DE_OBRA!A:B,2,FALSE()),"?") -> ESPECIALIZADO | F6: j | G6: 1 | H6: 0 | I6: =IFERROR(VLOOKUP(D6,MANO_DE_OBRA!A:C,3,FALSE()),0) -> 94177.138 | J6: =G6*I6 -> 94177.138 | K6: =A6&"|"&B6 -> ALB-110|MO | L6: =COUNTIFS($K$2:K6,K6) -> 1 | M6: =K6&"|"&L6 -> ALB-110|MO|1 | N6: =IFERROR(VLOOKUP(A6,PARTIDAS!A:F,6,FALSE()),0) -> 36 | O6: =+IF(C6="ALB",G6/N6,0) -> 0.027777778 | P6: =+_xlfn.XLOOKUP(A6,PPTO_GENERADOR!Q:Q,PPTO_GENERADOR!E:E,"-",0) -> - | Q6: =IFERROR(P6*O6,0) -> 0 | R6: =+_xlfn.XLOOKUP(A6,PPTO_GENERADOR!$Q:$Q,PPTO_GENERADOR!A:A,"-",0) -> -
A7: ALB-110 | B7: MO | C7: ALB | D7: MO-EAYUD | E7: =IFERROR(VLOOKUP(D7,MANO_DE_OBRA!A:B,2,FALSE()),"?") -> AYUDANTE | F7: j | G7: 2 | H7: 0 | I7: =IFERROR(VLOOKUP(D7,MANO_DE_OBRA!A:C,3,FALSE()),0) -> 67240.499 | J7: =G7*I7 -> 134481 | K7: =A7&"|"&B7 -> ALB-110|MO | L7: =COUNTIFS($K$2:K7,K7) -> 2 | M7: =K7&"|"&L7 -> ALB-110|MO|2 | N7: =IFERROR(VLOOKUP(A7,PARTIDAS!A:F,6,FALSE()),0) -> 36 | O7: =+IF(C7="ALB",G7/N7,0) -> 0.055555556 | P7: =+_xlfn.XLOOKUP(A7,PPTO_GENERADOR!Q:Q,PPTO_GENERADOR!E:E,"-",0) -> - | Q7: =IFERROR(P7*O7,0) -> 0 | R7: =+_xlfn.XLOOKUP(A7,PPTO_GENERADOR!$Q:$Q,PPTO_GENERADOR!A:A,"-",0) -> -
A8: ALB-110 | B8: MO | C8: ALB | D8: MO-EMEDI | E8: =IFERROR(VLOOKUP(D8,MANO_DE_OBRA!A:B,2,FALSE()),"?") -> MEDIO OFICIAL | F8: j | G8: 5 | H8: 0 | I8: =IFERROR(VLOOKUP(D8,MANO_DE_OBRA!A:C,3,FALSE()),0) -> 72132.138 | J8: =G8*I8 -> 360660.69 | K8: =A8&"|"&B8 -> ALB-110|MO | L8: =COUNTIFS($K$2:K8,K8) -> 3 | M8: =K8&"|"&L8 -> ALB-110|MO|3 | N8: =IFERROR(VLOOKUP(A8,PARTIDAS!A:F,6,FALSE()),0) -> 36 | O8: =+IF(C8="ALB",G8/N8,0) -> 0.13888889 | P8: =+_xlfn.XLOOKUP(A8,PPTO_GENERADOR!Q:Q,PPTO_GENERADOR!E:E,"-",0) -> - | Q8: =IFERROR(P8*O8,0) -> 0 | R8: =+_xlfn.XLOOKUP(A8,PPTO_GENERADOR!$Q:$Q,PPTO_GENERADOR!A:A,"-",0) -> -
A9: AIS-113 | B9: MAT | C9: OTR | D9: PIN-008 | E9: =IFERROR(VLOOKUP(D9,MATERIALES!A:B,2,FALSE()),"?") -> Pintura Asfaltica Asfasol x18ts | F9: =IFERROR(VLOOKUP(D9,MATERIALES!A:C,3,FALSE()),"?") -> 0 | G9: 0.0278 | H9: 0.1 | I9: =IFERROR(VLOOKUP(D9,MATERIALES!A:D,4,FALSE()),0) -> 35525.95 | J9: =G9*I9*(1+H9) -> 1086.3836 | K9: =A9&"|"&B9 -> AIS-113|MAT | L9: =COUNTIFS($K$2:K9,K9) -> 1 | M9: =K9&"|"&L9 -> AIS-113|MAT|1 | N9: =IFERROR(VLOOKUP(A9,PARTIDAS!A:F,6,FALSE()),0) -> 80 | O9: =+IF(C9="ALB",G9/N9,0) -> 0 | P9: =+_xlfn.XLOOKUP(A9,PPTO_GENERADOR!Q:Q,PPTO_GENERADOR!E:E,"-",0) -> - | Q9: =IFERROR(P9*O9,0) -> 0 | R9: =+_xlfn.XLOOKUP(A9,PPTO_GENERADOR!$Q:$Q,PPTO_GENERADOR!A:A,"-",0) -> -
A10: AIS-113 | B10: MAT | C10: OTR | D10: OTR-027 | E10: =IFERROR(VLOOKUP(D10,MATERIALES!A:B,2,FALSE()),"?") -> Rodillo de lana pelo largo N°22 - El Galgo | F10: =IFERROR(VLOOKUP(D10,MATERIALES!A:C,3,FALSE()),"?") -> u | G10: 0.01 | H10: 0.05 | I10: =IFERROR(VLOOKUP(D10,MATERIALES!A:D,4,FALSE()),0) -> 6442.15 | J10: =G10*I10*(1+H10) -> 67.642575 | K10: =A10&"|"&B10 -> AIS-113|MAT | L10: =COUNTIFS($K$2:K10,K10) -> 2 | M10: =K10&"|"&L10 -> AIS-113|MAT|2 | N10: =IFERROR(VLOOKUP(A10,PARTIDAS!A:F,6,FALSE()),0) -> 80 | O10: =+IF(C10="ALB",G10/N10,0) -> 0 | P10: =+_xlfn.XLOOKUP(A10,PPTO_GENERADOR!Q:Q,PPTO_GENERADOR!E:E,"-",0) -> - | Q10: =IFERROR(P10*O10,0) -> 0 | R10: =+_xlfn.XLOOKUP(A10,PPTO_GENERADOR!$Q:$Q,PPTO_GENERADOR!A:A,"-",0) -> -
A11: AIS-113 | B11: MAT | C11: OTR | D11: OTR-028 | E11: =IFERROR(VLOOKUP(D11,MATERIALES!A:B,2,FALSE()),"?") -> Pincel N° 20 - El Galgo | F11: =IFERROR(VLOOKUP(D11,MATERIALES!A:C,3,FALSE()),"?") -> u | G11: 0.02 | H11: 0.05 | I11: =IFERROR(VLOOKUP(D11,MATERIALES!A:D,4,FALSE()),0) -> 4418.1818 | J11: =G11*I11*(1+H11) -> 92.781818 | K11: =A11&"|"&B11 -> AIS-113|MAT | L11: =COUNTIFS($K$2:K11,K11) -> 3 | M11: =K11&"|"&L11 -> AIS-113|MAT|3 | N11: =IFERROR(VLOOKUP(A11,PARTIDAS!A:F,6,FALSE()),0) -> 80 | O11: =+IF(C11="ALB",G11/N11,0) -> 0 | P11: =+_xlfn.XLOOKUP(A11,PPTO_GENERADOR!Q:Q,PPTO_GENERADOR!E:E,"-",0) -> - | Q11: =IFERROR(P11*O11,0) -> 0 | R11: =+_xlfn.XLOOKUP(A11,PPTO_GENERADOR!$Q:$Q,PPTO_GENERADOR!A:A,"-",0) -> -
A12: AIS-113 | B12: MAT | C12: OTR | D12: OTR-022 | E12: =IFERROR(VLOOKUP(D12,MATERIALES!A:B,2,FALSE()),"?") -> Aguarras Hydrarras Hydra x 18lts | F12: =IFERROR(VLOOKUP(D12,MATERIALES!A:C,3,FALSE()),"?") -> 0 | G12: 0.002 | H12: 0.05 | I12: =IFERROR(VLOOKUP(D12,MATERIALES!A:D,4,FALSE()),0) -> 58016.529 | J12: =G12*I12*(1+H12) -> 121.83471 | K12: =A12&"|"&B12 -> AIS-113|MAT | L12: =COUNTIFS($K$2:K12,K12) -> 4 | M12: =K12&"|"&L12 -> AIS-113|MAT|4 | N12: =IFERROR(VLOOKUP(A12,PARTIDAS!A:F,6,FALSE()),0) -> 80 | O12: =+IF(C12="ALB",G12/N12,0) -> 0 | P12: =+_xlfn.XLOOKUP(A12,PPTO_GENERADOR!Q:Q,PPTO_GENERADOR!E:E,"-",0) -> - | Q12: =IFERROR(P12*O12,0) -> 0 | R12: =+_xlfn.XLOOKUP(A12,PPTO_GENERADOR!$Q:$Q,PPTO_GENERADOR!A:A,"-",0) -> -
A13: AIS-113 | B13: MAT | C13: OTR | D13: OTR-025 | E13: =IFERROR(VLOOKUP(D13,MATERIALES!A:B,2,FALSE()),"?") -> Trapo | F13: =IFERROR(VLOOKUP(D13,MATERIALES!A:C,3,FALSE()),"?") -> 0 | G13: 0.02 | H13: 0.05 | I13: =IFERROR(VLOOKUP(D13,MATERIALES!A:D,4,FALSE()),0) -> 1182.6446 | J13: =G13*I13*(1+H13) -> 24.835537 | K13: =A13&"|"&B13 -> AIS-113|MAT | L13: =COUNTIFS($K$2:K13,K13) -> 5 | M13: =K13&"|"&L13 -> AIS-113|MAT|5 | N13: =IFERROR(VLOOKUP(A13,PARTIDAS!A:F,6,FALSE()),0) -> 80 | O13: =+IF(C13="ALB",G13/N13,0) -> 0 | P13: =+_xlfn.XLOOKUP(A13,PPTO_GENERADOR!Q:Q,PPTO_GENERADOR!E:E,"-",0) -> - | Q13: =IFERROR(P13*O13,0) -> 0 | R13: =+_xlfn.XLOOKUP(A13,PPTO_GENERADOR!$Q:$Q,PPTO_GENERADOR!A:A,"-",0) -> -
A14: AIS-113 | B14: EQ | D14: EQ-SOLD00 | E14: =IFERROR(VLOOKUP(D14,EQUIPOS!A:B,2,FALSE()),"?") -> Soldador Soplete A Gas Techista Membrana 10 Kg Boca 50mm | G14: 1 | H14: 0 | I14: =IFERROR(VLOOKUP(D14,EQUIPOS!A:F,6,FALSE()),0) -> 874.41131 | J14: =G14*I14 -> 874.41131 | K14: =A14&"|"&B14 -> AIS-113|EQ | L14: =COUNTIFS($K$2:K14,K14) -> 1 | M14: =K14&"|"&L14 -> AIS-113|EQ|1 | N14: =IFERROR(VLOOKUP(A14,PARTIDAS!A:F,6,FALSE()),0) -> 80 | O14: =+IF(C14="ALB",G14/N14,0) -> 0 | P14: =+_xlfn.XLOOKUP(A14,PPTO_GENERADOR!Q:Q,PPTO_GENERADOR!E:E,"-",0) -> - | Q14: =IFERROR(P14*O14,0) -> 0 | R14: =+_xlfn.XLOOKUP(A14,PPTO_GENERADOR!$Q:$Q,PPTO_GENERADOR!A:A,"-",0) -> -
A15: AIS-113 | B15: MO | C15: ALB | D15: MO-EAYUD | E15: =IFERROR(VLOOKUP(D15,MANO_DE_OBRA!A:B,2,FALSE()),"?") -> AYUDANTE | F15: j | G15: 1 | H15: 0 | I15: =IFERROR(VLOOKUP(D15,MANO_DE_OBRA!A:C,3,FALSE()),0) -> 67240.499 | J15: =G15*I15 -> 67240.499 | K15: =A15&"|"&B15 -> AIS-113|MO | L15: =COUNTIFS($K$2:K15,K15) -> 1 | M15: =K15&"|"&L15 -> AIS-113|MO|1 | N15: =IFERROR(VLOOKUP(A15,PARTIDAS!A:F,6,FALSE()),0) -> 80 | O15: =+IF(C15="ALB",G15/N15,0) -> 0.0125 | P15: =+_xlfn.XLOOKUP(A15,PPTO_GENERADOR!Q:Q,PPTO_GENERADOR!E:E,"-",0) -> - | Q15: =IFERROR(P15*O15,0) -> 0 | R15: =+_xlfn.XLOOKUP(A15,PPTO_GENERADOR!$Q:$Q,PPTO_GENERADOR!A:A,"-",0) -> -
A16: AIS-113 | B16: MO | C16: ALB | D16: MO-EESPE | E16: =IFERROR(VLOOKUP(D16,MANO_DE_OBRA!A:B,2,FALSE()),"?") -> ESPECIALIZADO | F16: j | G16: 1 | H16: 0 | I16: =IFERROR(VLOOKUP(D16,MANO_DE_OBRA!A:C,3,FALSE()),0) -> 94177.138 | J16: =G16*I16 -> 94177.138 | K16: =A16&"|"&B16 -> AIS-113|MO | L16: =COUNTIFS($K$2:K16,K16) -> 2 | M16: =K16&"|"&L16 -> AIS-113|MO|2 | N16: =IFERROR(VLOOKUP(A16,PARTIDAS!A:F,6,FALSE()),0) -> 80 | O16: =+IF(C16="ALB",G16/N16,0) -> 0.0125 | P16: =+_xlfn.XLOOKUP(A16,PPTO_GENERADOR!Q:Q,PPTO_GENERADOR!E:E,"-",0) -> - | Q16: =IFERROR(P16*O16,0) -> 0 | R16: =+_xlfn.XLOOKUP(A16,PPTO_GENERADOR!$Q:$Q,PPTO_GENERADOR!A:A,"-",0) -> -
A17: AIS-114 | B17: MAT | C17: OTR | D17: PIN-008 | E17: =IFERROR(VLOOKUP(D17,MATERIALES!A:B,2,FALSE()),"?") -> Pintura Asfaltica Asfasol x18ts | F17: =IFERROR(VLOOKUP(D17,MATERIALES!A:C,3,FALSE()),"?") -> 0 | G17: 0.015 | H17: 0.1 | I17: =IFERROR(VLOOKUP(D17,MATERIALES!A:D,4,FALSE()),0) -> 35525.95 | J17: =G17*I17*(1+H17) -> 586.17818 | K17: =A17&"|"&B17 -> AIS-114|MAT | L17: =COUNTIFS($K$2:K17,K17) -> 1 | M17: =K17&"|"&L17 -> AIS-114|MAT|1 | N17: =IFERROR(VLOOKUP(A17,PARTIDAS!A:F,6,FALSE()),0) -> 60 | O17: =+IF(C17="ALB",G17/N17,0) -> 0 | P17: =+_xlfn.XLOOKUP(A17,PPTO_GENERADOR!Q:Q,PPTO_GENERADOR!E:E,"-",0) -> - | Q17: =IFERROR(P17*O17,0) -> 0 | R17: =+_xlfn.XLOOKUP(A17,PPTO_GENERADOR!$Q:$Q,PPTO_GENERADOR!A:A,"-",0) -> -
A18: AIS-114 | B18: MAT | C18: OTR | D18: AIS-002 | E18: =IFERROR(VLOOKUP(D18,MATERIALES!A:B,2,FALSE()),"?") -> Membrana Geotextil Ormiflex 4mm - (35kg) x10m | F18: =IFERROR(VLOOKUP(D18,MATERIALES!A:C,3,FALSE()),"?") -> u | G18: 0.05 | H18: 0.1 | I18: =IFERROR(VLOOKUP(D18,MATERIALES!A:D,4,FALSE()),0) -> 57227.91 | J18: =G18*I18*(1+H18) -> 3147.5351 | K18: =A18&"|"&B18 -> AIS-114|MAT | L18: =COUNTIFS($K$2:K18,K18) -> 2 | M18: =K18&"|"&L18 -> AIS-114|MAT|2 | N18: =IFERROR(VLOOKUP(A18,PARTIDAS!A:F,6,FALSE()),0) -> 60 | O18: =+IF(C18="ALB",G18/N18,0) -> 0 | P18: =+_xlfn.XLOOKUP(A18,PPTO_GENERADOR!Q:Q,PPTO_GENERADOR!E:E,"-",0) -> - | Q18: =IFERROR(P18*O18,0) -> 0 | R18: =+_xlfn.XLOOKUP(A18,PPTO_GENERADOR!$Q:$Q,PPTO_GENERADOR!A:A,"-",0) -> -
A19: AIS-114 | B19: EQ | D19: EQ-SOLD00 | E19: =IFERROR(VLOOKUP(D19,EQUIPOS!A:B,2,FALSE()),"?") -> Soldador Soplete A Gas Techista Membrana 10 Kg Boca 50mm | G19: 1 | H19: 0 | I19: =IFERROR(VLOOKUP(D19,EQUIPOS!A:F,6,FALSE()),0) -> 874.41131 | J19: =G19*I19 -> 874.41131 | K19: =A19&"|"&B19 -> AIS-114|EQ | L19: =COUNTIFS($K$2:K19,K19) -> 1 | M19: =K19&"|"&L19 -> AIS-114|EQ|1 | N19: =IFERROR(VLOOKUP(A19,PARTIDAS!A:F,6,FALSE()),0) -> 60 | O19: =+IF(C19="ALB",G19/N19,0) -> 0 | P19: =+_xlfn.XLOOKUP(A19,PPTO_GENERADOR!Q:Q,PPTO_GENERADOR!E:E,"-",0) -> - | Q19: =IFERROR(P19*O19,0) -> 0 | R19: =+_xlfn.XLOOKUP(A19,PPTO_GENERADOR!$Q:$Q,PPTO_GENERADOR!A:A,"-",0) -> -
A20: AIS-114 | B20: MO | C20: ALB | D20: MO-EAYUD | E20: =IFERROR(VLOOKUP(D20,MANO_DE_OBRA!A:B,2,FALSE()),"?") -> AYUDANTE | F20: j | G20: 1 | H20: 0 | I20: =IFERROR(VLOOKUP(D20,MANO_DE_OBRA!A:C,3,FALSE()),0) -> 67240.499 | J20: =G20*I20 -> 67240.499 | K20: =A20&"|"&B20 -> AIS-114|MO | L20: =COUNTIFS($K$2:K20,K20) -> 1 | M20: =K20&"|"&L20 -> AIS-114|MO|1 | N20: =IFERROR(VLOOKUP(A20,PARTIDAS!A:F,6,FALSE()),0) -> 60 | O20: =+IF(C20="ALB",G20/N20,0) -> 0.016666667 | P20: =+_xlfn.XLOOKUP(A20,PPTO_GENERADOR!Q:Q,PPTO_GENERADOR!E:E,"-",0) -> - | Q20: =IFERROR(P20*O20,0) -> 0 | R20: =+_xlfn.XLOOKUP(A20,PPTO_GENERADOR!$Q:$Q,PPTO_GENERADOR!A:A,"-",0) -> -
A21: AIS-114 | B21: MO | C21: ALB | D21: MO-EESPE | E21: =IFERROR(VLOOKUP(D21,MANO_DE_OBRA!A:B,2,FALSE()),"?") -> ESPECIALIZADO | F21: j | G21: 1 | H21: 0 | I21: =IFERROR(VLOOKUP(D21,MANO_DE_OBRA!A:C,3,FALSE()),0) -> 94177.138 | J21: =G21*I21 -> 94177.138 | K21: =A21&"|"&B21 -> AIS-114|MO | L21: =COUNTIFS($K$2:K21,K21) -> 2 | M21: =K21&"|"&L21 -> AIS-114|MO|2 | N21: =IFERROR(VLOOKUP(A21,PARTIDAS!A:F,6,FALSE()),0) -> 60 | O21: =+IF(C21="ALB",G21/N21,0) -> 0.016666667 | P21: =+_xlfn.XLOOKUP(A21,PPTO_GENERADOR!Q:Q,PPTO_GENERADOR!E:E,"-",0) -> - | Q21: =IFERROR(P21*O21,0) -> 0 | R21: =+_xlfn.XLOOKUP(A21,PPTO_GENERADOR!$Q:$Q,PPTO_GENERADOR!A:A,"-",0) -> -
A22: REV-115 | B22: MAT | C22: OTR | D22: AGR-001 | E22: =IFERROR(VLOOKUP(D22,MATERIALES!A:B,2,FALSE()),"?") -> ARENA LAVADA | F22: =IFERROR(VLOOKUP(D22,MATERIALES!A:C,3,FALSE()),"?") -> 0 | G22: 0.02 | H22: 0.03 | I22: =IFERROR(VLOOKUP(D22,MATERIALES!A:D,4,FALSE()),0) -> 32620.38 | J22: =G22*I22*(1+H22) -> 671.97983 | K22: =A22&"|"&B22 -> REV-115|MAT | L22: =COUNTIFS($K$2:K22,K22) -> 1 | M22: =K22&"|"&L22 -> REV-115|MAT|1 | N22: =IFERROR(VLOOKUP(A22,PARTIDAS!A:F,6,FALSE()),0) -> 15 | O22: =+IF(C22="ALB",G22/N22,0) -> 0 | P22: =+_xlfn.XLOOKUP(A22,PPTO_GENERADOR!Q:Q,PPTO_GENERADOR!E:E,"-",0) -> - | Q22: =IFERROR(P22*O22,0) -> 0 | R22: =+_xlfn.XLOOKUP(A22,PPTO_GENERADOR!$Q:$Q,PPTO_GENERADOR!A:A,"-",0) -> -
A23: REV-115 | B23: MAT | C23: OTR | D23: AGR-005 | E23: =IFERROR(VLOOKUP(D23,MATERIALES!A:B,2,FALSE()),"?") -> Cal Comun x 25kg | F23: =IFERROR(VLOOKUP(D23,MATERIALES!A:C,3,FALSE()),"?") -> 0 | G23: 0.06 | H23: 0.05 | I23: =IFERROR(VLOOKUP(D23,MATERIALES!A:D,4,FALSE()),0) -> 3927.28 | J23: =G23*I23*(1+H23) -> 247.41864 | K23: =A23&"|"&B23 -> REV-115|MAT | L23: =COUNTIFS($K$2:K23,K23) -> 2 | M23: =K23&"|"&L23 -> REV-115|MAT|2 | N23: =IFERROR(VLOOKUP(A23,PARTIDAS!A:F,6,FALSE()),0) -> 15 | O23: =+IF(C23="ALB",G23/N23,0) -> 0 | P23: =+_xlfn.XLOOKUP(A23,PPTO_GENERADOR!Q:Q,PPTO_GENERADOR!E:E,"-",0) -> - | Q23: =IFERROR(P23*O23,0) -> 0 | R23: =+_xlfn.XLOOKUP(A23,PPTO_GENERADOR!$Q:$Q,PPTO_GENERADOR!A:A,"-",0) -> -
A24: REV-115 | B24: MAT | C24: OTR | D24: AGR-004 | E24: =IFERROR(VLOOKUP(D24,MATERIALES!A:B,2,FALSE()),"?") -> Cemento Portland x 50kg | F24: =IFERROR(VLOOKUP(D24,MATERIALES!A:C,3,FALSE()),"?") -> 0 | G24: 0.26 | H24: 0.03 | I24: =IFERROR(VLOOKUP(D24,MATERIALES!A:D,4,FALSE()),0) -> 7891.74 | J24: =G24*I24*(1+H24) -> 2113.408 | K24: =A24&"|"&B24 -> REV-115|MAT | L24: =COUNTIFS($K$2:K24,K24) -> 3 | M24: =K24&"|"&L24 -> REV-115|MAT|3 | N24: =IFERROR(VLOOKUP(A24,PARTIDAS!A:F,6,FALSE()),0) -> 15 | O24: =+IF(C24="ALB",G24/N24,0) -> 0 | P24: =+_xlfn.XLOOKUP(A24,PPTO_GENERADOR!Q:Q,PPTO_GENERADOR!E:E,"-",0) -> - | Q24: =IFERROR(P24*O24,0) -> 0 | R24: =+_xlfn.XLOOKUP(A24,PPTO_GENERADOR!$Q:$Q,PPTO_GENERADOR!A:A,"-",0) -> -
A25: REV-115 | B25: MO | C25: ALB | D25: MO-EESPE | E25: =IFERROR(VLOOKUP(D25,MANO_DE_OBRA!A:B,2,FALSE()),"?") -> ESPECIALIZADO | F25: j | G25: 1 | H25: 0 | I25: =IFERROR(VLOOKUP(D25,MANO_DE_OBRA!A:C,3,FALSE()),0) -> 94177.138 | J25: =G25*I25 -> 94177.138 | K25: =A25&"|"&B25 -> REV-115|MO | L25: =COUNTIFS($K$2:K25,K25) -> 1 | M25: =K25&"|"&L25 -> REV-115|MO|1 | N25: =IFERROR(VLOOKUP(A25,PARTIDAS!A:F,6,FALSE()),0) -> 15 | O25: =+IF(C25="ALB",G25/N25,0) -> 0.066666667 | P25: =+_xlfn.XLOOKUP(A25,PPTO_GENERADOR!Q:Q,PPTO_GENERADOR!E:E,"-",0) -> - | Q25: =IFERROR(P25*O25,0) -> 0 | R25: =+_xlfn.XLOOKUP(A25,PPTO_GENERADOR!$Q:$Q,PPTO_GENERADOR!A:A,"-",0) -> -
A26: REV-115 | B26: MO | C26: ALB | D26: MO-EAYUD | E26: =IFERROR(VLOOKUP(D26,MANO_DE_OBRA!A:B,2,FALSE()),"?") -> AYUDANTE | F26: j | G26: 1 | H26: 0 | I26: =IFERROR(VLOOKUP(D26,MANO_DE_OBRA!A:C,3,FALSE()),0) -> 67240.499 | J26: =G26*I26 -> 67240.499 | K26: =A26&"|"&B26 -> REV-115|MO | L26: =COUNTIFS($K$2:K26,K26) -> 2 | M26: =K26&"|"&L26 -> REV-115|MO|2 | N26: =IFERROR(VLOOKUP(A26,PARTIDAS!A:F,6,FALSE()),0) -> 15 | O26: =+IF(C26="ALB",G26/N26,0) -> 0.066666667 | P26: =+_xlfn.XLOOKUP(A26,PPTO_GENERADOR!Q:Q,PPTO_GENERADOR!E:E,"-",0) -> - | Q26: =IFERROR(P26*O26,0) -> 0 | R26: =+_xlfn.XLOOKUP(A26,PPTO_GENERADOR!$Q:$Q,PPTO_GENERADOR!A:A,"-",0) -> -
A27: REV-115 | B27: MO | C27: ALB | D27: MO-EMEDI | E27: =IFERROR(VLOOKUP(D27,MANO_DE_OBRA!A:B,2,FALSE()),"?") -> MEDIO OFICIAL | F27: j | G27: 0 | H27: 0 | I27: =IFERROR(VLOOKUP(D27,MANO_DE_OBRA!A:C,3,FALSE()),0) -> 72132.138 | J27: =G27*I27 -> 0 | K27: =A27&"|"&B27 -> REV-115|MO | L27: =COUNTIFS($K$2:K27,K27) -> 3 | M27: =K27&"|"&L27 -> REV-115|MO|3 | N27: =IFERROR(VLOOKUP(A27,PARTIDAS!A:F,6,FALSE()),0) -> 15 | O27: =+IF(C27="ALB",G27/N27,0) -> 0 | P27: =+_xlfn.XLOOKUP(A27,PPTO_GENERADOR!Q:Q,PPTO_GENERADOR!E:E,"-",0) -> - | Q27: =IFERROR(P27*O27,0) -> 0 | R27: =+_xlfn.XLOOKUP(A27,PPTO_GENERADOR!$Q:$Q,PPTO_GENERADOR!A:A,"-",0) -> -
A28: REV-116 | B28: MAT | C28: OTR | D28: DUR-007 | E28: =IFERROR(VLOOKUP(D28,MATERIALES!A:B,2,FALSE()),"?") -> Perfil Perimetral x 3.05 | F28: =IFERROR(VLOOKUP(D28,MATERIALES!A:C,3,FALSE()),"?") -> u | G28: 0.495 | H28: 0.1 | I28: =IFERROR(VLOOKUP(D28,MATERIALES!A:D,4,FALSE()),0) -> 3028.9421 | J28: =G28*I28*(1+H28) -> 1649.259 | K28: =A28&"|"&B28 -> REV-116|MAT | L28: =COUNTIFS($K$2:K28,K28) -> 1 | M28: =K28&"|"&L28 -> REV-116|MAT|1 | N28: =IFERROR(VLOOKUP(A28,PARTIDAS!A:F,6,FALSE()),0) -> 12 | O28: =+IF(C28="ALB",G28/N28,0) -> 0 | P28: =+_xlfn.XLOOKUP(A28,PPTO_GENERADOR!Q:Q,PPTO_GENERADOR!E:E,"-",0) -> - | Q28: =IFERROR(P28*O28,0) -> 0 | R28: =+_xlfn.XLOOKUP(A28,PPTO_GENERADOR!$Q:$Q,PPTO_GENERADOR!A:A,"-",0) -> -
A29: REV-116 | B29: MAT | C29: OTR | D29: OTR-015 | E29: =IFERROR(VLOOKUP(D29,MATERIALES!A:B,2,FALSE()),"?") -> Larguero x 3.66 | F29: =IFERROR(VLOOKUP(D29,MATERIALES!A:C,3,FALSE()),"?") -> u | G29: 0.45 | H29: 0.1 | I29: =IFERROR(VLOOKUP(D29,MATERIALES!A:D,4,FALSE()),0) -> 4774.9091 | J29: =G29*I29*(1+H29) -> 2363.58 | K29: =A29&"|"&B29 -> REV-116|MAT | L29: =COUNTIFS($K$2:K29,K29) -> 2 | M29: =K29&"|"&L29 -> REV-116|MAT|2 | N29: =IFERROR(VLOOKUP(A29,PARTIDAS!A:F,6,FALSE()),0) -> 12 | O29: =+IF(C29="ALB",G29/N29,0) -> 0 | P29: =+_xlfn.XLOOKUP(A29,PPTO_GENERADOR!Q:Q,PPTO_GENERADOR!E:E,"-",0) -> - | Q29: =IFERROR(P29*O29,0) -> 0 | R29: =+_xlfn.XLOOKUP(A29,PPTO_GENERADOR!$Q:$Q,PPTO_GENERADOR!A:A,"-",0) -> -
A30: REV-116 | B30: MAT | C30: OTR | D30: OTR-016 | E30: =IFERROR(VLOOKUP(D30,MATERIALES!A:B,2,FALSE()),"?") -> Travesaño x 1.22 | F30: =IFERROR(VLOOKUP(D30,MATERIALES!A:C,3,FALSE()),"?") -> u | G30: 2.62 | H30: 0.1 | I30: =IFERROR(VLOOKUP(D30,MATERIALES!A:D,4,FALSE()),0) -> 1547.438 | J30: =G30*I30*(1+H30) -> 4459.7164 | K30: =A30&"|"&B30 -> REV-116|MAT | L30: =COUNTIFS($K$2:K30,K30) -> 3 | M30: =K30&"|"&L30 -> REV-116|MAT|3 | N30: =IFERROR(VLOOKUP(A30,PARTIDAS!A:F,6,FALSE()),0) -> 12 | O30: =+IF(C30="ALB",G30/N30,0) -> 0 | P30: =+_xlfn.XLOOKUP(A30,PPTO_GENERADOR!Q:Q,PPTO_GENERADOR!E:E,"-",0) -> - | Q30: =IFERROR(P30*O30,0) -> 0 | R30: =+_xlfn.XLOOKUP(A30,PPTO_GENERADOR!$Q:$Q,PPTO_GENERADOR!A:A,"-",0) -> -
A31: REV-116 | B31: MAT | C31: OTR | D31: OTR-017 | E31: =IFERROR(VLOOKUP(D31,MATERIALES!A:B,2,FALSE()),"?") -> Travesaño x 0.60 | F31: =IFERROR(VLOOKUP(D31,MATERIALES!A:C,3,FALSE()),"?") -> u | G31: 0 | H31: 0.1 | I31: =IFERROR(VLOOKUP(D31,MATERIALES!A:D,4,FALSE()),0) -> 793.53719 | J31: =G31*I31*(1+H31) -> 0 | K31: =A31&"|"&B31 -> REV-116|MAT | L31: =COUNTIFS($K$2:K31,K31) -> 4 | M31: =K31&"|"&L31 -> REV-116|MAT|4 | N31: =IFERROR(VLOOKUP(A31,PARTIDAS!A:F,6,FALSE()),0) -> 12 | O31: =+IF(C31="ALB",G31/N31,0) -> 0 | P31: =+_xlfn.XLOOKUP(A31,PPTO_GENERADOR!Q:Q,PPTO_GENERADOR!E:E,"-",0) -> - | Q31: =IFERROR(P31*O31,0) -> 0 | R31: =+_xlfn.XLOOKUP(A31,PPTO_GENERADOR!$Q:$Q,PPTO_GENERADOR!A:A,"-",0) -> -
A32: REV-116 | B32: MAT | C32: OTR | D32: OTR-010 | E32: =IFERROR(VLOOKUP(D32,MATERIALES!A:B,2,FALSE()),"?") -> Fijacion completa del 8 | F32: =IFERROR(VLOOKUP(D32,MATERIALES!A:C,3,FALSE()),"?") -> u | G32: 6 | H32: 0.1 | I32: =IFERROR(VLOOKUP(D32,MATERIALES!A:D,4,FALSE()),0) -> 63.381983 | J32: =G32*I32*(1+H32) -> 418.32109 | K32: =A32&"|"&B32 -> REV-116|MAT | L32: =COUNTIFS($K$2:K32,K32) -> 5 | M32: =K32&"|"&L32 -> REV-116|MAT|5 | N32: =IFERROR(VLOOKUP(A32,PARTIDAS!A:F,6,FALSE()),0) -> 12 | O32: =+IF(C32="ALB",G32/N32,0) -> 0 | P32: =+_xlfn.XLOOKUP(A32,PPTO_GENERADOR!Q:Q,PPTO_GENERADOR!E:E,"-",0) -> - | Q32: =IFERROR(P32*O32,0) -> 0 | R32: =+_xlfn.XLOOKUP(A32,PPTO_GENERADOR!$Q:$Q,PPTO_GENERADOR!A:A,"-",0) -> -
A33: REV-116 | B33: MAT | C33: OTR | D33: ACE-014 | E33: =IFERROR(VLOOKUP(D33,MATERIALES!A:B,2,FALSE()),"?") -> Alambre galvanizado N°14 x kg | F33: =IFERROR(VLOOKUP(D33,MATERIALES!A:C,3,FALSE()),"?") -> kg | G33: 0.06 | H33: 0.1 | I33: =IFERROR(VLOOKUP(D33,MATERIALES!A:D,4,FALSE()),0) -> 2755.6116 | J33: =G33*I33*(1+H33) -> 181.87036 | K33: =A33&"|"&B33 -> REV-116|MAT | L33: =COUNTIFS($K$2:K33,K33) -> 6 | M33: =K33&"|"&L33 -> REV-116|MAT|6 | N33: =IFERROR(VLOOKUP(A33,PARTIDAS!A:F,6,FALSE()),0) -> 12 | O33: =+IF(C33="ALB",G33/N33,0) -> 0 | P33: =+_xlfn.XLOOKUP(A33,PPTO_GENERADOR!Q:Q,PPTO_GENERADOR!E:E,"-",0) -> - | Q33: =IFERROR(P33*O33,0) -> 0 | R33: =+_xlfn.XLOOKUP(A33,PPTO_GENERADOR!$Q:$Q,PPTO_GENERADOR!A:A,"-",0) -> -
A34: REV-116 | B34: MAT | C34: OTR | D34: OTR-019 | E34: =IFERROR(VLOOKUP(D34,MATERIALES!A:B,2,FALSE()),"?") -> Placa Decovinyl Liso 120x60 | F34: =IFERROR(VLOOKUP(D34,MATERIALES!A:C,3,FALSE()),"?") -> u | G34: 1.3889 | H34: 0.1 | I34: =IFERROR(VLOOKUP(D34,MATERIALES!A:D,4,FALSE()),0) -> 4751.7079 | J34: =G34*I34*(1+H34) -> 7259.6118 | K34: =A34&"|"&B34 -> REV-116|MAT | L34: =COUNTIFS($K$2:K34,K34) -> 7 | M34: =K34&"|"&L34 -> REV-116|MAT|7 | N34: =IFERROR(VLOOKUP(A34,PARTIDAS!A:F,6,FALSE()),0) -> 12 | O34: =+IF(C34="ALB",G34/N34,0) -> 0 | P34: =+_xlfn.XLOOKUP(A34,PPTO_GENERADOR!Q:Q,PPTO_GENERADOR!E:E,"-",0) -> - | Q34: =IFERROR(P34*O34,0) -> 0 | R34: =+_xlfn.XLOOKUP(A34,PPTO_GENERADOR!$Q:$Q,PPTO_GENERADOR!A:A,"-",0) -> -
A35: REV-116 | B35: EQ | D35: EQ-ESCALE | E35: =IFERROR(VLOOKUP(D35,EQUIPOS!A:B,2,FALSE()),"?") -> ESCALERA GLOSS ALUMINIO ARTICULADA 4 X 4 ESCALONES HASTA 150KG | G35: 1 | H35: 0 | I35: =IFERROR(VLOOKUP(D35,EQUIPOS!A:F,6,FALSE()),0) -> 152.38027 | J35: =G35*I35 -> 152.38027 | K35: =A35&"|"&B35 -> REV-116|EQ | L35: =COUNTIFS($K$2:K35,K35) -> 1 | M35: =K35&"|"&L35 -> REV-116|EQ|1 | N35: =IFERROR(VLOOKUP(A35,PARTIDAS!A:F,6,FALSE()),0) -> 12 | O35: =+IF(C35="ALB",G35/N35,0) -> 0 | P35: =+_xlfn.XLOOKUP(A35,PPTO_GENERADOR!Q:Q,PPTO_GENERADOR!E:E,"-",0) -> - | Q35: =IFERROR(P35*O35,0) -> 0 | R35: =+_xlfn.XLOOKUP(A35,PPTO_GENERADOR!$Q:$Q,PPTO_GENERADOR!A:A,"-",0) -> -
A36: REV-116 | B36: EQ | D36: EQ-PTO024 | E36: =IFERROR(VLOOKUP(D36,EQUIPOS!A:B,2,FALSE()),"?") -> EQUIPO DE CONSTRUCCION EN SECO | G36: 1 | H36: 0 | I36: =IFERROR(VLOOKUP(D36,EQUIPOS!A:F,6,FALSE()),0) -> 2570.7599 | J36: =G36*I36 -> 2570.7599 | K36: =A36&"|"&B36 -> REV-116|EQ | L36: =COUNTIFS($K$2:K36,K36) -> 2 | M36: =K36&"|"&L36 -> REV-116|EQ|2 | N36: =IFERROR(VLOOKUP(A36,PARTIDAS!A:F,6,FALSE()),0) -> 12 | O36: =+IF(C36="ALB",G36/N36,0) -> 0 | P36: =+_xlfn.XLOOKUP(A36,PPTO_GENERADOR!Q:Q,PPTO_GENERADOR!E:E,"-",0) -> - | Q36: =IFERROR(P36*O36,0) -> 0 | R36: =+_xlfn.XLOOKUP(A36,PPTO_GENERADOR!$Q:$Q,PPTO_GENERADOR!A:A,"-",0) -> -
A37: REV-116 | B37: MO | C37: ALB | D37: MO-EESPE | E37: =IFERROR(VLOOKUP(D37,MANO_DE_OBRA!A:B,2,FALSE()),"?") -> ESPECIALIZADO | F37: j | G37: 1 | H37: 0 | I37: =IFERROR(VLOOKUP(D37,MANO_DE_OBRA!A:C,3,FALSE()),0) -> 94177.138 | J37: =G37*I37 -> 94177.138 | K37: =A37&"|"&B37 -> REV-116|MO | L37: =COUNTIFS($K$2:K37,K37) -> 1 | M37: =K37&"|"&L37 -> REV-116|MO|1 | N37: =IFERROR(VLOOKUP(A37,PARTIDAS!A:F,6,FALSE()),0) -> 12 | O37: =+IF(C37="ALB",G37/N37,0) -> 0.083333333 | P37: =+_xlfn.XLOOKUP(A37,PPTO_GENERADOR!Q:Q,PPTO_GENERADOR!E:E,"-",0) -> - | Q37: =IFERROR(P37*O37,0) -> 0 | R37: =+_xlfn.XLOOKUP(A37,PPTO_GENERADOR!$Q:$Q,PPTO_GENERADOR!A:A,"-",0) -> -
A38: REV-116 | B38: MO | C38: ALB | D38: MO-EMEDI | E38: =IFERROR(VLOOKUP(D38,MANO_DE_OBRA!A:B,2,FALSE()),"?") -> MEDIO OFICIAL | F38: j | G38: 1 | H38: 0 | I38: =IFERROR(VLOOKUP(D38,MANO_DE_OBRA!A:C,3,FALSE()),0) -> 72132.138 | J38: =G38*I38 -> 72132.138 | K38: =A38&"|"&B38 -> REV-116|MO | L38: =COUNTIFS($K$2:K38,K38) -> 2 | M38: =K38&"|"&L38 -> REV-116|MO|2 | N38: =IFERROR(VLOOKUP(A38,PARTIDAS!A:F,6,FALSE()),0) -> 12 | O38: =+IF(C38="ALB",G38/N38,0) -> 0.083333333 | P38: =+_xlfn.XLOOKUP(A38,PPTO_GENERADOR!Q:Q,PPTO_GENERADOR!E:E,"-",0) -> - | Q38: =IFERROR(P38*O38,0) -> 0 | R38: =+_xlfn.XLOOKUP(A38,PPTO_GENERADOR!$Q:$Q,PPTO_GENERADOR!A:A,"-",0) -> -
A39: YES-117 | B39: MAT | C39: OTR | D39: OTR-014 | E39: =IFERROR(VLOOKUP(D39,MATERIALES!A:B,2,FALSE()),"?") -> Buña Z x 2.60m | F39: =IFERROR(VLOOKUP(D39,MATERIALES!A:C,3,FALSE()),"?") -> u | G39: 0.39 | H39: 0.1 | I39: =IFERROR(VLOOKUP(D39,MATERIALES!A:D,4,FALSE()),0) -> 2234.18 | J39: =G39*I39*(1+H39) -> 958.46322 | K39: =A39&"|"&B39 -> YES-117|MAT | L39: =COUNTIFS($K$2:K39,K39) -> 1 | M39: =K39&"|"&L39 -> YES-117|MAT|1 | N39: =IFERROR(VLOOKUP(A39,PARTIDAS!A:F,6,FALSE()),0) -> 15 | O39: =+IF(C39="ALB",G39/N39,0) -> 0 | P39: =+_xlfn.XLOOKUP(A39,PPTO_GENERADOR!Q:Q,PPTO_GENERADOR!E:E,"-",0) -> - | Q39: =IFERROR(P39*O39,0) -> 0 | R39: =+_xlfn.XLOOKUP(A39,PPTO_GENERADOR!$Q:$Q,PPTO_GENERADOR!A:A,"-",0) -> -
A40: YES-117 | B40: MAT | C40: OTR | D40: OTR-008 | E40: =IFERROR(VLOOKUP(D40,MATERIALES!A:B,2,FALSE()),"?") -> Tornillo T2 - Aguja | F40: =IFERROR(VLOOKUP(D40,MATERIALES!A:C,3,FALSE()),"?") -> u | G40: 3 | H40: 0.05 | I40: =IFERROR(VLOOKUP(D40,MATERIALES!A:D,4,FALSE()),0) -> 9.114692 | J40: =G40*I40*(1+H40) -> 28.71128 | K40: =A40&"|"&B40 -> YES-117|MAT | L40: =COUNTIFS($K$2:K40,K40) -> 2 | M40: =K40&"|"&L40 -> YES-117|MAT|2 | N40: =IFERROR(VLOOKUP(A40,PARTIDAS!A:F,6,FALSE()),0) -> 15 | O40: =+IF(C40="ALB",G40/N40,0) -> 0 | P40: =+_xlfn.XLOOKUP(A40,PPTO_GENERADOR!Q:Q,PPTO_GENERADOR!E:E,"-",0) -> - | Q40: =IFERROR(P40*O40,0) -> 0 | R40: =+_xlfn.XLOOKUP(A40,PPTO_GENERADOR!$Q:$Q,PPTO_GENERADOR!A:A,"-",0) -> -
...

Sheet PARTIDAS
A1: Código | B1: P# | C1: Rubro | D1: Descripción | E1: Ud. | F1: Rend. | G1: Cant Cons. | H1: % Cons. Desp. | I1: Grado Dif. | J1: MAT (sum/ud) | K1: MO (sum/día) | L1: EQ (sum/día) | M1: MAT/ud | N1: MO/ud | O1: EQ/ud | P1: CD/ud | Q1: # Comp. | S1: Fuente | T1: GDR MAT | U1: GDR MO | V1: GDR EQ
A2: APU-101 | B2: 101 | C2: General | D2: Viga de Hormigon Armado - Encofrado Fenolico | E2: m3 | F2: 1 | G2: 0 | H2: 0 | I2: 1 | J2: =SUMIFS(COMPOSICIÓN!J$2:J$1892,COMPOSICIÓN!A$2:A$1892,A2,COMPOSICIÓN!B$2:B$1892,"MAT") -> 0 | K2: =SUMIFS(COMPOSICIÓN!J$2:J$1892,COMPOSICIÓN!A$2:A$1892,A2,COMPOSICIÓN!B$2:B$1892,"MO")*I2 -> 161417.64 | L2: =SUMIFS(COMPOSICIÓN!J$2:J$1892,COMPOSICIÓN!A$2:A$1892,A2,COMPOSICIÓN!B$2:B$1892,"EQ") -> 0 | M2: =J2 -> 0 | N2: =IF(F2=0,0,K2/F2) -> 161417.64 | O2: =IF(F2=0,0,L2/F2) -> 0 | P2: =M2+N2+O2 -> 161417.64 | Q2: =COUNTIF(COMPOSICIÓN!$A:$A,A2) -> 2 | S2: APU
A3: BAN-106 | B3: 106 | C3: Bandeja | D3: Viga de Hormigon Armado - FE Doblado y Armado | E3: m3 | F3: 3.8 | G3: 0 | H3: 0 | I3: 1 | J3: =SUMIFS(COMPOSICIÓN!J$2:J$1892,COMPOSICIÓN!A$2:A$1892,A3,COMPOSICIÓN!B$2:B$1892,"MAT") -> 0 | K3: =SUMIFS(COMPOSICIÓN!J$2:J$1892,COMPOSICIÓN!A$2:A$1892,A3,COMPOSICIÓN!B$2:B$1892,"MO")*I3 -> 161417.64 | L3: =SUMIFS(COMPOSICIÓN!J$2:J$1892,COMPOSICIÓN!A$2:A$1892,A3,COMPOSICIÓN!B$2:B$1892,"EQ") -> 0 | M3: =J3 -> 0 | N3: =IF(F3=0,0,K3/F3) -> 42478.325 | O3: =IF(F3=0,0,L3/F3) -> 0 | P3: =M3+N3+O3 -> 42478.325 | Q3: =COUNTIF(COMPOSICIÓN!$A:$A,A3) -> 2 | R3: REVISAR — P-XX sin Unitario Materiales legible. Sin corrección pendiente. Chat 5. | S3: APU
A4: ALB-110 | B4: 110 | C4: MAMPOSTERÍA | D4: Viga de Hormigon Armado - Llenado | E4: m3 | F4: 36 | G4: 0 | H4: 0 | I4: 1 | J4: =SUMIFS(COMPOSICIÓN!J$2:J$1892,COMPOSICIÓN!A$2:A$1892,A4,COMPOSICIÓN!B$2:B$1892,"MAT") -> 0 | K4: =SUMIFS(COMPOSICIÓN!J$2:J$1892,COMPOSICIÓN!A$2:A$1892,A4,COMPOSICIÓN!B$2:B$1892,"MO")*I4 -> 589318.83 | L4: =SUMIFS(COMPOSICIÓN!J$2:J$1892,COMPOSICIÓN!A$2:A$1892,A4,COMPOSICIÓN!B$2:B$1892,"EQ") -> 0 | M4: =J4 -> 0 | N4: =IF(F4=0,0,K4/F4) -> 16369.967 | O4: =IF(F4=0,0,L4/F4) -> 0 | P4: =M4+N4+O4 -> 16369.967 | Q4: =COUNTIF(COMPOSICIÓN!$A:$A,A4) -> 3 | R4: REVISAR — P-XX sin Unitario Materiales legible. Sin corrección pendiente. Chat 5. | S4: APU
A5: AIS-113 | B5: 113 | C5: AISLACIONES | D5: Impermeabilizacion de azotea con pintura asfaltica / Barrera de vapor | E5: m2 | F5: 80 | G5: 0 | H5: 0 | I5: 1 | J5: =SUMIFS(COMPOSICIÓN!J$2:J$1892,COMPOSICIÓN!A$2:A$1892,A5,COMPOSICIÓN!B$2:B$1892,"MAT") -> 1393.4782 | K5: =SUMIFS(COMPOSICIÓN!J$2:J$1892,COMPOSICIÓN!A$2:A$1892,A5,COMPOSICIÓN!B$2:B$1892,"MO")*I5 -> 161417.64 | L5: =SUMIFS(COMPOSICIÓN!J$2:J$1892,COMPOSICIÓN!A$2:A$1892,A5,COMPOSICIÓN!B$2:B$1892,"EQ") -> 874.41131 | M5: =J5 -> 1393.4782 | N5: =IF(F5=0,0,K5/F5) -> 2017.7205 | O5: =IF(F5=0,0,L5/F5) -> 10.930141 | P5: =M5+N5+O5 -> 3422.1288 | Q5: =COUNTIF(COMPOSICIÓN!$A:$A,A5) -> 8 | S5: APU | T5: 1392.6098 | U5: 2017.7205 | V5: 10.930141
A6: AIS-114 | B6: 114 | C6: AISLACIONES | D6: Babeta en Azotea con membrana Geotextil Ormiflex de 4mm, a soplete. | E6: m | F6: 60 | G6: 0 | H6: 0 | I6: 1 | J6: =SUMIFS(COMPOSICIÓN!J$2:J$1892,COMPOSICIÓN!A$2:A$1892,A6,COMPOSICIÓN!B$2:B$1892,"MAT") -> 4401.83 | K6: =SUMIFS(COMPOSICIÓN!J$2:J$1892,COMPOSICIÓN!A$2:A$1892,A6,COMPOSICIÓN!B$2:B$1892,"MO")*I6 -> 161417.64 | L6: =SUMIFS(COMPOSICIÓN!J$2:J$1892,COMPOSICIÓN!A$2:A$1892,A6,COMPOSICIÓN!B$2:B$1892,"EQ") -> 874.41131 | M6: =J6 -> 4401.83 | N6: =IF(F6=0,0,K6/F6) -> 2690.2939 | O6: =IF(F6=0,0,L6/F6) -> 14.573522 | P6: =M6+N6+O6 -> 7106.6974 | Q6: =COUNTIF(COMPOSICIÓN!$A:$A,A6) -> 11 | S6: APU | T6: 3733.7132 | U6: 2690.2939 | V6: 14.573522
A7: REV-115 | B7: 115 | C7: REVOQUES | D7: Revoque Grueso Exterior S/hidrofugo hasta 3.00 m | E7: m2 | F7: 15 | G7: 0 | H7: 0 | I7: 1 | J7: =SUMIFS(COMPOSICIÓN!J$2:J$1892,COMPOSICIÓN!A$2:A$1892,A7,COMPOSICIÓN!B$2:B$1892,"MAT") -> 3032.8064 | K7: =SUMIFS(COMPOSICIÓN!J$2:J$1892,COMPOSICIÓN!A$2:A$1892,A7,COMPOSICIÓN!B$2:B$1892,"MO")*I7 -> 161417.64 | L7: =SUMIFS(COMPOSICIÓN!J$2:J$1892,COMPOSICIÓN!A$2:A$1892,A7,COMPOSICIÓN!B$2:B$1892,"EQ") -> 0 | M7: =J7 -> 3032.8064 | N7: =IF(F7=0,0,K7/F7) -> 10761.176 | O7: =IF(F7=0,0,L7/F7) -> 0 | P7: =M7+N7+O7 -> 13793.982 | Q7: =COUNTIF(COMPOSICIÓN!$A:$A,A7) -> 6 | R7: Desvío MAT +2.8%. Probable redondeo de %desp vs APU original. Sin acción correctiva. | S7: APU | T7: 2950.8968 | U7: 10761.176 | V7: 0
A8: REV-116 | B8: 116 | C8: REVOQUES | D8: Cielorraso Desmontable 120x60 - incluye placa | E8: m2 | F8: 12 | G8: 0 | H8: 0 | I8: 1 | J8: =SUMIFS(COMPOSICIÓN!J$2:J$1892,COMPOSICIÓN!A$2:A$1892,A8,COMPOSICIÓN!B$2:B$1892,"MAT") -> 16332.359 | K8: =SUMIFS(COMPOSICIÓN!J$2:J$1892,COMPOSICIÓN!A$2:A$1892,A8,COMPOSICIÓN!B$2:B$1892,"MO")*I8 -> 166309.28 | L8: =SUMIFS(COMPOSICIÓN!J$2:J$1892,COMPOSICIÓN!A$2:A$1892,A8,COMPOSICIÓN!B$2:B$1892,"EQ") -> 2723.1402 | M8: =J8 -> 16332.359 | N8: =IF(F8=0,0,K8/F8) -> 13859.106 | O8: =IF(F8=0,0,L8/F8) -> 226.92835 | P8: =M8+N8+O8 -> 30418.393 | Q8: =COUNTIF(COMPOSICIÓN!$A:$A,A8) -> 11 | S8: APU | T8: 16332.301 | U8: 13859.106 | V8: 226.92835
A9: YES-117 | B9: 117 | C9: REVOQUES FINOS Y CIELORRASOS | D9: Perfil buña Z / Cantonera | E9: ml | F9: 15 | G9: 0 | H9: 0 | I9: 1 | J9: =SUMIFS(COMPOSICIÓN!J$2:J$1892,COMPOSICIÓN!A$2:A$1892,A9,COMPOSICIÓN!B$2:B$1892,"MAT") -> 987.1745 | K9: =SUMIFS(COMPOSICIÓN!J$2:J$1892,COMPOSICIÓN!A$2:A$1892,A9,COMPOSICIÓN!B$2:B$1892,"MO")*I9 -> 94177.138 | L9: =SUMIFS(COMPOSICIÓN!J$2:J$1892,COMPOSICIÓN!A$2:A$1892,A9,COMPOSICIÓN!B$2:B$1892,"EQ") -> 2723.1402 | M9: =J9 -> 987.1745 | N9: =IF(F9=0,0,K9/F9) -> 6278.4759 | O9: =IF(F9=0,0,L9/F9) -> 181.54268 | P9: =M9+N9+O9 -> 7447.193 | Q9: =COUNTIF(COMPOSICIÓN!$A:$A,A9) -> 5 | S9: APU | T9: 987.1745 | U9: 6278.4759 | V9: 181.54268
A10: YES-118 | B10: 118 | C10: REVOQUES FINOS Y CIELORRASOS | D10: Bloque de Hormigon 10 x 19 x 39 | E10: m2 | F10: 11.5 | G10: 0 | H10: 0 | I10: 1 | J10: =SUMIFS(COMPOSICIÓN!J$2:J$1892,COMPOSICIÓN!A$2:A$1892,A10,COMPOSICIÓN!B$2:B$1892,"MAT") -> 12733.789 | K10: =SUMIFS(COMPOSICIÓN!J$2:J$1892,COMPOSICIÓN!A$2:A$1892,A10,COMPOSICIÓN!B$2:B$1892,"MO")*I10 -> 148276.24 | L10: =SUMIFS(COMPOSICIÓN!J$2:J$1892,COMPOSICIÓN!A$2:A$1892,A10,COMPOSICIÓN!B$2:B$1892,"EQ") -> 3836.7078 | M10: =J10 -> 12733.789 | N10: =IF(F10=0,0,K10/F10) -> 12893.586 | O10: =IF(F10=0,0,L10/F10) -> 333.62677 | P10: =M10+N10+O10 -> 25961.002 | Q10: =COUNTIF(COMPOSICIÓN!$A:$A,A10) -> 11 | R10: Desvío MO +2.5%. Desvío menor. Sin acción correctiva. | S10: APU | T10: 12733.789 | U10: 12574.566 | V10: 333.62677
A11: PIN-119 | B11: 119 | C11: PINTURA | D11: Bloque de Hormigon 19 x 19 x 39 | E11: m2 | F11: 11.5 | G11: 0 | H11: 0 | I11: 1 | J11: =SUMIFS(COMPOSICIÓN!J$2:J$1892,COMPOSICIÓN!A$2:A$1892,A11,COMPOSICIÓN!B$2:B$1892,"MAT") -> 18247.942 | K11: =SUMIFS(COMPOSICIÓN!J$2:J$1892,COMPOSICIÓN!A$2:A$1892,A11,COMPOSICIÓN!B$2:B$1892,"MO")*I11 -> 148276.24 | L11: =SUMIFS(COMPOSICIÓN!J$2:J$1892,COMPOSICIÓN!A$2:A$1892,A11,COMPOSICIÓN!B$2:B$1892,"EQ") -> 3836.7078 | M11: =J11 -> 18247.942 | N11: =IF(F11=0,0,K11/F11) -> 12893.586 | O11: =IF(F11=0,0,L11/F11) -> 333.62677 | P11: =M11+N11+O11 -> 31475.155 | Q11: =COUNTIF(COMPOSICIÓN!$A:$A,A11) -> 11 | R11: Desvío MO +2.5%. Desvío menor. Sin acción correctiva. | S11: APU | T11: 18247.942 | U11: 12574.566 | V11: 333.62677
A12: ELE-120 | B12: 120 | C12: INSTALACIÓN ELÉCTRICA | D12: BOCA ILUMINACIÓN | E12: m2 | F12: 3.25 | G12: 0 | H12: 0 | I12: 1 | J12: =SUMIFS(COMPOSICIÓN!J$2:J$1892,COMPOSICIÓN!A$2:A$1892,A12,COMPOSICIÓN!B$2:B$1892,"MAT") -> 17610.205 | K12: =SUMIFS(COMPOSICIÓN!J$2:J$1892,COMPOSICIÓN!A$2:A$1892,A12,COMPOSICIÓN!B$2:B$1892,"MO")*I12 -> 161417.64 | L12: =SUMIFS(COMPOSICIÓN!J$2:J$1892,COMPOSICIÓN!A$2:A$1892,A12,COMPOSICIÓN!B$2:B$1892,"EQ") -> 5889.636 | M12: =J12 -> 17610.205 | N12: =IF(F12=0,0,K12/F12) -> 49666.965 | O12: =IF(F12=0,0,L12/F12) -> 1812.1957 | P12: =M12+N12+O12 -> 69089.366 | Q12: =COUNTIF(COMPOSICIÓN!$A:$A,A12) -> 14 | S12: APU | T12: 17610.205 | U12: 49666.965 | V12: 1812.1957
A13: ELE-121 | B13: 121 | C13: INSTALACIÓN ELÉCTRICA | D13: BOCA TOMACORRIENTE | E13: m2 | F13: 3.25 | G13: 0 | H13: 0 | I13: 1 | J13: =SUMIFS(COMPOSICIÓN!J$2:J$1892,COMPOSICIÓN!A$2:A$1892,A13,COMPOSICIÓN!B$2:B$1892,"MAT") -> 15896.431 | K13: =SUMIFS(COMPOSICIÓN!J$2:J$1892,COMPOSICIÓN!A$2:A$1892,A13,COMPOSICIÓN!B$2:B$1892,"MO")*I13 -> 161417.64 | L13: =SUMIFS(COMPOSICIÓN!J$2:J$1892,COMPOSICIÓN!A$2:A$1892,A13,COMPOSICIÓN!B$2:B$1892,"EQ") -> 5889.636 | M13: =J13 -> 15896.431 | N13: =IF(F13=0,0,K13/F13) -> 49666.965 | O13: =IF(F13=0,0,L13/F13) -> 1812.1957 | P13: =M13+N13+O13 -> 67375.592 | Q13: =COUNTIF(COMPOSICIÓN!$A:$A,A13) -> 12 | S13: APU | T13: 15896.431 | U13: 49666.965 | V13: 1812.1957
A14: BAN-122 | B14: 122 | C14: Bandeja | D14: BANDEJA PORTACABLES 200 | E14: m2 | F14: 12 | G14: 0 | H14: 0 | I14: 1 | J14: =SUMIFS(COMPOSICIÓN!J$2:J$1892,COMPOSICIÓN!A$2:A$1892,A14,COMPOSICIÓN!B$2:B$1892,"MAT") -> 18848.235 | K14: =SUMIFS(COMPOSICIÓN!J$2:J$1892,COMPOSICIÓN!A$2:A$1892,A14,COMPOSICIÓN!B$2:B$1892,"MO")*I14 -> 134013.79 | L14: =SUMIFS(COMPOSICIÓN!J$2:J$1892,COMPOSICIÓN!A$2:A$1892,A14,COMPOSICIÓN!B$2:B$1892,"EQ") -> 0 | M14: =J14 -> 18848.235 | N14: =IF(F14=0,0,K14/F14) -> 11167.816 | O14: =IF(F14=0,0,L14/F14) -> 0 | P14: =M14+N14+O14 -> 30016.05 | Q14: =COUNTIF(COMPOSICIÓN!$A:$A,A14) -> 11 | R14: MO: MO-MOFA→MO-AYU02 (APU P-122 usa Ayudante Albañil $67,240, no Medio Oficial $72,132). cant=0.5925 para paridad con RESUMEN APU 06.25 ($11,167.82/ud). Hoja P-122 calcula $12,050.63 (cant=0.75×AYU02) — divergencia documentada. | S14: APU | T14: 18848.235 | U14: 11167.816 | V14: 0
A15: HHA-123 | B15: 123 | C15: ESTRUCTURA DE HORMIGÓN ARMADO | D15: COLUMNA HORMIGÓN RÚSTICO 85 kg/m3 | E15: m3 | F15: 12 | G15: 0 | H15: 0 | I15: 1 | J15: =SUMIFS(COMPOSICIÓN!J$2:J$1892,COMPOSICIÓN!A$2:A$1892,A15,COMPOSICIÓN!B$2:B$1892,"MAT") -> 1.1 | K15: =SUMIFS(COMPOSICIÓN!J$2:J$1892,COMPOSICIÓN!A$2:A$1892,A15,COMPOSICIÓN!B$2:B$1892,"MO")*I15 -> 148276.24 | L15: =SUMIFS(COMPOSICIÓN!J$2:J$1892,COMPOSICIÓN!A$2:A$1892,A15,COMPOSICIÓN!B$2:B$1892,"EQ") -> 0 | M15: =J15 -> 1.1 | N15: =IF(F15=0,0,K15/F15) -> 12356.353 | O15: =IF(F15=0,0,L15/F15) -> 0 | P15: =M15+N15+O15 -> 12357.453 | Q15: =COUNTIF(COMPOSICIÓN!$A:$A,A15) -> 3 | R15: REVISAR — P-XX sin Unitario Materiales legible. Sin corrección pendiente. Chat 5. | S15: APU
A16: HHA-124 | B16: 124 | C16: ESTRUCTURA DE HORMIGÓN ARMADO | D16: COLUMNA HORMIGÓN VISTO | E16: m3 | F16: 12 | G16: 0 | H16: 0 | I16: 1 | J16: =SUMIFS(COMPOSICIÓN!J$2:J$1892,COMPOSICIÓN!A$2:A$1892,A16,COMPOSICIÓN!B$2:B$1892,"MAT") -> 2.1 | K16: =SUMIFS(COMPOSICIÓN!J$2:J$1892,COMPOSICIÓN!A$2:A$1892,A16,COMPOSICIÓN!B$2:B$1892,"MO")*I16 -> 148276.24 | L16: =SUMIFS(COMPOSICIÓN!J$2:J$1892,COMPOSICIÓN!A$2:A$1892,A16,COMPOSICIÓN!B$2:B$1892,"EQ") -> 0 | M16: =J16 -> 2.1 | N16: =IF(F16=0,0,K16/F16) -> 12356.353 | O16: =IF(F16=0,0,L16/F16) -> 0 | P16: =M16+N16+O16 -> 12358.453 | Q16: =COUNTIF(COMPOSICIÓN!$A:$A,A16) -> 4 | R16: REVISAR — P-XX sin Unitario Materiales legible. Sin corrección pendiente. Chat 5. | S16: APU
A17: CER-134 | B17: 134 | C17: CERÁMICOS | D17: Revoque grueso para interiores | E17: m2 | F17: 18 | G17: 0 | H17: 0 | I17: 1 | J17: =SUMIFS(COMPOSICIÓN!J$2:J$1892,COMPOSICIÓN!A$2:A$1892,A17,COMPOSICIÓN!B$2:B$1892,"MAT") -> 1553.2761 | K17: =SUMIFS(COMPOSICIÓN!J$2:J$1892,COMPOSICIÓN!A$2:A$1892,A17,COMPOSICIÓN!B$2:B$1892,"MO")*I17 -> 144607.51 | L17: =SUMIFS(COMPOSICIÓN!J$2:J$1892,COMPOSICIÓN!A$2:A$1892,A17,COMPOSICIÓN!B$2:B$1892,"EQ") -> 3106.6818 | M17: =J17 -> 1553.2761 | N17: =IF(F17=0,0,K17/F17) -> 8033.7507 | O17: =IF(F17=0,0,L17/F17) -> 172.59343 | P17: =M17+N17+O17 -> 9759.6202 | Q17: =COUNTIF(COMPOSICIÓN!$A:$A,A17) -> 8 | R17: EQ: EQ-TROMPO cant=0. APU P-134 lo incluye pero RESUMEN APU lo omitió; GDR tomó valor del RESUMEN ($172.59). Bug del RESUMEN APU — paridad preservada. | S17: APU | T17: 1553.2761 | U17: 8033.7507 | V17: 172.59343
A18: CER-135 | B18: 135 | C18: CERÁMICOS | D18: Revoque fino a la cal | E18: m2 | F18: 9 | G18: 0 | H18: 0 | I18: 1 | J18: =SUMIFS(COMPOSICIÓN!J$2:J$1892,COMPOSICIÓN!A$2:A$1892,A18,COMPOSICIÓN!B$2:B$1892,"MAT") -> 1337.9415 | K18: =SUMIFS(COMPOSICIÓN!J$2:J$1892,COMPOSICIÓN!A$2:A$1892,A18,COMPOSICIÓN!B$2:B$1892,"MO")*I18 -> 134521.44 | L18: =SUMIFS(COMPOSICIÓN!J$2:J$1892,COMPOSICIÓN!A$2:A$1892,A18,COMPOSICIÓN!B$2:B$1892,"EQ") -> 4147.1132 | M18: =J18 -> 1337.9415 | N18: =IF(F18=0,0,K18/F18) -> 14946.826 | O18: =IF(F18=0,0,L18/F18) -> 460.79036 | P18: =M18+N18+O18 -> 16745.558 | Q18: =COUNTIF(COMPOSICIÓN!$A:$A,A18) -> 8 | S18: APU | T18: 1337.9415 | U18: 14946.826 | V18: 460.79036
A19: CER-136 | B19: 136 | C19: CERÁMICOS | D19: Carpeta cal reforzada (e: 1,5 cm) | E19: m2 | F19: 14.5 | G19: 0 | H19: 0 | I19: 1 | J19: =SUMIFS(COMPOSICIÓN!J$2:J$1892,COMPOSICIÓN!A$2:A$1892,A19,COMPOSICIÓN!B$2:B$1892,"MAT") -> 2755.4985 | K19: =SUMIFS(COMPOSICIÓN!J$2:J$1892,COMPOSICIÓN!A$2:A$1892,A19,COMPOSICIÓN!B$2:B$1892,"MO")*I19 -> 124435.36 | L19: =SUMIFS(COMPOSICIÓN!J$2:J$1892,COMPOSICIÓN!A$2:A$1892,A19,COMPOSICIÓN!B$2:B$1892,"EQ") -> 3526.3024 | M19: =J19 -> 2755.4985 | N19: =IF(F19=0,0,K19/F19) -> 8581.7491 | O19: =IF(F19=0,0,L19/F19) -> 243.19327 | P19: =M19+N19+O19 -> 11580.441 | Q19: =COUNTIF(COMPOSICIÓN!$A:$A,A19) -> 7 | S19: APU | T19: 2755.4985 | U19: 8581.7491 | V19: 243.19327
A20: CER-137 | B20: 137 | C20: CERÁMICOS | D20: Látex interior para paredes (enduido parcial) | E20: m2 | F20: 20 | G20: 0 | H20: 0 | I20: 1 | J20: =SUMIFS(COMPOSICIÓN!J$2:J$1892,COMPOSICIÓN!A$2:A$1892,A20,COMPOSICIÓN!B$2:B$1892,"MAT") -> 2880.1573 | K20: =SUMIFS(COMPOSICIÓN!J$2:J$1892,COMPOSICIÓN!A$2:A$1892,A20,COMPOSICIÓN!B$2:B$1892,"MO")*I20 -> 94177.138 | L20: =SUMIFS(COMPOSICIÓN!J$2:J$1892,COMPOSICIÓN!A$2:A$1892,A20,COMPOSICIÓN!B$2:B$1892,"EQ") -> 2091.05 | M20: =J20 -> 2880.1573 | N20: =IF(F20=0,0,K20/F20) -> 4708.8569 | O20: =IF(F20=0,0,L20/F20) -> 104.5525 | P20: =M20+N20+O20 -> 7693.5667 | Q20: =COUNTIF(COMPOSICIÓN!$A:$A,A20) -> 14 | R20: EQ: EQ-EQUIPI ok. EQ-ESCPINT cant=1 agregado (fila nueva). MAT +0.24% residual: redondeo float APU $4251.394 vs GDR $4251.40. | S20: APU | T20: 2880.1573 | U20: 4708.8569 | V20: 104.5525
A21: PIN-146 | B21: 146 | C21: PINTURA | D21: Látex interior para paredes (s/enduido) | E21: m2 | F21: 25 | G21: 0 | H21: 0 | I21: 1 | J21: =SUMIFS(COMPOSICIÓN!J$2:J$1892,COMPOSICIÓN!A$2:A$1892,A21,COMPOSICIÓN!B$2:B$1892,"MAT") -> 2664.568 | K21: =SUMIFS(COMPOSICIÓN!J$2:J$1892,COMPOSICIÓN!A$2:A$1892,A21,COMPOSICIÓN!B$2:B$1892,"MO")*I21 -> 94177.138 | L21: =SUMIFS(COMPOSICIÓN!J$2:J$1892,COMPOSICIÓN!A$2:A$1892,A21,COMPOSICIÓN!B$2:B$1892,"EQ") -> 2091.05 | M21: =J21 -> 2664.568 | N21: =IF(F21=0,0,K21/F21) -> 3767.0855 | O21: =IF(F21=0,0,L21/F21) -> 83.641998 | P21: =M21+N21+O21 -> 6515.2955 | Q21: =COUNTIF(COMPOSICIÓN!$A:$A,A21) -> 11 | R21: EQ: EQ-EQUIPI ok. EQ-ESCPINT cant=1 agregado (fila nueva). | S21: APU | T21: 2664.568 | U21: 3767.0855 | V21: 83.641998
A22: PRE-032 | B22: 32 | C22: MOVIMIENTO DE TIERRA | D22: Movimiento de suelos para bases c/ aporte de tosca (e: 40 cm en 2 capas de 20 cm) | E22: m3 | F22: 25 | G22: 0 | H22: 0 | I22: 1 | J22: =SUMIFS(COMPOSICIÓN!J$2:J$1892,COMPOSICIÓN!A$2:A$1892,A22,COMPOSICIÓN!B$2:B$1892,"MAT") -> 12754.673 | K22: =SUMIFS(COMPOSICIÓN!J$2:J$1892,COMPOSICIÓN!A$2:A$1892,A22,COMPOSICIÓN!B$2:B$1892,"MO")*I22 -> 166309.28 | L22: =SUMIFS(COMPOSICIÓN!J$2:J$1892,COMPOSICIÓN!A$2:A$1892,A22,COMPOSICIÓN!B$2:B$1892,"EQ") -> 1005000 | M22: =J22 -> 12754.673 | N22: =IF(F22=0,0,K22/F22) -> 6652.371 | O22: =IF(F22=0,0,L22/F22) -> 40200 | P22: =M22+N22+O22 -> 59607.044 | Q22: =COUNTIF(COMPOSICIÓN!$A:$A,A22) -> 4 | R22: EQ: EQ-PTO087 vida corregida 1año(360d)→1día; APU P-32 usa alquiler diario dep=1 → $1,005,000/día. EQ/ud=$40,200. | S22: APU | T22: 12754.673 | U22: 6652.371 | V22: 40200
A23: ALB-033 | B23: 33 | C23: MAMPOSTERÍA | D23: Ladrillo común 12,5 x 5,5 x 25 (e:15 cm) | E23: m2 | F23: 7 | G23: 0 | H23: 0 | I23: 1 | J23: =SUMIFS(COMPOSICIÓN!J$2:J$1892,COMPOSICIÓN!A$2:A$1892,A23,COMPOSICIÓN!B$2:B$1892,"MAT") -> 14000.877 | K23: =SUMIFS(COMPOSICIÓN!J$2:J$1892,COMPOSICIÓN!A$2:A$1892,A23,COMPOSICIÓN!B$2:B$1892,"MO")*I23 -> 161417.64 | L23: =SUMIFS(COMPOSICIÓN!J$2:J$1892,COMPOSICIÓN!A$2:A$1892,A23,COMPOSICIÓN!B$2:B$1892,"EQ") -> 3836.7078 | M23: =J23 -> 14000.877 | N23: =IF(F23=0,0,K23/F23) -> 23059.662 | O23: =IF(F23=0,0,L23/F23) -> 548.10112 | P23: =M23+N23+O23 -> 37608.641 | Q23: =COUNTIF(COMPOSICIÓN!$A:$A,A23) -> 11 | S23: APU | T23: 14000.877 | U23: 23059.662 | V23: 548.10112
A24: ALB-034 | B24: 34 | C24: MAMPOSTERÍA | D24: Ladrillo cerámico 8 x 18 x 33 cm | E24: m2 | F24: 15 | G24: 0 | H24: 0 | I24: 1 | J24: =SUMIFS(COMPOSICIÓN!J$2:J$1892,COMPOSICIÓN!A$2:A$1892,A24,COMPOSICIÓN!B$2:B$1892,"MAT") -> 10053.788 | K24: =SUMIFS(COMPOSICIÓN!J$2:J$1892,COMPOSICIÓN!A$2:A$1892,A24,COMPOSICIÓN!B$2:B$1892,"MO")*I24 -> 161417.64 | L24: =SUMIFS(COMPOSICIÓN!J$2:J$1892,COMPOSICIÓN!A$2:A$1892,A24,COMPOSICIÓN!B$2:B$1892,"EQ") -> 3836.7078 | M24: =J24 -> 10053.788 | N24: =IF(F24=0,0,K24/F24) -> 10761.176 | O24: =IF(F24=0,0,L24/F24) -> 255.78052 | P24: =M24+N24+O24 -> 21070.744 | Q24: =COUNTIF(COMPOSICIÓN!$A:$A,A24) -> 11 | S24: APU | T24: 10053.788 | U24: 10761.176 | V24: 255.78052
A25: ALB-035 | B25: 35 | C25: MAMPOSTERÍA | D25: Ladrillo cerámico 12 x 18 x 33 cm | E25: m2 | F25: 15 | G25: 0 | H25: 0 | I25: 1 | J25: =SUMIFS(COMPOSICIÓN!J$2:J$1892,COMPOSICIÓN!A$2:A$1892,A25,COMPOSICIÓN!B$2:B$1892,"MAT") -> 12465.038 | K25: =SUMIFS(COMPOSICIÓN!J$2:J$1892,COMPOSICIÓN!A$2:A$1892,A25,COMPOSICIÓN!B$2:B$1892,"MO")*I25 -> 161417.64 | L25: =SUMIFS(COMPOSICIÓN!J$2:J$1892,COMPOSICIÓN!A$2:A$1892,A25,COMPOSICIÓN!B$2:B$1892,"EQ") -> 3836.7078 | M25: =J25 -> 12465.038 | N25: =IF(F25=0,0,K25/F25) -> 10761.176 | O25: =IF(F25=0,0,L25/F25) -> 255.78052 | P25: =M25+N25+O25 -> 23481.994 | Q25: =COUNTIF(COMPOSICIÓN!$A:$A,A25) -> 10 | S25: APU | T25: 12465.038 | U25: 10761.176 | V25: 255.78052
A26: ALB-036 | B26: 36 | C26: MAMPOSTERÍA | D26: Ladrillo cerámico 18 x 18 x 33 cm | E26: m2 | F26: 15 | G26: 0 | H26: 0 | I26: 1 | J26: =SUMIFS(COMPOSICIÓN!J$2:J$1892,COMPOSICIÓN!A$2:A$1892,A26,COMPOSICIÓN!B$2:B$1892,"MAT") -> 17538.995 | K26: =SUMIFS(COMPOSICIÓN!J$2:J$1892,COMPOSICIÓN!A$2:A$1892,A26,COMPOSICIÓN!B$2:B$1892,"MO")*I26 -> 161417.64 | L26: =SUMIFS(COMPOSICIÓN!J$2:J$1892,COMPOSICIÓN!A$2:A$1892,A26,COMPOSICIÓN!B$2:B$1892,"EQ") -> 3836.7078 | M26: =J26 -> 17538.995 | N26: =IF(F26=0,0,K26/F26) -> 10761.176 | O26: =IF(F26=0,0,L26/F26) -> 255.78052 | P26: =M26+N26+O26 -> 28555.952 | Q26: =COUNTIF(COMPOSICIÓN!$A:$A,A26) -> 11 | S26: APU | T26: 17538.995 | U26: 10761.176 | V26: 255.78052
A27: ALB-037 | B27: 37 | C27: MAMPOSTERÍA | D27: Pared DOBLE Comun / 5 / LHC 08 - (ladrillo a la vista) | E27: m2 | F27: 4 | G27: 0 | H27: 0 | I27: 1 | J27: =SUMIFS(COMPOSICIÓN!J$2:J$1892,COMPOSICIÓN!A$2:A$1892,A27,COMPOSICIÓN!B$2:B$1892,"MAT") -> 31798.204 | K27: =SUMIFS(COMPOSICIÓN!J$2:J$1892,COMPOSICIÓN!A$2:A$1892,A27,COMPOSICIÓN!B$2:B$1892,"MO")*I27 -> 155365.99 | L27: =SUMIFS(COMPOSICIÓN!J$2:J$1892,COMPOSICIÓN!A$2:A$1892,A27,COMPOSICIÓN!B$2:B$1892,"EQ") -> 3836.7078 | M27: =J27 -> 31798.204 | N27: =IF(F27=0,0,K27/F27) -> 38841.498 | O27: =IF(F27=0,0,L27/F27) -> 959.17696 | P27: =M27+N27+O27 -> 71598.879 | Q27: =COUNTIF(COMPOSICIÓN!$A:$A,A27) -> 16 | S27: APU | T27: 31798.204 | U27: 38841.498 | V27: 959.17696
