Workbook

Sheet README
A1: PRESUPUESTO UNIFICADO GDR 3760 — APU + Presupuesto
A3: OBJETIVO
A4: Modelo unificado donde cada partida del presupuesto está vinculada a una fila en PARTIDAS,
A5: y cada partida está alimentada por filas en COMPOSICIÓN (materiales, mano de obra, equipos).
A6: Estructura formula-pure, sin macros, vinculada por VLOOKUP/SUMIFS a tablas maestras de insumos.
A8: OBJETIVO PRIMARIO: Reconstruir correctamente la composición técnica real de cada partida,
A9: manteniendo trazabilidad de materiales, mano de obra, equipos, subcontratos, consumibles,
A10: desperdicios y relaciones entre partidas/APUs. Igualar el costo del GDR original es secundario.
A12: REGLAS ESTRUCTURALES DEL MODELO
A14: REGLA 1 — PRIORIDAD DE TRAZABILIDAD DE COMPOSICIÓN
A15: Siempre revisar de dónde viene el costo unitario de cada partida del presupuesto original.
A16: Orden de prioridad:
... A158: Los hallazgos detectados se documentan en la hoja OBSERVACIONES.

Sheet CONFIG
A1: CONFIGURACIÓN DEL APU
A3: Parámetro | B3: Valor | C3: Notas
A4: Mes de referencia | B4: Diciembre | C4: Mes de precios del APU
A5: Año de referencia | B5: 2024
A6: Versión | B6: v7.0 — Migración a APU 12-24 + Presupuesto GDR 3760 unificado
A7: GG% | B7: 0 | C7: 0 = se aplica en presupuesto de obra
A8: BB% | B8: 0 | C8: 0 = se aplica en presupuesto de obra
A9: Tipo Cambio USD (MEP) | B9: 1500 | C9: Pesos por dólar
A10: Revisado por | B10: MC | C10: Según archivo original
A11: Mes base CAC | B11: Diciembre 2024 | C11: Mes base para normalización de precios
A12: CAC base (valor) | B12: 13278 | C12: Índice CAC Diciembre 2024 (referencial — verificar)
A14: TABLA DE CARGAS MO
A15: Componente | B15: Tipo | C15: Valor | D15: Fuente
A16: Cargas patronales | B16: % | C16: 0.42 | D16: Convenio UOCRA (estimado)
A17: ART | B17: % | C17: 0.085 | D17: Aseguradora (estimado)
A18: Ropa de trabajo | B18: $/mes | C18: 85000 | D18: Compras (estimado)
A19: Viáticos | B19: $/día | C19: 3200 | D19: Convenio UOCRA (estimado)
A20: Vacaciones + SAC | B20: % | C20: 0.15 | D20: Cálculo legal (estimado)
A22: COEFICIENTE FINAL | B22: multiplicador | C22: =1+C16+C17+C20+(C18/78291/22)+(C19/78291) -> 1.7452228
A24: CONTROLES DE INTEGRIDAD
A25: Duplicados MATERIALES | B25: =SUMPRODUCT((COUNTIF(MATERIALES!$A$2:$A$200,MATERIALES!$A$2:$A$200)>1)*(MATERIALES!$A$2:$A$200<>"")) -> 0 | C25: =IF(B25>0,"¡DUPLICADOS DETECTADOS!","OK") -> OK
A26: Duplicados MANO_DE_OBRA | B26: =SUMPRODUCT((COUNTIF(MANO_DE_OBRA!$A$2:$A$11,MANO_DE_OBRA!$A$2:$A$11)>1)*(MANO_DE_OBRA!$A$2:$A$11<>"")) -> 0 | C26: =IF(B26>0,"¡DUPLICADOS DETECTADOS!","OK") -> OK
A27: Duplicados EQUIPOS | B27: =SUMPRODUCT((COUNTIF(EQUIPOS!$A$2:$A$50,EQUIPOS!$A$2:$A$50)>1)*(EQUIPOS!$A$2:$A$50<>"")) -> 0 | C27: =IF(B27>0,"¡DUPLICADOS DETECTADOS!","OK") -> OK
A28: Duplicados PARTIDAS | B28: =SUMPRODUCT((COUNTIF(PARTIDAS!$A$2:$A$198,PARTIDAS!$A$2:$A$198)>1)*(PARTIDAS!$A$2:$A$198<>"")) -> 0 | C28: =IF(B28>0,"¡DUPLICADOS DETECTADOS!","OK") -> OK
A30: INTEGRIDAD REFERENCIAL
A31: MAT sin match en MATERIALES | B31: {=SUMPRODUCT((COMPOSICIÓN!B$2:B$1838="MAT")*(COMPOSICIÓN!C$2:C$1838<>"")*(ISNA(MATCH(COMPOSICIÓN!C$2:C$1838,MATERIALES!$A$2:$A$200,0))))} -> 1032 | C31: =IF(B31>0,"¡REFS ROTAS!","OK") -> ¡REFS ROTAS!
A32: MO sin match en MANO_DE_OBRA | B32: {=SUMPRODUCT((COMPOSICIÓN!B$2:B$1838="MO")*(COMPOSICIÓN!C$2:C$1838<>"")*(ISNA(MATCH(COMPOSICIÓN!C$2:C$1838,MANO_DE_OBRA!$A$2:$A$11,0))))} -> 432 | C32: =IF(B32>0,"¡REFS ROTAS!","OK") -> ¡REFS ROTAS!
A33: EQ sin match en EQUIPOS | B33: {=SUMPRODUCT((COMPOSICIÓN!B$2:B$1838="EQ")*(COMPOSICIÓN!C$2:C$1838<>"")*(ISNA(MATCH(COMPOSICIÓN!C$2:C$1838,EQUIPOS!$A$2:$A$50,0))))} -> 0 | C33: =IF(B33>0,"¡REFS ROTAS!","OK") -> OK

Sheet MATERIALES
A1: Código | B1: Descripción | C1: Unidad | D1: Precio $ | E1: Proveedor | F1: Fecha Cotiz. | G1: Categoría | H1: Cód. Original | I1: Nota | J1: Alerta
A2: AGR-001 | B2: ARENA LAVADA | C2: m3 | D2: 32399.77 | E2: Cutuli Hnos | F2: 2024-11-29 | G2: Corralón | H2: *AGREG02 | I2: BOLSÓN | J2: =IF(F2="","SIN FECHA","")
A3: AGR-002 | B3: Piedra Partida | C3: m3 | D3: 56202.3 | E3: Cutuli Hnos | F3: 2024-11-29 | G3: Corralón | I3: BOLSÓN | J3: =IF(F3="","SIN FECHA","")
A4: AGR-003 | B4: Cascote | C4: m3 | D4: 34246.8 | E4: Cutuli Hnos | F4: 2024-11-29 | G4: Corralón | I4: BOLSÓN | J4: =IF(F4="","SIN FECHA","")
A5: AGR-004 | B5: Cemento Portland x 50kg | C5: Bol | D5: 7809.48 | E5: Cutuli Hnos | F5: 2024-11-29 | G5: Corralón | H5: *AGREG01 | I5: CEMENTO AVELLANEDA | J5: =IF(F5="","SIN FECHA","")
A6: AGR-005 | B6: Cal Comun x 25kg | C6: bol | D6: 3837.96 | E6: Cutuli Hnos | F6: 2024-11-29 | G6: Corralón | H6: AGREG11 | J6: =IF(F6="","SIN FECHA","")
A7: AGR-006 | B7: cal milagro | C7: bol | D7: 10936.8 | E7: Cutuli Hnos | F7: 2024-11-29 | G7: Corralón | H7: CALMILAG | J7: =IF(F7="","SIN FECHA","")
A8: ACE-001 | B8: Barra de Acero Aleteado - 6mm x 12m | C8: u | D8: 3424.53 | E8: Cutuli Hnos | F8: 2024-11-29 | G8: Corralón | H8: FE06 | J8: =IF(F8="","SIN FECHA","")
A9: ACE-002 | B9: Barra de Acero Aleteado - 8mm x 12m | C9: u | D9: 6017.04 | E9: Cutuli Hnos | F9: 2024-11-29 | G9: Corralón | J9: =IF(F9="","SIN FECHA","")
A10: ACE-003 | B10: Barra de Acero Aleteado - 10mm x 12m | C10: u | D10: 9272.75 | E10: Cutuli Hnos | F10: 2024-11-29 | G10: Corralón | J10: =IF(F10="","SIN FECHA","")
A11: ACE-004 | B11: Barra de Acero Aleteado - 12mm x 12m | C11: u | D11: 13312.25 | E11: Cutuli Hnos | F11: 2024-11-29 | G11: Corralón | J11: =IF(F11="","SIN FECHA","")
A12: ACE-005 | B12: Barra de Acero Aleteado - 16mm x 12m | C12: u | D12: 23236.16 | E12: Cutuli Hnos | F12: 2024-11-29 | G12: Corralón | J12: =IF(F12="","SIN FECHA","")
A13: ACE-006 | B13: Barra de Acero Aleteado - 20mm x 12m | C13: u | D13: 36391.64 | E13: Cutuli Hnos | F13: 2024-11-29 | G13: Corralón | J13: =IF(F13="","SIN FECHA","")
A14: ACE-007 | B14: Barra de Acero Aleteado - 25mm x 12m | C14: u | D14: 56794.12 | E14: Cutuli Hnos | F14: 2024-11-29 | G14: Corralón | J14: =IF(F14="","SIN FECHA","")
A15: CER-001 | B15: ladrillo a la vista 1 cara | C15: u | D15: 233.44 | E15: Cutuli Hnos | F15: 2024-11-29 | G15: Corralón | H15: LADVISTA | I15: 1/2 VISTA MDQ | J15: =IF(F15="","SIN FECHA","")
A16: CER-002 | B16: LADRILLO CERAMICO 8 x 18 x 33 cm | C16: u | D16: 292.32 | E16: Cutuli Hnos | F16: 2024-11-29 | G16: Corralón | H16: *LADRI03 | J16: =IF(F16="","SIN FECHA","")
A17: CER-003 | B17: LADRILLO CERAMICO 12 x 18 x 33 cm | C17: u | D17: 365.4 | E17: Cutuli Hnos | F17: 2024-11-29 | G17: Corralón | H17: LADRI12 | I17: 9 AGUJEROS | J17: =IF(F17="","SIN FECHA","")
A18: CER-004 | B18: LADRILLO CERAMICO 18 x 18 x 33 cm | C18: u | D18: 519.12 | E18: Cutuli Hnos | F18: 2024-11-29 | G18: Corralón | H18: LADRI181 | J18: =IF(F18="","SIN FECHA","")
A19: CER-005 | B19: Ladrillo Comun 12.5 x 5.5 x 25 | C19: u | D19: 132.3 | E19: Cutuli Hnos | F19: 2024-11-29 | G19: Corralón | H19: LADRIC | J19: =IF(F19="","SIN FECHA","")
A20: CER-006 | B20: Ladrillo hueco ceramico 12x19x33 - Portante | C20: u | D20: 563.22 | E20: Cutuli Hnos | F20: 2024-11-29 | G20: Corralón | H20: LADRI182 | J20: =IF(F20="","SIN FECHA","")
A21: CER-007 | B21: Ladrillo hueco ceramico 18x19x33 - Portante | C21: u | D21: 694.26 | E21: Cutuli Hnos | F21: 2024-11-29 | G21: Corralón | J21: =IF(F21="","SIN FECHA","")
A22: BLO-001 | B22: Bloque de Hormigon 19 x 19 x 39 | C22: u | D22: 1016.6 | E22: Cutuli Hnos | F22: 2024-11-29 | G22: Corralón | J22: =IF(F22="","SIN FECHA","")
A23: BLO-002 | B23: Bloque de Hormigon 10 x 19 x 39 | C23: u | D23: 682.52 | E23: Cutuli Hnos | F23: 2024-11-29 | G23: Corralón | J23: =IF(F23="","SIN FECHA","")
A24: ADH-001 | B24: Adhesivo Klaukol Porcellanato Fluido x 30Kg | C24: bol | D24: 18802.512 | E24: Cutuli Hnos | F24: 2024-11-29 | G24: Adhesivos y pastinas | H24: *AGREG11 | I24: WEBER FORTE PORCELLANATO X 25 KG | J24: =IF(F24="","SIN FECHA","")
A25: ADH-002 | B25: Adhesivo Klaukol Impermeable Petenciado x 30Kg | C25: bol | D25: 29811.732 | E25: Cutuli Hnos | F25: 2024-11-29 | G25: Adhesivos y pastinas | I25: WEBER SUPLER FLEX 25 KG | J25: =IF(F25="","SIN FECHA","")
A26: AIS-001 | B26: Aditivo Hidrofugo en pasta - Ceresita x 1kg | C26: kg | D26: 1256.128 | E26: Cutuli Hnos | F26: 2024-11-29 | G26: Impermeabilizantes | H26: AGREG07 | I26: CERESITA X 20 LTS | J26: =IF(F26="","SIN FECHA","")
A27: REV-001 | B27: Yeso Tuyango x 30kg | C27: b | D27: 9639 | E27: Cutuli Hnos | F27: 2024-11-29 | G27: Revestimientos y yesos | H27: PINT015 | J27: =IF(F27="","SIN FECHA","")
A28: ADH-003 | B28: Pastina Klaukol x 1kg - Alta performance | C28: u | D28: 3214.35 | E28: Cutuli Hnos | F28: 2024-11-29 | G28: Adhesivos y pastinas | I28: Prestige nieve | J28: =IF(F28="","SIN FECHA","")
A29: REV-002 | B29: Promex E x 30 kg (3 en 1 proyectable exterior) | C29: bol | D29: 6683.37 | E29: Cutuli Hnos | F29: 2024-12-05 | G29: Revestimientos y yesos | I29: PROMEX E X 30 [Deflactado v6/1.27] | J29: =IF(F29="","SIN FECHA","")
A30: REV-003 | B30: Promex I x 30 kg (2 en 1 proyectable interior) | C30: bol | D30: 5260 | E30: Cutuli Hnos | F30: 2024-12-05 | G30: Revestimientos y yesos | I30: [Deflactado v6/1.27] | J30: =IF(F30="","SIN FECHA","")
A31: ACE-008 | B31: Malla SIMA Q335 (8mm) | C31: u | D31: 126755.8 | E31: Cutuli Hnos | F31: 2024-11-29 | G31: Corralón | J31: =IF(F31="","SIN FECHA","")
A32: ACE-009 | B32: Malla SIMA Q188 (6mm) | C32: u | D32: 69985.79 | E32: Cutuli Hnos | F32: 2024-11-29 | G32: Corralón | J32: =IF(F32="","SIN FECHA","")
A33: ACE-010 | B33: Alambre de Fardo | C33: kg | D33: 2302.02 | E33: Cutuli Hnos | F33: 2024-11-29 | G33: Corralón | I33: Alambre N°16 | J33: =IF(F33="","SIN FECHA","")
A34: ADT-001 | B34: Sika Poro Plus x 10 kg | C34: b | D34: 252066.12 | E34: ML | F34: 2024-12-05 | G34: Impermeabilizantes | I34: https://articulo.mercadolibre.com.ar/MLA-1239468887-sika-poro-plus-espumigeno-para-hormigon-10-kg-_JM#polycard_client=search-nordic&position=11&search_layout=grid&type=item&tracking_id=c5802d9e-4804-403a-958c-824dd473f5b4 | J34: =IF(F34="","SIN FECHA","")
A35: BLO-003 | B35: Bloque HCCA Brimax 5 x 20 x 60 | C35: u | D35: 1140.68 | E35: Cutuli Hnos | F35: 2024-12-05 | G35: Corralón | I35: BRIMAX (Pallet 260 u) [Deflactado v6/1.27] | J35: =IF(F35="","SIN FECHA","")
A36: BLO-004 | B36: Bloque HCCA Brimax 7,5 x 20 x 60 | C36: u | D36: 1516.11 | E36: Cutuli Hnos | F36: 2024-12-05 | G36: Corralón | I36: BRIMAX (Pallet 200 u) [Deflactado v6/1.27] | J36: =IF(F36="","SIN FECHA","")
A37: BLO-005 | B37: Bloque HCCA Brimax 10 x 20 x 60 | C37: u | D37: 2003.62 | E37: Cutuli Hnos | F37: 2024-12-05 | G37: Corralón | I37: BRIMAX (Pallet 150 u) [Deflactado v6/1.27] | J37: =IF(F37="","SIN FECHA","")
A38: BLO-006 | B38: Bloque HCCA Brimax 12,5 x 20 x 60 | C38: u | D38: 2504.53 | E38: Cutuli Hnos | F38: 2024-12-05 | G38: Corralón | I38: BRIMAX (Pallet 120 u) [Deflactado v6/1.27] | J38: =IF(F38="","SIN FECHA","")
A39: BLO-007 | B39: Bloque HCCA Brimax 15 x 20 x 60 | C39: u | D39: 3094.7 | E39: Cutuli Hnos | F39: 2024-12-05 | G39: Corralón | I39: BRIMAX (Pallet 100 u) [Deflactado v6/1.27] | J39: =IF(F39="","SIN FECHA","")
A40: BLO-008 | B40: Bloque HCCA Brimax 17,5 x 20 x 60 | C40: u | D40: 3625.36 | E40: Cutuli Hnos | F40: 2024-12-05 | G40: Corralón | I40: BRIMAX (Pallet 80 u) [Deflactado v6/1.27] | J40: =IF(F40="","SIN FECHA","")
...

Sheet MANO_DE_OBRA
A1: Código | B1: Descripción | C1: Salario/día $ | D1: Coef. Cargas | E1: Costo Jornal $ | F1: Tipo | G1: Cód. Original
A2: MO-TOP | B2: TOPOGRAFO | C2: 171854.19 | D2: =CONFIG!C22 -> 1.7452228 | E2: =C2*D2 -> 299923.87 | F2: Operativo | G2: *TOPOGRA
A3: MO-EESPE | B3: ESPECIALIZADO | C3: 85927.097 | D3: =CONFIG!C22 -> 1.7452228 | E3: =C3*D3 -> 149961.93 | F3: Estructura | G3: EST-ESPE
A4: MO-EOFIC | B4: OFICIAL | C4: 76955.08 | D4: =CONFIG!C22 -> 1.7452228 | E4: =C4*D4 -> 134303.76 | F4: Estructura | G4: EST-OFIC
A5: MO-EMEDI | B5: MEDIO OFICIAL | C5: 65493.072 | D5: =CONFIG!C22 -> 1.7452228 | E5: =C5*D5 -> 114300 | F5: Estructura | G5: EST-MEDI
A6: MO-EAYUD | B6: AYUDANTE | C6: 60860.581 | D6: =CONFIG!C22 -> 1.7452228 | E6: =C6*D6 -> 106215.28 | F6: Estructura | G6: EST-AYUD
A7: ── ESTRUCTURA GERENCIAL — NO USAR EN APU ──
A8: MO-ESOBR | B8: SOBRESTANTE | C8: 3009340.6 | D8: =CONFIG!C22 -> 1.7452228 | E8: =C8*D8 -> 5251969.9 | F8: Estructura | G8: EST-SOBR
A9: MO-EJEFE | B9: JEFE DE OBRA | C9: 4372210.6 | D9: =CONFIG!C22 -> 1.7452228 | E9: =C9*D9 -> 7630481.8 | F9: Estructura | G9: EST-JEFE
A10: MO-ECOOR | B10: COORD OBRAS | C10: 5273644.1 | D10: =CONFIG!C22 -> 1.7452228 | E10: =C10*D10 -> 9203684.1 | F10: Estructura | G10: EST-COOR
F11: Estructura | G11: EST-CAPA

Sheet EQUIPOS
A1: Código | B1: Descripción | C1: Costo Total Set $ | D1: Vida (años) | E1: Vida (días) | F1: $/día | G1: Categoría | H1: Cód. Original
A2: EQ-ANDAM0 | B2: ANDAMIO TUBULAR DE UNO A TRES CUERPOS | C2: 1028123.1 | D2: 5 | E2: =D2*360 -> 1800 | F2: =IF(E2=0,0,C2/E2) -> 571.17949 | G2: Equipo propio | H2: *ANDAM05
A3: EQ-EQALBA | B3: EQUIPO DE ALBAÑILERIA, carpetas, ladrillo | C3: 2470106.6 | D3: 3 | E3: =D3*360 -> 1080 | F3: =IF(E3=0,0,C3/E3) -> 2287.1357 | G3: Equipo propio | H3: EQALBA
A4: EQ-EQCERA | B4: EQUIPO PARA COLOCACION DE CERAMICA | C4: 1424056.6 | D4: 1.5 | E4: =D4*360 -> 540 | F4: =IF(E4=0,0,C4/E4) -> 2637.1418 | G4: Equipo propio | H4: EQCERAMI
A5: EQ-EQUIP0 | B5: EQUIPO PARA INSTALACION ELECTRICA | C5: 2734071.2 | D5: 1.5 | E5: =D5*360 -> 540 | F5: =IF(E5=0,0,C5/E5) -> 5063.0948 | G5: Equipo propio | H5: *EQUIP09
A6: EQ-EQUIPI | B6: EQUIPO PARA PINTAR | C6: 1241010.7 | D6: 2 | E6: =D6*360 -> 720 | F6: =IF(E6=0,0,C6/E6) -> 1723.626 | G6: Equipo propio | H6: *EQUIPIN
A7: EQ-EQPLOM | B7: EQUIPO PARA PLOMERIA | C7: 2058254 | D7: 2 | E7: =D7*360 -> 720 | F7: =IF(E7=0,0,C7/E7) -> 2858.6861 | G7: Equipo propio | H7: EQPLOME
A8: EQ-HORMI | B8: EQUIPO PARA HORMIGON | C8: 3739856.7 | D8: 1.5 | E8: =D8*360 -> 540 | F8: =IF(E8=0,0,C8/E8) -> 6925.6605 | G8: Equipo propio | H8: *EQUIP02
A9: EQ-TROMPO | B9: Hormigonera De 150 Litros 1hp Con Rueda Maciza | C9: 689222.3 | D9: 2 | E9: =D9*360 -> 720 | F9: =IF(E9=0,0,C9/E9) -> 957.2532 | G9: Equipo propio | H9: TROMPO
A10: EQ-SOLD00 | B10: Soldador Soplete A Gas Techista Membrana 10 Kg Boca 50mm | C10: 579244.09 | D10: 2 | E10: =D10*360 -> 720 | F10: =IF(E10=0,0,C10/E10) -> 804.50569 | G10: Equipo propio | H10: SOLD003
A11: EQ-CORTA | B11: CORTADORA CERAMICA PROFESIONAL 1200MM (PORCELANATO HASTA 16MM) | C11: 537162.92 | D11: 5 | E11: =D11*360 -> 1800 | F11: =IF(E11=0,0,C11/E11) -> 298.42384 | G11: Equipo propio | H11: EQCERAMI02
A12: EQ-ESCALE | B12: ESCALERA GLOSS ALUMINIO ARTICULADA 4 X 4 ESCALONES HASTA 150KG | C12: 201885.25 | D12: 4 | E12: =D12*360 -> 1440 | F12: =IF(E12=0,0,C12/E12) -> 140.19809 | G12: Equipo propio | H12: *ESCALE1
A13: EQ-SILLET | B13: Kit Complementario Silleta Descensor Conector Soga X 50 Mts | C13: 683705.75 | D13: 1 | E13: =D13*360 -> 360 | F13: =IF(E13=0,0,C13/E13) -> 1899.1826 | G13: Equipo propio | H13: SILLETA
... A18: EQ-KITPIN | B18: Kit de pintura completo | C18: 1468137.4 | D18: 3 | E18: =D18*360 -> 1080 | F18: =IF(E18=0,0,C18/E18) -> 1359.3865 | G18: Equipo propio | H18: *KITPINT
A19: EQ-REVOC | B19: Máquina revocadora proyectable - Alquiler mensual | C19: 976113.01 | E19: 30 | F19: =IF(E19=0,0,C19/E19) -> 32537.1 | G19: Equipo propio | H19: SIN_COD
A20: EQ-FRAT36 | B20: FRATACHADORA MASTERPAC PMT36H - Alq. X dia | C20: 61876.7 | E20: 1 | F20: =IF(E20=0,0,C20/E20) -> 61876.7 | G20: Alquiler diario | H20: ALQ_DIARIO
A21: EQ-FRAT24 | B21: FRATACHADORA MASALTA MT24-2 - Alq. X dia | C21: 72723.2 | E21: 1 | F21: =IF(E21=0,0,C21/E21) -> 72723.2 | G21: Alquiler diario | H21: ALQ_DIARIO
A22: EQ-REVOC2 | B22: Maquina revocadora Revoque/Yeso - Alq. X mes | C22: 1230000 | E22: 30 | F22: =IF(E22=0,0,C22/E22) -> 41000 | G22: Equipo propio | H22: ALQ_DIARIO
A23: EQ-COMBB | B23: Combustible bobcat (36 lts) | C23: 40428 | E23: 1 | F23: =IF(E23=0,0,C23/E23) -> 40428 | G23: Alquiler diario | H23: ALQ_DIARIO
A24: EQ-COMBPR | B24: Combustible Pala y Retro (60 lts) | C24: 67380 | E24: 1 | F24: =IF(E24=0,0,C24/E24) -> 67380 | G24: Alquiler diario | H24: ALQ_DIARIO
A25: EQ-CARG2M | B25: Pala cargadora frontal (2 m) 936 - (c/ operario y combustible) - Alq. X dia | C25: 506170 | E25: 1 | F25: =IF(E25=0,0,C25/E25) -> 506170 | G25: Alquiler diario | H25: ALQ_DIARIO
A26: EQ-CARG3M | B26: Pala cargadora frontal (3 m) 950 - (c/ operario y combustible) - Alq. X dia | C26: 588810 | E26: 1 | F26: =IF(E26=0,0,C26/E26) -> 588810 | G26: Alquiler diario | H26: ALQ_DIARIO
A27: EQ-COMPCT | B27: Compactador pata de cabra 612H - (c/operario y combustible) - Alq. X dia | C27: 568150 | E27: 1 | F27: =IF(E27=0,0,C27/E27) -> 568150 | G27: Alquiler diario | H27: ALQ_DIARIO
A28: EQ-EXCAV | B28: Excavador sobre orugas PC-200 - (c/operario y combustible) - Alq. X dia | C28: 878050 | E28: 1 | F28: =IF(E28=0,0,C28/E28) -> 878050 | G28: Alquiler diario | H28: ALQ_DIARIO
A29: EQ-MOTON | B29: Motoniveladora 120H - (c/operario y combustible) - Alq. X dia | C29: 929700 | E29: 1 | F29: =IF(E29=0,0,C29/E29) -> 929700 | G29: Alquiler diario | H29: ALQ_DIARIO
A30: EQ-VOLC | B30: Camion chasis volcador 170E22 - (c/ operario y combustible) - Alq. X dia | C30: 258250 | E30: 1 | F30: =IF(E30=0,0,C30/E30) -> 258250 | G30: Alquiler diario | H30: ALQ_DIARIO
... A34: EQ-PALA310 | B34: Pala y retro 310J (c/ operario y combustible) | C34: 464850 | E34: 1 | F34: =IF(E34=0,0,C34/E34) -> 464850 | G34: Alquiler diario | H34: ALQ_DIARIO
A35: EQ-PTO001 | B35: Baño portatil / Ducha | C35: 1 | E35: 1 | F35: 79748.53 | G35: Herramientas — Preliminares | H35: Cotizaciones D47
A36: EQ-PTO002 | B36: Traslado flete entrega/ retiro | C36: 1 | E36: 1 | F36: 13291.422 | G36: Herramientas — Preliminares | H36: Cotizaciones D48
A37: EQ-PTO003 | B37: Alquiler vibropisson | C37: 1 | E37: 1 | F37: 65000 | G37: Herramientas — Hormigón | H37: Tareas/2.02 alquiler
A38: EQ-PTO004 | B38: Herramientas y consumibles Excavación manual para vigas de fundación | C38: 1 | E38: 1 | F38: 1302.9087 | G38: Herramientas — Hormigón | H38: PTO 2.03 (% s/MAT+MO)
A39: EQ-PTO005 | B39: Herramientas y consumibles Tabique submuración - H35 (95 kg/m3 de hierro) | C39: 1 | E39: 1 | F39: 11395.702 | G39: Herramientas — Hormigón | H39: PTO 3.03 (% s/MAT+MO)
A40: EQ-PTO006 | B40: Herramientas y consumibles Zapata corrida tabique - H35 (120 kg/m3 de hierro) | C40: 1 | E40: 1 | F40: 10647.458 | G40: Herramientas — Hormigón | H40: PTO 3.04 (% s/MAT+MO)
A41: EQ-PTO007 | B41: Herramientas y consumibles Platea - H35 (95 kg/m3 de hierro) | C41: 1 | E41: 1 | F41: 7920.4191 | G41: Herramientas — Hormigón | H41: PTO 3.05 (% s/MAT+MO)
A42: EQ-PTO008 | B42: Herramientas y consumibles Bases aisladas - (60 kg/m3 de hierro) | C42: 1 | E42: 1 | F42: 7040.5472 | G42: Herramientas — Hormigón | H42: PTO 3.06 (% s/MAT+MO)
A43: EQ-PTO009 | B43: Herramientas y consumibles Troncos de columnas - H35 (240 kg/m3 de hierro) | C43: 1 | E43: 1 | F43: 14296.601 | G43: Herramientas — Hormigón | H43: PTO 3.07 (% s/MAT+MO)
A44: EQ-PTO010 | B44: Herramientas y consumibles Viga de encadenado - H35 (180 kg/m3 de hierro) | C44: 1 | E44: 1 | F44: 12155.81 | G44: Herramientas — Hormigón | H44: PTO 3.08 (% s/MAT+MO)
A45: EQ-PTO011 | B45: Herramientas y consumibles Losa maciza - H35 (100 kg/m3 de hierro) | C45: 1 | E45: 1 | F45: 8915.6269 | G45: Herramientas — Hormigón | H45: PTO 3.09 (% s/MAT+MO)
A46: EQ-PTO012 | B46: Herramientas y consumibles Losa maciza de Hº visto - H35 (100 kg/m3 de hierro | C46: 1 | E46: 1 | F46: 9854.9599 | G46: Herramientas — Hormigón | H46: PTO 3.1 (% s/MAT+MO)
... A157: EQ-PTO123 | B157: Herramientas y consumibles - PTO-1832 Puesta tierra | C157: 1 | E157: 1 | F157: 10618.104 | G157: Herramientas — Instalaciones | H157: PTO-1832 EQ 1.5% s/MAT+MO

Sheet SUBCONTRATOS
A1: Rubro | B1: Tarea | C1: Contratista | D1: Ud. | E1: PU Actualizado $ | F1: Fecha Act. | G1: PU Original | H1: Fecha Orig.
A2: Colocacion | B2: Ceramico en pisos y pared | C2: Zotelo | D2: m2 | E2: 19490.499 | F2: 2025-09-19 | G2: 2000 | H2: 2022-10-01
A3: Colocacion | B3: Porcelanato en piso | C3: Zotelo | D3: m2 | E3: 17541.449 | F3: 2025-09-19 | G3: 1800 | H3: 2022-10-01
A4: Pintura | B4: Latex Mate | C4: Lionel | D4: m2 | E4: 6620.5651 | F4: 2025-09-19 | G4: 800 | H4: 2022-12-01
A5: Pintura | B5: Latex Mate s/ Pared + Enduido | C5: Lionel | D5: m2 | E5: 8275.7063 | F5: 2025-09-19 | G5: 1000 | H5: 2022-12-01
A6: Pintura | B6: Latex Mate s/ Cielorraso + Enduido | C6: Lionel | D6: m2 | E6: 8275.7063 | F6: 2025-09-19 | G6: 1000 | H6: 2022-12-01
A7: Pintura | B7: Latex Satinado s/ Pared + Enduido | C7: Lionel | D7: m2 | E7: 16551.413 | F7: 2025-09-19 | G7: 2000 | H7: 2022-12-01
A8: Pintura | B8: Latex Satinado s/ Cielorraso + Enduido | C8: Lionel | D8: m2 | E8: 16551.413 | F8: 2025-09-19 | G8: 2000 | H8: 2022-12-01
A9: Pintura | B9: Esmalte Sintetico | C9: Lionel | D9: m2 | E9: 10758.418 | F9: 2025-09-19 | G9: 1300 | H9: 2022-12-01
A10: Pintura | B10: Esmalte sintetico en Herrerias | C10: Lionel | D10: m2 | E10: 10758.418 | F10: 2025-09-19 | G10: 1300 | H10: 2022-12-01
A11: Pintura | B11: Tarquini | C11: Lionel | D11: m2 | E11: 12413.56 | F11: 2025-09-19 | G11: 1500 | H11: 2023-04-01
A12: Durlock | B12: Tabique simple | C12: Mario Silva | D12: m2 | E12: 28402.767 | F12: 2025-09-19 | G12: 2500 | H12: 2022-08-01
A13: Durlock | B13: Medio Forro | C13: Mario Silva | D13: m2 | E13: 20449.992 | F13: 2025-09-19 | G13: 1800 | H13: 2022-08-01
... A20: Yeso | B20: Aristas | C20: Miguel Galleguillo | D20: ml | E20: 6620.5651 | F20: 2025-09-19 | G20: 750 | H20: 2022-11-25
A21: Yeso | B21: Enlucidos en paredes | C21: Miguel Galleguillo | D21: m2 | E21: 13241.13 | F21: 2025-09-19
A22: Yeso | B22: Buñas | C22: Jorge Yesero (CDR) | D22: ml | E22: 6620.5651 | F22: 2025-09-19 | G22: 750 | H22: 2022-11-25
A23: Electrico | B23: Cableado x boca | C23: Demian | D23: u | E23: 14617.874 | F23: 2025-09-19 | G23: 1500 | H23: 2022-10-01
A24: Electrico | B24: Cableado x bandeja (cable 4x10mm x ml) | C24: Demian | D24: ml | E24: 14617.874 | F24: 2025-09-19 | G24: 1500 | H24: 2022-10-01
A25: Electrico | B25: Cañeria PVC (x boca) | C25: Demian | D25: u | E25: 29235.748 | F25: 2025-09-19 | G25: 3000 | H25: 2022-10-01
A26: Electrico | B26: Cañeria Metalica (x boca) | C26: Demian | D26: u | E26: 29235.748 | F26: 2025-09-19 | G26: 3000 | H26: 2022-10-01
A27: Electrico | B27: Cañeria EXT | C27: Demian | D27: ml | E27: 29235.748 | F27: 2025-09-19 | G27: 3000 | H27: 2022-10-01
A28: Electrico | B28: Bandeja 450/600 (xml) | C28: Demian | D28: ml | E28: 13156.087 | F28: 2025-09-19 | G28: 1350 | H28: 2022-10-01
A29: Electrico | B29: Colocacion Interruptores / Tomas | C29: Demian | D29: u | E29: 4872.6247 | F29: 2025-09-19 | G29: 500 | H29: 2022-10-01
A30: Electrico | B30: Colocacion de fichas / tomas de Telefono o TV | C30: Demian | D30: u | E30: 4872.6247 | F30: 2025-09-19 | G30: 500 | H30: 2022-10-01
A31: Electrico | B31: Colocacion de Artefactos tipo (aplique, extractores, campanillas, etc) | C31: Demian | D31: u | E31: 14617.874 | F31: 2025-09-19 | G31: 1500 | H31: 2022-10-01
A32: Electrico | B32: Armado de Tablero de Bombas | C32: Demian | D32: u | E32: 194904.99 | F32: 2025-09-19 | G32: 20000 | H32: 2022-10-01
A33: Electrico | B33: Portero Electrico hasta 2m | C33: Demian | D33: u | E33: 43853.622 | F33: 2025-09-19 | G33: 4500 | H33: 2022-10-01
... A42: Electrico | B42: Cable subterraneo (1 boca cada 5 metros) | C42: Demian | D42: b | E42: 34108.373 | F42: 2025-09-19 | G42: 3500 | H42: 2022-10-01

Sheet SUBCONTRATOS_PRY
A1: Código | B1: Descripción | C1: Ud | D1: Precio Unitario Dic-24 ($) | E1: Categoría | F1: Notas
A2: SUB-PRYELEC | B2: Proyecto instalacion electrica | C2: gl | D2: 1204015.5 | E2: Electricidad — Gestión | F2: GESTOR ELECTRICO
A3: SUB-BAJASUM | B3: Baja de suministros | C3: gl | D3: 49052.483 | E3: Electricidad — Gestión | F3: GESTOR ELECTRICO
A4: SUB-CORDEM | B4: Corte por demolicion | C4: gl | D4: 109996.48 | E4: Electricidad — Gestión | F4: GESTOR ELECTRICO
A5: SUB-INSDES | B5: Instalacion electrica desenergizada | C5: gl | D5: 135265.94 | E5: Electricidad — Gestión | F5: GESTOR ELECTRICO
A6: SUB-TRASLA | B6: Traslado de alumbrado publico | C6: gl | D6: 114455.79 | E6: Electricidad — Gestión | F6: GESTOR ELECTRICO
A7: SUB-FACTIB | B7: Factibilidad y renovacion | C7: gl | D7: 245262.41 | E7: Electricidad — Gestión | F7: GESTOR ELECTRICO
A8: SUB-CERTLUZ | B8: Gestion suministros luz de obra | C8: gl | D8: 148643.89 | E8: Electricidad — Gestión | F8: GESTOR ELECTRICO
A9: SUB-SALAMED | B9: Sala de medidores / Camara transformadora | C9: gl | D9: 520253.61 | E9: Electricidad — Gestión | F9: GESTOR ELECTRICO
A10: SUB-CERTLUZ2 | B10: Luz de Obra | C10: u | D10: 107023.6 | E10: Electricidad — Gestión | F10: Certificados
A11: SUB-CERTSGT1 | B11: Servicios grales T1 | C11: u | D11: 107023.6 | E11: Electricidad — Gestión | F11: Certificados
A12: SUB-CERTSGT2 | B12: Servicios grales T2 | C12: u | D12: 157562.52 | E12: Electricidad — Gestión | F12: Certificados
A13: SUB-CERTRES | B13: Residencial | C13: u | D13: 74321.944 | E13: Electricidad — Gestión | F13: Certificados
... A146: SUB-VIBRO3 | B146: Alquiler vibropison | C146: sem | D146: 250000 | E146: Varios | F146: MO/OTR PTO-1104/1105

Sheet PARTIDAS
A1: Código | B1: P# | C1: Rubro | D1: Descripción | E1: Ud. | F1: Rend. | G1: Cant Cons. | H1: % Cons. Desp. | I1: Grado Dif. | J1: MAT (sum/ud) | K1: MO (sum/día) | L1: EQ (sum/día) | M1: MAT/ud | N1: MO/ud | O1: EQ/ud | P1: CD/ud | Q1: # Comp. | R1: Fuente
A2: PRE-032 | B2: 32 | C2: MOVIMIENTO DE TIERRA | D2: Movimiento de suelos para bases c/ aporte de tosca (e: 40 cm en 2 capas de 20 cm) | E2: m3 | F2: 25 | G2: 0 | H2: 0 | I2: 1 | J2: =SUMIFS(COMPOSICIÓN!J$2:J$1879,COMPOSICIÓN!A$2:A$1879,A2,COMPOSICIÓN!B$2:B$1879,"MAT") -> 12754.673 | K2: =SUMIFS(COMPOSICIÓN!J$2:J$1879,COMPOSICIÓN!A$2:A$1879,A2,COMPOSICIÓN!B$2:B$1879,"MO")*I2 -> 151420.17 | L2: =SUMIFS(COMPOSICIÓN!J$2:J$1879,COMPOSICIÓN!A$2:A$1879,A2,COMPOSICIÓN!B$2:B$1879,"EQ") -> 865137.5 | M2: =J2 -> 12754.673 | N2: =IF(F2=0,0,K2/F2) -> 6056.8068 | O2: =IF(F2=0,0,L2/F2) -> 34605.5 | P2: =M2+N2+O2 -> 53416.98 | Q2: =COUNTIF(COMPOSICIÓN!$A:$A,A2) -> 6 | R2: APU
A3: ALB-033 | B3: 33 | C3: MAMPOSTERÍA | D3: Ladrillo común 12,5 x 5,5 x 25 (e:15 cm) | E3: m2 | F3: 7 | G3: 0 | H3: 0 | I3: 1 | J3: =SUMIFS(COMPOSICIÓN!J$2:J$1879,COMPOSICIÓN!A$2:A$1879,A3,COMPOSICIÓN!B$2:B$1879,"MAT") -> 12779.085 | K3: =SUMIFS(COMPOSICIÓN!J$2:J$1879,COMPOSICIÓN!A$2:A$1879,A3,COMPOSICIÓN!B$2:B$1879,"MO")*I3 -> 146787.68 | L3: =SUMIFS(COMPOSICIÓN!J$2:J$1879,COMPOSICIÓN!A$2:A$1879,A3,COMPOSICIÓN!B$2:B$1879,"EQ") -> 3529.9787 | M3: =J3 -> 12779.085 | N3: =IF(F3=0,0,K3/F3) -> 20969.668 | O3: =IF(F3=0,0,L3/F3) -> 504.28267 | P3: =M3+N3+O3 -> 34253.036 | Q3: =COUNTIF(COMPOSICIÓN!$A:$A,A3) -> 11 | R3: APU
A4: ALB-034 | B4: 34 | C4: MAMPOSTERÍA | D4: Ladrillo cerámico 8 x 18 x 33 cm | E4: m2 | F4: 15 | G4: 0 | H4: 0 | I4: 1 | J4: =SUMIFS(COMPOSICIÓN!J$2:J$1879,COMPOSICIÓN!A$2:A$1879,A4,COMPOSICIÓN!B$2:B$1879,"MAT") -> 6590.9962 | K4: =SUMIFS(COMPOSICIÓN!J$2:J$1879,COMPOSICIÓN!A$2:A$1879,A4,COMPOSICIÓN!B$2:B$1879,"MO")*I4 -> 146787.68 | L4: =SUMIFS(COMPOSICIÓN!J$2:J$1879,COMPOSICIÓN!A$2:A$1879,A4,COMPOSICIÓN!B$2:B$1879,"EQ") -> 3529.9787 | M4: =J4 -> 6590.9962 | N4: =IF(F4=0,0,K4/F4) -> 9785.8452 | O4: =IF(F4=0,0,L4/F4) -> 235.33191 | P4: =M4+N4+O4 -> 16612.173 | Q4: =COUNTIF(COMPOSICIÓN!$A:$A,A4) -> 11 | R4: APU
A5: ALB-035 | B5: 35 | C5: MAMPOSTERÍA | D5: Ladrillo cerámico 12 x 18 x 33 cm | E5: m2 | F5: 15 | G5: 0 | H5: 0 | I5: 1 | J5: =SUMIFS(COMPOSICIÓN!J$2:J$1879,COMPOSICIÓN!A$2:A$1879,A5,COMPOSICIÓN!B$2:B$1879,"MAT") -> 8400.1374 | K5: =SUMIFS(COMPOSICIÓN!J$2:J$1879,COMPOSICIÓN!A$2:A$1879,A5,COMPOSICIÓN!B$2:B$1879,"MO")*I5 -> 146787.68 | L5: =SUMIFS(COMPOSICIÓN!J$2:J$1879,COMPOSICIÓN!A$2:A$1879,A5,COMPOSICIÓN!B$2:B$1879,"EQ") -> 3529.9787 | M5: =J5 -> 8400.1374 | N5: =IF(F5=0,0,K5/F5) -> 9785.8452 | O5: =IF(F5=0,0,L5/F5) -> 235.33191 | P5: =M5+N5+O5 -> 18421.314 | Q5: =COUNTIF(COMPOSICIÓN!$A:$A,A5) -> 11 | R5: APU
A6: ALB-036 | B6: 36 | C6: MAMPOSTERÍA | D6: Ladrillo cerámico 18 x 18 x 33 cm | E6: m2 | F6: 15 | G6: 0 | H6: 0 | I6: 1 | J6: =SUMIFS(COMPOSICIÓN!J$2:J$1879,COMPOSICIÓN!A$2:A$1879,A6,COMPOSICIÓN!B$2:B$1879,"MAT") -> 11492.44 | K6: =SUMIFS(COMPOSICIÓN!J$2:J$1879,COMPOSICIÓN!A$2:A$1879,A6,COMPOSICIÓN!B$2:B$1879,"MO")*I6 -> 146787.68 | L6: =SUMIFS(COMPOSICIÓN!J$2:J$1879,COMPOSICIÓN!A$2:A$1879,A6,COMPOSICIÓN!B$2:B$1879,"EQ") -> 3529.9787 | M6: =J6 -> 11492.44 | N6: =IF(F6=0,0,K6/F6) -> 9785.8452 | O6: =IF(F6=0,0,L6/F6) -> 235.33191 | P6: =M6+N6+O6 -> 21513.617 | Q6: =COUNTIF(COMPOSICIÓN!$A:$A,A6) -> 11 | R6: APU
A7: ALB-037 | B7: 37 | C7: MAMPOSTERÍA | D7: Pared DOBLE Comun / 5 / LHC 08 - (ladrillo a la vista) | E7: m2 | F7: 4 | G7: 0 | H7: 0 | I7: 1 | J7: =SUMIFS(COMPOSICIÓN!J$2:J$1879,COMPOSICIÓN!A$2:A$1879,A7,COMPOSICIÓN!B$2:B$1879,"MAT") -> 27983.303 | K7: =SUMIFS(COMPOSICIÓN!J$2:J$1879,COMPOSICIÓN!A$2:A$1879,A7,COMPOSICIÓN!B$2:B$1879,"MO")*I7 -> 141310.23 | L7: =SUMIFS(COMPOSICIÓN!J$2:J$1879,COMPOSICIÓN!A$2:A$1879,A7,COMPOSICIÓN!B$2:B$1879,"EQ") -> 3529.9787 | M7: =J7 -> 27983.303 | N7: =IF(F7=0,0,K7/F7) -> 35327.556 | O7: =IF(F7=0,0,L7/F7) -> 882.49467 | P7: =M7+N7+O7 -> 64193.354 | Q7: =COUNTIF(COMPOSICIÓN!$A:$A,A7) -> 16 | R7: APU
A8: ALB-038 | B8: 38 | C8: MAMPOSTERÍA | D8: Ladrillo hueco portante 12 x 19 x 33 | E8: m2 | F8: 15 | G8: 0 | H8: 0 | I8: 1 | J8: =SUMIFS(COMPOSICIÓN!J$2:J$1879,COMPOSICIÓN!A$2:A$1879,A8,COMPOSICIÓN!B$2:B$1879,"MAT") -> 11547.894 | K8: =SUMIFS(COMPOSICIÓN!J$2:J$1879,COMPOSICIÓN!A$2:A$1879,A8,COMPOSICIÓN!B$2:B$1879,"MO")*I8 -> 146787.68 | L8: =SUMIFS(COMPOSICIÓN!J$2:J$1879,COMPOSICIÓN!A$2:A$1879,A8,COMPOSICIÓN!B$2:B$1879,"EQ") -> 3529.9787 | M8: =J8 -> 11547.894 | N8: =IF(F8=0,0,K8/F8) -> 9785.8452 | O8: =IF(F8=0,0,L8/F8) -> 235.33191 | P8: =M8+N8+O8 -> 21569.071 | Q8: =COUNTIF(COMPOSICIÓN!$A:$A,A8) -> 11 | R8: APU
A9: ALB-039 | B9: 39 | C9: MAMPOSTERÍA | D9: Amure puertas tipo (0,90 x 2,00 m) | E9: u | F9: 2 | G9: 0 | H9: 0 | I9: 1 | J9: =SUMIFS(COMPOSICIÓN!J$2:J$1879,COMPOSICIÓN!A$2:A$1879,A9,COMPOSICIÓN!B$2:B$1879,"MAT") -> 4066.3296 | K9: =SUMIFS(COMPOSICIÓN!J$2:J$1879,COMPOSICIÓN!A$2:A$1879,A9,COMPOSICIÓN!B$2:B$1879,"MO")*I9 -> 110090.76 | L9: =SUMIFS(COMPOSICIÓN!J$2:J$1879,COMPOSICIÓN!A$2:A$1879,A9,COMPOSICIÓN!B$2:B$1879,"EQ") -> 811.09724 | M9: =J9 -> 4066.3296 | N9: =IF(F9=0,0,K9/F9) -> 55045.379 | O9: =IF(F9=0,0,L9/F9) -> 405.54862 | P9: =M9+N9+O9 -> 59517.257 | Q9: =COUNTIF(COMPOSICIÓN!$A:$A,A9) -> 6 | R9: APU
A10: ALB-040 | B10: 40 | C10: MAMPOSTERÍA | D10: Amure Premarcos | E10: u | F10: 4 | G10: 0 | H10: 0 | I10: 1 | J10: =SUMIFS(COMPOSICIÓN!J$2:J$1879,COMPOSICIÓN!A$2:A$1879,A10,COMPOSICIÓN!B$2:B$1879,"MAT") -> 1487.907 | K10: =SUMIFS(COMPOSICIÓN!J$2:J$1879,COMPOSICIÓN!A$2:A$1879,A10,COMPOSICIÓN!B$2:B$1879,"MO")*I10 -> 146787.68 | L10: =SUMIFS(COMPOSICIÓN!J$2:J$1879,COMPOSICIÓN!A$2:A$1879,A10,COMPOSICIÓN!B$2:B$1879,"EQ") -> 811.09724 | M10: =J10 -> 1487.907 | N10: =IF(F10=0,0,K10/F10) -> 36696.919 | O10: =IF(F10=0,0,L10/F10) -> 202.77431 | P10: =M10+N10+O10 -> 38387.601 | Q10: =COUNTIF(COMPOSICIÓN!$A:$A,A10) -> 6 | R10: APU
A11: ALB-041 | B11: 41 | C11: MAMPOSTERÍA | D11: Amure barandas (insertos c/1,00 m) | E11: ml | F11: 5 | G11: 0 | H11: 0 | I11: 1 | J11: =SUMIFS(COMPOSICIÓN!J$2:J$1879,COMPOSICIÓN!A$2:A$1879,A11,COMPOSICIÓN!B$2:B$1879,"MAT") -> 204.36356 | K11: =SUMIFS(COMPOSICIÓN!J$2:J$1879,COMPOSICIÓN!A$2:A$1879,A11,COMPOSICIÓN!B$2:B$1879,"MO")*I11 -> 146787.68 | L11: =SUMIFS(COMPOSICIÓN!J$2:J$1879,COMPOSICIÓN!A$2:A$1879,A11,COMPOSICIÓN!B$2:B$1879,"EQ") -> 1382.8812 | M11: =J11 -> 204.36356 | N11: =IF(F11=0,0,K11/F11) -> 29357.536 | O11: =IF(F11=0,0,L11/F11) -> 276.57623 | P11: =M11+N11+O11 -> 29838.475 | Q11: =COUNTIF(COMPOSICIÓN!$A:$A,A11) -> 7 | R11: APU
A12: ALB-042 | B12: 42 | C12: MAMPOSTERÍA | D12: Azotado hidrófugo | E12: m2 | F12: 28 | G12: 0 | H12: 0 | I12: 1 | J12: =SUMIFS(COMPOSICIÓN!J$2:J$1879,COMPOSICIÓN!A$2:A$1879,A12,COMPOSICIÓN!B$2:B$1879,"MAT") -> 809.61503 | K12: =SUMIFS(COMPOSICIÓN!J$2:J$1879,COMPOSICIÓN!A$2:A$1879,A12,COMPOSICIÓN!B$2:B$1879,"MO")*I12 -> 110271.33 | L12: =SUMIFS(COMPOSICIÓN!J$2:J$1879,COMPOSICIÓN!A$2:A$1879,A12,COMPOSICIÓN!B$2:B$1879,"EQ") -> 3529.9787 | M12: =J12 -> 809.61503 | N12: =IF(F12=0,0,K12/F12) -> 3938.2618 | O12: =IF(F12=0,0,L12/F12) -> 126.07067 | P12: =M12+N12+O12 -> 4873.9475 | Q12: =COUNTIF(COMPOSICIÓN!$A:$A,A12) -> 8 | R12: APU
A13: ALB-043 | B13: 43 | C13: MAMPOSTERÍA | D13: Interior jaharro a la cal + Enlucido a la cal | E13: m2 | F13: 6 | G13: 0 | H13: 0 | I13: 1 | J13: =SUMIFS(COMPOSICIÓN!J$2:J$1879,COMPOSICIÓN!A$2:A$1879,A13,COMPOSICIÓN!B$2:B$1879,"MAT") -> 2735.3164 | K13: =SUMIFS(COMPOSICIÓN!J$2:J$1879,COMPOSICIÓN!A$2:A$1879,A13,COMPOSICIÓN!B$2:B$1879,"MO")*I13 -> 125486.47 | L13: =SUMIFS(COMPOSICIÓN!J$2:J$1879,COMPOSICIÓN!A$2:A$1879,A13,COMPOSICIÓN!B$2:B$1879,"EQ") -> 3529.9787 | M13: =J13 -> 2735.3164 | N13: =IF(F13=0,0,K13/F13) -> 20914.412 | O13: =IF(F13=0,0,L13/F13) -> 588.32978 | P13: =M13+N13+O13 -> 24238.059 | Q13: =COUNTIF(COMPOSICIÓN!$A:$A,A13) -> 9 | R13: APU
... A78: PIN-146 | B78: 146 | C78: PINTURA | D78: Látex interior para paredes (s/enduido) | E78: m2 | F78: 25 | G78: 0 | H78: 0 | I78: 1 | J78: =SUMIFS(COMPOSICIÓN!J$2:J$1879,COMPOSICIÓN!A$2:A$1879,A78,COMPOSICIÓN!B$2:B$1879,"MAT") -> 2141.693 | K78: =SUMIFS(COMPOSICIÓN!J$2:J$1879,COMPOSICIÓN!A$2:A$1879,A78,COMPOSICIÓN!B$2:B$1879,"MO")*I78 -> 85927.097 | L78: =SUMIFS(COMPOSICIÓN!J$2:J$1879,COMPOSICIÓN!A$2:A$1879,A78,COMPOSICIÓN!B$2:B$1879,"EQ") -> 1923.879 | M78: =J78 -> 2141.693 | N78: =IF(F78=0,0,K78/F78) -> 3437.0839 | O78: =IF(F78=0,0,L78/F78) -> 76.955162 | P78: =M78+N78+O78 -> 5655.732 | Q78: =COUNTIF(COMPOSICIÓN!$A:$A,A78) -> 11 | R78: APU
A79: PTO-0101 | C79: PRELIMINARES | D79: Limpieza y preparación del terreno - No cotiza | E79: gl | F79: 1 | G79: 0 | H79: 0 | I79: 1 | J79: =SUMIFS(COMPOSICIÓN!J$2:J$1879,COMPOSICIÓN!A$2:A$1879,A79,COMPOSICIÓN!B$2:B$1879,"MAT") -> 0 | K79: =SUMIFS(COMPOSICIÓN!J$2:J$1879,COMPOSICIÓN!A$2:A$1879,A79,COMPOSICIÓN!B$2:B$1879,"MO")*I79 -> 0 | L79: =SUMIFS(COMPOSICIÓN!J$2:J$1879,COMPOSICIÓN!A$2:A$1879,A79,COMPOSICIÓN!B$2:B$1879,"EQ") -> 0 | M79: =J79 -> 0 | N79: =IF(F79=0,0,K79/F79) -> 0 | O79: =IF(F79=0,0,L79/F79) -> 0 | P79: =M79+N79+O79 -> 0 | Q79: =COUNTIF(COMPOSICIÓN!$A:$A,A79) -> 0 | R79: PTO/sin cotizar
A80: PTO-0102 | C80: PRELIMINARES | D80: Topógrafo - Visita de obra replanteo | E80: gl | F80: 1 | G80: 0 | H80: 0 | I80: 1 | J80: =SUMIFS(COMPOSICIÓN!J$2:J$1879,COMPOSICIÓN!A$2:A$1879,A80,COMPOSICIÓN!B$2:B$1879,"MAT") -> 25000 | K80: =SUMIFS(COMPOSICIÓN!J$2:J$1879,COMPOSICIÓN!A$2:A$1879,A80,COMPOSICIÓN!B$2:B$1879,"MO")*I80 -> 259597.43 | L80: =SUMIFS(COMPOSICIÓN!J$2:J$1879,COMPOSICIÓN!A$2:A$1879,A80,COMPOSICIÓN!B$2:B$1879,"EQ") -> 4268.9614 | M80: =J80 -> 25000 | N80: =IF(F80=0,0,K80/F80) -> 259597.43 | O80: =IF(F80=0,0,L80/F80) -> 4268.9614 | P80: =M80+N80+O80 -> 288866.39 | Q80: =COUNTIF(COMPOSICIÓN!$A:$A,A80) -> 4 | R80: PTO/Tareas
A81: PTO-0103 | C81: PRELIMINARES | D81: Cartel de Obra - No cotiza | E81: gl | F81: 1 | G81: 0 | H81: 0 | I81: 1 | J81: =SUMIFS(COMPOSICIÓN!J$2:J$1879,COMPOSICIÓN!A$2:A$1879,A81,COMPOSICIÓN!B$2:B$1879,"MAT") -> 0 | K81: =SUMIFS(COMPOSICIÓN!J$2:J$1879,COMPOSICIÓN!A$2:A$1879,A81,COMPOSICIÓN!B$2:B$1879,"MO")*I81 -> 0 | L81: =SUMIFS(COMPOSICIÓN!J$2:J$1879,COMPOSICIÓN!A$2:A$1879,A81,COMPOSICIÓN!B$2:B$1879,"EQ") -> 0 | M81: =J81 -> 0 | N81: =IF(F81=0,0,K81/F81) -> 0 | O81: =IF(F81=0,0,L81/F81) -> 0 | P81: =M81+N81+O81 -> 0 | Q81: =COUNTIF(COMPOSICIÓN!$A:$A,A81) -> 0 | R81: PTO/sin cotizar
A82: PTO-0104 | C82: PRELIMINARES | D82: Cerco de obra perimetral - En chapa C25 + Concertina + Porton corredizo | E82: ml | F82: 1 | G82: 0 | H82: 0 | I82: 1 | J82: =SUMIFS(COMPOSICIÓN!J$2:J$1879,COMPOSICIÓN!A$2:A$1879,A82,COMPOSICIÓN!B$2:B$1879,"MAT") -> 88330.703 | K82: =SUMIFS(COMPOSICIÓN!J$2:J$1879,COMPOSICIÓN!A$2:A$1879,A82,COMPOSICIÓN!B$2:B$1879,"MO")*I82 -> 101654.37 | L82: =SUMIFS(COMPOSICIÓN!J$2:J$1879,COMPOSICIÓN!A$2:A$1879,A82,COMPOSICIÓN!B$2:B$1879,"EQ") -> 2849.776 | M82: =J82 -> 88330.703 | N82: =IF(F82=0,0,K82/F82) -> 101654.37 | O82: =IF(F82=0,0,L82/F82) -> 2849.776 | P82: =M82+N82+O82 -> 192834.84 | Q82: =COUNTIF(COMPOSICIÓN!$A:$A,A82) -> 12 | R82: PTO/Tareas
A83: PTO-0105 | C83: PRELIMINARES | D83: Obrador, pañol y ducha. | E83: gl | F83: 1 | G83: 0 | H83: 0 | I83: 1 | J83: =SUMIFS(COMPOSICIÓN!J$2:J$1879,COMPOSICIÓN!A$2:A$1879,A83,COMPOSICIÓN!B$2:B$1879,"MAT") -> 2078824.7 | K83: =SUMIFS(COMPOSICIÓN!J$2:J$1879,COMPOSICIÓN!A$2:A$1879,A83,COMPOSICIÓN!B$2:B$1879,"MO")*I83 -> 5174962.9 | L83: =SUMIFS(COMPOSICIÓN!J$2:J$1879,COMPOSICIÓN!A$2:A$1879,A83,COMPOSICIÓN!B$2:B$1879,"EQ") -> 108806.81 | M83: =J83 -> 2078824.7 | N83: =IF(F83=0,0,K83/F83) -> 5174962.9 | O83: =IF(F83=0,0,L83/F83) -> 108806.81 | P83: =M83+N83+O83 -> 7362594.4 | Q83: =COUNTIF(COMPOSICIÓN!$A:$A,A83) -> 23 | R83: PTO/Tareas
A84: PTO-0106 | C84: PRELIMINARES | D84: Alquiler de baños quimicos y duchas portatiles | E84: mes | F84: 1 | G84: 0 | H84: 0 | I84: 1 | J84: =SUMIFS(COMPOSICIÓN!J$2:J$1879,COMPOSICIÓN!A$2:A$1879,A84,COMPOSICIÓN!B$2:B$1879,"MAT") -> 0 | K84: =SUMIFS(COMPOSICIÓN!J$2:J$1879,COMPOSICIÓN!A$2:A$1879,A84,COMPOSICIÓN!B$2:B$1879,"MO")*I84 -> 332285.54 | L84: =SUMIFS(COMPOSICIÓN!J$2:J$1879,COMPOSICIÓN!A$2:A$1879,A84,COMPOSICIÓN!B$2:B$1879,"EQ") -> 0 | M84: =J84 -> 0 | N84: =IF(F84=0,0,K84/F84) -> 332285.54 | O84: =IF(F84=0,0,L84/F84) -> 0 | P84: =M84+N84+O84 -> 332285.54 | Q84: =COUNTIF(COMPOSICIÓN!$A:$A,A84) -> 2 | R84: PTO/Cotizaciones
A85: PTO-0107 | C85: PRELIMINARES | D85: Conexión pilar y luz de obra + Tablero de obra | E85: gl | F85: 1 | G85: 0 | H85: 0 | I85: 1 | J85: =SUMIFS(COMPOSICIÓN!J$2:J$1879,COMPOSICIÓN!A$2:A$1879,A85,COMPOSICIÓN!B$2:B$1879,"MAT") -> 1090000 | K85: =SUMIFS(COMPOSICIÓN!J$2:J$1879,COMPOSICIÓN!A$2:A$1879,A85,COMPOSICIÓN!B$2:B$1879,"MO")*I85 -> 601395.67 | L85: =SUMIFS(COMPOSICIÓN!J$2:J$1879,COMPOSICIÓN!A$2:A$1879,A85,COMPOSICIÓN!B$2:B$1879,"EQ") -> 25370.935 | M85: =J85 -> 1090000 | N85: =IF(F85=0,0,K85/F85) -> 601395.67 | O85: =IF(F85=0,0,L85/F85) -> 25370.935 | P85: =M85+N85+O85 -> 1716766.6 | Q85: =COUNTIF(COMPOSICIÓN!$A:$A,A85) -> 9 | R85: PTO/Tareas
A86: PTO-0108 | C86: PRELIMINARES | D86: Conexión agua de obra, tanque + bomba | E86: gl | F86: 1 | G86: 0 | H86: 0 | I86: 1 | J86: =SUMIFS(COMPOSICIÓN!J$2:J$1879,COMPOSICIÓN!A$2:A$1879,A86,COMPOSICIÓN!B$2:B$1879,"MAT") -> 685200 | K86: =SUMIFS(COMPOSICIÓN!J$2:J$1879,COMPOSICIÓN!A$2:A$1879,A86,COMPOSICIÓN!B$2:B$1879,"MO")*I86 -> 651528.71 | L86: =SUMIFS(COMPOSICIÓN!J$2:J$1879,COMPOSICIÓN!A$2:A$1879,A86,COMPOSICIÓN!B$2:B$1879,"EQ") -> 20050.931 | M86: =J86 -> 685200 | N86: =IF(F86=0,0,K86/F86) -> 651528.71 | O86: =IF(F86=0,0,L86/F86) -> 20050.931 | P86: =M86+N86+O86 -> 1356779.6 | Q86: =COUNTIF(COMPOSICIÓN!$A:$A,A86) -> 11 | R86: PTO/Tareas
A87: PTO-0109 | C87: PRELIMINARES | D87: Tramite luz de obra, certificado luz de obra (2) y medición PAT | E87: gl | F87: 1 | G87: 0 | H87: 0 | I87: 1 | J87: =SUMIFS(COMPOSICIÓN!J$2:J$1879,COMPOSICIÓN!A$2:A$1879,A87,COMPOSICIÓN!B$2:B$1879,"MAT") -> 0 | K87: =SUMIFS(COMPOSICIÓN!J$2:J$1879,COMPOSICIÓN!A$2:A$1879,A87,COMPOSICIÓN!B$2:B$1879,"MO")*I87 -> 456336.73 | L87: =SUMIFS(COMPOSICIÓN!J$2:J$1879,COMPOSICIÓN!A$2:A$1879,A87,COMPOSICIÓN!B$2:B$1879,"EQ") -> 0 | M87: =J87 -> 0 | N87: =IF(F87=0,0,K87/F87) -> 456336.73 | O87: =IF(F87=0,0,L87/F87) -> 0 | P87: =M87+N87+O87 -> 456336.73 | Q87: =COUNTIF(COMPOSICIÓN!$A:$A,A87) -> 3 | R87: PTO/Tareas
A88: PTO-0201 | C88: MOVIMIENTO DE TIERRA | D88: Excavación a maquina para submuración, subsuelo y fundaciones | E88: m3 | F88: 1 | G88: 0 | H88: 0 | I88: 1 | J88: =SUMIFS(COMPOSICIÓN!J$2:J$1879,COMPOSICIÓN!A$2:A$1879,A88,COMPOSICIÓN!B$2:B$1879,"MAT") -> 0 | K88: =SUMIFS(COMPOSICIÓN!J$2:J$1879,COMPOSICIÓN!A$2:A$1879,A88,COMPOSICIÓN!B$2:B$1879,"MO")*I88 -> 39520.777 | L88: =SUMIFS(COMPOSICIÓN!J$2:J$1879,COMPOSICIÓN!A$2:A$1879,A88,COMPOSICIÓN!B$2:B$1879,"EQ") -> 97.811648 | M88: =J88 -> 0 | N88: =IF(F88=0,0,K88/F88) -> 39520.777 | O88: =IF(F88=0,0,L88/F88) -> 97.811648 | P88: =M88+N88+O88 -> 39618.588 | Q88: =COUNTIF(COMPOSICIÓN!$A:$A,A88) -> 3 | R88: PTO/Tareas
A89: PTO-0202 | C89: MOVIMIENTO DE TIERRA | D89: Perfilado manual de bases. Relleno y compactación de pozos | E89: gl | F89: 1 | G89: 0 | H89: 0 | I89: 1 | J89: =SUMIFS(COMPOSICIÓN!J$2:J$1879,COMPOSICIÓN!A$2:A$1879,A89,COMPOSICIÓN!B$2:B$1879,"MAT") -> 105000 | K89: =SUMIFS(COMPOSICIÓN!J$2:J$1879,COMPOSICIÓN!A$2:A$1879,A89,COMPOSICIÓN!B$2:B$1879,"MO")*I89 -> 8488596.7 | L89: =SUMIFS(COMPOSICIÓN!J$2:J$1879,COMPOSICIÓN!A$2:A$1879,A89,COMPOSICIÓN!B$2:B$1879,"EQ") -> 128903.95 | M89: =J89 -> 105000 | N89: =IF(F89=0,0,K89/F89) -> 8488596.7 | O89: =IF(F89=0,0,L89/F89) -> 128903.95 | P89: =M89+N89+O89 -> 8722500.6 | Q89: =COUNTIF(COMPOSICIÓN!$A:$A,A89) -> 4 | R89: PTO/Tareas
A90: PTO-0203 | C90: MOVIMIENTO DE TIERRA | D90: Excavación manual para vigas de fundación | E90: m3 | F90: 1 | G90: 0 | H90: 0 | I90: 1 | J90: =SUMIFS(COMPOSICIÓN!J$2:J$1879,COMPOSICIÓN!A$2:A$1879,A90,COMPOSICIÓN!B$2:B$1879,"MAT") -> 26000 | K90: =SUMIFS(COMPOSICIÓN!J$2:J$1879,COMPOSICIÓN!A$2:A$1879,A90,COMPOSICIÓN!B$2:B$1879,"MO")*I90 -> 60860.581 | L90: =SUMIFS(COMPOSICIÓN!J$2:J$1879,COMPOSICIÓN!A$2:A$1879,A90,COMPOSICIÓN!B$2:B$1879,"EQ") -> 1302.9087 | M90: =J90 -> 26000 | N90: =IF(F90=0,0,K90/F90) -> 60860.581 | O90: =IF(F90=0,0,L90/F90) -> 1302.9087 | P90: =M90+N90+O90 -> 88163.489 | Q90: =COUNTIF(COMPOSICIÓN!$A:$A,A90) -> 3 | R90: PTO/lump
... A113: PTO-0322 | C113: ESTRUCTURA DE HORMIGÓN ARMADO | D113: Picado de medianeras para columnas y vigas - Cotizado para PB y 1P | E113: m2 | F113: 1 | G113: 0 | H113: 0 | I113: 1 | J113: =SUMIFS(COMPOSICIÓN!J$2:J$1879,COMPOSICIÓN!A$2:A$1879,A113,COMPOSICIÓN!B$2:B$1879,"MAT") -> 7051.2821 | K113: =SUMIFS(COMPOSICIÓN!J$2:J$1879,COMPOSICIÓN!A$2:A$1879,A113,COMPOSICIÓN!B$2:B$1879,"MO")*I113 -> 17829.919 | L113: =SUMIFS(COMPOSICIÓN!J$2:J$1879,COMPOSICIÓN!A$2:A$1879,A113,COMPOSICIÓN!B$2:B$1879,"EQ") -> 373.21802 | M113: =J113 -> 7051.2821 | N113: =IF(F113=0,0,K113/F113) -> 17829.919 | O113: =IF(F113=0,0,L113/F113) -> 373.21802 | P113: =M113+N113+O113 -> 25254.419 | Q113: =COUNTIF(COMPOSICIÓN!$A:$A,A113) -> 5 | R113: PTO/Tareas
A114: PTO-0401 | B114: 34 | C114: MAMPOSTERÍA | D114: Muro tipo 1 - Ladrillo hueco 8 x 18 x 33 | E114: m2 | F114: 15 | G114: 0 | H114: 0 | I114: 1 | J114: =SUMIFS(COMPOSICIÓN!J$2:J$1879,COMPOSICIÓN!A$2:A$1879,A114,COMPOSICIÓN!B$2:B$1879,"MAT") -> 6523.8011 | K114: =SUMIFS(COMPOSICIÓN!J$2:J$1879,COMPOSICIÓN!A$2:A$1879,A114,COMPOSICIÓN!B$2:B$1879,"MO")*I114 -> 146787.68 | L114: =SUMIFS(COMPOSICIÓN!J$2:J$1879,COMPOSICIÓN!A$2:A$1879,A114,COMPOSICIÓN!B$2:B$1879,"EQ") -> 3529.9787 | M114: =J114 -> 6523.8011 | N114: =IF(F114=0,0,K114/F114) -> 9785.8452 | O114: =IF(F114=0,0,L114/F114) -> 235.33191 | P114: =M114+N114+O114 -> 16544.978 | Q114: =COUNTIF(COMPOSICIÓN!$A:$A,A114) -> 10 | R114: PTO/APU P-34
A115: PTO-0402 | B115: 35 | C115: MAMPOSTERÍA | D115: Muro tipo 2 - Ladrillo hueco 12 x 18 x 33 | E115: m2 | F115: 15 | G115: 0 | H115: 0 | I115: 1 | J115: =SUMIFS(COMPOSICIÓN!J$2:J$1879,COMPOSICIÓN!A$2:A$1879,A115,COMPOSICIÓN!B$2:B$1879,"MAT") -> 8314.4981 | K115: =SUMIFS(COMPOSICIÓN!J$2:J$1879,COMPOSICIÓN!A$2:A$1879,A115,COMPOSICIÓN!B$2:B$1879,"MO")*I115 -> 146787.68 | L115: =SUMIFS(COMPOSICIÓN!J$2:J$1879,COMPOSICIÓN!A$2:A$1879,A115,COMPOSICIÓN!B$2:B$1879,"EQ") -> 3529.9787 | M115: =J115 -> 8314.4981 | N115: =IF(F115=0,0,K115/F115) -> 9785.8452 | O115: =IF(F115=0,0,L115/F115) -> 235.33191 | P115: =M115+N115+O115 -> 18335.675 | Q115: =COUNTIF(COMPOSICIÓN!$A:$A,A115) -> 10 | R115: PTO/APU P-35
A116: PTO-0403 | B116: 33 | C116: MAMPOSTERÍA | D116: Muro tipo 3 - Ladrillo comun en panderete | E116: m2 | F116: 7 | G116: 0 | H116: 0 | I116: 1 | J116: =SUMIFS(COMPOSICIÓN!J$2:J$1879,COMPOSICIÓN!A$2:A$1879,A116,COMPOSICIÓN!B$2:B$1879,"MAT") -> 6454.6901 | K116: =SUMIFS(COMPOSICIÓN!J$2:J$1879,COMPOSICIÓN!A$2:A$1879,A116,COMPOSICIÓN!B$2:B$1879,"MO")*I116 -> 73393.839 | L116: =SUMIFS(COMPOSICIÓN!J$2:J$1879,COMPOSICIÓN!A$2:A$1879,A116,COMPOSICIÓN!B$2:B$1879,"EQ") -> 3529.9787 | M116: =J116 -> 6454.6901 | N116: =IF(F116=0,0,K116/F116) -> 10484.834 | O116: =IF(F116=0,0,L116/F116) -> 504.28267 | P116: =M116+N116+O116 -> 17443.807 | Q116: =COUNTIF(COMPOSICIÓN!$A:$A,A116) -> 11 | R116: PTO/APU P-33 MAT÷2 MO÷2 EQ÷1
A117: PTO-0404 | B117: 38 | C117: MAMPOSTERÍA | D117: Muro tipo 4 - Ladrillo hueco portante 12 x 18 x 33 | E117: m2 | F117: 15 | G117: 0 | H117: 0 | I117: 1 | J117: =SUMIFS(COMPOSICIÓN!J$2:J$1879,COMPOSICIÓN!A$2:A$1879,A117,COMPOSICIÓN!B$2:B$1879,"MAT") -> 11430.163 | K117: =SUMIFS(COMPOSICIÓN!J$2:J$1879,COMPOSICIÓN!A$2:A$1879,A117,COMPOSICIÓN!B$2:B$1879,"MO")*I117 -> 146787.68 | L117: =SUMIFS(COMPOSICIÓN!J$2:J$1879,COMPOSICIÓN!A$2:A$1879,A117,COMPOSICIÓN!B$2:B$1879,"EQ") -> 3529.9787 | M117: =J117 -> 11430.163 | N117: =IF(F117=0,0,K117/F117) -> 9785.8452 | O117: =IF(F117=0,0,L117/F117) -> 235.33191 | P117: =M117+N117+O117 -> 21451.34 | Q117: =COUNTIF(COMPOSICIÓN!$A:$A,A117) -> 10 | R117: PTO/APU P-38
A118: PTO-0405 | C118: MAMPOSTERÍA | D118: Muro tipo 5 - Bloque HCCA e: 7,5 cm | E118: m2 | F118: 1 | G118: 0 | H118: 0 | I118: 1 | J118: =SUMIFS(COMPOSICIÓN!J$2:J$1879,COMPOSICIÓN!A$2:A$1879,A118,COMPOSICIÓN!B$2:B$1879,"MAT") -> 16817.941 | K118: =SUMIFS(COMPOSICIÓN!J$2:J$1879,COMPOSICIÓN!A$2:A$1879,A118,COMPOSICIÓN!B$2:B$1879,"MO")*I118 -> 10484.834 | L118: =SUMIFS(COMPOSICIÓN!J$2:J$1879,COMPOSICIÓN!A$2:A$1879,A118,COMPOSICIÓN!B$2:B$1879,"EQ") -> 409.54162 | M118: =J118 -> 16817.941 | N118: =IF(F118=0,0,K118/F118) -> 10484.834 | O118: =IF(F118=0,0,L118/F118) -> 409.54162 | P118: =M118+N118+O118 -> 27712.316 | Q118: =COUNTIF(COMPOSICIÓN!$A:$A,A118) -> 7 | R118: PTO/Tareas
A119: PTO-0406 | B119: 36 | C119: MAMPOSTERÍA | D119: Muro tipo 6 - Ladrillo hueco 18 x 18 x 33 | E119: m2 | F119: 15 | G119: 0 | H119: 0 | I119: 1 | J119: =SUMIFS(COMPOSICIÓN!J$2:J$1879,COMPOSICIÓN!A$2:A$1879,A119,COMPOSICIÓN!B$2:B$1879,"MAT") -> 11375.275 | K119: =SUMIFS(COMPOSICIÓN!J$2:J$1879,COMPOSICIÓN!A$2:A$1879,A119,COMPOSICIÓN!B$2:B$1879,"MO")*I119 -> 146787.68 | L119: =SUMIFS(COMPOSICIÓN!J$2:J$1879,COMPOSICIÓN!A$2:A$1879,A119,COMPOSICIÓN!B$2:B$1879,"EQ") -> 3529.9787 | M119: =J119 -> 11375.275 | N119: =IF(F119=0,0,K119/F119) -> 9785.8452 | O119: =IF(F119=0,0,L119/F119) -> 235.33191 | P119: =M119+N119+O119 -> 21396.452 | Q119: =COUNTIF(COMPOSICIÓN!$A:$A,A119) -> 10 | R119: PTO/APU P-36
A120: PTO-0407 | B120: 33 | C120: MAMPOSTERÍA | D120: Enchape de medianeras existentes - Contemplamos picado zonas sueltas y enchape con ladrillo comun para PB | E120: m2 | F120: 7 | G120: 0 | H120: 0 | I120: 1 | J120: =SUMIFS(COMPOSICIÓN!J$2:J$1879,COMPOSICIÓN!A$2:A$1879,A120,COMPOSICIÓN!B$2:B$1879,"MAT") -> 3227.3451 | K120: =SUMIFS(COMPOSICIÓN!J$2:J$1879,COMPOSICIÓN!A$2:A$1879,A120,COMPOSICIÓN!B$2:B$1879,"MO")*I120 -> 73393.839 | L120: =SUMIFS(COMPOSICIÓN!J$2:J$1879,COMPOSICIÓN!A$2:A$1879,A120,COMPOSICIÓN!B$2:B$1879,"EQ") -> 1764.9893 | M120: =J120 -> 3227.3451 | N120: =IF(F120=0,0,K120/F120) -> 10484.834 | O120: =IF(F120=0,0,L120/F120) -> 252.14133 | P120: =M120+N120+O120 -> 13964.321 | Q120: =COUNTIF(COMPOSICIÓN!$A:$A,A120) -> 11 | R120: PTO/APU P-33 MAT÷4 MO÷2 EQ÷2
A121: PTO-0408 | C121: MAMPOSTERÍA | D121: Cordón de hormigón en umbrales carpinterías | E121: ml | F121: 1 | G121: 0 | H121: 0 | I121: 1 | J121: =SUMIFS(COMPOSICIÓN!J$2:J$1879,COMPOSICIÓN!A$2:A$1879,A121,COMPOSICIÓN!B$2:B$1879,"MAT") -> 9093.9863 | K121: =SUMIFS(COMPOSICIÓN!J$2:J$1879,COMPOSICIÓN!A$2:A$1879,A121,COMPOSICIÓN!B$2:B$1879,"MO")*I121 -> 12031.777 | L121: =SUMIFS(COMPOSICIÓN!J$2:J$1879,COMPOSICIÓN!A$2:A$1879,A121,COMPOSICIÓN!B$2:B$1879,"EQ") -> 316.88645 | M121: =J121 -> 9093.9863 | N121: =IF(F121=0,0,K121/F121) -> 12031.777 | O121: =IF(F121=0,0,L121/F121) -> 316.88645 | P121: =M121+N121+O121 -> 21442.65 | Q121: =COUNTIF(COMPOSICIÓN!$A:$A,A121) -> 7 | R121: PTO/Tareas
A122: PTO-0409 | C122: MAMPOSTERÍA | D122: Banquina Sala tanque de bombeo | E122: gl | F122: 1 | G122: 0 | H122: 0 | I122: 1 | J122: =SUMIFS(COMPOSICIÓN!J$2:J$1879,COMPOSICIÓN!A$2:A$1879,A122,COMPOSICIÓN!B$2:B$1879,"MAT") -> 60811.031 | K122: =SUMIFS(COMPOSICIÓN!J$2:J$1879,COMPOSICIÓN!A$2:A$1879,A122,COMPOSICIÓN!B$2:B$1879,"MO")*I122 -> 146787.68 | L122: =SUMIFS(COMPOSICIÓN!J$2:J$1879,COMPOSICIÓN!A$2:A$1879,A122,COMPOSICIÓN!B$2:B$1879,"EQ") -> 3113.9806 | M122: =J122 -> 60811.031 | N122: =IF(F122=0,0,K122/F122) -> 146787.68 | O122: =IF(F122=0,0,L122/F122) -> 3113.9806 | P122: =M122+N122+O122 -> 210712.69 | Q122: =COUNTIF(COMPOSICIÓN!$A:$A,A122) -> 6 | R122: PTO/Tareas
A123: PTO-0410 | C123: MAMPOSTERÍA | D123: Banquina en parrillas | E123: gl | F123: 1 | G123: 0 | H123: 0 | I123: 1 | J123: =SUMIFS(COMPOSICIÓN!J$2:J$1879,COMPOSICIÓN!A$2:A$1879,A123,COMPOSICIÓN!B$2:B$1879,"MAT") -> 151935.62 | K123: =SUMIFS(COMPOSICIÓN!J$2:J$1879,COMPOSICIÓN!A$2:A$1879,A123,COMPOSICIÓN!B$2:B$1879,"MO")*I123 -> 440363.03 | L123: =SUMIFS(COMPOSICIÓN!J$2:J$1879,COMPOSICIÓN!A$2:A$1879,A123,COMPOSICIÓN!B$2:B$1879,"EQ") -> 8884.4798 | M123: =J123 -> 151935.62 | N123: =IF(F123=0,0,K123/F123) -> 440363.03 | O123: =IF(F123=0,0,L123/F123) -> 8884.4798 | P123: =M123+N123+O123 -> 601183.14 | Q123: =COUNTIF(COMPOSICIÓN!$A:$A,A123) -> 6 | R123: PTO/Tareas
A124: PTO-0411 | C124: MAMPOSTERÍA | D124: Excavación y amurado con Hº tanque de recuperación de agua de lluvia | E124: gl | F124: 1 | G124: 0 | H124: 0 | I124: 1 | J124: =SUMIFS(COMPOSICIÓN!J$2:J$1879,COMPOSICIÓN!A$2:A$1879,A124,COMPOSICIÓN!B$2:B$1879,"MAT") -> 128742.89 | K124: =SUMIFS(COMPOSICIÓN!J$2:J$1879,COMPOSICIÓN!A$2:A$1879,A124,COMPOSICIÓN!B$2:B$1879,"MO")*I124 -> 259536.82 | L124: =SUMIFS(COMPOSICIÓN!J$2:J$1879,COMPOSICIÓN!A$2:A$1879,A124,COMPOSICIÓN!B$2:B$1879,"EQ") -> 5824.1958 | M124: =J124 -> 128742.89 | N124: =IF(F124=0,0,K124/F124) -> 259536.82 | O124: =IF(F124=0,0,L124/F124) -> 5824.1958 | P124: =M124+N124+O124 -> 394103.91 | Q124: =COUNTIF(COMPOSICIÓN!$A:$A,A124) -> 5 | R124: PTO/Tareas
A125: PTO-0412 | C125: MAMPOSTERÍA | D125: Provisión y amurado de tapas de inspección para tanque de reserva | E125: u | F125: 1 | G125: 0 | H125: 0 | I125: 1 | J125: =SUMIFS(COMPOSICIÓN!J$2:J$1879,COMPOSICIÓN!A$2:A$1879,A125,COMPOSICIÓN!B$2:B$1879,"MAT") -> 121487.6 | K125: =SUMIFS(COMPOSICIÓN!J$2:J$1879,COMPOSICIÓN!A$2:A$1879,A125,COMPOSICIÓN!B$2:B$1879,"MO")*I125 -> 54294.059 | L125: =SUMIFS(COMPOSICIÓN!J$2:J$1879,COMPOSICIÓN!A$2:A$1879,A125,COMPOSICIÓN!B$2:B$1879,"EQ") -> 2636.7249 | M125: =J125 -> 121487.6 | N125: =IF(F125=0,0,K125/F125) -> 54294.059 | O125: =IF(F125=0,0,L125/F125) -> 2636.7249 | P125: =M125+N125+O125 -> 178418.39 | Q125: =COUNTIF(COMPOSICIÓN!$A:$A,A125) -> 4 | R125: PTO/Tareas
A126: PTO-0413 | C126: MAMPOSTERÍA | D126: Vigas de encadenado - Cuantía aprox. 60 kg/m3 | E126: ml | F126: 1 | G126: 0 | H126: 0 | I126: 1 | J126: =SUMIFS(COMPOSICIÓN!J$2:J$1879,COMPOSICIÓN!A$2:A$1879,A126,COMPOSICIÓN!B$2:B$1879,"MAT") -> 36748.882 | K126: =SUMIFS(COMPOSICIÓN!J$2:J$1879,COMPOSICIÓN!A$2:A$1879,A126,COMPOSICIÓN!B$2:B$1879,"MO")*I126 -> 35716.756 | L126: =SUMIFS(COMPOSICIÓN!J$2:J$1879,COMPOSICIÓN!A$2:A$1879,A126,COMPOSICIÓN!B$2:B$1879,"EQ") -> 1086.9846 | M126: =J126 -> 36748.882 | N126: =IF(F126=0,0,K126/F126) -> 35716.756 | O126: =IF(F126=0,0,L126/F126) -> 1086.9846 | P126: =M126+N126+O126 -> 73552.623 | Q126: =COUNTIF(COMPOSICIÓN!$A:$A,A126) -> 8 | R126: PTO/Tareas
...

Sheet COMPOSICIÓN
A1: Partida | B1: Tipo | C1: Subtipo | D1: Cod_Insumo | E1: Descripción | F1: Unidad de medida | G1: Cant | H1: %Desp | I1: Precio | J1: Costo | K1: Clave | L1: Count | M1: Clave2 | N1: Rend. Part. | O1: Cant MO/ALB Unit | P1: Cant. Ej. Part. | Q1: Cant MO/ALB Total | R1: en PPTO?
A2: AIS-114 | B2: EQ | D2: EQ-SOLD00 | E2: =IFERROR(VLOOKUP(D2,EQUIPOS!A:B,2,FALSE()),"?") -> Soldador Soplete A Gas Techista Membrana 10 Kg Boca 50mm | G2: 1 | H2: 0 | I2: =IFERROR(VLOOKUP(D2,EQUIPOS!A:F,6,FALSE()),0) -> 804.50569 | J2: =G2*I2 -> 804.50569 | K2: =A2&"|"&B2 -> AIS-114|EQ | L2: =COUNTIFS($K$2:K2,K2) -> 1 | M2: =K2&"|"&L2 -> AIS-114|EQ|1 | N2: =IFERROR(VLOOKUP(A2,PARTIDAS!A:F,6,FALSE()),0) -> 60 | O2: =+IF(C2="ALB",G2/N2,G2) -> 1 | P2: =+_xlfn.XLOOKUP(A2,PPTO_GENERADOR!Q:Q,PPTO_GENERADOR!E:E,"-",0) -> - | Q2: =IFERROR(P2*O2,0) -> 0 | R2: =+_xlfn.XLOOKUP(A2,PPTO_GENERADOR!$Q:$Q,PPTO_GENERADOR!A:A,"-",0) -> -
A3: AIS-114 | B3: MAT | C3: OTR | D3: OTR-022 | E3: =IFERROR(VLOOKUP(D3,MATERIALES!A:B,2,FALSE()),"?") -> Aguarras Hydrarras Hydra x 18lts | F3: =IFERROR(VLOOKUP(D3,MATERIALES!A:C,3,FALSE()),"?") -> b | G3: 0.005 | H3: 0.05 | I3: =IFERROR(VLOOKUP(D3,MATERIALES!A:D,4,FALSE()),0) -> 26907.33 | J3: =G3*I3*(1+H3) -> 141.26348 | K3: =A3&"|"&B3 -> AIS-114|MAT | L3: =COUNTIFS($K$2:K3,K3) -> 1 | M3: =K3&"|"&L3 -> AIS-114|MAT|1 | N3: =IFERROR(VLOOKUP(A3,PARTIDAS!A:F,6,FALSE()),0) -> 60 | O3: =+IF(C3="ALB",G3/N3,G3) -> 0.005 | P3: =+_xlfn.XLOOKUP(A3,PPTO_GENERADOR!Q:Q,PPTO_GENERADOR!E:E,"-",0) -> - | Q3: =IFERROR(P3*O3,0) -> 0 | R3: =+_xlfn.XLOOKUP(A3,PPTO_GENERADOR!$Q:$Q,PPTO_GENERADOR!A:A,"-",0) -> -
A4: AIS-114 | B4: MAT | C4: OTR | D4: OTR-025 | E4: =IFERROR(VLOOKUP(D4,MATERIALES!A:B,2,FALSE()),"?") -> Trapo | F4: =IFERROR(VLOOKUP(D4,MATERIALES!A:C,3,FALSE()),"?") -> u | G4: 0.01 | H4: 0.05 | I4: =IFERROR(VLOOKUP(D4,MATERIALES!A:D,4,FALSE()),0) -> 735.06 | J4: =G4*I4*(1+H4) -> 7.71813 | K4: =A4&"|"&B4 -> AIS-114|MAT | L4: =COUNTIFS($K$2:K4,K4) -> 2 | M4: =K4&"|"&L4 -> AIS-114|MAT|2 | N4: =IFERROR(VLOOKUP(A4,PARTIDAS!A:F,6,FALSE()),0) -> 60 | O4: =+IF(C4="ALB",G4/N4,G4) -> 0.01 | P4: =+_xlfn.XLOOKUP(A4,PPTO_GENERADOR!Q:Q,PPTO_GENERADOR!E:E,"-",0) -> - | Q4: =IFERROR(P4*O4,0) -> 0 | R4: =+_xlfn.XLOOKUP(A4,PPTO_GENERADOR!$Q:$Q,PPTO_GENERADOR!A:A,"-",0) -> -
A5: AIS-114 | B5: MAT | C5: OTR | D5: OTR-027 | E5: =IFERROR(VLOOKUP(D5,MATERIALES!A:B,2,FALSE()),"?") -> Rodillo de lana pelo largo N°22 - El Galgo | F5: =IFERROR(VLOOKUP(D5,MATERIALES!A:C,3,FALSE()),"?") -> u | G5: 0.005 | H5: 0.05 | I5: =IFERROR(VLOOKUP(D5,MATERIALES!A:D,4,FALSE()),0) -> 6678.36 | J5: =G5*I5*(1+H5) -> 35.06139 | K5: =A5&"|"&B5 -> AIS-114|MAT | L5: =COUNTIFS($K$2:K5,K5) -> 3 | M5: =K5&"|"&L5 -> AIS-114|MAT|3 | N5: =IFERROR(VLOOKUP(A5,PARTIDAS!A:F,6,FALSE()),0) -> 60 | O5: =+IF(C5="ALB",G5/N5,G5) -> 0.005 | P5: =+_xlfn.XLOOKUP(A5,PPTO_GENERADOR!Q:Q,PPTO_GENERADOR!E:E,"-",0) -> - | Q5: =IFERROR(P5*O5,0) -> 0 | R5: =+_xlfn.XLOOKUP(A5,PPTO_GENERADOR!$Q:$Q,PPTO_GENERADOR!A:A,"-",0) -> -
A6: AIS-114 | B6: MAT | C6: OTR | D6: OTR-028 | E6: =IFERROR(VLOOKUP(D6,MATERIALES!A:B,2,FALSE()),"?") -> Pincel N° 20 - El Galgo | F6: =IFERROR(VLOOKUP(D6,MATERIALES!A:C,3,FALSE()),"?") -> u | G6: 0.01 | H6: 0.05 | I6: =IFERROR(VLOOKUP(D6,MATERIALES!A:D,4,FALSE()),0) -> 5282.24 | J6: =G6*I6*(1+H6) -> 55.46352 | K6: =A6&"|"&B6 -> AIS-114|MAT | L6: =COUNTIFS($K$2:K6,K6) -> 4 | M6: =K6&"|"&L6 -> AIS-114|MAT|4 | N6: =IFERROR(VLOOKUP(A6,PARTIDAS!A:F,6,FALSE()),0) -> 60 | O6: =+IF(C6="ALB",G6/N6,G6) -> 0.01 | P6: =+_xlfn.XLOOKUP(A6,PPTO_GENERADOR!Q:Q,PPTO_GENERADOR!E:E,"-",0) -> - | Q6: =IFERROR(P6*O6,0) -> 0 | R6: =+_xlfn.XLOOKUP(A6,PPTO_GENERADOR!$Q:$Q,PPTO_GENERADOR!A:A,"-",0) -> -
A7: AIS-114 | B7: MAT | C7: OTR | D7: OTR-047 | E7: =IFERROR(VLOOKUP(D7,MATERIALES!A:B,2,FALSE()),"?") -> Guante Vaqueta Medio Paseo | F7: =IFERROR(VLOOKUP(D7,MATERIALES!A:C,3,FALSE()),"?") -> par | G7: 0.03 | H7: 0.05 | I7: =IFERROR(VLOOKUP(D7,MATERIALES!A:D,4,FALSE()),0) -> 4842 | J7: =G7*I7*(1+H7) -> 152.523 | K7: =A7&"|"&B7 -> AIS-114|MAT | L7: =COUNTIFS($K$2:K7,K7) -> 5 | M7: =K7&"|"&L7 -> AIS-114|MAT|5 | N7: =IFERROR(VLOOKUP(A7,PARTIDAS!A:F,6,FALSE()),0) -> 60 | O7: =+IF(C7="ALB",G7/N7,G7) -> 0.03 | P7: =+_xlfn.XLOOKUP(A7,PPTO_GENERADOR!Q:Q,PPTO_GENERADOR!E:E,"-",0) -> - | Q7: =IFERROR(P7*O7,0) -> 0 | R7: =+_xlfn.XLOOKUP(A7,PPTO_GENERADOR!$Q:$Q,PPTO_GENERADOR!A:A,"-",0) -> -
A8: AIS-114 | B8: MAT | C8: OTR | D8: OTR-048 | E8: =IFERROR(VLOOKUP(D8,MATERIALES!A:B,2,FALSE()),"?") -> Recarga de garrafa | F8: =IFERROR(VLOOKUP(D8,MATERIALES!A:C,3,FALSE()),"?") -> u | G8: 0.01 | H8: 0.05 | I8: =IFERROR(VLOOKUP(D8,MATERIALES!A:D,4,FALSE()),0) -> 12396.694 | J8: =G8*I8*(1+H8) -> 130.16529 | K8: =A8&"|"&B8 -> AIS-114|MAT | L8: =COUNTIFS($K$2:K8,K8) -> 6 | M8: =K8&"|"&L8 -> AIS-114|MAT|6 | N8: =IFERROR(VLOOKUP(A8,PARTIDAS!A:F,6,FALSE()),0) -> 60 | O8: =+IF(C8="ALB",G8/N8,G8) -> 0.01 | P8: =+_xlfn.XLOOKUP(A8,PPTO_GENERADOR!Q:Q,PPTO_GENERADOR!E:E,"-",0) -> - | Q8: =IFERROR(P8*O8,0) -> 0 | R8: =+_xlfn.XLOOKUP(A8,PPTO_GENERADOR!$Q:$Q,PPTO_GENERADOR!A:A,"-",0) -> -
A9: AIS-114 | B9: MAT | C9: OTR | D9: PIN-008 | E9: =IFERROR(VLOOKUP(D9,MATERIALES!A:B,2,FALSE()),"?") -> Pintura Asfaltica Asfasol x18ts | F9: =IFERROR(VLOOKUP(D9,MATERIALES!A:C,3,FALSE()),"?") -> b | G9: 0.015 | H9: 0.1 | I9: =IFERROR(VLOOKUP(D9,MATERIALES!A:D,4,FALSE()),0) -> 32845.78 | J9: =G9*I9*(1+H9) -> 541.95537 | K9: =A9&"|"&B9 -> AIS-114|MAT | L9: =COUNTIFS($K$2:K9,K9) -> 7 | M9: =K9&"|"&L9 -> AIS-114|MAT|7 | N9: =IFERROR(VLOOKUP(A9,PARTIDAS!A:F,6,FALSE()),0) -> 60 | O9: =+IF(C9="ALB",G9/N9,G9) -> 0.015 | P9: =+_xlfn.XLOOKUP(A9,PPTO_GENERADOR!Q:Q,PPTO_GENERADOR!E:E,"-",0) -> - | Q9: =IFERROR(P9*O9,0) -> 0 | R9: =+_xlfn.XLOOKUP(A9,PPTO_GENERADOR!$Q:$Q,PPTO_GENERADOR!A:A,"-",0) -> -
A10: AIS-114 | B10: MAT | C10: OTR | D10: AIS-002 | E10: =IFERROR(VLOOKUP(D10,MATERIALES!A:B,2,FALSE()),"?") -> Membrana Geotextil Ormiflex 4mm - (35kg) x10m | F10: =IFERROR(VLOOKUP(D10,MATERIALES!A:C,3,FALSE()),"?") -> u | G10: 0.05 | H10: 0.1 | I10: =IFERROR(VLOOKUP(D10,MATERIALES!A:D,4,FALSE()),0) -> 70192.21 | J10: =G10*I10*(1+H10) -> 3860.5716 | K10: =A10&"|"&B10 -> AIS-114|MAT | L10: =COUNTIFS($K$2:K10,K10) -> 8 | M10: =K10&"|"&L10 -> AIS-114|MAT|8 | N10: =IFERROR(VLOOKUP(A10,PARTIDAS!A:F,6,FALSE()),0) -> 60 | O10: =+IF(C10="ALB",G10/N10,G10) -> 0.05 | P10: =+_xlfn.XLOOKUP(A10,PPTO_GENERADOR!Q:Q,PPTO_GENERADOR!E:E,"-",0) -> - | Q10: =IFERROR(P10*O10,0) -> 0 | R10: =+_xlfn.XLOOKUP(A10,PPTO_GENERADOR!$Q:$Q,PPTO_GENERADOR!A:A,"-",0) -> -
A11: AIS-114 | B11: MO | C11: ALB | D11: MO-EAYUD | E11: =IFERROR(VLOOKUP(D11,MANO_DE_OBRA!A:B,2,FALSE()),"?") -> AYUDANTE | F11: j | G11: 1 | H11: 0 | I11: =IFERROR(VLOOKUP(D11,MANO_DE_OBRA!A:C,3,FALSE()),0) -> 60860.581 | J11: =G11*I11 -> 60860.581 | K11: =A11&"|"&B11 -> AIS-114|MO | L11: =COUNTIFS($K$2:K11,K11) -> 1 | M11: =K11&"|"&L11 -> AIS-114|MO|1 | N11: =IFERROR(VLOOKUP(A11,PARTIDAS!A:F,6,FALSE()),0) -> 60 | O11: =+IF(C11="ALB",G11/N11,G11) -> 0.016666667 | P11: =+_xlfn.XLOOKUP(A11,PPTO_GENERADOR!Q:Q,PPTO_GENERADOR!E:E,"-",0) -> - | Q11: =IFERROR(P11*O11,0) -> 0 | R11: =+_xlfn.XLOOKUP(A11,PPTO_GENERADOR!$Q:$Q,PPTO_GENERADOR!A:A,"-",0) -> -
A12: AIS-114 | B12: MO | C12: ALB | D12: MO-EESPE | E12: =IFERROR(VLOOKUP(D12,MANO_DE_OBRA!A:B,2,FALSE()),"?") -> ESPECIALIZADO | F12: j | G12: 1 | H12: 0 | I12: =IFERROR(VLOOKUP(D12,MANO_DE_OBRA!A:C,3,FALSE()),0) -> 85927.097 | J12: =G12*I12 -> 85927.097 | K12: =A12&"|"&B12 -> AIS-114|MO | L12: =COUNTIFS($K$2:K12,K12) -> 2 | M12: =K12&"|"&L12 -> AIS-114|MO|2 | N12: =IFERROR(VLOOKUP(A12,PARTIDAS!A:F,6,FALSE()),0) -> 60 | O12: =+IF(C12="ALB",G12/N12,G12) -> 0.016666667 | P12: =+_xlfn.XLOOKUP(A12,PPTO_GENERADOR!Q:Q,PPTO_GENERADOR!E:E,"-",0) -> - | Q12: =IFERROR(P12*O12,0) -> 0 | R12: =+_xlfn.XLOOKUP(A12,PPTO_GENERADOR!$Q:$Q,PPTO_GENERADOR!A:A,"-",0) -> -
A13: ALB-033 | B13: EQ | D13: EQ-ANDAM0 | E13: =IFERROR(VLOOKUP(D13,EQUIPOS!A:B,2,FALSE()),"?") -> ANDAMIO TUBULAR DE UNO A TRES CUERPOS | G13: 0.5 | H13: 0 | I13: =IFERROR(VLOOKUP(D13,EQUIPOS!A:F,6,FALSE()),0) -> 571.17949 | J13: =G13*I13 -> 285.58975 | K13: =A13&"|"&B13 -> ALB-033|EQ | L13: =COUNTIFS($K$2:K13,K13) -> 1 | M13: =K13&"|"&L13 -> ALB-033|EQ|1 | N13: =IFERROR(VLOOKUP(A13,PARTIDAS!A:F,6,FALSE()),0) -> 7 | O13: =+IF(C13="ALB",G13/N13,G13) -> 0.5 | P13: =+_xlfn.XLOOKUP(A13,PPTO_GENERADOR!Q:Q,PPTO_GENERADOR!E:E,"-",0) -> - | Q13: =IFERROR(P13*O13,0) -> 0 | R13: =+_xlfn.XLOOKUP(A13,PPTO_GENERADOR!$Q:$Q,PPTO_GENERADOR!A:A,"-",0) -> -
