Workbook

Sheet 0_CONFIG
A1: CONFIGURACIÓN DE OBRA
A3: Obra | B3: Edificio GDR 3760 — García del Río 3760
A4: Estado | B4: En ejecución
A5: Fecha de inicio de obra | B5: 45689 | C5: (presupuesto cerrado dic-2024)
A6: Duración estimada (meses) | B6: 18 | C6: feb-2025 a ago-2026
A7: — ÍNDICE CAC —
A8: Mes base CAC | B8: ='0_Indice_CAC'!A4 -> 45627 | C8: fecha base del presupuesto
A9: Valor CAC base | B9: ='0_Indice_CAC'!B4 -> 15356.4 | C9: valor del índice en mes base
A10: Mes CAC más reciente cargado | B10: =INDEX('0_Indice_CAC'!A:A,MATCH(1E+300,'0_Indice_CAC'!B:B)) -> 46174 | C10: último mes con valor en B
A11: Ratio CAC mes corriente | B11: =MIN('0_Indice_CAC'!D:D) -> 0.79437459 | C11: ratio del mes más reciente
A13: — COEFICIENTE K —
A14: K (coeficiente GG+B) | B14: ='1_GGBB'!F67 -> 1.4355353 | C14: incluye GG + Equipos + Imprevistos + Beneficio
A15: % GG+B sobre costo | B15: ='1_GGBB'!F65 -> 0.43553532 | C15: sumatoria sin el 1
A17: — PRESUPUESTO —
A18: Costo total presupuestado | B18: =SUMPRODUCT(('1_Presupuesto'!$K$5:$K$227+'1_Presupuesto'!$L$5:$L$227+'1_Presupuesto'!$M$5:$M$227)*'1_Presupuesto'!$J$5:$J$227) -> 9.9459803e+08 | C18: costo controlable por rubro (excl. EQ $21.5M)
A19: Precio de venta total | B19: =SUMPRODUCT('1_Presupuesto'!$O$5:$O$227*'1_Presupuesto'!$J$5:$J$227)*B14 -> 1.4587531e+09 | C19: costo × K
A20: Sanity Check (P. Costo) | B20: =SUMPRODUCT('1_Presupuesto'!$P$5:$P$227*'1_Presupuesto'!$J$5:$J$227)-B19 -> 0
A21: — NOTAS DE VERSIÓN —
A22: Versión | B22: Resumen GDR 3760 — v7 (Cash Flow Monto Base + 6 mejoras Cat. A)
A23: Hojas eliminadas en Tanda 1 | B23: "HOJA DE OBRA", "Certificaciones de avance" (vieja)
A24: Bugs corregidos | B24: CAC D17-D20 contra $B$2; K vinculado a GGBB!F67; cols fantasma Gastos
A25: Columna nueva en Gastos | B25: U: "Contrato" — llenar SC-XXX en pagos a subcontratos
A27: — TANDA 2 (rediseño certificación/facturación) —
A28: Hojas eliminadas en T2 | B28: "Cert. Pto. 01", "Cert. Pto. 02", "Certificados", "Facturacion", "Preventivo Vta", "Contratistas"
A29: Hoja nueva en T2 | B29: 2_Certificaciones — registro unificado con estado Certificado → Facturado → Cobrado
A30: Renombre con prefijos | B30: 0_ (config/refs) / 1_ (presupuesto) / 2_ (operativo) / 3_ (control) / _ (legacy)
A31: Pagos actualizada | B31: usa Tabla18[Contrato] — se llena sola con pagos que tengan código SC- cargado
A32: Pendiente para T3 | B32: Reconstruir Cash Flow y armar Dashboard
A34: — TANDA 3 (Cash Flow + Gastos Directos/Indirectos) —
A35: Hoja nueva: 2_Gastos_DirInd | B35: Carga mensual de 13 directos + 3 indirectos. Total Real y Total Descontado por CAC calculados.
A36: Hoja rediseñada: 3_Cash_Flow | B36: 22 meses (nov-24 → ago-26). 8 filas: Ingresos, Ingresos CAC, Egresos, Directos, Indirectos, Total Eg., Resultado mes, Acumulado.
A37: Col nueva en 2_Gastos: X "En Ppto" | B37: TRUE/FALSE según si el Rubro está en Control PPTO. Filtra egresos del Cash Flow.
A38: Control PPTO ampliado | B38: Filas 40-52 (Directos) completadas con ppto desde GGBB. Filas 55-57 (Indirectos) con ppto VACÍO (cargar manual).
A39: Pendiente — Ingresos por CAC | B39: Stand by: usar col V "Monto CAC" para identificar componente CAC en cobros, cuando se defina con Arquinering.
A40: — AUDITORÍA FINAL (Dashboard + Limpieza) —
A41: Hoja nueva: 3_Dashboard | B41: Vista ejecutiva una página con 5 secciones (Avance Fin., Avance Pres., Rentab., Top desvíos, Subcontratos)
A42: Hoja eliminada | B42: _01_snapshot (250 filas, 0 referencias — historial obsoleto)
A43: Validaciones de datos | B43: 2_Gastos col A (Rubro) y B (MT/MO) ahora usan listas desde _Listas
A44: Formato condicional | B44: Semáforos en %desvío (Control PPTO) + resultado del mes (Cash Flow) + KPIs (Dashboard)
A45: Protección de hojas 3_ | B45: Las 4 vistas calculadas están bloqueadas para edición accidental — desproteger desde Revisar > Desproteger Hoja
...

Sheet 0_Indice_CAC
A1: INDICE CAC
A3: Escala de tiempo | B3: Valores | C3: Previsión | D3: Indice
A4: 45627 | B4: 15356.4 | D4: =$B$4/B4 -> 1
A5: 45658 | B5: 15592.5 | D5: =$B$4/B5 -> 0.9848581
A6: 45689 | B6: 15852.4 | D6: =$B$4/B6 -> 0.96871136
A7: 45717 | B7: 15995.4 | D7: =$B$4/B7 -> 0.96005101
A8: 45748 | B8: 16253.5 | D8: =$B$4/B8 -> 0.94480573
A9: 45778 | B9: 16521.3 | D9: =$B$4/B9 -> 0.92949102
A10: 45809 | B10: 16643.4 | D10: =$B$4/B10 -> 0.92267205
A11: 45839 | B11: 16939.5 | D11: =$B$4/B11 -> 0.90654388
A12: 45870 | B12: 17187.6 | D12: =$B$4/B12 -> 0.89345807
A13: 45901 | B13: 17762.3 | D13: =$B$4/B13 -> 0.8645502
A14: 45931 | B14: 18172.8 | D14: =$B$4/B14 -> 0.84502113
A15: 45962 | B15: 18534.9 | D15: =$B$4/B15 -> 0.8285127
A16: 45992 | B16: 18993.891 | C16: 18993.891 | D16: =$B$4/B16 -> 0.80849152
A17: 46023 | B17: 19331.434 | C17: 19331.434 | D17: =$B$4/B17 -> 0.79437459
A18: 46054 | B18: 19331.434 | D18: =$B$4/B18 -> 0.79437459
A19: 46082 | B19: 19331.434 | D19: =$B$4/B19 -> 0.79437459
A20: 46113 | B20: 19331.434 | D20: =$B$4/B20 -> 0.79437459
A21: 46143 | B21: 19331.434 | D21: =$B$4/B21 -> 0.79437459
A22: 46174 | B22: 19331.434 | D22: =$B$4/B22 -> 0.79437459

Sheet 0_Jornales_MO
A1: SECCIÓN A — TABLA DE TARIFAS POR CATEGORÍA (Costo por Día/Quincena)
A3: PERÍODO | B3: ESPEC. ($/día) | C3: OFICIAL ($/día) | D3: 1/2 OFICIAL ($/día) | E3: AYUDANTE ($/día) | G3: ESPEC. ($/hr) | H3: OFICIAL ($/día) | I3: 1/2 OFICIAL ($/día) | J3: AYUDANTE ($/día)
A4: 45627 | B4: 85927.1 | C4: 76955.08 | D4: 65493.07 | E4: 60860.58 | G4: =+B4/8 -> 10740.888 | H4: =+C4/8 -> 9619.385 | I4: =+D4/8 -> 8186.6337 | J4: =+E4/8 -> 7607.5725
A5: 45658 | B5: 87384 | C5: 78375 | D5: 66853 | E5: 61892 | G5: =+B5/8 -> 10923 | H5: =+C5/8 -> 9796.875 | I5: =+D5/8 -> 8356.625 | J5: =+E5/8 -> 7736.5
A6: 45689 | B6: 89383 | C6: 80395 | D6: 68472 | E6: 63382 | G6: =+B6/8 -> 11172.875 | H6: =+C6/8 -> 10049.375 | I6: =+D6/8 -> 8559 | J6: =+E6/8 -> 7922.75
A7: 45717 | B7: 91464 | C7: 82269 | D7: 70296 | E7: 65595 | G7: =+B7/8 -> 11433 | H7: =+C7/8 -> 10283.625 | I7: =+D7/8 -> 8787 | J7: =+E7/8 -> 8199.375
A8: 45778 | B8: 93235.367 | C8: 83766.388 | D8: 71410.817 | E8: 66568.094 | G8: =+B8/8 -> 11654.421 | H8: =+C8/8 -> 10470.798 | I8: =+D8/8 -> 8926.3521 | J8: =+E8/8 -> 8321.0117
A9: 45809 | B9: 94177.138 | C9: 84612.513 | D9: 72132.138 | E9: 67240.499 | G9: =+B9/8 -> 11772.142 | H9: =+C9/8 -> 10576.564 | I9: =+D9/8 -> 9016.5173 | J9: =+E9/8 -> 8405.0624
A10: 45839 | B10: 95080 | C10: 85425 | D10: 72871 | E10: 67908 | G10: =+B10/8 -> 11885 | H10: =+C10/8 -> 10678.125 | I10: =+D10/8 -> 9108.875 | J10: =+E10/8 -> 8488.5
A11: 45870 | B11: 95889.2 | C11: 86356.18 | D11: 73781.11 | E11: 68935.35 | G11: =+B11/8 -> 11986.15 | H11: =+C11/8 -> 10794.522 | I11: =+D11/8 -> 9222.6388 | J11: =+E11/8 -> 8616.9188
A12: 45901 | B12: 106516.02 | C12: 88649.808 | D12: 75758.192 | E12: 71041.119 | G12: =+B12/8 -> 13314.502 | H12: =+C12/8 -> 11081.226 | I12: =+D12/8 -> 9469.774 | J12: =+E12/8 -> 8880.1398
A13: 45931 | B13: 106864.21 | C13: 88971.073 | D13: 76032.176 | E13: 71292.271 | G13: =+B13/8 -> 13358.026 | H13: =+C13/8 -> 11121.384 | I13: =+D13/8 -> 9504.0221 | J13: =+E13/8 -> 8911.5339
A14: 45962 | B14: 109621.11 | C14: 91252.851 | D14: 77612.118 | E14: 72486.683 | G14: =+B14/8 -> 13702.638 | H14: =+C14/8 -> 11406.606 | I14: =+D14/8 -> 9701.5148 | J14: =+E14/8 -> 9060.8353
A15: 45992 | B15: 113865.18 | C15: 95196.927 | D15: 81356.194 | E15: 76230.759 | G15: =+B15/8 -> 14233.148 | H15: =+C15/8 -> 11899.616 | I15: =+D15/8 -> 10169.524 | J15: =+E15/8 -> 9528.8449
... A21: 46174 | B21: 122445.79 | C21: 102029.07 | D21: 87100.47 | E21: 81453.719 | G21: =+B21/8 -> 15305.724 | H21: =+C21/8 -> 12753.633 | I21: =+D21/8 -> 10887.559 | J21: =+E21/8 -> 10181.715

Sheet 1_Presupuesto
A1: PRESUPUESTO OBRA CIVIL y CERTIFICACIONES DE AVANCE
P2: ='1_GGBB'!F67 -> 1.4355353
A3: Rubro MT | B3: Rubro MT / Prov | C3: Rubro MO / OTR | D3: Rubro MO / ALB | G3: E | H3: Descripción | I3: U | J3: Cant | K3: MT | L3: MO / OTR | M3: MO / ALB | N3: EQ | O3: Costo Unit. | P3: P Unit. | R3: MT | S3: MO / OTR | T3: MO / ALB | U3: EQ | V3: P.Unit | X3: MT | Y3: MO | Z3: Subtotal | AB3: ETAPA | AC3: % Acum. Ant. | AD3: % Cert. Actual | AE3: % Acum. Total | AG3: Imp. Acum. Ant. | AH3: Imp. Cert. Actual | AI3: Imp. Acum. Total | AK3: Acum. MT | AL3: Acum. MO/OTR | AM3: Acum. MO/ALB | AN3: Acum. EQ | AO3: Acum. Subtotal | AQ3: Costo_ud | AR3: Costo_total
F4: 1 | H4: TAREAS PRELIMINARES | AA4: =+SUM(Z5:Z13) -> 21422381 | AB4: TAREAS PRELIMINARES
A5: - | B5: - | C5: - | D5: - | F5: 1.01 | G5: OK | H5: Limpieza y preparación del terreno - No cotiza | I5: gl | J5: 1 | K5: 0 | L5: 0 | M5: 0 | N5: 0 | O5: =+SUM(K5:N5) -> 0 | P5: =+O5*$P$2 -> 0 | R5: =+K5*$P$2 -> 0 | S5: =+L5*$P$2 -> 0 | T5: =+M5*$P$2 -> 0 | U5: =+N5*$P$2 -> 0 | V5: =+SUM(R5:U5) -> 0 | X5: =+R5*J5 -> 0 | Y5: =+Z5-X5 -> 0 | Z5: =+V5*J5 -> 0 | AB5: TAREAS PRELIMINARES | AC5: 0 | AD5: 0 | AE5: =AC5+AD5 -> 0 | AF5: =IF($AE5=1,"🔴","⚪") -> ⚪ | AG5: =AC5*Z5 -> 0 | AH5: =AD5*Z5 -> 0 | AI5: =AE5*Z5 -> 0 | AK5: =AE5*X5 -> 0 | AL5: =AE5*S5*J5 -> 0 | AM5: =AE5*T5*J5 -> 0 | AN5: =AE5*U5*J5 -> 0 | AO5: =AK5+AL5+AM5+AN5 -> 0 | AQ5: =+O5 -> 0 | AR5: =+O5*J5 -> 0
A6: Agrimensura | B6: - | C6: Agrimensura | D6: Preliminar | F6: 1.02 | G6: OK | H6: Topógrafo - Visita de obra replanteo | I6: gl | J6: 3 | K6: 25000 | L6: 198736.84 | M6: 60860.581 | N6: 4268.9614 | O6: =+SUM(K6:N6) -> 288866.39 | P6: =+O6*$P$2 -> 414677.9 | R6: =+K6*$P$2 -> 35888.383 | S6: =+L6*$P$2 -> 285293.76 | T6: =+M6*$P$2 -> 87367.513 | U6: =+N6*$P$2 -> 6128.2448 | V6: =+SUM(R6:U6) -> 414677.9 | X6: =+R6*J6 -> 107665.15 | Y6: =+Z6-X6 -> 1136368.6 | Z6: =+V6*J6 -> 1244033.7 | AB6: TAREAS PRELIMINARES | AC6: 1 | AD6: 0 | AE6: =AC6+AD6 -> 1 | AF6: =IF($AE6=1,"🔴","⚪") -> 🔴 | AG6: =AC6*Z6 -> 1244033.7 | AH6: =AD6*Z6 -> 0 | AI6: =AE6*Z6 -> 1244033.7 | AK6: =AE6*X6 -> 107665.15 | AL6: =AE6*S6*J6 -> 855881.28 | AM6: =AE6*T6*J6 -> 262102.54 | AN6: =AE6*U6*J6 -> 18384.735 | AO6: =AK6+AL6+AM6+AN6 -> 1244033.7 | AQ6: =+O6 -> 288866.39 | AR6: =+O6*J6 -> 866599.16
A7: - | B7: - | C7: - | D7: - | F7: 1.03 | G7: OK | H7: Cartel de Obra - No cotiza | I7: gl | J7: 1 | K7: 0 | L7: 0 | M7: 0 | N7: 0 | O7: =+SUM(K7:N7) -> 0 | P7: =+O7*$P$2 -> 0 | R7: =+K7*$P$2 -> 0 | S7: =+L7*$P$2 -> 0 | T7: =+M7*$P$2 -> 0 | U7: =+N7*$P$2 -> 0 | V7: =+SUM(R7:U7) -> 0 | X7: =+R7*J7 -> 0 | Y7: =+Z7-X7 -> 0 | Z7: =+V7*J7 -> 0 | AB7: TAREAS PRELIMINARES | AC7: 0 | AD7: 0 | AE7: =AC7+AD7 -> 0 | AF7: =IF($AE7=1,"🔴","⚪") -> ⚪ | AG7: =AC7*Z7 -> 0 | AH7: =AD7*Z7 -> 0 | AI7: =AE7*Z7 -> 0 | AK7: =AE7*X7 -> 0 | AL7: =AE7*S7*J7 -> 0 | AM7: =AE7*T7*J7 -> 0 | AN7: =AE7*U7*J7 -> 0 | AO7: =AK7+AL7+AM7+AN7 -> 0 | AQ7: =+O7 -> 0 | AR7: =+O7*J7 -> 0
A8: Preliminar | B8: - | C8: - | D8: Preliminar | F8: 1.04 | G8: OK | H8: Cerco de obra perimetral - En chapa C25 + Concertina + Porton corredizo | I8: ml | J8: 10 | K8: 88330.703 | L8: 0 | M8: 101654.37 | N8: 2849.776 | O8: =+SUM(K8:N8) -> 192834.84 | P8: =+O8*$P$2 -> 276821.23 | R8: =+K8*$P$2 -> 126801.84 | S8: =+L8*$P$2 -> 0 | T8: =+M8*$P$2 -> 145928.43 | U8: =+N8*$P$2 -> 4090.9541 | V8: =+SUM(R8:U8) -> 276821.23 | X8: =+R8*J8 -> 1268018.4 | Y8: =+Z8-X8 -> 1500193.9 | Z8: =+V8*J8 -> 2768212.3 | AB8: TAREAS PRELIMINARES | AC8: 1 | AD8: 0 | AE8: =AC8+AD8 -> 1 | AF8: =IF($AE8=1,"🔴","⚪") -> 🔴 | AG8: =AC8*Z8 -> 2768212.3 | AH8: =AD8*Z8 -> 0 | AI8: =AE8*Z8 -> 2768212.3 | AK8: =AE8*X8 -> 1268018.4 | AL8: =AE8*S8*J8 -> 0 | AM8: =AE8*T8*J8 -> 1459284.3 | AN8: =AE8*U8*J8 -> 40909.541 | AO8: =AK8+AL8+AM8+AN8 -> 2768212.3 | AQ8: =+O8 -> 192834.84 | AR8: =+O8*J8 -> 1928348.4
A9: Preliminar | B9: - | C9: Preliminar | D9: Preliminar | F9: 1.05 | G9: OK | H9: Obrador, pañol y ducha. | I9: gl | J9: 1 | K9: 2078824.7 | L9: 750000 | M9: 4424962.9 | N9: 108806.81 | O9: =+SUM(K9:N9) -> 7362594.4 | P9: =+O9*$P$2 -> 10569264 | R9: =+K9*$P$2 -> 2984226.3 | S9: =+L9*$P$2 -> 1076651.5 | T9: =+M9*$P$2 -> 6352190.5 | U9: =+N9*$P$2 -> 156196.02 | V9: =+SUM(R9:U9) -> 10569264 | X9: =+R9*J9 -> 2984226.3 | Y9: =+Z9-X9 -> 7585038 | Z9: =+V9*J9 -> 10569264 | AB9: TAREAS PRELIMINARES | AC9: 1 | AD9: 0 | AE9: =AC9+AD9 -> 1 | AF9: =IF($AE9=1,"🔴","⚪") -> 🔴 | AG9: =AC9*Z9 -> 10569264 | AH9: =AD9*Z9 -> 0 | AI9: =AE9*Z9 -> 10569264 | AK9: =AE9*X9 -> 2984226.3 | AL9: =AE9*S9*J9 -> 1076651.5 | AM9: =AE9*T9*J9 -> 6352190.5 | AN9: =AE9*U9*J9 -> 156196.02 | AO9: =AK9+AL9+AM9+AN9 -> 10569264 | AQ9: =+O9 -> 7362594.4 | AR9: =+O9*J9 -> 7362594.4
A10: Gastos Generales Obra | B10: - | C10: Gastos Generales Obra | D10: Preliminar | F10: 1.06 | G10: OK | H10: Alquiler de baños quimicos y duchas portatiles | I10: mes | J10: 4 | K10: 0 | L10: 318994.12 | M10: 13291.422 | N10: 0 | O10: =+SUM(K10:N10) -> 332285.54 | P10: =+O10*$P$2 -> 477007.63 | R10: =+K10*$P$2 -> 0 | S10: =+L10*$P$2 -> 457927.33 | T10: =+M10*$P$2 -> 19080.305 | U10: =+N10*$P$2 -> 0 | V10: =+SUM(R10:U10) -> 477007.63 | X10: =+R10*J10 -> 0 | Y10: =+Z10-X10 -> 1908030.5 | Z10: =+V10*J10 -> 1908030.5 | AB10: TAREAS PRELIMINARES | AC10: 1 | AD10: 0 | AE10: =AC10+AD10 -> 1 | AF10: =IF($AE10=1,"🔴","⚪") -> 🔴 | AG10: =AC10*Z10 -> 1908030.5 | AH10: =AD10*Z10 -> 0 | AI10: =AE10*Z10 -> 1908030.5 | AK10: =AE10*X10 -> 0 | AL10: =AE10*S10*J10 -> 1831709.3 | AM10: =AE10*T10*J10 -> 76321.221 | AN10: =AE10*U10*J10 -> 0 | AO10: =AK10+AL10+AM10+AN10 -> 1908030.5 | AQ10: =+O10 -> 332285.54 | AR10: =+O10*J10 -> 1329142.2
A11: Preliminar | B11: - | C11: - | D11: Preliminar | F11: 1.07 | G11: OK | H11: Conexión pilar y luz de obra + Tablero de obra | I11: gl | J11: 1 | K11: 1090000 | L11: 0 | M11: 601395.67 | N11: 25370.935 | O11: =+SUM(K11:N11) -> 1716766.6 | P11: =+O11*$P$2 -> 2464479.1 | R11: =+K11*$P$2 -> 1564733.5 | S11: =+L11*$P$2 -> 0 | T11: =+M11*$P$2 -> 863324.73 | U11: =+N11*$P$2 -> 36420.873 | V11: =+SUM(R11:U11) -> 2464479.1 | X11: =+R11*J11 -> 1564733.5 | Y11: =+Z11-X11 -> 899745.6 | Z11: =+V11*J11 -> 2464479.1 | AB11: TAREAS PRELIMINARES | AC11: 1 | AD11: 0 | AE11: =AC11+AD11 -> 1 | AF11: =IF($AE11=1,"🔴","⚪") -> 🔴 | AG11: =AC11*Z11 -> 2464479.1 | AH11: =AD11*Z11 -> 0 | AI11: =AE11*Z11 -> 2464479.1 | AK11: =AE11*X11 -> 1564733.5 | AL11: =AE11*S11*J11 -> 0 | AM11: =AE11*T11*J11 -> 863324.73 | AN11: =AE11*U11*J11 -> 36420.873 | AO11: =AK11+AL11+AM11+AN11 -> 2464479.1 | AQ11: =+O11 -> 1716766.6 | AR11: =+O11*J11 -> 1716766.6
A12: Preliminar | B12: - | C12: - | D12: Preliminar | F12: 1.08 | G12: OK | H12: Conexión agua de obra, tanque + bomba | I12: gl | J12: 1 | K12: 685200 | L12: 0 | M12: 651528.71 | N12: 20050.931 | O12: =+SUM(K12:N12) -> 1356779.6 | P12: =+O12*$P$2 -> 1947705.1 | R12: =+K12*$P$2 -> 983628.8 | S12: =+L12*$P$2 -> 0 | T12: =+M12*$P$2 -> 935292.47 | U12: =+N12*$P$2 -> 28783.819 | V12: =+SUM(R12:U12) -> 1947705.1 | X12: =+R12*J12 -> 983628.8 | Y12: =+Z12-X12 -> 964076.29 | Z12: =+V12*J12 -> 1947705.1 | AB12: TAREAS PRELIMINARES | AC12: 1 | AD12: 0 | AE12: =AC12+AD12 -> 1 | AF12: =IF($AE12=1,"🔴","⚪") -> 🔴 | AG12: =AC12*Z12 -> 1947705.1 | AH12: =AD12*Z12 -> 0 | AI12: =AE12*Z12 -> 1947705.1 | AK12: =AE12*X12 -> 983628.8 | AL12: =AE12*S12*J12 -> 0 | AM12: =AE12*T12*J12 -> 935292.47 | AN12: =AE12*U12*J12 -> 28783.819 | AO12: =AK12+AL12+AM12+AN12 -> 1947705.1 | AQ12: =+O12 -> 1356779.6 | AR12: =+O12*J12 -> 1356779.6
A13: Preliminar | B13: - | C13: Preliminar | D13: - | F13: 1.09 | G13: OK | H13: Tramite luz de obra, certificado luz de obra (2) y medición PAT | I13: gl | J13: 1 | K13: 0 | L13: 362691.09 | M13: 0 | N13: 0 | O13: =+SUM(K13:N13) -> 362691.09 | P13: =+O13*$P$2 -> 520655.86 | R13: =+K13*$P$2 -> 0 | S13: =+L13*$P$2 -> 520655.86 | T13: =+M13*$P$2 -> 0 | U13: =+N13*$P$2 -> 0 | V13: =+SUM(R13:U13) -> 520655.86 | X13: =+R13*J13 -> 0 | Y13: =+Z13-X13 -> 520655.86 | Z13: =+V13*J13 -> 520655.86 | AB13: TAREAS PRELIMINARES | AC13: 1 | AD13: 0 | AE13: =AC13+AD13 -> 1 | AF13: =IF($AE13=1,"🔴","⚪") -> 🔴 | AG13: =AC13*Z13 -> 520655.86 | AH13: =AD13*Z13 -> 0 | AI13: =AE13*Z13 -> 520655.86 | AK13: =AE13*X13 -> 0 | AL13: =AE13*S13*J13 -> 520655.86 | AM13: =AE13*T13*J13 -> 0 | AN13: =AE13*U13*J13 -> 0 | AO13: =AK13+AL13+AM13+AN13 -> 520655.86 | AQ13: =+O13 -> 362691.09 | AR13: =+O13*J13 -> 362691.09
A14: - | B14: - | C14: - | D14: - | F14: 2 | H14: MOVIMIENTO DE TIERRA, COMPACTACION Y RELLENO | AA14: =+SUM(Z15:Z19) -> 31937041 | AB14: MOVIMIENTO DE TIERRA, COMPACTACION Y RELLENO
A15: Excavación y Mov. de Suelos | B15: - | C15: Excavación y Mov. de Suelos | D15: Hormigón | F15: 2.01 | G15: OK | H15: Excavación a maquina para submuración, subsuelo y fundaciones | I15: m3 | J15: 308 | K15: 0 | L15: 33000 | M15: 6520.7765 | N15: 97.811648 | O15: =+SUM(K15:N15) -> 39618.588 | P15: =+O15*$P$2 -> 56873.883 | R15: =+K15*$P$2 -> 0 | S15: =+L15*$P$2 -> 47372.665 | T15: =+M15*$P$2 -> 9360.805 | U15: =+N15*$P$2 -> 140.41207 | V15: =+SUM(R15:U15) -> 56873.883 | X15: =+R15*J15 -> 0 | Y15: =+Z15-X15 -> 17517156 | Z15: =+V15*J15 -> 17517156 | AB15: MOVIMIENTO DE TIERRA, COMPACTACION Y RELLENO | AC15: 1 | AD15: 0 | AE15: =AC15+AD15 -> 1 | AF15: =IF($AE15=1,"🔴","⚪") -> 🔴 | AG15: =AC15*Z15 -> 17517156 | AH15: =AD15*Z15 -> 0 | AI15: =AE15*Z15 -> 17517156 | AK15: =AE15*X15 -> 0 | AL15: =AE15*S15*J15 -> 14590781 | AM15: =AE15*T15*J15 -> 2883127.9 | AN15: =AE15*U15*J15 -> 43246.919 | AO15: =AK15+AL15+AM15+AN15 -> 17517156 | AQ15: =+O15 -> 39618.588 | AR15: =+O15*J15 -> 12202525
A16: Excavación y Mov. de Suelos | B16: - | C16: Excavación y Mov. de Suelos | D16: Preliminar | F16: 2.02 | G16: OK | H16: Perfilado manual de bases. Relleno y compactación de pozos | I16: gl | J16: 1 | K16: 105000 | L16: 455000 | M16: 8033596.7 | N16: 128903.95 | O16: =+SUM(K16:N16) -> 8722500.6 | P16: =+O16*$P$2 -> 12521458 | R16: =+K16*$P$2 -> 150731.21 | S16: =+L16*$P$2 -> 653168.57 | T16: =+M16*$P$2 -> 11532512 | U16: =+N16*$P$2 -> 185046.17 | V16: =+SUM(R16:U16) -> 12521458 | X16: =+R16*J16 -> 150731.21 | Y16: =+Z16-X16 -> 12370726 | Z16: =+V16*J16 -> 12521458 | AB16: MOVIMIENTO DE TIERRA, COMPACTACION Y RELLENO | AC16: 1 | AD16: 0 | AE16: =AC16+AD16 -> 1 | AF16: =IF($AE16=1,"🔴","⚪") -> 🔴 | AG16: =AC16*Z16 -> 12521458 | AH16: =AD16*Z16 -> 0 | AI16: =AE16*Z16 -> 12521458 | AK16: =AE16*X16 -> 150731.21 | AL16: =AE16*S16*J16 -> 653168.57 | AM16: =AE16*T16*J16 -> 11532512 | AN16: =AE16*U16*J16 -> 185046.17 | AO16: =AK16+AL16+AM16+AN16 -> 12521458 | AQ16: =+O16 -> 8722500.6 | AR16: =+O16*J16 -> 8722500.6
A17: Excavación y Mov. de Suelos | B17: - | C17: - | D17: Preliminar | F17: 2.03 | G17: OK | H17: Excavación manual para vigas de fundación | I17: m3 | J17: 15 | K17: 26000 | L17: 0 | M17: 60860.581 | N17: 1302.9087 | O17: =+SUM(K17:N17) -> 88163.489 | P17: =+O17*$P$2 -> 126561.8 | R17: =+K17*$P$2 -> 37323.918 | S17: =+L17*$P$2 -> 0 | T17: =+M17*$P$2 -> 87367.513 | U17: =+N17*$P$2 -> 1870.3715 | V17: =+SUM(R17:U17) -> 126561.8 | X17: =+R17*J17 -> 559858.77 | Y17: =+Z17-X17 -> 1338568.3 | Z17: =+V17*J17 -> 1898427 | AB17: MOVIMIENTO DE TIERRA, COMPACTACION Y RELLENO | AC17: 1 | AD17: 0 | AE17: =AC17+AD17 -> 1 | AF17: =IF($AE17=1,"🔴","⚪") -> 🔴 | AG17: =AC17*Z17 -> 1898427 | AH17: =AD17*Z17 -> 0 | AI17: =AE17*Z17 -> 1898427 | AK17: =AE17*X17 -> 559858.77 | AL17: =AE17*S17*J17 -> 0 | AM17: =AE17*T17*J17 -> 1310512.7 | AN17: =AE17*U17*J17 -> 28055.572 | AO17: =AK17+AL17+AM17+AN17 -> 1898427 | AQ17: =+O17 -> 88163.489 | AR17: =+O17*J17 -> 1322452.3
A18: - | B18: - | C18: - | D18: - | F18: 2.04 | G18: IN | H18: Aporte y compactación de suelo seleccionado, e: 40 cm (2 capas de 20 cm) - Cotizado Hº Pobre en item 8,02 | I18: m2 | J18: 0 | K18: 0 | L18: 0 | M18: 0 | N18: 0 | O18: =+SUM(K18:N18) -> 0 | P18: =+O18*$P$2 -> 0 | R18: =+K18*$P$2 -> 0 | S18: =+L18*$P$2 -> 0 | T18: =+M18*$P$2 -> 0 | U18: =+N18*$P$2 -> 0 | V18: =+SUM(R18:U18) -> 0 | X18: =+R18*J18 -> 0 | Y18: =+Z18-X18 -> 0 | Z18: =+V18*J18 -> 0 | AB18: MOVIMIENTO DE TIERRA, COMPACTACION Y RELLENO | AC18: 0 | AD18: 0 | AE18: =AC18+AD18 -> 0 | AF18: =IF($AE18=1,"🔴","⚪") -> ⚪ | AG18: =AC18*Z18 -> 0 | AH18: =AD18*Z18 -> 0 | AI18: =AE18*Z18 -> 0 | AK18: =AE18*X18 -> 0 | AL18: =AE18*S18*J18 -> 0 | AM18: =AE18*T18*J18 -> 0 | AN18: =AE18*U18*J18 -> 0 | AO18: =AK18+AL18+AM18+AN18 -> 0 | AQ18: =+O18 -> 0 | AR18: =+O18*J18 -> 0
A19: - | B19: - | C19: - | D19: - | F19: 2.05 | G19: OK | H19: Demolición de bases existentes - No cotiza | I19: gl | J19: 0 | K19: 0 | L19: 0 | M19: 0 | N19: 0 | O19: =+SUM(K19:N19) -> 0 | P19: =+O19*$P$2 -> 0 | R19: =+K19*$P$2 -> 0 | S19: =+L19*$P$2 -> 0 | T19: =+M19*$P$2 -> 0 | U19: =+N19*$P$2 -> 0 | V19: =+SUM(R19:U19) -> 0 | X19: =+R19*J19 -> 0 | Y19: =+Z19-X19 -> 0 | Z19: =+V19*J19 -> 0 | AB19: MOVIMIENTO DE TIERRA, COMPACTACION Y RELLENO | AC19: 0 | AD19: 0 | AE19: =AC19+AD19 -> 0 | AF19: =IF($AE19=1,"🔴","⚪") -> ⚪ | AG19: =AC19*Z19 -> 0 | AH19: =AD19*Z19 -> 0 | AI19: =AE19*Z19 -> 0 | AK19: =AE19*X19 -> 0 | AL19: =AE19*S19*J19 -> 0 | AM19: =AE19*T19*J19 -> 0 | AN19: =AE19*U19*J19 -> 0 | AO19: =AK19+AL19+AM19+AN19 -> 0 | AQ19: =+O19 -> 0 | AR19: =+O19*J19 -> 0
A20: - | B20: - | C20: - | D20: - | F20: 3 | H20: ESTRUCTURA RESISTENTE | AA20: =+SUM(Z21:Z41) -> 4.8618836e+08 | AB20: ESTRUCTURA RESISTENTE
A21: Hormigón | B21: - | C21: - | D21: Hormigón | F21: 3.01 | G21: OK | H21: Hormigón de limpieza - e: 10 cm | I21: m3 | J21: 13 | K21: 115100 | L21: 0 | M21: 101603.58 | N21: 3250.5537 | O21: =+SUM(K21:N21) -> 219954.14 | P21: =+O21*$P$2 -> 315751.93 | R21: =+K21*$P$2 -> 165230.12 | S21: =+L21*$P$2 -> 0 | T21: =+M21*$P$2 -> 145855.53 | U21: =+N21*$P$2 -> 4666.2847 | V21: =+SUM(R21:U21) -> 315751.93 | X21: =+R21*J21 -> 2147991.5 | Y21: =+Z21-X21 -> 1956783.6 | Z21: =+V21*J21 -> 4104775.1 | AB21: ESTRUCTURA RESISTENTE | AC21: 1 | AD21: 0 | AE21: =AC21+AD21 -> 1 | AF21: =IF($AE21=1,"🔴","⚪") -> 🔴 | AG21: =AC21*Z21 -> 4104775.1 | AH21: =AD21*Z21 -> 0 | AI21: =AE21*Z21 -> 4104775.1 | AK21: =AE21*X21 -> 2147991.5 | AL21: =AE21*S21*J21 -> 0 | AM21: =AE21*T21*J21 -> 1896121.9 | AN21: =AE21*U21*J21 -> 60661.701 | AO21: =AK21+AL21+AM21+AN21 -> 4104775.1 | AQ21: =+O21 -> 219954.14 | AR21: =+O21*J21 -> 2859403.8
A22: Hormigón | B22: - | C22: Hormigón | D22: - | F22: 3.02 | G22: OK | H22: Pilotes de tracción Ø 20 cm - (120 kg/m3 de hierro) | I22: u | J22: 18 | K22: 90570.796 | L22: 250000 | M22: 0 | N22: 5108.5619 | O22: =+SUM(K22:N22) -> 345679.36 | P22: =+O22*$P$2 -> 496234.93 | R22: =+K22*$P$2 -> 130017.58 | S22: =+L22*$P$2 -> 358883.83 | T22: =+M22*$P$2 -> 0 | U22: =+N22*$P$2 -> 7333.5211 | V22: =+SUM(R22:U22) -> 496234.93 | X22: =+R22*J22 -> 2340316.4 | Y22: =+Z22-X22 -> 6591912.3 | Z22: =+V22*J22 -> 8932228.7 | AB22: ESTRUCTURA RESISTENTE | AC22: 1 | AD22: 0 | AE22: =AC22+AD22 -> 1 | AF22: =IF($AE22=1,"🔴","⚪") -> 🔴 | AG22: =AC22*Z22 -> 8932228.7 | AH22: =AD22*Z22 -> 0 | AI22: =AE22*Z22 -> 8932228.7 | AK22: =AE22*X22 -> 2340316.4 | AL22: =AE22*S22*J22 -> 6459908.9 | AM22: =AE22*T22*J22 -> 0 | AN22: =AE22*U22*J22 -> 132003.38 | AO22: =AK22+AL22+AM22+AN22 -> 8932228.7 | AQ22: =+O22 -> 345679.36 | AR22: =+O22*J22 -> 6222228.4
A23: Hormigón | B23: - | C23: Hormigón | D23: - | F23: 3.03 | G23: OK | H23: Tabique submuración - H35 (95 kg/m3 de hierro) | I23: m3 | J23: 12 | K23: 402072.54 | L23: 357640.9 | M23: 0 | N23: 11395.702 | O23: =+SUM(K23:N23) -> 771109.14 | P23: =+O23*$P$2 -> 1106954.4 | R23: =+K23*$P$2 -> 577189.33 | S23: =+L23*$P$2 -> 513406.14 | T23: =+M23*$P$2 -> 0 | U23: =+N23*$P$2 -> 16358.932 | V23: =+SUM(R23:U23) -> 1106954.4 | X23: =+R23*J23 -> 6926272 | Y23: =+Z23-X23 -> 6357180.9 | Z23: =+V23*J23 -> 13283453 | AB23: ESTRUCTURA RESISTENTE | AC23: 1 | AD23: 0 | AE23: =AC23+AD23 -> 1 | AF23: =IF($AE23=1,"🔴","⚪") -> 🔴 | AG23: =AC23*Z23 -> 13283453 | AH23: =AD23*Z23 -> 0 | AI23: =AE23*Z23 -> 13283453 | AK23: =AE23*X23 -> 6926272 | AL23: =AE23*S23*J23 -> 6160873.7 | AM23: =AE23*T23*J23 -> 0 | AN23: =AE23*U23*J23 -> 196307.19 | AO23: =AK23+AL23+AM23+AN23 -> 13283453 | AQ23: =+O23 -> 771109.14 | AR23: =+O23*J23 -> 9253309.7
A24: Hormigón | B24: - | C24: Hormigón | D24: - | F24: 3.04 | G24: OK | H24: Zapata corrida tabique - H35 (120 kg/m3 de hierro) | I24: m3 | J24: 7 | K24: 428196.58 | L24: 281633.96 | M24: 0 | N24: 10647.458 | O24: =+SUM(K24:N24) -> 720478 | P24: =+O24*$P$2 -> 1034271.6 | R24: =+K24*$P$2 -> 614691.31 | S24: =+L24*$P$2 -> 404295.5 | T24: =+M24*$P$2 -> 0 | U24: =+N24*$P$2 -> 15284.802 | V24: =+SUM(R24:U24) -> 1034271.6 | X24: =+R24*J24 -> 4302839.2 | Y24: =+Z24-X24 -> 2937062.1 | Z24: =+V24*J24 -> 7239901.3 | AB24: ESTRUCTURA RESISTENTE | AC24: 1 | AD24: 0 | AE24: =AC24+AD24 -> 1 | AF24: =IF($AE24=1,"🔴","⚪") -> 🔴 | AG24: =AC24*Z24 -> 7239901.3 | AH24: =AD24*Z24 -> 0 | AI24: =AE24*Z24 -> 7239901.3 | AK24: =AE24*X24 -> 4302839.2 | AL24: =AE24*S24*J24 -> 2830068.5 | AM24: =AE24*T24*J24 -> 0 | AN24: =AE24*U24*J24 -> 106993.62 | AO24: =AK24+AL24+AM24+AN24 -> 7239901.3 | AQ24: =+O24 -> 720478 | AR24: =+O24*J24 -> 5043346
A25: Hormigón | B25: - | C25: Hormigón | D25: - | F25: 3.05 | G25: OK | H25: Platea - H35 (95 kg/m3 de hierro) | I25: m3 | J25: 38 | K25: 333700.51 | L25: 194327.43 | M25: 0 | N25: 7920.4191 | O25: =+SUM(K25:N25) -> 535948.36 | P25: =+O25*$P$2 -> 769372.8 | R25: =+K25*$P$2 -> 479038.86 | S25: =+L25*$P$2 -> 278963.89 | T25: =+M25*$P$2 -> 0 | U25: =+N25*$P$2 -> 11370.041 | V25: =+SUM(R25:U25) -> 769372.8 | X25: =+R25*J25 -> 18203477 | Y25: =+Z25-X25 -> 11032690 | Z25: =+V25*J25 -> 29236166 | AB25: ESTRUCTURA RESISTENTE | AC25: 1 | AD25: 0 | AE25: =AC25+AD25 -> 1 | AF25: =IF($AE25=1,"🔴","⚪") -> 🔴 | AG25: =AC25*Z25 -> 29236166 | AH25: =AD25*Z25 -> 0 | AI25: =AE25*Z25 -> 29236166 | AK25: =AE25*X25 -> 18203477 | AL25: =AE25*S25*J25 -> 10600628 | AM25: =AE25*T25*J25 -> 0 | AN25: =AE25*U25*J25 -> 432061.57 | AO25: =AK25+AL25+AM25+AN25 -> 29236166 | AQ25: =+O25 -> 535948.36 | AR25: =+O25*J25 -> 20366038
A26: Hormigón | B26: - | C26: Hormigón | D26: - | F26: 3.06 | G26: OK | H26: Bases aisladas - (60 kg/m3 de hierro) | I26: m3 | J26: 51 | K26: 275042.38 | L26: 194327.43 | M26: 0 | N26: 7040.5472 | O26: =+SUM(K26:N26) -> 476410.36 | P26: =+O26*$P$2 -> 683903.9 | R26: =+K26*$P$2 -> 394833.05 | S26: =+L26*$P$2 -> 278963.89 | T26: =+M26*$P$2 -> 0 | U26: =+N26*$P$2 -> 10106.954 | V26: =+SUM(R26:U26) -> 683903.9 | X26: =+R26*J26 -> 20136485 | Y26: =+Z26-X26 -> 14742613 | Z26: =+V26*J26 -> 34879099 | AB26: ESTRUCTURA RESISTENTE | AC26: 1 | AD26: 0 | AE26: =AC26+AD26 -> 1 | AF26: =IF($AE26=1,"🔴","⚪") -> 🔴 | AG26: =AC26*Z26 -> 34879099 | AH26: =AD26*Z26 -> 0 | AI26: =AE26*Z26 -> 34879099 | AK26: =AE26*X26 -> 20136485 | AL26: =AE26*S26*J26 -> 14227159 | AM26: =AE26*T26*J26 -> 0 | AN26: =AE26*U26*J26 -> 515454.66 | AO26: =AK26+AL26+AM26+AN26 -> 34879099 | AQ26: =+O26 -> 476410.36 | AR26: =+O26*J26 -> 24296928
A27: Hormigón | B27: - | C27: Hormigón | D27: - | F27: 3.07 | G27: OK | H27: Troncos de columnas - H35 (240 kg/m3 de hierro) | I27: m3 | J27: 16 | K27: 635192.72 | L27: 317914.05 | M27: 0 | N27: 14296.601 | O27: =+SUM(K27:N27) -> 967403.37 | P27: =+O27*$P$2 -> 1388741.7 | R27: =+K27*$P$2 -> 911841.58 | S27: =+L27*$P$2 -> 456376.84 | T27: =+M27*$P$2 -> 0 | U27: =+N27*$P$2 -> 20523.276 | V27: =+SUM(R27:U27) -> 1388741.7 | X27: =+R27*J27 -> 14589465 | Y27: =+Z27-X27 -> 7630401.9 | Z27: =+V27*J27 -> 22219867 | AB27: ESTRUCTURA RESISTENTE | AC27: 1 | AD27: 0 | AE27: =AC27+AD27 -> 1 | AF27: =IF($AE27=1,"🔴","⚪") -> 🔴 | AG27: =AC27*Z27 -> 22219867 | AH27: =AD27*Z27 -> 0 | AI27: =AE27*Z27 -> 22219867 | AK27: =AE27*X27 -> 14589465 | AL27: =AE27*S27*J27 -> 7302029.5 | AM27: =AE27*T27*J27 -> 0 | AN27: =AE27*U27*J27 -> 328372.42 | AO27: =AK27+AL27+AM27+AN27 -> 22219867 | AQ27: =+O27 -> 967403.37 | AR27: =+O27*J27 -> 15478454
A28: Hormigón | B28: - | C28: Hormigón | D28: - | F28: 3.08 | G28: OK | H28: Viga de encadenado - H35 (180 kg/m3 de hierro) | I28: m3 | J28: 7 | K28: 528753.37 | L28: 281633.96 | M28: 0 | N28: 12155.81 | O28: =+SUM(K28:N28) -> 822543.14 | P28: =+O28*$P$2 -> 1180789.7 | R28: =+K28*$P$2 -> 759044.14 | S28: =+L28*$P$2 -> 404295.5 | T28: =+M28*$P$2 -> 0 | U28: =+N28*$P$2 -> 17450.095 | V28: =+SUM(R28:U28) -> 1180789.7 | X28: =+R28*J28 -> 5313309 | Y28: =+Z28-X28 -> 2952219.2 | Z28: =+V28*J28 -> 8265528.1 | AB28: ESTRUCTURA RESISTENTE | AC28: 1 | AD28: 0 | AE28: =AC28+AD28 -> 1 | AF28: =IF($AE28=1,"🔴","⚪") -> 🔴 | AG28: =AC28*Z28 -> 8265528.1 | AH28: =AD28*Z28 -> 0 | AI28: =AE28*Z28 -> 8265528.1 | AK28: =AE28*X28 -> 5313309 | AL28: =AE28*S28*J28 -> 2830068.5 | AM28: =AE28*T28*J28 -> 0 | AN28: =AE28*U28*J28 -> 122150.66 | AO28: =AK28+AL28+AM28+AN28 -> 8265528.1 | AQ28: =+O28 -> 822543.14 | AR28: =+O28*J28 -> 5757802
A29: Hormigón | B29: - | C29: Hormigón | D29: - | F29: 3.09 | G29: OK | H29: Losa maciza - H35 (100 kg/m3 de hierro) | I29: m3 | J29: 90 | K29: 372584.33 | L29: 221790.79 | M29: 0 | N29: 8915.6269 | O29: =+SUM(K29:N29) -> 603290.75 | P29: =+O29*$P$2 -> 866045.18 | R29: =+K29*$P$2 -> 534857.96 | S29: =+L29*$P$2 -> 318388.52 | T29: =+M29*$P$2 -> 0 | U29: =+N29*$P$2 -> 12798.697 | V29: =+SUM(R29:U29) -> 866045.18 | X29: =+R29*J29 -> 48137217 | Y29: =+Z29-X29 -> 29806849 | Z29: =+V29*J29 -> 77944066 | AB29: ESTRUCTURA RESISTENTE | AC29: 0.1591 | AD29: 0 | AE29: =AC29+AD29 -> 0.1591 | AF29: =IF($AE29=1,"🔴","⚪") -> ⚪ | AG29: =AC29*Z29 -> 12400901 | AH29: =AD29*Z29 -> 0 | AI29: =AE29*Z29 -> 12400901 | AK29: =AE29*X29 -> 7658631.2 | AL29: =AE29*S29*J29 -> 4559005.2 | AM29: =AE29*T29*J29 -> 0 | AN29: =AE29*U29*J29 -> 183264.55 | AO29: =AK29+AL29+AM29+AN29 -> 12400901 | AQ29: =+O29 -> 603290.75 | AR29: =+O29*J29 -> 54296168
A30: Hormigón | B30: - | C30: Hormigón | D30: Hormigón | F30: 3.1 | G30: OK | H30: Losa maciza de Hº visto - H35 (100 kg/m3 de hierro) | I30: m3 | J30: 32 | K30: 379758.83 | L30: 221790.79 | M30: 55447.699 | N30: 9854.9599 | O30: =+SUM(K30:N30) -> 666852.29 | P30: =+O30*$P$2 -> 957290.01 | R30: =+K30*$P$2 -> 545157.22 | S30: =+L30*$P$2 -> 318388.52 | T30: =+M30*$P$2 -> 79597.13 | U30: =+N30*$P$2 -> 14147.143 | V30: =+SUM(R30:U30) -> 957290.01 | X30: =+R30*J30 -> 17445031 | Y30: =+Z30-X30 -> 13188249 | Z30: =+V30*J30 -> 30633280 | AB30: ESTRUCTURA RESISTENTE | AC30: 1 | AD30: 0 | AE30: =AC30+AD30 -> 1 | AF30: =IF($AE30=1,"🔴","⚪") -> 🔴 | AG30: =AC30*Z30 -> 30633280 | AH30: =AD30*Z30 -> 0 | AI30: =AE30*Z30 -> 30633280 | AK30: =AE30*X30 -> 17445031 | AL30: =AE30*S30*J30 -> 10188433 | AM30: =AE30*T30*J30 -> 2547108.2 | AN30: =AE30*U30*J30 -> 452708.58 | AO30: =AK30+AL30+AM30+AN30 -> 30633280 | AQ30: =+O30 -> 666852.29 | AR30: =+O30*J30 -> 21339273
A31: Hormigón | B31: - | C31: Hormigón | D31: - | F31: 3.11 | G31: OK | H31: Vigas - H35 (180 kg/m3 de hierro) | I31: m3 | J31: 46 | K31: 567913.51 | L31: 537036.81 | M31: 0 | N31: 16574.255 | O31: =+SUM(K31:N31) -> 1121524.6 | P31: =+O31*$P$2 -> 1609988.1 | R31: =+K31*$P$2 -> 815259.9 | S31: =+L31*$P$2 -> 770935.3 | T31: =+M31*$P$2 -> 0 | U31: =+N31*$P$2 -> 23792.928 | V31: =+SUM(R31:U31) -> 1609988.1 | X31: =+R31*J31 -> 37501955 | Y31: =+Z31-X31 -> 36557499 | Z31: =+V31*J31 -> 74059454 | AB31: ESTRUCTURA RESISTENTE | AC31: 0.6984 | AD31: 0 | AE31: =AC31+AD31 -> 0.6984 | AF31: =IF($AE31=1,"🔴","⚪") -> ⚪ | AG31: =AC31*Z31 -> 51723123 | AH31: =AD31*Z31 -> 0 | AI31: =AE31*Z31 -> 51723123 | AK31: =AE31*X31 -> 26191366 | AL31: =AE31*S31*J31 -> 24767376 | AM31: =AE31*T31*J31 -> 0 | AN31: =AE31*U31*J31 -> 764381.12 | AO31: =AK31+AL31+AM31+AN31 -> 51723123 | AQ31: =+O31 -> 1121524.6 | AR31: =+O31*J31 -> 51590130
A32: Hormigón | B32: - | C32: Hormigón | D32: Hormigón | F32: 3.12 | G32: OK | H32: Vigas de H° visto - H35 (180 kg/m3 de hierro) | I32: m3 | J32: 31 | K32: 565756.87 | L32: 537036.81 | M32: 134259.2 | N32: 18555.793 | O32: =+SUM(K32:N32) -> 1255608.7 | P32: =+O32*$P$2 -> 1802470.6 | R32: =+K32*$P$2 -> 812163.96 | S32: =+L32*$P$2 -> 770935.3 | T32: =+M32*$P$2 -> 192733.83 | U32: =+N32*$P$2 -> 26637.496 | V32: =+SUM(R32:U32) -> 1802470.6 | X32: =+R32*J32 -> 25177083 | Y32: =+Z32-X32 -> 30699505 | Z32: =+V32*J32 -> 55876588 | AB32: ESTRUCTURA RESISTENTE | AC32: 1 | AD32: 0 | AE32: =AC32+AD32 -> 1 | AF32: =IF($AE32=1,"🔴","⚪") -> 🔴 | AG32: =AC32*Z32 -> 55876588 | AH32: =AD32*Z32 -> 0 | AI32: =AE32*Z32 -> 55876588 | AK32: =AE32*X32 -> 25177083 | AL32: =AE32*S32*J32 -> 23898994 | AM32: =AE32*T32*J32 -> 5974748.6 | AN32: =AE32*U32*J32 -> 825762.39 | AO32: =AK32+AL32+AM32+AN32 -> 55876588 | AQ32: =+O32 -> 1255608.7 | AR32: =+O32*J32 -> 38923869
... A41: Hormigón | B41: - | C41: - | D41: Hormigón | F41: 3.22 | G41: OK | H41: Picado de medianeras para columnas y vigas - Cotizado para PB y 1P | I41: m2 | J41: 78 | K41: 7051.2821 | L41: 0 | M41: 17829.919 | N41: 373.21802 | O41: =+SUM(K41:N41) -> 25254.419 | P41: =+O41*$P$2 -> 36253.611 | R41: =+K41*$P$2 -> 10122.364 | S41: =+L41*$P$2 -> 0 | T41: =+M41*$P$2 -> 25595.479 | U41: =+N41*$P$2 -> 535.76764 | V41: =+SUM(R41:U41) -> 36253.611 | X41: =+R41*J41 -> 789544.42 | Y41: =+Z41-X41 -> 2038237.2 | Z41: =+V41*J41 -> 2827781.6 | AB41: ESTRUCTURA RESISTENTE | AC41: 1 | AD41: 0 | AE41: =AC41+AD41 -> 1 | AF41: =IF($AE41=1,"🔴","⚪") -> 🔴 | AG41: =AC41*Z41 -> 2827781.6 | AH41: =AD41*Z41 -> 0 | AI41: =AE41*Z41 -> 2827781.6 | AK41: =AE41*X41 -> 789544.42 | AL41: =AE41*S41*J41 -> 0 | AM41: =AE41*T41*J41 -> 1996447.3 | AN41: =AE41*U41*J41 -> 41789.876 | AO41: =AK41+AL41+AM41+AN41 -> 2827781.6 | AQ41: =+O41 -> 25254.419 | AR41: =+O41*J41 -> 1969844.7
A42: - | B42: - | C42: - | D42: - | F42: 4 | H42: MAMPOSTERÍA | AA42: =+SUM(Z43:Z56) -> 64182207 | AB42: MAMPOSTERÍA
A43: Albañilería | B43: - | C43: - | D43: Albañilería | F43: 4.01 | G43: OK | H43: Muro tipo 1 - Ladrillo hueco 8 x 18 x 33 | I43: m2 | J43: 621 | K43: 10253.952 | L43: 0 | M43: 16311.975 | N43: 365.95526 | O43: =+SUM(K43:N43) -> 26931.882 | P43: =+O43*$P$2 -> 38661.668 | R43: =+K43*$P$2 -> 14719.91 | S43: =+L43*$P$2 -> 0 | T43: =+M43*$P$2 -> 23416.416 | U43: =+N43*$P$2 -> 525.34171 | V43: =+SUM(R43:U43) -> 38661.668 | X43: =+R43*J43 -> 9141064.1 | Y43: =+Z43-X43 -> 14867832 | Z43: =+V43*J43 -> 24008896 | AB43: MAMPOSTERÍA | AC43: 0.85 | AD43: 0 | AE43: =AC43+AD43 -> 0.85 | AF43: =IF($AE43=1,"🔴","⚪") -> ⚪ | AG43: =AC43*Z43 -> 20407561 | AH43: =AD43*Z43 -> 0 | AI43: =AE43*Z43 -> 20407561 | AK43: =AE43*X43 -> 7769904.5 | AL43: =AE43*S43*J43 -> 0 | AM43: =AE43*T43*J43 -> 12360355 | AN43: =AE43*U43*J43 -> 277301.62 | AO43: =AK43+AL43+AM43+AN43 -> 20407561 | AQ43: =+O43 -> 26931.882 | AR43: =+O43*J43 -> 16724699
A44: Albañilería | B44: - | C44: - | D44: Albañilería | F44: 4.02 | G44: OK | H44: Muro tipo 2 - Ladrillo hueco 12 x 18 x 33 | I44: m2 | J44: 780 | K44: 8314.4981 | L44: 0 | M44: 9785.8452 | N44: 235.33191 | O44: =+SUM(K44:N44) -> 18335.675 | P44: =+O44*$P$2 -> 26321.509 | R44: =+K44*$P$2 -> 11935.756 | S44: =+L44*$P$2 -> 0 | T44: =+M44*$P$2 -> 14047.926 | U44: =+N44*$P$2 -> 337.82727 | V44: =+SUM(R44:U44) -> 26321.509 | X44: =+R44*J44 -> 9309889.4 | Y44: =+Z44-X44 -> 11220888 | Z44: =+V44*J44 -> 20530777 | AB44: MAMPOSTERÍA | AC44: 0.85 | AD44: 0 | AE44: =AC44+AD44 -> 0.85 | AF44: =IF($AE44=1,"🔴","⚪") -> ⚪ | AG44: =AC44*Z44 -> 17451161 | AH44: =AD44*Z44 -> 0 | AI44: =AE44*Z44 -> 17451161 | AK44: =AE44*X44 -> 7913406 | AL44: =AE44*S44*J44 -> 0 | AM44: =AE44*T44*J44 -> 9313775.2 | AN44: =AE44*U44*J44 -> 223979.48 | AO44: =AK44+AL44+AM44+AN44 -> 17451161 | AQ44: =+O44 -> 18335.675 | AR44: =+O44*J44 -> 14301827
A45: Albañilería | B45: - | C45: - | D45: Albañilería | F45: 4.03 | G45: OK | H45: Muro tipo 3 - Ladrillo comun en panderete | I45: m2 | J45: 56 | K45: 6454.6901 | L45: 0 | M45: 10484.834 | N45: 504.28267 | O45: =+SUM(K45:N45) -> 17443.807 | P45: =+O45*$P$2 -> 25041.201 | R45: =+K45*$P$2 -> 9265.9357 | S45: =+L45*$P$2 -> 0 | T45: =+M45*$P$2 -> 15051.35 | U45: =+N45*$P$2 -> 723.91558 | V45: =+SUM(R45:U45) -> 25041.201 | X45: =+R45*J45 -> 518892.4 | Y45: =+Z45-X45 -> 883414.86 | Z45: =+V45*J45 -> 1402307.3 | AB45: MAMPOSTERÍA | AC45: 1 | AD45: 0 | AE45: =AC45+AD45 -> 1 | AF45: =IF($AE45=1,"🔴","⚪") -> 🔴 | AG45: =AC45*Z45 -> 1402307.3 | AH45: =AD45*Z45 -> 0 | AI45: =AE45*Z45 -> 1402307.3 | AK45: =AE45*X45 -> 518892.4 | AL45: =AE45*S45*J45 -> 0 | AM45: =AE45*T45*J45 -> 842875.58 | AN45: =AE45*U45*J45 -> 40539.273 | AO45: =AK45+AL45+AM45+AN45 -> 1402307.3 | AQ45: =+O45 -> 17443.807 | AR45: =+O45*J45 -> 976853.19
A46: Albañilería | B46: - | C46: - | D46: Albañilería | F46: 4.04 | G46: OK | H46: Muro tipo 4 - Ladrillo hueco portante 12 x 18 x 33 | I46: m2 | J46: 42 | K46: 11547.894 | L46: 0 | M46: 9785.8452 | N46: 235.33191 | O46: =+SUM(K46:N46) -> 21569.071 | P46: =+O46*$P$2 -> 30963.163 | R46: =+K46*$P$2 -> 16577.409 | S46: =+L46*$P$2 -> 0 | T46: =+M46*$P$2 -> 14047.926 | U46: =+N46*$P$2 -> 337.82727 | V46: =+SUM(R46:U46) -> 30963.163 | X46: =+R46*J46 -> 696251.19 | Y46: =+Z46-X46 -> 604201.65 | Z46: =+V46*J46 -> 1300452.8 | AB46: MAMPOSTERÍA | AC46: 0.7 | AD46: 0 | AE46: =AC46+AD46 -> 0.7 | AF46: =IF($AE46=1,"🔴","⚪") -> ⚪ | AG46: =AC46*Z46 -> 910316.99 | AH46: =AD46*Z46 -> 0 | AI46: =AE46*Z46 -> 910316.99 | AK46: =AE46*X46 -> 487375.83 | AL46: =AE46*S46*J46 -> 0 | AM46: =AE46*T46*J46 -> 413009.04 | AN46: =AE46*U46*J46 -> 9932.1218 | AO46: =AK46+AL46+AM46+AN46 -> 910316.99 | AQ46: =+O46 -> 21569.071 | AR46: =+O46*J46 -> 905900.98
A47: Albañilería | B47: - | C47: - | D47: Albañilería | F47: 4.05 | G47: IN | H47: Muro tipo 5 - Bloque HCCA e: 7,5 cm | I47: m2 | J47: 70 | K47: 16817.941 | L47: 0 | M47: 10484.834 | N47: 409.54162 | O47: =+SUM(K47:N47) -> 27712.316 | P47: =+O47*$P$2 -> 39782.009 | R47: =+K47*$P$2 -> 24142.748 | S47: =+L47*$P$2 -> 0 | T47: =+M47*$P$2 -> 15051.35 | U47: =+N47*$P$2 -> 587.91146 | V47: =+SUM(R47:U47) -> 39782.009 | X47: =+R47*J47 -> 1689992.3 | Y47: =+Z47-X47 -> 1094748.3 | Z47: =+V47*J47 -> 2784740.6 | AB47: MAMPOSTERÍA | AC47: 0.1 | AD47: 0 | AE47: =AC47+AD47 -> 0.1 | AF47: =IF($AE47=1,"🔴","⚪") -> ⚪ | AG47: =AC47*Z47 -> 278474.06 | AH47: =AD47*Z47 -> 0 | AI47: =AE47*Z47 -> 278474.06 | AK47: =AE47*X47 -> 168999.23 | AL47: =AE47*S47*J47 -> 0 | AM47: =AE47*T47*J47 -> 105359.45 | AN47: =AE47*U47*J47 -> 4115.3802 | AO47: =AK47+AL47+AM47+AN47 -> 278474.06 | AQ47: =+O47 -> 27712.316 | AR47: =+O47*J47 -> 1939862.2
A48: Albañilería | B48: - | C48: - | D48: Albañilería | F48: 4.06 | G48: OK | H48: Muro tipo 6 - Ladrillo hueco 18 x 18 x 33 | I48: m2 | J48: 5 | K48: 11492.44 | L48: 0 | M48: 9785.8452 | N48: 235.33191 | O48: =+SUM(K48:N48) -> 21513.617 | P48: =+O48*$P$2 -> 30883.558 | R48: =+K48*$P$2 -> 16497.804 | S48: =+L48*$P$2 -> 0 | T48: =+M48*$P$2 -> 14047.926 | U48: =+N48*$P$2 -> 337.82727 | V48: =+SUM(R48:U48) -> 30883.558 | X48: =+R48*J48 -> 82489.02 | Y48: =+Z48-X48 -> 71928.768 | Z48: =+V48*J48 -> 154417.79 | AB48: MAMPOSTERÍA | AC48: 0.1 | AD48: 0 | AE48: =AC48+AD48 -> 0.1 | AF48: =IF($AE48=1,"🔴","⚪") -> ⚪ | AG48: =AC48*Z48 -> 15441.779 | AH48: =AD48*Z48 -> 0 | AI48: =AE48*Z48 -> 15441.779 | AK48: =AE48*X48 -> 8248.902 | AL48: =AE48*S48*J48 -> 0 | AM48: =AE48*T48*J48 -> 7023.9632 | AN48: =AE48*U48*J48 -> 168.91364 | AO48: =AK48+AL48+AM48+AN48 -> 15441.779 | AQ48: =+O48 -> 21513.617 | AR48: =+O48*J48 -> 107568.09
...

Sheet 1_GGBB
H2: 45679 | O2: 26
F3: MESES | G3: DÓLAR BNA | H3: DÓLAR MEP | M3: Descrip | N3: Mes | O3: Total Dias
B4: GASTOS GENERALES y BENEFICIO | F4: =+ROUNDUP(N17,0) -> 17 | G4: 1066.5 | H4: 1170 | M4: Prelim | N4: 1 | O4: =+N4*$O$2 -> 26 | Q4: Syh permanente
M5: Mov de suelos y excav. | N5: 2.5 | O5: =+N5*$O$2 -> 65 | Q5: =+ROUNDUP(SUM(N4:N5),0) -> 4
B6: Gastos Grales de obra en items | C6: U | D6: Cant | F6: Precio Unit | G6: Subtotal | H6: =SUM(G7:G10) -> 0 | M6: Losa sobre PB | N6: 1 | O6: =+N6*$O$2 -> 26
B7: Oficina en obra (6x3 c/AA) | C7: mes | D7: =+$F$4 -> 17 | E7: 0 | F7: =E7*I7+J7 -> 0 | G7: =+F7*D7*E7 -> 0 | M7: Losa sobre 1 | N7: 0.75 | O7: =+N7*$O$2 -> 19.5
B8: Obrador 6x3 s/AA | C8: mes | D8: =+$F$4 -> 17 | E8: 0 | F8: =E8*I8+J8 -> 0 | G8: =+F8*D8*E8 -> 0 | M8: Losa sobre 2 | N8: 0.75 | O8: =+N8*$O$2 -> 19.5
B9: Pañol (6x3) | C9: mes | D9: =+$F$4 -> 17 | E9: 1 | F9: =E9*I9+J9 -> 0 | G9: =+F9*D9*E9 -> 0 | M9: Losa sobre 3 | N9: 0.75 | O9: =+N9*$O$2 -> 19.5 | P9: Inicio mamposteria
B10: Baños | C10: mes | D10: =+$F$4 -> 17 | E10: 2 | F10: =E10*I10+J10 -> 0 | G10: =+F10*D10*E10 -> 0 | M10: Losa sobre 4 | N10: 0.75 | O10: =+N10*$O$2 -> 19.5
B11: Gastos Grales de obra en items | H11: =SUM(G12:G19) -> 40948076 | M11: Losa sobre SM | N11: 0.5 | O11: =+N11*$O$2 -> 13 | Q11: Meses H° | R11: Estacionamiento en contramano
B12: HyS permanente | C12: mes | D12: =+Q5 -> 4 | E12: 1 | G12: =+K12 -> 6018681.2 | J12: 1504670.3 | K12: =+J12*D12*E12 -> 6018681.2 | M12: Mampostería | N12: 2 | O12: =+N12*$O$2 -> 52 | Q12: =+SUM(N5:N11) -> 7 | R12: =+ROUNDUP(Q12/3,0) -> 3
B13: HyS | C13: mes | D13: =+$F$4 -> 17 | E13: 1 | G13: =+K13 -> 2550000 | J13: 150000 | K13: =+J13*D13*E13 -> 2550000 | M13: Revoques, contrap y carp | N13: 2 | O13: =+N13*$O$2 -> 52
B14: Energía de obra | C14: mes | D14: =+$F$4 -> 17 | E14: 0.5 | F14: 200000 | G14: =+F14*D14*E14 -> 1700000 | M14: Colocación | N14: 2 | O14: =+N14*$O$2 -> 52
B15: Agua de obra | C15: mes | D15: =+$F$4 -> 17 | E15: 1 | F15: 250000 | G15: =+F15*D15*E15 -> 4250000 | M15: Pintura | N15: 2 | O15: =+N15*$O$2 -> 52
B16: Internet | C16: mes | D16: =+$F$4 -> 17 | E16: 1 | F16: 50000 | G16: =+F16*D16*E16 -> 850000 | M16: Terminaciones | N16: 1 | O16: =+N16*$O$2 -> 26
B17: Alquiler cerco de obra chapa | C17: mes | D17: =+$F$4 -> 17 | E17: 0 | F17: 10000 | G17: =+F17*D17*E17 -> 0 | N17: =SUM(N4:N16) -> 17 | O17: =SUM(O4:O16) -> 442
B18: Proyecto Ejecutivo | C18: mes | D18: =+$F$4 -> 17 | E18: 0 | F18: 3009340.6 | G18: =+F18*D18*E18 -> 0
B19: Proyecto (50%) | C19: mes | D19: =+$F$4 -> 17 | E19: 0.5 | F19: 3009340.6 | G19: =+F19*D19*E19 -> 25579395
B20: Gastos Directos | H20: =SUM(G21:G31) -> 1.5582366e+08
B21: Coordinacion de obra | C21: mes | D21: =+$F$4 -> 17 | E21: 0.15 | F21: 5273644.1 | G21: =+F21*D21*E21 -> 13447792
B22: Jefe de obra | C22: mes | D22: =+$F$4 -> 17 | E22: 1 | G22: =+K22 -> 74327580 | J22: 4372210.6 | K22: =+J22*D22*E22 -> 74327580
B23: Sobrestante | C23: mes | D23: =+$F$4 -> 17 | E23: 0 | F23: 3009340.6 | G23: =+F23*D23*E23 -> 0
B24: Administrativo en obra | C24: mes | D24: =+$F$4 -> 17 | E24: 0 | F24: =+F23 -> 3009340.6 | G24: =+F24*D24*E24 -> 0
B25: Capataz | C25: mes | D25: =+$F$4 -> 17 | E25: 0.5 | F25: 3545026.5 | G25: =+F25*D25*E25 -> 30132725
B26: Logistica | C26: mes | D26: =+$F$4 -> 17 | E26: 1 | F26: 500000 | G26: =+F26*D26*E26 -> 8500000
B27: Vehiculo obra | C27: mes | D27: =+$F$4 -> 17 | E27: 1 | F27: =F26 -> 500000 | G27: =+F27*D27*E27 -> 8500000
B28: Mov y viaticos | C28: mes | D28: =+$F$4 -> 17 | E28: 1 | G28: =+K28 -> 8500000 | J28: =F26 -> 500000 | K28: =+J28*D28*E28 -> 8500000
B29: UOCRA | C29: mes | D29: =+$F$4 -> 17 | E29: 1 | G29: =+F29*D29*E29 -> 0
B30: Pañolero/Sereno | C30: mes | D30: =+$F$4 -> 17 | E30: 1 | G30: =+K30 -> 12415558 | J30: 730326.97 | K30: =+J30*D30*E30 -> 12415558
B32: Equipos | H32: =SUM(G33:G41) -> 0
B33: Bobcat | C33: mes | F33: 130000 | G33: =+F33*D33 -> 0
B34: Camion limpieza | C34: mes | F34: 100000 | G34: =+F34*D34 -> 0
B35: Tijera electrica 12 | C35: mes | F35: 33600 | G35: =+F35*D35 -> 0
B36: JLG | C36: mes | F36: 89000 | G36: =+F36*D36 -> 0
B37: Grua 20ton | C37: mes | F37: 70000 | G37: =+F37*D37 -> 0
B42: Gastos Indirectos | H42: =SUM(G43:G48) -> 82753395
B43: Admin (50%Compras - 50%RRHH) | C43: mes | D43: =+$F$4 -> 17 | E43: 0.5 | F43: 3009340.6 | G43: =+F43*D43*E43 -> 25579395
B44: Seguros | C44: gl | D44: =+D43 -> 17 | E44: 1 | F44: 250000 | G44: =+F44*D44 -> 4250000
B45: IIBB (monto venta obra gris) | C45: gl | D45: 0.04 | E45: 0.7 | F45: 1400000000 | G45: =+F45*D45*E45 -> 39200000
B46: Imp cheque | C46: gl | D46: =1.2/100 -> 0.012 | E46: =+E45 -> 0.7 | F46: =+F45*1.15 -> 1.61e+09 | G46: =+F46*D46*E46 -> 13524000
...

Sheet 1_Composicion
A1: Partida | B1: Tipo | C1: Subtipo | D1: Cod_Insumo | E1: Descripción | F1: Unidad de medida | G1: Cant | H1: %Desp | I1: Precio | J1: Costo | K1: Clave | L1: Count | M1: Clave2 | N1: Rend. Part. | O1: Cant MO/ALB Unit | P1: Cant. Ej. Part. | Q1: Cant MO/ALB Total | R1: Cod_Item_Ppto | S1: MO/ALB
A2: AIS-114 | B2: EQ | D2: EQ-SOLD00 | E2: Soldador Soplete A Gas Techista Membrana 10 Kg Boca 50mm | G2: 1 | H2: 0 | I2: 804.50569 | J2: 804.50569 | K2: AIS-114|EQ | L2: 1 | M2: AIS-114|EQ|1 | N2: 60 | O2: 1 | P2: - | Q2: 0 | R2: - | S2: -
A3: AIS-114 | B3: MAT | C3: OTR | D3: OTR-022 | E3: Aguarras Hydrarras Hydra x 18lts | F3: b | G3: 0.005 | H3: 0.05 | I3: 26907.33 | J3: 141.26348 | K3: AIS-114|MAT | L3: 1 | M3: AIS-114|MAT|1 | N3: 60 | O3: 0.005 | P3: - | Q3: 0 | R3: - | S3: -
A4: AIS-114 | B4: MAT | C4: OTR | D4: OTR-025 | E4: Trapo | F4: u | G4: 0.01 | H4: 0.05 | I4: 735.06 | J4: 7.71813 | K4: AIS-114|MAT | L4: 2 | M4: AIS-114|MAT|2 | N4: 60 | O4: 0.01 | P4: - | Q4: 0 | R4: - | S4: -
A5: AIS-114 | B5: MAT | C5: OTR | D5: OTR-027 | E5: Rodillo de lana pelo largo N°22 - El Galgo | F5: u | G5: 0.005 | H5: 0.05 | I5: 6678.36 | J5: 35.06139 | K5: AIS-114|MAT | L5: 3 | M5: AIS-114|MAT|3 | N5: 60 | O5: 0.005 | P5: - | Q5: 0 | R5: - | S5: -
A6: AIS-114 | B6: MAT | C6: OTR | D6: OTR-028 | E6: Pincel N° 20 - El Galgo | F6: u | G6: 0.01 | H6: 0.05 | I6: 5282.24 | J6: 55.46352 | K6: AIS-114|MAT | L6: 4 | M6: AIS-114|MAT|4 | N6: 60 | O6: 0.01 | P6: - | Q6: 0 | R6: - | S6: -
A7: AIS-114 | B7: MAT | C7: OTR | D7: OTR-047 | E7: Guante Vaqueta Medio Paseo | F7: par | G7: 0.03 | H7: 0.05 | I7: 4842 | J7: 152.523 | K7: AIS-114|MAT | L7: 5 | M7: AIS-114|MAT|5 | N7: 60 | O7: 0.03 | P7: - | Q7: 0 | R7: - | S7: -
A8: AIS-114 | B8: MAT | C8: OTR | D8: OTR-048 | E8: Recarga de garrafa | F8: u | G8: 0.01 | H8: 0.05 | I8: 12396.694 | J8: 130.16529 | K8: AIS-114|MAT | L8: 6 | M8: AIS-114|MAT|6 | N8: 60 | O8: 0.01 | P8: - | Q8: 0 | R8: - | S8: -
A9: AIS-114 | B9: MAT | C9: OTR | D9: PIN-008 | E9: Pintura Asfaltica Asfasol x18ts | F9: b | G9: 0.015 | H9: 0.1 | I9: 32845.78 | J9: 541.95537 | K9: AIS-114|MAT | L9: 7 | M9: AIS-114|MAT|7 | N9: 60 | O9: 0.015 | P9: - | Q9: 0 | R9: - | S9: -
A10: AIS-114 | B10: MAT | C10: OTR | D10: AIS-002 | E10: Membrana Geotextil Ormiflex 4mm - (35kg) x10m | F10: u | G10: 0.05 | H10: 0.1 | I10: 70192.21 | J10: 3860.5716 | K10: AIS-114|MAT | L10: 8 | M10: AIS-114|MAT|8 | N10: 60 | O10: 0.05 | P10: - | Q10: 0 | R10: - | S10: -
A11: AIS-114 | B11: MO | C11: ALB | D11: MO-EAYUD | E11: AYUDANTE | F11: j | G11: 1 | H11: 0 | I11: 60860.581 | J11: 60860.581 | K11: AIS-114|MO | L11: 1 | M11: AIS-114|MO|1 | N11: 60 | O11: 0.016666667 | P11: - | Q11: 0 | R11: - | S11: -
A12: AIS-114 | B12: MO | C12: ALB | D12: MO-EESPE | E12: ESPECIALIZADO | F12: j | G12: 1 | H12: 0 | I12: 85927.097 | J12: 85927.097 | K12: AIS-114|MO | L12: 2 | M12: AIS-114|MO|2 | N12: 60 | O12: 0.016666667 | P12: - | Q12: 0 | R12: - | S12: -
A13: ALB-033 | B13: EQ | D13: EQ-ANDAM0 | E13: ANDAMIO TUBULAR DE UNO A TRES CUERPOS | G13: 0.5 | H13: 0 | I13: 571.17949 | J13: 285.58975 | K13: ALB-033|EQ | L13: 1 | M13: ALB-033|EQ|1 | N13: 7 | O13: 0.5 | P13: - | Q13: 0 | R13: - | S13: -
A14: ALB-033 | B14: EQ | D14: EQ-EQALBA | E14: EQUIPO DE ALBAÑILERIA, carpetas, ladrillo | G14: 1 | H14: 0 | I14: 2287.1357 | J14: 2287.1357 | K14: ALB-033|EQ | L14: 2 | M14: ALB-033|EQ|2 | N14: 7 | O14: 1 | P14: - | Q14: 0 | R14: - | S14: -
A15: ALB-033 | B15: EQ | D15: EQ-TROMPO | E15: Hormigonera De 150 Litros 1hp Con Rueda Maciza | G15: 1 | H15: 0 | I15: 957.2532 | J15: 957.2532 | K15: ALB-033|EQ | L15: 3 | M15: ALB-033|EQ|3 | N15: 7 | O15: 1 | P15: - | Q15: 0 | R15: - | S15: -
A16: ALB-033 | B16: MAT | C16: OTR | D16: ACE-001 | E16: Barra de Acero Aleteado - 6mm x 12m | F16: u | G16: 0.17 | H16: 0.1 | I16: 3424.53 | J16: 640.38711 | K16: ALB-033|MAT | L16: 1 | M16: ALB-033|MAT|1 | N16: 7 | O16: 0.17 | P16: - | Q16: 0 | R16: - | S16: -
A17: ALB-033 | B17: MAT | C17: OTR | D17: AGR-001 | E17: ARENA LAVADA | F17: m3 | G17: 0.035 | H17: 0.1 | I17: 32399.77 | J17: 1247.3911 | K17: ALB-033|MAT | L17: 2 | M17: ALB-033|MAT|2 | N17: 7 | O17: 0.035 | P17: - | Q17: 0 | R17: - | S17: -
A18: ALB-033 | B18: MAT | C18: OTR | D18: AGR-004 | E18: Cemento Portland x 50kg | F18: Bol | G18: 0.15 | H18: 0.1 | I18: 7809.48 | J18: 1288.5642 | K18: ALB-033|MAT | L18: 3 | M18: ALB-033|MAT|3 | N18: 7 | O18: 0.15 | P18: - | Q18: 0 | R18: - | S18: -
A19: ALB-033 | B19: MAT | C19: OTR | D19: AGR-005 | E19: Cal Comun x 25kg | F19: bol | G19: 0.3 | H19: 0.1 | I19: 3837.96 | J19: 1266.5268 | K19: ALB-033|MAT | L19: 4 | M19: ALB-033|MAT|4 | N19: 7 | O19: 0.3 | P19: - | Q19: 0 | R19: - | S19: -
A20: ALB-033 | B20: MAT | C20: OTR | D20: CER-005 | E20: Ladrillo Comun 12.5 x 5.5 x 25 | F20: u | G20: 60 | H20: 0.05 | I20: 132.3 | J20: 8334.9 | K20: ALB-033|MAT | L20: 5 | M20: ALB-033|MAT|5 | N20: 7 | O20: 60 | P20: - | Q20: 0 | R20: - | S20: -
A21: ALB-033 | B21: MAT | C21: OTR | D21: MAT-CONS | E21: Consumibles | F21: gl | G21: 1.3161102 | H21: 0 | I21: 1 | J21: 1.3161102 | K21: ALB-033|MAT | L21: 6 | M21: ALB-033|MAT|6 | N21: 7 | O21: 1.3161102 | P21: - | Q21: 0 | R21: - | S21: -
A22: ALB-033 | B22: MO | C22: ALB | D22: MO-EAYUD | E22: AYUDANTE | F22: j | G22: 1 | H22: 0 | I22: 60860.581 | J22: 60860.581 | K22: ALB-033|MO | L22: 1 | M22: ALB-033|MO|1 | N22: 7 | O22: 0.14285714 | P22: - | Q22: 0 | R22: - | S22: -
A23: ALB-033 | B23: MO | C23: ALB | D23: MO-EESPE | E23: ESPECIALIZADO | F23: j | G23: 1 | H23: 0 | I23: 85927.097 | J23: 85927.097 | K23: ALB-033|MO | L23: 2 | M23: ALB-033|MO|2 | N23: 7 | O23: 0.14285714 | P23: - | Q23: 0 | R23: - | S23: -
A24: ALB-034 | B24: EQ | D24: EQ-ANDAM0 | E24: ANDAMIO TUBULAR DE UNO A TRES CUERPOS | G24: 0.5 | H24: 0 | I24: 571.17949 | J24: 285.58975 | K24: ALB-034|EQ | L24: 1 | M24: ALB-034|EQ|1 | N24: 15 | O24: 0.5 | P24: 621 | Q24: 310.5 | R24: 4.01 | S24: Albañilería
A25: ALB-034 | B25: EQ | D25: EQ-EQALBA | E25: EQUIPO DE ALBAÑILERIA, carpetas, ladrillo | G25: 1 | H25: 0 | I25: 2287.1357 | J25: 2287.1357 | K25: ALB-034|EQ | L25: 2 | M25: ALB-034|EQ|2 | N25: 15 | O25: 1 | P25: 621 | Q25: 621 | R25: 4.01 | S25: Albañilería
A26: ALB-034 | B26: EQ | D26: EQ-TROMPO | E26: Hormigonera De 150 Litros 1hp Con Rueda Maciza | G26: 1 | H26: 0 | I26: 957.2532 | J26: 957.2532 | K26: ALB-034|EQ | L26: 3 | M26: ALB-034|EQ|3 | N26: 15 | O26: 1 | P26: 621 | Q26: 621 | R26: 4.01 | S26: Albañilería
A27: ALB-034 | B27: MAT | C27: OTR | D27: ACE-001 | E27: Barra de Acero Aleteado - 6mm x 12m | F27: u | G27: 0.17 | H27: 0.1 | I27: 3424.53 | J27: 640.38711 | K27: ALB-034|MAT | L27: 1 | M27: ALB-034|MAT|1 | N27: 15 | O27: 0.17 | P27: 621 | Q27: 105.57 | R27: 4.01 | S27: Albañilería
A28: ALB-034 | B28: MAT | C28: OTR | D28: AGR-001 | E28: ARENA LAVADA | F28: m3 | G28: 0.012 | H28: 0.1 | I28: 32399.77 | J28: 427.67696 | K28: ALB-034|MAT | L28: 2 | M28: ALB-034|MAT|2 | N28: 15 | O28: 0.012 | P28: 621 | Q28: 7.452 | R28: 4.01 | S28: Albañilería
A29: ALB-034 | B29: MAT | C29: OTR | D29: AGR-004 | E29: Cemento Portland x 50kg | F29: Bol | G29: 0.05 | H29: 0.1 | I29: 7809.48 | J29: 429.5214 | K29: ALB-034|MAT | L29: 3 | M29: ALB-034|MAT|3 | N29: 15 | O29: 0.05 | P29: 621 | Q29: 31.05 | R29: 4.01 | S29: Albañilería
A30: ALB-034 | B30: MAT | C30: OTR | D30: AGR-005 | E30: Cal Comun x 25kg | F30: bol | G30: 0.1 | H30: 0.1 | I30: 3837.96 | J30: 422.1756 | K30: ALB-034|MAT | L30: 4 | M30: ALB-034|MAT|4 | N30: 15 | O30: 0.1 | P30: 621 | Q30: 62.1 | R30: 4.01 | S30: Albañilería
A31: ALB-034 | B31: MAT | C31: OTR | D31: CER-002 | E31: LADRILLO CERAMICO 8 x 18 x 33 cm | F31: u | G31: 15 | H31: 0.05 | I31: 292.32 | J31: 4604.04 | K31: ALB-034|MAT | L31: 5 | M31: ALB-034|MAT|5 | N31: 15 | O31: 15 | P31: 621 | Q31: 9315 | R31: 4.01 | S31: Albañilería
A32: ALB-034 | B32: MAT | C32: OTR | D32: MAT-CONS | E32: Consumibles | F32: gl | G32: 67.195151 | H32: 0 | I32: 1 | J32: 67.195151 | K32: ALB-034|MAT | L32: 6 | M32: ALB-034|MAT|6 | N32: 15 | O32: 67.195151 | P32: 621 | Q32: 41728.189 | R32: 4.01 | S32: Albañilería
A33: ALB-034 | B33: MO | C33: ALB | D33: MO-EAYUD | E33: AYUDANTE | F33: j | G33: 1 | H33: 0 | I33: 60860.581 | J33: 60860.581 | K33: ALB-034|MO | L33: 1 | M33: ALB-034|MO|1 | N33: 15 | O33: 0.066666667 | P33: 621 | Q33: 41.4 | R33: 4.01 | S33: Albañilería
A34: ALB-034 | B34: MO | C34: ALB | D34: MO-EESPE | E34: ESPECIALIZADO | F34: j | G34: 1 | H34: 0 | I34: 85927.097 | J34: 85927.097 | K34: ALB-034|MO | L34: 2 | M34: ALB-034|MO|2 | N34: 15 | O34: 0.066666667 | P34: 621 | Q34: 41.4 | R34: 4.01 | S34: Albañilería
A35: ALB-035 | B35: EQ | D35: EQ-ANDAM0 | E35: ANDAMIO TUBULAR DE UNO A TRES CUERPOS | G35: 0.5 | H35: 0 | I35: 571.17949 | J35: 285.58975 | K35: ALB-035|EQ | L35: 1 | M35: ALB-035|EQ|1 | N35: 15 | O35: 0.5 | P35: 780 | Q35: 390 | R35: 4.02 | S35: Albañilería
A36: ALB-035 | B36: EQ | D36: EQ-EQALBA | E36: EQUIPO DE ALBAÑILERIA, carpetas, ladrillo | G36: 1 | H36: 0 | I36: 2287.1357 | J36: 2287.1357 | K36: ALB-035|EQ | L36: 2 | M36: ALB-035|EQ|2 | N36: 15 | O36: 1 | P36: 780 | Q36: 780 | R36: 4.02 | S36: Albañilería
A37: ALB-035 | B37: EQ | D37: EQ-TROMPO | E37: Hormigonera De 150 Litros 1hp Con Rueda Maciza | G37: 1 | H37: 0 | I37: 957.2532 | J37: 957.2532 | K37: ALB-035|EQ | L37: 3 | M37: ALB-035|EQ|3 | N37: 15 | O37: 1 | P37: 780 | Q37: 780 | R37: 4.02 | S37: Albañilería
A38: ALB-035 | B38: MAT | C38: OTR | D38: ACE-001 | E38: Barra de Acero Aleteado - 6mm x 12m | F38: u | G38: 0.17 | H38: 0.1 | I38: 3424.53 | J38: 640.38711 | K38: ALB-035|MAT | L38: 1 | M38: ALB-035|MAT|1 | N38: 15 | O38: 0.17 | P38: 780 | Q38: 132.6 | R38: 4.02 | S38: Albañilería
A39: ALB-035 | B39: MAT | C39: OTR | D39: AGR-001 | E39: ARENA LAVADA | F39: m3 | G39: 0.018 | H39: 0.1 | I39: 32399.77 | J39: 641.51545 | K39: ALB-035|MAT | L39: 2 | M39: ALB-035|MAT|2 | N39: 15 | O39: 0.018 | P39: 780 | Q39: 14.04 | R39: 4.02 | S39: Albañilería
A40: ALB-035 | B40: MAT | C40: OTR | D40: AGR-004 | E40: Cemento Portland x 50kg | F40: Bol | G40: 0.075 | H40: 0.1 | I40: 7809.48 | J40: 644.2821 | K40: ALB-035|MAT | L40: 3 | M40: ALB-035|MAT|3 | N40: 15 | O40: 0.075 | P40: 780 | Q40: 58.5 | R40: 4.02 | S40: Albañilería
...

Sheet 2_Gastos
A1: Rubro | B1: MT/MO | C1: Mes | D1: Cuenta | E1: Descripción de Cuenta | F1: Fecha Asiento | G1: Número de Asiento | H1: Observaciones | I1: Cliente / Proveedor | J1: Código de Comprobante | K1: Número de comprobante | L1: Debe | M1: Haber | N1: Unidad | O1: Descripción de Unidad | P1: Centro de Costo | Q1: Descripción de Centro de Costo | R1: Saldo Inicial | S1: Monto Descontado | T1: Monto Real | U1: Contrato | V1: Monto CAC | W1: Monto Base | X1: En Ppto
A2: - | B2: - | C2: =+EOMONTH(Tabla18[[#This Row],[Fecha Asiento]],-1)+1 -> 45597 | D2: 52210 | E2: H. Gestoria | F2: 45604 | G2: 89 | H2: Viarq U$ 250 | J2: OPXX | K2: 5521 | L2: 275000 | M2: 0 | N2: DESA | O2: Desarrollos | P2: GDR | Q2: García del Río 3760 | R2: 0 | S2: =(Tabla18[[#This Row],[Debe]]-Tabla18[[#This Row],[Haber]])* SUMIF('0_Indice_CAC'!$A:$A,Tabla18[[#This Row],[Mes]],'0_Indice_CAC'!$D:$D) -> 0 | T2: =Tabla18[[#This Row],[Debe]]-Tabla18[[#This Row],[Haber]] -> 275000 | W2: =IFERROR(T2-IF(V2="",0,V2),0) -> 275000 | X2: =ISNUMBER(MATCH(A2,'3_Control_Ppto'!$A$4:$A$70,0)) -> FALSE
A3: Gastos Generales Obra | B3: - | C3: =+EOMONTH(Tabla18[[#This Row],[Fecha Asiento]],-1)+1 -> 45627 | D3: 53022 | E3: Gastos Generales | F3: 45632 | G3: 413 | H3: Encomienda - Instalaciones DO | J3: OPG | K3: 3488 | L3: 53000 | M3: 0 | N3: DESA | O3: Desarrollos | P3: GDR | Q3: García del Río 3760 | R3: 0 | S3: =(Tabla18[[#This Row],[Debe]]-Tabla18[[#This Row],[Haber]])* SUMIF('0_Indice_CAC'!$A:$A,Tabla18[[#This Row],[Mes]],'0_Indice_CAC'!$D:$D) -> 53000 | T3: =Tabla18[[#This Row],[Debe]]-Tabla18[[#This Row],[Haber]] -> 53000 | W3: =IFERROR(T3-IF(V3="",0,V3),0) -> 53000 | X3: =ISNUMBER(MATCH(A3,'3_Control_Ppto'!$A$4:$A$70,0)) -> TRUE
A4: Gastos Generales Obra | B4: - | C4: =+EOMONTH(Tabla18[[#This Row],[Fecha Asiento]],-1)+1 -> 45627 | D4: 53022 | E4: Gastos Generales | F4: 45632 | G4: 414 | H4: Encomienda Obra - DO | J4: OPG | K4: 3489 | L4: 180000 | M4: 0 | N4: DESA | O4: Desarrollos | P4: GDR | Q4: García del Río 3760 | R4: 0 | S4: =(Tabla18[[#This Row],[Debe]]-Tabla18[[#This Row],[Haber]])* SUMIF('0_Indice_CAC'!$A:$A,Tabla18[[#This Row],[Mes]],'0_Indice_CAC'!$D:$D) -> 180000 | T4: =Tabla18[[#This Row],[Debe]]-Tabla18[[#This Row],[Haber]] -> 180000 | W4: =IFERROR(T4-IF(V4="",0,V4),0) -> 180000 | X4: =ISNUMBER(MATCH(A4,'3_Control_Ppto'!$A$4:$A$70,0)) -> TRUE
A5: - | B5: - | C5: =+EOMONTH(Tabla18[[#This Row],[Fecha Asiento]],-1)+1 -> 45627 | D5: 52210 | E5: H. Gestoria | F5: 45638 | G5: 865 | H5: H. Gestoria- USD 450 A TC 1070 | J5: OPXX | K5: 6281 | L5: 481500 | M5: 0 | N5: DESA | O5: Desarrollos | P5: GDR | Q5: García del Río 3760 | R5: 0 | S5: =(Tabla18[[#This Row],[Debe]]-Tabla18[[#This Row],[Haber]])* SUMIF('0_Indice_CAC'!$A:$A,Tabla18[[#This Row],[Mes]],'0_Indice_CAC'!$D:$D) -> 481500 | T5: =Tabla18[[#This Row],[Debe]]-Tabla18[[#This Row],[Haber]] -> 481500 | W5: =IFERROR(T5-IF(V5="",0,V5),0) -> 481500 | X5: =ISNUMBER(MATCH(A5,'3_Control_Ppto'!$A$4:$A$70,0)) -> FALSE
A6: - | B6: - | C6: =+EOMONTH(Tabla18[[#This Row],[Fecha Asiento]],-1)+1 -> 45627 | D6: 52205 | E6: H. Escribanía | F6: 45642 | G6: 252 | H6: Pto. 720 - Varios | J6: OPXX | K6: 5679 | L6: 3000000 | M6: 0 | N6: DESA | O6: Desarrollos | P6: GDR | Q6: García del Río 3760 | R6: 0 | S6: =(Tabla18[[#This Row],[Debe]]-Tabla18[[#This Row],[Haber]])* SUMIF('0_Indice_CAC'!$A:$A,Tabla18[[#This Row],[Mes]],'0_Indice_CAC'!$D:$D) -> 3000000 | T6: =Tabla18[[#This Row],[Debe]]-Tabla18[[#This Row],[Haber]] -> 3000000 | W6: =IFERROR(T6-IF(V6="",0,V6),0) -> 3000000 | X6: =ISNUMBER(MATCH(A6,'3_Control_Ppto'!$A$4:$A$70,0)) -> FALSE
A7: Gastos Generales Obra | B7: - | C7: =+EOMONTH(Tabla18[[#This Row],[Fecha Asiento]],-1)+1 -> 45627 | D7: 53022 | E7: Gastos Generales | F7: 45645 | G7: 186 | H7: Combustible para cortar pasto | J7: OPXX | K7: 5612 | L7: 7005 | M7: 0 | N7: DESA | O7: Desarrollos | P7: GDR | Q7: García del Río 3760 | R7: 0 | S7: =(Tabla18[[#This Row],[Debe]]-Tabla18[[#This Row],[Haber]])* SUMIF('0_Indice_CAC'!$A:$A,Tabla18[[#This Row],[Mes]],'0_Indice_CAC'!$D:$D) -> 7005 | T7: =Tabla18[[#This Row],[Debe]]-Tabla18[[#This Row],[Haber]] -> 7005 | W7: =IFERROR(T7-IF(V7="",0,V7),0) -> 7005 | X7: =ISNUMBER(MATCH(A7,'3_Control_Ppto'!$A$4:$A$70,0)) -> TRUE
A8: Gastos Generales Obra | B8: - | C8: =+EOMONTH(Tabla18[[#This Row],[Fecha Asiento]],-1)+1 -> 45627 | D8: 53022 | E8: Gastos Generales | F8: 45645 | G8: 538 | H8: Combustible para desmalecedora | I8: ESTACION DE SERVICIO NORTENA S.R.L. | J8: TIQA | K8: 2100049507 | L8: 5258.93 | M8: 0 | N8: DESA | O8: Desarrollos | P8: GDR | Q8: García del Río 3760 | R8: 0 | S8: =(Tabla18[[#This Row],[Debe]]-Tabla18[[#This Row],[Haber]])* SUMIF('0_Indice_CAC'!$A:$A,Tabla18[[#This Row],[Mes]],'0_Indice_CAC'!$D:$D) -> 5258.93 | T8: =Tabla18[[#This Row],[Debe]]-Tabla18[[#This Row],[Haber]] -> 5258.93 | W8: =IFERROR(T8-IF(V8="",0,V8),0) -> 5258.93 | X8: =ISNUMBER(MATCH(A8,'3_Control_Ppto'!$A$4:$A$70,0)) -> TRUE
A9: Gastos Generales Obra | B9: - | C9: =+EOMONTH(Tabla18[[#This Row],[Fecha Asiento]],-1)+1 -> 45627 | D9: 53022 | E9: Gastos Generales | F9: 45645 | G9: 538 | H9: GASTOS GENERALAES - ESTACION D | I9: ESTACION DE SERVICIO NORTENA S.R.L. | J9: TIQA | K9: 2100049507 | L9: 641.7 | M9: 0 | N9: DESA | O9: Desarrollos | P9: GDR | Q9: García del Río 3760 | R9: 0 | S9: =(Tabla18[[#This Row],[Debe]]-Tabla18[[#This Row],[Haber]])* SUMIF('0_Indice_CAC'!$A:$A,Tabla18[[#This Row],[Mes]],'0_Indice_CAC'!$D:$D) -> 641.7 | T9: =Tabla18[[#This Row],[Debe]]-Tabla18[[#This Row],[Haber]] -> 641.7 | W9: =IFERROR(T9-IF(V9="",0,V9),0) -> 641.7 | X9: =ISNUMBER(MATCH(A9,'3_Control_Ppto'!$A$4:$A$70,0)) -> TRUE
A10: - | B10: - | C10: =+EOMONTH(Tabla18[[#This Row],[Fecha Asiento]],-1)+1 -> 45627 | D10: 52206 | E10: H. Arquitectura | F10: 45646 | G10: 202 | H10: Alejandro Ardiles - Agrimensor | J10: OPXX | K10: 5628 | L10: 110000 | M10: 0 | N10: DESA | O10: Desarrollos | P10: GDR | Q10: García del Río 3760 | R10: 0 | S10: =(Tabla18[[#This Row],[Debe]]-Tabla18[[#This Row],[Haber]])* SUMIF('0_Indice_CAC'!$A:$A,Tabla18[[#This Row],[Mes]],'0_Indice_CAC'!$D:$D) -> 110000 | T10: =Tabla18[[#This Row],[Debe]]-Tabla18[[#This Row],[Haber]] -> 110000 | W10: =IFERROR(T10-IF(V10="",0,V10),0) -> 110000 | X10: =ISNUMBER(MATCH(A10,'3_Control_Ppto'!$A$4:$A$70,0)) -> FALSE
