Workbook
Name GASTOS_CONCEPTO: _Listas!$I$2:$I$17
Name RUBROS_PLAN: _Listas!$A$2:$A$34

Sheet 0_CONFIG
A1: ▌ CONFIGURACIÓN DE OBRA — CH 2171
A3: Nombre de obra | B3: Chivilcoy 2171
A4: Estado | B4: En ejecución
A5: Fecha inicio | B5: 46023
A6: Duración estimada (meses) | B6: 18
A7: — ÍNDICE CAC —
A8: Mes base CAC | B8: 45809
A9: Valor CAC base (INDEC) | B9: 16643.4
A10: Mes corriente | B10: ='0_Indice_CAC'!A4 -> 45778
A11: Ratio CAC corriente | B11: ='0_Indice_CAC'!D4 -> 1.0073905
A12: — COEFICIENTE K —
A13: K (Gastos Generales y Beneficio) | B13: ='1_GGBB'!F61 -> 1.3564671 | C13: CRÍTICO: no modificar manualmente
A14: — PRESUPUESTO —
A15: Apertura fiscal | B15: B65 / N35 / GDN
A16: Costo controlable (sin EQ) | B16: {=SUMPRODUCT(('1_Presupuesto'!$J$4:$J$212+'1_Presupuesto'!$K$4:$K$212+'1_Presupuesto'!$L$4:$L$212)*'1_Presupuesto'!$I$4:$I$212)} -> 1.109935e+09
A17: Costo total (con EQ) | B17: {=SUMPRODUCT('1_Presupuesto'!$N$4:$N$212*'1_Presupuesto'!$I$4:$I$212)} -> 1.1357519e+09
A18: Precio de venta total | B18: {=SUMPRODUCT('1_Presupuesto'!$S$4:$S$212*'1_Presupuesto'!$I$4:$I$212)} -> 1.5406101e+09
A19: Sanity check (debe ser 0) | B19: =+B17*B13-B18 -> 0 | C19: EQ no tiene rubro asignado → excluido de costo controlable
A44: — RECONCILIACIÓN MENSUAL —
A45: Total egresos (2_Movimientos) | B45: =SUMPRODUCT('2_Movimientos'!$I$2:$I$1000,N(LEFT(TEXT('2_Movimientos'!$A$2:$A$1000,"0"),1)<>"4"))-SUMPRODUCT('2_Movimientos'!$J$2:$J$1000,N(LEFT(TEXT('2_Movimientos'!$A$2:$A$1000,"0"),1)<>"4")) -> 93309801
A46: Total Tezamat (pegar mensual)
A47: Diferencia (debe ser 0) | B47: =B45-B46 -> 93309801
A49: Tolerancia conciliación ($) | B49: 100
A52: — PENDIENTES (celdas amarillas) —
A53: 0_Indice_CAC col B | B53: CAC meses futuros sin publicar
A54: 0_Jornales_MO | B54: Tarifas UOCRA meses futuros
A55: 0_CONFIG!B46 | B55: Input mensual total Tezamat
A56: 1_Presupuesto cols A,B,C,D | B56: Asignación de rubros por ítem (4 cols input manual)

Sheet 0_Indice_CAC
A1: INDICE CAC | F1: IMPORTACIÓN MAESTRA (pendiente): este índice se actualiza por proceso Python desde archivo maestro externo (p.ej. archivos/fuente/CAC_maestro.xlsx). NO usar vínculos externos vivos. Una sola actualización en el maestro -> import a cada Resumen.
A2: En rojo se pinta el mes cerrado anterior
A3: Mes | B3: Valor INDEC | C3: Previsión | D3: Ratio deflactación
A4: 45778 | B4: 16521.3 | D4: =$B$5/B4 -> 1.0073905
A5: 45809 | B5: 16643.4 | D5: =$B$5/B5 -> 1
A6: 45839 | B6: 16939.5 | D6: =$B$5/B6 -> 0.98252015
A7: 45870 | B7: 17187.6 | D7: =$B$5/B7 -> 0.96833764
A8: 45901 | B8: 17762.3 | D8: =$B$5/B8 -> 0.93700703
A9: 45931 | B9: 18172.8 | D9: =$B$5/B9 -> 0.91584126
A10: 45962 | B10: 18534.9 | D10: =$B$5/B10 -> 0.89794927
A11: 45992 | B11: 18776.5 | D11: =$B$5/B11 -> 0.88639523
A12: 46023 | B12: 19209.4 | D12: =$B$5/B12 -> 0.86641957
A13: 46054 | B13: 19453 | D13: =$B$5/B13 -> 0.85556983
A14: 46082 | B14: 19771.2 | D14: =$B$5/B14 -> 0.84180019
A15: 46113 | B15: 20138.793 | D15: =$B$5/B15 -> 0.82643481
... A18: 46204 | B18: 20800 | D18: =$B$5/B18 -> 0.80016346

Sheet 0_Jornales_MO
A1: TABLA DE TARIFAS UOCRA POR CATEGORÍA | L1: IMPORTACIÓN MAESTRA (pendiente): tarifas UOCRA se actualizan por proceso Python desde archivo maestro externo (p.ej. archivos/fuente/Jornales_maestro.xlsx). NO usar vínculos externos vivos.
A3: Mes | B3: ESPECIALIZADO | C3: OFICIAL | D3: MEDIO OFICIAL | E3: AYUDANTE | G3: ESP/hora | H3: OF/hora | I3: 1/2OF/hora | J3: AYU/hora
A4: 46023 | B4: 117452.66 | C4: 97866.77 | D4: 83614.94 | E4: 78291.04 | G4: =IF(B4="","",B4/8) -> 14681.583 | H4: =IF(C4="","",C4/8) -> 12233.346 | I4: =IF(D4="","",D4/8) -> 10451.868 | J4: =IF(E4="","",E4/8) -> 9786.38
A5: 46054 | B5: 119406.33 | C5: 99479.56 | D5: 84948.75 | E5: 79490.6 | G5: =IF(B5="","",B5/8) -> 14925.791 | H5: =IF(C5="","",C5/8) -> 12434.945 | I5: =IF(D5="","",D5/8) -> 10618.594 | J5: =IF(E5="","",E5/8) -> 9936.325
A6: 46082 | B6: 122445.79 | C6: 102029.07 | D6: 87100.47 | E6: 81453.72 | G6: =IF(B6="","",B6/8) -> 15305.724 | H6: =IF(C6="","",C6/8) -> 12753.634 | I6: =IF(D6="","",D6/8) -> 10887.559 | J6: =IF(E6="","",E6/8) -> 10181.715
A7: 46113 | B7: 128780.87 | C7: 106995.86 | D7: 91265.84 | E7: 85242.81 | G7: =IF(B7="","",B7/8) -> 16097.609 | H7: =IF(C7="","",C7/8) -> 13374.483 | I7: =IF(D7="","",D7/8) -> 11408.23 | J7: =IF(E7="","",E7/8) -> 10655.351
A8: 46143 | B8: 131727.59 | C8: 109491.85 | D8: 93345.07 | E8: 87239.92 | G8: =IF(B8="","",B8/8) -> 16465.949 | H8: =IF(C8="","",C8/8) -> 13686.481 | I8: =IF(D8="","",D8/8) -> 11668.134 | J8: =IF(E8="","",E8/8) -> 10904.99
A9: 46174 | G9: =IF(B9="","",B9/8) | H9: =IF(C9="","",C9/8) | I9: =IF(D9="","",D9/8) | J9: =IF(E9="","",E9/8)
A10: 46204 | G10: =IF(B10="","",B10/8) | H10: =IF(C10="","",C10/8) | I10: =IF(D10="","",D10/8) | J10: =IF(E10="","",E10/8)
A11: 46235 | G11: =IF(B11="","",B11/8) | H11: =IF(C11="","",C11/8) | I11: =IF(D11="","",D11/8) | J11: =IF(E11="","",E11/8)
A12: 46266 | G12: =IF(B12="","",B12/8) | H12: =IF(C12="","",C12/8) | I12: =IF(D12="","",D12/8) | J12: =IF(E12="","",E12/8)
A13: 46296 | G13: =IF(B13="","",B13/8) | H13: =IF(C13="","",C13/8) | I13: =IF(D13="","",D13/8) | J13: =IF(E13="","",E13/8)
A14: 46327 | G14: =IF(B14="","",B14/8) | H14: =IF(C14="","",C14/8) | I14: =IF(D14="","",D14/8) | J14: =IF(E14="","",E14/8)
A15: 46357 | G15: =IF(B15="","",B15/8) | H15: =IF(C15="","",C15/8) | I15: =IF(D15="","",D15/8) | J15: =IF(E15="","",E15/8)
A16: 46388 | G16: =IF(B16="","",B16/8) | H16: =IF(C16="","",C16/8) | I16: =IF(D16="","",D16/8) | J16: =IF(E16="","",E16/8)
A17: 46419 | G17: =IF(B17="","",B17/8) | H17: =IF(C17="","",C17/8) | I17: =IF(D17="","",D17/8) | J17: =IF(E17="","",E17/8)
A18: 46447 | G18: =IF(B18="","",B18/8) | H18: =IF(C18="","",C18/8) | I18: =IF(D18="","",D18/8) | J18: =IF(E18="","",E18/8)
A19: 46478 | G19: =IF(B19="","",B19/8) | H19: =IF(C19="","",C19/8) | I19: =IF(D19="","",D19/8) | J19: =IF(E19="","",E19/8)
A20: 46508 | G20: =IF(B20="","",B20/8) | H20: =IF(C20="","",C20/8) | I20: =IF(D20="","",D20/8) | J20: =IF(E20="","",E20/8)
A21: 46539 | G21: =IF(B21="","",B21/8) | H21: =IF(C21="","",C21/8) | I21: =IF(D21="","",D21/8) | J21: =IF(E21="","",E21/8)

Sheet 1_Presupuesto
A1: PRESUPUESTO AL COSTO Y PRECIO DE VENTA — CH 2171
A3: Rubro MT | B3: Rubro MT/Prov | C3: Rubro MO/OTR | D3: Rubro MO/ALB | E3: Cod. Ítem | F3: Estado | G3: Descripción | H3: U | I3: Cant | J3: MT | K3: MO/OTR | L3: MO/ALB | M3: EQ | N3: Costo Unit. | O3: MT | P3: MO/OTR | Q3: MO/ALB | R3: EQ | S3: P.Unit | T3: Margen | U3: Costo total | V3: PV subtotal | W3: Etapa | X3: Presupuesto | Y3: % Acum Tot
F4: - | G4: TAREAS PRELIMINARES | W4: Tareas Preliminares | X4: PTO 01
E5: 1.01 | F5: OK | G5: Limpieza y preparación del terreno - No cotiza | H5: gl | I5: 0 | J5: 0 | K5: 0 | L5: 0 | M5: 0 | N5: =SUM(J5:M5) -> 0 | O5: =IF($N5=0,$S5,J5/$N5*$S5) -> 0 | P5: =IF($N5=0,0,K5/$N5*$S5) -> 0 | Q5: =IF($N5=0,0,L5/$N5*$S5) -> 0 | R5: =IF($N5=0,0,M5/$N5*$S5) -> 0 | S5: 0 | T5: =IFERROR(S5/N5,"") | U5: =N5*I5 -> 0 | V5: =S5*I5 -> 0 | W5: Tareas Preliminares | X5: PTO 01 | Y5: =SUMIFS(Cert_App_Output!$G:$G,Cert_App_Output!$E:$E,$E5,Cert_App_Output!$K:$K,$X5) -> 0
A6: Preliminares | C6: Preliminares | D6: Preliminares | E6: 1.02 | F6: OK | G6: Topógrafo - Visita de obra replanteo | H6: un | I6: 4 | J6: 25000 | K6: 214394.06 | L6: 67240.5 | M6: 4599.52 | N6: =SUM(J6:M6) -> 311234.08 | O6: =IF($N6=0,$S6,J6/$N6*$S6) -> 33911.678 | P6: =IF($N6=0,0,K6/$N6*$S6) -> 290818.49 | Q6: =IF($N6=0,0,L6/$N6*$S6) -> 91209.528 | R6: =IF($N6=0,0,M6/$N6*$S6) -> 6239.0977 | S6: 422178.8 | T6: =IFERROR(S6/N6,"") -> 1.3564671 | U6: =N6*I6 -> 1244936.3 | V6: =S6*I6 -> 1688715.2 | W6: Tareas Preliminares | X6: PTO 01 | Y6: =SUMIFS(Cert_App_Output!$G:$G,Cert_App_Output!$E:$E,$E6,Cert_App_Output!$K:$K,$X6) -> 0.5
E7: 1.03 | F7: OK | G7: Cartel de Obra - No cotiza | H7: gl | I7: 1 | J7: 0 | K7: 0 | L7: 0 | M7: 0 | N7: =SUM(J7:M7) -> 0 | O7: =IF($N7=0,$S7,J7/$N7*$S7) -> 0 | P7: =IF($N7=0,0,K7/$N7*$S7) -> 0 | Q7: =IF($N7=0,0,L7/$N7*$S7) -> 0 | R7: =IF($N7=0,0,M7/$N7*$S7) -> 0 | S7: 0 | T7: =IFERROR(S7/N7,"") | U7: =N7*I7 -> 0 | V7: =S7*I7 -> 0 | W7: Tareas Preliminares | X7: PTO 01 | Y7: =SUMIFS(Cert_App_Output!$G:$G,Cert_App_Output!$E:$E,$E7,Cert_App_Output!$K:$K,$X7) -> 0
A8: Preliminares | D8: Preliminares | E8: 1.04 | F8: OK | G8: Cerco de obra perimetral - En chapa C25 + Concertina + Porton corredizo | H8: ml | I8: 10 | J8: 98815.57 | K8: 0 | L8: 111992.57 | M8: 3162.12 | N8: =SUM(J8:M8) -> 213970.26 | O8: =IF($N8=0,$S8,J8/$N8*$S8) -> 134040.07 | P8: =IF($N8=0,0,K8/$N8*$S8) -> 0 | Q8: =IF($N8=0,0,L8/$N8*$S8) -> 151914.24 | R8: =IF($N8=0,0,M8/$N8*$S8) -> 4289.3118 | S8: 290243.62 | T8: =IFERROR(S8/N8,"") -> 1.3564671 | U8: =N8*I8 -> 2139702.6 | V8: =S8*I8 -> 2902436.2 | W8: Tareas Preliminares | X8: PTO 01 | Y8: =SUMIFS(Cert_App_Output!$G:$G,Cert_App_Output!$E:$E,$E8,Cert_App_Output!$K:$K,$X8) -> 1
A9: Preliminares | C9: Preliminares | D9: Preliminares | E9: 1.05 | F9: OK | G9: Obrador, pañol y ducha | H9: gl | I9: 1 | J9: 2570625.2 | K9: 1000000 | L9: 5023936.3 | M9: 128918.42 | N9: =SUM(J9:M9) -> 8723479.9 | O9: =IF($N9=0,$S9,J9/$N9*$S9) -> 3486968.5 | P9: =IF($N9=0,0,K9/$N9*$S9) -> 1356467.1 | Q9: =IF($N9=0,0,L9/$N9*$S9) -> 6814804.5 | R9: =IF($N9=0,0,M9/$N9*$S9) -> 174873.6 | S9: 11833114 | T9: =IFERROR(S9/N9,"") -> 1.3564671 | U9: =N9*I9 -> 8723479.9 | V9: =S9*I9 -> 11833114 | W9: Tareas Preliminares | X9: PTO 01 | Y9: =SUMIFS(Cert_App_Output!$G:$G,Cert_App_Output!$E:$E,$E9,Cert_App_Output!$K:$K,$X9) -> 0.75
C10: Gastos Generales | E10: 1.06 | F10: OK | G10: Alquiler de baños quimicos y duchas portatiles | H10: mes | I10: 4 | J10: 0 | K10: 260000 | L10: 0 | M10: 0 | N10: =SUM(J10:M10) -> 260000 | O10: =IF($N10=0,$S10,J10/$N10*$S10) -> 0 | P10: =IF($N10=0,0,K10/$N10*$S10) -> 352681.45 | Q10: =IF($N10=0,0,L10/$N10*$S10) -> 0 | R10: =IF($N10=0,0,M10/$N10*$S10) -> 0 | S10: 352681.45 | T10: =IFERROR(S10/N10,"") -> 1.3564671 | U10: =N10*I10 -> 1040000 | V10: =S10*I10 -> 1410725.8 | W10: Tareas Preliminares | X10: PTO 01 | Y10: =SUMIFS(Cert_App_Output!$G:$G,Cert_App_Output!$E:$E,$E10,Cert_App_Output!$K:$K,$X10) -> 0.25
A11: Preliminares | D11: Preliminares | E11: 1.07 | F11: OK | G11: Conexión pilar y luz de obra + Tablero de obra | H11: gl | I11: 1 | J11: 1390000 | K11: 0 | L11: 661285.32 | M11: 30769.28 | N11: =SUM(J11:M11) -> 2082054.6 | O11: =IF($N11=0,$S11,J11/$N11*$S11) -> 1885489.3 | P11: =IF($N11=0,0,K11/$N11*$S11) -> 0 | Q11: =IF($N11=0,0,L11/$N11*$S11) -> 897011.8 | R11: =IF($N11=0,0,M11/$N11*$S11) -> 41737.517 | S11: 2824238.6 | T11: =IFERROR(S11/N11,"") -> 1.3564671 | U11: =N11*I11 -> 2082054.6 | V11: =S11*I11 -> 2824238.6 | W11: Tareas Preliminares | X11: PTO 01 | Y11: =SUMIFS(Cert_App_Output!$G:$G,Cert_App_Output!$E:$E,$E11,Cert_App_Output!$K:$K,$X11) -> 1
A12: Preliminares | D12: Preliminares | E12: 1.08 | F12: OK | G12: Conexión agua de obra, tanque + bomba | H12: gl | I12: 1 | J12: 936000 | K12: 0 | L12: 536368.95 | M12: 22085.53 | N12: =SUM(J12:M12) -> 1494454.5 | O12: =IF($N12=0,$S12,J12/$N12*$S12) -> 1269653.2 | P12: =IF($N12=0,0,K12/$N12*$S12) -> 0 | Q12: =IF($N12=0,0,L12/$N12*$S12) -> 727566.85 | R12: =IF($N12=0,0,M12/$N12*$S12) -> 29958.295 | S12: 2027178.4 | T12: =IFERROR(S12/N12,"") -> 1.3564671 | U12: =N12*I12 -> 1494454.5 | V12: =S12*I12 -> 2027178.4 | W12: Tareas Preliminares | X12: PTO 01 | Y12: =SUMIFS(Cert_App_Output!$G:$G,Cert_App_Output!$E:$E,$E12,Cert_App_Output!$K:$K,$X12) -> 0
C13: Preliminares | E13: 1.09 | F13: OK | G13: Tramite luz de obra, certificado luz de obra (2) y medición PAT | H13: gl | I13: 1 | J13: 0 | K13: 482995.31 | L13: 0 | M13: 0 | N13: =SUM(J13:M13) -> 482995.31 | O13: =IF($N13=0,$S13,J13/$N13*$S13) -> 0 | P13: =IF($N13=0,0,K13/$N13*$S13) -> 655167.26 | Q13: =IF($N13=0,0,L13/$N13*$S13) -> 0 | R13: =IF($N13=0,0,M13/$N13*$S13) -> 0 | S13: 655167.26 | T13: =IFERROR(S13/N13,"") -> 1.3564671 | U13: =N13*I13 -> 482995.31 | V13: =S13*I13 -> 655167.26 | W13: Tareas Preliminares | X13: PTO 01 | Y13: =SUMIFS(Cert_App_Output!$G:$G,Cert_App_Output!$E:$E,$E13,Cert_App_Output!$K:$K,$X13) -> 0.7
F14: - | G14: MOVIMIENTO DE TIERRA, COMPACTACION Y RELLENO | W14: Movimiento de Tierra | X14: PTO 01
C15: Movimiento de Suelos | D15: Homigón MO | E15: 2.01 | F15: OK | G15: Retiro de suelo vegetal e: 50 cm, aporte y compactación de tosca e: 40 cm (dos capas de 20 cm) | H15: m2 | I15: 219 | J15: 0 | K15: 25907.44 | L15: 3070.34 | M15: 0 | N15: =SUM(J15:M15) -> 28977.78 | O15: =IF($N15=0,$S15,J15/$N15*$S15) -> 0 | P15: =IF($N15=0,0,K15/$N15*$S15) -> 35142.591 | Q15: =IF($N15=0,0,L15/$N15*$S15) -> 4164.8153 | R15: =IF($N15=0,0,M15/$N15*$S15) -> 0 | S15: 39307.406 | T15: =IFERROR(S15/N15,"") -> 1.3564671 | U15: =N15*I15 -> 6346133.8 | V15: =S15*I15 -> 8608321.9 | W15: Movimiento de Tierra | X15: PTO 01 | Y15: =SUMIFS(Cert_App_Output!$G:$G,Cert_App_Output!$E:$E,$E15,Cert_App_Output!$K:$K,$X15) -> 0.5
C16: Movimiento de Suelos | D16: Homigón MO | E16: 2.02 | F16: OK | G16: Excavación para cámara transformadora | H16: m3 | I16: 100 | J16: 0 | K16: 24440 | L16: 6724.05 | M16: 467.46 | N16: =SUM(J16:M16) -> 31631.51 | O16: =IF($N16=0,$S16,J16/$N16*$S16) -> 0 | P16: =IF($N16=0,0,K16/$N16*$S16) -> 33152.057 | Q16: =IF($N16=0,0,L16/$N16*$S16) -> 9120.9528 | R16: =IF($N16=0,0,M16/$N16*$S16) -> 634.09412 | S16: 42907.103 | T16: =IFERROR(S16/N16,"") -> 1.3564671 | U16: =N16*I16 -> 3163151 | V16: =S16*I16 -> 4290710.3 | W16: Movimiento de Tierra | X16: PTO 01 | Y16: =SUMIFS(Cert_App_Output!$G:$G,Cert_App_Output!$E:$E,$E16,Cert_App_Output!$K:$K,$X16) -> 0
D17: Homigón MO | E17: 2.03 | F17: OK | G17: Excavación manual para tensores y vigas de fundación | H17: m3 | I17: 43 | J17: 0 | K17: 0 | L17: 67240.5 | M17: 0 | N17: =SUM(J17:M17) -> 67240.5 | O17: =IF($N17=0,$S17,J17/$N17*$S17) -> 0 | P17: =IF($N17=0,0,K17/$N17*$S17) -> 0 | Q17: =IF($N17=0,0,L17/$N17*$S17) -> 91209.528 | R17: =IF($N17=0,0,M17/$N17*$S17) -> 0 | S17: 91209.528 | T17: =IFERROR(S17/N17,"") -> 1.3564671 | U17: =N17*I17 -> 2891341.5 | V17: =S17*I17 -> 3922009.7 | W17: Movimiento de Tierra | X17: PTO 01 | Y17: =SUMIFS(Cert_App_Output!$G:$G,Cert_App_Output!$E:$E,$E17,Cert_App_Output!$K:$K,$X17) -> 0.4
E18: 2.04 | F18: OK | G18: Demolición y retiro de fundaciones existentes - No cotiza | H18: gl | I18: 0 | J18: 0 | K18: 0 | L18: 0 | M18: 0 | N18: =SUM(J18:M18) -> 0 | O18: =IF($N18=0,$S18,J18/$N18*$S18) -> 0 | P18: =IF($N18=0,0,K18/$N18*$S18) -> 0 | Q18: =IF($N18=0,0,L18/$N18*$S18) -> 0 | R18: =IF($N18=0,0,M18/$N18*$S18) -> 0 | S18: 0 | T18: =IFERROR(S18/N18,"") | U18: =N18*I18 -> 0 | V18: =S18*I18 -> 0 | W18: Movimiento de Tierra | X18: PTO 01 | Y18: =SUMIFS(Cert_App_Output!$G:$G,Cert_App_Output!$E:$E,$E18,Cert_App_Output!$K:$K,$X18) -> 0
F19: - | G19: ESTRUCTURA RESISTENTE | W19: Estructura Resistente | X19: PTO 01
A20: Hormigón MT | D20: Homigón MO | E20: 3.01 | F20: OK | G20: Hormigón de limpieza - e: 10 cm | H20: m3 | I20: 3 | J20: 120430 | K20: 0 | L20: 155041.22 | M20: 4132.07 | N20: =SUM(J20:M20) -> 279603.29 | O20: =IF($N20=0,$S20,J20/$N20*$S20) -> 163359.34 | P20: =IF($N20=0,0,K20/$N20*$S20) -> 0 | Q20: =IF($N20=0,0,L20/$N20*$S20) -> 210308.32 | R20: =IF($N20=0,0,M20/$N20*$S20) -> 5605.0171 | S20: 379272.67 | T20: =IFERROR(S20/N20,"") -> 1.3564671 | U20: =N20*I20 -> 838809.87 | V20: =S20*I20 -> 1137818 | W20: Estructura Resistente | X20: PTO 01 | Y20: =SUMIFS(Cert_App_Output!$G:$G,Cert_App_Output!$E:$E,$E20,Cert_App_Output!$K:$K,$X20) -> 0
A21: Hormigón MT | C21: Homigón MO | D21: Homigón MO | E21: 3.02 | F21: OK | G21: Micropilotes Ø 20 cm | H21: gl | I21: 1 | J21: 11090041 | K21: 34350000 | L21: 2460301.5 | M21: 718505.14 | N21: =SUM(J21:M21) -> 48618848 | O21: =IF($N21=0,$S21,J21/$N21*$S21) -> 15043276 | P21: =IF($N21=0,0,K21/$N21*$S21) -> 46594646 | Q21: =IF($N21=0,0,L21/$N21*$S21) -> 3337318.1 | R21: =IF($N21=0,0,M21/$N21*$S21) -> 974628.6 | S21: 65949869 | T21: =IFERROR(S21/N21,"") -> 1.3564671 | U21: =N21*I21 -> 48618848 | V21: =S21*I21 -> 65949869 | W21: Estructura Resistente | X21: PTO 01 | Y21: =SUMIFS(Cert_App_Output!$G:$G,Cert_App_Output!$E:$E,$E21,Cert_App_Output!$K:$K,$X21) -> 1
A22: Hormigón MT | C22: Homigón MO | E22: 3.03 | F22: OK | G22: Platea - H30 (110 kg/m3 de hierro) | H22: m3 | I22: 7 | J22: 357146.17 | K22: 222927.96 | L22: 0 | M22: 8701.11 | N22: =SUM(J22:M22) -> 588775.24 | O22: =IF($N22=0,$S22,J22/$N22*$S22) -> 484457.04 | P22: =IF($N22=0,0,K22/$N22*$S22) -> 302394.45 | Q22: =IF($N22=0,0,L22/$N22*$S22) -> 0 | R22: =IF($N22=0,0,M22/$N22*$S22) -> 11802.77 | S22: 798654.26 | T22: =IFERROR(S22/N22,"") -> 1.3564671 | U22: =N22*I22 -> 4121426.7 | V22: =S22*I22 -> 5590579.8 | W22: Estructura Resistente | X22: PTO 01 | Y22: =SUMIFS(Cert_App_Output!$G:$G,Cert_App_Output!$E:$E,$E22,Cert_App_Output!$K:$K,$X22) -> 0.5
A23: Hormigón MT | C23: Homigón MO | E23: 3.04 | F23: OK | G23: Zapata corrida tabique - H30 (180 kg/m3 de hierro) | H23: m3 | I23: 4 | J23: 537813.29 | K23: 323084 | L23: 0 | M23: 12913.46 | N23: =SUM(J23:M23) -> 873810.75 | O23: =IF($N23=0,$S23,J23/$N23*$S23) -> 729526.05 | P23: =IF($N23=0,0,K23/$N23*$S23) -> 438252.82 | Q23: =IF($N23=0,0,L23/$N23*$S23) -> 0 | R23: =IF($N23=0,0,M23/$N23*$S23) -> 17516.684 | S23: 1185295.6 | T23: =IFERROR(S23/N23,"") -> 1.3564671 | U23: =N23*I23 -> 3495243 | V23: =S23*I23 -> 4741182.2 | W23: Estructura Resistente | X23: PTO 01 | Y23: =SUMIFS(Cert_App_Output!$G:$G,Cert_App_Output!$E:$E,$E23,Cert_App_Output!$K:$K,$X23) -> 0.5
A24: Hormigón MT | C24: Homigón MO | E24: 3.05 | F24: OK | G24: Bases aisladas - H30 (110 kg/m3 de hierro) | H24: m3 | I24: 2 | J24: 357146.17 | K24: 222927.96 | L24: 0 | M24: 8701.11 | N24: =SUM(J24:M24) -> 588775.24 | O24: =IF($N24=0,$S24,J24/$N24*$S24) -> 484457.04 | P24: =IF($N24=0,0,K24/$N24*$S24) -> 302394.45 | Q24: =IF($N24=0,0,L24/$N24*$S24) -> 0 | R24: =IF($N24=0,0,M24/$N24*$S24) -> 11802.77 | S24: 798654.26 | T24: =IFERROR(S24/N24,"") -> 1.3564671 | U24: =N24*I24 -> 1177550.5 | V24: =S24*I24 -> 1597308.5 | W24: Estructura Resistente | X24: PTO 01 | Y24: =SUMIFS(Cert_App_Output!$G:$G,Cert_App_Output!$E:$E,$E24,Cert_App_Output!$K:$K,$X24) -> 0.5
A25: Hormigón MT | C25: Homigón MO | E25: 3.06 | F25: OK | G25: Cabezales - H30 (130 kg/m3 de hierro) | H25: m3 | I25: 11 | J25: 392586.17 | K25: 222927.96 | L25: 0 | M25: 9232.71 | N25: =SUM(J25:M25) -> 624746.84 | O25: =IF($N25=0,$S25,J25/$N25*$S25) -> 532530.23 | P25: =IF($N25=0,0,K25/$N25*$S25) -> 302394.45 | Q25: =IF($N25=0,0,L25/$N25*$S25) -> 0 | R25: =IF($N25=0,0,M25/$N25*$S25) -> 12523.868 | S25: 847448.55 | T25: =IFERROR(S25/N25,"") -> 1.3564671 | U25: =N25*I25 -> 6872215.2 | V25: =S25*I25 -> 9321934 | W25: Estructura Resistente | X25: PTO 01 | Y25: =SUMIFS(Cert_App_Output!$G:$G,Cert_App_Output!$E:$E,$E25,Cert_App_Output!$K:$K,$X25) -> 0.7
A26: Hormigón MT | C26: Homigón MO | E26: 3.07 | F26: OK | G26: Viga de fundación - H30 (180 kg/m3 de hierro) | H26: m3 | I26: 9 | J26: 537813.29 | K26: 323084 | L26: 0 | M26: 12913.46 | N26: =SUM(J26:M26) -> 873810.75 | O26: =IF($N26=0,$S26,J26/$N26*$S26) -> 729526.05 | P26: =IF($N26=0,0,K26/$N26*$S26) -> 438252.82 | Q26: =IF($N26=0,0,L26/$N26*$S26) -> 0 | R26: =IF($N26=0,0,M26/$N26*$S26) -> 17516.684 | S26: 1185295.6 | T26: =IFERROR(S26/N26,"") -> 1.3564671 | U26: =N26*I26 -> 7864296.8 | V26: =S26*I26 -> 10667660 | W26: Estructura Resistente | X26: PTO 01 | Y26: =SUMIFS(Cert_App_Output!$G:$G,Cert_App_Output!$E:$E,$E26,Cert_App_Output!$K:$K,$X26) -> 0.7
A27: Hormigón MT | C27: Homigón MO | E27: 3.08 | F27: OK | G27: Tabique submuración - H30 (90 kg/m3 de hierro) | H27: m3 | I27: 9 | J27: 394401.89 | K27: 392678.73 | L27: 0 | M27: 11806.21 | N27: =SUM(J27:M27) -> 798886.83 | O27: =IF($N27=0,$S27,J27/$N27*$S27) -> 534993.2 | P27: =IF($N27=0,0,K27/$N27*$S27) -> 532655.79 | Q27: =IF($N27=0,0,L27/$N27*$S27) -> 0 | R27: =IF($N27=0,0,M27/$N27*$S27) -> 16014.736 | S27: 1083663.7 | T27: =IFERROR(S27/N27,"") -> 1.3564671 | U27: =N27*I27 -> 7189981.5 | V27: =S27*I27 -> 9752973.5 | W27: Estructura Resistente | X27: PTO 01 | Y27: =SUMIFS(Cert_App_Output!$G:$G,Cert_App_Output!$E:$E,$E27,Cert_App_Output!$K:$K,$X27) -> 0.5
A28: Hormigón MT | C28: Homigón MO | E28: 3.09 | F28: OK | G28: Puntales de compresión/codales - H30 (120 kg/m3) | H28: m3 | I28: 1 | J28: 542036.05 | K28: 362209.61 | L28: 0 | M28: 13563.68 | N28: =SUM(J28:M28) -> 917809.34 | O28: =IF($N28=0,$S28,J28/$N28*$S28) -> 735254.08 | P28: =IF($N28=0,0,K28/$N28*$S28) -> 491325.43 | Q28: =IF($N28=0,0,L28/$N28*$S28) -> 0 | R28: =IF($N28=0,0,M28/$N28*$S28) -> 18398.686 | S28: 1244978.2 | T28: =IFERROR(S28/N28,"") -> 1.3564671 | U28: =N28*I28 -> 917809.34 | V28: =S28*I28 -> 1244978.2 | W28: Estructura Resistente | X28: PTO 01 | Y28: =SUMIFS(Cert_App_Output!$G:$G,Cert_App_Output!$E:$E,$E28,Cert_App_Output!$K:$K,$X28) -> 0.5
A29: Hormigón MT | C29: Homigón MO | E29: 3.1 | F29: OK | G29: Columna - H30 (240 kg/m3 de hierro) | H29: m3 | I29: 32 | J29: 648356.05 | K29: 362209.61 | L29: 0 | M29: 15158.48 | N29: =SUM(J29:M29) -> 1025724.1 | O29: =IF($N29=0,$S29,J29/$N29*$S29) -> 879473.67 | P29: =IF($N29=0,0,K29/$N29*$S29) -> 491325.43 | Q29: =IF($N29=0,0,L29/$N29*$S29) -> 0 | R29: =IF($N29=0,0,M29/$N29*$S29) -> 20561.98 | S29: 1391361.1 | T29: =IFERROR(S29/N29,"") -> 1.3564671 | U29: =N29*I29 -> 32823172 | V29: =S29*I29 -> 44523554 | W29: Estructura Resistente | X29: PTO 01 | Y29: =SUMIFS(Cert_App_Output!$G:$G,Cert_App_Output!$E:$E,$E29,Cert_App_Output!$K:$K,$X29) -> 0
A30: Hormigón MT | C30: Homigón MO | E30: 3.11 | F30: OK | G30: Tabiques - H30 (120 kg/m3 de hierro) | H30: m3 | I30: 30 | J30: 447561.89 | K30: 392678.73 | L30: 0 | M30: 12603.61 | N30: =SUM(J30:M30) -> 852844.23 | O30: =IF($N30=0,$S30,J30/$N30*$S30) -> 607102.99 | P30: =IF($N30=0,0,K30/$N30*$S30) -> 532655.79 | Q30: =IF($N30=0,0,L30/$N30*$S30) -> 0 | R30: =IF($N30=0,0,M30/$N30*$S30) -> 17096.383 | S30: 1156855.2 | T30: =IFERROR(S30/N30,"") -> 1.3564671 | U30: =N30*I30 -> 25585327 | V30: =S30*I30 -> 34705655 | W30: Estructura Resistente | X30: PTO 01 | Y30: =SUMIFS(Cert_App_Output!$G:$G,Cert_App_Output!$E:$E,$E30,Cert_App_Output!$K:$K,$X30) -> 0
A31: Hormigón MT | C31: Homigón MO | D31: Homigón MO | E31: 3.12 | F31: OK | G31: Viga H° Visto - H30 (120 kg/m3 de hierro) | H31: m3 | I31: 7 | J31: 466389.3 | K31: 629584.36 | L31: 157396.09 | M31: 18800.55 | N31: =SUM(J31:M31) -> 1272170.3 | O31: =IF($N31=0,$S31,J31/$N31*$S31) -> 632641.75 | P31: =IF($N31=0,0,K31/$N31*$S31) -> 854010.49 | Q31: =IF($N31=0,0,L31/$N31*$S31) -> 213502.62 | R31: =IF($N31=0,0,M31/$N31*$S31) -> 25502.328 | S31: 1725657.2 | T31: =IFERROR(S31/N31,"") -> 1.3564671 | U31: =N31*I31 -> 8905192.1 | V31: =S31*I31 -> 12079600 | W31: Estructura Resistente | X31: PTO 01 | Y31: =SUMIFS(Cert_App_Output!$G:$G,Cert_App_Output!$E:$E,$E31,Cert_App_Output!$K:$K,$X31) -> 0
A32: Hormigón MT | C32: Homigón MO | D32: Homigón MO | E32: 3.13 | F32: OK | G32: Viga apeo s/PB - H30 (180 kg/m3 de hierro) | H32: m3 | I32: 12 | J32: 578369.51 | K32: 629584.36 | L32: 157396.09 | M32: 20480.25 | N32: =SUM(J32:M32) -> 1385830.2 | O32: =IF($N32=0,$S32,J32/$N32*$S32) -> 784539.23 | P32: =IF($N32=0,0,K32/$N32*$S32) -> 854010.49 | Q32: =IF($N32=0,0,L32/$N32*$S32) -> 213502.62 | R32: =IF($N32=0,0,M32/$N32*$S32) -> 27780.786 | S32: 1879833.1 | T32: =IFERROR(S32/N32,"") -> 1.3564671 | U32: =N32*I32 -> 16629963 | V32: =S32*I32 -> 22557997 | W32: Estructura Resistente | X32: PTO 01 | Y32: =SUMIFS(Cert_App_Output!$G:$G,Cert_App_Output!$E:$E,$E32,Cert_App_Output!$K:$K,$X32) -> 0.2
A33: Hormigón MT | C33: Homigón MO | E33: 3.14 | F33: OK | G33: Viga - H30 (120 kg/m3 de hierro) | H33: m3 | I33: 41 | J33: 472049.51 | K33: 629584.36 | L33: 0 | M33: 16524.51 | N33: =SUM(J33:M33) -> 1118158.4 | O33: =IF($N33=0,$S33,J33/$N33*$S33) -> 640319.64 | P33: =IF($N33=0,0,K33/$N33*$S33) -> 854010.49 | Q33: =IF($N33=0,0,L33/$N33*$S33) -> 0 | R33: =IF($N33=0,0,M33/$N33*$S33) -> 22414.955 | S33: 1516745.1 | T33: =IFERROR(S33/N33,"") -> 1.3564671 | U33: =N33*I33 -> 45844494 | V33: =S33*I33 -> 62186548 | W33: Estructura Resistente | X33: PTO 01 | Y33: =SUMIFS(Cert_App_Output!$G:$G,Cert_App_Output!$E:$E,$E33,Cert_App_Output!$K:$K,$X33) -> 0
A34: Hormigón MT | C34: Homigón MO | E34: 3.15 | F34: OK | G34: Losa - H30 (95 kg/m3 de hierro) | H34: m3 | I34: 135 | J34: 361563.22 | K34: 253632.45 | L34: 0 | M34: 9227.94 | N34: =SUM(J34:M34) -> 624423.61 | O34: =IF($N34=0,$S34,J34/$N34*$S34) -> 490448.62 | P34: =IF($N34=0,0,K34/$N34*$S34) -> 344044.08 | Q34: =IF($N34=0,0,L34/$N34*$S34) -> 0 | R34: =IF($N34=0,0,M34/$N34*$S34) -> 12517.397 | S34: 847010.1 | T34: =IFERROR(S34/N34,"") -> 1.3564671 | U34: =N34*I34 -> 84297187 | V34: =S34*I34 -> 1.1434636e+08 | W34: Estructura Resistente | X34: PTO 01 | Y34: =SUMIFS(Cert_App_Output!$G:$G,Cert_App_Output!$E:$E,$E34,Cert_App_Output!$K:$K,$X34) -> 0
A35: Hormigón MT | C35: Homigón MO | D35: Homigón MO | E35: 3.16 | F35: OK | G35: Losa H° Visto - H30 (95 kg/m3 de hierro) | H35: m3 | I35: 13 | J35: 367994.55 | K35: 253632.45 | L35: 63408.11 | M35: 10275.53 | N35: =SUM(J35:M35) -> 695310.64 | O35: =IF($N35=0,$S35,J35/$N35*$S35) -> 499172.51 | P35: =IF($N35=0,0,K35/$N35*$S35) -> 344044.08 | Q35: =IF($N35=0,0,L35/$N35*$S35) -> 86011.017 | R35: =IF($N35=0,0,M35/$N35*$S35) -> 13938.419 | S35: 943166.02 | T35: =IFERROR(S35/N35,"") -> 1.3564671 | U35: =N35*I35 -> 9039038.3 | V35: =S35*I35 -> 12261158 | W35: Estructura Resistente | X35: PTO 01 | Y35: =SUMIFS(Cert_App_Output!$G:$G,Cert_App_Output!$E:$E,$E35,Cert_App_Output!$K:$K,$X35) -> 0
A36: Hormigón MT | C36: Homigón MO | E36: 3.17 | F36: OK | G36: Escalera - H30 (105 kg/m3) | H36: m3 | I36: 14 | J36: 404870.23 | K36: 370454.15 | L36: 0 | M36: 11629.87 | N36: =SUM(J36:M36) -> 786954.25 | O36: =IF($N36=0,$S36,J36/$N36*$S36) -> 549193.16 | P36: =IF($N36=0,0,K36/$N36*$S36) -> 502508.88 | Q36: =IF($N36=0,0,L36/$N36*$S36) -> 0 | R36: =IF($N36=0,0,M36/$N36*$S36) -> 15775.536 | S36: 1067477.6 | T36: =IFERROR(S36/N36,"") -> 1.3564671 | U36: =N36*I36 -> 11017360 | V36: =S36*I36 -> 14944686 | W36: Estructura Resistente | X36: PTO 01 | Y36: =SUMIFS(Cert_App_Output!$G:$G,Cert_App_Output!$E:$E,$E36,Cert_App_Output!$K:$K,$X36) -> 0
A37: Hormigón MT | C37: Homigón MO | D37: Homigón MO | E37: 3.18 | F37: OK | G37: Viga alero - H30 (120 kg/m3 de hierro) | H37: m3 | I37: 2 | J37: 466389.3 | K37: 629584.36 | L37: 157396.09 | M37: 18800.55 | N37: =SUM(J37:M37) -> 1272170.3 | O37: =IF($N37=0,$S37,J37/$N37*$S37) -> 632641.75 | P37: =IF($N37=0,0,K37/$N37*$S37) -> 854010.49 | Q37: =IF($N37=0,0,L37/$N37*$S37) -> 213502.62 | R37: =IF($N37=0,0,M37/$N37*$S37) -> 25502.328 | S37: 1725657.2 | T37: =IFERROR(S37/N37,"") -> 1.3564671 | U37: =N37*I37 -> 2544340.6 | V37: =S37*I37 -> 3451314.4 | W37: Estructura Resistente | X37: PTO 01 | Y37: =SUMIFS(Cert_App_Output!$G:$G,Cert_App_Output!$E:$E,$E37,Cert_App_Output!$K:$K,$X37) -> 0
E38: 3.19 | F38: OK | G38: Sistema de apuntalamiento y reapuntalamiento | H38: gl | I38: 1 | J38: 0 | K38: 0 | L38: 0 | M38: 10584988 | N38: =SUM(J38:M38) -> 10584988 | O38: =IF($N38=0,$S38,J38/$N38*$S38) -> 0 | P38: =IF($N38=0,0,K38/$N38*$S38) -> 0 | Q38: =IF($N38=0,0,L38/$N38*$S38) -> 0 | R38: =IF($N38=0,0,M38/$N38*$S38) -> 14358188 | S38: 14358188 | T38: =IFERROR(S38/N38,"") -> 1.3564671 | U38: =N38*I38 -> 10584988 | V38: =S38*I38 -> 14358188 | W38: Estructura Resistente | X38: PTO 01 | Y38: =SUMIFS(Cert_App_Output!$G:$G,Cert_App_Output!$E:$E,$E38,Cert_App_Output!$K:$K,$X38) -> 0
C39: Homigón MO | E39: 3.2 | F39: OK | G39: Ensayos de Hormigon por etapas de hormigonado | H39: u | I39: 13 | J39: 0 | K39: 246942.15 | L39: 0 | M39: 0 | N39: =SUM(J39:M39) -> 246942.15 | O39: =IF($N39=0,$S39,J39/$N39*$S39) -> 0 | P39: =IF($N39=0,0,K39/$N39*$S39) -> 334968.91 | Q39: =IF($N39=0,0,L39/$N39*$S39) -> 0 | R39: =IF($N39=0,0,M39/$N39*$S39) -> 0 | S39: 334968.91 | T39: =IFERROR(S39/N39,"") -> 1.3564671 | U39: =N39*I39 -> 3210247.9 | V39: =S39*I39 -> 4354595.8 | W39: Estructura Resistente | X39: PTO 01 | Y39: =SUMIFS(Cert_App_Output!$G:$G,Cert_App_Output!$E:$E,$E39,Cert_App_Output!$K:$K,$X39) -> 0
A40: Hormigón MT | E40: 3.21 | F40: OK | G40: Permiso de estacionamiento de bomba de hormigón a contramano | H40: gl | I40: 3 | J40: 55000 | K40: 0 | L40: 0 | M40: 0 | N40: =SUM(J40:M40) -> 55000 | O40: =IF($N40=0,$S40,J40/$N40*$S40) -> 74605.692 | P40: =IF($N40=0,0,K40/$N40*$S40) -> 0 | Q40: =IF($N40=0,0,L40/$N40*$S40) -> 0 | R40: =IF($N40=0,0,M40/$N40*$S40) -> 0 | S40: 74605.692 | T40: =IFERROR(S40/N40,"") -> 1.3564671 | U40: =N40*I40 -> 165000 | V40: =S40*I40 -> 223817.08 | W40: Estructura Resistente | X40: PTO 01 | Y40: =SUMIFS(Cert_App_Output!$G:$G,Cert_App_Output!$E:$E,$E40,Cert_App_Output!$K:$K,$X40) -> 0.35
A41: Hormigón MT | D41: Homigón MO | E41: 3.22 | F41: OK | G41: Picado de medianeras para columnas y vigas - Cotizado solo para PB, 1P, NO contempla picado en CT | H41: m2 | I41: 65 | J41: 9230.77 | K41: 0 | L41: 20224.02 | M41: 441.82 | N41: =SUM(J41:M41) -> 29896.61 | O41: =IF($N41=0,$S41,J41/$N41*$S41) -> 12521.236 | P41: =IF($N41=0,0,K41/$N41*$S41) -> 0 | Q41: =IF($N41=0,0,L41/$N41*$S41) -> 27433.218 | R41: =IF($N41=0,0,M41/$N41*$S41) -> 599.3143 | S41: 40553.769 | T41: =IFERROR(S41/N41,"") -> 1.3564671 | U41: =N41*I41 -> 1943279.7 | V41: =S41*I41 -> 2635995 | W41: Estructura Resistente | X41: PTO 01 | Y41: =SUMIFS(Cert_App_Output!$G:$G,Cert_App_Output!$E:$E,$E41,Cert_App_Output!$K:$K,$X41) -> 0
...

Sheet 1_Composicion
A1: Partida | B1: Tipo | C1: Subtipo | D1: Cod_Insumo | E1: Descripción | F1: Unidad de medida | G1: Cant | H1: %Desp | I1: Precio | J1: Costo | K1: Clave | L1: Count | M1: Clave2 | N1: Rend. Part. | O1: Cant MO/ALB Unit | P1: Cant. Ej. Part. | Q1: Cant MO/ALB Total | R1: Cod_Item_Ppto | S1: Rubro
A2: APU-101 | B2: MO | C2: ALB | D2: MO-EESPE | E2: ESPECIALIZADO | F2: j | G2: 1 | H2: 0 | I2: 94177.138 | J2: 94177.138 | K2: APU-101|MO | L2: 1 | M2: APU-101|MO|1 | N2: 1 | O2: 1 | P2: - | Q2: 0 | R2: - | S2: =IFERROR(_xlfn.XLOOKUP(R2,'1_Presupuesto'!$E:$E,'1_Presupuesto'!$D:$D),"")
A3: APU-101 | B3: MO | C3: ALB | D3: MO-EAYUD | E3: AYUDANTE | F3: j | G3: 1 | H3: 0 | I3: 67240.499 | J3: 67240.499 | K3: APU-101|MO | L3: 2 | M3: APU-101|MO|2 | N3: 1 | O3: 1 | P3: - | Q3: 0 | R3: - | S3: =IFERROR(_xlfn.XLOOKUP(R3,'1_Presupuesto'!$E:$E,'1_Presupuesto'!$D:$D),"")
A4: BAN-106 | B4: MO | C4: ALB | D4: MO-EESPE | E4: ESPECIALIZADO | F4: j | G4: 1 | H4: 0 | I4: 94177.138 | J4: 94177.138 | K4: BAN-106|MO | L4: 1 | M4: BAN-106|MO|1 | N4: 3.8 | O4: 0.26315789 | P4: - | Q4: 0 | R4: - | S4: =IFERROR(_xlfn.XLOOKUP(R4,'1_Presupuesto'!$E:$E,'1_Presupuesto'!$D:$D),"")
A5: BAN-106 | B5: MO | C5: ALB | D5: MO-EAYUD | E5: AYUDANTE | F5: j | G5: 1 | H5: 0 | I5: 67240.499 | J5: 67240.499 | K5: BAN-106|MO | L5: 2 | M5: BAN-106|MO|2 | N5: 3.8 | O5: 0.26315789 | P5: - | Q5: 0 | R5: - | S5: =IFERROR(_xlfn.XLOOKUP(R5,'1_Presupuesto'!$E:$E,'1_Presupuesto'!$D:$D),"")
A6: ALB-110 | B6: MO | C6: ALB | D6: MO-EESPE | E6: ESPECIALIZADO | F6: j | G6: 1 | H6: 0 | I6: 94177.138 | J6: 94177.138 | K6: ALB-110|MO | L6: 1 | M6: ALB-110|MO|1 | N6: 36 | O6: 0.027777778 | P6: - | Q6: 0 | R6: - | S6: =IFERROR(_xlfn.XLOOKUP(R6,'1_Presupuesto'!$E:$E,'1_Presupuesto'!$D:$D),"")
A7: ALB-110 | B7: MO | C7: ALB | D7: MO-EAYUD | E7: AYUDANTE | F7: j | G7: 2 | H7: 0 | I7: 67240.499 | J7: 134481 | K7: ALB-110|MO | L7: 2 | M7: ALB-110|MO|2 | N7: 36 | O7: 0.055555556 | P7: - | Q7: 0 | R7: - | S7: =IFERROR(_xlfn.XLOOKUP(R7,'1_Presupuesto'!$E:$E,'1_Presupuesto'!$D:$D),"")
A8: ALB-110 | B8: MO | C8: ALB | D8: MO-EMEDI | E8: MEDIO OFICIAL | F8: j | G8: 5 | H8: 0 | I8: 72132.138 | J8: 360660.69 | K8: ALB-110|MO | L8: 3 | M8: ALB-110|MO|3 | N8: 36 | O8: 0.13888889 | P8: - | Q8: 0 | R8: - | S8: =IFERROR(_xlfn.XLOOKUP(R8,'1_Presupuesto'!$E:$E,'1_Presupuesto'!$D:$D),"")
A9: AIS-113 | B9: MAT | C9: OTR | D9: PIN-008 | E9: Pintura Asfaltica Asfasol x18ts | F9: 0 | G9: 0.0278 | H9: 0.1 | I9: 35525.95 | J9: 1086.3836 | K9: AIS-113|MAT | L9: 1 | M9: AIS-113|MAT|1 | N9: 80 | O9: 0 | P9: - | Q9: 0 | R9: - | S9: =IFERROR(_xlfn.XLOOKUP(R9,'1_Presupuesto'!$E:$E,'1_Presupuesto'!$D:$D),"")
A10: AIS-113 | B10: MAT | C10: OTR | D10: OTR-027 | E10: Rodillo de lana pelo largo N°22 - El Galgo | F10: u | G10: 0.01 | H10: 0.05 | I10: 6442.15 | J10: 67.642575 | K10: AIS-113|MAT | L10: 2 | M10: AIS-113|MAT|2 | N10: 80 | O10: 0 | P10: - | Q10: 0 | R10: - | S10: =IFERROR(_xlfn.XLOOKUP(R10,'1_Presupuesto'!$E:$E,'1_Presupuesto'!$D:$D),"")
A11: AIS-113 | B11: MAT | C11: OTR | D11: OTR-028 | E11: Pincel N° 20 - El Galgo | F11: u | G11: 0.02 | H11: 0.05 | I11: 4418.1818 | J11: 92.781818 | K11: AIS-113|MAT | L11: 3 | M11: AIS-113|MAT|3 | N11: 80 | O11: 0 | P11: - | Q11: 0 | R11: - | S11: =IFERROR(_xlfn.XLOOKUP(R11,'1_Presupuesto'!$E:$E,'1_Presupuesto'!$D:$D),"")
A12: AIS-113 | B12: MAT | C12: OTR | D12: OTR-022 | E12: Aguarras Hydrarras Hydra x 18lts | F12: 0 | G12: 0.002 | H12: 0.05 | I12: 58016.529 | J12: 121.83471 | K12: AIS-113|MAT | L12: 4 | M12: AIS-113|MAT|4 | N12: 80 | O12: 0 | P12: - | Q12: 0 | R12: - | S12: =IFERROR(_xlfn.XLOOKUP(R12,'1_Presupuesto'!$E:$E,'1_Presupuesto'!$D:$D),"")
A13: AIS-113 | B13: MAT | C13: OTR | D13: OTR-025 | E13: Trapo | F13: 0 | G13: 0.02 | H13: 0.05 | I13: 1182.6446 | J13: 24.835537 | K13: AIS-113|MAT | L13: 5 | M13: AIS-113|MAT|5 | N13: 80 | O13: 0 | P13: - | Q13: 0 | R13: - | S13: =IFERROR(_xlfn.XLOOKUP(R13,'1_Presupuesto'!$E:$E,'1_Presupuesto'!$D:$D),"")
A14: AIS-113 | B14: EQ | D14: EQ-SOLD00 | E14: Soldador Soplete A Gas Techista Membrana 10 Kg Boca 50mm | G14: 1 | H14: 0 | I14: 874.41131 | J14: 874.41131 | K14: AIS-113|EQ | L14: 1 | M14: AIS-113|EQ|1 | N14: 80 | O14: 0 | P14: - | Q14: 0 | R14: - | S14: =IFERROR(_xlfn.XLOOKUP(R14,'1_Presupuesto'!$E:$E,'1_Presupuesto'!$D:$D),"")
A15: AIS-113 | B15: MO | C15: ALB | D15: MO-EAYUD | E15: AYUDANTE | F15: j | G15: 1 | H15: 0 | I15: 67240.499 | J15: 67240.499 | K15: AIS-113|MO | L15: 1 | M15: AIS-113|MO|1 | N15: 80 | O15: 0.0125 | P15: - | Q15: 0 | R15: - | S15: =IFERROR(_xlfn.XLOOKUP(R15,'1_Presupuesto'!$E:$E,'1_Presupuesto'!$D:$D),"")
A16: AIS-113 | B16: MO | C16: ALB | D16: MO-EESPE | E16: ESPECIALIZADO | F16: j | G16: 1 | H16: 0 | I16: 94177.138 | J16: 94177.138 | K16: AIS-113|MO | L16: 2 | M16: AIS-113|MO|2 | N16: 80 | O16: 0.0125 | P16: - | Q16: 0 | R16: - | S16: =IFERROR(_xlfn.XLOOKUP(R16,'1_Presupuesto'!$E:$E,'1_Presupuesto'!$D:$D),"")
A17: AIS-114 | B17: MAT | C17: OTR | D17: PIN-008 | E17: Pintura Asfaltica Asfasol x18ts | F17: 0 | G17: 0.015 | H17: 0.1 | I17: 35525.95 | J17: 586.17818 | K17: AIS-114|MAT | L17: 1 | M17: AIS-114|MAT|1 | N17: 60 | O17: 0 | P17: - | Q17: 0 | R17: - | S17: =IFERROR(_xlfn.XLOOKUP(R17,'1_Presupuesto'!$E:$E,'1_Presupuesto'!$D:$D),"")
A18: AIS-114 | B18: MAT | C18: OTR | D18: AIS-002 | E18: Membrana Geotextil Ormiflex 4mm - (35kg) x10m | F18: u | G18: 0.05 | H18: 0.1 | I18: 57227.91 | J18: 3147.535 | K18: AIS-114|MAT | L18: 2 | M18: AIS-114|MAT|2 | N18: 60 | O18: 0 | P18: - | Q18: 0 | R18: - | S18: =IFERROR(_xlfn.XLOOKUP(R18,'1_Presupuesto'!$E:$E,'1_Presupuesto'!$D:$D),"")
A19: AIS-114 | B19: EQ | D19: EQ-SOLD00 | E19: Soldador Soplete A Gas Techista Membrana 10 Kg Boca 50mm | G19: 1 | H19: 0 | I19: 874.41131 | J19: 874.41131 | K19: AIS-114|EQ | L19: 1 | M19: AIS-114|EQ|1 | N19: 60 | O19: 0 | P19: - | Q19: 0 | R19: - | S19: =IFERROR(_xlfn.XLOOKUP(R19,'1_Presupuesto'!$E:$E,'1_Presupuesto'!$D:$D),"")
A20: AIS-114 | B20: MO | C20: ALB | D20: MO-EAYUD | E20: AYUDANTE | F20: j | G20: 1 | H20: 0 | I20: 67240.499 | J20: 67240.499 | K20: AIS-114|MO | L20: 1 | M20: AIS-114|MO|1 | N20: 60 | O20: 0.016666667 | P20: - | Q20: 0 | R20: - | S20: =IFERROR(_xlfn.XLOOKUP(R20,'1_Presupuesto'!$E:$E,'1_Presupuesto'!$D:$D),"")
A21: AIS-114 | B21: MO | C21: ALB | D21: MO-EESPE | E21: ESPECIALIZADO | F21: j | G21: 1 | H21: 0 | I21: 94177.138 | J21: 94177.138 | K21: AIS-114|MO | L21: 2 | M21: AIS-114|MO|2 | N21: 60 | O21: 0.016666667 | P21: - | Q21: 0 | R21: - | S21: =IFERROR(_xlfn.XLOOKUP(R21,'1_Presupuesto'!$E:$E,'1_Presupuesto'!$D:$D),"")
A22: REV-115 | B22: MAT | C22: OTR | D22: AGR-001 | E22: ARENA LAVADA | F22: 0 | G22: 0.02 | H22: 0.03 | I22: 32620.38 | J22: 671.97983 | K22: REV-115|MAT | L22: 1 | M22: REV-115|MAT|1 | N22: 15 | O22: 0 | P22: - | Q22: 0 | R22: - | S22: =IFERROR(_xlfn.XLOOKUP(R22,'1_Presupuesto'!$E:$E,'1_Presupuesto'!$D:$D),"")
A23: REV-115 | B23: MAT | C23: OTR | D23: AGR-005 | E23: Cal Comun x 25kg | F23: 0 | G23: 0.06 | H23: 0.05 | I23: 3927.28 | J23: 247.41864 | K23: REV-115|MAT | L23: 2 | M23: REV-115|MAT|2 | N23: 15 | O23: 0 | P23: - | Q23: 0 | R23: - | S23: =IFERROR(_xlfn.XLOOKUP(R23,'1_Presupuesto'!$E:$E,'1_Presupuesto'!$D:$D),"")
A24: REV-115 | B24: MAT | C24: OTR | D24: AGR-004 | E24: Cemento Portland x 50kg | F24: 0 | G24: 0.26 | H24: 0.03 | I24: 7891.74 | J24: 2113.408 | K24: REV-115|MAT | L24: 3 | M24: REV-115|MAT|3 | N24: 15 | O24: 0 | P24: - | Q24: 0 | R24: - | S24: =IFERROR(_xlfn.XLOOKUP(R24,'1_Presupuesto'!$E:$E,'1_Presupuesto'!$D:$D),"")
A25: REV-115 | B25: MO | C25: ALB | D25: MO-EESPE | E25: ESPECIALIZADO | F25: j | G25: 1 | H25: 0 | I25: 94177.138 | J25: 94177.138 | K25: REV-115|MO | L25: 1 | M25: REV-115|MO|1 | N25: 15 | O25: 0.066666667 | P25: - | Q25: 0 | R25: - | S25: =IFERROR(_xlfn.XLOOKUP(R25,'1_Presupuesto'!$E:$E,'1_Presupuesto'!$D:$D),"")
A26: REV-115 | B26: MO | C26: ALB | D26: MO-EAYUD | E26: AYUDANTE | F26: j | G26: 1 | H26: 0 | I26: 67240.499 | J26: 67240.499 | K26: REV-115|MO | L26: 2 | M26: REV-115|MO|2 | N26: 15 | O26: 0.066666667 | P26: - | Q26: 0 | R26: - | S26: =IFERROR(_xlfn.XLOOKUP(R26,'1_Presupuesto'!$E:$E,'1_Presupuesto'!$D:$D),"")
A27: REV-115 | B27: MO | C27: ALB | D27: MO-EMEDI | E27: MEDIO OFICIAL | F27: j | G27: 0 | H27: 0 | I27: 72132.138 | J27: 0 | K27: REV-115|MO | L27: 3 | M27: REV-115|MO|3 | N27: 15 | O27: 0 | P27: - | Q27: 0 | R27: - | S27: =IFERROR(_xlfn.XLOOKUP(R27,'1_Presupuesto'!$E:$E,'1_Presupuesto'!$D:$D),"")
A28: REV-116 | B28: MAT | C28: OTR | D28: DUR-007 | E28: Perfil Perimetral x 3.05 | F28: u | G28: 0.495 | H28: 0.1 | I28: 3028.9421 | J28: 1649.259 | K28: REV-116|MAT | L28: 1 | M28: REV-116|MAT|1 | N28: 12 | O28: 0 | P28: - | Q28: 0 | R28: - | S28: =IFERROR(_xlfn.XLOOKUP(R28,'1_Presupuesto'!$E:$E,'1_Presupuesto'!$D:$D),"")
A29: REV-116 | B29: MAT | C29: OTR | D29: OTR-015 | E29: Larguero x 3.66 | F29: u | G29: 0.45 | H29: 0.1 | I29: 4774.9091 | J29: 2363.58 | K29: REV-116|MAT | L29: 2 | M29: REV-116|MAT|2 | N29: 12 | O29: 0 | P29: - | Q29: 0 | R29: - | S29: =IFERROR(_xlfn.XLOOKUP(R29,'1_Presupuesto'!$E:$E,'1_Presupuesto'!$D:$D),"")
A30: REV-116 | B30: MAT | C30: OTR | D30: OTR-016 | E30: Travesaño x 1.22 | F30: u | G30: 2.62 | H30: 0.1 | I30: 1547.438 | J30: 4459.7164 | K30: REV-116|MAT | L30: 3 | M30: REV-116|MAT|3 | N30: 12 | O30: 0 | P30: - | Q30: 0 | R30: - | S30: =IFERROR(_xlfn.XLOOKUP(R30,'1_Presupuesto'!$E:$E,'1_Presupuesto'!$D:$D),"")
A31: REV-116 | B31: MAT | C31: OTR | D31: OTR-017 | E31: Travesaño x 0.60 | F31: u | G31: 0 | H31: 0.1 | I31: 793.53719 | J31: 0 | K31: REV-116|MAT | L31: 4 | M31: REV-116|MAT|4 | N31: 12 | O31: 0 | P31: - | Q31: 0 | R31: - | S31: =IFERROR(_xlfn.XLOOKUP(R31,'1_Presupuesto'!$E:$E,'1_Presupuesto'!$D:$D),"")
A32: REV-116 | B32: MAT | C32: OTR | D32: OTR-010 | E32: Fijacion completa del 8 | F32: u | G32: 6 | H32: 0.1 | I32: 63.381983 | J32: 418.32109 | K32: REV-116|MAT | L32: 5 | M32: REV-116|MAT|5 | N32: 12 | O32: 0 | P32: - | Q32: 0 | R32: - | S32: =IFERROR(_xlfn.XLOOKUP(R32,'1_Presupuesto'!$E:$E,'1_Presupuesto'!$D:$D),"")
A33: REV-116 | B33: MAT | C33: OTR | D33: ACE-014 | E33: Alambre galvanizado N°14 x kg | F33: kg | G33: 0.06 | H33: 0.1 | I33: 2755.6116 | J33: 181.87036 | K33: REV-116|MAT | L33: 6 | M33: REV-116|MAT|6 | N33: 12 | O33: 0 | P33: - | Q33: 0 | R33: - | S33: =IFERROR(_xlfn.XLOOKUP(R33,'1_Presupuesto'!$E:$E,'1_Presupuesto'!$D:$D),"")
A34: REV-116 | B34: MAT | C34: OTR | D34: OTR-019 | E34: Placa Decovinyl Liso 120x60 | F34: u | G34: 1.3889 | H34: 0.1 | I34: 4751.7079 | J34: 7259.6118 | K34: REV-116|MAT | L34: 7 | M34: REV-116|MAT|7 | N34: 12 | O34: 0 | P34: - | Q34: 0 | R34: - | S34: =IFERROR(_xlfn.XLOOKUP(R34,'1_Presupuesto'!$E:$E,'1_Presupuesto'!$D:$D),"")
A35: REV-116 | B35: EQ | D35: EQ-ESCALE | E35: ESCALERA GLOSS ALUMINIO ARTICULADA 4 X 4 ESCALONES HASTA 150KG | G35: 1 | H35: 0 | I35: 152.38027 | J35: 152.38027 | K35: REV-116|EQ | L35: 1 | M35: REV-116|EQ|1 | N35: 12 | O35: 0 | P35: - | Q35: 0 | R35: - | S35: =IFERROR(_xlfn.XLOOKUP(R35,'1_Presupuesto'!$E:$E,'1_Presupuesto'!$D:$D),"")
A36: REV-116 | B36: EQ | D36: EQ-PTO024 | E36: EQUIPO DE CONSTRUCCION EN SECO | G36: 1 | H36: 0 | I36: 2570.7599 | J36: 2570.7599 | K36: REV-116|EQ | L36: 2 | M36: REV-116|EQ|2 | N36: 12 | O36: 0 | P36: - | Q36: 0 | R36: - | S36: =IFERROR(_xlfn.XLOOKUP(R36,'1_Presupuesto'!$E:$E,'1_Presupuesto'!$D:$D),"")
A37: REV-116 | B37: MO | C37: ALB | D37: MO-EESPE | E37: ESPECIALIZADO | F37: j | G37: 1 | H37: 0 | I37: 94177.138 | J37: 94177.138 | K37: REV-116|MO | L37: 1 | M37: REV-116|MO|1 | N37: 12 | O37: 0.083333333 | P37: - | Q37: 0 | R37: - | S37: =IFERROR(_xlfn.XLOOKUP(R37,'1_Presupuesto'!$E:$E,'1_Presupuesto'!$D:$D),"")
A38: REV-116 | B38: MO | C38: ALB | D38: MO-EMEDI | E38: MEDIO OFICIAL | F38: j | G38: 1 | H38: 0 | I38: 72132.138 | J38: 72132.138 | K38: REV-116|MO | L38: 2 | M38: REV-116|MO|2 | N38: 12 | O38: 0.083333333 | P38: - | Q38: 0 | R38: - | S38: =IFERROR(_xlfn.XLOOKUP(R38,'1_Presupuesto'!$E:$E,'1_Presupuesto'!$D:$D),"")
A39: YES-117 | B39: MAT | C39: OTR | D39: OTR-014 | E39: Buña Z x 2.60m | F39: u | G39: 0.39 | H39: 0.1 | I39: 2234.18 | J39: 958.46322 | K39: YES-117|MAT | L39: 1 | M39: YES-117|MAT|1 | N39: 15 | O39: 0 | P39: - | Q39: 0 | R39: - | S39: =IFERROR(_xlfn.XLOOKUP(R39,'1_Presupuesto'!$E:$E,'1_Presupuesto'!$D:$D),"")
A40: YES-117 | B40: MAT | C40: OTR | D40: OTR-008 | E40: Tornillo T2 - Aguja | F40: u | G40: 3 | H40: 0.05 | I40: 9.114692 | J40: 28.71128 | K40: YES-117|MAT | L40: 2 | M40: YES-117|MAT|2 | N40: 15 | O40: 0 | P40: - | Q40: 0 | R40: - | S40: =IFERROR(_xlfn.XLOOKUP(R40,'1_Presupuesto'!$E:$E,'1_Presupuesto'!$D:$D),"")
...

Sheet 1_GGBB
H2: 45846 | O2: 24
F3: MESES | G3: DÓLAR BNA | H3: DÓLAR MEP | M3: Descrip | N3: Mes | O3: Total Dias
B4: GASTOS GENERALES y BENEFICIO | F4: 19 | G4: 1280 | H4: 1276 | M4: Prelim | N4: 0.5 | O4: 12 | Q4: Syh permanente
M5: Micropilotes | N5: 2 | O5: 48 | Q5: 1
B6: Gastos Grales de obra en items | C6: Un | D6: Meses | E6: Cant | F6: Precio Unit | G6: Subtotal | H6: 3040000 | M6: Subsuelo y VF | N6: 1 | O6: 24
B7: Oficina en obra (6x3 c/AA) | C7: mes | D7: 19 | E7: 0 | F7: 0 | G7: 0 | M7: Losa sobre PB | N7: 1 | O7: 24
B8: Obrador 6x3 s/AA | C8: mes | D8: 19 | E8: 0 | F8: 0 | G8: 0 | M8: Losa sobre 1 | N8: 0.75 | O8: 18
B9: Pañol (6x3) | C9: mes | D9: 19 | E9: 0 | F9: 180000 | G9: 0 | M9: Losa sobre 2 | N9: 0.75 | O9: 18
B10: Baños | C10: mes | D10: 19 | E10: 2 | F10: 80000 | G10: 3040000 | M10: Losa sobre 3 | N10: 0.75 | O10: 18
B11: Gastos Grales de obra en items | H11: 39866835 | M11: Losa sobre 4 | N11: 0.75 | O11: 18 | P11: Inicio mamposteria | Q11: Meses H° | R11: Estacionamiento en contramano
B12: HyS permanente | C12: mes | D12: 1 | E12: 1 | J12: 1623254.5 | K12: 1623254.5 | M12: Losa sobre 5 | N12: 0.75 | O12: 18 | Q12: 7.5 | R12: 3
B13: HyS | C13: mes | D13: 19 | E13: 1 | J13: 300000 | K13: 5700000 | M13: Losa sobre 6 | N13: 0.75 | O13: 18
B14: Energía de obra | C14: mes | D14: 19 | E14: 0.5 | F14: 200000 | G14: 1900000 | M14: Losa sobre 7 | N14: 0.5 | O14: 12
B15: Agua de obra | C15: mes | D15: 19 | E15: 1 | F15: 300000 | G15: 5700000 | M15: Losa Techos | N15: 0.5 | O15: 12
B16: Internet | C16: mes | D16: 19 | E16: 1 | F16: 75000 | G16: 1425000 | M16: Mampostería | N16: 2 | O16: 48
B17: Alquiler cerco de obra chapa | C17: mes | D17: 19 | E17: 0 | F17: 10000 | G17: 0 | M17: Revoques, contrap y carp | N17: 2 | O17: 48
B18: Proyecto Ejecutivo | C18: mes | D18: 19 | E18: 0 | F18: 3246508.9 | G18: 0 | M18: Colocación | N18: 2 | O18: 48
B19: Proyecto (50%) | C19: mes | D19: 19 | E19: 0.5 | F19: 3246508.9 | G19: 30841835 | M19: Pintura | N19: 2 | O19: 48
B20: Gastos Directos | H20: 89942566 | M20: Terminaciones | N20: 1 | O20: 24
B21: Coordinacion de obra | C21: mes | D21: 19 | E21: 0.15 | F21: 5688802.4 | G21: 16213087 | N21: 19 | O21: 456
B22: Jefe de obra | C22: mes | D22: 19 | E22: 0.2 | F22: 4716669.4 | G22: 17923344
B23: Sobrestante | C23: mes | D23: 19 | E23: 1 | J23: 3246508.9 | K23: 61683669
B24: Administrativo en obra | C24: mes | D24: 19 | E24: 0 | F24: 3246508.9 | G24: 0
B25: Capataz | C25: mes | D25: 19 | E25: 0.5 | F25: 3874330.1 | G25: 36806136
B26: Logistica | C26: mes | D26: 19 | E26: 1 | F26: 500000 | G26: 9500000
B27: Vehiculo obra | C27: mes | D27: 19 | E27: 1 | F27: 500000 | G27: 9500000
B28: Mov y viaticos | C28: mes | D28: 19 | E28: 1 | J28: 500000 | K28: 9500000
B29: UOCRA | C29: mes | D29: 19 | E29: 1 | G29: 0
B30: Pañolero/Sereno | C30: mes | D30: 19 | E30: 1 | J30: 806885.99 | K30: 15330834
B31: Equipos | H31: 0
B32: Bobcat | C32: mes | F32: 130000 | G32: 0
B33: Camion limpieza | C33: mes | F33: 100000 | G33: 0
B34: Tijera electrica 12 | C34: mes | F34: 33600 | G34: 0
B35: JLG | C35: mes | F35: 89000 | G35: 0
B36: Grua 20ton | C36: mes | F36: 70000 | G36: 0
B37: Gastos Indirectos | H37: 94164835
B38: Admin (50%Compras - 50%RRHH) | C38: mes | D38: 19 | E38: 0.5 | F38: 3246508.9 | G38: 30841835
B39: Seguros | C39: gl | D39: 19 | E39: 1 | F39: 250000 | G39: 4750000
B40: IIBB (monto venta obra gris) | C40: gl | D40: 0.04 | E40: 0.7 | F40: 1550000000 | G40: 43400000
B41: Imp cheque | C41: gl | D41: 0.012 | E41: 0.7 | F41: 1782500000 | G41: 14973000
...

Sheet 2_Movimientos
A1: Cuenta | B1: Desc Cuenta | C1: Fecha Asiento | D1: Nº Asiento | E1: Observaciones | F1: Cliente/Proveedor | G1: Cód Comprobante | H1: Nº Comprobante | I1: Debe | J1: Haber | K1: Unidad | L1: Desc Unidad | M1: Centro de Costo | N1: Desc Centro Costo | O1: Saldo Inicial | P1: Observaciones original | Q1: mov_id | R1: mov_tipo
A2: 53001 | B2: Preliminares | C2: 46042 | D2: 972 | E2: PRELIMINARES - Comercial cmp S | F2: Comercial cmp S.A | G2: FCA3 | H2: 21100144871 | I2: 885229.7 | J2: 0 | K2: DESA | L2: Desarrollos | M2: CHIVILCOY | N2: CHIVILCOY 2171 | O2: 0 | P2: PRELIMINARES - Comercial cmp S | Q2: =IFERROR(TRIM(LEFT($E2,FIND(" | ",$E2)-1)),"") | R2: =IFERROR(TRIM(UPPER(MID($E2,FIND(" | ",$E2)+3,IFERROR(FIND(" | ",$E2,FIND(" | ",$E2)+3),LEN($E2)+1)-FIND(" | ",$E2)-3))),"")
A3: 53023 | B3: Varios Ferreteria | C3: 46044 | D3: 393 | E3: Varios Ferreteria | G3: OPXX | H3: 8417 | I3: 2000 | J3: 0 | K3: DESA | L3: Desarrollos | M3: CHIVILCOY | N3: CHIVILCOY 2171 | O3: 0 | P3: Varios Ferreteria | Q3: =IFERROR(TRIM(LEFT($E3,FIND(" | ",$E3)-1)),"") | R3: =IFERROR(TRIM(UPPER(MID($E3,FIND(" | ",$E3)+3,IFERROR(FIND(" | ",$E3,FIND(" | ",$E3)+3),LEN($E3)+1)-FIND(" | ",$E3)-3))),"")
A4: 53001 | B4: Preliminares | C4: 46045 | D4: 986 | E4: PRELIMINARES - CUTULI HNOS S.A | F4: CUTULI HNOS S.A. | G4: FCA3 | H4: 1500090204 | I4: 45752.4 | J4: 0 | K4: DESA | L4: Desarrollos | M4: CHIVILCOY | N4: CHIVILCOY 2171 | O4: 0 | P4: PRELIMINARES - CUTULI HNOS S.A | Q4: =IFERROR(TRIM(LEFT($E4,FIND(" | ",$E4)-1)),"") | R4: =IFERROR(TRIM(UPPER(MID($E4,FIND(" | ",$E4)+3,IFERROR(FIND(" | ",$E4,FIND(" | ",$E4)+3),LEN($E4)+1)-FIND(" | ",$E4)-3))),"")
A5: 53023 | B5: Varios Ferreteria | C5: 46045 | D5: 398 | E5: Varios Ferreteria | G5: OPXX | H5: 8422 | I5: 6200 | J5: 0 | K5: DESA | L5: Desarrollos | M5: CHIVILCOY | N5: CHIVILCOY 2171 | O5: 0 | P5: Varios Ferreteria | Q5: =IFERROR(TRIM(LEFT($E5,FIND(" | ",$E5)-1)),"") | R5: =IFERROR(TRIM(UPPER(MID($E5,FIND(" | ",$E5)+3,IFERROR(FIND(" | ",$E5,FIND(" | ",$E5)+3),LEN($E5)+1)-FIND(" | ",$E5)-3))),"")
A6: 52204 | B6: H. Seguridad e Higiene | C6: 46055 | D6: 1381 | E6: Honorarios Seguridad e Higiene | F6: Petrini David Osvaldo | G6: FCA3 | H6: 300001414 | I6: 517195 | J6: 0 | K6: DESA | L6: Desarrollos | M6: CHIVILCOY | N6: CHIVILCOY 2171 | O6: 0 | P6: Honorarios Seguridad e Higiene | Q6: =IFERROR(TRIM(LEFT($E6,FIND(" | ",$E6)-1)),"") | R6: =IFERROR(TRIM(UPPER(MID($E6,FIND(" | ",$E6)+3,IFERROR(FIND(" | ",$E6,FIND(" | ",$E6)+3),LEN($E6)+1)-FIND(" | ",$E6)-3))),"")
A7: 53001 | B7: Preliminares | C7: 46057 | D7: 2341 | E7: Cerco de obra - Pinturerias Pr | F7: Pinturerias Prestigio S.A | G7: FCA3 | H7: 502000000000 | I7: 119384.31 | J7: 0 | K7: DESA | L7: Desarrollos | M7: CHIVILCOY | N7: CHIVILCOY 2171 | O7: 0 | P7: Cerco de obra - Pinturerias Pr | Q7: =IFERROR(TRIM(LEFT($E7,FIND(" | ",$E7)-1)),"") | R7: =IFERROR(TRIM(UPPER(MID($E7,FIND(" | ",$E7)+3,IFERROR(FIND(" | ",$E7,FIND(" | ",$E7)+3),LEN($E7)+1)-FIND(" | ",$E7)-3))),"")
A8: 53008 | B8: Albañilería MT | C8: 46057 | D8: 1242 | E8: ALBAÑILERIA MT - CUTULI HNOS S | F8: CUTULI HNOS S.A. | G8: FCA3 | H8: 1500090674 | I8: 48248.1 | J8: 0 | K8: DESA | L8: Desarrollos | M8: CHIVILCOY | N8: CHIVILCOY 2171 | O8: 0 | P8: ALBAÑILERIA MT - CUTULI HNOS S | Q8: =IFERROR(TRIM(LEFT($E8,FIND(" | ",$E8)-1)),"") | R8: =IFERROR(TRIM(UPPER(MID($E8,FIND(" | ",$E8)+3,IFERROR(FIND(" | ",$E8,FIND(" | ",$E8)+3),LEN($E8)+1)-FIND(" | ",$E8)-3))),"")
A9: 53022 | B9: Gastos Generales | C9: 46077 | D9: 1388 | E9: Baño portatil - ECOBAT SRL | F9: ECOBAT SRL | G9: FCA3 | H9: 300025194 | I9: 247000 | J9: 0 | K9: DESA | L9: Desarrollos | M9: CHIVILCOY | N9: CHIVILCOY 2171 | O9: 0 | P9: Baño portatil - ECOBAT SRL | Q9: =IFERROR(TRIM(LEFT($E9,FIND(" | ",$E9)-1)),"") | R9: =IFERROR(TRIM(UPPER(MID($E9,FIND(" | ",$E9)+3,IFERROR(FIND(" | ",$E9,FIND(" | ",$E9)+3),LEN($E9)+1)-FIND(" | ",$E9)-3))),"")
A10: 53001 | B10: Preliminares | C10: 46080 | D10: 1406 | E10: PRELIMINARES - Pinturerias Pre | F10: Pinturerias Prestigio S.A | G10: FCA3 | H10: 126000000000 | I10: 89183.46 | J10: 0 | K10: DESA | L10: Desarrollos | M10: CHIVILCOY | N10: CHIVILCOY 2171 | O10: 0 | P10: PRELIMINARES - Pinturerias Pre | Q10: =IFERROR(TRIM(LEFT($E10,FIND(" | ",$E10)-1)),"") | R10: =IFERROR(TRIM(UPPER(MID($E10,FIND(" | ",$E10)+3,IFERROR(FIND(" | ",$E10,FIND(" | ",$E10)+3),LEN($E10)+1)-FIND(" | ",$E10)-3))),"")
A11: 53001 | B11: Preliminares | C11: 46080 | D11: 614 | E11: CH-SC-001 | BASE | Claudio Balaclav - Gestor Elec | G11: OPXX | H11: 8632 | I11: 520000 | J11: 0 | K11: DESA | L11: Desarrollos | M11: CHIVILCOY | N11: CHIVILCOY 2171 | O11: 0 | P11: Claudio Balaclav - Gestor Elec | Q11: =IFERROR(TRIM(LEFT($E11,FIND(" | ",$E11)-1)),"") -> CH-SC-001 | R11: =IFERROR(TRIM(UPPER(MID($E11,FIND(" | ",$E11)+3,IFERROR(FIND(" | ",$E11,FIND(" | ",$E11)+3),LEN($E11)+1)-FIND(" | ",$E11)-3))),"") -> BASE
A12: 53001 | B12: Preliminares | C12: 46080 | D12: 1398 | E12: PRELIMINARES - FABELEC | F12: FABELEC | G12: FCA3 | H12: 500005390 | I12: 291421.17 | J12: 0 | K12: DESA | L12: Desarrollos | M12: CHIVILCOY | N12: CHIVILCOY 2171 | O12: 0 | P12: PRELIMINARES - FABELEC | Q12: =IFERROR(TRIM(LEFT($E12,FIND(" | ",$E12)-1)),"") | R12: =IFERROR(TRIM(UPPER(MID($E12,FIND(" | ",$E12)+3,IFERROR(FIND(" | ",$E12,FIND(" | ",$E12)+3),LEN($E12)+1)-FIND(" | ",$E12)-3))),"")
A13: 53001 | B13: Preliminares | C13: 46083 | D13: 1405 | E13: Constancia Inspeccion Cartel - | F13: DESSINS CARTELERIA S.R.L | G13: FCA3 | H13: 200008045 | I13: 8181.82 | J13: 0 | K13: DESA | L13: Desarrollos | M13: CHIVILCOY | N13: CHIVILCOY 2171 | O13: 0 | P13: Constancia Inspeccion Cartel - | Q13: =IFERROR(TRIM(LEFT($E13,FIND(" | ",$E13)-1)),"") | R13: =IFERROR(TRIM(UPPER(MID($E13,FIND(" | ",$E13)+3,IFERROR(FIND(" | ",$E13,FIND(" | ",$E13)+3),LEN($E13)+1)-FIND(" | ",$E13)-3))),"")
A14: 52204 | B14: H. Seguridad e Higiene | C14: 46084 | D14: 2072 | E14: Honorarios Seguridad e Higiene | F14: Petrini David Osvaldo | G14: FCA3 | H14: 300001433 | I14: 517195 | J14: 0 | K14: DESA | L14: Desarrollos | M14: CHIVILCOY | N14: CHIVILCOY 2171 | O14: 0 | P14: Honorarios Seguridad e Higiene | Q14: =IFERROR(TRIM(LEFT($E14,FIND(" | ",$E14)-1)),"") | R14: =IFERROR(TRIM(UPPER(MID($E14,FIND(" | ",$E14)+3,IFERROR(FIND(" | ",$E14,FIND(" | ",$E14)+3),LEN($E14)+1)-FIND(" | ",$E14)-3))),"")
A15: 53023 | B15: Varios Ferreteria | C15: 46084 | D15: 870 | E15: Varios Ferreteria | G15: OPXX | H15: 8902 | I15: 18500 | J15: 0 | K15: DESA | L15: Desarrollos | M15: CHIVILCOY | N15: CHIVILCOY 2171 | O15: 0 | P15: Varios Ferreteria | Q15: =IFERROR(TRIM(LEFT($E15,FIND(" | ",$E15)-1)),"") | R15: =IFERROR(TRIM(UPPER(MID($E15,FIND(" | ",$E15)+3,IFERROR(FIND(" | ",$E15,FIND(" | ",$E15)+3),LEN($E15)+1)-FIND(" | ",$E15)-3))),"")
A16: 53001 | B16: Preliminares | C16: 46085 | D16: 1499 | E16: PRELIMINARES - CUTULI HNOS S.A | F16: CUTULI HNOS S.A. | G16: FCA3 | H16: 1500091777 | I16: 111030.25 | J16: 0 | K16: DESA | L16: Desarrollos | M16: CHIVILCOY | N16: CHIVILCOY 2171 | O16: 0 | P16: PRELIMINARES - CUTULI HNOS S.A | Q16: =IFERROR(TRIM(LEFT($E16,FIND(" | ",$E16)-1)),"") | R16: =IFERROR(TRIM(UPPER(MID($E16,FIND(" | ",$E16)+3,IFERROR(FIND(" | ",$E16,FIND(" | ",$E16)+3),LEN($E16)+1)-FIND(" | ",$E16)-3))),"")
A17: 5108 | B17: Gastos en personal | C17: 46086 | D17: 875 | E17: Gastos en personal | G17: OPXX | H17: 8907 | I17: 8000 | J17: 0 | K17: DESA | L17: Desarrollos | M17: CHIVILCOY | N17: CHIVILCOY 2171 | O17: 0 | P17: Gastos en personal | Q17: =IFERROR(TRIM(LEFT($E17,FIND(" | ",$E17)-1)),"") | R17: =IFERROR(TRIM(UPPER(MID($E17,FIND(" | ",$E17)+3,IFERROR(FIND(" | ",$E17,FIND(" | ",$E17)+3),LEN($E17)+1)-FIND(" | ",$E17)-3))),"")
A18: 53001 | B18: Preliminares | C18: 46086 | D18: 649 | E18: CH-SC-002 | BASE | Alejandro Ardiles - Agrimensor | G18: OPXX | H18: 8667 | I18: 380000 | J18: 0 | K18: DESA | L18: Desarrollos | M18: CHIVILCOY | N18: CHIVILCOY 2171 | O18: 0 | P18: Alejandro Ardiles - Agrimensor | Q18: =IFERROR(TRIM(LEFT($E18,FIND(" | ",$E18)-1)),"") -> CH-SC-002 | R18: =IFERROR(TRIM(UPPER(MID($E18,FIND(" | ",$E18)+3,IFERROR(FIND(" | ",$E18,FIND(" | ",$E18)+3),LEN($E18)+1)-FIND(" | ",$E18)-3))),"") -> BASE
A19: 53023 | B19: Varios Ferreteria | C19: 46087 | D19: 871 | E19: Varios Ferreteria | G19: OPXX | H19: 8903 | I19: 21000 | J19: 0 | K19: DESA | L19: Desarrollos | M19: CHIVILCOY | N19: CHIVILCOY 2171 | O19: 0 | P19: Varios Ferreteria | Q19: =IFERROR(TRIM(LEFT($E19,FIND(" | ",$E19)-1)),"") | R19: =IFERROR(TRIM(UPPER(MID($E19,FIND(" | ",$E19)+3,IFERROR(FIND(" | ",$E19,FIND(" | ",$E19)+3),LEN($E19)+1)-FIND(" | ",$E19)-3))),"")
A20: 53001 | B20: Preliminares | C20: 46090 | D20: 1637 | E20: PRELIMINARES - Casa Castelao S | F20: Casa Castelao S.A. | G20: FCA3 | H20: 300011389 | I20: 676125.38 | J20: 0 | K20: DESA | L20: Desarrollos | M20: CHIVILCOY | N20: CHIVILCOY 2171 | O20: 0 | P20: PRELIMINARES - Casa Castelao S | Q20: =IFERROR(TRIM(LEFT($E20,FIND(" | ",$E20)-1)),"") | R20: =IFERROR(TRIM(UPPER(MID($E20,FIND(" | ",$E20)+3,IFERROR(FIND(" | ",$E20,FIND(" | ",$E20)+3),LEN($E20)+1)-FIND(" | ",$E20)-3))),"")
A21: 53001 | B21: Preliminares | C21: 46090 | D21: 1637 | E21: PRELIMINARES - Casa Castelao S | F21: Casa Castelao S.A. | G21: FCA3 | H21: 300011389 | I21: 15605.79 | J21: 0 | K21: DESA | L21: Desarrollos | M21: CHIVILCOY | N21: CHIVILCOY 2171 | O21: 0 | P21: PRELIMINARES - Casa Castelao S | Q21: =IFERROR(TRIM(LEFT($E21,FIND(" | ",$E21)-1)),"") | R21: =IFERROR(TRIM(UPPER(MID($E21,FIND(" | ",$E21)+3,IFERROR(FIND(" | ",$E21,FIND(" | ",$E21)+3),LEN($E21)+1)-FIND(" | ",$E21)-3))),"")
A22: 53001 | B22: Preliminares | C22: 46090 | D22: 1638 | E22: PRELIMINARES - Casa Castelao S | F22: Casa Castelao S.A. | G22: FCA3 | H22: 300011390 | I22: 32617.84 | J22: 0 | K22: DESA | L22: Desarrollos | M22: CHIVILCOY | N22: CHIVILCOY 2171 | O22: 0 | P22: PRELIMINARES - Casa Castelao S | Q22: =IFERROR(TRIM(LEFT($E22,FIND(" | ",$E22)-1)),"") | R22: =IFERROR(TRIM(UPPER(MID($E22,FIND(" | ",$E22)+3,IFERROR(FIND(" | ",$E22,FIND(" | ",$E22)+3),LEN($E22)+1)-FIND(" | ",$E22)-3))),"")
A23: 53001 | B23: Preliminares | C23: 46091 | D23: 1640 | E23: PRELIMINARES - Comercial cmp S | F23: Comercial cmp S.A | G23: FCA3 | H23: 21100146499 | I23: 115372.69 | J23: 0 | K23: DESA | L23: Desarrollos | M23: CHIVILCOY | N23: CHIVILCOY 2171 | O23: 0 | P23: PRELIMINARES - Comercial cmp S | Q23: =IFERROR(TRIM(LEFT($E23,FIND(" | ",$E23)-1)),"") | R23: =IFERROR(TRIM(UPPER(MID($E23,FIND(" | ",$E23)+3,IFERROR(FIND(" | ",$E23,FIND(" | ",$E23)+3),LEN($E23)+1)-FIND(" | ",$E23)-3))),"")
A24: 53004 | B24: Hormigón MT | C24: 46091 | D24: 1590 | E24: CH-SC-003 | BASE | HORMIGON MT - FEIS DEL OESTE C | F24: FEIS DEL OESTE CONSTRUCTORA SA | G24: FCA3 | H24: 100001478 | I24: 16781280 | J24: 0 | K24: DESA | L24: Desarrollos | M24: CHIVILCOY | N24: CHIVILCOY 2171 | O24: 0 | P24: HORMIGON MT - FEIS DEL OESTE C | Q24: =IFERROR(TRIM(LEFT($E24,FIND(" | ",$E24)-1)),"") -> CH-SC-003 | R24: =IFERROR(TRIM(UPPER(MID($E24,FIND(" | ",$E24)+3,IFERROR(FIND(" | ",$E24,FIND(" | ",$E24)+3),LEN($E24)+1)-FIND(" | ",$E24)-3))),"") -> BASE
A25: 53017 | B25: Sanitaria MT | C25: 46091 | D25: 1641 | E25: SANITARIA MT - Sanitriun S.R.L | F25: Sanitriun S.R.L | G25: FCA3 | H25: 400033694 | I25: 434539.28 | J25: 0 | K25: DESA | L25: Desarrollos | M25: CHIVILCOY | N25: CHIVILCOY 2171 | O25: 0 | P25: SANITARIA MT - Sanitriun S.R.L | Q25: =IFERROR(TRIM(LEFT($E25,FIND(" | ",$E25)-1)),"") | R25: =IFERROR(TRIM(UPPER(MID($E25,FIND(" | ",$E25)+3,IFERROR(FIND(" | ",$E25,FIND(" | ",$E25)+3),LEN($E25)+1)-FIND(" | ",$E25)-3))),"")
A26: 53001 | B26: Preliminares | C26: 46092 | D26: 1644 | E26: Cartel obra - DESSINS CARTELER | F26: DESSINS CARTELERIA S.R.L | G26: FCA3 | H26: 200008143 | I26: 23223.14 | J26: 0 | K26: DESA | L26: Desarrollos | M26: CHIVILCOY | N26: CHIVILCOY 2171 | O26: 0 | P26: Cartel obra - DESSINS CARTELER | Q26: =IFERROR(TRIM(LEFT($E26,FIND(" | ",$E26)-1)),"") | R26: =IFERROR(TRIM(UPPER(MID($E26,FIND(" | ",$E26)+3,IFERROR(FIND(" | ",$E26,FIND(" | ",$E26)+3),LEN($E26)+1)-FIND(" | ",$E26)-3))),"")
A27: 53001 | B27: Preliminares | C27: 46092 | D27: 1650 | E27: PRELIMINARES - CUTULI HNOS S.A | F27: CUTULI HNOS S.A. | G27: FCA3 | H27: 1500092093 | I27: 47742.28 | J27: 0 | K27: DESA | L27: Desarrollos | M27: CHIVILCOY | N27: CHIVILCOY 2171 | O27: 0 | P27: PRELIMINARES - CUTULI HNOS S.A | Q27: =IFERROR(TRIM(LEFT($E27,FIND(" | ",$E27)-1)),"") | R27: =IFERROR(TRIM(UPPER(MID($E27,FIND(" | ",$E27)+3,IFERROR(FIND(" | ",$E27,FIND(" | ",$E27)+3),LEN($E27)+1)-FIND(" | ",$E27)-3))),"")
A28: 52302 | B28: Mov. Variables | C28: 46093 | D28: 2156 | E28: Fletes - ROBLES EDUARDO NICOLA | F28: ROBLES EDUARDO NICOLAS | G28: FCA3 | H28: 200000062 | I28: 200000 | J28: 0 | K28: DESA | L28: Desarrollos | M28: CHIVILCOY | N28: CHIVILCOY 2171 | O28: 0 | P28: Fletes - ROBLES EDUARDO NICOLA | Q28: =IFERROR(TRIM(LEFT($E28,FIND(" | ",$E28)-1)),"") | R28: =IFERROR(TRIM(UPPER(MID($E28,FIND(" | ",$E28)+3,IFERROR(FIND(" | ",$E28,FIND(" | ",$E28)+3),LEN($E28)+1)-FIND(" | ",$E28)-3))),"")
A29: 53001 | B29: Preliminares | C29: 46094 | D29: 1674 | E29: PRELIMINARES - Casa Castelao S | F29: Casa Castelao S.A. | G29: FCA3 | H29: 300011508 | I29: 187369.3 | J29: 0 | K29: DESA | L29: Desarrollos | M29: CHIVILCOY | N29: CHIVILCOY 2171 | O29: 0 | P29: PRELIMINARES - Casa Castelao S | Q29: =IFERROR(TRIM(LEFT($E29,FIND(" | ",$E29)-1)),"") | R29: =IFERROR(TRIM(UPPER(MID($E29,FIND(" | ",$E29)+3,IFERROR(FIND(" | ",$E29,FIND(" | ",$E29)+3),LEN($E29)+1)-FIND(" | ",$E29)-3))),"")
A30: 53001 | B30: Preliminares | C30: 46094 | D30: 1675 | E30: PRELIMINARES - Casa Castelao S | F30: Casa Castelao S.A. | G30: FCA3 | H30: 300011507 | I30: 706017.99 | J30: 0 | K30: DESA | L30: Desarrollos | M30: CHIVILCOY | N30: CHIVILCOY 2171 | O30: 0 | P30: PRELIMINARES - Casa Castelao S | Q30: =IFERROR(TRIM(LEFT($E30,FIND(" | ",$E30)-1)),"") | R30: =IFERROR(TRIM(UPPER(MID($E30,FIND(" | ",$E30)+3,IFERROR(FIND(" | ",$E30,FIND(" | ",$E30)+3),LEN($E30)+1)-FIND(" | ",$E30)-3))),"")
A31: 53001 | B31: Preliminares | C31: 46094 | D31: 1679 | E31: PRELIMINARES - CUTULI HNOS S.A | F31: CUTULI HNOS S.A. | G31: FCA3 | H31: 1500092213 | I31: 52488.39 | J31: 0 | K31: DESA | L31: Desarrollos | M31: CHIVILCOY | N31: CHIVILCOY 2171 | O31: 0 | P31: PRELIMINARES - CUTULI HNOS S.A | Q31: =IFERROR(TRIM(LEFT($E31,FIND(" | ",$E31)-1)),"") | R31: =IFERROR(TRIM(UPPER(MID($E31,FIND(" | ",$E31)+3,IFERROR(FIND(" | ",$E31,FIND(" | ",$E31)+3),LEN($E31)+1)-FIND(" | ",$E31)-3))),"")
