Workbook
Name GASTOS_CONCEPTO: _Listas!$I$2:$I$17
Name RUBROS_PLAN: _Listas!$A$2:$A$34

Sheet 0_CONFIG
A1: ▌ CONFIGURACIÓN DE OBRA — GDR 3760
A3: Nombre de obra | B3: Edificio GDR 3760 — García del Río 3760
A4: Estado | B4: En ejecución
A5: Fecha inicio | B5: 45689 | C5: presupuesto cerrado dic-2024
A6: Duración estimada (meses) | B6: 18 | C6: feb-2025 a ago-2026
A7: — ÍNDICE CAC —
A8: Mes base CAC | B8: 45627 | C8: fecha base del presupuesto
A9: Valor CAC base (INDEC) | B9: 15356.4 | C9: índice INDEC del mes base
A10: Mes corriente | B10: =INDEX('0_Indice_CAC'!$A$4:$A$33,MATCH(1E+300,'0_Indice_CAC'!$B$4:$B$33)) -> 46174 | C10: último mes cargado
A11: Ratio CAC corriente | B11: =MIN('0_Indice_CAC'!$D$4:$D$33) -> 0.79437459 | C11: ratio del mes más reciente
A12: — COEFICIENTE K —
A13: K (Gastos Generales y Beneficio) | B13: ='1_GGBB'!F67 -> 1.3327274 | C13: CRÍTICO: no modificar manualmente
A14: — PRESUPUESTO —
A15: Apertura fiscal | B15: B70 / N30 / GGN | C15: Blanco 70% c/IVA · Negro 30% · GGN
A16: Costo controlable (sin EQ) | B16: =SUMPRODUCT(('1_Presupuesto'!$J$5:$J$227+'1_Presupuesto'!$K$5:$K$227+'1_Presupuesto'!$L$5:$L$227)*'1_Presupuesto'!$I$5:$I$227) -> 9.9459803e+08 | C16: MT+MO/OTR+MO/ALB × Cant (EQ excluido)
A17: Costo total (con EQ) | B17: =SUMPRODUCT('1_Presupuesto'!$N$5:$N$227*'1_Presupuesto'!$I$5:$I$227) -> 1.0161736e+09 | C17: Costo Unit. × Cant
A18: Precio de venta total | B18: =SUMPRODUCT('1_Presupuesto'!$S$5:$S$227*'1_Presupuesto'!$I$5:$I$227) -> 1.3542825e+09 | C18: P Unit. × Cant
A19: Sanity check (debe ser 0) | B19: =+B17*B13-B18 -> 0 | C19: EQ no tiene rubro → excluido de costo controlable
A44: — RECONCILIACIÓN MENSUAL —
A45: Total egresos (2_Movimientos) | B45: =SUMPRODUCT('2_Movimientos'!$I$2:$I$1000,N(LEFT(TEXT('2_Movimientos'!$A$2:$A$1000,"0"),1)<>"4"))-SUMPRODUCT('2_Movimientos'!$J$2:$J$1000,N(LEFT(TEXT('2_Movimientos'!$A$2:$A$1000,"0"),1)<>"4")) -> 4.2322121e+08 | C45: ← se cablea en bloque 6 (crear 2_Movimientos)
A46: Total Tezamat (pegar mensual) | C46: input mensual
A47: Diferencia (debe ser 0) | B47: =B45-B46 -> 4.2322121e+08 | C47: se activa al cablear B45
A49: Tolerancia conciliación ($) | B49: 100
A52: — PENDIENTES (celdas amarillas) —
A53: 0_Indice_CAC col B | B53: CAC meses futuros sin publicar
A54: 0_Jornales_MO | B54: Tarifas UOCRA meses futuros
A55: 0_CONFIG!B46 | B55: Input mensual total Tezamat
A56: 1_Presupuesto cols A,B,C,D | B56: Asignación de rubros por ítem (4 cols input manual)

Sheet 0_Indice_CAC
A1: INDICE CAC
A3: Escala de tiempo | B3: Valores | C3: Previsión | D3: Indice
A4: 45627 | B4: 15356.4 | D4: =$B$4/B4 -> 1
A5: 45658 | B5: 15592.5 | D5: =$B$4/B5 -> 0.9848581
A6: 45689 | B6: 15852.4 | D6: =$B$4/B6 -> 0.96871136
A7: 45717 | B7: 15995.4 | D7: =$B$4/B7 -> 0.96005101
A8: 45748 | B8: 16253.5 | D8: =$B$4/B8 -> 0.94480573
A9: 45778 | B9: 16521.3 | D9: =$B$4/B9 -> 0.92949102
A10: 45809 | B10: 16643.4 | D10: =$B$4/B10 -> 0.92267205
A11: 45839 | B11: 16939.5 | D11: =$B$4/B11 -> 0.90654388
A12: 45870 | B12: 17187.6 | D12: =$B$4/B12 -> 0.89345807
A13: 45901 | B13: 17762.3 | D13: =$B$4/B13 -> 0.8645502
A14: 45931 | B14: 18172.8 | D14: =$B$4/B14 -> 0.84502113
A15: 45962 | B15: 18534.9 | D15: =$B$4/B15 -> 0.8285127
A16: 45992 | B16: 18993.891 | C16: 18993.891 | D16: =$B$4/B16 -> 0.80849152
A17: 46023 | B17: 19331.434 | C17: 19331.434 | D17: =$B$4/B17 -> 0.79437459
A18: 46054 | B18: 19331.434 | D18: =$B$4/B18 -> 0.79437459
A19: 46082 | B19: 19331.434 | D19: =$B$4/B19 -> 0.79437459
A20: 46113 | B20: 19331.434 | D20: =$B$4/B20 -> 0.79437459
A21: 46143 | B21: 19331.434 | D21: =$B$4/B21 -> 0.79437459
A22: 46174 | B22: 19331.434 | D22: =$B$4/B22 -> 0.79437459

Sheet 0_Jornales_MO
A1: SECCIÓN A — TABLA DE TARIFAS POR CATEGORÍA (Costo por Día/Quincena)
A3: PERÍODO | B3: ESPEC. ($/día) | C3: OFICIAL ($/día) | D3: 1/2 OFICIAL ($/día) | E3: AYUDANTE ($/día) | G3: ESPEC. ($/hr) | H3: OFICIAL ($/día) | I3: 1/2 OFICIAL ($/día) | J3: AYUDANTE ($/día)
A4: 45627 | B4: 85927.1 | C4: 76955.08 | D4: 65493.07 | E4: 60860.58 | G4: =+B4/8 -> 10740.888 | H4: =+C4/8 -> 9619.385 | I4: =+D4/8 -> 8186.6337 | J4: =+E4/8 -> 7607.5725
A5: 45658 | B5: 87384 | C5: 78375 | D5: 66853 | E5: 61892 | G5: =+B5/8 -> 10923 | H5: =+C5/8 -> 9796.875 | I5: =+D5/8 -> 8356.625 | J5: =+E5/8 -> 7736.5
A6: 45689 | B6: 89383 | C6: 80395 | D6: 68472 | E6: 63382 | G6: =+B6/8 -> 11172.875 | H6: =+C6/8 -> 10049.375 | I6: =+D6/8 -> 8559 | J6: =+E6/8 -> 7922.75
A7: 45717 | B7: 91464 | C7: 82269 | D7: 70296 | E7: 65595 | G7: =+B7/8 -> 11433 | H7: =+C7/8 -> 10283.625 | I7: =+D7/8 -> 8787 | J7: =+E7/8 -> 8199.375
A8: 45778 | B8: 93235.367 | C8: 83766.388 | D8: 71410.817 | E8: 66568.094 | G8: =+B8/8 -> 11654.421 | H8: =+C8/8 -> 10470.798 | I8: =+D8/8 -> 8926.3521 | J8: =+E8/8 -> 8321.0117
A9: 45809 | B9: 94177.138 | C9: 84612.513 | D9: 72132.138 | E9: 67240.499 | G9: =+B9/8 -> 11772.142 | H9: =+C9/8 -> 10576.564 | I9: =+D9/8 -> 9016.5173 | J9: =+E9/8 -> 8405.0624
A10: 45839 | B10: 95080 | C10: 85425 | D10: 72871 | E10: 67908 | G10: =+B10/8 -> 11885 | H10: =+C10/8 -> 10678.125 | I10: =+D10/8 -> 9108.875 | J10: =+E10/8 -> 8488.5
A11: 45870 | B11: 95889.2 | C11: 86356.18 | D11: 73781.11 | E11: 68935.35 | G11: =+B11/8 -> 11986.15 | H11: =+C11/8 -> 10794.522 | I11: =+D11/8 -> 9222.6388 | J11: =+E11/8 -> 8616.9188
A12: 45901 | B12: 106516.02 | C12: 88649.808 | D12: 75758.192 | E12: 71041.119 | G12: =+B12/8 -> 13314.502 | H12: =+C12/8 -> 11081.226 | I12: =+D12/8 -> 9469.774 | J12: =+E12/8 -> 8880.1398
A13: 45931 | B13: 106864.21 | C13: 88971.073 | D13: 76032.176 | E13: 71292.271 | G13: =+B13/8 -> 13358.026 | H13: =+C13/8 -> 11121.384 | I13: =+D13/8 -> 9504.0221 | J13: =+E13/8 -> 8911.5339
A14: 45962 | B14: 109621.11 | C14: 91252.851 | D14: 77612.118 | E14: 72486.683 | G14: =+B14/8 -> 13702.638 | H14: =+C14/8 -> 11406.606 | I14: =+D14/8 -> 9701.5148 | J14: =+E14/8 -> 9060.8353
A15: 45992 | B15: 113865.18 | C15: 95196.927 | D15: 81356.194 | E15: 76230.759 | G15: =+B15/8 -> 14233.148 | H15: =+C15/8 -> 11899.616 | I15: =+D15/8 -> 10169.524 | J15: =+E15/8 -> 9528.8449
... A21: 46174 | B21: 122445.79 | C21: 102029.07 | D21: 87100.47 | E21: 81453.719 | G21: =+B21/8 -> 15305.724 | H21: =+C21/8 -> 12753.633 | I21: =+D21/8 -> 10887.559 | J21: =+E21/8 -> 10181.715

Sheet 1_Presupuesto
A1: PRESUPUESTO OBRA CIVIL y CERTIFICACIONES DE AVANCE
A3: Rubro MT | B3: Rubro MT/Prov | C3: Rubro MO/OTR | D3: Rubro MO/ALB | E3: Cod. Ítem | F3: Estado | G3: Descripción | H3: U | I3: Cant | J3: MT | K3: MO/OTR | L3: MO/ALB | M3: EQ | N3: Costo Unit. | O3: MT | P3: MO/OTR | Q3: MO/ALB | R3: EQ | S3: P.Unit | T3: Margen | U3: Costo total | V3: PV subtotal | W3: Etapa | X3: Presupuesto | Y3: % Acum Tot
E4: 1 | G4: TAREAS PRELIMINARES | W4: TAREAS PRELIMINARES
A5: - | B5: - | C5: - | D5: - | E5: 1.01 | F5: OK | G5: Limpieza y preparación del terreno - No cotiza | H5: gl | I5: 1 | J5: 0 | K5: 0 | L5: 0 | M5: 0 | N5: =SUM(J5:M5) -> 0 | O5: =IF($N5=0,$S5,J5/$N5*$S5) -> 0 | P5: =IF($N5=0,0,K5/$N5*$S5) -> 0 | Q5: =IF($N5=0,0,L5/$N5*$S5) -> 0 | R5: =IF($N5=0,0,M5/$N5*$S5) -> 0 | S5: 0 | T5: =IFERROR(S5/N5,"") | U5: =N5*I5 -> 0 | V5: =S5*I5 -> 0 | W5: TAREAS PRELIMINARES | X5: PTO 01 | Y5: =SUMIFS(Cert_App_Output!$G:$G,Cert_App_Output!$E:$E,$E5,Cert_App_Output!$K:$K,$X5) -> 0
A6: Preliminares | B6: - | C6: Preliminares | D6: Preliminares | E6: 1.02 | F6: OK | G6: Topógrafo - Visita de obra replanteo | H6: gl | I6: 3 | J6: 25000 | K6: 198736.84 | L6: 60860.581 | M6: 4268.9614 | N6: =SUM(J6:M6) -> 288866.39 | O6: =IF($N6=0,$S6,J6/$N6*$S6) -> 33318.186 | P6: =IF($N6=0,0,K6/$N6*$S6) -> 264862.04 | Q6: =IF($N6=0,0,L6/$N6*$S6) -> 81110.565 | R6: =IF($N6=0,0,M6/$N6*$S6) -> 5689.3619 | S6: 384980.16 | T6: =IFERROR(S6/N6,"") -> 1.3327274 | U6: =N6*I6 -> 866599.16 | V6: =S6*I6 -> 1154940.5 | W6: TAREAS PRELIMINARES | X6: PTO 01 | Y6: =SUMIFS(Cert_App_Output!$G:$G,Cert_App_Output!$E:$E,$E6,Cert_App_Output!$K:$K,$X6) -> 1
A7: - | B7: - | C7: - | D7: - | E7: 1.03 | F7: OK | G7: Cartel de Obra - No cotiza | H7: gl | I7: 1 | J7: 0 | K7: 0 | L7: 0 | M7: 0 | N7: =SUM(J7:M7) -> 0 | O7: =IF($N7=0,$S7,J7/$N7*$S7) -> 0 | P7: =IF($N7=0,0,K7/$N7*$S7) -> 0 | Q7: =IF($N7=0,0,L7/$N7*$S7) -> 0 | R7: =IF($N7=0,0,M7/$N7*$S7) -> 0 | S7: 0 | T7: =IFERROR(S7/N7,"") | U7: =N7*I7 -> 0 | V7: =S7*I7 -> 0 | W7: TAREAS PRELIMINARES | X7: PTO 01 | Y7: =SUMIFS(Cert_App_Output!$G:$G,Cert_App_Output!$E:$E,$E7,Cert_App_Output!$K:$K,$X7) -> 0
A8: Preliminares | B8: - | C8: - | D8: Preliminares | E8: 1.04 | F8: OK | G8: Cerco de obra perimetral - En chapa C25 + Concertina + Porton corredizo | H8: ml | I8: 10 | J8: 88330.703 | K8: 0 | L8: 101654.37 | M8: 2849.776 | N8: =SUM(J8:M8) -> 192834.84 | O8: =IF($N8=0,$S8,J8/$N8*$S8) -> 117720.75 | P8: =IF($N8=0,0,K8/$N8*$S8) -> 0 | Q8: =IF($N8=0,0,L8/$N8*$S8) -> 135477.56 | R8: =IF($N8=0,0,M8/$N8*$S8) -> 3797.9747 | S8: 256996.29 | T8: =IFERROR(S8/N8,"") -> 1.3327274 | U8: =N8*I8 -> 1928348.4 | V8: =S8*I8 -> 2569962.9 | W8: TAREAS PRELIMINARES | X8: PTO 01 | Y8: =SUMIFS(Cert_App_Output!$G:$G,Cert_App_Output!$E:$E,$E8,Cert_App_Output!$K:$K,$X8) -> 1
A9: Preliminares | B9: - | C9: Preliminares | D9: Preliminares | E9: 1.05 | F9: OK | G9: Obrador, pañol y ducha. | H9: gl | I9: 1 | J9: 2078824.7 | K9: 750000 | L9: 4424962.9 | M9: 108806.81 | N9: =SUM(J9:M9) -> 7362594.4 | O9: =IF($N9=0,$S9,J9/$N9*$S9) -> 2770506.7 | P9: =IF($N9=0,0,K9/$N9*$S9) -> 999545.57 | Q9: =IF($N9=0,0,L9/$N9*$S9) -> 5897269.4 | R9: =IF($N9=0,0,M9/$N9*$S9) -> 145009.82 | S9: 9812331.4 | T9: =IFERROR(S9/N9,"") -> 1.3327274 | U9: =N9*I9 -> 7362594.4 | V9: =S9*I9 -> 9812331.4 | W9: TAREAS PRELIMINARES | X9: PTO 01 | Y9: =SUMIFS(Cert_App_Output!$G:$G,Cert_App_Output!$E:$E,$E9,Cert_App_Output!$K:$K,$X9) -> 1
A10: Gastos Generales | B10: - | C10: Gastos Generales | D10: Preliminares | E10: 1.06 | F10: OK | G10: Alquiler de baños quimicos y duchas portatiles | H10: mes | I10: 4 | J10: 0 | K10: 318994.12 | L10: 13291.422 | M10: 0 | N10: =SUM(J10:M10) -> 332285.54 | O10: =IF($N10=0,$S10,J10/$N10*$S10) -> 0 | P10: =IF($N10=0,0,K10/$N10*$S10) -> 425132.21 | Q10: =IF($N10=0,0,L10/$N10*$S10) -> 17713.842 | R10: =IF($N10=0,0,M10/$N10*$S10) -> 0 | S10: 442846.06 | T10: =IFERROR(S10/N10,"") -> 1.3327274 | U10: =N10*I10 -> 1329142.2 | V10: =S10*I10 -> 1771384.2 | W10: TAREAS PRELIMINARES | X10: PTO 01 | Y10: =SUMIFS(Cert_App_Output!$G:$G,Cert_App_Output!$E:$E,$E10,Cert_App_Output!$K:$K,$X10) -> 1
A11: Preliminares | B11: - | C11: - | D11: Preliminares | E11: 1.07 | F11: OK | G11: Conexión pilar y luz de obra + Tablero de obra | H11: gl | I11: 1 | J11: 1090000 | K11: 0 | L11: 601395.67 | M11: 25370.935 | N11: =SUM(J11:M11) -> 1716766.6 | O11: =IF($N11=0,$S11,J11/$N11*$S11) -> 1452672.9 | P11: =IF($N11=0,0,K11/$N11*$S11) -> 0 | Q11: =IF($N11=0,0,L11/$N11*$S11) -> 801496.51 | R11: =IF($N11=0,0,M11/$N11*$S11) -> 33812.541 | S11: 2287981.9 | T11: =IFERROR(S11/N11,"") -> 1.3327274 | U11: =N11*I11 -> 1716766.6 | V11: =S11*I11 -> 2287981.9 | W11: TAREAS PRELIMINARES | X11: PTO 01 | Y11: =SUMIFS(Cert_App_Output!$G:$G,Cert_App_Output!$E:$E,$E11,Cert_App_Output!$K:$K,$X11) -> 1
A12: Preliminares | B12: - | C12: - | D12: Preliminares | E12: 1.08 | F12: OK | G12: Conexión agua de obra, tanque + bomba | H12: gl | I12: 1 | J12: 685200 | K12: 0 | L12: 651528.71 | M12: 20050.931 | N12: =SUM(J12:M12) -> 1356779.6 | O12: =IF($N12=0,$S12,J12/$N12*$S12) -> 913184.83 | P12: =IF($N12=0,0,K12/$N12*$S12) -> 0 | Q12: =IF($N12=0,0,L12/$N12*$S12) -> 868310.18 | R12: =IF($N12=0,0,M12/$N12*$S12) -> 26722.425 | S12: 1808217.4 | T12: =IFERROR(S12/N12,"") -> 1.3327274 | U12: =N12*I12 -> 1356779.6 | V12: =S12*I12 -> 1808217.4 | W12: TAREAS PRELIMINARES | X12: PTO 01 | Y12: =SUMIFS(Cert_App_Output!$G:$G,Cert_App_Output!$E:$E,$E12,Cert_App_Output!$K:$K,$X12) -> 1
A13: Preliminares | B13: - | C13: Preliminares | D13: - | E13: 1.09 | F13: OK | G13: Tramite luz de obra, certificado luz de obra (2) y medición PAT | H13: gl | I13: 1 | J13: 0 | K13: 362691.09 | L13: 0 | M13: 0 | N13: =SUM(J13:M13) -> 362691.09 | O13: =IF($N13=0,$S13,J13/$N13*$S13) -> 0 | P13: =IF($N13=0,0,K13/$N13*$S13) -> 483368.36 | Q13: =IF($N13=0,0,L13/$N13*$S13) -> 0 | R13: =IF($N13=0,0,M13/$N13*$S13) -> 0 | S13: 483368.36 | T13: =IFERROR(S13/N13,"") -> 1.3327274 | U13: =N13*I13 -> 362691.09 | V13: =S13*I13 -> 483368.36 | W13: TAREAS PRELIMINARES | X13: PTO 01 | Y13: =SUMIFS(Cert_App_Output!$G:$G,Cert_App_Output!$E:$E,$E13,Cert_App_Output!$K:$K,$X13) -> 1
A14: - | B14: - | C14: - | D14: - | E14: 2 | G14: MOVIMIENTO DE TIERRA, COMPACTACION Y RELLENO | W14: MOVIMIENTO DE TIERRA, COMPACTACION Y RELLENO | X14: PTO 01
A15: Movimiento de Suelos | B15: - | C15: Movimiento de Suelos | D15: Homigón MO | E15: 2.01 | F15: OK | G15: Excavación a maquina para submuración, subsuelo y fundaciones | H15: m3 | I15: 308 | J15: 0 | K15: 33000 | L15: 6520.7765 | M15: 97.811648 | N15: =SUM(J15:M15) -> 39618.588 | O15: =IF($N15=0,$S15,J15/$N15*$S15) -> 0 | P15: =IF($N15=0,0,K15/$N15*$S15) -> 43980.005 | Q15: =IF($N15=0,0,L15/$N15*$S15) -> 8690.4177 | R15: =IF($N15=0,0,M15/$N15*$S15) -> 130.35627 | S15: 52800.779 | T15: =IFERROR(S15/N15,"") -> 1.3327274 | U15: =N15*I15 -> 12202525 | V15: =S15*I15 -> 16262640 | W15: MOVIMIENTO DE TIERRA, COMPACTACION Y RELLENO | X15: PTO 01 | Y15: =SUMIFS(Cert_App_Output!$G:$G,Cert_App_Output!$E:$E,$E15,Cert_App_Output!$K:$K,$X15) -> 1
A16: Movimiento de Suelos | B16: - | C16: Movimiento de Suelos | D16: Preliminares | E16: 2.02 | F16: OK | G16: Perfilado manual de bases. Relleno y compactación de pozos | H16: gl | I16: 1 | J16: 105000 | K16: 455000 | L16: 8033596.7 | M16: 128903.95 | N16: =SUM(J16:M16) -> 8722500.6 | O16: =IF($N16=0,$S16,J16/$N16*$S16) -> 139936.38 | P16: =IF($N16=0,0,K16/$N16*$S16) -> 606390.98 | Q16: =IF($N16=0,0,L16/$N16*$S16) -> 10706595 | R16: =IF($N16=0,0,M16/$N16*$S16) -> 171793.83 | S16: 11624716 | T16: =IFERROR(S16/N16,"") -> 1.3327274 | U16: =N16*I16 -> 8722500.6 | V16: =S16*I16 -> 11624716 | W16: MOVIMIENTO DE TIERRA, COMPACTACION Y RELLENO | X16: PTO 01 | Y16: =SUMIFS(Cert_App_Output!$G:$G,Cert_App_Output!$E:$E,$E16,Cert_App_Output!$K:$K,$X16) -> 1
A17: Movimiento de Suelos | B17: - | C17: - | D17: Preliminares | E17: 2.03 | F17: OK | G17: Excavación manual para vigas de fundación | H17: m3 | I17: 15 | J17: 26000 | K17: 0 | L17: 60860.581 | M17: 1302.9087 | N17: =SUM(J17:M17) -> 88163.489 | O17: =IF($N17=0,$S17,J17/$N17*$S17) -> 34650.913 | P17: =IF($N17=0,0,K17/$N17*$S17) -> 0 | Q17: =IF($N17=0,0,L17/$N17*$S17) -> 81110.565 | R17: =IF($N17=0,0,M17/$N17*$S17) -> 1736.4222 | S17: 117497.9 | T17: =IFERROR(S17/N17,"") -> 1.3327274 | U17: =N17*I17 -> 1322452.3 | V17: =S17*I17 -> 1762468.5 | W17: MOVIMIENTO DE TIERRA, COMPACTACION Y RELLENO | X17: PTO 01 | Y17: =SUMIFS(Cert_App_Output!$G:$G,Cert_App_Output!$E:$E,$E17,Cert_App_Output!$K:$K,$X17) -> 1
A18: - | B18: - | C18: - | D18: - | E18: 2.04 | F18: IN | G18: Aporte y compactación de suelo seleccionado, e: 40 cm (2 capas de 20 cm) - Cotizado Hº Pobre en item 8,02 | H18: m2 | I18: 0 | J18: 0 | K18: 0 | L18: 0 | M18: 0 | N18: =SUM(J18:M18) -> 0 | O18: =IF($N18=0,$S18,J18/$N18*$S18) -> 0 | P18: =IF($N18=0,0,K18/$N18*$S18) -> 0 | Q18: =IF($N18=0,0,L18/$N18*$S18) -> 0 | R18: =IF($N18=0,0,M18/$N18*$S18) -> 0 | S18: 0 | T18: =IFERROR(S18/N18,"") | U18: =N18*I18 -> 0 | V18: =S18*I18 -> 0 | W18: MOVIMIENTO DE TIERRA, COMPACTACION Y RELLENO | X18: PTO 01 | Y18: =SUMIFS(Cert_App_Output!$G:$G,Cert_App_Output!$E:$E,$E18,Cert_App_Output!$K:$K,$X18) -> 0
A19: - | B19: - | C19: - | D19: - | E19: 2.05 | F19: OK | G19: Demolición de bases existentes - No cotiza | H19: gl | I19: 0 | J19: 0 | K19: 0 | L19: 0 | M19: 0 | N19: =SUM(J19:M19) -> 0 | O19: =IF($N19=0,$S19,J19/$N19*$S19) -> 0 | P19: =IF($N19=0,0,K19/$N19*$S19) -> 0 | Q19: =IF($N19=0,0,L19/$N19*$S19) -> 0 | R19: =IF($N19=0,0,M19/$N19*$S19) -> 0 | S19: 0 | T19: =IFERROR(S19/N19,"") | U19: =N19*I19 -> 0 | V19: =S19*I19 -> 0 | W19: MOVIMIENTO DE TIERRA, COMPACTACION Y RELLENO | X19: PTO 01 | Y19: =SUMIFS(Cert_App_Output!$G:$G,Cert_App_Output!$E:$E,$E19,Cert_App_Output!$K:$K,$X19) -> 0
A20: - | B20: - | C20: - | D20: - | E20: 3 | G20: ESTRUCTURA RESISTENTE | W20: ESTRUCTURA RESISTENTE | X20: PTO 01
A21: Hormigón MT | B21: - | C21: - | D21: Homigón MO | E21: 3.01 | F21: OK | G21: Hormigón de limpieza - e: 10 cm | H21: m3 | I21: 13 | J21: 115100 | K21: 0 | L21: 101603.58 | M21: 3250.5537 | N21: =SUM(J21:M21) -> 219954.14 | O21: =IF($N21=0,$S21,J21/$N21*$S21) -> 153396.93 | P21: =IF($N21=0,0,K21/$N21*$S21) -> 0 | Q21: =IF($N21=0,0,L21/$N21*$S21) -> 135409.88 | R21: =IF($N21=0,0,M21/$N21*$S21) -> 4332.1021 | S21: 293138.91 | T21: =IFERROR(S21/N21,"") -> 1.3327274 | U21: =N21*I21 -> 2859403.8 | V21: =S21*I21 -> 3810805.8 | W21: ESTRUCTURA RESISTENTE | X21: PTO 01 | Y21: =SUMIFS(Cert_App_Output!$G:$G,Cert_App_Output!$E:$E,$E21,Cert_App_Output!$K:$K,$X21) -> 1
A22: Hormigón MT | B22: - | C22: Homigón MO | D22: - | E22: 3.02 | F22: OK | G22: Pilotes de tracción Ø 20 cm - (120 kg/m3 de hierro) | H22: u | I22: 18 | J22: 90570.796 | K22: 250000 | L22: 0 | M22: 5108.5619 | N22: =SUM(J22:M22) -> 345679.36 | O22: =IF($N22=0,$S22,J22/$N22*$S22) -> 120706.18 | P22: =IF($N22=0,0,K22/$N22*$S22) -> 333181.86 | Q22: =IF($N22=0,0,L22/$N22*$S22) -> 0 | R22: =IF($N22=0,0,M22/$N22*$S22) -> 6808.3206 | S22: 460696.36 | T22: =IFERROR(S22/N22,"") -> 1.3327274 | U22: =N22*I22 -> 6222228.4 | V22: =S22*I22 -> 8292534.5 | W22: ESTRUCTURA RESISTENTE | X22: PTO 01 | Y22: =SUMIFS(Cert_App_Output!$G:$G,Cert_App_Output!$E:$E,$E22,Cert_App_Output!$K:$K,$X22) -> 1
A23: Hormigón MT | B23: - | C23: Homigón MO | D23: - | E23: 3.03 | F23: OK | G23: Tabique submuración - H35 (95 kg/m3 de hierro) | H23: m3 | I23: 12 | J23: 402072.54 | K23: 357640.9 | L23: 0 | M23: 11395.702 | N23: =SUM(J23:M23) -> 771109.14 | O23: =IF($N23=0,$S23,J23/$N23*$S23) -> 535853.1 | P23: =IF($N23=0,0,K23/$N23*$S23) -> 476637.84 | Q23: =IF($N23=0,0,L23/$N23*$S23) -> 0 | R23: =IF($N23=0,0,M23/$N23*$S23) -> 15187.364 | S23: 1027678.3 | T23: =IFERROR(S23/N23,"") -> 1.3327274 | U23: =N23*I23 -> 9253309.7 | V23: =S23*I23 -> 12332140 | W23: ESTRUCTURA RESISTENTE | X23: PTO 01 | Y23: =SUMIFS(Cert_App_Output!$G:$G,Cert_App_Output!$E:$E,$E23,Cert_App_Output!$K:$K,$X23) -> 1
A24: Hormigón MT | B24: - | C24: Homigón MO | D24: - | E24: 3.04 | F24: OK | G24: Zapata corrida tabique - H35 (120 kg/m3 de hierro) | H24: m3 | I24: 7 | J24: 428196.58 | K24: 281633.96 | L24: 0 | M24: 10647.458 | N24: =SUM(J24:M24) -> 720478 | O24: =IF($N24=0,$S24,J24/$N24*$S24) -> 570669.33 | P24: =IF($N24=0,0,K24/$N24*$S24) -> 375341.31 | Q24: =IF($N24=0,0,L24/$N24*$S24) -> 0 | R24: =IF($N24=0,0,M24/$N24*$S24) -> 14190.159 | S24: 960200.79 | T24: =IFERROR(S24/N24,"") -> 1.3327274 | U24: =N24*I24 -> 5043346 | V24: =S24*I24 -> 6721405.5 | W24: ESTRUCTURA RESISTENTE | X24: PTO 01 | Y24: =SUMIFS(Cert_App_Output!$G:$G,Cert_App_Output!$E:$E,$E24,Cert_App_Output!$K:$K,$X24) -> 1
A25: Hormigón MT | B25: - | C25: Homigón MO | D25: - | E25: 3.05 | F25: OK | G25: Platea - H35 (95 kg/m3 de hierro) | H25: m3 | I25: 38 | J25: 333700.51 | K25: 194327.43 | L25: 0 | M25: 7920.4191 | N25: =SUM(J25:M25) -> 535948.36 | O25: =IF($N25=0,$S25,J25/$N25*$S25) -> 444731.82 | P25: =IF($N25=0,0,K25/$N25*$S25) -> 258985.5 | Q25: =IF($N25=0,0,L25/$N25*$S25) -> 0 | R25: =IF($N25=0,0,M25/$N25*$S25) -> 10555.76 | S25: 714273.08 | T25: =IFERROR(S25/N25,"") -> 1.3327274 | U25: =N25*I25 -> 20366038 | V25: =S25*I25 -> 27142377 | W25: ESTRUCTURA RESISTENTE | X25: PTO 01 | Y25: =SUMIFS(Cert_App_Output!$G:$G,Cert_App_Output!$E:$E,$E25,Cert_App_Output!$K:$K,$X25) -> 1
A26: Hormigón MT | B26: - | C26: Homigón MO | D26: - | E26: 3.06 | F26: OK | G26: Bases aisladas - (60 kg/m3 de hierro) | H26: m3 | I26: 51 | J26: 275042.38 | K26: 194327.43 | L26: 0 | M26: 7040.5472 | N26: =SUM(J26:M26) -> 476410.36 | O26: =IF($N26=0,$S26,J26/$N26*$S26) -> 366556.52 | P26: =IF($N26=0,0,K26/$N26*$S26) -> 258985.5 | Q26: =IF($N26=0,0,L26/$N26*$S26) -> 0 | R26: =IF($N26=0,0,M26/$N26*$S26) -> 9383.1303 | S26: 634925.15 | T26: =IFERROR(S26/N26,"") -> 1.3327274 | U26: =N26*I26 -> 24296928 | V26: =S26*I26 -> 32381183 | W26: ESTRUCTURA RESISTENTE | X26: PTO 01 | Y26: =SUMIFS(Cert_App_Output!$G:$G,Cert_App_Output!$E:$E,$E26,Cert_App_Output!$K:$K,$X26) -> 1
A27: Hormigón MT | B27: - | C27: Homigón MO | D27: - | E27: 3.07 | F27: OK | G27: Troncos de columnas - H35 (240 kg/m3 de hierro) | H27: m3 | I27: 16 | J27: 635192.72 | K27: 317914.05 | L27: 0 | M27: 14296.601 | N27: =SUM(J27:M27) -> 967403.37 | O27: =IF($N27=0,$S27,J27/$N27*$S27) -> 846538.76 | P27: =IF($N27=0,0,K27/$N27*$S27) -> 423692.77 | Q27: =IF($N27=0,0,L27/$N27*$S27) -> 0 | R27: =IF($N27=0,0,M27/$N27*$S27) -> 19053.473 | S27: 1289285 | T27: =IFERROR(S27/N27,"") -> 1.3327274 | U27: =N27*I27 -> 15478454 | V27: =S27*I27 -> 20628560 | W27: ESTRUCTURA RESISTENTE | X27: PTO 01 | Y27: =SUMIFS(Cert_App_Output!$G:$G,Cert_App_Output!$E:$E,$E27,Cert_App_Output!$K:$K,$X27) -> 1
A28: Hormigón MT | B28: - | C28: Homigón MO | D28: - | E28: 3.08 | F28: OK | G28: Viga de encadenado - H35 (180 kg/m3 de hierro) | H28: m3 | I28: 7 | J28: 528753.37 | K28: 281633.96 | L28: 0 | M28: 12155.81 | N28: =SUM(J28:M28) -> 822543.14 | O28: =IF($N28=0,$S28,J28/$N28*$S28) -> 704684.12 | P28: =IF($N28=0,0,K28/$N28*$S28) -> 375341.31 | Q28: =IF($N28=0,0,L28/$N28*$S28) -> 0 | R28: =IF($N28=0,0,M28/$N28*$S28) -> 16200.381 | S28: 1096225.8 | T28: =IFERROR(S28/N28,"") -> 1.3327274 | U28: =N28*I28 -> 5757802 | V28: =S28*I28 -> 7673580.6 | W28: ESTRUCTURA RESISTENTE | X28: PTO 01 | Y28: =SUMIFS(Cert_App_Output!$G:$G,Cert_App_Output!$E:$E,$E28,Cert_App_Output!$K:$K,$X28) -> 1
A29: Hormigón MT | B29: - | C29: Homigón MO | D29: - | E29: 3.09 | F29: OK | G29: Losa maciza - H35 (100 kg/m3 de hierro) | H29: m3 | I29: 90 | J29: 372584.33 | K29: 221790.79 | L29: 0 | M29: 8915.6269 | N29: =SUM(J29:M29) -> 603290.75 | O29: =IF($N29=0,$S29,J29/$N29*$S29) -> 496553.36 | P29: =IF($N29=0,0,K29/$N29*$S29) -> 295586.68 | Q29: =IF($N29=0,0,L29/$N29*$S29) -> 0 | R29: =IF($N29=0,0,M29/$N29*$S29) -> 11882.1 | S29: 804022.13 | T29: =IFERROR(S29/N29,"") -> 1.3327274 | U29: =N29*I29 -> 54296168 | V29: =S29*I29 -> 72361992 | W29: ESTRUCTURA RESISTENTE | X29: PTO 01 | Y29: =SUMIFS(Cert_App_Output!$G:$G,Cert_App_Output!$E:$E,$E29,Cert_App_Output!$K:$K,$X29) -> 1
A30: Hormigón MT | B30: - | C30: Homigón MO | D30: Homigón MO | E30: 3.1 | F30: OK | G30: Losa maciza de Hº visto - H35 (100 kg/m3 de hierro) | H30: m3 | I30: 32 | J30: 379758.83 | K30: 221790.79 | L30: 55447.699 | M30: 9854.9599 | N30: =SUM(J30:M30) -> 666852.29 | O30: =IF($N30=0,$S30,J30/$N30*$S30) -> 506115.01 | P30: =IF($N30=0,0,K30/$N30*$S30) -> 295586.68 | Q30: =IF($N30=0,0,L30/$N30*$S30) -> 73896.669 | R30: =IF($N30=0,0,M30/$N30*$S30) -> 13133.975 | S30: 888732.33 | T30: =IFERROR(S30/N30,"") -> 1.3327274 | U30: =N30*I30 -> 21339273 | V30: =S30*I30 -> 28439435 | W30: ESTRUCTURA RESISTENTE | X30: PTO 01 | Y30: =SUMIFS(Cert_App_Output!$G:$G,Cert_App_Output!$E:$E,$E30,Cert_App_Output!$K:$K,$X30) -> 1
A31: Hormigón MT | B31: - | C31: Homigón MO | D31: - | E31: 3.11 | F31: OK | G31: Vigas - H35 (180 kg/m3 de hierro) | H31: m3 | I31: 46 | J31: 567913.51 | K31: 537036.81 | L31: 0 | M31: 16574.255 | N31: =SUM(J31:M31) -> 1121524.6 | O31: =IF($N31=0,$S31,J31/$N31*$S31) -> 756873.91 | P31: =IF($N31=0,0,K31/$N31*$S31) -> 715723.68 | Q31: =IF($N31=0,0,L31/$N31*$S31) -> 0 | R31: =IF($N31=0,0,M31/$N31*$S31) -> 22088.964 | S31: 1494686.6 | T31: =IFERROR(S31/N31,"") -> 1.3327274 | U31: =N31*I31 -> 51590130 | V31: =S31*I31 -> 68755581 | W31: ESTRUCTURA RESISTENTE | X31: PTO 01 | Y31: =SUMIFS(Cert_App_Output!$G:$G,Cert_App_Output!$E:$E,$E31,Cert_App_Output!$K:$K,$X31) -> 1
A32: Hormigón MT | B32: - | C32: Homigón MO | D32: Homigón MO | E32: 3.12 | F32: OK | G32: Vigas de H° visto - H35 (180 kg/m3 de hierro) | H32: m3 | I32: 31 | J32: 565756.87 | K32: 537036.81 | L32: 134259.2 | M32: 18555.793 | N32: =SUM(J32:M32) -> 1255608.7 | O32: =IF($N32=0,$S32,J32/$N32*$S32) -> 753999.69 | P32: =IF($N32=0,0,K32/$N32*$S32) -> 715723.68 | Q32: =IF($N32=0,0,L32/$N32*$S32) -> 178930.92 | R32: =IF($N32=0,0,M32/$N32*$S32) -> 24729.814 | S32: 1673384.1 | T32: =IFERROR(S32/N32,"") -> 1.3327274 | U32: =N32*I32 -> 38923869 | V32: =S32*I32 -> 51874907 | W32: ESTRUCTURA RESISTENTE | X32: PTO 01 | Y32: =SUMIFS(Cert_App_Output!$G:$G,Cert_App_Output!$E:$E,$E32,Cert_App_Output!$K:$K,$X32) -> 1
... A41: Hormigón MT | B41: - | C41: - | D41: Homigón MO | E41: 3.22 | F41: OK | G41: Picado de medianeras para columnas y vigas - Cotizado para PB y 1P | H41: m2 | I41: 78 | J41: 7051.2821 | K41: 0 | L41: 17829.919 | M41: 373.21802 | N41: =SUM(J41:M41) -> 25254.419 | O41: =IF($N41=0,$S41,J41/$N41*$S41) -> 9397.437 | P41: =IF($N41=0,0,K41/$N41*$S41) -> 0 | Q41: =IF($N41=0,0,L41/$N41*$S41) -> 23762.422 | R41: =IF($N41=0,0,M41/$N41*$S41) -> 497.39789 | S41: 33657.257 | T41: =IFERROR(S41/N41,"") -> 1.3327274 | U41: =N41*I41 -> 1969844.7 | V41: =S41*I41 -> 2625266.1 | W41: ESTRUCTURA RESISTENTE | X41: PTO 01 | Y41: =SUMIFS(Cert_App_Output!$G:$G,Cert_App_Output!$E:$E,$E41,Cert_App_Output!$K:$K,$X41) -> 1
A42: - | B42: - | C42: - | D42: - | E42: 4 | G42: MAMPOSTERÍA | W42: MAMPOSTERÍA | X42: PTO 02
A43: Albañilería MT | B43: - | C43: - | D43: Albañilería MO | E43: 4.01 | F43: OK | G43: Muro tipo 1 - Ladrillo hueco 8 x 18 x 33 | H43: m2 | I43: 621 | J43: 10253.952 | K43: 0 | L43: 16311.975 | M43: 365.95526 | N43: =SUM(J43:M43) -> 26931.882 | O43: =IF($N43=0,$S43,J43/$N43*$S43) -> 13665.723 | P43: =IF($N43=0,0,K43/$N43*$S43) -> 0 | Q43: =IF($N43=0,0,L43/$N43*$S43) -> 21739.416 | R43: =IF($N43=0,0,M43/$N43*$S43) -> 487.71862 | S43: 35892.858 | T43: =IFERROR(S43/N43,"") -> 1.3327274 | U43: =N43*I43 -> 16724699 | V43: =S43*I43 -> 22289465 | W43: MAMPOSTERÍA | X43: PTO 02 | Y43: =SUMIFS(Cert_App_Output!$G:$G,Cert_App_Output!$E:$E,$E43,Cert_App_Output!$K:$K,$X43) -> 0.93
A44: Albañilería MT | B44: - | C44: - | D44: Albañilería MO | E44: 4.02 | F44: OK | G44: Muro tipo 2 - Ladrillo hueco 12 x 18 x 33 | H44: m2 | I44: 780 | J44: 8314.4981 | K44: 0 | L44: 9785.8452 | M44: 235.33191 | N44: =SUM(J44:M44) -> 18335.675 | O44: =IF($N44=0,$S44,J44/$N44*$S44) -> 11080.96 | P44: =IF($N44=0,0,K44/$N44*$S44) -> 0 | Q44: =IF($N44=0,0,L44/$N44*$S44) -> 13041.864 | R44: =IF($N44=0,0,M44/$N44*$S44) -> 313.63329 | S44: 24436.457 | T44: =IFERROR(S44/N44,"") -> 1.3327274 | U44: =N44*I44 -> 14301827 | V44: =S44*I44 -> 19060437 | W44: MAMPOSTERÍA | X44: PTO 02 | Y44: =SUMIFS(Cert_App_Output!$G:$G,Cert_App_Output!$E:$E,$E44,Cert_App_Output!$K:$K,$X44) -> 0.94
A45: Albañilería MT | B45: - | C45: - | D45: Albañilería MO | E45: 4.03 | F45: OK | G45: Muro tipo 3 - Ladrillo comun en panderete | H45: m2 | I45: 56 | J45: 6454.6901 | K45: 0 | L45: 10484.834 | M45: 504.28267 | N45: =SUM(J45:M45) -> 17443.807 | O45: =IF($N45=0,$S45,J45/$N45*$S45) -> 8602.3426 | P45: =IF($N45=0,0,K45/$N45*$S45) -> 0 | Q45: =IF($N45=0,0,L45/$N45*$S45) -> 13973.426 | R45: =IF($N45=0,0,M45/$N45*$S45) -> 672.07134 | S45: 23247.84 | T45: =IFERROR(S45/N45,"") -> 1.3327274 | U45: =N45*I45 -> 976853.19 | V45: =S45*I45 -> 1301879 | W45: MAMPOSTERÍA | X45: PTO 02 | Y45: =SUMIFS(Cert_App_Output!$G:$G,Cert_App_Output!$E:$E,$E45,Cert_App_Output!$K:$K,$X45) -> 1
A46: Albañilería MT | B46: - | C46: - | D46: Albañilería MO | E46: 4.04 | F46: OK | G46: Muro tipo 4 - Ladrillo hueco portante 12 x 18 x 33 | H46: m2 | I46: 42 | J46: 11547.894 | K46: 0 | L46: 9785.8452 | M46: 235.33191 | N46: =SUM(J46:M46) -> 21569.071 | O46: =IF($N46=0,$S46,J46/$N46*$S46) -> 15390.195 | P46: =IF($N46=0,0,K46/$N46*$S46) -> 0 | Q46: =IF($N46=0,0,L46/$N46*$S46) -> 13041.864 | R46: =IF($N46=0,0,M46/$N46*$S46) -> 313.63329 | S46: 28745.692 | T46: =IFERROR(S46/N46,"") -> 1.3327274 | U46: =N46*I46 -> 905900.98 | V46: =S46*I46 -> 1207319.1 | W46: MAMPOSTERÍA | X46: PTO 02 | Y46: =SUMIFS(Cert_App_Output!$G:$G,Cert_App_Output!$E:$E,$E46,Cert_App_Output!$K:$K,$X46) -> 0.95
A47: Albañilería MT | B47: - | C47: - | D47: Albañilería MO | E47: 4.05 | F47: IN | G47: Muro tipo 5 - Bloque HCCA e: 7,5 cm | H47: m2 | I47: 70 | J47: 16817.941 | K47: 0 | L47: 10484.834 | M47: 409.54162 | N47: =SUM(J47:M47) -> 27712.316 | O47: =IF($N47=0,$S47,J47/$N47*$S47) -> 22413.731 | P47: =IF($N47=0,0,K47/$N47*$S47) -> 0 | Q47: =IF($N47=0,0,L47/$N47*$S47) -> 13973.426 | R47: =IF($N47=0,0,M47/$N47*$S47) -> 545.80735 | S47: 36932.964 | T47: =IFERROR(S47/N47,"") -> 1.3327274 | U47: =N47*I47 -> 1939862.2 | V47: =S47*I47 -> 2585307.5 | W47: MAMPOSTERÍA | X47: PTO 02 | Y47: =SUMIFS(Cert_App_Output!$G:$G,Cert_App_Output!$E:$E,$E47,Cert_App_Output!$K:$K,$X47) -> 0.8
A48: Albañilería MT | B48: - | C48: - | D48: Albañilería MO | E48: 4.06 | F48: OK | G48: Muro tipo 6 - Ladrillo hueco 18 x 18 x 33 | H48: m2 | I48: 5 | J48: 11492.44 | K48: 0 | L48: 9785.8452 | M48: 235.33191 | N48: =SUM(J48:M48) -> 21513.617 | O48: =IF($N48=0,$S48,J48/$N48*$S48) -> 15316.29 | P48: =IF($N48=0,0,K48/$N48*$S48) -> 0 | Q48: =IF($N48=0,0,L48/$N48*$S48) -> 13041.864 | R48: =IF($N48=0,0,M48/$N48*$S48) -> 313.63329 | S48: 28671.788 | T48: =IFERROR(S48/N48,"") -> 1.3327274 | U48: =N48*I48 -> 107568.09 | V48: =S48*I48 -> 143358.94 | W48: MAMPOSTERÍA | X48: PTO 02 | Y48: =SUMIFS(Cert_App_Output!$G:$G,Cert_App_Output!$E:$E,$E48,Cert_App_Output!$K:$K,$X48) -> 1
A49: Albañilería MT | B49: - | C49: - | D49: Albañilería MO | E49: 4.07 | F49: OK | G49: Enchape de medianeras existentes - Contemplamos picado zonas sueltas y enchape con ladrillo comun para PB | H49: m2 | I49: 193 | J49: 3227.3451 | K49: 0 | L49: 10484.834 | M49: 252.14133 | N49: =SUM(J49:M49) -> 13964.321 | O49: =IF($N49=0,$S49,J49/$N49*$S49) -> 4301.1713 | P49: =IF($N49=0,0,K49/$N49*$S49) -> 0 | Q49: =IF($N49=0,0,L49/$N49*$S49) -> 13973.426 | R49: =IF($N49=0,0,M49/$N49*$S49) -> 336.03567 | S49: 18610.633 | T49: =IFERROR(S49/N49,"") -> 1.3327274 | U49: =N49*I49 -> 2695113.9 | V49: =S49*I49 -> 3591852.2 | W49: MAMPOSTERÍA | X49: PTO 02 | Y49: =SUMIFS(Cert_App_Output!$G:$G,Cert_App_Output!$E:$E,$E49,Cert_App_Output!$K:$K,$X49) -> 0.1
...

Sheet 1_GGBB
H2: 45679 | O2: 26
F3: MESES | G3: DÓLAR BNA | H3: DÓLAR MEP | M3: Descrip | N3: Mes | O3: Total Dias
B4: GASTOS GENERALES y BENEFICIO | F4: =+ROUNDUP(N17,0) -> 17 | G4: 1066.5 | H4: 1170 | M4: Prelim | N4: 1 | O4: =+N4*$O$2 -> 26 | Q4: Syh permanente
M5: Mov de suelos y excav. | N5: 2.5 | O5: =+N5*$O$2 -> 65 | Q5: =+ROUNDUP(SUM(N4:N5),0) -> 4
B6: Gastos Grales de obra en items | C6: U | D6: Cant | F6: Precio Unit | G6: Subtotal | H6: =SUM(G7:G10) -> 0 | M6: Losa sobre PB | N6: 1 | O6: =+N6*$O$2 -> 26
B7: Oficina en obra (6x3 c/AA) | C7: mes | D7: =+$F$4 -> 17 | E7: 0 | F7: =E7*I7+J7 -> 0 | G7: =+F7*D7*E7 -> 0 | M7: Losa sobre 1 | N7: 0.75 | O7: =+N7*$O$2 -> 19.5
B8: Obrador 6x3 s/AA | C8: mes | D8: =+$F$4 -> 17 | E8: 0 | F8: =E8*I8+J8 -> 0 | G8: =+F8*D8*E8 -> 0 | M8: Losa sobre 2 | N8: 0.75 | O8: =+N8*$O$2 -> 19.5
B9: Pañol (6x3) | C9: mes | D9: =+$F$4 -> 17 | E9: 1 | F9: =E9*I9+J9 -> 0 | G9: =+F9*D9*E9 -> 0 | M9: Losa sobre 3 | N9: 0.75 | O9: =+N9*$O$2 -> 19.5 | P9: Inicio mamposteria
B10: Baños | C10: mes | D10: =+$F$4 -> 17 | E10: 2 | F10: =E10*I10+J10 -> 0 | G10: =+F10*D10*E10 -> 0 | M10: Losa sobre 4 | N10: 0.75 | O10: =+N10*$O$2 -> 19.5
B11: Gastos Grales de obra en items | H11: =SUM(G12:G19) -> 32379395 | M11: Losa sobre SM | N11: 0.5 | O11: =+N11*$O$2 -> 13 | Q11: Meses H° | R11: Estacionamiento en contramano
B12: HyS permanente | C12: mes | D12: =+Q5 -> 4 | E12: 1 | J12: 1504670.3 | K12: =+J12*D12*E12 -> 6018681.2 | M12: Mampostería | N12: 2 | O12: =+N12*$O$2 -> 52 | Q12: =+SUM(N5:N11) -> 7 | R12: =+ROUNDUP(Q12/3,0) -> 3
B13: HyS | C13: mes | D13: =+$F$4 -> 17 | E13: 1 | J13: 150000 | K13: =+J13*D13*E13 -> 2550000 | M13: Revoques, contrap y carp | N13: 2 | O13: =+N13*$O$2 -> 52
B14: Energía de obra | C14: mes | D14: =+$F$4 -> 17 | E14: 0.5 | F14: 200000 | G14: =+F14*D14*E14 -> 1700000 | M14: Colocación | N14: 2 | O14: =+N14*$O$2 -> 52
B15: Agua de obra | C15: mes | D15: =+$F$4 -> 17 | E15: 1 | F15: 250000 | G15: =+F15*D15*E15 -> 4250000 | M15: Pintura | N15: 2 | O15: =+N15*$O$2 -> 52
B16: Internet | C16: mes | D16: =+$F$4 -> 17 | E16: 1 | F16: 50000 | G16: =+F16*D16*E16 -> 850000 | M16: Terminaciones | N16: 1 | O16: =+N16*$O$2 -> 26
B17: Alquiler cerco de obra chapa | C17: mes | D17: =+$F$4 -> 17 | E17: 0 | F17: 10000 | G17: =+F17*D17*E17 -> 0 | N17: =SUM(N4:N16) -> 17 | O17: =SUM(O4:O16) -> 442
B18: Proyecto Ejecutivo | C18: mes | D18: =+$F$4 -> 17 | E18: 0 | F18: 3009340.6 | G18: =+F18*D18*E18 -> 0
B19: Proyecto (50%) | C19: mes | D19: =+$F$4 -> 17 | E19: 0.5 | F19: 3009340.6 | G19: =+F19*D19*E19 -> 25579395
B20: Gastos Directos | H20: =SUM(G21:G31) -> 60580518
B21: Coordinacion de obra | C21: mes | D21: =+$F$4 -> 17 | E21: 0.15 | F21: 5273644.1 | G21: =+F21*D21*E21 -> 13447792
B22: Jefe de obra | C22: mes | D22: =+$F$4 -> 17 | E22: 1 | J22: 4372210.6 | K22: =+J22*D22*E22 -> 74327580
B23: Sobrestante | C23: mes | D23: =+$F$4 -> 17 | E23: 0 | F23: 3009340.6 | G23: =+F23*D23*E23 -> 0
B24: Administrativo en obra | C24: mes | D24: =+$F$4 -> 17 | E24: 0 | F24: =+F23 -> 3009340.6 | G24: =+F24*D24*E24 -> 0
B25: Capataz | C25: mes | D25: =+$F$4 -> 17 | E25: 0.5 | F25: 3545026.5 | G25: =+F25*D25*E25 -> 30132725
B26: Logistica | C26: mes | D26: =+$F$4 -> 17 | E26: 1 | F26: 500000 | G26: =+F26*D26*E26 -> 8500000
B27: Vehiculo obra | C27: mes | D27: =+$F$4 -> 17 | E27: 1 | F27: =F26 -> 500000 | G27: =+F27*D27*E27 -> 8500000
B28: Mov y viaticos | C28: mes | D28: =+$F$4 -> 17 | E28: 1 | J28: =F26 -> 500000 | K28: =+J28*D28*E28 -> 8500000
B29: UOCRA | C29: mes | D29: =+$F$4 -> 17 | E29: 1 | G29: =+F29*D29*E29 -> 0
B30: Pañolero/Sereno | C30: mes | D30: =+$F$4 -> 17 | E30: 1 | J30: 730326.97 | K30: =+J30*D30*E30 -> 12415558
B32: Equipos | H32: =SUM(G33:G41) -> 0
B33: Bobcat | C33: mes | F33: 130000 | G33: =+F33*D33 -> 0
B34: Camion limpieza | C34: mes | F34: 100000 | G34: =+F34*D34 -> 0
B35: Tijera electrica 12 | C35: mes | F35: 33600 | G35: =+F35*D35 -> 0
B36: JLG | C36: mes | F36: 89000 | G36: =+F36*D36 -> 0
B37: Grua 20ton | C37: mes | F37: 70000 | G37: =+F37*D37 -> 0
B42: Gastos Indirectos | H42: =SUM(G43:G48) -> 82753395
B43: Admin (50%Compras - 50%RRHH) | C43: mes | D43: =+$F$4 -> 17 | E43: 0.5 | F43: 3009340.6 | G43: =+F43*D43*E43 -> 25579395
B44: Seguros | C44: gl | D44: =+D43 -> 17 | E44: 1 | F44: 250000 | G44: =+F44*D44 -> 4250000
B45: IIBB (monto venta obra gris) | C45: gl | D45: 0.04 | E45: 0.7 | F45: 1400000000 | G45: =+F45*D45*E45 -> 39200000
B46: Imp cheque | C46: gl | D46: =1.2/100 -> 0.012 | E46: =+E45 -> 0.7 | F46: =+F45*1.15 -> 1.61e+09 | G46: =+F46*D46*E46 -> 13524000
...

Sheet 2_Movimientos
A1: Cuenta | B1: Desc Cuenta | C1: Fecha Asiento | D1: Nº Asiento | E1: Observaciones | F1: Cliente/Proveedor | G1: Cód Comprobante | H1: Nº Comprobante | I1: Debe | J1: Haber | K1: Unidad | L1: Desc Unidad | M1: Centro de Costo | N1: Desc Centro Costo | O1: Saldo Inicial | P1: Observaciones original | Q1: mov_id | R1: mov_tipo
A2: 410222 | B2: Obra civil Reforma | C2: 45784 | D2: 2442 | E2: Obras - Garcia del Rio 3760 CA | F2: Garcia del Rio 3760 CABA Fideicomiso | G2: FAWS | H2: 300000653 | I2: 0 | J2: 44000000 | K2: DESA | L2: Desarrollos | M2: GDR | N2: García del Río 3760 | O2: 0 | Q2: =IFERROR(TRIM(LEFT($E2,FIND(" | ",$E2)-1)),"") | R2: =IFERROR(TRIM(UPPER(MID($E2,FIND(" | ",$E2)+3,IFERROR(FIND(" | ",$E2,FIND(" | ",$E2)+3),LEN($E2)+1)-FIND(" | ",$E2)-3))),"")
A3: 410222 | B3: Obra civil Reforma | C3: 45838 | D3: 3476 | E3: Obras - Garcia del Rio 3760 CA | F3: Garcia del Rio 3760 CABA Fideicomiso | G3: FAWS | H3: 300000683 | I3: 0 | J3: 34000000 | K3: DESA | L3: Desarrollos | M3: GDR | N3: García del Río 3760 | O3: 0 | Q3: =IFERROR(TRIM(LEFT($E3,FIND(" | ",$E3)-1)),"") | R3: =IFERROR(TRIM(UPPER(MID($E3,FIND(" | ",$E3)+3,IFERROR(FIND(" | ",$E3,FIND(" | ",$E3)+3),LEN($E3)+1)-FIND(" | ",$E3)-3))),"")
A4: 410222 | B4: Obra civil Reforma | C4: 45866 | D4: 3872 | E4: Obras - Garcia del Rio 3760 CA | F4: Garcia del Rio 3760 CABA Fideicomiso | G4: FAWS | H4: 300000699 | I4: 0 | J4: 27500000 | K4: DESA | L4: Desarrollos | M4: GDR | N4: García del Río 3760 | O4: 0 | Q4: =IFERROR(TRIM(LEFT($E4,FIND(" | ",$E4)-1)),"") | R4: =IFERROR(TRIM(UPPER(MID($E4,FIND(" | ",$E4)+3,IFERROR(FIND(" | ",$E4,FIND(" | ",$E4)+3),LEN($E4)+1)-FIND(" | ",$E4)-3))),"")
A5: 410222 | B5: Obra civil Reforma | C5: 45869 | D5: 3914 | E5: Obras - Garcia del Rio 3760 CA | F5: Garcia del Rio 3760 CABA Fideicomiso | G5: FAWS | H5: 300000704 | I5: 0 | J5: 20000000 | K5: DESA | L5: Desarrollos | M5: GDR | N5: García del Río 3760 | O5: 0 | Q5: =IFERROR(TRIM(LEFT($E5,FIND(" | ",$E5)-1)),"") | R5: =IFERROR(TRIM(UPPER(MID($E5,FIND(" | ",$E5)+3,IFERROR(FIND(" | ",$E5,FIND(" | ",$E5)+3),LEN($E5)+1)-FIND(" | ",$E5)-3))),"")
A6: 410222 | B6: Obra civil Reforma | C6: 45891 | D6: 4284 | E6: Obras - Garcia del Rio 3760 CA | F6: Garcia del Rio 3760 CABA Fideicomiso | G6: FAWS | H6: 300000719 | I6: 0 | J6: 17731795 | K6: DESA | L6: Desarrollos | M6: GDR | N6: García del Río 3760 | O6: 0 | Q6: =IFERROR(TRIM(LEFT($E6,FIND(" | ",$E6)-1)),"") | R6: =IFERROR(TRIM(UPPER(MID($E6,FIND(" | ",$E6)+3,IFERROR(FIND(" | ",$E6,FIND(" | ",$E6)+3),LEN($E6)+1)-FIND(" | ",$E6)-3))),"")
A7: 410222 | B7: Obra civil Reforma | C7: 45898 | D7: 4424 | E7: Obras - Garcia del Rio 3760 CA | F7: Garcia del Rio 3760 CABA Fideicomiso | G7: FAWS | H7: 300000721 | I7: 0 | J7: 9049773.8 | K7: DESA | L7: Desarrollos | M7: GDR | N7: García del Río 3760 | O7: 0 | Q7: =IFERROR(TRIM(LEFT($E7,FIND(" | ",$E7)-1)),"") | R7: =IFERROR(TRIM(UPPER(MID($E7,FIND(" | ",$E7)+3,IFERROR(FIND(" | ",$E7,FIND(" | ",$E7)+3),LEN($E7)+1)-FIND(" | ",$E7)-3))),"")
A8: 410222 | B8: Obra civil Reforma | C8: 45900 | D8: 4425 | E8: Obras - Garcia del Rio 3760 CA | F8: Garcia del Rio 3760 CABA Fideicomiso | G8: FAWS | H8: 300000722 | I8: 0 | J8: 30190424 | K8: DESA | L8: Desarrollos | M8: GDR | N8: García del Río 3760 | O8: 0 | Q8: =IFERROR(TRIM(LEFT($E8,FIND(" | ",$E8)-1)),"") | R8: =IFERROR(TRIM(UPPER(MID($E8,FIND(" | ",$E8)+3,IFERROR(FIND(" | ",$E8,FIND(" | ",$E8)+3),LEN($E8)+1)-FIND(" | ",$E8)-3))),"")
A9: 410222 | B9: Obra civil Reforma | C9: 45900 | D9: 4426 | E9: Obras - Garcia del Rio 3760 CA | F9: Garcia del Rio 3760 CABA Fideicomiso | G9: FAWS | H9: 300000723 | I9: 0 | J9: 35460488 | K9: DESA | L9: Desarrollos | M9: GDR | N9: García del Río 3760 | O9: 0 | Q9: =IFERROR(TRIM(LEFT($E9,FIND(" | ",$E9)-1)),"") | R9: =IFERROR(TRIM(UPPER(MID($E9,FIND(" | ",$E9)+3,IFERROR(FIND(" | ",$E9,FIND(" | ",$E9)+3),LEN($E9)+1)-FIND(" | ",$E9)-3))),"")
A10: 410222 | B10: Obra civil Reforma | C10: 45930 | D10: 5100 | E10: Obras - Garcia del Rio 3760 CA | F10: Garcia del Rio 3760 CABA Fideicomiso | G10: FAWS | H10: 300000736 | I10: 0 | J10: 22499464 | K10: DESA | L10: Desarrollos | M10: GDR | N10: García del Río 3760 | O10: 0 | Q10: =IFERROR(TRIM(LEFT($E10,FIND(" | ",$E10)-1)),"") | R10: =IFERROR(TRIM(UPPER(MID($E10,FIND(" | ",$E10)+3,IFERROR(FIND(" | ",$E10,FIND(" | ",$E10)+3),LEN($E10)+1)-FIND(" | ",$E10)-3))),"")
A11: 410222 | B11: Obra civil Reforma | C11: 45959 | D11: 5524 | E11: Obras - Garcia del Rio 3760 CA | F11: Garcia del Rio 3760 CABA Fideicomiso | G11: FAWS | H11: 300000754 | I11: 0 | J11: 50900937 | K11: DESA | L11: Desarrollos | M11: GDR | N11: García del Río 3760 | O11: 0 | Q11: =IFERROR(TRIM(LEFT($E11,FIND(" | ",$E11)-1)),"") | R11: =IFERROR(TRIM(UPPER(MID($E11,FIND(" | ",$E11)+3,IFERROR(FIND(" | ",$E11,FIND(" | ",$E11)+3),LEN($E11)+1)-FIND(" | ",$E11)-3))),"")
A12: 410222 | B12: Obra civil Reforma | C12: 46009 | D12: 490 | E12: Obras - Garcia del Rio 3760 CA | F12: Garcia del Rio 3760 CABA Fideicomiso | G12: FAWS | H12: 300000784 | I12: 0 | J12: 33776391 | K12: DESA | L12: Desarrollos | M12: GDR | N12: García del Río 3760 | O12: 0 | Q12: =IFERROR(TRIM(LEFT($E12,FIND(" | ",$E12)-1)),"") | R12: =IFERROR(TRIM(UPPER(MID($E12,FIND(" | ",$E12)+3,IFERROR(FIND(" | ",$E12,FIND(" | ",$E12)+3),LEN($E12)+1)-FIND(" | ",$E12)-3))),"")
A13: 410222 | B13: Obra civil Reforma | C13: 46041 | D13: 988 | E13: Obras - Garcia del Rio 3760 CA | F13: Garcia del Rio 3760 CABA Fideicomiso | G13: FAWS | H13: 300000800 | I13: 0 | J13: 25136093 | K13: DESA | L13: Desarrollos | M13: GDR | N13: García del Río 3760 | O13: 0 | Q13: =IFERROR(TRIM(LEFT($E13,FIND(" | ",$E13)-1)),"") | R13: =IFERROR(TRIM(UPPER(MID($E13,FIND(" | ",$E13)+3,IFERROR(FIND(" | ",$E13,FIND(" | ",$E13)+3),LEN($E13)+1)-FIND(" | ",$E13)-3))),"")
... A18: 410222 | B18: Obra civil Reforma | C18: 46120 | D18: 2138 | E18: Obras - Garcia del Rio 3760 CA | F18: Garcia del Rio 3760 CABA Fideicomiso | G18: FAWS | H18: 300000845 | I18: 0 | J18: 27641241 | K18: DESA | L18: Desarrollos | M18: GDR | N18: García del Río 3760 | O18: 0 | Q18: =IFERROR(TRIM(LEFT($E18,FIND(" | ",$E18)-1)),"") | R18: =IFERROR(TRIM(UPPER(MID($E18,FIND(" | ",$E18)+3,IFERROR(FIND(" | ",$E18,FIND(" | ",$E18)+3),LEN($E18)+1)-FIND(" | ",$E18)-3))),"")
A19: 4201 | B19: Otros ingresos | C19: 45751 | D19: 1405 | E19: A cuent Ant Obra-10000 TC 1300 | G19: OIXX | H19: 185 | I19: 0 | J19: 13000000 | K19: DESA | L19: Desarrollos | M19: GDR | N19: García del Río 3760 | O19: 0 | Q19: =IFERROR(TRIM(LEFT($E19,FIND(" | ",$E19)-1)),"") | R19: =IFERROR(TRIM(UPPER(MID($E19,FIND(" | ",$E19)+3,IFERROR(FIND(" | ",$E19,FIND(" | ",$E19)+3),LEN($E19)+1)-FIND(" | ",$E19)-3))),"")
A20: 4201 | B20: Otros ingresos | C20: 45762 | D20: 1406 | E20: A cta Ant Obra-4000 TC 1270 | G20: OIXX | H20: 186 | I20: 0 | J20: 5080000 | K20: DESA | L20: Desarrollos | M20: GDR | N20: García del Río 3760 | O20: 0 | Q20: =IFERROR(TRIM(LEFT($E20,FIND(" | ",$E20)-1)),"") | R20: =IFERROR(TRIM(UPPER(MID($E20,FIND(" | ",$E20)+3,IFERROR(FIND(" | ",$E20,FIND(" | ",$E20)+3),LEN($E20)+1)-FIND(" | ",$E20)-3))),"")
A21: 4201 | B21: Otros ingresos | C21: 45779 | D21: 1597 | E21: Deposito factura GDR TC 1.190 | G21: OIXX | H21: 193 | I21: 0 | J21: 23800000 | K21: DESA | L21: Desarrollos | M21: GDR | N21: García del Río 3760 | O21: 0 | Q21: =IFERROR(TRIM(LEFT($E21,FIND(" | ",$E21)-1)),"") | R21: =IFERROR(TRIM(UPPER(MID($E21,FIND(" | ",$E21)+3,IFERROR(FIND(" | ",$E21,FIND(" | ",$E21)+3),LEN($E21)+1)-FIND(" | ",$E21)-3))),"")
A22: 4201 | B22: Otros ingresos | C22: 45786 | D22: 1598 | E22: A cta de Deuda de GDR TC 1.555 | G22: OIXX | H22: 194 | I22: 0 | J22: 57750000 | K22: DESA | L22: Desarrollos | M22: GDR | N22: García del Río 3760 | O22: 0 | Q22: =IFERROR(TRIM(LEFT($E22,FIND(" | ",$E22)-1)),"") | R22: =IFERROR(TRIM(UPPER(MID($E22,FIND(" | ",$E22)+3,IFERROR(FIND(" | ",$E22,FIND(" | ",$E22)+3),LEN($E22)+1)-FIND(" | ",$E22)-3))),"")
A23: 4201 | B23: Otros ingresos | C23: 45787 | D23: 1599 | E23: A cta de Deuda de GDR TC 1155 | G23: OIXX | H23: 195 | I23: 0 | J23: 3465000 | K23: DESA | L23: Desarrollos | M23: GDR | N23: García del Río 3760 | O23: 0 | Q23: =IFERROR(TRIM(LEFT($E23,FIND(" | ",$E23)-1)),"") | R23: =IFERROR(TRIM(UPPER(MID($E23,FIND(" | ",$E23)+3,IFERROR(FIND(" | ",$E23,FIND(" | ",$E23)+3),LEN($E23)+1)-FIND(" | ",$E23)-3))),"")
A24: 4201 | B24: Otros ingresos | C24: 45793 | D24: 1600 | E24: A cta de Deuda de GDR TC 1.155 | G24: OIXX | H24: 196 | I24: 0 | J24: 57750000 | K24: DESA | L24: Desarrollos | M24: GDR | N24: García del Río 3760 | O24: 0 | Q24: =IFERROR(TRIM(LEFT($E24,FIND(" | ",$E24)-1)),"") | R24: =IFERROR(TRIM(UPPER(MID($E24,FIND(" | ",$E24)+3,IFERROR(FIND(" | ",$E24,FIND(" | ",$E24)+3),LEN($E24)+1)-FIND(" | ",$E24)-3))),"")
A25: 4201 | B25: Otros ingresos | C25: 45831 | D25: 1969 | E25: Pago Cta Ant-usd 30000 tc 1190 | G25: OIXX | H25: 206 | I25: 0 | J25: 35700000 | K25: DESA | L25: Desarrollos | M25: GDR | N25: García del Río 3760 | O25: 0 | Q25: =IFERROR(TRIM(LEFT($E25,FIND(" | ",$E25)-1)),"") | R25: =IFERROR(TRIM(UPPER(MID($E25,FIND(" | ",$E25)+3,IFERROR(FIND(" | ",$E25,FIND(" | ",$E25)+3),LEN($E25)+1)-FIND(" | ",$E25)-3))),"")
A26: 4201 | B26: Otros ingresos | C26: 45835 | D26: 1970 | E26: Pago Cta Ant-usd 3505 tc 1200 | G26: OIXX | H26: 207 | I26: 0 | J26: 4206000 | K26: DESA | L26: Desarrollos | M26: GDR | N26: García del Río 3760 | O26: 0 | Q26: =IFERROR(TRIM(LEFT($E26,FIND(" | ",$E26)-1)),"") | R26: =IFERROR(TRIM(UPPER(MID($E26,FIND(" | ",$E26)+3,IFERROR(FIND(" | ",$E26,FIND(" | ",$E26)+3),LEN($E26)+1)-FIND(" | ",$E26)-3))),"")
A27: 4201 | B27: Otros ingresos | C27: 45877 | D27: 2072 | E27: cta deu AING-usd 1200 tc 1310 | G27: OIXX | H27: 215 | I27: 0 | J27: 1572000 | K27: DESA | L27: Desarrollos | M27: GDR | N27: García del Río 3760 | O27: 0 | Q27: =IFERROR(TRIM(LEFT($E27,FIND(" | ",$E27)-1)),"") | R27: =IFERROR(TRIM(UPPER(MID($E27,FIND(" | ",$E27)+3,IFERROR(FIND(" | ",$E27,FIND(" | ",$E27)+3),LEN($E27)+1)-FIND(" | ",$E27)-3))),"")
A28: 4201 | B28: Otros ingresos | C28: 45891 | D28: 2073 | E28: A cta d deu AIN-usd 2650 1315 | G28: OIXX | H28: 216 | I28: 0 | J28: 3484750 | K28: DESA | L28: Desarrollos | M28: GDR | N28: García del Río 3760 | O28: 0 | Q28: =IFERROR(TRIM(LEFT($E28,FIND(" | ",$E28)-1)),"") | R28: =IFERROR(TRIM(UPPER(MID($E28,FIND(" | ",$E28)+3,IFERROR(FIND(" | ",$E28,FIND(" | ",$E28)+3),LEN($E28)+1)-FIND(" | ",$E28)-3))),"")
A29: 5101 | B29: Sueldos | C29: 45845 | D29: 1738 | E29: Javier Antequera - 06-2025 | G29: OPXX | H29: 7138 | I29: 3500000 | J29: 0 | K29: DESA | L29: Desarrollos | M29: GDR | N29: García del Río 3760 | O29: 0 | Q29: =IFERROR(TRIM(LEFT($E29,FIND(" | ",$E29)-1)),"") | R29: =IFERROR(TRIM(UPPER(MID($E29,FIND(" | ",$E29)+3,IFERROR(FIND(" | ",$E29,FIND(" | ",$E29)+3),LEN($E29)+1)-FIND(" | ",$E29)-3))),"")
A30: 5101 | B30: Sueldos | C30: 45845 | D30: 1739 | E30: Javier Antequera - SAC | G30: OPXX | H30: 7139 | I30: 875000 | J30: 0 | K30: DESA | L30: Desarrollos | M30: GDR | N30: García del Río 3760 | O30: 0 | Q30: =IFERROR(TRIM(LEFT($E30,FIND(" | ",$E30)-1)),"") | R30: =IFERROR(TRIM(UPPER(MID($E30,FIND(" | ",$E30)+3,IFERROR(FIND(" | ",$E30,FIND(" | ",$E30)+3),LEN($E30)+1)-FIND(" | ",$E30)-3))),"")
... A34: 5101 | B34: Sueldos | C34: 46073 | D34: 576 | E34: Yohen Rodriguez-Premio Hormigo | G34: OPXX | H34: 8597 | I34: 2078000 | J34: 0 | K34: DESA | L34: Desarrollos | M34: GDR | N34: García del Río 3760 | O34: 0 | Q34: =IFERROR(TRIM(LEFT($E34,FIND(" | ",$E34)-1)),"") | R34: =IFERROR(TRIM(UPPER(MID($E34,FIND(" | ",$E34)+3,IFERROR(FIND(" | ",$E34,FIND(" | ",$E34)+3),LEN($E34)+1)-FIND(" | ",$E34)-3))),"")
A35: 5108 | B35: Gastos en personal | C35: 45706 | D35: 1305 | E35: Gastos en Personales - Abrafer | F35: Abrafer S.R.L. | G35: FCA3 | H35: 1000192524 | I35: 138171.31 | J35: 0 | K35: DESA | L35: Desarrollos | M35: GDR | N35: García del Río 3760 | O35: 0 | Q35: =IFERROR(TRIM(LEFT($E35,FIND(" | ",$E35)-1)),"") | R35: =IFERROR(TRIM(UPPER(MID($E35,FIND(" | ",$E35)+3,IFERROR(FIND(" | ",$E35,FIND(" | ",$E35)+3),LEN($E35)+1)-FIND(" | ",$E35)-3))),"")
A36: 5108 | B36: Gastos en personal | C36: 45726 | D36: 1808 | E36: Gastos en Personales - Abrafer | F36: Abrafer S.R.L. | G36: NCA3 | H36: 1000012643 | I36: 0 | J36: 59490.47 | K36: DESA | L36: Desarrollos | M36: GDR | N36: García del Río 3760 | O36: 0 | Q36: =IFERROR(TRIM(LEFT($E36,FIND(" | ",$E36)-1)),"") | R36: =IFERROR(TRIM(UPPER(MID($E36,FIND(" | ",$E36)+3,IFERROR(FIND(" | ",$E36,FIND(" | ",$E36)+3),LEN($E36)+1)-FIND(" | ",$E36)-3))),"")
A37: 5108 | B37: Gastos en personal | C37: 45727 | D37: 1582 | E37: EPP - Abrafer S.R.L. | F37: Abrafer S.R.L. | G37: FCA3 | H37: 1000193810 | I37: 389523.63 | J37: 0 | K37: DESA | L37: Desarrollos | M37: GDR | N37: García del Río 3760 | O37: 0 | Q37: =IFERROR(TRIM(LEFT($E37,FIND(" | ",$E37)-1)),"") | R37: =IFERROR(TRIM(UPPER(MID($E37,FIND(" | ",$E37)+3,IFERROR(FIND(" | ",$E37,FIND(" | ",$E37)+3),LEN($E37)+1)-FIND(" | ",$E37)-3))),"")
A38: 5108 | B38: Gastos en personal | C38: 45850 | D38: 3670 | E38: Gastos en Personales - Abrafer | F38: Abrafer S.R.L. | G38: FCA3 | H38: 1000203135 | I38: 440804.68 | J38: 0 | K38: DESA | L38: Desarrollos | M38: GDR | N38: García del Río 3760 | O38: 0 | Q38: =IFERROR(TRIM(LEFT($E38,FIND(" | ",$E38)-1)),"") | R38: =IFERROR(TRIM(UPPER(MID($E38,FIND(" | ",$E38)+3,IFERROR(FIND(" | ",$E38,FIND(" | ",$E38)+3),LEN($E38)+1)-FIND(" | ",$E38)-3))),"")
A39: 5108 | B39: Gastos en personal | C39: 45850 | D39: 3671 | E39: Gastos en Personales - Abrafer | F39: Abrafer S.R.L. | G39: FCA3 | H39: 1000203122 | I39: 993.6 | J39: 0 | K39: DESA | L39: Desarrollos | M39: GDR | N39: García del Río 3760 | O39: 0 | Q39: =IFERROR(TRIM(LEFT($E39,FIND(" | ",$E39)-1)),"") | R39: =IFERROR(TRIM(UPPER(MID($E39,FIND(" | ",$E39)+3,IFERROR(FIND(" | ",$E39,FIND(" | ",$E39)+3),LEN($E39)+1)-FIND(" | ",$E39)-3))),"")
A40: 5108 | B40: Gastos en personal | C40: 45867 | D40: 3899 | E40: Gastos en Personales - Abrafer | F40: Abrafer S.R.L. | G40: NCA3 | H40: 1000013415 | I40: 0 | J40: 993.6 | K40: DESA | L40: Desarrollos | M40: GDR | N40: García del Río 3760 | O40: 0 | Q40: =IFERROR(TRIM(LEFT($E40,FIND(" | ",$E40)-1)),"") | R40: =IFERROR(TRIM(UPPER(MID($E40,FIND(" | ",$E40)+3,IFERROR(FIND(" | ",$E40,FIND(" | ",$E40)+3),LEN($E40)+1)-FIND(" | ",$E40)-3))),"")
A41: 5108 | B41: Gastos en personal | C41: 45895 | D41: 4361 | E41: Gastos en Personales - Abrafer | F41: Abrafer S.R.L. | G41: FCA3 | H41: 1000206822 | I41: 27040.04 | J41: 0 | K41: DESA | L41: Desarrollos | M41: GDR | N41: García del Río 3760 | O41: 0 | Q41: =IFERROR(TRIM(LEFT($E41,FIND(" | ",$E41)-1)),"") | R41: =IFERROR(TRIM(UPPER(MID($E41,FIND(" | ",$E41)+3,IFERROR(FIND(" | ",$E41,FIND(" | ",$E41)+3),LEN($E41)+1)-FIND(" | ",$E41)-3))),"")
A42: 52001 | B42: Aysa | C42: 45841 | D42: 1716 | E42: AYSA - pendientes | G42: OPXX | H42: 7116 | I42: 32438.6 | J42: 0 | K42: DESA | L42: Desarrollos | M42: GDR | N42: García del Río 3760 | O42: 0 | Q42: =IFERROR(TRIM(LEFT($E42,FIND(" | ",$E42)-1)),"") | R42: =IFERROR(TRIM(UPPER(MID($E42,FIND(" | ",$E42)+3,IFERROR(FIND(" | ",$E42,FIND(" | ",$E42)+3),LEN($E42)+1)-FIND(" | ",$E42)-3))),"")
A43: 52001 | B43: Aysa | C43: 45841 | D43: 1761 | E43: AYSA - pendientes | G43: OPXX | H43: 7161 | I43: 32438.6 | J43: 0 | K43: DESA | L43: Desarrollos | M43: GDR | N43: García del Río 3760 | O43: 0 | Q43: =IFERROR(TRIM(LEFT($E43,FIND(" | ",$E43)-1)),"") | R43: =IFERROR(TRIM(UPPER(MID($E43,FIND(" | ",$E43)+3,IFERROR(FIND(" | ",$E43,FIND(" | ",$E43)+3),LEN($E43)+1)-FIND(" | ",$E43)-3))),"")
A44: 52002 | B44: Edenor | C44: 45679 | D44: 340 | E44: EDENOR - Fact. 45239049 | G44: OPXX | H44: 5772 | I44: 64900 | J44: 0 | K44: DESA | L44: Desarrollos | M44: GDR | N44: García del Río 3760 | O44: 0 | Q44: =IFERROR(TRIM(LEFT($E44,FIND(" | ",$E44)-1)),"") | R44: =IFERROR(TRIM(UPPER(MID($E44,FIND(" | ",$E44)+3,IFERROR(FIND(" | ",$E44,FIND(" | ",$E44)+3),LEN($E44)+1)-FIND(" | ",$E44)-3))),"")
A45: 52002 | B45: Edenor | C45: 45680 | D45: 274 | E45: Deuda Edenor | G45: OPXX | H45: 5702 | I45: 64897 | J45: 0 | K45: DESA | L45: Desarrollos | M45: GDR | N45: García del Río 3760 | O45: 0 | Q45: =IFERROR(TRIM(LEFT($E45,FIND(" | ",$E45)-1)),"") | R45: =IFERROR(TRIM(UPPER(MID($E45,FIND(" | ",$E45)+3,IFERROR(FIND(" | ",$E45,FIND(" | ",$E45)+3),LEN($E45)+1)-FIND(" | ",$E45)-3))),"")
A46: 52002 | B46: Edenor | C46: 45832 | D46: 3946 | E46: Edenor - Prestamo a GDR | G46: OPG | H46: 3947 | I46: 283606.9 | J46: 0 | K46: DESA | L46: Desarrollos | M46: GDR | N46: García del Río 3760 | O46: 0 | Q46: =IFERROR(TRIM(LEFT($E46,FIND(" | ",$E46)-1)),"") | R46: =IFERROR(TRIM(UPPER(MID($E46,FIND(" | ",$E46)+3,IFERROR(FIND(" | ",$E46,FIND(" | ",$E46)+3),LEN($E46)+1)-FIND(" | ",$E46)-3))),"")
A47: 52005 | B47: Internet | C47: 45765 | D47: 2337 | E47: Internet - Telecom Argentina S | F47: Telecom Argentina S.A. | G47: FCA3 | H47: 426405225578 | I47: 19365 | J47: 0 | K47: DESA | L47: Desarrollos | M47: GDR | N47: García del Río 3760 | O47: 0 | Q47: =IFERROR(TRIM(LEFT($E47,FIND(" | ",$E47)-1)),"") | R47: =IFERROR(TRIM(UPPER(MID($E47,FIND(" | ",$E47)+3,IFERROR(FIND(" | ",$E47,FIND(" | ",$E47)+3),LEN($E47)+1)-FIND(" | ",$E47)-3))),"")
...

Sheet 1_Composicion
A1: Partida | B1: Tipo | C1: Subtipo | D1: Cod_Insumo | E1: Descripción | F1: Unidad de medida | G1: Cant | H1: %Desp | I1: Precio | J1: Costo | K1: Clave | L1: Count | M1: Clave2 | N1: Rend. Part. | O1: Cant MO/ALB Unit | P1: Cant. Ej. Part. | Q1: Cant MO/ALB Total | R1: Cod_Item_Ppto | S1: MO/ALB
A2: AIS-114 | B2: EQ | D2: EQ-SOLD00 | E2: Soldador Soplete A Gas Techista Membrana 10 Kg Boca 50mm | G2: 1 | H2: 0 | I2: 804.50569 | J2: 804.50569 | K2: AIS-114|EQ | L2: 1 | M2: AIS-114|EQ|1 | N2: 60 | O2: 1 | P2: - | Q2: 0 | R2: - | S2: -
A3: AIS-114 | B3: MAT | C3: OTR | D3: OTR-022 | E3: Aguarras Hydrarras Hydra x 18lts | F3: b | G3: 0.005 | H3: 0.05 | I3: 26907.33 | J3: 141.26348 | K3: AIS-114|MAT | L3: 1 | M3: AIS-114|MAT|1 | N3: 60 | O3: 0.005 | P3: - | Q3: 0 | R3: - | S3: -
A4: AIS-114 | B4: MAT | C4: OTR | D4: OTR-025 | E4: Trapo | F4: u | G4: 0.01 | H4: 0.05 | I4: 735.06 | J4: 7.71813 | K4: AIS-114|MAT | L4: 2 | M4: AIS-114|MAT|2 | N4: 60 | O4: 0.01 | P4: - | Q4: 0 | R4: - | S4: -
A5: AIS-114 | B5: MAT | C5: OTR | D5: OTR-027 | E5: Rodillo de lana pelo largo N°22 - El Galgo | F5: u | G5: 0.005 | H5: 0.05 | I5: 6678.36 | J5: 35.06139 | K5: AIS-114|MAT | L5: 3 | M5: AIS-114|MAT|3 | N5: 60 | O5: 0.005 | P5: - | Q5: 0 | R5: - | S5: -
A6: AIS-114 | B6: MAT | C6: OTR | D6: OTR-028 | E6: Pincel N° 20 - El Galgo | F6: u | G6: 0.01 | H6: 0.05 | I6: 5282.24 | J6: 55.46352 | K6: AIS-114|MAT | L6: 4 | M6: AIS-114|MAT|4 | N6: 60 | O6: 0.01 | P6: - | Q6: 0 | R6: - | S6: -
A7: AIS-114 | B7: MAT | C7: OTR | D7: OTR-047 | E7: Guante Vaqueta Medio Paseo | F7: par | G7: 0.03 | H7: 0.05 | I7: 4842 | J7: 152.523 | K7: AIS-114|MAT | L7: 5 | M7: AIS-114|MAT|5 | N7: 60 | O7: 0.03 | P7: - | Q7: 0 | R7: - | S7: -
A8: AIS-114 | B8: MAT | C8: OTR | D8: OTR-048 | E8: Recarga de garrafa | F8: u | G8: 0.01 | H8: 0.05 | I8: 12396.694 | J8: 130.16529 | K8: AIS-114|MAT | L8: 6 | M8: AIS-114|MAT|6 | N8: 60 | O8: 0.01 | P8: - | Q8: 0 | R8: - | S8: -
A9: AIS-114 | B9: MAT | C9: OTR | D9: PIN-008 | E9: Pintura Asfaltica Asfasol x18ts | F9: b | G9: 0.015 | H9: 0.1 | I9: 32845.78 | J9: 541.95537 | K9: AIS-114|MAT | L9: 7 | M9: AIS-114|MAT|7 | N9: 60 | O9: 0.015 | P9: - | Q9: 0 | R9: - | S9: -
A10: AIS-114 | B10: MAT | C10: OTR | D10: AIS-002 | E10: Membrana Geotextil Ormiflex 4mm - (35kg) x10m | F10: u | G10: 0.05 | H10: 0.1 | I10: 70192.21 | J10: 3860.5716 | K10: AIS-114|MAT | L10: 8 | M10: AIS-114|MAT|8 | N10: 60 | O10: 0.05 | P10: - | Q10: 0 | R10: - | S10: -
A11: AIS-114 | B11: MO | C11: ALB | D11: MO-EAYUD | E11: AYUDANTE | F11: j | G11: 1 | H11: 0 | I11: 60860.581 | J11: 60860.581 | K11: AIS-114|MO | L11: 1 | M11: AIS-114|MO|1 | N11: 60 | O11: 0.016666667 | P11: - | Q11: 0 | R11: - | S11: -
A12: AIS-114 | B12: MO | C12: ALB | D12: MO-EESPE | E12: ESPECIALIZADO | F12: j | G12: 1 | H12: 0 | I12: 85927.097 | J12: 85927.097 | K12: AIS-114|MO | L12: 2 | M12: AIS-114|MO|2 | N12: 60 | O12: 0.016666667 | P12: - | Q12: 0 | R12: - | S12: -
A13: ALB-033 | B13: EQ | D13: EQ-ANDAM0 | E13: ANDAMIO TUBULAR DE UNO A TRES CUERPOS | G13: 0.5 | H13: 0 | I13: 571.17949 | J13: 285.58975 | K13: ALB-033|EQ | L13: 1 | M13: ALB-033|EQ|1 | N13: 7 | O13: 0.5 | P13: - | Q13: 0 | R13: - | S13: -
A14: ALB-033 | B14: EQ | D14: EQ-EQALBA | E14: EQUIPO DE ALBAÑILERIA, carpetas, ladrillo | G14: 1 | H14: 0 | I14: 2287.1357 | J14: 2287.1357 | K14: ALB-033|EQ | L14: 2 | M14: ALB-033|EQ|2 | N14: 7 | O14: 1 | P14: - | Q14: 0 | R14: - | S14: -
A15: ALB-033 | B15: EQ | D15: EQ-TROMPO | E15: Hormigonera De 150 Litros 1hp Con Rueda Maciza | G15: 1 | H15: 0 | I15: 957.2532 | J15: 957.2532 | K15: ALB-033|EQ | L15: 3 | M15: ALB-033|EQ|3 | N15: 7 | O15: 1 | P15: - | Q15: 0 | R15: - | S15: -
A16: ALB-033 | B16: MAT | C16: OTR | D16: ACE-001 | E16: Barra de Acero Aleteado - 6mm x 12m | F16: u | G16: 0.17 | H16: 0.1 | I16: 3424.53 | J16: 640.38711 | K16: ALB-033|MAT | L16: 1 | M16: ALB-033|MAT|1 | N16: 7 | O16: 0.17 | P16: - | Q16: 0 | R16: - | S16: -
A17: ALB-033 | B17: MAT | C17: OTR | D17: AGR-001 | E17: ARENA LAVADA | F17: m3 | G17: 0.035 | H17: 0.1 | I17: 32399.77 | J17: 1247.3911 | K17: ALB-033|MAT | L17: 2 | M17: ALB-033|MAT|2 | N17: 7 | O17: 0.035 | P17: - | Q17: 0 | R17: - | S17: -
A18: ALB-033 | B18: MAT | C18: OTR | D18: AGR-004 | E18: Cemento Portland x 50kg | F18: Bol | G18: 0.15 | H18: 0.1 | I18: 7809.48 | J18: 1288.5642 | K18: ALB-033|MAT | L18: 3 | M18: ALB-033|MAT|3 | N18: 7 | O18: 0.15 | P18: - | Q18: 0 | R18: - | S18: -
A19: ALB-033 | B19: MAT | C19: OTR | D19: AGR-005 | E19: Cal Comun x 25kg | F19: bol | G19: 0.3 | H19: 0.1 | I19: 3837.96 | J19: 1266.5268 | K19: ALB-033|MAT | L19: 4 | M19: ALB-033|MAT|4 | N19: 7 | O19: 0.3 | P19: - | Q19: 0 | R19: - | S19: -
A20: ALB-033 | B20: MAT | C20: OTR | D20: CER-005 | E20: Ladrillo Comun 12.5 x 5.5 x 25 | F20: u | G20: 60 | H20: 0.05 | I20: 132.3 | J20: 8334.9 | K20: ALB-033|MAT | L20: 5 | M20: ALB-033|MAT|5 | N20: 7 | O20: 60 | P20: - | Q20: 0 | R20: - | S20: -
A21: ALB-033 | B21: MAT | C21: OTR | D21: MAT-CONS | E21: Consumibles | F21: gl | G21: 1.3161102 | H21: 0 | I21: 1 | J21: 1.3161102 | K21: ALB-033|MAT | L21: 6 | M21: ALB-033|MAT|6 | N21: 7 | O21: 1.3161102 | P21: - | Q21: 0 | R21: - | S21: -
A22: ALB-033 | B22: MO | C22: ALB | D22: MO-EAYUD | E22: AYUDANTE | F22: j | G22: 1 | H22: 0 | I22: 60860.581 | J22: 60860.581 | K22: ALB-033|MO | L22: 1 | M22: ALB-033|MO|1 | N22: 7 | O22: 0.14285714 | P22: - | Q22: 0 | R22: - | S22: -
A23: ALB-033 | B23: MO | C23: ALB | D23: MO-EESPE | E23: ESPECIALIZADO | F23: j | G23: 1 | H23: 0 | I23: 85927.097 | J23: 85927.097 | K23: ALB-033|MO | L23: 2 | M23: ALB-033|MO|2 | N23: 7 | O23: 0.14285714 | P23: - | Q23: 0 | R23: - | S23: -
A24: ALB-034 | B24: EQ | D24: EQ-ANDAM0 | E24: ANDAMIO TUBULAR DE UNO A TRES CUERPOS | G24: 0.5 | H24: 0 | I24: 571.17949 | J24: 285.58975 | K24: ALB-034|EQ | L24: 1 | M24: ALB-034|EQ|1 | N24: 15 | O24: 0.5 | P24: 621 | Q24: 310.5 | R24: 4.01 | S24: Albañilería
A25: ALB-034 | B25: EQ | D25: EQ-EQALBA | E25: EQUIPO DE ALBAÑILERIA, carpetas, ladrillo | G25: 1 | H25: 0 | I25: 2287.1357 | J25: 2287.1357 | K25: ALB-034|EQ | L25: 2 | M25: ALB-034|EQ|2 | N25: 15 | O25: 1 | P25: 621 | Q25: 621 | R25: 4.01 | S25: Albañilería
A26: ALB-034 | B26: EQ | D26: EQ-TROMPO | E26: Hormigonera De 150 Litros 1hp Con Rueda Maciza | G26: 1 | H26: 0 | I26: 957.2532 | J26: 957.2532 | K26: ALB-034|EQ | L26: 3 | M26: ALB-034|EQ|3 | N26: 15 | O26: 1 | P26: 621 | Q26: 621 | R26: 4.01 | S26: Albañilería
A27: ALB-034 | B27: MAT | C27: OTR | D27: ACE-001 | E27: Barra de Acero Aleteado - 6mm x 12m | F27: u | G27: 0.17 | H27: 0.1 | I27: 3424.53 | J27: 640.38711 | K27: ALB-034|MAT | L27: 1 | M27: ALB-034|MAT|1 | N27: 15 | O27: 0.17 | P27: 621 | Q27: 105.57 | R27: 4.01 | S27: Albañilería
A28: ALB-034 | B28: MAT | C28: OTR | D28: AGR-001 | E28: ARENA LAVADA | F28: m3 | G28: 0.012 | H28: 0.1 | I28: 32399.77 | J28: 427.67696 | K28: ALB-034|MAT | L28: 2 | M28: ALB-034|MAT|2 | N28: 15 | O28: 0.012 | P28: 621 | Q28: 7.452 | R28: 4.01 | S28: Albañilería
A29: ALB-034 | B29: MAT | C29: OTR | D29: AGR-004 | E29: Cemento Portland x 50kg | F29: Bol | G29: 0.05 | H29: 0.1 | I29: 7809.48 | J29: 429.5214 | K29: ALB-034|MAT | L29: 3 | M29: ALB-034|MAT|3 | N29: 15 | O29: 0.05 | P29: 621 | Q29: 31.05 | R29: 4.01 | S29: Albañilería
A30: ALB-034 | B30: MAT | C30: OTR | D30: AGR-005 | E30: Cal Comun x 25kg | F30: bol | G30: 0.1 | H30: 0.1 | I30: 3837.96 | J30: 422.1756 | K30: ALB-034|MAT | L30: 4 | M30: ALB-034|MAT|4 | N30: 15 | O30: 0.1 | P30: 621 | Q30: 62.1 | R30: 4.01 | S30: Albañilería
A31: ALB-034 | B31: MAT | C31: OTR | D31: CER-002 | E31: LADRILLO CERAMICO 8 x 18 x 33 cm | F31: u | G31: 15 | H31: 0.05 | I31: 292.32 | J31: 4604.04 | K31: ALB-034|MAT | L31: 5 | M31: ALB-034|MAT|5 | N31: 15 | O31: 15 | P31: 621 | Q31: 9315 | R31: 4.01 | S31: Albañilería
A32: ALB-034 | B32: MAT | C32: OTR | D32: MAT-CONS | E32: Consumibles | F32: gl | G32: 67.195151 | H32: 0 | I32: 1 | J32: 67.195151 | K32: ALB-034|MAT | L32: 6 | M32: ALB-034|MAT|6 | N32: 15 | O32: 67.195151 | P32: 621 | Q32: 41728.189 | R32: 4.01 | S32: Albañilería
