Workbook
Name GASTOS_CONCEPTO: _Listas!$I$2:$I$17
Name RUBROS_PLAN: _Listas!$A$2:$A$34

Sheet 0_CONFIG
A1: ▌ CONFIGURACIÓN DE OBRA — SVD 4140
A3: Nombre de obra | B3: Edificio El Salvador 4140
A4: Estado | B4: En ejecución
A5: Fecha inicio | B5: 45658 | C5: presupuesto base sep-2024
A6: Duración estimada (meses) | B6: 18 | C6: feb-2025 a ago-2026
A7: — ÍNDICE CAC —
A8: Mes base CAC | B8: 45536 | C8: fecha base del presupuesto (sep-2024)
A9: Valor CAC base (INDEC) | B9: 14366.9 | C9: índice INDEC del mes base
A10: Mes corriente | B10: =INDEX('0_Indice_CAC'!$A$4:$A$33,MATCH(1E+300,'0_Indice_CAC'!$B$4:$B$33)) -> 46174 | C10: último mes cargado
A11: Ratio CAC corriente | B11: =MIN('0_Indice_CAC'!$D$4:$D$33) -> 0.70180534 | C11: ratio del mes más reciente
A12: — COEFICIENTE K —
A13: K (Gastos Generales y Beneficio) | B13: ='1_GGBB'!F66 -> 1.2568826 | C13: CRÍTICO: no modificar manualmente
A14: — PRESUPUESTO —
A15: Apertura fiscal | B15: B31 / N69 / GGN | C15: Blanco 31% c/IVA · Negro 69% — DERIVADO de Facturación, revisar
A16: Costo controlable (sin EQ) | B16: =SUMPRODUCT(('1_Presupuesto'!$J$5:$J$219+'1_Presupuesto'!$K$5:$K$219+'1_Presupuesto'!$L$5:$L$219)*'1_Presupuesto'!$I$5:$I$219) -> 8.7650815e+08 | C16: MT+MO/OTR+MO/ALB × Cant (EQ excluido)
A17: Costo total (con EQ) | B17: =SUMPRODUCT('1_Presupuesto'!$N$5:$N$219*'1_Presupuesto'!$I$5:$I$219) -> 8.9704289e+08 | C17: Costo Unit. × Cant
A18: Precio de venta total | B18: =SUMPRODUCT('1_Presupuesto'!$S$5:$S$219*'1_Presupuesto'!$I$5:$I$219) -> 1.1581632e+09 | C18: P Unit. × Cant
A19: Sanity check venta (debe ser 0) | B19: =+B18-1158163185 -> 0.019499779 | C19: venta total = subtotales legacy Pto.Vta (markup no uniforme; K solo informativo)
A44: — RECONCILIACIÓN MENSUAL —
A45: Total egresos (2_Movimientos) | B45: =SUMPRODUCT('2_Movimientos'!$I$2:$I$999,N(LEFT(TEXT('2_Movimientos'!$A$2:$A$999,"0"),1)<>"4"))-SUMPRODUCT('2_Movimientos'!$J$2:$J$999,N(LEFT(TEXT('2_Movimientos'!$A$2:$A$999,"0"),1)<>"4")) -> 2.809937e+08 | C45: ← se cablea en bloque 6 (crear 2_Movimientos)
A46: Total Tezamat (pegar mensual) | C46: input mensual
A47: Diferencia (debe ser 0) | B47: =B45-B46 -> 2.809937e+08 | C47: se activa al cablear B45
A49: Tolerancia conciliación ($) | B49: 100
A52: — PENDIENTES (celdas amarillas) —
A53: 0_Indice_CAC col B | B53: CAC meses futuros sin publicar
A54: 0_Jornales_MO | B54: Tarifas UOCRA meses futuros
A55: 0_CONFIG!B46 | B55: Input mensual total Tezamat
A56: 1_Presupuesto cols A,B,C,D | B56: Asignación de rubros por ítem (4 cols input manual)

Sheet 0_Indice_CAC
A1: INDICE CAC
A3: Escala de tiempo | B3: Valores | C3: Previsión | D3: Indice
A4: 45536 | B4: 14366.9 | D4: =$B$4/B4 -> 1
A5: 45566 | B5: 14614.9 | D5: =$B$4/B5 -> 0.98303102
A6: 45597 | B6: 15043 | D6: =$B$4/B6 -> 0.95505551
A7: 45627 | B7: 15356.4 | D7: =$B$4/B7 -> 0.93556432
A8: 45658 | B8: 15592.5 | D8: =$B$4/B8 -> 0.92139811
A9: 45689 | B9: 15852.4 | D9: =$B$4/B9 -> 0.90629179
A10: 45717 | B10: 15995.4 | D10: =$B$4/B10 -> 0.89818948
A11: 45748 | B11: 16253.5 | D11: =$B$4/B11 -> 0.88392654
A12: 45778 | B12: 16521.3 | D12: =$B$4/B12 -> 0.86959864
A13: 45809 | B13: 16643.4 | D13: =$B$4/B13 -> 0.86321905
A14: 45839 | B14: 16939.5 | D14: =$B$4/B14 -> 0.84813011
A15: 45870 | B15: 17187.6 | D15: =$B$4/B15 -> 0.8358875
... A21: 46054 | B21: 19453 | D21: =$B$4/B21 -> 0.73854418
A22: 46082 | B22: 19806.241 | C22: 19806.241 | D22: =$B$4/B22 -> 0.72537239
A23: 46113 | B23: 20138.793 | C23: 20138.793 | D23: =$B$4/B23 -> 0.71339428
A24: 46143 | B24: 20471.346 | C24: 20471.346 | D24: =$B$4/B24 -> 0.70180534
A25: 46174 | B25: 20471.346 | C25: 20471.346 | D25: =$B$4/B25 -> 0.70180534

Sheet 0_Jornales_MO
A1: SECCIÓN A — TABLA DE TARIFAS POR CATEGORÍA (Costo por Día/Quincena)
A3: PERÍODO | B3: ESPEC. ($/día) | C3: OFICIAL ($/día) | D3: 1/2 OFICIAL ($/día) | E3: AYUDANTE ($/día) | G3: ESPEC. ($/hr) | H3: OFICIAL ($/día) | I3: 1/2 OFICIAL ($/día) | J3: AYUDANTE ($/día)
A4: 45627 | B4: 85927.1 | C4: 76955.08 | D4: 65493.07 | E4: 60860.58 | G4: =+B4/8 -> 10740.888 | H4: =+C4/8 -> 9619.385 | I4: =+D4/8 -> 8186.6337 | J4: =+E4/8 -> 7607.5725
A5: 45658 | B5: 87384 | C5: 78375 | D5: 66853 | E5: 61892 | G5: =+B5/8 -> 10923 | H5: =+C5/8 -> 9796.875 | I5: =+D5/8 -> 8356.625 | J5: =+E5/8 -> 7736.5
A6: 45689 | B6: 89383 | C6: 80395 | D6: 68472 | E6: 63382 | G6: =+B6/8 -> 11172.875 | H6: =+C6/8 -> 10049.375 | I6: =+D6/8 -> 8559 | J6: =+E6/8 -> 7922.75
A7: 45717 | B7: 91464 | C7: 82269 | D7: 70296 | E7: 65595 | G7: =+B7/8 -> 11433 | H7: =+C7/8 -> 10283.625 | I7: =+D7/8 -> 8787 | J7: =+E7/8 -> 8199.375
A8: 45778 | B8: 93235.367 | C8: 83766.388 | D8: 71410.817 | E8: 66568.094 | G8: =+B8/8 -> 11654.421 | H8: =+C8/8 -> 10470.798 | I8: =+D8/8 -> 8926.3521 | J8: =+E8/8 -> 8321.0117
A9: 45809 | B9: 94177.138 | C9: 84612.513 | D9: 72132.138 | E9: 67240.499 | G9: =+B9/8 -> 11772.142 | H9: =+C9/8 -> 10576.564 | I9: =+D9/8 -> 9016.5173 | J9: =+E9/8 -> 8405.0624
A10: 45839 | B10: 95080 | C10: 85425 | D10: 72871 | E10: 67908 | G10: =+B10/8 -> 11885 | H10: =+C10/8 -> 10678.125 | I10: =+D10/8 -> 9108.875 | J10: =+E10/8 -> 8488.5
A11: 45870 | B11: 95889.2 | C11: 86356.18 | D11: 73781.11 | E11: 68935.35 | G11: =+B11/8 -> 11986.15 | H11: =+C11/8 -> 10794.522 | I11: =+D11/8 -> 9222.6388 | J11: =+E11/8 -> 8616.9188
A12: 45901 | B12: 106516.02 | C12: 88649.808 | D12: 75758.192 | E12: 71041.119 | G12: =+B12/8 -> 13314.502 | H12: =+C12/8 -> 11081.226 | I12: =+D12/8 -> 9469.774 | J12: =+E12/8 -> 8880.1398
A13: 45931 | B13: 106864.21 | C13: 88971.073 | D13: 76032.176 | E13: 71292.271 | G13: =+B13/8 -> 13358.026 | H13: =+C13/8 -> 11121.384 | I13: =+D13/8 -> 9504.0221 | J13: =+E13/8 -> 8911.5339
A14: 45962 | B14: 109621.11 | C14: 91252.851 | D14: 77612.118 | E14: 72486.683 | G14: =+B14/8 -> 13702.638 | H14: =+C14/8 -> 11406.606 | I14: =+D14/8 -> 9701.5148 | J14: =+E14/8 -> 9060.8353
A15: 45992 | B15: 113865.18 | C15: 95196.927 | D15: 81356.194 | E15: 76230.759 | G15: =+B15/8 -> 14233.148 | H15: =+C15/8 -> 11899.616 | I15: =+D15/8 -> 10169.524 | J15: =+E15/8 -> 9528.8449
... A21: 46174 | B21: 122445.79 | C21: 102029.07 | D21: 87100.47 | E21: 81453.719 | G21: =+B21/8 -> 15305.724 | H21: =+C21/8 -> 12753.633 | I21: =+D21/8 -> 10887.559 | J21: =+E21/8 -> 10181.715

Sheet 1_Presupuesto
A1: PRESUPUESTO OBRA CIVIL y CERTIFICACIONES DE AVANCE
A3: Rubro MT | B3: Rubro MT/Prov | C3: Rubro MO/OTR | D3: Rubro MO/ALB | E3: Cod. Ítem | F3: Estado | G3: Descripción | H3: U | I3: Cant | J3: MT | K3: MO/OTR | L3: MO/ALB | M3: EQ | N3: Costo Unit. | O3: MT | P3: MO/OTR | Q3: MO/ALB | R3: EQ | S3: P.Unit | T3: Margen | U3: Costo total | V3: PV subtotal | W3: Etapa | X3: Presupuesto | Y3: % Acum Tot
E4: 1 | G4: TAREAS PRELIMINARES
A5: Preliminares | B5: - | C5: - | D5: - | E5: 1.01 | F5: OK | G5: Limpieza y preparación del terreno - No cotiza | H5: gl | I5: 0 | J5: 0 | K5: 0 | L5: 0 | M5: 0 | N5: =SUM(J5:M5) -> 0 | O5: =IF($N5=0,$S5,J5/$N5*$S5) -> 0 | P5: =IF($N5=0,0,K5/$N5*$S5) -> 0 | Q5: =IF($N5=0,0,L5/$N5*$S5) -> 0 | R5: =IF($N5=0,0,M5/$N5*$S5) -> 0 | S5: 0 | T5: =IFERROR(S5/N5,"") | U5: =N5*I5 -> 0 | V5: =S5*I5 -> 0 | W5: TAREAS PRELIMINARES | X5: PTO 01 | Y5: =SUMIFS(Cert_App_Output!$G:$G,Cert_App_Output!$E:$E,$E5,Cert_App_Output!$K:$K,$X5) -> 0
A6: Preliminares | B6: - | C6: Preliminares | D6: Preliminares | E6: 1.02 | F6: OK | G6: Topógrafo - Visita de obra replanteo | H6: un | I6: 3 | J6: 41666.667 | K6: 172653.21 | L6: 83223.729 | M6: 4463.1541 | N6: =SUM(J6:M6) -> 302006.76 | O6: =IF($N6=0,$S6,J6/$N6*$S6) -> 52370.241 | P6: =IF($N6=0,0,K6/$N6*$S6) -> 217005.36 | Q6: =IF($N6=0,0,L6/$N6*$S6) -> 104602.72 | R6: =IF($N6=0,0,M6/$N6*$S6) -> 5609.6749 | S6: 379588 | T6: =IFERROR(S6/N6,"") -> 1.2568858 | U6: =N6*I6 -> 906020.27 | V6: =S6*I6 -> 1138764 | W6: TAREAS PRELIMINARES | X6: PTO 01 | Y6: =SUMIFS(Cert_App_Output!$G:$G,Cert_App_Output!$E:$E,$E6,Cert_App_Output!$K:$K,$X6) -> 1
A7: Preliminares | B7: - | C7: - | D7: - | E7: 1.03 | F7: OK | G7: Cartel de Obra - No cotiza | H7: gl | I7: 0 | J7: 0 | K7: 0 | L7: 0 | M7: 0 | N7: =SUM(J7:M7) -> 0 | O7: =IF($N7=0,$S7,J7/$N7*$S7) -> 0 | P7: =IF($N7=0,0,K7/$N7*$S7) -> 0 | Q7: =IF($N7=0,0,L7/$N7*$S7) -> 0 | R7: =IF($N7=0,0,M7/$N7*$S7) -> 0 | S7: 0 | T7: =IFERROR(S7/N7,"") | U7: =N7*I7 -> 0 | V7: =S7*I7 -> 0 | W7: TAREAS PRELIMINARES | X7: PTO 01 | Y7: =SUMIFS(Cert_App_Output!$G:$G,Cert_App_Output!$E:$E,$E7,Cert_App_Output!$K:$K,$X7) -> 0
A8: Preliminares | B8: - | C8: - | D8: Preliminares | E8: 1.04 | F8: OK | G8: Cerco de obra perimetral - En chapa C25 + Concertina + Porton corredizo | H8: ml | I8: 11 | J8: 79773.183 | K8: 0 | L8: 30923.374 | M8: 1660.4484 | N8: =SUM(J8:M8) -> 112357.01 | O8: =IF($N8=0,$S8,J8/$N8*$S8) -> 100265.83 | P8: =IF($N8=0,0,K8/$N8*$S8) -> 0 | Q8: =IF($N8=0,0,L8/$N8*$S8) -> 38867.171 | R8: =IF($N8=0,0,M8/$N8*$S8) -> 2086.9951 | S8: 141220 | T8: =IFERROR(S8/N8,"") -> 1.2568865 | U8: =N8*I8 -> 1235927.1 | V8: =S8*I8 -> 1553420 | W8: TAREAS PRELIMINARES | X8: PTO 01 | Y8: =SUMIFS(Cert_App_Output!$G:$G,Cert_App_Output!$E:$E,$E8,Cert_App_Output!$K:$K,$X8) -> 1
A9: Preliminares | B9: - | C9: Preliminares | D9: Preliminares | E9: 1.05 | F9: OK | G9: Obrador colgante, pañol y ducha | H9: gl | I9: 1 | J9: 2400856.7 | K9: 500000 | L9: 3016332.5 | M9: 88757.838 | N9: =SUM(J9:M9) -> 6005947 | O9: =IF($N9=0,$S9,J9/$N9*$S9) -> 3017595.3 | P9: =IF($N9=0,0,K9/$N9*$S9) -> 628441.36 | Q9: =IF($N9=0,0,L9/$N9*$S9) -> 3791176.2 | R9: =IF($N9=0,0,M9/$N9*$S9) -> 111558.19 | S9: 7548771 | T9: =IFERROR(S9/N9,"") -> 1.2568827 | U9: =N9*I9 -> 6005947 | V9: =S9*I9 -> 7548771 | W9: TAREAS PRELIMINARES | X9: PTO 01 | Y9: =SUMIFS(Cert_App_Output!$G:$G,Cert_App_Output!$E:$E,$E9,Cert_App_Output!$K:$K,$X9) -> 1
A10: - | B10: - | C10: Gastos Generales | D10: - | E10: 1.06 | F10: OK | G10: Alquiler de baños quimicos y duchas portatiles | H10: mes | I10: 3 | J10: 0 | K10: 311904.59 | L10: 0 | M10: 0 | N10: =SUM(J10:M10) -> 311904.59 | O10: =IF($N10=0,$S10,J10/$N10*$S10) -> 0 | P10: =IF($N10=0,0,K10/$N10*$S10) -> 392028 | Q10: =IF($N10=0,0,L10/$N10*$S10) -> 0 | R10: =IF($N10=0,0,M10/$N10*$S10) -> 0 | S10: 392028 | T10: =IFERROR(S10/N10,"") -> 1.2568844 | U10: =N10*I10 -> 935713.77 | V10: =S10*I10 -> 1176084 | W10: TAREAS PRELIMINARES | X10: PTO 01 | Y10: =SUMIFS(Cert_App_Output!$G:$G,Cert_App_Output!$E:$E,$E10,Cert_App_Output!$K:$K,$X10) -> 1
A11: Preliminares | B11: - | C11: - | D11: Preliminares | E11: 1.07 | F11: OK | G11: Conexión pilar y luz de obra + Tablero de obra | H11: gl | I11: 1 | J11: 845578.51 | K11: 0 | L11: 511535.56 | M11: 20356.711 | N11: =SUM(J11:M11) -> 1377470.8 | O11: =IF($N11=0,$S11,J11/$N11*$S11) -> 1062793.5 | P11: =IF($N11=0,0,K11/$N11*$S11) -> 0 | Q11: =IF($N11=0,0,L11/$N11*$S11) -> 642940.5 | R11: =IF($N11=0,0,M11/$N11*$S11) -> 25586.01 | S11: 1731320 | T11: =IFERROR(S11/N11,"") -> 1.2568833 | U11: =N11*I11 -> 1377470.8 | V11: =S11*I11 -> 1731320 | W11: TAREAS PRELIMINARES | X11: PTO 01 | Y11: =SUMIFS(Cert_App_Output!$G:$G,Cert_App_Output!$E:$E,$E11,Cert_App_Output!$K:$K,$X11) -> 1
A12: Preliminares | B12: - | C12: - | D12: Preliminares | E12: 1.08 | F12: OK | G12: Conexión agua de obra, tanque + bomba | H12: gl | I12: 1 | J12: 680400 | K12: 0 | L12: 421419.89 | M12: 16527.298 | N12: =SUM(J12:M12) -> 1118347.2 | O12: =IF($N12=0,$S12,J12/$N12*$S12) -> 855183.46 | P12: =IF($N12=0,0,K12/$N12*$S12) -> 0 | Q12: =IF($N12=0,0,L12/$N12*$S12) -> 529675.66 | R12: =IF($N12=0,0,M12/$N12*$S12) -> 20772.887 | S12: 1405632 | T12: =IFERROR(S12/N12,"") -> 1.2568834 | U12: =N12*I12 -> 1118347.2 | V12: =S12*I12 -> 1405632 | W12: TAREAS PRELIMINARES | X12: PTO 01 | Y12: =SUMIFS(Cert_App_Output!$G:$G,Cert_App_Output!$E:$E,$E12,Cert_App_Output!$K:$K,$X12) -> 1
A13: - | B13: - | C13: Gastos Generales | D13: - | E13: 1.09 | F13: OK | G13: Tramite luz de obra, certificado luz de obra (2) y medición PAT | H13: gl | I13: 1 | J13: 0 | K13: 339320.84 | L13: 0 | M13: 0 | N13: =SUM(J13:M13) -> 339320.84 | O13: =IF($N13=0,$S13,J13/$N13*$S13) -> 0 | P13: =IF($N13=0,0,K13/$N13*$S13) -> 426487 | Q13: =IF($N13=0,0,L13/$N13*$S13) -> 0 | R13: =IF($N13=0,0,M13/$N13*$S13) -> 0 | S13: 426487 | T13: =IFERROR(S13/N13,"") -> 1.2568842 | U13: =N13*I13 -> 339320.84 | V13: =S13*I13 -> 426487 | W13: TAREAS PRELIMINARES | X13: PTO 01 | Y13: =SUMIFS(Cert_App_Output!$G:$G,Cert_App_Output!$E:$E,$E13,Cert_App_Output!$K:$K,$X13) -> 1
A14: - | B14: - | C14: Movimiento de Suelos | D14: - | E14: 1.1 | F14: OK | G14: Sistema de depresión de napas | H14: gl | I14: 1 | J14: 0 | K14: 7800000 | L14: 0 | M14: 0 | N14: =SUM(J14:M14) -> 7800000 | O14: =IF($N14=0,$S14,J14/$N14*$S14) -> 0 | P14: =IF($N14=0,0,K14/$N14*$S14) -> 9803685 | Q14: =IF($N14=0,0,L14/$N14*$S14) -> 0 | R14: =IF($N14=0,0,M14/$N14*$S14) -> 0 | S14: 9803685 | T14: =IFERROR(S14/N14,"") -> 1.2568827 | U14: =N14*I14 -> 7800000 | V14: =S14*I14 -> 9803685 | W14: TAREAS PRELIMINARES | X14: PTO 01 | Y14: =SUMIFS(Cert_App_Output!$G:$G,Cert_App_Output!$E:$E,$E14,Cert_App_Output!$K:$K,$X14) -> 1
E15: 2 | G15: MOVIMIENTO DE TIERRA, COMPACTACION Y RELLENO
A16: - | B16: - | C16: Movimiento de Suelos | D16: Homigón MO | E16: 2.01 | F16: OK | G16: Excavación a maquina para submuración y subsuelo | H16: m3 | I16: 1266 | J16: 0 | K16: 18400 | L16: 7809.62 | M16: 117.1443 | N16: =SUM(J16:M16) -> 26326.764 | O16: =IF($N16=0,$S16,J16/$N16*$S16) -> 0 | P16: =IF($N16=0,0,K16/$N16*$S16) -> 23126.883 | Q16: =IF($N16=0,0,L16/$N16*$S16) -> 9815.8788 | R16: =IF($N16=0,0,M16/$N16*$S16) -> 147.23818 | S16: 33090 | T16: =IFERROR(S16/N16,"") -> 1.2568958 | U16: =N16*I16 -> 33329684 | V16: =S16*I16 -> 41891940 | W16: MOVIMIENTO DE TIERRA, COMPACTACION Y RELLENO | X16: PTO 01 | Y16: =SUMIFS(Cert_App_Output!$G:$G,Cert_App_Output!$E:$E,$E16,Cert_App_Output!$K:$K,$X16) -> 1
A17: Movimiento de Suelos | B17: - | C17: - | D17: - | E17: 2.02 | F17: OK | G17: Demolición y retiro de fundaciones existentes - No cotiza | H17: gl | I17: 0 | J17: 0 | K17: 0 | L17: 0 | M17: 0 | N17: =SUM(J17:M17) -> 0 | O17: =IF($N17=0,$S17,J17/$N17*$S17) -> 0 | P17: =IF($N17=0,0,K17/$N17*$S17) -> 0 | Q17: =IF($N17=0,0,L17/$N17*$S17) -> 0 | R17: =IF($N17=0,0,M17/$N17*$S17) -> 0 | S17: 0 | T17: =IFERROR(S17/N17,"") | U17: =N17*I17 -> 0 | V17: =S17*I17 -> 0 | W17: MOVIMIENTO DE TIERRA, COMPACTACION Y RELLENO | X17: PTO 01 | Y17: =SUMIFS(Cert_App_Output!$G:$G,Cert_App_Output!$E:$E,$E17,Cert_App_Output!$K:$K,$X17) -> 0
A18: - | B18: - | C18: - | D18: Homigón MO | E18: 2.03 | F18: OK | G18: Excavación manual para pozo de achique y bombeo | H18: m3 | I18: 2 | J18: 0 | K18: 0 | L18: 49934.237 | M18: 0 | N18: =SUM(J18:M18) -> 49934.237 | O18: =IF($N18=0,$S18,J18/$N18*$S18) -> 0 | P18: =IF($N18=0,0,K18/$N18*$S18) -> 0 | Q18: =IF($N18=0,0,L18/$N18*$S18) -> 62762 | R18: =IF($N18=0,0,M18/$N18*$S18) -> 0 | S18: 62762 | T18: =IFERROR(S18/N18,"") -> 1.2568931 | U18: =N18*I18 -> 99868.474 | V18: =S18*I18 -> 125524 | W18: MOVIMIENTO DE TIERRA, COMPACTACION Y RELLENO | X18: PTO 01 | Y18: =SUMIFS(Cert_App_Output!$G:$G,Cert_App_Output!$E:$E,$E18,Cert_App_Output!$K:$K,$X18) -> 1
E19: 3 | G19: ESTRUCTURA RESISTENTE - sin provision de hierro y hormigon (incluye corte y doblado en obra)
A20: Hormigón MT | B20: - | C20: - | D20: Homigón MO | E20: 3.01 | F20: OK | G20: Hormigón de limpieza - e: 10 cm | H20: m3 | I20: 35 | J20: 196572.86 | K20: 0 | L20: 49934.237 | M20: 3697.6064 | N20: =SUM(J20:M20) -> 250204.7 | O20: =IF($N20=0,$S20,J20/$N20*$S20) -> 247069.05 | P20: =IF($N20=0,0,K20/$N20*$S20) -> 0 | Q20: =IF($N20=0,0,L20/$N20*$S20) -> 62761.487 | R20: =IF($N20=0,0,M20/$N20*$S20) -> 4647.4581 | S20: 314478 | T20: =IFERROR(S20/N20,"") -> 1.2568829 | U20: =N20*I20 -> 8757164.5 | V20: =S20*I20 -> 11006730 | W20: ESTRUCTURA RESISTENTE - sin provision de hierro y hormigon (incluye corte y doblado en obra) | X20: PTO 01 | Y20: =SUMIFS(Cert_App_Output!$G:$G,Cert_App_Output!$E:$E,$E20,Cert_App_Output!$K:$K,$X20) -> 1
A21: Hormigón MT | B21: - | C21: - | D21: Homigón MO | E21: 3.02 | F21: OK | G21: Tabique submuración - H30 hidrófugo (95 kg/m3 de hierro) | H21: m3 | I21: 40 | J21: 70843.446 | K21: 0 | L21: 307690.19 | M21: 5678.0046 | N21: =SUM(J21:M21) -> 384211.64 | O21: =IF($N21=0,$S21,J21/$N21*$S21) -> 98842.531 | P21: =IF($N21=0,0,K21/$N21*$S21) -> 0 | Q21: =IF($N21=0,0,L21/$N21*$S21) -> 429296.98 | R21: =IF($N21=0,0,M21/$N21*$S21) -> 7922.0927 | S21: 536061.6 | T21: =IFERROR(S21/N21,"") -> 1.3952248 | U21: =N21*I21 -> 15368466 | V21: =S21*I21 -> 21442464 | W21: ESTRUCTURA RESISTENTE - sin provision de hierro y hormigon (incluye corte y doblado en obra) | X21: PTO 01 | Y21: =SUMIFS(Cert_App_Output!$G:$G,Cert_App_Output!$E:$E,$E21,Cert_App_Output!$K:$K,$X21) -> 1
A22: Hormigón MT | B22: - | C22: Homigón MO | D22: - | E22: 3.03 | F22: OK | G22: Zapata corrida tabique - H30 hidrófugo (120 kg/m3) | H22: m3 | I22: 28 | J22: 55068.822 | K22: 253994.14 | L22: 3e-05 | M22: 4635.9445 | N22: =SUM(J22:M22) -> 313698.91 | O22: =IF($N22=0,$S22,J22/$N22*$S22) -> 76833.432 | P22: =IF($N22=0,0,K22/$N22*$S22) -> 354379.14 | Q22: =IF($N22=0,0,L22/$N22*$S22) -> 4.1856769e-05 | R22: =IF($N22=0,0,M22/$N22*$S22) -> 6468.1886 | S22: 437680.76 | T22: =IFERROR(S22/N22,"") -> 1.3952256 | U22: =N22*I22 -> 8783569.5 | V22: =S22*I22 -> 12255061 | W22: ESTRUCTURA RESISTENTE - sin provision de hierro y hormigon (incluye corte y doblado en obra) | X22: PTO 01 | Y22: =SUMIFS(Cert_App_Output!$G:$G,Cert_App_Output!$E:$E,$E22,Cert_App_Output!$K:$K,$X22) -> 1
A23: Hormigón MT | B23: - | C23: Homigón MO | D23: - | E23: 3.04 | F23: OK | G23: Platea - H30 hidrófugo (95 kg/m3 de hierro) | H23: m3 | I23: 179 | J23: 2471.4098 | K23: 148967.56 | L23: -3e-05 | M23: 2271.5846 | N23: =SUM(J23:M23) -> 153710.56 | O23: =IF($N23=0,$S23,J23/$N23*$S23) -> 3448.1872 | P23: =IF($N23=0,0,K23/$N23*$S23) -> 207844.15 | Q23: =IF($N23=0,0,L23/$N23*$S23) -> -4.1856926e-05 | R23: =IF($N23=0,0,M23/$N23*$S23) -> 3169.385 | S23: 214461.72 | T23: =IFERROR(S23/N23,"") -> 1.3952309 | U23: =N23*I23 -> 27514190 | V23: =S23*I23 -> 38388648 | W23: ESTRUCTURA RESISTENTE - sin provision de hierro y hormigon (incluye corte y doblado en obra) | X23: PTO 01 | Y23: =SUMIFS(Cert_App_Output!$G:$G,Cert_App_Output!$E:$E,$E23,Cert_App_Output!$K:$K,$X23) -> 1
A24: Hormigón MT | B24: - | C24: - | D24: Homigón MO | E24: 3.05 | F24: OK | G24: Rampa - H30 (120 kg/m3 de hierro) | H24: m3 | I24: 10 | J24: 40150.005 | K24: 0 | L24: 286602.43 | M24: 4901.2865 | N24: =SUM(J24:M24) -> 331653.72 | O24: =IF($N24=0,$S24,J24/$N24*$S24) -> 56018.303 | P24: =IF($N24=0,0,K24/$N24*$S24) -> 0 | Q24: =IF($N24=0,0,L24/$N24*$S24) -> 399874.95 | R24: =IF($N24=0,0,M24/$N24*$S24) -> 6838.3988 | S24: 462731.65 | T24: =IFERROR(S24/N24,"") -> 1.3952253 | U24: =N24*I24 -> 3316537.2 | V24: =S24*I24 -> 4627316.5 | W24: ESTRUCTURA RESISTENTE - sin provision de hierro y hormigon (incluye corte y doblado en obra) | X24: PTO 01 | Y24: =SUMIFS(Cert_App_Output!$G:$G,Cert_App_Output!$E:$E,$E24,Cert_App_Output!$K:$K,$X24) -> 1
A25: Hormigón MT | B25: - | C25: - | D25: Homigón MO | E25: 3.06 | F25: OK | G25: Losa maciza - H30 (110 kg/m3 de hierro) | H25: m3 | I25: 177 | J25: 32975.501 | K25: 0 | L25: 191068.28 | M25: 3360.6568 | N25: =SUM(J25:M25) -> 227404.44 | O25: =IF($N25=0,$S25,J25/$N25*$S25) -> 46008.28 | P25: =IF($N25=0,0,K25/$N25*$S25) -> 0 | Q25: =IF($N25=0,0,L25/$N25*$S25) -> 266583.46 | R25: =IF($N25=0,0,M25/$N25*$S25) -> 4688.8761 | S25: 317280.61 | T25: =IFERROR(S25/N25,"") -> 1.3952261 | U25: =N25*I25 -> 40250586 | V25: =S25*I25 -> 56158669 | W25: ESTRUCTURA RESISTENTE - sin provision de hierro y hormigon (incluye corte y doblado en obra) | X25: PTO 01 | Y25: =SUMIFS(Cert_App_Output!$G:$G,Cert_App_Output!$E:$E,$E25,Cert_App_Output!$K:$K,$X25) -> 1
A26: Hormigón MT | B26: - | C26: - | D26: Homigón MO | E26: 3.07 | F26: OK | G26: Vigas - H30 (140 kg/m3 de hierro) | H26: m3 | I26: 65 | J26: 94228.958 | K26: 0 | L26: 462949.29 | M26: 8357.6737 | N26: =SUM(J26:M26) -> 565535.92 | O26: =IF($N26=0,$S26,J26/$N26*$S26) -> 131470.69 | P26: =IF($N26=0,0,K26/$N26*$S26) -> 0 | Q26: =IF($N26=0,0,L26/$N26*$S26) -> 645918.9 | R26: =IF($N26=0,0,M26/$N26*$S26) -> 11660.844 | S26: 789050.44 | T26: =IFERROR(S26/N26,"") -> 1.395226 | U26: =N26*I26 -> 36759835 | V26: =S26*I26 -> 51288278 | W26: ESTRUCTURA RESISTENTE - sin provision de hierro y hormigon (incluye corte y doblado en obra) | X26: PTO 01 | Y26: =SUMIFS(Cert_App_Output!$G:$G,Cert_App_Output!$E:$E,$E26,Cert_App_Output!$K:$K,$X26) -> 1
A27: Hormigón MT | B27: - | C27: - | D27: Homigón MO | E27: 3.08 | F27: OK | G27: Vigas de H° visto - H30 (140 kg/m3 de hierro) | H27: m3 | I27: 12 | J27: 92072.317 | K27: 0 | L27: 555539.15 | M27: 9714.172 | N27: =SUM(J27:M27) -> 657325.64 | O27: =IF($N27=0,$S27,J27/$N27*$S27) -> 128461.69 | P27: =IF($N27=0,0,K27/$N27*$S27) -> 0 | Q27: =IF($N27=0,0,L27/$N27*$S27) -> 775102.66 | R27: =IF($N27=0,0,M27/$N27*$S27) -> 13553.465 | S27: 917117.82 | T27: =IFERROR(S27/N27,"") -> 1.395226 | U27: =N27*I27 -> 7887907.6 | V27: =S27*I27 -> 11005414 | W27: ESTRUCTURA RESISTENTE - sin provision de hierro y hormigon (incluye corte y doblado en obra) | X27: PTO 01 | Y27: =SUMIFS(Cert_App_Output!$G:$G,Cert_App_Output!$E:$E,$E27,Cert_App_Output!$K:$K,$X27) -> 1
A28: Hormigón MT | B28: - | C28: - | D28: Homigón MO | E28: 3.09 | F28: OK | G28: Tabiques - H30 (120 kg/m3 de hierro) | H28: m3 | I28: 28 | J28: 70843.446 | K28: 0 | L28: 307690.19 | M28: 5678.0046 | N28: =SUM(J28:M28) -> 384211.64 | O28: =IF($N28=0,$S28,J28/$N28*$S28) -> 98842.531 | P28: =IF($N28=0,0,K28/$N28*$S28) -> 0 | Q28: =IF($N28=0,0,L28/$N28*$S28) -> 429296.98 | R28: =IF($N28=0,0,M28/$N28*$S28) -> 7922.0927 | S28: 536061.6 | T28: =IFERROR(S28/N28,"") -> 1.3952248 | U28: =N28*I28 -> 10757926 | V28: =S28*I28 -> 15009725 | W28: ESTRUCTURA RESISTENTE - sin provision de hierro y hormigon (incluye corte y doblado en obra) | X28: PTO 01 | Y28: =SUMIFS(Cert_App_Output!$G:$G,Cert_App_Output!$E:$E,$E28,Cert_App_Output!$K:$K,$X28) -> 1
A29: Hormigón MT | B29: - | C29: - | D29: Homigón MO | E29: 3.1 | F29: OK | G29: Columna - H30 (240 Kg/m3 de hierro) | H29: m3 | I29: 54 | J29: 60951.379 | K29: 0 | L29: 273658.45 | M29: 5019.1474 | N29: =SUM(J29:M29) -> 339628.98 | O29: =IF($N29=0,$S29,J29/$N29*$S29) -> 85040.911 | P29: =IF($N29=0,0,K29/$N29*$S29) -> 0 | Q29: =IF($N29=0,0,L29/$N29*$S29) -> 381815.22 | R29: =IF($N29=0,0,M29/$N29*$S29) -> 7002.8419 | S29: 473858.97 | T29: =IFERROR(S29/N29,"") -> 1.3952254 | U29: =N29*I29 -> 18339965 | V29: =S29*I29 -> 25588384 | W29: ESTRUCTURA RESISTENTE - sin provision de hierro y hormigon (incluye corte y doblado en obra) | X29: PTO 01 | Y29: =SUMIFS(Cert_App_Output!$G:$G,Cert_App_Output!$E:$E,$E29,Cert_App_Output!$K:$K,$X29) -> 1
A30: Hormigón MT | B30: - | C30: - | D30: Homigón MO | E30: 3.11 | F30: OK | G30: Escaleras - H30 (105 kg/m3 de hierro) | H30: m3 | I30: 11 | J30: 68185.041 | K30: 0 | L30: 283180.32 | M30: 5270.4803 | N30: =SUM(J30:M30) -> 356635.84 | O30: =IF($N30=0,$S30,J30/$N30*$S30) -> 95133.577 | P30: =IF($N30=0,0,K30/$N30*$S30) -> 0 | Q30: =IF($N30=0,0,L30/$N30*$S30) -> 395100.68 | R30: =IF($N30=0,0,M30/$N30*$S30) -> 7353.5139 | S30: 497587.77 | T30: =IFERROR(S30/N30,"") -> 1.3952265 | U30: =N30*I30 -> 3922994.2 | V30: =S30*I30 -> 5473465.5 | W30: ESTRUCTURA RESISTENTE - sin provision de hierro y hormigon (incluye corte y doblado en obra) | X30: PTO 01 | Y30: =SUMIFS(Cert_App_Output!$G:$G,Cert_App_Output!$E:$E,$E30,Cert_App_Output!$K:$K,$X30) -> 1
A31: Hormigón MT | B31: - | C31: - | D31: Homigón MO | E31: 3.12 | F31: OK | G31: Tabiques tanques de H° - H30 (120 kg/m3 de hierro) | H31: m3 | I31: 3 | J31: 70843.446 | K31: 0 | L31: 307690.19 | M31: 5678.0046 | N31: =SUM(J31:M31) -> 384211.64 | O31: =IF($N31=0,$S31,J31/$N31*$S31) -> 98842.531 | P31: =IF($N31=0,0,K31/$N31*$S31) -> 0 | Q31: =IF($N31=0,0,L31/$N31*$S31) -> 429296.98 | R31: =IF($N31=0,0,M31/$N31*$S31) -> 7922.0927 | S31: 536061.6 | T31: =IFERROR(S31/N31,"") -> 1.3952248 | U31: =N31*I31 -> 1152634.9 | V31: =S31*I31 -> 1608184.8 | W31: ESTRUCTURA RESISTENTE - sin provision de hierro y hormigon (incluye corte y doblado en obra) | X31: PTO 01 | Y31: =SUMIFS(Cert_App_Output!$G:$G,Cert_App_Output!$E:$E,$E31,Cert_App_Output!$K:$K,$X31) -> 1
... A36: Hormigón MT | B36: - | C36: - | D36: Homigón MO | E36: 3.17 | F36: OK | G36: Picado de medianeras para columnas y vigas - Cotizado solo para PB y 1P, No contempla picado en SS | H36: m2 | I36: 93 | J36: 5053.7634 | K36: 0 | L36: 14213.223 | M36: 289.0048 | N36: =SUM(J36:M36) -> 19555.992 | O36: =IF($N36=0,$S36,J36/$N36*$S36) -> 6352.0944 | P36: =IF($N36=0,0,K36/$N36*$S36) -> 0 | Q36: =IF($N36=0,0,L36/$N36*$S36) -> 17864.654 | R36: =IF($N36=0,0,M36/$N36*$S36) -> 363.25123 | S36: 24580 | T36: =IFERROR(S36/N36,"") -> 1.2569038 | U36: =N36*I36 -> 1818707.2 | V36: =S36*I36 -> 2285940 | W36: ESTRUCTURA RESISTENTE - sin provision de hierro y hormigon (incluye corte y doblado en obra) | X36: PTO 01 | Y36: =SUMIFS(Cert_App_Output!$G:$G,Cert_App_Output!$E:$E,$E36,Cert_App_Output!$K:$K,$X36) -> 1
E37: 24 | G37: AYUDA DE GREMIOS
A38: - | B38: - | C38: Albañilería MO | D38: - | E38: 24.01 | F38: OK | G38: Sereno | H38: mes | I38: 8 | J38: 0 | K38: 599210.85 | L38: 1.9e-05 | M38: 0 | N38: =SUM(J38:M38) -> 599210.85 | O38: =IF($N38=0,$S38,J38/$N38*$S38) -> 0 | P38: =IF($N38=0,0,K38/$N38*$S38) -> 753138 | Q38: =IF($N38=0,0,L38/$N38*$S38) -> 2.3880779e-05 | R38: =IF($N38=0,0,M38/$N38*$S38) -> 0 | S38: 753138 | T38: =IFERROR(S38/N38,"") -> 1.2568831 | U38: =N38*I38 -> 4793686.8 | V38: =S38*I38 -> 6025104 | W38: AYUDA DE GREMIOS | X38: PTO 01 | Y38: =SUMIFS(Cert_App_Output!$G:$G,Cert_App_Output!$E:$E,$E38,Cert_App_Output!$K:$K,$X38) -> 1
A39: - | B39: - | C39: Seguridad e Higiene | D39: - | E39: 24.02 | F39: OK | G39: Tecnico de seguridad & higiene permanente en Obra | H39: mes | I39: 4 | J39: 0 | K39: 1547376.3 | L39: 0 | M39: 0 | N39: =SUM(J39:M39) -> 1547376.3 | O39: =IF($N39=0,$S39,J39/$N39*$S39) -> 0 | P39: =IF($N39=0,0,K39/$N39*$S39) -> 1944871 | Q39: =IF($N39=0,0,L39/$N39*$S39) -> 0 | R39: =IF($N39=0,0,M39/$N39*$S39) -> 0 | S39: 1944871 | T39: =IFERROR(S39/N39,"") -> 1.256883 | U39: =N39*I39 -> 6189505.4 | V39: =S39*I39 -> 7779484 | W39: AYUDA DE GREMIOS | X39: PTO 01 | Y39: =SUMIFS(Cert_App_Output!$G:$G,Cert_App_Output!$E:$E,$E39,Cert_App_Output!$K:$K,$X39) -> 1
A40: - | B40: - | C40: Seguridad e Higiene | D40: - | E40: 24.03 | F40: OK | G40: Higiene y seguridad Res 51 | H40: mes | I40: 8 | J40: 0 | K40: 150000 | L40: 0 | M40: 0 | N40: =SUM(J40:M40) -> 150000 | O40: =IF($N40=0,$S40,J40/$N40*$S40) -> 0 | P40: =IF($N40=0,0,K40/$N40*$S40) -> 188533 | Q40: =IF($N40=0,0,L40/$N40*$S40) -> 0 | R40: =IF($N40=0,0,M40/$N40*$S40) -> 0 | S40: 188533 | T40: =IFERROR(S40/N40,"") -> 1.2568867 | U40: =N40*I40 -> 1200000 | V40: =S40*I40 -> 1508264 | W40: AYUDA DE GREMIOS | X40: PTO 01 | Y40: =SUMIFS(Cert_App_Output!$G:$G,Cert_App_Output!$E:$E,$E40,Cert_App_Output!$K:$K,$X40) -> 1
A41: Albañilería MT | B41: - | C41: - | D41: Albañilería MO | E41: 24.04 | F41: OK | G41: Protecciones y defensas | H41: gl | I41: 1 | J41: 2388097.3 | K41: 0 | L41: 1222808.1 | M41: 54163.58 | N41: =SUM(J41:M41) -> 3665068.9 | O41: =IF($N41=0,$S41,J41/$N41*$S41) -> 3001558.3 | P41: =IF($N41=0,0,K41/$N41*$S41) -> 0 | Q41: =IF($N41=0,0,L41/$N41*$S41) -> 1536926.4 | R41: =IF($N41=0,0,M41/$N41*$S41) -> 68077.271 | S41: 4606562 | T41: =IFERROR(S41/N41,"") -> 1.2568828 | U41: =N41*I41 -> 3665068.9 | V41: =S41*I41 -> 4606562 | W41: AYUDA DE GREMIOS | X41: PTO 01 | Y41: =SUMIFS(Cert_App_Output!$G:$G,Cert_App_Output!$E:$E,$E41,Cert_App_Output!$K:$K,$X41) -> 1
A42: Albañilería MT | B42: - | C42: - | D42: Albañilería MO | E42: 24.05 | F42: OK | G42: Ayuda de Gremios | H42: mes | I42: 8 | J42: 50000 | K42: 0 | L42: 495686.17 | M42: 8185.2925 | N42: =SUM(J42:M42) -> 553871.46 | O42: =IF($N42=0,$S42,J42/$N42*$S42) -> 62844.184 | P42: =IF($N42=0,0,K42/$N42*$S42) -> 0 | Q42: =IF($N42=0,0,L42/$N42*$S42) -> 623019.86 | R42: =IF($N42=0,0,M42/$N42*$S42) -> 10287.961 | S42: 696152 | T42: =IFERROR(S42/N42,"") -> 1.2568837 | U42: =N42*I42 -> 4430971.7 | V42: =S42*I42 -> 5569216 | W42: AYUDA DE GREMIOS | X42: PTO 01 | Y42: =SUMIFS(Cert_App_Output!$G:$G,Cert_App_Output!$E:$E,$E42,Cert_App_Output!$K:$K,$X42) -> 1
A43: Albañilería MT | B43: - | C43: - | D43: Albañilería MO | E43: 24.06 | F43: OK | G43: Limpieza periodica | H43: mes | I43: 8 | J43: 25000 | K43: 0 | L43: 329565.97 | M43: 5318.4895 | N43: =SUM(J43:M43) -> 359884.46 | O43: =IF($N43=0,$S43,J43/$N43*$S43) -> 31422.099 | P43: =IF($N43=0,0,K43/$N43*$S43) -> 0 | Q43: =IF($N43=0,0,L43/$N43*$S43) -> 414226.18 | R43: =IF($N43=0,0,M43/$N43*$S43) -> 6684.7241 | S43: 452333 | T43: =IFERROR(S43/N43,"") -> 1.256884 | U43: =N43*I43 -> 2879075.6 | V43: =S43*I43 -> 3618664 | W43: AYUDA DE GREMIOS | X43: PTO 01 | Y43: =SUMIFS(Cert_App_Output!$G:$G,Cert_App_Output!$E:$E,$E43,Cert_App_Output!$K:$K,$X43) -> 1
A44: Albañilería MT | B44: - | C44: - | D44: - | E44: 24.07 | F44: OK | G44: Limpieza final de Obra | H44: gl | I44: 0 | J44: 0 | K44: 0 | L44: 0 | M44: 0 | N44: =SUM(J44:M44) -> 0 | O44: =IF($N44=0,$S44,J44/$N44*$S44) -> 0 | P44: =IF($N44=0,0,K44/$N44*$S44) -> 0 | Q44: =IF($N44=0,0,L44/$N44*$S44) -> 0 | R44: =IF($N44=0,0,M44/$N44*$S44) -> 0 | S44: 0 | T44: =IFERROR(S44/N44,"") | U44: =N44*I44 -> 0 | V44: =S44*I44 -> 0 | W44: AYUDA DE GREMIOS | X44: PTO 01 | Y44: =SUMIFS(Cert_App_Output!$G:$G,Cert_App_Output!$E:$E,$E44,Cert_App_Output!$K:$K,$X44) -> 0
A45: - | B45: - | C45: Mov. Variables | D45: - | E45: 24.08 | F45: OK | G45: Fletes | H45: mes | I45: 8 | J45: 0 | K45: 250000 | L45: 0 | M45: 0 | N45: =SUM(J45:M45) -> 250000 | O45: =IF($N45=0,$S45,J45/$N45*$S45) -> 0 | P45: =IF($N45=0,0,K45/$N45*$S45) -> 314221 | Q45: =IF($N45=0,0,L45/$N45*$S45) -> 0 | R45: =IF($N45=0,0,M45/$N45*$S45) -> 0 | S45: 314221 | T45: =IFERROR(S45/N45,"") -> 1.256884 | U45: =N45*I45 -> 2000000 | V45: =S45*I45 -> 2513768 | W45: AYUDA DE GREMIOS | X45: PTO 01 | Y45: =SUMIFS(Cert_App_Output!$G:$G,Cert_App_Output!$E:$E,$E45,Cert_App_Output!$K:$K,$X45) -> 1
...

Sheet 1_GGBB
H2: 45590 | O2: 22
F3: MESES | G3: DÓLAR BNA | H3: DÓLAR MEP | M3: Descrip | N3: Mes | O3: Total Dias
B4: GASTOS GENERALES y BENEFICIO | F4: 14 | G4: 1005 | H4: 1170 | M4: Prelim | N4: 0.75 | O4: =+N4*$O$2 -> 16.5 | Q4: Syh permanente
M5: Mov de suelos y excav. + micro | N5: 2.5 | O5: =+N5*$O$2 -> 55 | Q5: =+ROUNDUP(SUM(N4:N5),0) -> 4
B6: Gastos Grales de obra en items | C6: U | D6: Cant | F6: Precio Unit | G6: Subtotal | H6: =SUM(G7:G10) -> 0 | M6: Fundac | N6: 0 | O6: =+N6*$O$2 -> 0
B7: Oficina en obra (6x3 c/AA) | C7: mes | D7: =+$F$4 -> 14 | E7: 0 | F7: =E7*I7+J7 -> 0 | G7: =+F7*D7*E7 -> 0 | M7: Losa sobre PB | N7: 1 | O7: =+N7*$O$2 -> 22
B8: Obrador 6x3 s/AA | C8: mes | D8: =+$F$4 -> 14 | E8: 0 | F8: =E8*I8+J8 -> 0 | G8: =+F8*D8*E8 -> 0 | M8: Losa sobre 1 | N8: 1 | O8: =+N8*$O$2 -> 22
B9: Pañol (6x3) | C9: mes | D9: =+$F$4 -> 14 | E9: 1 | F9: =E9*I9+J9 -> 0 | G9: =+F9*D9*E9 -> 0 | M9: Losa sobre 2 | N9: 0.75 | O9: =+N9*$O$2 -> 16.5
B10: Baños | C10: mes | D10: =+$F$4 -> 14 | E10: 2 | F10: =E10*I10+J10 -> 0 | G10: =+F10*D10*E10 -> 0 | M10: Losa sobre 3 | N10: 0.75 | O10: =+N10*$O$2 -> 16.5 | P10: Inicio mamposteria
B11: Gastos Grales de obra en items | H11: =SUM(G12:G18) -> 16192179 | M11: Losa sobre 4 | N11: 0.75 | O11: =+N11*$O$2 -> 16.5 | Q11: Meses H° | R11: Estacionamiento en contramano
B12: HyS permanente | C12: mes | D12: 4 | E12: 1 | G12: =+F12*D12*E12 -> 0 | J12: 2578960.6 | K12: =+J12*D12*E12 -> 10315842 | M12: Techo escalera y sobrerecorrido | N12: 0.5 | O12: =+N12*$O$2 -> 11 | Q12: =+SUM(N4:N12) -> 8 | R12: =+Q12/2 -> 4
B13: HyS | C13: mes | D13: =+$F$4 -> 14 | E13: 1 | G13: =+F13*D13*E13 -> 0 | J13: 150000 | K13: =+J13*D13*E13 -> 2100000 | M13: Mampostería | N13: 2 | O13: =+N13*$O$2 -> 44
B14: Energía de obra | C14: mes | D14: =+F4 -> 14 | E14: 0.5 | F14: 200000 | G14: =+F14*D14*E14 -> 1400000 | I14: =+G14/$H$4 -> 1196.5812 | M14: Revoques, contrap y carp | N14: 2 | O14: =+N14*$O$2 -> 44 | P14: =+SUM(N13:N14) -> 4
B15: Agua de obra | C15: mes | D15: =+$F$4 -> 14 | E15: 1 | F15: 25000 | G15: =+F15*D15*E15 -> 350000 | M15: Amures | N15: 0 | O15: =+N15*$O$2 -> 0
B16: Alquiler cerco de obra chapa | C16: mes | D16: =+$F$4 -> 14 | E16: 0 | F16: 10000 | G16: =+F16*D16*E16 -> 0 | M16: Colocación | N16: 2 | O16: =+N16*$O$2 -> 44
B17: Proyecto Ejecutivo | C17: mes | D17: =+$F$4 -> 14 | E17: 0 | F17: 2578960.6 | G17: =+F17*D17*E17 -> 0 | M17: Pintura | N17: 2 | O17: =+N17*$O$2 -> 44
B18: Proyecto (50%) | C18: mes | D18: =+$F$4 -> 14 | E18: 0.4 | F18: 2578960.6 | G18: =+F18*D18*E18 -> 14442179 | I18: =+G18/$H$4 -> 12343.743 | M18: Terminaciones | N18: 0 | O18: =+L18*$O$2 -> 0
B19: Gastos Directos | H19: =SUM(G20:G30) -> 38913603 | N19: =SUM(N4:N18) -> 16 | O19: =SUM(O4:O18) -> 352
B20: Coordinacion de obra | C20: mes | D20: =+$F$4 -> 14 | E20: 0.15 | F20: 4680364.1 | G20: =+F20*D20*E20 -> 9828764.6 | I20: =+G20/$H$4 -> 8400.6535
B21: Jefe de obra | C21: mes | D21: =+$F$4 -> 14 | E21: 1 | G21: =+F21*D21*E21 -> 0 | J21: 3798370.6 | K21: =+J21*D21*E21 -> 53177188
B22: Sobrestante | C22: mes | D22: =+$F$4 -> 14 | E22: 0 | F22: 2578960.6 | G22: =+F22*D22*E22 -> 0
B23: Administrativo en obra | C23: mes | D23: =+$F$4 -> 14 | E23: 0 | F23: =+F22 -> 2578960.6 | G23: =+F23*D23*E23 -> 0
B24: Capataz | C24: mes | D24: =+$F$4 -> 14 | E24: 0.5 | F24: 3154977 | G24: =+F24*D24*E24 -> 22084839 | I24: =+G24/$H$4 -> 18875.931
B25: Logistica | C25: mes | D25: =+$F$4 -> 14 | E25: 0.5 | F25: 500000 | G25: =+F25*D25*E25 -> 3500000 | I25: =+G25/$H$4 -> 2991.453
B26: Vehiculo obra | C26: mes | D26: =+$F$4 -> 14 | E26: 0.5 | F26: =F25 -> 500000 | G26: =+F26*D26*E26 -> 3500000 | I26: =+G26/$H$4 -> 2991.453
B27: Mov y viaticos | C27: mes | D27: =+$F$4 -> 14 | E27: 1 | G27: =+F27*D27*E27 -> 0 | J27: =F25 -> 500000 | K27: =+J27*D27*E27 -> 7000000
B28: UOCRA | C28: mes | D28: =+$F$4 -> 14 | E28: 1 | G28: =+F28*D28*E28 -> 0
B29: Pañolero/Sereno | C29: mes | D29: =+$F$4 -> 14 | E29: 1 | J29: 1198421.7 | K29: =+J29*D29*E29 -> 16777904
B31: Equipos | H31: =SUM(G32:G40) -> 0
B32: Bobcat | C32: mes | D32: 0 | F32: 130000 | G32: =+F32*D32 -> 0
B33: Camion limpieza | C33: mes | D33: 0 | F33: 100000 | G33: =+F33*D33 -> 0
B34: Tijera electrica 12 | C34: mes | F34: 33600 | G34: =+F34*D34 -> 0
B35: JLG | C35: mes | F35: 89000 | G35: =+F35*D35 -> 0
B36: Grua 20ton | C36: mes | F36: 70000 | G36: =+F36*D36 -> 0
B41: Gastos Indirectos | H41: =SUM(G42:G47) -> 58713324
B42: Admin (50%Compras - 50%RRHH) | C42: mes | D42: =+$F$4 -> 14 | E42: 0.5 | F42: 2578960.6 | G42: =+F42*D42*E42 -> 18052724 | I42: =+G42/$H$4 -> 15429.679
B43: Seguros | C43: gl | D43: =+D42 -> 14 | E43: 1 | F43: 250000 | G43: =+F43*D43 -> 3500000 | I43: =+G43/$H$4 -> 2991.453
B44: IIBB (monto venta obra gris) | C44: gl | D44: 0.04 | E44: 0.6 | F44: 1145000000 | G44: =+F44*D44*E44 -> 27480000 | I44: =+G44/$H$4 -> 23487.179
B45: Imp cheque | C45: gl | D45: =1.2/100 -> 0.012 | E45: =+E44 -> 0.6 | F45: =+F44*1.15 -> 1316750000 | G45: =+F45*D45*E45 -> 9480600 | I45: =+G45/$H$4 -> 8103.0769
B46: Contrato | C46: gl | D46: 1 | E46: 1 | F46: 200000 | G46: =+F46*D46*E46 -> 200000 | I46: =+G46/$H$4 -> 170.94017
...

Sheet 2_Movimientos
A1: Cuenta | B1: Desc Cuenta | C1: Fecha Asiento | D1: Nº Asiento | E1: Observaciones | F1: Cliente/Proveedor | G1: Cód Comprobante | H1: Nº Comprobante | I1: Debe | J1: Haber | K1: Unidad | L1: Desc Unidad | M1: Centro de Costo | N1: Desc Centro Costo | O1: Saldo Inicial | P1: Observaciones original | Q1: mov_id | R1: mov_tipo
A2: 410222 | B2: Obra civil Reforma | C2: 45964 | D2: 4 | E2: Obras - SVD HOUSE S.R.L. | F2: SVD HOUSE S.R.L. | G2: FAWS | H2: 300000760 | I2: 0 | J2: 15000000 | K2: DESA | L2: Desarrollos | M2: SALVA4140 | N2: El Salvador 4140
A3: 410222 | B3: Obra civil Reforma | C3: 45964 | D3: 4 | E3: Obras - SVD HOUSE S.R.L. | F3: SVD HOUSE S.R.L. | G3: FAWS | H3: 300000760 | I3: 0 | J3: 5000000 | K3: DESA | L3: Desarrollos | M3: SALVA4140 | N3: El Salvador 4140
A4: 410222 | B4: Obra civil Reforma | C4: 46009 | D4: 489 | E4: Obras - SVD HOUSE S.R.L. | F4: SVD HOUSE S.R.L. | G4: FAWS | H4: 300000783 | I4: 0 | J4: 13000000 | K4: DESA | L4: Desarrollos | M4: SALVA4140 | N4: El Salvador 4140
A5: 410222 | B5: Obra civil Reforma | C5: 46009 | D5: 489 | E5: Obras - SVD HOUSE S.R.L. | F5: SVD HOUSE S.R.L. | G5: FAWS | H5: 300000783 | I5: 0 | J5: 3500000 | K5: DESA | L5: Desarrollos | M5: SALVA4140 | N5: El Salvador 4140
A6: 410222 | B6: Obra civil Reforma | C6: 46028 | D6: 680 | E6: Obras - SVD HOUSE S.R.L. | F6: SVD HOUSE S.R.L. | G6: FAWS | H6: 300000791 | I6: 0 | J6: 15750000 | K6: DESA | L6: Desarrollos | M6: SALVA4140 | N6: El Salvador 4140
A7: 410222 | B7: Obra civil Reforma | C7: 46028 | D7: 680 | E7: Obras - SVD HOUSE S.R.L. | F7: SVD HOUSE S.R.L. | G7: FAWS | H7: 300000791 | I7: 0 | J7: 5480000 | K7: DESA | L7: Desarrollos | M7: SALVA4140 | N7: El Salvador 4140
A8: 410222 | B8: Obra civil Reforma | C8: 46056 | D8: 1144 | E8: Obras - SVD HOUSE S.R.L. | F8: SVD HOUSE S.R.L. | G8: FAWS | H8: 300000809 | I8: 0 | J8: 20200000 | K8: DESA | L8: Desarrollos | M8: SALVA4140 | N8: El Salvador 4140
A9: 410222 | B9: Obra civil Reforma | C9: 46056 | D9: 1144 | E9: Obras - SVD HOUSE S.R.L. | F9: SVD HOUSE S.R.L. | G9: FAWS | H9: 300000809 | I9: 0 | J9: 13150000 | K9: DESA | L9: Desarrollos | M9: SALVA4140 | N9: El Salvador 4140
A10: 410222 | B10: Obra civil Reforma | C10: 46056 | D10: 1144 | E10: Obras - SVD HOUSE S.R.L. | F10: SVD HOUSE S.R.L. | G10: FAWS | H10: 300000809 | I10: 0 | J10: 4650000 | K10: DESA | L10: Desarrollos | M10: SALVA4140 | N10: El Salvador 4140
A11: 410222 | B11: Obra civil Reforma | C11: 46098 | D11: 1712 | E11: Obras - SVD HOUSE S.R.L. | F11: SVD HOUSE S.R.L. | G11: FAWS | H11: 300000831 | I11: 0 | J11: 13000000 | K11: DESA | L11: Desarrollos | M11: SALVA4140 | N11: El Salvador 4140
A12: 410222 | B12: Obra civil Reforma | C12: 46098 | D12: 1712 | E12: Obras - SVD HOUSE S.R.L. | F12: SVD HOUSE S.R.L. | G12: FAWS | H12: 300000831 | I12: 0 | J12: 5000000 | K12: DESA | L12: Desarrollos | M12: SALVA4140 | N12: El Salvador 4140
A13: 410222 | B13: Obra civil Reforma | C13: 46120 | D13: 2139 | E13: Obras - SVD HOUSE S.R.L. | F13: SVD HOUSE S.R.L. | G13: FAWS | H13: 300000846 | I13: 0 | J13: 20000000 | K13: DESA | L13: Desarrollos | M13: SALVA4140 | N13: El Salvador 4140
A14: 410222 | B14: Obra civil Reforma | C14: 46164 | D14: 2839 | E14: Obras - SVD HOUSE S.R.L. | F14: SVD HOUSE S.R.L. | G14: FAWS | H14: 300000865 | I14: 0 | J14: 29650000 | K14: DESA | L14: Desarrollos | M14: SALVA4140 | N14: El Salvador 4140
A15: 4201 | B15: Otros ingresos | C15: 45973 | D15: 23 | E15: SVD House SRL-Pto 1 Cert 8 | G15: OIXX | H15: 237 | I15: 0 | J15: 1350661 | K15: DESA | L15: Desarrollos | M15: SALVA4140 | N15: El Salvador 4140
A16: 4201 | B16: Otros ingresos | C16: 45973 | D16: 24 | E16: SVD House SRL-Pto. 2 Cert 1 | G16: OIXX | H16: 238 | I16: 0 | J16: 9792918 | K16: DESA | L16: Desarrollos | M16: SALVA4140 | N16: El Salvador 4140
A17: 4201 | B17: Otros ingresos | C17: 45995 | D17: 163 | E17: SVD House SRL | G17: OIXX | H17: 242 | I17: 0 | J17: 43800000 | K17: DESA | L17: Desarrollos | M17: SALVA4140 | N17: El Salvador 4140
A18: 4201 | B18: Otros ingresos | C18: 46037 | D18: 326 | E18: SVD House SRL - Certif. | G18: OIXX | H18: 252 | I18: 0 | J18: 30330000 | K18: DESA | L18: Desarrollos | M18: SALVA4140 | N18: El Salvador 4140
A19: 4201 | B19: Otros ingresos | C19: 46086 | D19: 672 | E19: SVD House SRL | G19: OIXX | H19: 263 | I19: 0 | J19: 27240000 | K19: DESA | L19: Desarrollos | M19: SALVA4140 | N19: El Salvador 4140
A20: 4201 | B20: Otros ingresos | C20: 46122 | D20: 937 | E20: SVD House SRL | G20: OIXX | H20: 271 | I20: 0 | J20: 35025000 | K20: DESA | L20: Desarrollos | M20: SALVA4140 | N20: El Salvador 4140
A21: 4201 | B21: Otros ingresos | C21: 46154 | D21: 1227 | E21: SVD HOUSE SRL - Certif. #7 Pto | G21: OIXX | H21: 274 | I21: 0 | J21: 56000000 | K21: DESA | L21: Desarrollos | M21: SALVA4140 | N21: El Salvador 4140
A22: 4201 | B22: Otros ingresos | C22: 46154 | D22: 1228 | E22: SVD HOUSE SRL - Certif. #2 Pto | G22: OIXX | H22: 275 | I22: 0 | J22: 1870000 | K22: DESA | L22: Desarrollos | M22: SALVA4140 | N22: El Salvador 4140
A23: 5101 | B23: Sueldos | C23: 46073 | D23: 577 | E23: Nelson Aguilera-Premio Hormigo | G23: OPXX | H23: 8598 | I23: 2199000 | J23: 0 | K23: DESA | L23: Desarrollos | M23: SALVA4140 | N23: El Salvador 4140
A24: 5108 | B24: Gastos en personal | C24: 46134 | D24: 2535 | E24: Gastos en Personales - Abrafer | F24: Abrafer S.R.L. | G24: FCA3 | H24: 1000223626 | I24: 26100 | J24: 0 | K24: DESA | L24: Desarrollos | M24: SALVA4140 | N24: El Salvador 4140
A25: 52005 | B25: Internet | C25: 45982 | D25: 218 | E25: Internet - Telecom Argentina S | F25: Telecom Argentina S.A. | G25: FCA3 | H25: 395005503422 | I25: 57041.33 | J25: 0 | K25: DESA | L25: Desarrollos | M25: SALVA4140 | N25: El Salvador 4140
A26: 52005 | B26: Internet | C26: 46012 | D26: 841 | E26: Internet - Telecom Argentina S | F26: Telecom Argentina S.A. | G26: FCA3 | H26: 395005786141 | I26: 58734.3 | J26: 0 | K26: DESA | L26: Desarrollos | M26: SALVA4140 | N26: El Salvador 4140
A27: 52005 | B27: Internet | C27: 46043 | D27: 1003 | E27: Internet - Telecom Argentina S | F27: Telecom Argentina S.A. | G27: FCA3 | H27: 395006067664 | I27: 60188.44 | J27: 0 | K27: DESA | L27: Desarrollos | M27: SALVA4140 | N27: El Salvador 4140
A28: 52005 | B28: Internet | C28: 46074 | D28: 1383 | E28: Internet - Telecom Argentina S | F28: Telecom Argentina S.A. | G28: FCA3 | H28: 395006348871 | I28: 61986.79 | J28: 0 | K28: DESA | L28: Desarrollos | M28: SALVA4140 | N28: El Salvador 4140
A29: 52005 | B29: Internet | C29: 46102 | D29: 2164 | E29: Internet - Telecom Argentina S | F29: Telecom Argentina S.A. | G29: FCA3 | H29: 395006630182 | I29: 64143.4 | J29: 0 | K29: DESA | L29: Desarrollos | M29: SALVA4140 | N29: El Salvador 4140
A30: 52005 | B30: Internet | C30: 46133 | D30: 2525 | E30: Internet - Telecom Argentina S | F30: Telecom Argentina S.A. | G30: FCA3 | H30: 395006903339 | I30: 54669.43 | J30: 0 | K30: DESA | L30: Desarrollos | M30: SALVA4140 | N30: El Salvador 4140
A31: 52101 | B31: Librería | C31: 45974 | D31: 461 | E31: LIBRERIA - D&D PAPELERA SRL | F31: D&D PAPELERA SRL | G31: TIQA | H31: 300008979 | I31: 6198.35 | J31: 0 | K31: DESA | L31: Desarrollos | M31: SALVA4140 | N31: El Salvador 4140
A32: 52103 | B32: Supermercados | C32: 45996 | D32: 162 | E32: Supermercados | G32: OPXX | H32: 8181 | I32: 150000 | J32: 0 | K32: DESA | L32: Desarrollos | M32: SALVA4140 | N32: El Salvador 4140
A33: 52103 | B33: Supermercados | C33: 46104 | D33: 1058 | E33: Supermercados | G33: OPXX | H33: 9086 | I33: 11810 | J33: 0 | K33: DESA | L33: Desarrollos | M33: SALVA4140 | N33: El Salvador 4140
A34: 52104 | B34: Aguas | C34: 45962 | D34: 15 | E34: Aguas - La Estradense SRL | F34: La Estradense SRL | G34: FCA3 | H34: 2900053162 | I34: 164600 | J34: 0 | K34: DESA | L34: Desarrollos | M34: SALVA4140 | N34: El Salvador 4140
A35: 52104 | B35: Aguas | C35: 45992 | D35: 246 | E35: Aguas - La Estradense SRL | F35: La Estradense SRL | G35: FCA3 | H35: 2900053592 | I35: 281250 | J35: 0 | K35: DESA | L35: Desarrollos | M35: SALVA4140 | N35: El Salvador 4140
A36: 52104 | B36: Aguas | C36: 46023 | D36: 700 | E36: Aguas - La Estradense SRL | F36: La Estradense SRL | G36: FCA3 | H36: 2900054002 | I36: 320400 | J36: 0 | K36: DESA | L36: Desarrollos | M36: SALVA4140 | N36: El Salvador 4140
A37: 52104 | B37: Aguas | C37: 46055 | D37: 1199 | E37: Aguas - La Estradense SRL | F37: La Estradense SRL | G37: FCA3 | H37: 2900054427 | I37: 431150 | J37: 0 | K37: DESA | L37: Desarrollos | M37: SALVA4140 | N37: El Salvador 4140
A38: 52104 | B38: Aguas | C38: 46082 | D38: 1402 | E38: Aguas - La Estradense SRL | F38: La Estradense SRL | G38: FCA3 | H38: 2900054845 | I38: 240000 | J38: 0 | K38: DESA | L38: Desarrollos | M38: SALVA4140 | N38: El Salvador 4140
A39: 52104 | B39: Aguas | C39: 46113 | D39: 2124 | E39: Aguas - La Estradense SRL | F39: La Estradense SRL | G39: FCA3 | H39: 2900055264 | I39: 291400 | J39: 0 | K39: DESA | L39: Desarrollos | M39: SALVA4140 | N39: El Salvador 4140
A40: 52104 | B40: Aguas | C40: 46143 | D40: 2604 | E40: Aguas - La Estradense SRL | F40: La Estradense SRL | G40: FCA3 | H40: 2900055674 | I40: 281750 | J40: 0 | K40: DESA | L40: Desarrollos | M40: SALVA4140 | N40: El Salvador 4140
...

Sheet 1_Composicion
A1: Partida | B1: Tipo | C1: Subtipo | D1: Cod_Insumo | E1: Descripción | F1: Unidad de medida | G1: Cant | H1: %Desp | I1: Precio | J1: Costo | K1: Clave | L1: Count | M1: Clave2 | N1: Rend. Part. | O1: Cant MO/ALB Unit | P1: Cant. Ej. Part. | Q1: Cant MO/ALB Total | R1: Cod_Item_Ppto | S1: Rubro
A2: PTO-0102 | B2: MO | C2: OTR | D2: SUB-0001 | E2: JEFE DE OBRA | F2: j | G2: 1 | H2: 0 | I2: 172653.21 | J2: 172653.21 | K2: PTO-0102|MO | L2: 1 | M2: PTO-0102|MO|1 | N2: 1 | O2: 0 | P2: 3 | Q2: 0 | R2: 1.02 | S2: =IFERROR(_xlfn.XLOOKUP(R2,'1_Presupuesto'!$E:$E,'1_Presupuesto'!$D:$D),"") -> Preliminares
A3: PTO-0102 | B3: MO | C3: ALB | D3: MO-AYU | E3: AYUDANTE | F3: j | G3: 1.6666667 | H3: 0 | I3: 49934.24 | J3: 83223.733 | K3: PTO-0102|MO | L3: 2 | M3: PTO-0102|MO|2 | N3: 1 | O3: 1.6666667 | P3: 3 | Q3: 5 | R3: 1.02 | S3: =IFERROR(_xlfn.XLOOKUP(R3,'1_Presupuesto'!$E:$E,'1_Presupuesto'!$D:$D),"") -> Preliminares
A4: PTO-0102 | B4: EQ | D4: EQ-0001 | E4: Herramientas/consumibles - Topógrafo - Visita de obra replanteo | G4: 1 | H4: 0 | I4: 4463.1541 | J4: 4463.1541 | K4: PTO-0102|EQ | L4: 1 | M4: PTO-0102|EQ|1 | N4: 1 | O4: 0 | P4: 3 | Q4: 0 | R4: 1.02 | S4: =IFERROR(_xlfn.XLOOKUP(R4,'1_Presupuesto'!$E:$E,'1_Presupuesto'!$D:$D),"") -> Preliminares
A5: PTO-0102 | B5: MAT | C5: CONS | D5: MAT-CONS | E5: Consumibles | G5: 41666.667 | H5: 0 | I5: 1 | J5: 41666.667 | K5: PTO-0102|MAT | L5: 1 | M5: PTO-0102|MAT|1 | N5: 1 | O5: 0 | P5: 3 | Q5: 0 | R5: 1.02 | S5: =IFERROR(_xlfn.XLOOKUP(R5,'1_Presupuesto'!$E:$E,'1_Presupuesto'!$D:$D),"") -> Preliminares
A6: PTO-0104 | B6: MAT | C6: OTR | D6: MAT-0001 | E6: C. CIN. T101 ESP 0,50 MM (C25) | G6: 2.5 | H6: 0 | I6: 10599.984 | J6: 26499.959 | K6: PTO-0104|MAT | L6: 1 | M6: PTO-0104|MAT|1 | N6: 1 | O6: 0 | P6: 11 | Q6: 0 | R6: 1.04 | S6: =IFERROR(_xlfn.XLOOKUP(R6,'1_Presupuesto'!$E:$E,'1_Presupuesto'!$D:$D),"") -> Preliminares
A7: PTO-0104 | B7: MAT | C7: OTR | D7: MAT-0002 | E7: Peril UPN 100 x 12 m | G7: 0.09090909 | H7: 0 | I7: 267019.02 | J7: 24274.456 | K7: PTO-0104|MAT | L7: 2 | M7: PTO-0104|MAT|2 | N7: 1 | O7: 0 | P7: 11 | Q7: 0 | R7: 1.04 | S7: =IFERROR(_xlfn.XLOOKUP(R7,'1_Presupuesto'!$E:$E,'1_Presupuesto'!$D:$D),"") -> Preliminares
A8: PTO-0104 | B8: MAT | C8: OTR | D8: MAT-0003 | E8: Tubo estructural 40 x 40 x 2, Largo 6 metros | G8: 0.18181818 | H8: 0 | I8: 26250.62 | J8: 4772.8399 | K8: PTO-0104|MAT | L8: 3 | M8: PTO-0104|MAT|3 | N8: 1 | O8: 0 | P8: 11 | Q8: 0 | R8: 1.04 | S8: =IFERROR(_xlfn.XLOOKUP(R8,'1_Presupuesto'!$E:$E,'1_Presupuesto'!$D:$D),"") -> Preliminares
A9: PTO-0104 | B9: MAT | C9: OTR | D9: MAT-0004 | E9: Riel Roma 174 e: 2,1 mm. 53 x 60 x 6000 | G9: 0.09090909 | H9: 0 | I9: 81509.95 | J9: 7409.9954 | K9: PTO-0104|MAT | L9: 4 | M9: PTO-0104|MAT|4 | N9: 1 | O9: 0 | P9: 11 | Q9: 0 | R9: 1.04 | S9: =IFERROR(_xlfn.XLOOKUP(R9,'1_Presupuesto'!$E:$E,'1_Presupuesto'!$D:$D),"") -> Preliminares
A10: PTO-0104 | B10: MAT | C10: OTR | D10: MAT-0005 | E10: Carro acero 174 4 ruedas puertas portones Ø45mm | G10: 0.18181818 | H10: 0 | I10: 12131.562 | J10: 2205.7385 | K10: PTO-0104|MAT | L10: 5 | M10: PTO-0104|MAT|5 | N10: 1 | O10: 0 | P10: 11 | Q10: 0 | R10: 1.04 | S10: =IFERROR(_xlfn.XLOOKUP(R10,'1_Presupuesto'!$E:$E,'1_Presupuesto'!$D:$D),"") -> Preliminares
A11: PTO-0104 | B11: MAT | C11: OTR | D11: MAT-0006 | E11: Autoperforantes punta mecha 14 x 2 | G11: 11.25 | H11: 0 | I11: 120 | J11: 1350 | K11: PTO-0104|MAT | L11: 6 | M11: PTO-0104|MAT|6 | N11: 1 | O11: 0 | P11: 11 | Q11: 0 | R11: 1.04 | S11: =IFERROR(_xlfn.XLOOKUP(R11,'1_Presupuesto'!$E:$E,'1_Presupuesto'!$D:$D),"") -> Preliminares
A12: PTO-0104 | B12: MAT | C12: OTR | D12: MAT-0007 | E12: Rollo Concertina | G12: 0.09090909 | H12: 0 | I12: 31404.959 | J12: 2854.9962 | K12: PTO-0104|MAT | L12: 7 | M12: PTO-0104|MAT|7 | N12: 1 | O12: 0 | P12: 11 | Q12: 0 | R12: 1.04 | S12: =IFERROR(_xlfn.XLOOKUP(R12,'1_Presupuesto'!$E:$E,'1_Presupuesto'!$D:$D),"") -> Preliminares
A13: PTO-0104 | B13: MO | C13: ALB | D13: MO-OFI | E13: OFICIAL | F13: j | G13: 0.18181818 | H13: 0 | I13: 65360.25 | J13: 11883.682 | K13: PTO-0104|MO | L13: 1 | M13: PTO-0104|MO|1 | N13: 1 | O13: 0.18181818 | P13: 11 | Q13: 2 | R13: 1.04 | S13: =IFERROR(_xlfn.XLOOKUP(R13,'1_Presupuesto'!$E:$E,'1_Presupuesto'!$D:$D),"") -> Preliminares
A14: PTO-0104 | B14: MO | C14: ALB | D14: MO-MED | E14: MEDIO OFICIAL | F14: j | G14: 0.18181818 | H14: 0 | I14: 54784.07 | J14: 9960.7399 | K14: PTO-0104|MO | L14: 2 | M14: PTO-0104|MO|2 | N14: 1 | O14: 0.18181818 | P14: 11 | Q14: 2 | R14: 1.04 | S14: =IFERROR(_xlfn.XLOOKUP(R14,'1_Presupuesto'!$E:$E,'1_Presupuesto'!$D:$D),"") -> Preliminares
A15: PTO-0104 | B15: MO | C15: ALB | D15: MO-AYU | E15: AYUDANTE | F15: j | G15: 0.18181818 | H15: 0 | I15: 49934.24 | J15: 9078.9526 | K15: PTO-0104|MO | L15: 3 | M15: PTO-0104|MO|3 | N15: 1 | O15: 0.18181818 | P15: 11 | Q15: 2 | R15: 1.04 | S15: =IFERROR(_xlfn.XLOOKUP(R15,'1_Presupuesto'!$E:$E,'1_Presupuesto'!$D:$D),"") -> Preliminares
A16: PTO-0104 | B16: EQ | D16: EQ-0002 | E16: Herramientas/consumibles - Cerco de obra perimetral - En chapa C25 | G16: 1 | H16: 0 | I16: 1660.4484 | J16: 1660.4484 | K16: PTO-0104|EQ | L16: 1 | M16: PTO-0104|EQ|1 | N16: 1 | O16: 0 | P16: 11 | Q16: 0 | R16: 1.04 | S16: =IFERROR(_xlfn.XLOOKUP(R16,'1_Presupuesto'!$E:$E,'1_Presupuesto'!$D:$D),"") -> Preliminares
A17: PTO-0104 | B17: MAT | C17: CONS | D17: MAT-CONS | E17: Consumibles | G17: 10405.195 | H17: 0 | I17: 1 | J17: 10405.195 | K17: PTO-0104|MAT | L17: 8 | M17: PTO-0104|MAT|8 | N17: 1 | O17: 0 | P17: 11 | Q17: 0 | R17: 1.04 | S17: =IFERROR(_xlfn.XLOOKUP(R17,'1_Presupuesto'!$E:$E,'1_Presupuesto'!$D:$D),"") -> Preliminares
A18: PTO-0105 | B18: MAT | C18: OTR | D18: MAT-0008 | E18: C. CIN. T101 ESP 0,50 MM (C25) | G18: 35 | H18: 0 | I18: 5299.9917 | J18: 185499.71 | K18: PTO-0105|MAT | L18: 1 | M18: PTO-0105|MAT|1 | N18: 1 | O18: 0 | P18: 1 | Q18: 0 | R18: 1.05 | S18: =IFERROR(_xlfn.XLOOKUP(R18,'1_Presupuesto'!$E:$E,'1_Presupuesto'!$D:$D),"") -> Preliminares
A19: PTO-0105 | B19: MAT | C19: OTR | D19: MAT-0009 | E19: Precio fenolico comun e: 18 mm | G19: 33 | H19: 0 | I19: 13161.34 | J19: 434324.22 | K19: PTO-0105|MAT | L19: 2 | M19: PTO-0105|MAT|2 | N19: 1 | O19: 0 | P19: 1 | Q19: 0 | R19: 1.05 | S19: =IFERROR(_xlfn.XLOOKUP(R19,'1_Presupuesto'!$E:$E,'1_Presupuesto'!$D:$D),"") -> Preliminares
A20: PTO-0105 | B20: MAT | C20: OTR | D20: MAT-0010 | E20: Tabla 4 x 1 x 3,6 Saligna bruto | G20: 80 | H20: 0 | I20: 970.974 | J20: 77677.92 | K20: PTO-0105|MAT | L20: 3 | M20: PTO-0105|MAT|3 | N20: 1 | O20: 0 | P20: 1 | Q20: 0 | R20: 1.05 | S20: =IFERROR(_xlfn.XLOOKUP(R20,'1_Presupuesto'!$E:$E,'1_Presupuesto'!$D:$D),"") -> Preliminares
A21: PTO-0105 | B21: MAT | C21: OTR | D21: MAT-0011 | E21: Tirante 3 x 3 x 3,6 Saligna bruto | G21: 40 | H21: 0 | I21: 2184.714 | J21: 87388.56 | K21: PTO-0105|MAT | L21: 4 | M21: PTO-0105|MAT|4 | N21: 1 | O21: 0 | P21: 1 | Q21: 0 | R21: 1.05 | S21: =IFERROR(_xlfn.XLOOKUP(R21,'1_Presupuesto'!$E:$E,'1_Presupuesto'!$D:$D),"") -> Preliminares
A22: PTO-0105 | B22: MAT | C22: OTR | D22: MAT-0012 | E22: Flechas 3 x 6 x 3,7 - Reutilizado (estimado 3 usos) | G22: 20 | H22: 0 | I22: 4369.428 | J22: 87388.56 | K22: PTO-0105|MAT | L22: 5 | M22: PTO-0105|MAT|5 | N22: 1 | O22: 0 | P22: 1 | Q22: 0 | R22: 1.05 | S22: =IFERROR(_xlfn.XLOOKUP(R22,'1_Presupuesto'!$E:$E,'1_Presupuesto'!$D:$D),"") -> Preliminares
A23: PTO-0105 | B23: MAT | C23: OTR | D23: MAT-0013 | E23: Escalera | G23: 0.5 | H23: 0 | I23: 252455.04 | J23: 126227.52 | K23: PTO-0105|MAT | L23: 6 | M23: PTO-0105|MAT|6 | N23: 1 | O23: 0 | P23: 1 | Q23: 0 | R23: 1.05 | S23: =IFERROR(_xlfn.XLOOKUP(R23,'1_Presupuesto'!$E:$E,'1_Presupuesto'!$D:$D),"") -> Preliminares
A24: PTO-0105 | B24: MO | C24: OTR | D24: SUB-0002 | E24: Flete madera | F24: j | G24: 2 | H24: 0 | I24: 250000 | J24: 500000 | K24: PTO-0105|MO | L24: 1 | M24: PTO-0105|MO|1 | N24: 1 | O24: 0 | P24: 1 | Q24: 0 | R24: 1.05 | S24: =IFERROR(_xlfn.XLOOKUP(R24,'1_Presupuesto'!$E:$E,'1_Presupuesto'!$D:$D),"") -> Preliminares
A25: PTO-0105 | B25: MAT | C25: COR | D25: MAT-0014 | E25: Materiales varios | G25: 1 | H25: 0 | I25: 100000 | J25: 100000 | K25: PTO-0105|MAT | L25: 7 | M25: PTO-0105|MAT|7 | N25: 1 | O25: 0 | P25: 1 | Q25: 0 | R25: 1.05 | S25: =IFERROR(_xlfn.XLOOKUP(R25,'1_Presupuesto'!$E:$E,'1_Presupuesto'!$D:$D),"") -> Preliminares
A26: PTO-0105 | B26: MO | C26: ALB | D26: MO-ESP | E26: ESPECIALIZADO | F26: j | G26: 12 | H26: 0 | I26: 75113.05 | J26: 901356.6 | K26: PTO-0105|MO | L26: 2 | M26: PTO-0105|MO|2 | N26: 1 | O26: 12 | P26: 1 | Q26: 12 | R26: 1.05 | S26: =IFERROR(_xlfn.XLOOKUP(R26,'1_Presupuesto'!$E:$E,'1_Presupuesto'!$D:$D),"") -> Preliminares
A27: PTO-0105 | B27: MO | C27: ALB | D27: MO-OFI | E27: OFICIAL | F27: j | G27: 19 | H27: 0 | I27: 65360.25 | J27: 1241844.8 | K27: PTO-0105|MO | L27: 3 | M27: PTO-0105|MO|3 | N27: 1 | O27: 19 | P27: 1 | Q27: 19 | R27: 1.05 | S27: =IFERROR(_xlfn.XLOOKUP(R27,'1_Presupuesto'!$E:$E,'1_Presupuesto'!$D:$D),"") -> Preliminares
A28: PTO-0105 | B28: MO | C28: ALB | D28: MO-MED | E28: MEDIO OFICIAL | F28: j | G28: 5 | H28: 0 | I28: 54784.07 | J28: 273920.35 | K28: PTO-0105|MO | L28: 4 | M28: PTO-0105|MO|4 | N28: 1 | O28: 5 | P28: 1 | Q28: 5 | R28: 1.05 | S28: =IFERROR(_xlfn.XLOOKUP(R28,'1_Presupuesto'!$E:$E,'1_Presupuesto'!$D:$D),"") -> Preliminares
A29: PTO-0105 | B29: MO | C29: ALB | D29: MO-AYU | E29: AYUDANTE | F29: j | G29: 12 | H29: 0 | I29: 49934.24 | J29: 599210.88 | K29: PTO-0105|MO | L29: 5 | M29: PTO-0105|MO|5 | N29: 1 | O29: 12 | P29: 1 | Q29: 12 | R29: 1.05 | S29: =IFERROR(_xlfn.XLOOKUP(R29,'1_Presupuesto'!$E:$E,'1_Presupuesto'!$D:$D),"") -> Preliminares
A30: PTO-0105 | B30: MAT | C30: OTR | D30: MAT-0015 | E30: Rollo de cable TPR 3 x 2,5 | G30: 1 | H30: 0 | I30: 214876.03 | J30: 214876.03 | K30: PTO-0105|MAT | L30: 8 | M30: PTO-0105|MAT|8 | N30: 1 | O30: 0 | P30: 1 | Q30: 0 | R30: 1.05 | S30: =IFERROR(_xlfn.XLOOKUP(R30,'1_Presupuesto'!$E:$E,'1_Presupuesto'!$D:$D),"") -> Preliminares
A31: PTO-0105 | B31: MAT | C31: OTR | D31: MAT-0016 | E31: Zocalo E27 | G31: 10 | H31: 0 | I31: 369.8347 | J31: 3698.347 | K31: PTO-0105|MAT | L31: 9 | M31: PTO-0105|MAT|9 | N31: 1 | O31: 0 | P31: 1 | Q31: 0 | R31: 1.05 | S31: =IFERROR(_xlfn.XLOOKUP(R31,'1_Presupuesto'!$E:$E,'1_Presupuesto'!$D:$D),"") -> Preliminares
A32: PTO-0105 | B32: MAT | C32: OTR | D32: MAT-0017 | E32: Lampara Led 12 w | G32: 10 | H32: 0 | I32: 2363.6364 | J32: 23636.364 | K32: PTO-0105|MAT | L32: 10 | M32: PTO-0105|MAT|10 | N32: 1 | O32: 0 | P32: 1 | Q32: 0 | R32: 1.05 | S32: =IFERROR(_xlfn.XLOOKUP(R32,'1_Presupuesto'!$E:$E,'1_Presupuesto'!$D:$D),"") -> Preliminares
A33: PTO-0105 | B33: MAT | C33: OTR | D33: MAT-0018 | E33: Mat. Elect. (tomas, enchufes, etc.) | G33: 0.25 | H33: 0 | I33: 242210.74 | J33: 60552.686 | K33: PTO-0105|MAT | L33: 11 | M33: PTO-0105|MAT|11 | N33: 1 | O33: 0 | P33: 1 | Q33: 0 | R33: 1.05 | S33: =IFERROR(_xlfn.XLOOKUP(R33,'1_Presupuesto'!$E:$E,'1_Presupuesto'!$D:$D),"") -> Preliminares
A34: PTO-0105 | B34: MAT | C34: OTR | D34: MAT-0019 | E34: Materiales Sanit | G34: 1 | H34: 0 | I34: 500000 | J34: 500000 | K34: PTO-0105|MAT | L34: 12 | M34: PTO-0105|MAT|12 | N34: 1 | O34: 0 | P34: 1 | Q34: 0 | R34: 1.05 | S34: =IFERROR(_xlfn.XLOOKUP(R34,'1_Presupuesto'!$E:$E,'1_Presupuesto'!$D:$D),"") -> Preliminares
A35: PTO-0105 | B35: MAT | C35: OTR | D35: MAT-0020 | E35: Inodoro | G35: 2 | H35: 0 | I35: 100000 | J35: 200000 | K35: PTO-0105|MAT | L35: 13 | M35: PTO-0105|MAT|13 | N35: 1 | O35: 0 | P35: 1 | Q35: 0 | R35: 1.05 | S35: =IFERROR(_xlfn.XLOOKUP(R35,'1_Presupuesto'!$E:$E,'1_Presupuesto'!$D:$D),"") -> Preliminares
A36: PTO-0105 | B36: MAT | C36: OTR | D36: MAT-0021 | E36: Mochila plastico | G36: 2 | H36: 0 | I36: 25000 | J36: 50000 | K36: PTO-0105|MAT | L36: 14 | M36: PTO-0105|MAT|14 | N36: 1 | O36: 0 | P36: 1 | Q36: 0 | R36: 1.05 | S36: =IFERROR(_xlfn.XLOOKUP(R36,'1_Presupuesto'!$E:$E,'1_Presupuesto'!$D:$D),"") -> Preliminares
A37: PTO-0105 | B37: MAT | C37: OTR | D37: MAT-0022 | E37: Bacha | G37: 2 | H37: 0 | I37: 24793.388 | J37: 49586.777 | K37: PTO-0105|MAT | L37: 15 | M37: PTO-0105|MAT|15 | N37: 1 | O37: 0 | P37: 1 | Q37: 0 | R37: 1.05 | S37: =IFERROR(_xlfn.XLOOKUP(R37,'1_Presupuesto'!$E:$E,'1_Presupuesto'!$D:$D),"") -> Preliminares
A38: PTO-0105 | B38: MAT | C38: OTR | D38: MAT-0023 | E38: Termo electrico 40 lts | G38: 1 | H38: 0 | I38: 200000 | J38: 200000 | K38: PTO-0105|MAT | L38: 16 | M38: PTO-0105|MAT|16 | N38: 1 | O38: 0 | P38: 1 | Q38: 0 | R38: 1.05 | S38: =IFERROR(_xlfn.XLOOKUP(R38,'1_Presupuesto'!$E:$E,'1_Presupuesto'!$D:$D),"") -> Preliminares
A39: PTO-0105 | B39: EQ | D39: EQ-0003 | E39: Herramientas/consumibles - Obrador colgante, pañol y ducha | G39: 1 | H39: 0 | I39: 88757.838 | J39: 88757.838 | K39: PTO-0105|EQ | L39: 1 | M39: PTO-0105|EQ|1 | N39: 1 | O39: 0 | P39: 1 | Q39: 0 | R39: 1.05 | S39: =IFERROR(_xlfn.XLOOKUP(R39,'1_Presupuesto'!$E:$E,'1_Presupuesto'!$D:$D),"") -> Preliminares
A40: PTO-0106 | B40: MO | C40: OTR | D40: SUB-0003 | E40: Baño portatil / Ducha | F40: j | G40: 1 | H40: 0 | I40: 295488.56 | J40: 295488.56 | K40: PTO-0106|MO | L40: 1 | M40: PTO-0106|MO|1 | N40: 1 | O40: 0 | P40: 3 | Q40: 0 | R40: 1.06 | S40: =IFERROR(_xlfn.XLOOKUP(R40,'1_Presupuesto'!$E:$E,'1_Presupuesto'!$D:$D),"") -> -
...

Sheet 2_Gastos_DirInd
A1: Fecha | B1: Tipo | C1: Concepto | D1: Monto

Sheet 2_Quincenas
A1: Resumen Consolidado por Obra (Horas)
A3: Mes | B3: Período | C3: Obra | D3: Categoría | E3: Rubro | F3: Horas totales | G3: Horas normales | H3: Horas extra 50% | I3: Horas extra 100% | K3: Costo Hs. Normales | L3: Costo Hs. Extra 50% | M3: Costo Hs. Extra 100% | N3: Total | O3: Total Descontado
A4: 45689 | B4: 2Q | C4: EL SALVADOR | D4: OFICIAL | E4: Homigón MO | F4: =G4+H4+I4 -> 248 | G4: 248 | H4: 0 | I4: 0
A5: 45689 | B5: 2Q | C5: EL SALVADOR | D5: AYUDANTE | E5: Homigón MO | F5: =G5+H5+I5 -> 8 | G5: 8 | H5: 0 | I5: 0
A6: 45717 | B6: 1Q | C6: EL SALVADOR | D6: OFICIAL | E6: Homigón MO | F6: =G6+H6+I6 -> 280 | G6: 280 | H6: 0 | I6: 0
A7: 45717 | B7: 2Q | C7: EL SALVADOR | D7: CAPATAZ | E7: Homigón MO | F7: =G7+H7+I7 -> 136 | G7: 136 | H7: 0 | I7: 0
A8: 45717 | B8: 2Q | C8: EL SALVADOR | D8: OFICIAL | E8: Homigón MO | F8: =G8+H8+I8 -> 28 | G8: 28 | H8: 0 | I8: 0
A9: 45717 | B9: 2Q | C9: EL SALVADOR | D9: MEDIO OFICIAL | E9: Homigón MO | F9: =G9+H9+I9 -> 44 | G9: 44 | H9: 0 | I9: 0
A10: 45748 | B10: 1Q | C10: EL SALVADOR | D10: CAPATAZ | E10: Homigón MO | F10: =G10+H10+I10 -> 288 | G10: 288 | H10: 0 | I10: 0
A11: 45748 | B11: 1Q | C11: EL SALVADOR | D11: OFICIAL | E11: Homigón MO | F11: =G11+H11+I11 -> 304 | G11: 304 | H11: 0 | I11: 0
A12: 45748 | B12: 1Q | C12: EL SALVADOR | D12: MEDIO OFICIAL | E12: Homigón MO | F12: =G12+H12+I12 -> 88 | G12: 88 | H12: 0 | I12: 0
A13: 45748 | B13: 2Q | C13: EL SALVADOR | D13: CAPATAZ | E13: Homigón MO | F13: =G13+H13+I13 -> 384 | G13: 384 | H13: 0 | I13: 0
A14: 45748 | B14: 2Q | C14: EL SALVADOR | D14: OFICIAL | E14: Homigón MO | F14: =G14+H14+I14 -> 456 | G14: 456 | H14: 0 | I14: 0
A15: 45748 | B15: 2Q | C15: EL SALVADOR | D15: MEDIO OFICIAL | E15: Homigón MO | F15: =G15+H15+I15 -> 96 | G15: 96 | H15: 0 | I15: 0
... A166: 46143 | B166: 2Q | C166: EL SALVADOR | D166: AYUDANTE | E166: Sanitaria MO | F166: =G166+H166+I166 -> 88 | G166: 88 | H166: 0 | I166: 0

Sheet 2_Subcontratos
A1: SUBCONTRATOS — MAESTRO DE CONTRATOS
A3: Contrato# | B3: Proveedor | C3: Rubro | D3: Descripción | E3: Monto Presup. | F3: Ajusta CAC | G3: % Anticipo | H3: Pagado BASE+ANT | I3: CAC pagado | J3: CS pagado | K3: Total pagado | L3: Saldo disponible | M3: % consumido | N3: Estado
